<?xml version="1.0" encoding="UTF-8"?>
<testsuite name="Results (powered by Planemo)"
           tests="35"
           errors="19"
           failures="2"
           skip="0">
    
    <testcase classname="bcftools_convert_to_vcf (Test #1)" name="0" time="10.728789567947388">
        
            <error type="error" message="Input staging problem: Traceback (most recent call last):
  File "/opt/hostedtoolcache/Python/3.12.9/x64/lib/python3.12/site-packages/galaxy/tool_util/verify/interactor.py", line 1434, in verify_tool
    stage_data_in_history(
  File "/opt/hostedtoolcache/Python/3.12.9/x64/lib/python3.12/site-packages/galaxy/tool_util/verify/interactor.py", line 175, in stage_data_in_history
    staging_interface.handle_jobs()
  File "/opt/hostedtoolcache/Python/3.12.9/x64/lib/python3.12/site-packages/galaxy/tool_util/verify/interactor.py", line 212, in handle_jobs
    self.galaxy_interactor.wait_for_job(job_response["id"], job_response["history_id"], self.maxseconds)
  File "/opt/hostedtoolcache/Python/3.12.9/x64/lib/python3.12/site-packages/galaxy/tool_util/verify/interactor.py", line 399, in wait_for_job
    self.wait_for(lambda: self.__job_ready(job_id, history_id), maxseconds=maxseconds)
  File "/opt/hostedtoolcache/Python/3.12.9/x64/lib/python3.12/site-packages/galaxy/tool_util/verify/interactor.py", line 403, in wait_for
    wait_on(func, what, walltime_exceeded)
  File "/opt/hostedtoolcache/Python/3.12.9/x64/lib/python3.12/site-packages/galaxy/tool_util/verify/wait.py", line 38, in wait_on
    value = function()
            ^^^^^^^^^^
  File "/opt/hostedtoolcache/Python/3.12.9/x64/lib/python3.12/site-packages/galaxy/tool_util/verify/interactor.py", line 399, in <lambda>
    self.wait_for(lambda: self.__job_ready(job_id, history_id), maxseconds=maxseconds)
                          ^^^^^^^^^^^^^^^^^^^^^^^^^^^^^^^^^^^^
  File "/opt/hostedtoolcache/Python/3.12.9/x64/lib/python3.12/site-packages/galaxy/tool_util/verify/interactor.py", line 747, in __job_ready
    return self._state_ready(job_id, error_msg="Job in error state.")
           ^^^^^^^^^^^^^^^^^^^^^^^^^^^^^^^^^^^^^^^^^^^^^^^^^^^^^^^^^^
  File "/opt/hostedtoolcache/Python/3.12.9/x64/lib/python3.12/site-packages/galaxy/tool_util/verify/interactor.py", line 839, in _state_ready
    raise Exception(
Exception: Job in error state.. tool_id: __DATA_FETCH__, exit_code: None, stderr: .
"><![CDATA[
                { "execution_problem": "Input staging problem: Traceback (most recent call last):\n  File \"/opt/hostedtoolcache/Python/3.12.9/x64/lib/python3.12/site-packages/galaxy/tool_util/verify/interactor.py\", line 1434, in verify_tool\n    stage_data_in_history(\n  File \"/opt/hostedtoolcache/Python/3.12.9/x64/lib/python3.12/site-packages/galaxy/tool_util/verify/interactor.py\", line 175, in stage_data_in_history\n    staging_interface.handle_jobs()\n  File \"/opt/hostedtoolcache/Python/3.12.9/x64/lib/python3.12/site-packages/galaxy/tool_util/verify/interactor.py\", line 212, in handle_jobs\n    self.galaxy_interactor.wait_for_job(job_response[\"id\"], job_response[\"history_id\"], self.maxseconds)\n  File \"/opt/hostedtoolcache/Python/3.12.9/x64/lib/python3.12/site-packages/galaxy/tool_util/verify/interactor.py\", line 399, in wait_for_job\n    self.wait_for(lambda: self.__job_ready(job_id, history_id), maxseconds=maxseconds)\n  File \"/opt/hostedtoolcache/Python/3.12.9/x64/lib/python3.12/site-packages/galaxy/tool_util/verify/interactor.py\", line 403, in wait_for\n    wait_on(func, what, walltime_exceeded)\n  File \"/opt/hostedtoolcache/Python/3.12.9/x64/lib/python3.12/site-packages/galaxy/tool_util/verify/wait.py\", line 38, in wait_on\n    value = function()\n            ^^^^^^^^^^\n  File \"/opt/hostedtoolcache/Python/3.12.9/x64/lib/python3.12/site-packages/galaxy/tool_util/verify/interactor.py\", line 399, in \u003clambda\u003e\n    self.wait_for(lambda: self.__job_ready(job_id, history_id), maxseconds=maxseconds)\n                          ^^^^^^^^^^^^^^^^^^^^^^^^^^^^^^^^^^^^\n  File \"/opt/hostedtoolcache/Python/3.12.9/x64/lib/python3.12/site-packages/galaxy/tool_util/verify/interactor.py\", line 747, in __job_ready\n    return self._state_ready(job_id, error_msg=\"Job in error state.\")\n           ^^^^^^^^^^^^^^^^^^^^^^^^^^^^^^^^^^^^^^^^^^^^^^^^^^^^^^^^^^\n  File \"/opt/hostedtoolcache/Python/3.12.9/x64/lib/python3.12/site-packages/galaxy/tool_util/verify/interactor.py\", line 839, in _state_ready\n    raise Exception(\nException: Job in error state.. tool_id: __DATA_FETCH__, exit_code: None, stderr: .\n", "status": "error", "test_index": 0, "time_seconds": 10.728789567947388, "tool_id": "bcftools_convert_to_vcf", "tool_version": "1.15.1+galaxy4"}
            ]]></error>
        
    </testcase>
    
    <testcase classname="bcftools_convert_to_vcf (Test #2)" name="1" time="46.09956240653992">
        
            
            <system-out><![CDATA[
            
            ]]></system-out>
            <system-err><![CDATA[
            Number of processed rows: 35
            ]]></system-err>
        
    </testcase>
    
    <testcase classname="bcftools_convert_to_vcf (Test #3)" name="2" time="35.83207392692566">
        
            
            <system-out><![CDATA[
            
            ]]></system-out>
            <system-err><![CDATA[
            Number of processed rows: 35
            ]]></system-err>
        
    </testcase>
    
    <testcase classname="bcftools_convert_to_vcf (Test #4)" name="3" time="32.56157088279724">
        
            
            <system-out><![CDATA[
            
            ]]></system-out>
            <system-err><![CDATA[
            
            ]]></system-err>
        
    </testcase>
    
    <testcase classname="bcftools_convert_to_vcf (Test #5)" name="4" time="">
        
            <error type="error" message=""><![CDATA[
                { "status": "skip", "test_index": 4, "tool_id": "bcftools_convert_to_vcf", "tool_version": "1.15.1+galaxy4"}
            ]]></error>
        
    </testcase>
    
    <testcase classname="bcftools_convert_to_vcf (Test #6)" name="5" time="10.808410406112671">
        
            <error type="error" message="Input staging problem: Traceback (most recent call last):
  File "/opt/hostedtoolcache/Python/3.12.9/x64/lib/python3.12/site-packages/galaxy/tool_util/verify/interactor.py", line 1434, in verify_tool
    stage_data_in_history(
  File "/opt/hostedtoolcache/Python/3.12.9/x64/lib/python3.12/site-packages/galaxy/tool_util/verify/interactor.py", line 175, in stage_data_in_history
    staging_interface.handle_jobs()
  File "/opt/hostedtoolcache/Python/3.12.9/x64/lib/python3.12/site-packages/galaxy/tool_util/verify/interactor.py", line 212, in handle_jobs
    self.galaxy_interactor.wait_for_job(job_response["id"], job_response["history_id"], self.maxseconds)
  File "/opt/hostedtoolcache/Python/3.12.9/x64/lib/python3.12/site-packages/galaxy/tool_util/verify/interactor.py", line 399, in wait_for_job
    self.wait_for(lambda: self.__job_ready(job_id, history_id), maxseconds=maxseconds)
  File "/opt/hostedtoolcache/Python/3.12.9/x64/lib/python3.12/site-packages/galaxy/tool_util/verify/interactor.py", line 403, in wait_for
    wait_on(func, what, walltime_exceeded)
  File "/opt/hostedtoolcache/Python/3.12.9/x64/lib/python3.12/site-packages/galaxy/tool_util/verify/wait.py", line 38, in wait_on
    value = function()
            ^^^^^^^^^^
  File "/opt/hostedtoolcache/Python/3.12.9/x64/lib/python3.12/site-packages/galaxy/tool_util/verify/interactor.py", line 399, in <lambda>
    self.wait_for(lambda: self.__job_ready(job_id, history_id), maxseconds=maxseconds)
                          ^^^^^^^^^^^^^^^^^^^^^^^^^^^^^^^^^^^^
  File "/opt/hostedtoolcache/Python/3.12.9/x64/lib/python3.12/site-packages/galaxy/tool_util/verify/interactor.py", line 747, in __job_ready
    return self._state_ready(job_id, error_msg="Job in error state.")
           ^^^^^^^^^^^^^^^^^^^^^^^^^^^^^^^^^^^^^^^^^^^^^^^^^^^^^^^^^^
  File "/opt/hostedtoolcache/Python/3.12.9/x64/lib/python3.12/site-packages/galaxy/tool_util/verify/interactor.py", line 839, in _state_ready
    raise Exception(
Exception: Job in error state.. tool_id: __DATA_FETCH__, exit_code: None, stderr: .
"><![CDATA[
                { "execution_problem": "Input staging problem: Traceback (most recent call last):\n  File \"/opt/hostedtoolcache/Python/3.12.9/x64/lib/python3.12/site-packages/galaxy/tool_util/verify/interactor.py\", line 1434, in verify_tool\n    stage_data_in_history(\n  File \"/opt/hostedtoolcache/Python/3.12.9/x64/lib/python3.12/site-packages/galaxy/tool_util/verify/interactor.py\", line 175, in stage_data_in_history\n    staging_interface.handle_jobs()\n  File \"/opt/hostedtoolcache/Python/3.12.9/x64/lib/python3.12/site-packages/galaxy/tool_util/verify/interactor.py\", line 212, in handle_jobs\n    self.galaxy_interactor.wait_for_job(job_response[\"id\"], job_response[\"history_id\"], self.maxseconds)\n  File \"/opt/hostedtoolcache/Python/3.12.9/x64/lib/python3.12/site-packages/galaxy/tool_util/verify/interactor.py\", line 399, in wait_for_job\n    self.wait_for(lambda: self.__job_ready(job_id, history_id), maxseconds=maxseconds)\n  File \"/opt/hostedtoolcache/Python/3.12.9/x64/lib/python3.12/site-packages/galaxy/tool_util/verify/interactor.py\", line 403, in wait_for\n    wait_on(func, what, walltime_exceeded)\n  File \"/opt/hostedtoolcache/Python/3.12.9/x64/lib/python3.12/site-packages/galaxy/tool_util/verify/wait.py\", line 38, in wait_on\n    value = function()\n            ^^^^^^^^^^\n  File \"/opt/hostedtoolcache/Python/3.12.9/x64/lib/python3.12/site-packages/galaxy/tool_util/verify/interactor.py\", line 399, in \u003clambda\u003e\n    self.wait_for(lambda: self.__job_ready(job_id, history_id), maxseconds=maxseconds)\n                          ^^^^^^^^^^^^^^^^^^^^^^^^^^^^^^^^^^^^\n  File \"/opt/hostedtoolcache/Python/3.12.9/x64/lib/python3.12/site-packages/galaxy/tool_util/verify/interactor.py\", line 747, in __job_ready\n    return self._state_ready(job_id, error_msg=\"Job in error state.\")\n           ^^^^^^^^^^^^^^^^^^^^^^^^^^^^^^^^^^^^^^^^^^^^^^^^^^^^^^^^^^\n  File \"/opt/hostedtoolcache/Python/3.12.9/x64/lib/python3.12/site-packages/galaxy/tool_util/verify/interactor.py\", line 839, in _state_ready\n    raise Exception(\nException: Job in error state.. tool_id: __DATA_FETCH__, exit_code: None, stderr: .\n", "status": "error", "test_index": 5, "time_seconds": 10.808410406112671, "tool_id": "bcftools_convert_to_vcf", "tool_version": "1.15.1+galaxy4"}
            ]]></error>
        
    </testcase>
    
    <testcase classname="bcftools_convert_to_vcf (Test #7)" name="6" time="">
        
            <error type="error" message=""><![CDATA[
                { "status": "skip", "test_index": 6, "tool_id": "bcftools_convert_to_vcf", "tool_version": "1.15.1+galaxy4"}
            ]]></error>
        
    </testcase>
    
    <testcase classname="bcftools_plugin_fill_an_ac (Test #1)" name="0" time="38.62837791442871">
        
            
            <system-out><![CDATA[
            
            ]]></system-out>
            <system-err><![CDATA[
            
            ]]></system-err>
        
    </testcase>
    
    <testcase classname="collection_column_join (Test #1)" name="0" time="0.10150527954101562">
        
            <error type="error" message="Input staging problem: Traceback (most recent call last):
  File "/opt/hostedtoolcache/Python/3.12.9/x64/lib/python3.12/site-packages/galaxy/tool_util/verify/interactor.py", line 1434, in verify_tool
    stage_data_in_history(
  File "/opt/hostedtoolcache/Python/3.12.9/x64/lib/python3.12/site-packages/galaxy/tool_util/verify/interactor.py", line 163, in stage_data_in_history
    test_dict = galaxy_interactor.remote_to_input(
                ^^^^^^^^^^^^^^^^^^^^^^^^^^^^^^^^^^
  File "/opt/hostedtoolcache/Python/3.12.9/x64/lib/python3.12/site-packages/galaxy/tool_util/verify/interactor.py", line 582, in remote_to_input
    path_or_location = self._get_path_or_location(
                       ^^^^^^^^^^^^^^^^^^^^^^^^^^^
  File "/opt/hostedtoolcache/Python/3.12.9/x64/lib/python3.12/site-packages/galaxy/tool_util/verify/interactor.py", line 619, in _get_path_or_location
    path = self.test_data_download(
           ^^^^^^^^^^^^^^^^^^^^^^^^
  File "/opt/hostedtoolcache/Python/3.12.9/x64/lib/python3.12/site-packages/galaxy/tool_util/verify/interactor.py", line 525, in test_data_download
    raise AssertionError(f"Test input file ({filename}) cannot be found.")
AssertionError: Test input file (in_1.tabular) cannot be found.
"><![CDATA[
                { "execution_problem": "Input staging problem: Traceback (most recent call last):\n  File \"/opt/hostedtoolcache/Python/3.12.9/x64/lib/python3.12/site-packages/galaxy/tool_util/verify/interactor.py\", line 1434, in verify_tool\n    stage_data_in_history(\n  File \"/opt/hostedtoolcache/Python/3.12.9/x64/lib/python3.12/site-packages/galaxy/tool_util/verify/interactor.py\", line 163, in stage_data_in_history\n    test_dict = galaxy_interactor.remote_to_input(\n                ^^^^^^^^^^^^^^^^^^^^^^^^^^^^^^^^^^\n  File \"/opt/hostedtoolcache/Python/3.12.9/x64/lib/python3.12/site-packages/galaxy/tool_util/verify/interactor.py\", line 582, in remote_to_input\n    path_or_location = self._get_path_or_location(\n                       ^^^^^^^^^^^^^^^^^^^^^^^^^^^\n  File \"/opt/hostedtoolcache/Python/3.12.9/x64/lib/python3.12/site-packages/galaxy/tool_util/verify/interactor.py\", line 619, in _get_path_or_location\n    path = self.test_data_download(\n           ^^^^^^^^^^^^^^^^^^^^^^^^\n  File \"/opt/hostedtoolcache/Python/3.12.9/x64/lib/python3.12/site-packages/galaxy/tool_util/verify/interactor.py\", line 525, in test_data_download\n    raise AssertionError(f\"Test input file ({filename}) cannot be found.\")\nAssertionError: Test input file (in_1.tabular) cannot be found.\n", "status": "error", "test_index": 0, "time_seconds": 0.10150527954101562, "tool_id": "collection_column_join", "tool_version": "0.0.3"}
            ]]></error>
        
    </testcase>
    
    <testcase classname="collection_column_join (Test #2)" name="1" time="0.051619768142700195">
        
            <error type="error" message="Input staging problem: Traceback (most recent call last):
  File "/opt/hostedtoolcache/Python/3.12.9/x64/lib/python3.12/site-packages/galaxy/tool_util/verify/interactor.py", line 1434, in verify_tool
    stage_data_in_history(
  File "/opt/hostedtoolcache/Python/3.12.9/x64/lib/python3.12/site-packages/galaxy/tool_util/verify/interactor.py", line 163, in stage_data_in_history
    test_dict = galaxy_interactor.remote_to_input(
                ^^^^^^^^^^^^^^^^^^^^^^^^^^^^^^^^^^
  File "/opt/hostedtoolcache/Python/3.12.9/x64/lib/python3.12/site-packages/galaxy/tool_util/verify/interactor.py", line 582, in remote_to_input
    path_or_location = self._get_path_or_location(
                       ^^^^^^^^^^^^^^^^^^^^^^^^^^^
  File "/opt/hostedtoolcache/Python/3.12.9/x64/lib/python3.12/site-packages/galaxy/tool_util/verify/interactor.py", line 619, in _get_path_or_location
    path = self.test_data_download(
           ^^^^^^^^^^^^^^^^^^^^^^^^
  File "/opt/hostedtoolcache/Python/3.12.9/x64/lib/python3.12/site-packages/galaxy/tool_util/verify/interactor.py", line 525, in test_data_download
    raise AssertionError(f"Test input file ({filename}) cannot be found.")
AssertionError: Test input file (in_1_headerless.tabular) cannot be found.
"><![CDATA[
                { "execution_problem": "Input staging problem: Traceback (most recent call last):\n  File \"/opt/hostedtoolcache/Python/3.12.9/x64/lib/python3.12/site-packages/galaxy/tool_util/verify/interactor.py\", line 1434, in verify_tool\n    stage_data_in_history(\n  File \"/opt/hostedtoolcache/Python/3.12.9/x64/lib/python3.12/site-packages/galaxy/tool_util/verify/interactor.py\", line 163, in stage_data_in_history\n    test_dict = galaxy_interactor.remote_to_input(\n                ^^^^^^^^^^^^^^^^^^^^^^^^^^^^^^^^^^\n  File \"/opt/hostedtoolcache/Python/3.12.9/x64/lib/python3.12/site-packages/galaxy/tool_util/verify/interactor.py\", line 582, in remote_to_input\n    path_or_location = self._get_path_or_location(\n                       ^^^^^^^^^^^^^^^^^^^^^^^^^^^\n  File \"/opt/hostedtoolcache/Python/3.12.9/x64/lib/python3.12/site-packages/galaxy/tool_util/verify/interactor.py\", line 619, in _get_path_or_location\n    path = self.test_data_download(\n           ^^^^^^^^^^^^^^^^^^^^^^^^\n  File \"/opt/hostedtoolcache/Python/3.12.9/x64/lib/python3.12/site-packages/galaxy/tool_util/verify/interactor.py\", line 525, in test_data_download\n    raise AssertionError(f\"Test input file ({filename}) cannot be found.\")\nAssertionError: Test input file (in_1_headerless.tabular) cannot be found.\n", "status": "error", "test_index": 1, "time_seconds": 0.051619768142700195, "tool_id": "collection_column_join", "tool_version": "0.0.3"}
            ]]></error>
        
    </testcase>
    
    <testcase classname="collection_column_join (Test #3)" name="2" time="0.05215740203857422">
        
            <error type="error" message="Input staging problem: Traceback (most recent call last):
  File "/opt/hostedtoolcache/Python/3.12.9/x64/lib/python3.12/site-packages/galaxy/tool_util/verify/interactor.py", line 1434, in verify_tool
    stage_data_in_history(
  File "/opt/hostedtoolcache/Python/3.12.9/x64/lib/python3.12/site-packages/galaxy/tool_util/verify/interactor.py", line 163, in stage_data_in_history
    test_dict = galaxy_interactor.remote_to_input(
                ^^^^^^^^^^^^^^^^^^^^^^^^^^^^^^^^^^
  File "/opt/hostedtoolcache/Python/3.12.9/x64/lib/python3.12/site-packages/galaxy/tool_util/verify/interactor.py", line 582, in remote_to_input
    path_or_location = self._get_path_or_location(
                       ^^^^^^^^^^^^^^^^^^^^^^^^^^^
  File "/opt/hostedtoolcache/Python/3.12.9/x64/lib/python3.12/site-packages/galaxy/tool_util/verify/interactor.py", line 619, in _get_path_or_location
    path = self.test_data_download(
           ^^^^^^^^^^^^^^^^^^^^^^^^
  File "/opt/hostedtoolcache/Python/3.12.9/x64/lib/python3.12/site-packages/galaxy/tool_util/verify/interactor.py", line 525, in test_data_download
    raise AssertionError(f"Test input file ({filename}) cannot be found.")
AssertionError: Test input file (in_1.tabular) cannot be found.
"><![CDATA[
                { "execution_problem": "Input staging problem: Traceback (most recent call last):\n  File \"/opt/hostedtoolcache/Python/3.12.9/x64/lib/python3.12/site-packages/galaxy/tool_util/verify/interactor.py\", line 1434, in verify_tool\n    stage_data_in_history(\n  File \"/opt/hostedtoolcache/Python/3.12.9/x64/lib/python3.12/site-packages/galaxy/tool_util/verify/interactor.py\", line 163, in stage_data_in_history\n    test_dict = galaxy_interactor.remote_to_input(\n                ^^^^^^^^^^^^^^^^^^^^^^^^^^^^^^^^^^\n  File \"/opt/hostedtoolcache/Python/3.12.9/x64/lib/python3.12/site-packages/galaxy/tool_util/verify/interactor.py\", line 582, in remote_to_input\n    path_or_location = self._get_path_or_location(\n                       ^^^^^^^^^^^^^^^^^^^^^^^^^^^\n  File \"/opt/hostedtoolcache/Python/3.12.9/x64/lib/python3.12/site-packages/galaxy/tool_util/verify/interactor.py\", line 619, in _get_path_or_location\n    path = self.test_data_download(\n           ^^^^^^^^^^^^^^^^^^^^^^^^\n  File \"/opt/hostedtoolcache/Python/3.12.9/x64/lib/python3.12/site-packages/galaxy/tool_util/verify/interactor.py\", line 525, in test_data_download\n    raise AssertionError(f\"Test input file ({filename}) cannot be found.\")\nAssertionError: Test input file (in_1.tabular) cannot be found.\n", "status": "error", "test_index": 2, "time_seconds": 0.05215740203857422, "tool_id": "collection_column_join", "tool_version": "0.0.3"}
            ]]></error>
        
    </testcase>
    
    <testcase classname="collection_column_join (Test #4)" name="3" time="0.051627159118652344">
        
            <error type="error" message="Input staging problem: Traceback (most recent call last):
  File "/opt/hostedtoolcache/Python/3.12.9/x64/lib/python3.12/site-packages/galaxy/tool_util/verify/interactor.py", line 1434, in verify_tool
    stage_data_in_history(
  File "/opt/hostedtoolcache/Python/3.12.9/x64/lib/python3.12/site-packages/galaxy/tool_util/verify/interactor.py", line 163, in stage_data_in_history
    test_dict = galaxy_interactor.remote_to_input(
                ^^^^^^^^^^^^^^^^^^^^^^^^^^^^^^^^^^
  File "/opt/hostedtoolcache/Python/3.12.9/x64/lib/python3.12/site-packages/galaxy/tool_util/verify/interactor.py", line 582, in remote_to_input
    path_or_location = self._get_path_or_location(
                       ^^^^^^^^^^^^^^^^^^^^^^^^^^^
  File "/opt/hostedtoolcache/Python/3.12.9/x64/lib/python3.12/site-packages/galaxy/tool_util/verify/interactor.py", line 619, in _get_path_or_location
    path = self.test_data_download(
           ^^^^^^^^^^^^^^^^^^^^^^^^
  File "/opt/hostedtoolcache/Python/3.12.9/x64/lib/python3.12/site-packages/galaxy/tool_util/verify/interactor.py", line 525, in test_data_download
    raise AssertionError(f"Test input file ({filename}) cannot be found.")
AssertionError: Test input file (in_1_headerless.tabular) cannot be found.
"><![CDATA[
                { "execution_problem": "Input staging problem: Traceback (most recent call last):\n  File \"/opt/hostedtoolcache/Python/3.12.9/x64/lib/python3.12/site-packages/galaxy/tool_util/verify/interactor.py\", line 1434, in verify_tool\n    stage_data_in_history(\n  File \"/opt/hostedtoolcache/Python/3.12.9/x64/lib/python3.12/site-packages/galaxy/tool_util/verify/interactor.py\", line 163, in stage_data_in_history\n    test_dict = galaxy_interactor.remote_to_input(\n                ^^^^^^^^^^^^^^^^^^^^^^^^^^^^^^^^^^\n  File \"/opt/hostedtoolcache/Python/3.12.9/x64/lib/python3.12/site-packages/galaxy/tool_util/verify/interactor.py\", line 582, in remote_to_input\n    path_or_location = self._get_path_or_location(\n                       ^^^^^^^^^^^^^^^^^^^^^^^^^^^\n  File \"/opt/hostedtoolcache/Python/3.12.9/x64/lib/python3.12/site-packages/galaxy/tool_util/verify/interactor.py\", line 619, in _get_path_or_location\n    path = self.test_data_download(\n           ^^^^^^^^^^^^^^^^^^^^^^^^\n  File \"/opt/hostedtoolcache/Python/3.12.9/x64/lib/python3.12/site-packages/galaxy/tool_util/verify/interactor.py\", line 525, in test_data_download\n    raise AssertionError(f\"Test input file ({filename}) cannot be found.\")\nAssertionError: Test input file (in_1_headerless.tabular) cannot be found.\n", "status": "error", "test_index": 3, "time_seconds": 0.051627159118652344, "tool_id": "collection_column_join", "tool_version": "0.0.3"}
            ]]></error>
        
    </testcase>
    
    <testcase classname="deeptools_plot_coverage (Test #1)" name="0" time="55.10223913192749">
        
            
            <system-out><![CDATA[
            samplemeanstdmin25%50%75%maxbowtie2 test1.bam0.504.1000.00.00.035bowtie2 test1.bam0.504.1000.00.00.035
            ]]></system-out>
            <system-err><![CDATA[
            
            ]]></system-err>
        
    </testcase>
    
    <testcase classname="deeptools_plot_coverage (Test #2)" name="1" time="35.49914526939392">
        
            
            <system-out><![CDATA[
            samplemeanstdmin25%50%75%maxbowtie2 test1.bam0.504.1000.00.00.035bowtie2 test1.bam0.504.1000.00.00.035
            ]]></system-out>
            <system-err><![CDATA[
            
            ]]></system-err>
        
    </testcase>
    
    <testcase classname="fastq_paired_end_interlacer (Test #1)" name="0" time="0.09754228591918945">
        
            <error type="error" message="Input staging problem: Traceback (most recent call last):
  File "/opt/hostedtoolcache/Python/3.12.9/x64/lib/python3.12/site-packages/galaxy/tool_util/verify/interactor.py", line 1434, in verify_tool
    stage_data_in_history(
  File "/opt/hostedtoolcache/Python/3.12.9/x64/lib/python3.12/site-packages/galaxy/tool_util/verify/interactor.py", line 163, in stage_data_in_history
    test_dict = galaxy_interactor.remote_to_input(
                ^^^^^^^^^^^^^^^^^^^^^^^^^^^^^^^^^^
  File "/opt/hostedtoolcache/Python/3.12.9/x64/lib/python3.12/site-packages/galaxy/tool_util/verify/interactor.py", line 582, in remote_to_input
    path_or_location = self._get_path_or_location(
                       ^^^^^^^^^^^^^^^^^^^^^^^^^^^
  File "/opt/hostedtoolcache/Python/3.12.9/x64/lib/python3.12/site-packages/galaxy/tool_util/verify/interactor.py", line 619, in _get_path_or_location
    path = self.test_data_download(
           ^^^^^^^^^^^^^^^^^^^^^^^^
  File "/opt/hostedtoolcache/Python/3.12.9/x64/lib/python3.12/site-packages/galaxy/tool_util/verify/interactor.py", line 525, in test_data_download
    raise AssertionError(f"Test input file ({filename}) cannot be found.")
AssertionError: Test input file (paired_end_1.fastqsanger) cannot be found.
"><![CDATA[
                { "execution_problem": "Input staging problem: Traceback (most recent call last):\n  File \"/opt/hostedtoolcache/Python/3.12.9/x64/lib/python3.12/site-packages/galaxy/tool_util/verify/interactor.py\", line 1434, in verify_tool\n    stage_data_in_history(\n  File \"/opt/hostedtoolcache/Python/3.12.9/x64/lib/python3.12/site-packages/galaxy/tool_util/verify/interactor.py\", line 163, in stage_data_in_history\n    test_dict = galaxy_interactor.remote_to_input(\n                ^^^^^^^^^^^^^^^^^^^^^^^^^^^^^^^^^^\n  File \"/opt/hostedtoolcache/Python/3.12.9/x64/lib/python3.12/site-packages/galaxy/tool_util/verify/interactor.py\", line 582, in remote_to_input\n    path_or_location = self._get_path_or_location(\n                       ^^^^^^^^^^^^^^^^^^^^^^^^^^^\n  File \"/opt/hostedtoolcache/Python/3.12.9/x64/lib/python3.12/site-packages/galaxy/tool_util/verify/interactor.py\", line 619, in _get_path_or_location\n    path = self.test_data_download(\n           ^^^^^^^^^^^^^^^^^^^^^^^^\n  File \"/opt/hostedtoolcache/Python/3.12.9/x64/lib/python3.12/site-packages/galaxy/tool_util/verify/interactor.py\", line 525, in test_data_download\n    raise AssertionError(f\"Test input file ({filename}) cannot be found.\")\nAssertionError: Test input file (paired_end_1.fastqsanger) cannot be found.\n", "status": "error", "test_index": 0, "time_seconds": 0.09754228591918945, "tool_id": "fastq_paired_end_interlacer", "tool_version": "1.2.0.1+galaxy0"}
            ]]></error>
        
    </testcase>
    
    <testcase classname="fastq_paired_end_interlacer (Test #2)" name="1" time="0.051278114318847656">
        
            <error type="error" message="Input staging problem: Traceback (most recent call last):
  File "/opt/hostedtoolcache/Python/3.12.9/x64/lib/python3.12/site-packages/galaxy/tool_util/verify/interactor.py", line 1434, in verify_tool
    stage_data_in_history(
  File "/opt/hostedtoolcache/Python/3.12.9/x64/lib/python3.12/site-packages/galaxy/tool_util/verify/interactor.py", line 163, in stage_data_in_history
    test_dict = galaxy_interactor.remote_to_input(
                ^^^^^^^^^^^^^^^^^^^^^^^^^^^^^^^^^^
  File "/opt/hostedtoolcache/Python/3.12.9/x64/lib/python3.12/site-packages/galaxy/tool_util/verify/interactor.py", line 582, in remote_to_input
    path_or_location = self._get_path_or_location(
                       ^^^^^^^^^^^^^^^^^^^^^^^^^^^
  File "/opt/hostedtoolcache/Python/3.12.9/x64/lib/python3.12/site-packages/galaxy/tool_util/verify/interactor.py", line 619, in _get_path_or_location
    path = self.test_data_download(
           ^^^^^^^^^^^^^^^^^^^^^^^^
  File "/opt/hostedtoolcache/Python/3.12.9/x64/lib/python3.12/site-packages/galaxy/tool_util/verify/interactor.py", line 525, in test_data_download
    raise AssertionError(f"Test input file ({filename}) cannot be found.")
AssertionError: Test input file (paired_end_1_errors.fastqsanger) cannot be found.
"><![CDATA[
                { "execution_problem": "Input staging problem: Traceback (most recent call last):\n  File \"/opt/hostedtoolcache/Python/3.12.9/x64/lib/python3.12/site-packages/galaxy/tool_util/verify/interactor.py\", line 1434, in verify_tool\n    stage_data_in_history(\n  File \"/opt/hostedtoolcache/Python/3.12.9/x64/lib/python3.12/site-packages/galaxy/tool_util/verify/interactor.py\", line 163, in stage_data_in_history\n    test_dict = galaxy_interactor.remote_to_input(\n                ^^^^^^^^^^^^^^^^^^^^^^^^^^^^^^^^^^\n  File \"/opt/hostedtoolcache/Python/3.12.9/x64/lib/python3.12/site-packages/galaxy/tool_util/verify/interactor.py\", line 582, in remote_to_input\n    path_or_location = self._get_path_or_location(\n                       ^^^^^^^^^^^^^^^^^^^^^^^^^^^\n  File \"/opt/hostedtoolcache/Python/3.12.9/x64/lib/python3.12/site-packages/galaxy/tool_util/verify/interactor.py\", line 619, in _get_path_or_location\n    path = self.test_data_download(\n           ^^^^^^^^^^^^^^^^^^^^^^^^\n  File \"/opt/hostedtoolcache/Python/3.12.9/x64/lib/python3.12/site-packages/galaxy/tool_util/verify/interactor.py\", line 525, in test_data_download\n    raise AssertionError(f\"Test input file ({filename}) cannot be found.\")\nAssertionError: Test input file (paired_end_1_errors.fastqsanger) cannot be found.\n", "status": "error", "test_index": 1, "time_seconds": 0.051278114318847656, "tool_id": "fastq_paired_end_interlacer", "tool_version": "1.2.0.1+galaxy0"}
            ]]></error>
        
    </testcase>
    
    <testcase classname="fastq_paired_end_interlacer (Test #3)" name="2" time="0.0533299446105957">
        
            <error type="error" message="Input staging problem: Traceback (most recent call last):
  File "/opt/hostedtoolcache/Python/3.12.9/x64/lib/python3.12/site-packages/galaxy/tool_util/verify/interactor.py", line 1434, in verify_tool
    stage_data_in_history(
  File "/opt/hostedtoolcache/Python/3.12.9/x64/lib/python3.12/site-packages/galaxy/tool_util/verify/interactor.py", line 163, in stage_data_in_history
    test_dict = galaxy_interactor.remote_to_input(
                ^^^^^^^^^^^^^^^^^^^^^^^^^^^^^^^^^^
  File "/opt/hostedtoolcache/Python/3.12.9/x64/lib/python3.12/site-packages/galaxy/tool_util/verify/interactor.py", line 582, in remote_to_input
    path_or_location = self._get_path_or_location(
                       ^^^^^^^^^^^^^^^^^^^^^^^^^^^
  File "/opt/hostedtoolcache/Python/3.12.9/x64/lib/python3.12/site-packages/galaxy/tool_util/verify/interactor.py", line 619, in _get_path_or_location
    path = self.test_data_download(
           ^^^^^^^^^^^^^^^^^^^^^^^^
  File "/opt/hostedtoolcache/Python/3.12.9/x64/lib/python3.12/site-packages/galaxy/tool_util/verify/interactor.py", line 525, in test_data_download
    raise AssertionError(f"Test input file ({filename}) cannot be found.")
AssertionError: Test input file (paired_end_1_errors.fastqsanger.gz) cannot be found.
"><![CDATA[
                { "execution_problem": "Input staging problem: Traceback (most recent call last):\n  File \"/opt/hostedtoolcache/Python/3.12.9/x64/lib/python3.12/site-packages/galaxy/tool_util/verify/interactor.py\", line 1434, in verify_tool\n    stage_data_in_history(\n  File \"/opt/hostedtoolcache/Python/3.12.9/x64/lib/python3.12/site-packages/galaxy/tool_util/verify/interactor.py\", line 163, in stage_data_in_history\n    test_dict = galaxy_interactor.remote_to_input(\n                ^^^^^^^^^^^^^^^^^^^^^^^^^^^^^^^^^^\n  File \"/opt/hostedtoolcache/Python/3.12.9/x64/lib/python3.12/site-packages/galaxy/tool_util/verify/interactor.py\", line 582, in remote_to_input\n    path_or_location = self._get_path_or_location(\n                       ^^^^^^^^^^^^^^^^^^^^^^^^^^^\n  File \"/opt/hostedtoolcache/Python/3.12.9/x64/lib/python3.12/site-packages/galaxy/tool_util/verify/interactor.py\", line 619, in _get_path_or_location\n    path = self.test_data_download(\n           ^^^^^^^^^^^^^^^^^^^^^^^^\n  File \"/opt/hostedtoolcache/Python/3.12.9/x64/lib/python3.12/site-packages/galaxy/tool_util/verify/interactor.py\", line 525, in test_data_download\n    raise AssertionError(f\"Test input file ({filename}) cannot be found.\")\nAssertionError: Test input file (paired_end_1_errors.fastqsanger.gz) cannot be found.\n", "status": "error", "test_index": 2, "time_seconds": 0.0533299446105957, "tool_id": "fastq_paired_end_interlacer", "tool_version": "1.2.0.1+galaxy0"}
            ]]></error>
        
    </testcase>
    
    <testcase classname="fastq_paired_end_interlacer (Test #4)" name="3" time="0.05333685874938965">
        
            <error type="error" message="Input staging problem: Traceback (most recent call last):
  File "/opt/hostedtoolcache/Python/3.12.9/x64/lib/python3.12/site-packages/galaxy/tool_util/verify/interactor.py", line 1434, in verify_tool
    stage_data_in_history(
  File "/opt/hostedtoolcache/Python/3.12.9/x64/lib/python3.12/site-packages/galaxy/tool_util/verify/interactor.py", line 163, in stage_data_in_history
    test_dict = galaxy_interactor.remote_to_input(
                ^^^^^^^^^^^^^^^^^^^^^^^^^^^^^^^^^^
  File "/opt/hostedtoolcache/Python/3.12.9/x64/lib/python3.12/site-packages/galaxy/tool_util/verify/interactor.py", line 582, in remote_to_input
    path_or_location = self._get_path_or_location(
                       ^^^^^^^^^^^^^^^^^^^^^^^^^^^
  File "/opt/hostedtoolcache/Python/3.12.9/x64/lib/python3.12/site-packages/galaxy/tool_util/verify/interactor.py", line 619, in _get_path_or_location
    path = self.test_data_download(
           ^^^^^^^^^^^^^^^^^^^^^^^^
  File "/opt/hostedtoolcache/Python/3.12.9/x64/lib/python3.12/site-packages/galaxy/tool_util/verify/interactor.py", line 525, in test_data_download
    raise AssertionError(f"Test input file ({filename}) cannot be found.")
AssertionError: Test input file (paired_end_1_errors.fastqsanger.bz2) cannot be found.
"><![CDATA[
                { "execution_problem": "Input staging problem: Traceback (most recent call last):\n  File \"/opt/hostedtoolcache/Python/3.12.9/x64/lib/python3.12/site-packages/galaxy/tool_util/verify/interactor.py\", line 1434, in verify_tool\n    stage_data_in_history(\n  File \"/opt/hostedtoolcache/Python/3.12.9/x64/lib/python3.12/site-packages/galaxy/tool_util/verify/interactor.py\", line 163, in stage_data_in_history\n    test_dict = galaxy_interactor.remote_to_input(\n                ^^^^^^^^^^^^^^^^^^^^^^^^^^^^^^^^^^\n  File \"/opt/hostedtoolcache/Python/3.12.9/x64/lib/python3.12/site-packages/galaxy/tool_util/verify/interactor.py\", line 582, in remote_to_input\n    path_or_location = self._get_path_or_location(\n                       ^^^^^^^^^^^^^^^^^^^^^^^^^^^\n  File \"/opt/hostedtoolcache/Python/3.12.9/x64/lib/python3.12/site-packages/galaxy/tool_util/verify/interactor.py\", line 619, in _get_path_or_location\n    path = self.test_data_download(\n           ^^^^^^^^^^^^^^^^^^^^^^^^\n  File \"/opt/hostedtoolcache/Python/3.12.9/x64/lib/python3.12/site-packages/galaxy/tool_util/verify/interactor.py\", line 525, in test_data_download\n    raise AssertionError(f\"Test input file ({filename}) cannot be found.\")\nAssertionError: Test input file (paired_end_1_errors.fastqsanger.bz2) cannot be found.\n", "status": "error", "test_index": 3, "time_seconds": 0.05333685874938965, "tool_id": "fastq_paired_end_interlacer", "tool_version": "1.2.0.1+galaxy0"}
            ]]></error>
        
    </testcase>
    
    <testcase classname="fastq_paired_end_interlacer (Test #5)" name="4" time="0.05402541160583496">
        
            <error type="error" message="Input staging problem: Traceback (most recent call last):
  File "/opt/hostedtoolcache/Python/3.12.9/x64/lib/python3.12/site-packages/galaxy/tool_util/verify/interactor.py", line 1434, in verify_tool
    stage_data_in_history(
  File "/opt/hostedtoolcache/Python/3.12.9/x64/lib/python3.12/site-packages/galaxy/tool_util/verify/interactor.py", line 163, in stage_data_in_history
    test_dict = galaxy_interactor.remote_to_input(
                ^^^^^^^^^^^^^^^^^^^^^^^^^^^^^^^^^^
  File "/opt/hostedtoolcache/Python/3.12.9/x64/lib/python3.12/site-packages/galaxy/tool_util/verify/interactor.py", line 582, in remote_to_input
    path_or_location = self._get_path_or_location(
                       ^^^^^^^^^^^^^^^^^^^^^^^^^^^
  File "/opt/hostedtoolcache/Python/3.12.9/x64/lib/python3.12/site-packages/galaxy/tool_util/verify/interactor.py", line 619, in _get_path_or_location
    path = self.test_data_download(
           ^^^^^^^^^^^^^^^^^^^^^^^^
  File "/opt/hostedtoolcache/Python/3.12.9/x64/lib/python3.12/site-packages/galaxy/tool_util/verify/interactor.py", line 525, in test_data_download
    raise AssertionError(f"Test input file ({filename}) cannot be found.")
AssertionError: Test input file (paired_end_1.fastqsanger) cannot be found.
"><![CDATA[
                { "execution_problem": "Input staging problem: Traceback (most recent call last):\n  File \"/opt/hostedtoolcache/Python/3.12.9/x64/lib/python3.12/site-packages/galaxy/tool_util/verify/interactor.py\", line 1434, in verify_tool\n    stage_data_in_history(\n  File \"/opt/hostedtoolcache/Python/3.12.9/x64/lib/python3.12/site-packages/galaxy/tool_util/verify/interactor.py\", line 163, in stage_data_in_history\n    test_dict = galaxy_interactor.remote_to_input(\n                ^^^^^^^^^^^^^^^^^^^^^^^^^^^^^^^^^^\n  File \"/opt/hostedtoolcache/Python/3.12.9/x64/lib/python3.12/site-packages/galaxy/tool_util/verify/interactor.py\", line 582, in remote_to_input\n    path_or_location = self._get_path_or_location(\n                       ^^^^^^^^^^^^^^^^^^^^^^^^^^^\n  File \"/opt/hostedtoolcache/Python/3.12.9/x64/lib/python3.12/site-packages/galaxy/tool_util/verify/interactor.py\", line 619, in _get_path_or_location\n    path = self.test_data_download(\n           ^^^^^^^^^^^^^^^^^^^^^^^^\n  File \"/opt/hostedtoolcache/Python/3.12.9/x64/lib/python3.12/site-packages/galaxy/tool_util/verify/interactor.py\", line 525, in test_data_download\n    raise AssertionError(f\"Test input file ({filename}) cannot be found.\")\nAssertionError: Test input file (paired_end_1.fastqsanger) cannot be found.\n", "status": "error", "test_index": 4, "time_seconds": 0.05402541160583496, "tool_id": "fastq_paired_end_interlacer", "tool_version": "1.2.0.1+galaxy0"}
            ]]></error>
        
    </testcase>
    
    <testcase classname="ivar_consensus (Test #1)" name="0" time="43.47707152366638">
        
            
            <system-out><![CDATA[
            Minimum Quality: 20Threshold: 0Minimum depth: 10Minimum Insert Threshold: 0.8Regions with depth less than minimum depth covered by: NReference length: 29903Positions with 0 depth: 113Positions with depth below 10: 1034
            ]]></system-out>
            <system-err><![CDATA[
            [mpileup] 1 samples in 1 input files[mpileup] Max depth set to maximum value (2147483647)
            ]]></system-err>
        
    </testcase>
    
    <testcase classname="jq (Test #1)" name="0" time="18.511033296585083">
        
            <error type="error" message="Input staging problem: Traceback (most recent call last):
  File "/opt/hostedtoolcache/Python/3.12.9/x64/lib/python3.12/site-packages/galaxy/tool_util/verify/interactor.py", line 1434, in verify_tool
    stage_data_in_history(
  File "/opt/hostedtoolcache/Python/3.12.9/x64/lib/python3.12/site-packages/galaxy/tool_util/verify/interactor.py", line 175, in stage_data_in_history
    staging_interface.handle_jobs()
  File "/opt/hostedtoolcache/Python/3.12.9/x64/lib/python3.12/site-packages/galaxy/tool_util/verify/interactor.py", line 212, in handle_jobs
    self.galaxy_interactor.wait_for_job(job_response["id"], job_response["history_id"], self.maxseconds)
  File "/opt/hostedtoolcache/Python/3.12.9/x64/lib/python3.12/site-packages/galaxy/tool_util/verify/interactor.py", line 399, in wait_for_job
    self.wait_for(lambda: self.__job_ready(job_id, history_id), maxseconds=maxseconds)
  File "/opt/hostedtoolcache/Python/3.12.9/x64/lib/python3.12/site-packages/galaxy/tool_util/verify/interactor.py", line 403, in wait_for
    wait_on(func, what, walltime_exceeded)
  File "/opt/hostedtoolcache/Python/3.12.9/x64/lib/python3.12/site-packages/galaxy/tool_util/verify/wait.py", line 38, in wait_on
    value = function()
            ^^^^^^^^^^
  File "/opt/hostedtoolcache/Python/3.12.9/x64/lib/python3.12/site-packages/galaxy/tool_util/verify/interactor.py", line 399, in <lambda>
    self.wait_for(lambda: self.__job_ready(job_id, history_id), maxseconds=maxseconds)
                          ^^^^^^^^^^^^^^^^^^^^^^^^^^^^^^^^^^^^
  File "/opt/hostedtoolcache/Python/3.12.9/x64/lib/python3.12/site-packages/galaxy/tool_util/verify/interactor.py", line 747, in __job_ready
    return self._state_ready(job_id, error_msg="Job in error state.")
           ^^^^^^^^^^^^^^^^^^^^^^^^^^^^^^^^^^^^^^^^^^^^^^^^^^^^^^^^^^
  File "/opt/hostedtoolcache/Python/3.12.9/x64/lib/python3.12/site-packages/galaxy/tool_util/verify/interactor.py", line 839, in _state_ready
    raise Exception(
Exception: Job in error state.. tool_id: __DATA_FETCH__, exit_code: None, stderr: .
"><![CDATA[
                { "execution_problem": "Input staging problem: Traceback (most recent call last):\n  File \"/opt/hostedtoolcache/Python/3.12.9/x64/lib/python3.12/site-packages/galaxy/tool_util/verify/interactor.py\", line 1434, in verify_tool\n    stage_data_in_history(\n  File \"/opt/hostedtoolcache/Python/3.12.9/x64/lib/python3.12/site-packages/galaxy/tool_util/verify/interactor.py\", line 175, in stage_data_in_history\n    staging_interface.handle_jobs()\n  File \"/opt/hostedtoolcache/Python/3.12.9/x64/lib/python3.12/site-packages/galaxy/tool_util/verify/interactor.py\", line 212, in handle_jobs\n    self.galaxy_interactor.wait_for_job(job_response[\"id\"], job_response[\"history_id\"], self.maxseconds)\n  File \"/opt/hostedtoolcache/Python/3.12.9/x64/lib/python3.12/site-packages/galaxy/tool_util/verify/interactor.py\", line 399, in wait_for_job\n    self.wait_for(lambda: self.__job_ready(job_id, history_id), maxseconds=maxseconds)\n  File \"/opt/hostedtoolcache/Python/3.12.9/x64/lib/python3.12/site-packages/galaxy/tool_util/verify/interactor.py\", line 403, in wait_for\n    wait_on(func, what, walltime_exceeded)\n  File \"/opt/hostedtoolcache/Python/3.12.9/x64/lib/python3.12/site-packages/galaxy/tool_util/verify/wait.py\", line 38, in wait_on\n    value = function()\n            ^^^^^^^^^^\n  File \"/opt/hostedtoolcache/Python/3.12.9/x64/lib/python3.12/site-packages/galaxy/tool_util/verify/interactor.py\", line 399, in \u003clambda\u003e\n    self.wait_for(lambda: self.__job_ready(job_id, history_id), maxseconds=maxseconds)\n                          ^^^^^^^^^^^^^^^^^^^^^^^^^^^^^^^^^^^^\n  File \"/opt/hostedtoolcache/Python/3.12.9/x64/lib/python3.12/site-packages/galaxy/tool_util/verify/interactor.py\", line 747, in __job_ready\n    return self._state_ready(job_id, error_msg=\"Job in error state.\")\n           ^^^^^^^^^^^^^^^^^^^^^^^^^^^^^^^^^^^^^^^^^^^^^^^^^^^^^^^^^^\n  File \"/opt/hostedtoolcache/Python/3.12.9/x64/lib/python3.12/site-packages/galaxy/tool_util/verify/interactor.py\", line 839, in _state_ready\n    raise Exception(\nException: Job in error state.. tool_id: __DATA_FETCH__, exit_code: None, stderr: .\n", "status": "error", "test_index": 0, "time_seconds": 18.511033296585083, "tool_id": "jq", "tool_version": "1.0"}
            ]]></error>
        
    </testcase>
    
    <testcase classname="jq (Test #2)" name="1" time="64.82521677017212">
        
            
            <system-out><![CDATA[
            
            ]]></system-out>
            <system-err><![CDATA[
            
            ]]></system-err>
        
    </testcase>
    
    <testcase classname="medaka_variant_pipeline (Test #1)" name="0" time="">
        
            <error type="error" message=""><![CDATA[
                { "status": "skip", "test_index": 0, "tool_id": "medaka_variant_pipeline", "tool_version": "1.4.4+galaxy1"}
            ]]></error>
        
    </testcase>
    
    <testcase classname="miniasm (Test #1)" name="0" time="41.78230571746826">
        
            
                <error type="error" message="Tool exit code: None"><![CDATA[
                    { "inputs": {  "paf": {   "id": "5509cca795d4d449",   "src": "hda"  },  "readFile": {   "id": "2ef6a8dda5153860",   "src": "hda"  } }, "job": {  "command_line": "miniasm -f \u0027/galaxy/server/database/objects/8/6/0/dataset_860a5eb9-63c5-430b-85f6-24762ef9db5b.dat\u0027 -m \u0027100\u0027 -i \u00270.05\u0027 -s \u00271000\u0027 -c \u00273\u0027 -o \u00271000\u0027 -h \u00271000\u0027 -I \u00270.08\u0027 -g \u00271000\u0027 -d \u002750000\u0027 -e \u00274\u0027 -n \u00273\u0027 -F \u00270.8\u0027 \u0027/galaxy/server/database/objects/4/6/2/dataset_46290938-050e-423f-a863-af13e7974ff5.dat\u0027 \u003e \u0027/galaxy/server/database/objects/1/9/c/dataset_19c23162-cb9b-484d-8f98-52fbe49660e0.dat\u0027",  "command_version": null,  "copied_from_job_id": null,  "create_time": "2025-04-09T13:05:34.170877",  "dependencies": [],  "exit_code": null,  "external_id": "gxy-ljxtl",  "galaxy_version": "24.1",  "handler": null,  "history_id": "02d8f53ea0e37e9c",  "id": "2ef6a8dda5153860",  "inputs": {   "paf": {    "id": "a786e3995d83a65f",    "src": "hda",    "uuid": "46290938-050e-423f-a863-af13e7974ff5"   },   "readFile": {    "id": "2ef6a8dda5153860",    "src": "hda",    "uuid": "860a5eb9-63c5-430b-85f6-24762ef9db5b"   }  },  "job_messages": null,  "job_metrics": [],  "job_runner_name": null,  "job_stderr": null,  "job_stdout": null,  "model_class": "Job",  "output_collections": {},  "outputs": {   "gfa": {    "id": "84248685c3f4dfbc",    "src": "hda",    "uuid": "19c23162-cb9b-484d-8f98-52fbe49660e0"   }  },  "params": {   "__input_ext": "\"input\"",   "chromInfo": "\"/cvmfs/data.galaxyproject.org/managed/len/ucsc/?.len\"",   "dbkey": "\"?\"",   "graph": "{\"finalDropRatio\": \"0.8\", \"maxBubDist\": \"50000\", \"maxGapDiff\": \"1000\", \"minUtgSize\": \"4\", \"nRounds\": \"3\"}",   "overlapping": "{\"intThres\": \"0.08\", \"maxHang\": \"1000\", \"minOvlp\": \"1000\"}",   "preselection": "{\"minCov\": \"3\", \"minIden\": \"0.05\", \"minMatch\": \"100\", \"minSpan\": \"1000\"}"  },  "state": "error",  "stderr": "[M::main] ===\u003e Step 1: reading read mappings \u003c===\n[M::ma_hit_read::0.129*0.99] read 100000 hits; stored 187742 hits and 12067 sequences (111354001 bp)\n[M::main] ===\u003e Step 2: 1-pass (crude) read selection \u003c===\n[M::ma_hit_sub::0.150*0.99] 9155 query sequences remain after sub\n[M::ma_hit_cut::0.153*0.99] 161122 hits remain after cut\n[M::ma_hit_flt::0.156*0.99] 156936 hits remain after filtering; crude coverage after filtering: 11.85\n[M::main] ===\u003e Step 3: 2-pass (fine) read selection \u003c===\n[M::ma_hit_sub::0.161*0.99] 9023 query sequences remain after sub\n[M::ma_hit_cut::0.163*0.99] 152071 hits remain after cut\n[M::ma_hit_contained::0.167*0.99] 1536 sequences and 8359 hits remain after containment removal\n[M::main] ===\u003e Step 4: graph cleaning \u003c===\n[M::ma_sg_gen] read 8236 arcs\n[M::main] ===\u003e Step 4.1: transitive reduction \u003c===\n[M::asg_arc_del_trans] transitively reduced 4182 arcs\n[M::asg_arc_del_multi] removed 0 multi-arcs\n[M::asg_arc_del_asymm] removed 362 asymmetric arcs\n[M::main] ===\u003e Step 4.2: initial tip cutting and bubble popping \u003c===\n[M::asg_cut_tip] cut 260 tips\n[M::asg_pop_bubble] popped 105 bubbles and trimmed 4 tips\n[M::main] ===\u003e Step 4.3: cutting short overlaps (3 rounds in total) \u003c===\n[M::asg_arc_del_multi] removed 0 multi-arcs\n[M::asg_arc_del_asymm] removed 29 asymmetric arcs\n[M::asg_arc_del_short] removed 37 short overlaps\n[M::asg_cut_tip] cut 104 tips\n[M::asg_pop_bubble] popped 1 bubbles and trimmed 0 tips\n[M::asg_arc_del_multi] removed 0 multi-arcs\n[M::asg_arc_del_asymm] removed 1 asymmetric arcs\n[M::asg_arc_del_short] removed 1 short overlaps\n[M::asg_cut_tip] cut 3 tips\n[M::asg_pop_bubble] popped 0 bubbles and trimmed 0 tips\n[M::asg_arc_del_short] removed 0 short overlaps\n[M::main] ===\u003e Step 4.4: removing short internal sequences and bi-loops \u003c===\n[M::asg_cut_internal] cut 0 internal sequences\n[M::asg_cut_biloop] cut 0 small bi-loops\n[M::asg_cut_tip] cut 0 tips\n[M::asg_pop_bubble] popped 0 bubbles and trimmed 0 tips\n[M::main] ===\u003e Step 4.5: aggressively cutting short overlaps \u003c===\n[M::asg_arc_del_short] removed 0 short overlaps\n[M::main] ===\u003e Step 5: generating unitigs \u003c===\n[M::main] Version: 0.3-r179\n[M::main] CMD: miniasm -f /galaxy/server/database/objects/8/6/0/dataset_860a5eb9-63c5-430b-85f6-24762ef9db5b.dat -m 100 -i 0.05 -s 1000 -c 3 -o 1000 -h 1000 -I 0.08 -g 1000 -d 50000 -e 4 -n 3 -F 0.8 /galaxy/server/database/objects/4/6/2/dataset_46290938-050e-423f-a863-af13e7974ff5.dat\n[M::main] Real time: 0.179 sec; CPU: 0.175 sec\n",  "stdout": "",  "tool_id": "toolshed.g2.bx.psu.edu/repos/iuc/miniasm/miniasm/0.3_r179+galaxy1",  "tool_stderr": "[M::main] ===\u003e Step 1: reading read mappings \u003c===\n[M::ma_hit_read::0.129*0.99] read 100000 hits; stored 187742 hits and 12067 sequences (111354001 bp)\n[M::main] ===\u003e Step 2: 1-pass (crude) read selection \u003c===\n[M::ma_hit_sub::0.150*0.99] 9155 query sequences remain after sub\n[M::ma_hit_cut::0.153*0.99] 161122 hits remain after cut\n[M::ma_hit_flt::0.156*0.99] 156936 hits remain after filtering; crude coverage after filtering: 11.85\n[M::main] ===\u003e Step 3: 2-pass (fine) read selection \u003c===\n[M::ma_hit_sub::0.161*0.99] 9023 query sequences remain after sub\n[M::ma_hit_cut::0.163*0.99] 152071 hits remain after cut\n[M::ma_hit_contained::0.167*0.99] 1536 sequences and 8359 hits remain after containment removal\n[M::main] ===\u003e Step 4: graph cleaning \u003c===\n[M::ma_sg_gen] read 8236 arcs\n[M::main] ===\u003e Step 4.1: transitive reduction \u003c===\n[M::asg_arc_del_trans] transitively reduced 4182 arcs\n[M::asg_arc_del_multi] removed 0 multi-arcs\n[M::asg_arc_del_asymm] removed 362 asymmetric arcs\n[M::main] ===\u003e Step 4.2: initial tip cutting and bubble popping \u003c===\n[M::asg_cut_tip] cut 260 tips\n[M::asg_pop_bubble] popped 105 bubbles and trimmed 4 tips\n[M::main] ===\u003e Step 4.3: cutting short overlaps (3 rounds in total) \u003c===\n[M::asg_arc_del_multi] removed 0 multi-arcs\n[M::asg_arc_del_asymm] removed 29 asymmetric arcs\n[M::asg_arc_del_short] removed 37 short overlaps\n[M::asg_cut_tip] cut 104 tips\n[M::asg_pop_bubble] popped 1 bubbles and trimmed 0 tips\n[M::asg_arc_del_multi] removed 0 multi-arcs\n[M::asg_arc_del_asymm] removed 1 asymmetric arcs\n[M::asg_arc_del_short] removed 1 short overlaps\n[M::asg_cut_tip] cut 3 tips\n[M::asg_pop_bubble] popped 0 bubbles and trimmed 0 tips\n[M::asg_arc_del_short] removed 0 short overlaps\n[M::main] ===\u003e Step 4.4: removing short internal sequences and bi-loops \u003c===\n[M::asg_cut_internal] cut 0 internal sequences\n[M::asg_cut_biloop] cut 0 small bi-loops\n[M::asg_cut_tip] cut 0 tips\n[M::asg_pop_bubble] popped 0 bubbles and trimmed 0 tips\n[M::main] ===\u003e Step 4.5: aggressively cutting short overlaps \u003c===\n[M::asg_arc_del_short] removed 0 short overlaps\n[M::main] ===\u003e Step 5: generating unitigs \u003c===\n[M::main] Version: 0.3-r179\n[M::main] CMD: miniasm -f /galaxy/server/database/objects/8/6/0/dataset_860a5eb9-63c5-430b-85f6-24762ef9db5b.dat -m 100 -i 0.05 -s 1000 -c 3 -o 1000 -h 1000 -I 0.08 -g 1000 -d 50000 -e 4 -n 3 -F 0.8 /galaxy/server/database/objects/4/6/2/dataset_46290938-050e-423f-a863-af13e7974ff5.dat\n[M::main] Real time: 0.179 sec; CPU: 0.175 sec\n",  "tool_stdout": "",  "update_time": "2025-04-09T13:05:55.499522",  "user_email": "tests@fake.org" }, "output_problems": [  "Job in error state.. tool_id: toolshed.g2.bx.psu.edu/repos/iuc/miniasm/miniasm/0.3_r179+galaxy1, exit_code: None, stderr: [M::main] ===\u003e Step 1: reading read mappings \u003c===\n[M::ma_hit_read::0.129*0.99] read 100000 hits; stored 187742 hits and 12067 sequences (111354001 bp)\n[M::main] ===\u003e Step 2: 1-pass (crude) read selection \u003c===\n[M::ma_hit_sub::0.150*0.99] 9155 query sequences remain after sub\n[M::ma_hit_cut::0.153*0.99] 161122 hits remain after cut\n[M::ma_hit_flt::0.156*0.99] 156936 hits remain after filtering; crude coverage after filtering: 11.85\n[M::main] ===\u003e Step 3: 2-pass (fine) read selection \u003c===\n[M::ma_hit_sub::0.161*0.99] 9023 query sequences remain after sub\n[M::ma_hit_cut::0.163*0.99] 152071 hits remain after cut\n[M::ma_hit_contained::0.167*0.99] 1536 sequences and 8359 hits remain after containment removal\n[M::main] ===\u003e Step 4: graph cleaning \u003c===\n[M::ma_sg_gen] read 8236 arcs\n[M::main] ===\u003e Step 4.1: transitive reduction \u003c===\n[M::asg_arc_del_trans] transitively reduced 4182 arcs\n[M::asg_arc_del_multi] removed 0 multi-arcs\n[M::asg_arc_del_asymm] removed 362 asymmetric arcs\n[M::main] ===\u003e Step 4.2: initial tip cutting and bubble popping \u003c===\n[M::asg_cut_tip] cut 260 tips\n[M::asg_pop_bubble] popped 105 bubbles and trimmed 4 tips\n[M::main] ===\u003e Step 4.3: cutting short overlaps (3 rounds in total) \u003c===\n[M::asg_arc_del_multi] removed 0 multi-arcs\n[M::asg_arc_del_asymm] removed 29 asymmetric arcs\n[M::asg_arc_del_short] removed 37 short overlaps\n[M::asg_cut_tip] cut 104 tips\n[M::asg_pop_bubble] popped 1 bubbles and trimmed 0 tips\n[M::asg_arc_del_multi] removed 0 multi-arcs\n[M::asg_arc_del_asymm] removed 1 asymmetric arcs\n[M::asg_arc_del_short] removed 1 short overlaps\n[M::asg_cut_tip] cut 3 tips\n[M::asg_pop_bubble] popped 0 bubbles and trimmed 0 tips\n[M::asg_arc_del_short] removed 0 short overlaps\n[M::main] ===\u003e Step 4.4: removing short internal sequences and bi-loops \u003c===\n[M::asg_cut_internal] cut 0 internal sequences\n[M::asg_cut_biloop] cut 0 small bi-loops\n[M::asg_cut_tip] cut 0 tips\n[M::asg_pop_bubble] popped 0 bubbles and trimmed 0 tips\n[M::main] ===\u003e Step 4.5: aggressively cutting short overlaps \u003c===\n[M::asg_arc_del_short] removed 0 short overlaps\n[M::main] ===\u003e Step 5: generating unitigs \u003c===\n[M::main] Version: 0.3-r179\n[M::main] CMD: miniasm -f /galaxy/server/database/objects/8/6/0/dataset_860a5eb9-63c5-430b-85f6-24762ef9db5b.dat -m 100 -i 0.05 -s 1000 -c 3 -o 1000 -h 1000 -I 0.08 -g 1000 -d 50000 -e 4 -n 3 -F 0.8 /galaxy/server/database/objects/4/6/2/dataset_46290938-050e-423f-a863-af13e7974ff5.dat\n[M::main] Real time: 0.179 sec; CPU: 0.175 sec\n.",  "Job in error state.. tool_id: toolshed.g2.bx.psu.edu/repos/iuc/miniasm/miniasm/0.3_r179+galaxy1, exit_code: None, stderr: [M::main] ===\u003e Step 1: reading read mappings \u003c===\n[M::ma_hit_read::0.129*0.99] read 100000 hits; stored 187742 hits and 12067 sequences (111354001 bp)\n[M::main] ===\u003e Step 2: 1-pass (crude) read selection \u003c===\n[M::ma_hit_sub::0.150*0.99] 9155 query sequences remain after sub\n[M::ma_hit_cut::0.153*0.99] 161122 hits remain after cut\n[M::ma_hit_flt::0.156*0.99] 156936 hits remain after filtering; crude coverage after filtering: 11.85\n[M::main] ===\u003e Step 3: 2-pass (fine) read selection \u003c===\n[M::ma_hit_sub::0.161*0.99] 9023 query sequences remain after sub\n[M::ma_hit_cut::0.163*0.99] 152071 hits remain after cut\n[M::ma_hit_contained::0.167*0.99] 1536 sequences and 8359 hits remain after containment removal\n[M::main] ===\u003e Step 4: graph cleaning \u003c===\n[M::ma_sg_gen] read 8236 arcs\n[M::main] ===\u003e Step 4.1: transitive reduction \u003c===\n[M::asg_arc_del_trans] transitively reduced 4182 arcs\n[M::asg_arc_del_multi] removed 0 multi-arcs\n[M::asg_arc_del_asymm] removed 362 asymmetric arcs\n[M::main] ===\u003e Step 4.2: initial tip cutting and bubble popping \u003c===\n[M::asg_cut_tip] cut 260 tips\n[M::asg_pop_bubble] popped 105 bubbles and trimmed 4 tips\n[M::main] ===\u003e Step 4.3: cutting short overlaps (3 rounds in total) \u003c===\n[M::asg_arc_del_multi] removed 0 multi-arcs\n[M::asg_arc_del_asymm] removed 29 asymmetric arcs\n[M::asg_arc_del_short] removed 37 short overlaps\n[M::asg_cut_tip] cut 104 tips\n[M::asg_pop_bubble] popped 1 bubbles and trimmed 0 tips\n[M::asg_arc_del_multi] removed 0 multi-arcs\n[M::asg_arc_del_asymm] removed 1 asymmetric arcs\n[M::asg_arc_del_short] removed 1 short overlaps\n[M::asg_cut_tip] cut 3 tips\n[M::asg_pop_bubble] popped 0 bubbles and trimmed 0 tips\n[M::asg_arc_del_short] removed 0 short overlaps\n[M::main] ===\u003e Step 4.4: removing short internal sequences and bi-loops \u003c===\n[M::asg_cut_internal] cut 0 internal sequences\n[M::asg_cut_biloop] cut 0 small bi-loops\n[M::asg_cut_tip] cut 0 tips\n[M::asg_pop_bubble] popped 0 bubbles and trimmed 0 tips\n[M::main] ===\u003e Step 4.5: aggressively cutting short overlaps \u003c===\n[M::asg_arc_del_short] removed 0 short overlaps\n[M::main] ===\u003e Step 5: generating unitigs \u003c===\n[M::main] Version: 0.3-r179\n[M::main] CMD: miniasm -f /galaxy/server/database/objects/8/6/0/dataset_860a5eb9-63c5-430b-85f6-24762ef9db5b.dat -m 100 -i 0.05 -s 1000 -c 3 -o 1000 -h 1000 -I 0.08 -g 1000 -d 50000 -e 4 -n 3 -F 0.8 /galaxy/server/database/objects/4/6/2/dataset_46290938-050e-423f-a863-af13e7974ff5.dat\n[M::main] Real time: 0.179 sec; CPU: 0.175 sec\n." ], "status": "failure", "test_index": 0, "time_seconds": 41.78230571746826, "tool_id": "miniasm", "tool_version": "0.3_r179+galaxy1"}
                ]]></error>
            
            <system-out><![CDATA[
            
            ]]></system-out>
            <system-err><![CDATA[
            [M::main] ===> Step 1: reading read mappings <===[M::ma_hit_read::0.129*0.99] read 100000 hits; stored 187742 hits and 12067 sequences (111354001 bp)[M::main] ===> Step 2: 1-pass (crude) read selection <===[M::ma_hit_sub::0.150*0.99] 9155 query sequences remain after sub[M::ma_hit_cut::0.153*0.99] 161122 hits remain after cut[M::ma_hit_flt::0.156*0.99] 156936 hits remain after filtering; crude coverage after filtering: 11.85[M::main] ===> Step 3: 2-pass (fine) read selection <===[M::ma_hit_sub::0.161*0.99] 9023 query sequences remain after sub[M::ma_hit_cut::0.163*0.99] 152071 hits remain after cut[M::ma_hit_contained::0.167*0.99] 1536 sequences and 8359 hits remain after containment removal[M::main] ===> Step 4: graph cleaning <===[M::ma_sg_gen] read 8236 arcs[M::main] ===> Step 4.1: transitive reduction <===[M::asg_arc_del_trans] transitively reduced 4182 arcs[M::asg_arc_del_multi] removed 0 multi-arcs[M::asg_arc_del_asymm] removed 362 asymmetric arcs[M::main] ===> Step 4.2: initial tip cutting and bubble popping <===[M::asg_cut_tip] cut 260 tips[M::asg_pop_bubble] popped 105 bubbles and trimmed 4 tips[M::main] ===> Step 4.3: cutting short overlaps (3 rounds in total) <===[M::asg_arc_del_multi] removed 0 multi-arcs[M::asg_arc_del_asymm] removed 29 asymmetric arcs[M::asg_arc_del_short] removed 37 short overlaps[M::asg_cut_tip] cut 104 tips[M::asg_pop_bubble] popped 1 bubbles and trimmed 0 tips[M::asg_arc_del_multi] removed 0 multi-arcs[M::asg_arc_del_asymm] removed 1 asymmetric arcs[M::asg_arc_del_short] removed 1 short overlaps[M::asg_cut_tip] cut 3 tips[M::asg_pop_bubble] popped 0 bubbles and trimmed 0 tips[M::asg_arc_del_short] removed 0 short overlaps[M::main] ===> Step 4.4: removing short internal sequences and bi-loops <===[M::asg_cut_internal] cut 0 internal sequences[M::asg_cut_biloop] cut 0 small bi-loops[M::asg_cut_tip] cut 0 tips[M::asg_pop_bubble] popped 0 bubbles and trimmed 0 tips[M::main] ===> Step 4.5: aggressively cutting short overlaps <===[M::asg_arc_del_short] removed 0 short overlaps[M::main] ===> Step 5: generating unitigs <===[M::main] Version: 0.3-r179[M::main] CMD: miniasm -f /galaxy/server/database/objects/8/6/0/dataset_860a5eb9-63c5-430b-85f6-24762ef9db5b.dat -m 100 -i 0.05 -s 1000 -c 3 -o 1000 -h 1000 -I 0.08 -g 1000 -d 50000 -e 4 -n 3 -F 0.8 /galaxy/server/database/objects/4/6/2/dataset_46290938-050e-423f-a863-af13e7974ff5.dat[M::main] Real time: 0.179 sec; CPU: 0.175 sec
            ]]></system-err>
        
    </testcase>
    
    <testcase classname="miniasm (Test #2)" name="1" time="19.0460786819458">
        
            <error type="error" message="Input staging problem: Traceback (most recent call last):
  File "/opt/hostedtoolcache/Python/3.12.9/x64/lib/python3.12/site-packages/galaxy/tool_util/verify/interactor.py", line 1434, in verify_tool
    stage_data_in_history(
  File "/opt/hostedtoolcache/Python/3.12.9/x64/lib/python3.12/site-packages/galaxy/tool_util/verify/interactor.py", line 175, in stage_data_in_history
    staging_interface.handle_jobs()
  File "/opt/hostedtoolcache/Python/3.12.9/x64/lib/python3.12/site-packages/galaxy/tool_util/verify/interactor.py", line 212, in handle_jobs
    self.galaxy_interactor.wait_for_job(job_response["id"], job_response["history_id"], self.maxseconds)
  File "/opt/hostedtoolcache/Python/3.12.9/x64/lib/python3.12/site-packages/galaxy/tool_util/verify/interactor.py", line 399, in wait_for_job
    self.wait_for(lambda: self.__job_ready(job_id, history_id), maxseconds=maxseconds)
  File "/opt/hostedtoolcache/Python/3.12.9/x64/lib/python3.12/site-packages/galaxy/tool_util/verify/interactor.py", line 403, in wait_for
    wait_on(func, what, walltime_exceeded)
  File "/opt/hostedtoolcache/Python/3.12.9/x64/lib/python3.12/site-packages/galaxy/tool_util/verify/wait.py", line 38, in wait_on
    value = function()
            ^^^^^^^^^^
  File "/opt/hostedtoolcache/Python/3.12.9/x64/lib/python3.12/site-packages/galaxy/tool_util/verify/interactor.py", line 399, in <lambda>
    self.wait_for(lambda: self.__job_ready(job_id, history_id), maxseconds=maxseconds)
                          ^^^^^^^^^^^^^^^^^^^^^^^^^^^^^^^^^^^^
  File "/opt/hostedtoolcache/Python/3.12.9/x64/lib/python3.12/site-packages/galaxy/tool_util/verify/interactor.py", line 747, in __job_ready
    return self._state_ready(job_id, error_msg="Job in error state.")
           ^^^^^^^^^^^^^^^^^^^^^^^^^^^^^^^^^^^^^^^^^^^^^^^^^^^^^^^^^^
  File "/opt/hostedtoolcache/Python/3.12.9/x64/lib/python3.12/site-packages/galaxy/tool_util/verify/interactor.py", line 839, in _state_ready
    raise Exception(
Exception: Job in error state.. tool_id: __DATA_FETCH__, exit_code: None, stderr: .
"><![CDATA[
                { "execution_problem": "Input staging problem: Traceback (most recent call last):\n  File \"/opt/hostedtoolcache/Python/3.12.9/x64/lib/python3.12/site-packages/galaxy/tool_util/verify/interactor.py\", line 1434, in verify_tool\n    stage_data_in_history(\n  File \"/opt/hostedtoolcache/Python/3.12.9/x64/lib/python3.12/site-packages/galaxy/tool_util/verify/interactor.py\", line 175, in stage_data_in_history\n    staging_interface.handle_jobs()\n  File \"/opt/hostedtoolcache/Python/3.12.9/x64/lib/python3.12/site-packages/galaxy/tool_util/verify/interactor.py\", line 212, in handle_jobs\n    self.galaxy_interactor.wait_for_job(job_response[\"id\"], job_response[\"history_id\"], self.maxseconds)\n  File \"/opt/hostedtoolcache/Python/3.12.9/x64/lib/python3.12/site-packages/galaxy/tool_util/verify/interactor.py\", line 399, in wait_for_job\n    self.wait_for(lambda: self.__job_ready(job_id, history_id), maxseconds=maxseconds)\n  File \"/opt/hostedtoolcache/Python/3.12.9/x64/lib/python3.12/site-packages/galaxy/tool_util/verify/interactor.py\", line 403, in wait_for\n    wait_on(func, what, walltime_exceeded)\n  File \"/opt/hostedtoolcache/Python/3.12.9/x64/lib/python3.12/site-packages/galaxy/tool_util/verify/wait.py\", line 38, in wait_on\n    value = function()\n            ^^^^^^^^^^\n  File \"/opt/hostedtoolcache/Python/3.12.9/x64/lib/python3.12/site-packages/galaxy/tool_util/verify/interactor.py\", line 399, in \u003clambda\u003e\n    self.wait_for(lambda: self.__job_ready(job_id, history_id), maxseconds=maxseconds)\n                          ^^^^^^^^^^^^^^^^^^^^^^^^^^^^^^^^^^^^\n  File \"/opt/hostedtoolcache/Python/3.12.9/x64/lib/python3.12/site-packages/galaxy/tool_util/verify/interactor.py\", line 747, in __job_ready\n    return self._state_ready(job_id, error_msg=\"Job in error state.\")\n           ^^^^^^^^^^^^^^^^^^^^^^^^^^^^^^^^^^^^^^^^^^^^^^^^^^^^^^^^^^\n  File \"/opt/hostedtoolcache/Python/3.12.9/x64/lib/python3.12/site-packages/galaxy/tool_util/verify/interactor.py\", line 839, in _state_ready\n    raise Exception(\nException: Job in error state.. tool_id: __DATA_FETCH__, exit_code: None, stderr: .\n", "status": "error", "test_index": 1, "time_seconds": 19.0460786819458, "tool_id": "miniasm", "tool_version": "0.3_r179+galaxy1"}
            ]]></error>
        
    </testcase>
    
    <testcase classname="poretools_qualdist (Test #1)" name="0" time="57.30326199531555">
        
            
                <error type="error" message="Tool exit code: None"><![CDATA[
                    { "inputs": {  "input": {   "id": "0d96e024a0643f85",   "src": "hda"  } }, "job": {  "command_line": "poretools qualdist \u0027/galaxy/server/database/objects/6/0/4/dataset_604deb60-a011-4830-a845-c4e2caa5e1de.dat\u0027 \u003e \u0027/galaxy/server/database/objects/e/1/8/dataset_e18f832d-54f8-470c-b59e-1d5dcf7a7435.dat\u0027",  "command_version": null,  "copied_from_job_id": null,  "create_time": "2025-04-09T13:02:28.183049",  "dependencies": [],  "exit_code": null,  "external_id": "gxy-tlgpm",  "galaxy_version": "24.1",  "handler": null,  "history_id": "02d8f53ea0e37e9c",  "id": "4381faad6957a0f8",  "inputs": {   "input": {    "id": "0d96e024a0643f85",    "src": "hda",    "uuid": "604deb60-a011-4830-a845-c4e2caa5e1de"   }  },  "job_messages": null,  "job_metrics": [],  "job_runner_name": null,  "job_stderr": null,  "job_stdout": null,  "model_class": "Job",  "output_collections": {},  "outputs": {   "output": {    "id": "4381faad6957a0f8",    "src": "hda",    "uuid": "e18f832d-54f8-470c-b59e-1d5dcf7a7435"   }  },  "params": {   "__input_ext": "\"input\"",   "chromInfo": "\"/cvmfs/data.galaxyproject.org/managed/len/ucsc/?.len\"",   "dbkey": "\"?\""  },  "state": "error",  "stderr": "",  "stdout": "",  "tool_id": "toolshed.g2.bx.psu.edu/repos/iuc/poretools_qualdist/poretools_qualdist/0.6.1a1.0",  "tool_stderr": "",  "tool_stdout": "",  "update_time": "2025-04-09T13:03:06.348278",  "user_email": "tests@fake.org" }, "output_problems": [  "Job in error state.. tool_id: toolshed.g2.bx.psu.edu/repos/iuc/poretools_qualdist/poretools_qualdist/0.6.1a1.0, exit_code: None, stderr: .",  "Job in error state.. tool_id: toolshed.g2.bx.psu.edu/repos/iuc/poretools_qualdist/poretools_qualdist/0.6.1a1.0, exit_code: None, stderr: ." ], "status": "failure", "test_index": 0, "time_seconds": 57.30326199531555, "tool_id": "poretools_qualdist", "tool_version": "0.6.1a1.0"}
                ]]></error>
            
            <system-out><![CDATA[
            
            ]]></system-out>
            <system-err><![CDATA[
            
            ]]></system-err>
        
    </testcase>
    
    <testcase classname="poretools_qualdist (Test #2)" name="1" time="34.42916917800903">
        
            
            <system-out><![CDATA[
            
            ]]></system-out>
            <system-err><![CDATA[
            
            ]]></system-err>
        
    </testcase>
    
    <testcase classname="sam2interval (Test #1)" name="0" time="0.09641742706298828">
        
            <error type="error" message="Input staging problem: Traceback (most recent call last):
  File "/opt/hostedtoolcache/Python/3.12.9/x64/lib/python3.12/site-packages/galaxy/tool_util/verify/interactor.py", line 1434, in verify_tool
    stage_data_in_history(
  File "/opt/hostedtoolcache/Python/3.12.9/x64/lib/python3.12/site-packages/galaxy/tool_util/verify/interactor.py", line 163, in stage_data_in_history
    test_dict = galaxy_interactor.remote_to_input(
                ^^^^^^^^^^^^^^^^^^^^^^^^^^^^^^^^^^
  File "/opt/hostedtoolcache/Python/3.12.9/x64/lib/python3.12/site-packages/galaxy/tool_util/verify/interactor.py", line 582, in remote_to_input
    path_or_location = self._get_path_or_location(
                       ^^^^^^^^^^^^^^^^^^^^^^^^^^^
  File "/opt/hostedtoolcache/Python/3.12.9/x64/lib/python3.12/site-packages/galaxy/tool_util/verify/interactor.py", line 619, in _get_path_or_location
    path = self.test_data_download(
           ^^^^^^^^^^^^^^^^^^^^^^^^
  File "/opt/hostedtoolcache/Python/3.12.9/x64/lib/python3.12/site-packages/galaxy/tool_util/verify/interactor.py", line 525, in test_data_download
    raise AssertionError(f"Test input file ({filename}) cannot be found.")
AssertionError: Test input file (sam_bioinf_example.sam) cannot be found.
"><![CDATA[
                { "execution_problem": "Input staging problem: Traceback (most recent call last):\n  File \"/opt/hostedtoolcache/Python/3.12.9/x64/lib/python3.12/site-packages/galaxy/tool_util/verify/interactor.py\", line 1434, in verify_tool\n    stage_data_in_history(\n  File \"/opt/hostedtoolcache/Python/3.12.9/x64/lib/python3.12/site-packages/galaxy/tool_util/verify/interactor.py\", line 163, in stage_data_in_history\n    test_dict = galaxy_interactor.remote_to_input(\n                ^^^^^^^^^^^^^^^^^^^^^^^^^^^^^^^^^^\n  File \"/opt/hostedtoolcache/Python/3.12.9/x64/lib/python3.12/site-packages/galaxy/tool_util/verify/interactor.py\", line 582, in remote_to_input\n    path_or_location = self._get_path_or_location(\n                       ^^^^^^^^^^^^^^^^^^^^^^^^^^^\n  File \"/opt/hostedtoolcache/Python/3.12.9/x64/lib/python3.12/site-packages/galaxy/tool_util/verify/interactor.py\", line 619, in _get_path_or_location\n    path = self.test_data_download(\n           ^^^^^^^^^^^^^^^^^^^^^^^^\n  File \"/opt/hostedtoolcache/Python/3.12.9/x64/lib/python3.12/site-packages/galaxy/tool_util/verify/interactor.py\", line 525, in test_data_download\n    raise AssertionError(f\"Test input file ({filename}) cannot be found.\")\nAssertionError: Test input file (sam_bioinf_example.sam) cannot be found.\n", "status": "error", "test_index": 0, "time_seconds": 0.09641742706298828, "tool_id": "sam2interval", "tool_version": "1.0.2"}
            ]]></error>
        
    </testcase>
    
    <testcase classname="sam2interval (Test #2)" name="1" time="0.05177903175354004">
        
            <error type="error" message="Input staging problem: Traceback (most recent call last):
  File "/opt/hostedtoolcache/Python/3.12.9/x64/lib/python3.12/site-packages/galaxy/tool_util/verify/interactor.py", line 1434, in verify_tool
    stage_data_in_history(
  File "/opt/hostedtoolcache/Python/3.12.9/x64/lib/python3.12/site-packages/galaxy/tool_util/verify/interactor.py", line 163, in stage_data_in_history
    test_dict = galaxy_interactor.remote_to_input(
                ^^^^^^^^^^^^^^^^^^^^^^^^^^^^^^^^^^
  File "/opt/hostedtoolcache/Python/3.12.9/x64/lib/python3.12/site-packages/galaxy/tool_util/verify/interactor.py", line 582, in remote_to_input
    path_or_location = self._get_path_or_location(
                       ^^^^^^^^^^^^^^^^^^^^^^^^^^^
  File "/opt/hostedtoolcache/Python/3.12.9/x64/lib/python3.12/site-packages/galaxy/tool_util/verify/interactor.py", line 619, in _get_path_or_location
    path = self.test_data_download(
           ^^^^^^^^^^^^^^^^^^^^^^^^
  File "/opt/hostedtoolcache/Python/3.12.9/x64/lib/python3.12/site-packages/galaxy/tool_util/verify/interactor.py", line 525, in test_data_download
    raise AssertionError(f"Test input file ({filename}) cannot be found.")
AssertionError: Test input file (sam_bioinf_example.sam) cannot be found.
"><![CDATA[
                { "execution_problem": "Input staging problem: Traceback (most recent call last):\n  File \"/opt/hostedtoolcache/Python/3.12.9/x64/lib/python3.12/site-packages/galaxy/tool_util/verify/interactor.py\", line 1434, in verify_tool\n    stage_data_in_history(\n  File \"/opt/hostedtoolcache/Python/3.12.9/x64/lib/python3.12/site-packages/galaxy/tool_util/verify/interactor.py\", line 163, in stage_data_in_history\n    test_dict = galaxy_interactor.remote_to_input(\n                ^^^^^^^^^^^^^^^^^^^^^^^^^^^^^^^^^^\n  File \"/opt/hostedtoolcache/Python/3.12.9/x64/lib/python3.12/site-packages/galaxy/tool_util/verify/interactor.py\", line 582, in remote_to_input\n    path_or_location = self._get_path_or_location(\n                       ^^^^^^^^^^^^^^^^^^^^^^^^^^^\n  File \"/opt/hostedtoolcache/Python/3.12.9/x64/lib/python3.12/site-packages/galaxy/tool_util/verify/interactor.py\", line 619, in _get_path_or_location\n    path = self.test_data_download(\n           ^^^^^^^^^^^^^^^^^^^^^^^^\n  File \"/opt/hostedtoolcache/Python/3.12.9/x64/lib/python3.12/site-packages/galaxy/tool_util/verify/interactor.py\", line 525, in test_data_download\n    raise AssertionError(f\"Test input file ({filename}) cannot be found.\")\nAssertionError: Test input file (sam_bioinf_example.sam) cannot be found.\n", "status": "error", "test_index": 1, "time_seconds": 0.05177903175354004, "tool_id": "sam2interval", "tool_version": "1.0.2"}
            ]]></error>
        
    </testcase>
    
    <testcase classname="sam2interval (Test #3)" name="2" time="0.05245518684387207">
        
            <error type="error" message="Input staging problem: Traceback (most recent call last):
  File "/opt/hostedtoolcache/Python/3.12.9/x64/lib/python3.12/site-packages/galaxy/tool_util/verify/interactor.py", line 1434, in verify_tool
    stage_data_in_history(
  File "/opt/hostedtoolcache/Python/3.12.9/x64/lib/python3.12/site-packages/galaxy/tool_util/verify/interactor.py", line 163, in stage_data_in_history
    test_dict = galaxy_interactor.remote_to_input(
                ^^^^^^^^^^^^^^^^^^^^^^^^^^^^^^^^^^
  File "/opt/hostedtoolcache/Python/3.12.9/x64/lib/python3.12/site-packages/galaxy/tool_util/verify/interactor.py", line 582, in remote_to_input
    path_or_location = self._get_path_or_location(
                       ^^^^^^^^^^^^^^^^^^^^^^^^^^^
  File "/opt/hostedtoolcache/Python/3.12.9/x64/lib/python3.12/site-packages/galaxy/tool_util/verify/interactor.py", line 619, in _get_path_or_location
    path = self.test_data_download(
           ^^^^^^^^^^^^^^^^^^^^^^^^
  File "/opt/hostedtoolcache/Python/3.12.9/x64/lib/python3.12/site-packages/galaxy/tool_util/verify/interactor.py", line 525, in test_data_download
    raise AssertionError(f"Test input file ({filename}) cannot be found.")
AssertionError: Test input file (sam2interval-test3.sam) cannot be found.
"><![CDATA[
                { "execution_problem": "Input staging problem: Traceback (most recent call last):\n  File \"/opt/hostedtoolcache/Python/3.12.9/x64/lib/python3.12/site-packages/galaxy/tool_util/verify/interactor.py\", line 1434, in verify_tool\n    stage_data_in_history(\n  File \"/opt/hostedtoolcache/Python/3.12.9/x64/lib/python3.12/site-packages/galaxy/tool_util/verify/interactor.py\", line 163, in stage_data_in_history\n    test_dict = galaxy_interactor.remote_to_input(\n                ^^^^^^^^^^^^^^^^^^^^^^^^^^^^^^^^^^\n  File \"/opt/hostedtoolcache/Python/3.12.9/x64/lib/python3.12/site-packages/galaxy/tool_util/verify/interactor.py\", line 582, in remote_to_input\n    path_or_location = self._get_path_or_location(\n                       ^^^^^^^^^^^^^^^^^^^^^^^^^^^\n  File \"/opt/hostedtoolcache/Python/3.12.9/x64/lib/python3.12/site-packages/galaxy/tool_util/verify/interactor.py\", line 619, in _get_path_or_location\n    path = self.test_data_download(\n           ^^^^^^^^^^^^^^^^^^^^^^^^\n  File \"/opt/hostedtoolcache/Python/3.12.9/x64/lib/python3.12/site-packages/galaxy/tool_util/verify/interactor.py\", line 525, in test_data_download\n    raise AssertionError(f\"Test input file ({filename}) cannot be found.\")\nAssertionError: Test input file (sam2interval-test3.sam) cannot be found.\n", "status": "error", "test_index": 2, "time_seconds": 0.05245518684387207, "tool_id": "sam2interval", "tool_version": "1.0.2"}
            ]]></error>
        
    </testcase>
    
    <testcase classname="samtools_flagstat (Test #1)" name="0" time="0.0997011661529541">
        
            <error type="error" message="Input staging problem: Traceback (most recent call last):
  File "/opt/hostedtoolcache/Python/3.12.9/x64/lib/python3.12/site-packages/galaxy/tool_util/verify/interactor.py", line 1434, in verify_tool
    stage_data_in_history(
  File "/opt/hostedtoolcache/Python/3.12.9/x64/lib/python3.12/site-packages/galaxy/tool_util/verify/interactor.py", line 163, in stage_data_in_history
    test_dict = galaxy_interactor.remote_to_input(
                ^^^^^^^^^^^^^^^^^^^^^^^^^^^^^^^^^^
  File "/opt/hostedtoolcache/Python/3.12.9/x64/lib/python3.12/site-packages/galaxy/tool_util/verify/interactor.py", line 582, in remote_to_input
    path_or_location = self._get_path_or_location(
                       ^^^^^^^^^^^^^^^^^^^^^^^^^^^
  File "/opt/hostedtoolcache/Python/3.12.9/x64/lib/python3.12/site-packages/galaxy/tool_util/verify/interactor.py", line 619, in _get_path_or_location
    path = self.test_data_download(
           ^^^^^^^^^^^^^^^^^^^^^^^^
  File "/opt/hostedtoolcache/Python/3.12.9/x64/lib/python3.12/site-packages/galaxy/tool_util/verify/interactor.py", line 525, in test_data_download
    raise AssertionError(f"Test input file ({filename}) cannot be found.")
AssertionError: Test input file (samtools_flagstat_input1.bam) cannot be found.
"><![CDATA[
                { "execution_problem": "Input staging problem: Traceback (most recent call last):\n  File \"/opt/hostedtoolcache/Python/3.12.9/x64/lib/python3.12/site-packages/galaxy/tool_util/verify/interactor.py\", line 1434, in verify_tool\n    stage_data_in_history(\n  File \"/opt/hostedtoolcache/Python/3.12.9/x64/lib/python3.12/site-packages/galaxy/tool_util/verify/interactor.py\", line 163, in stage_data_in_history\n    test_dict = galaxy_interactor.remote_to_input(\n                ^^^^^^^^^^^^^^^^^^^^^^^^^^^^^^^^^^\n  File \"/opt/hostedtoolcache/Python/3.12.9/x64/lib/python3.12/site-packages/galaxy/tool_util/verify/interactor.py\", line 582, in remote_to_input\n    path_or_location = self._get_path_or_location(\n                       ^^^^^^^^^^^^^^^^^^^^^^^^^^^\n  File \"/opt/hostedtoolcache/Python/3.12.9/x64/lib/python3.12/site-packages/galaxy/tool_util/verify/interactor.py\", line 619, in _get_path_or_location\n    path = self.test_data_download(\n           ^^^^^^^^^^^^^^^^^^^^^^^^\n  File \"/opt/hostedtoolcache/Python/3.12.9/x64/lib/python3.12/site-packages/galaxy/tool_util/verify/interactor.py\", line 525, in test_data_download\n    raise AssertionError(f\"Test input file ({filename}) cannot be found.\")\nAssertionError: Test input file (samtools_flagstat_input1.bam) cannot be found.\n", "status": "error", "test_index": 0, "time_seconds": 0.0997011661529541, "tool_id": "samtools_flagstat", "tool_version": "2.0.5"}
            ]]></error>
        
    </testcase>
    
    <testcase classname="samtools_flagstat (Test #2)" name="1" time="0.05208396911621094">
        
            <error type="error" message="Input staging problem: Traceback (most recent call last):
  File "/opt/hostedtoolcache/Python/3.12.9/x64/lib/python3.12/site-packages/galaxy/tool_util/verify/interactor.py", line 1434, in verify_tool
    stage_data_in_history(
  File "/opt/hostedtoolcache/Python/3.12.9/x64/lib/python3.12/site-packages/galaxy/tool_util/verify/interactor.py", line 163, in stage_data_in_history
    test_dict = galaxy_interactor.remote_to_input(
                ^^^^^^^^^^^^^^^^^^^^^^^^^^^^^^^^^^
  File "/opt/hostedtoolcache/Python/3.12.9/x64/lib/python3.12/site-packages/galaxy/tool_util/verify/interactor.py", line 582, in remote_to_input
    path_or_location = self._get_path_or_location(
                       ^^^^^^^^^^^^^^^^^^^^^^^^^^^
  File "/opt/hostedtoolcache/Python/3.12.9/x64/lib/python3.12/site-packages/galaxy/tool_util/verify/interactor.py", line 619, in _get_path_or_location
    path = self.test_data_download(
           ^^^^^^^^^^^^^^^^^^^^^^^^
  File "/opt/hostedtoolcache/Python/3.12.9/x64/lib/python3.12/site-packages/galaxy/tool_util/verify/interactor.py", line 525, in test_data_download
    raise AssertionError(f"Test input file ({filename}) cannot be found.")
AssertionError: Test input file (samtools_flagstat_input1.bam) cannot be found.
"><![CDATA[
                { "execution_problem": "Input staging problem: Traceback (most recent call last):\n  File \"/opt/hostedtoolcache/Python/3.12.9/x64/lib/python3.12/site-packages/galaxy/tool_util/verify/interactor.py\", line 1434, in verify_tool\n    stage_data_in_history(\n  File \"/opt/hostedtoolcache/Python/3.12.9/x64/lib/python3.12/site-packages/galaxy/tool_util/verify/interactor.py\", line 163, in stage_data_in_history\n    test_dict = galaxy_interactor.remote_to_input(\n                ^^^^^^^^^^^^^^^^^^^^^^^^^^^^^^^^^^\n  File \"/opt/hostedtoolcache/Python/3.12.9/x64/lib/python3.12/site-packages/galaxy/tool_util/verify/interactor.py\", line 582, in remote_to_input\n    path_or_location = self._get_path_or_location(\n                       ^^^^^^^^^^^^^^^^^^^^^^^^^^^\n  File \"/opt/hostedtoolcache/Python/3.12.9/x64/lib/python3.12/site-packages/galaxy/tool_util/verify/interactor.py\", line 619, in _get_path_or_location\n    path = self.test_data_download(\n           ^^^^^^^^^^^^^^^^^^^^^^^^\n  File \"/opt/hostedtoolcache/Python/3.12.9/x64/lib/python3.12/site-packages/galaxy/tool_util/verify/interactor.py\", line 525, in test_data_download\n    raise AssertionError(f\"Test input file ({filename}) cannot be found.\")\nAssertionError: Test input file (samtools_flagstat_input1.bam) cannot be found.\n", "status": "error", "test_index": 1, "time_seconds": 0.05208396911621094, "tool_id": "samtools_flagstat", "tool_version": "2.0.5"}
            ]]></error>
        
    </testcase>
    
    <testcase classname="samtools_flagstat (Test #3)" name="2" time="0.05525779724121094">
        
            <error type="error" message="Input staging problem: Traceback (most recent call last):
  File "/opt/hostedtoolcache/Python/3.12.9/x64/lib/python3.12/site-packages/galaxy/tool_util/verify/interactor.py", line 1434, in verify_tool
    stage_data_in_history(
  File "/opt/hostedtoolcache/Python/3.12.9/x64/lib/python3.12/site-packages/galaxy/tool_util/verify/interactor.py", line 163, in stage_data_in_history
    test_dict = galaxy_interactor.remote_to_input(
                ^^^^^^^^^^^^^^^^^^^^^^^^^^^^^^^^^^
  File "/opt/hostedtoolcache/Python/3.12.9/x64/lib/python3.12/site-packages/galaxy/tool_util/verify/interactor.py", line 582, in remote_to_input
    path_or_location = self._get_path_or_location(
                       ^^^^^^^^^^^^^^^^^^^^^^^^^^^
  File "/opt/hostedtoolcache/Python/3.12.9/x64/lib/python3.12/site-packages/galaxy/tool_util/verify/interactor.py", line 619, in _get_path_or_location
    path = self.test_data_download(
           ^^^^^^^^^^^^^^^^^^^^^^^^
  File "/opt/hostedtoolcache/Python/3.12.9/x64/lib/python3.12/site-packages/galaxy/tool_util/verify/interactor.py", line 525, in test_data_download
    raise AssertionError(f"Test input file ({filename}) cannot be found.")
AssertionError: Test input file (samtools_flagstat_input1.bam) cannot be found.
"><![CDATA[
                { "execution_problem": "Input staging problem: Traceback (most recent call last):\n  File \"/opt/hostedtoolcache/Python/3.12.9/x64/lib/python3.12/site-packages/galaxy/tool_util/verify/interactor.py\", line 1434, in verify_tool\n    stage_data_in_history(\n  File \"/opt/hostedtoolcache/Python/3.12.9/x64/lib/python3.12/site-packages/galaxy/tool_util/verify/interactor.py\", line 163, in stage_data_in_history\n    test_dict = galaxy_interactor.remote_to_input(\n                ^^^^^^^^^^^^^^^^^^^^^^^^^^^^^^^^^^\n  File \"/opt/hostedtoolcache/Python/3.12.9/x64/lib/python3.12/site-packages/galaxy/tool_util/verify/interactor.py\", line 582, in remote_to_input\n    path_or_location = self._get_path_or_location(\n                       ^^^^^^^^^^^^^^^^^^^^^^^^^^^\n  File \"/opt/hostedtoolcache/Python/3.12.9/x64/lib/python3.12/site-packages/galaxy/tool_util/verify/interactor.py\", line 619, in _get_path_or_location\n    path = self.test_data_download(\n           ^^^^^^^^^^^^^^^^^^^^^^^^\n  File \"/opt/hostedtoolcache/Python/3.12.9/x64/lib/python3.12/site-packages/galaxy/tool_util/verify/interactor.py\", line 525, in test_data_download\n    raise AssertionError(f\"Test input file ({filename}) cannot be found.\")\nAssertionError: Test input file (samtools_flagstat_input1.bam) cannot be found.\n", "status": "error", "test_index": 2, "time_seconds": 0.05525779724121094, "tool_id": "samtools_flagstat", "tool_version": "2.0.5"}
            ]]></error>
        
    </testcase>
    
    <testcase classname="vcfaddinfo (Test #1)" name="0" time="45.01919221878052">
        
            
            <system-out><![CDATA[
            
            ]]></system-out>
            <system-err><![CDATA[
            
            ]]></system-err>
        
    </testcase>
    
    <testcase classname="vcfleftalign (Test #1)" name="0" time="32.19261288642883">
        
            
            <system-out><![CDATA[
            
            ]]></system-out>
            <system-err><![CDATA[
            index file localref.fa.fai not found, generating...
            ]]></system-err>
        
    </testcase>
    
</testsuite>