<?xml version="1.0" encoding="UTF-8"?>
<testsuite name="Results (powered by Planemo)"
           tests="50"
           errors="27"
           failures="5"
           skip="0">
    
    <testcase classname="bam_to_sam (Test #1)" name="0" time="67.73575782775879">
        
            
            <system-out><![CDATA[
            
            ]]></system-out>
            <system-err><![CDATA[
            
            ]]></system-err>
        
    </testcase>
    
    <testcase classname="bam_to_sam (Test #2)" name="1" time="12.620527505874634">
        
            <error type="error" message="Input staging problem: Traceback (most recent call last):
  File "/opt/hostedtoolcache/Python/3.12.10/x64/lib/python3.12/site-packages/galaxy/tool_util/verify/interactor.py", line 1434, in verify_tool
    stage_data_in_history(
  File "/opt/hostedtoolcache/Python/3.12.10/x64/lib/python3.12/site-packages/galaxy/tool_util/verify/interactor.py", line 175, in stage_data_in_history
    staging_interface.handle_jobs()
  File "/opt/hostedtoolcache/Python/3.12.10/x64/lib/python3.12/site-packages/galaxy/tool_util/verify/interactor.py", line 212, in handle_jobs
    self.galaxy_interactor.wait_for_job(job_response["id"], job_response["history_id"], self.maxseconds)
  File "/opt/hostedtoolcache/Python/3.12.10/x64/lib/python3.12/site-packages/galaxy/tool_util/verify/interactor.py", line 399, in wait_for_job
    self.wait_for(lambda: self.__job_ready(job_id, history_id), maxseconds=maxseconds)
  File "/opt/hostedtoolcache/Python/3.12.10/x64/lib/python3.12/site-packages/galaxy/tool_util/verify/interactor.py", line 403, in wait_for
    wait_on(func, what, walltime_exceeded)
  File "/opt/hostedtoolcache/Python/3.12.10/x64/lib/python3.12/site-packages/galaxy/tool_util/verify/wait.py", line 38, in wait_on
    value = function()
            ^^^^^^^^^^
  File "/opt/hostedtoolcache/Python/3.12.10/x64/lib/python3.12/site-packages/galaxy/tool_util/verify/interactor.py", line 399, in <lambda>
    self.wait_for(lambda: self.__job_ready(job_id, history_id), maxseconds=maxseconds)
                          ^^^^^^^^^^^^^^^^^^^^^^^^^^^^^^^^^^^^
  File "/opt/hostedtoolcache/Python/3.12.10/x64/lib/python3.12/site-packages/galaxy/tool_util/verify/interactor.py", line 747, in __job_ready
    return self._state_ready(job_id, error_msg="Job in error state.")
           ^^^^^^^^^^^^^^^^^^^^^^^^^^^^^^^^^^^^^^^^^^^^^^^^^^^^^^^^^^
  File "/opt/hostedtoolcache/Python/3.12.10/x64/lib/python3.12/site-packages/galaxy/tool_util/verify/interactor.py", line 839, in _state_ready
    raise Exception(
Exception: Job in error state.. tool_id: __DATA_FETCH__, exit_code: None, stderr: .
"><![CDATA[
                { "execution_problem": "Input staging problem: Traceback (most recent call last):\n  File \"/opt/hostedtoolcache/Python/3.12.10/x64/lib/python3.12/site-packages/galaxy/tool_util/verify/interactor.py\", line 1434, in verify_tool\n    stage_data_in_history(\n  File \"/opt/hostedtoolcache/Python/3.12.10/x64/lib/python3.12/site-packages/galaxy/tool_util/verify/interactor.py\", line 175, in stage_data_in_history\n    staging_interface.handle_jobs()\n  File \"/opt/hostedtoolcache/Python/3.12.10/x64/lib/python3.12/site-packages/galaxy/tool_util/verify/interactor.py\", line 212, in handle_jobs\n    self.galaxy_interactor.wait_for_job(job_response[\"id\"], job_response[\"history_id\"], self.maxseconds)\n  File \"/opt/hostedtoolcache/Python/3.12.10/x64/lib/python3.12/site-packages/galaxy/tool_util/verify/interactor.py\", line 399, in wait_for_job\n    self.wait_for(lambda: self.__job_ready(job_id, history_id), maxseconds=maxseconds)\n  File \"/opt/hostedtoolcache/Python/3.12.10/x64/lib/python3.12/site-packages/galaxy/tool_util/verify/interactor.py\", line 403, in wait_for\n    wait_on(func, what, walltime_exceeded)\n  File \"/opt/hostedtoolcache/Python/3.12.10/x64/lib/python3.12/site-packages/galaxy/tool_util/verify/wait.py\", line 38, in wait_on\n    value = function()\n            ^^^^^^^^^^\n  File \"/opt/hostedtoolcache/Python/3.12.10/x64/lib/python3.12/site-packages/galaxy/tool_util/verify/interactor.py\", line 399, in \u003clambda\u003e\n    self.wait_for(lambda: self.__job_ready(job_id, history_id), maxseconds=maxseconds)\n                          ^^^^^^^^^^^^^^^^^^^^^^^^^^^^^^^^^^^^\n  File \"/opt/hostedtoolcache/Python/3.12.10/x64/lib/python3.12/site-packages/galaxy/tool_util/verify/interactor.py\", line 747, in __job_ready\n    return self._state_ready(job_id, error_msg=\"Job in error state.\")\n           ^^^^^^^^^^^^^^^^^^^^^^^^^^^^^^^^^^^^^^^^^^^^^^^^^^^^^^^^^^\n  File \"/opt/hostedtoolcache/Python/3.12.10/x64/lib/python3.12/site-packages/galaxy/tool_util/verify/interactor.py\", line 839, in _state_ready\n    raise Exception(\nException: Job in error state.. tool_id: __DATA_FETCH__, exit_code: None, stderr: .\n", "status": "error", "test_index": 1, "time_seconds": 12.620527505874634, "tool_id": "bam_to_sam", "tool_version": "2.0.4"}
            ]]></error>
        
    </testcase>
    
    <testcase classname="bam_to_sam (Test #3)" name="2" time="33.05211663246155">
        
            
            <system-out><![CDATA[
            
            ]]></system-out>
            <system-err><![CDATA[
            
            ]]></system-err>
        
    </testcase>
    
    <testcase classname="bcftools_merge (Test #1)" name="0" time="56.48971343040466">
        
            
            <system-out><![CDATA[
            
            ]]></system-out>
            <system-err><![CDATA[
            
            ]]></system-err>
        
    </testcase>
    
    <testcase classname="bcftools_merge (Test #2)" name="1" time="35.144474267959595">
        
            
            <system-out><![CDATA[
            
            ]]></system-out>
            <system-err><![CDATA[
            
            ]]></system-err>
        
    </testcase>
    
    <testcase classname="bcftools_merge (Test #3)" name="2" time="34.84706115722656">
        
            
            <system-out><![CDATA[
            
            ]]></system-out>
            <system-err><![CDATA[
            
            ]]></system-err>
        
    </testcase>
    
    <testcase classname="bcftools_merge (Test #4)" name="3" time="35.238091707229614">
        
            
            <system-out><![CDATA[
            
            ]]></system-out>
            <system-err><![CDATA[
            
            ]]></system-err>
        
    </testcase>
    
    <testcase classname="bcftools_merge (Test #5)" name="4" time="34.124881744384766">
        
            
            <system-out><![CDATA[
            
            ]]></system-out>
            <system-err><![CDATA[
            
            ]]></system-err>
        
    </testcase>
    
    <testcase classname="bcftools_merge (Test #6)" name="5" time="35.32918906211853">
        
            
            <system-out><![CDATA[
            
            ]]></system-out>
            <system-err><![CDATA[
            [W::bcf_sr_add_reader] Using multiple unindexed files may produce errors, make sure chromosomes are in the same order!
            ]]></system-err>
        
    </testcase>
    
    <testcase classname="bcftools_merge (Test #7)" name="6" time="35.36154127120972">
        
            
            <system-out><![CDATA[
            
            ]]></system-out>
            <system-err><![CDATA[
            
            ]]></system-err>
        
    </testcase>
    
    <testcase classname="bcftools_plugin_missing2ref (Test #1)" name="0" time="12.182211637496948">
        
            <error type="error" message="Input staging problem: Traceback (most recent call last):
  File "/opt/hostedtoolcache/Python/3.12.10/x64/lib/python3.12/site-packages/galaxy/tool_util/verify/interactor.py", line 1434, in verify_tool
    stage_data_in_history(
  File "/opt/hostedtoolcache/Python/3.12.10/x64/lib/python3.12/site-packages/galaxy/tool_util/verify/interactor.py", line 175, in stage_data_in_history
    staging_interface.handle_jobs()
  File "/opt/hostedtoolcache/Python/3.12.10/x64/lib/python3.12/site-packages/galaxy/tool_util/verify/interactor.py", line 212, in handle_jobs
    self.galaxy_interactor.wait_for_job(job_response["id"], job_response["history_id"], self.maxseconds)
  File "/opt/hostedtoolcache/Python/3.12.10/x64/lib/python3.12/site-packages/galaxy/tool_util/verify/interactor.py", line 399, in wait_for_job
    self.wait_for(lambda: self.__job_ready(job_id, history_id), maxseconds=maxseconds)
  File "/opt/hostedtoolcache/Python/3.12.10/x64/lib/python3.12/site-packages/galaxy/tool_util/verify/interactor.py", line 403, in wait_for
    wait_on(func, what, walltime_exceeded)
  File "/opt/hostedtoolcache/Python/3.12.10/x64/lib/python3.12/site-packages/galaxy/tool_util/verify/wait.py", line 38, in wait_on
    value = function()
            ^^^^^^^^^^
  File "/opt/hostedtoolcache/Python/3.12.10/x64/lib/python3.12/site-packages/galaxy/tool_util/verify/interactor.py", line 399, in <lambda>
    self.wait_for(lambda: self.__job_ready(job_id, history_id), maxseconds=maxseconds)
                          ^^^^^^^^^^^^^^^^^^^^^^^^^^^^^^^^^^^^
  File "/opt/hostedtoolcache/Python/3.12.10/x64/lib/python3.12/site-packages/galaxy/tool_util/verify/interactor.py", line 747, in __job_ready
    return self._state_ready(job_id, error_msg="Job in error state.")
           ^^^^^^^^^^^^^^^^^^^^^^^^^^^^^^^^^^^^^^^^^^^^^^^^^^^^^^^^^^
  File "/opt/hostedtoolcache/Python/3.12.10/x64/lib/python3.12/site-packages/galaxy/tool_util/verify/interactor.py", line 839, in _state_ready
    raise Exception(
Exception: Job in error state.. tool_id: __DATA_FETCH__, exit_code: None, stderr: .
"><![CDATA[
                { "execution_problem": "Input staging problem: Traceback (most recent call last):\n  File \"/opt/hostedtoolcache/Python/3.12.10/x64/lib/python3.12/site-packages/galaxy/tool_util/verify/interactor.py\", line 1434, in verify_tool\n    stage_data_in_history(\n  File \"/opt/hostedtoolcache/Python/3.12.10/x64/lib/python3.12/site-packages/galaxy/tool_util/verify/interactor.py\", line 175, in stage_data_in_history\n    staging_interface.handle_jobs()\n  File \"/opt/hostedtoolcache/Python/3.12.10/x64/lib/python3.12/site-packages/galaxy/tool_util/verify/interactor.py\", line 212, in handle_jobs\n    self.galaxy_interactor.wait_for_job(job_response[\"id\"], job_response[\"history_id\"], self.maxseconds)\n  File \"/opt/hostedtoolcache/Python/3.12.10/x64/lib/python3.12/site-packages/galaxy/tool_util/verify/interactor.py\", line 399, in wait_for_job\n    self.wait_for(lambda: self.__job_ready(job_id, history_id), maxseconds=maxseconds)\n  File \"/opt/hostedtoolcache/Python/3.12.10/x64/lib/python3.12/site-packages/galaxy/tool_util/verify/interactor.py\", line 403, in wait_for\n    wait_on(func, what, walltime_exceeded)\n  File \"/opt/hostedtoolcache/Python/3.12.10/x64/lib/python3.12/site-packages/galaxy/tool_util/verify/wait.py\", line 38, in wait_on\n    value = function()\n            ^^^^^^^^^^\n  File \"/opt/hostedtoolcache/Python/3.12.10/x64/lib/python3.12/site-packages/galaxy/tool_util/verify/interactor.py\", line 399, in \u003clambda\u003e\n    self.wait_for(lambda: self.__job_ready(job_id, history_id), maxseconds=maxseconds)\n                          ^^^^^^^^^^^^^^^^^^^^^^^^^^^^^^^^^^^^\n  File \"/opt/hostedtoolcache/Python/3.12.10/x64/lib/python3.12/site-packages/galaxy/tool_util/verify/interactor.py\", line 747, in __job_ready\n    return self._state_ready(job_id, error_msg=\"Job in error state.\")\n           ^^^^^^^^^^^^^^^^^^^^^^^^^^^^^^^^^^^^^^^^^^^^^^^^^^^^^^^^^^\n  File \"/opt/hostedtoolcache/Python/3.12.10/x64/lib/python3.12/site-packages/galaxy/tool_util/verify/interactor.py\", line 839, in _state_ready\n    raise Exception(\nException: Job in error state.. tool_id: __DATA_FETCH__, exit_code: None, stderr: .\n", "status": "error", "test_index": 0, "time_seconds": 12.182211637496948, "tool_id": "bcftools_plugin_missing2ref", "tool_version": "1.15.1+galaxy4"}
            ]]></error>
        
    </testcase>
    
    <testcase classname="column_order_header_sort (Test #1)" name="0" time="0.10245752334594727">
        
            <error type="error" message="Input staging problem: Traceback (most recent call last):
  File "/opt/hostedtoolcache/Python/3.12.10/x64/lib/python3.12/site-packages/galaxy/tool_util/verify/interactor.py", line 1434, in verify_tool
    stage_data_in_history(
  File "/opt/hostedtoolcache/Python/3.12.10/x64/lib/python3.12/site-packages/galaxy/tool_util/verify/interactor.py", line 163, in stage_data_in_history
    test_dict = galaxy_interactor.remote_to_input(
                ^^^^^^^^^^^^^^^^^^^^^^^^^^^^^^^^^^
  File "/opt/hostedtoolcache/Python/3.12.10/x64/lib/python3.12/site-packages/galaxy/tool_util/verify/interactor.py", line 582, in remote_to_input
    path_or_location = self._get_path_or_location(
                       ^^^^^^^^^^^^^^^^^^^^^^^^^^^
  File "/opt/hostedtoolcache/Python/3.12.10/x64/lib/python3.12/site-packages/galaxy/tool_util/verify/interactor.py", line 619, in _get_path_or_location
    path = self.test_data_download(
           ^^^^^^^^^^^^^^^^^^^^^^^^
  File "/opt/hostedtoolcache/Python/3.12.10/x64/lib/python3.12/site-packages/galaxy/tool_util/verify/interactor.py", line 525, in test_data_download
    raise AssertionError(f"Test input file ({filename}) cannot be found.")
AssertionError: Test input file (in_1.tabular) cannot be found.
"><![CDATA[
                { "execution_problem": "Input staging problem: Traceback (most recent call last):\n  File \"/opt/hostedtoolcache/Python/3.12.10/x64/lib/python3.12/site-packages/galaxy/tool_util/verify/interactor.py\", line 1434, in verify_tool\n    stage_data_in_history(\n  File \"/opt/hostedtoolcache/Python/3.12.10/x64/lib/python3.12/site-packages/galaxy/tool_util/verify/interactor.py\", line 163, in stage_data_in_history\n    test_dict = galaxy_interactor.remote_to_input(\n                ^^^^^^^^^^^^^^^^^^^^^^^^^^^^^^^^^^\n  File \"/opt/hostedtoolcache/Python/3.12.10/x64/lib/python3.12/site-packages/galaxy/tool_util/verify/interactor.py\", line 582, in remote_to_input\n    path_or_location = self._get_path_or_location(\n                       ^^^^^^^^^^^^^^^^^^^^^^^^^^^\n  File \"/opt/hostedtoolcache/Python/3.12.10/x64/lib/python3.12/site-packages/galaxy/tool_util/verify/interactor.py\", line 619, in _get_path_or_location\n    path = self.test_data_download(\n           ^^^^^^^^^^^^^^^^^^^^^^^^\n  File \"/opt/hostedtoolcache/Python/3.12.10/x64/lib/python3.12/site-packages/galaxy/tool_util/verify/interactor.py\", line 525, in test_data_download\n    raise AssertionError(f\"Test input file ({filename}) cannot be found.\")\nAssertionError: Test input file (in_1.tabular) cannot be found.\n", "status": "error", "test_index": 0, "time_seconds": 0.10245752334594727, "tool_id": "column_order_header_sort", "tool_version": "0.0.1"}
            ]]></error>
        
    </testcase>
    
    <testcase classname="deeptools_plot_pca (Test #1)" name="0" time="52.45247173309326">
        
            
            <system-out><![CDATA[
            
            ]]></system-out>
            <system-err><![CDATA[
            
            ]]></system-err>
        
    </testcase>
    
    <testcase classname="deeptools_plot_pca (Test #2)" name="1" time="28.00425434112549">
        
            
                <error type="error" message="Tool exit code: None"><![CDATA[
                    { "inputs": {  "corData": {   "id": "0764a95aaac060e0",   "src": "hda"  },  "outFileFormat": "png",  "outFileNameData": true,  "plotTitle": "Test Plot" }, "job": {  "command_line": "plotPCA --corData \u0027/galaxy/server/database/objects/3/0/7/dataset_3070870e-ba82-47f4-9b49-670ecc3c0a09.dat\u0027 --plotTitle \u0027Test Plot\u0027 --plotFile \u0027/galaxy/server/database/objects/a/3/0/dataset_a3056c31-0082-4d07-b3e1-7d91023a8cf2.dat\u0027 --plotFileFormat \u0027png\u0027 --outFileNameData \u0027/galaxy/server/database/objects/1/5/a/dataset_15ae2edc-ebb3-4566-b156-199939b9bfab.dat\u0027",  "command_version": null,  "copied_from_job_id": null,  "create_time": "2025-05-23T01:08:20.236367",  "dependencies": [],  "exit_code": null,  "external_id": "gxy-bvq8j",  "galaxy_version": "24.1",  "handler": null,  "history_id": "bb3312a29e4a1991",  "id": "43e845a22d6631c7",  "inputs": {   "corData": {    "id": "0764a95aaac060e0",    "src": "hda",    "uuid": "3070870e-ba82-47f4-9b49-670ecc3c0a09"   }  },  "job_messages": null,  "job_metrics": [],  "job_runner_name": null,  "job_stderr": null,  "job_stdout": null,  "model_class": "Job",  "output_collections": {},  "outputs": {   "outFileName": {    "id": "43e845a22d6631c7",    "src": "hda",    "uuid": "a3056c31-0082-4d07-b3e1-7d91023a8cf2"   },   "output_outFileNameData": {    "id": "74d8f62a82715d57",    "src": "hda",    "uuid": "15ae2edc-ebb3-4566-b156-199939b9bfab"   }  },  "params": {   "__input_ext": "\"input\"",   "advancedOpt": "{\"__current_case__\": 0, \"showAdvancedOpt\": \"no\"}",   "chromInfo": "\"/cvmfs/data.galaxyproject.org/managed/len/ucsc/?.len\"",   "dbkey": "\"?\"",   "outFileFormat": "\"png\"",   "outFileNameData": "true",   "plotTitle": "\"Test Plot\""  },  "state": "error",  "stderr": "",  "stdout": "",  "tool_id": "toolshed.g2.bx.psu.edu/repos/bgruening/deeptools_plot_pca/deeptools_plot_pca/3.5.4+galaxy0",  "tool_stderr": "",  "tool_stdout": "",  "update_time": "2025-05-23T01:08:28.879844",  "user_email": "tests@fake.org" }, "output_problems": [  "Job in error state.. tool_id: toolshed.g2.bx.psu.edu/repos/bgruening/deeptools_plot_pca/deeptools_plot_pca/3.5.4+galaxy0, exit_code: None, stderr: .",  "Job in error state.. tool_id: toolshed.g2.bx.psu.edu/repos/bgruening/deeptools_plot_pca/deeptools_plot_pca/3.5.4+galaxy0, exit_code: None, stderr: .",  "Job in error state.. tool_id: toolshed.g2.bx.psu.edu/repos/bgruening/deeptools_plot_pca/deeptools_plot_pca/3.5.4+galaxy0, exit_code: None, stderr: ." ], "status": "failure", "test_index": 1, "time_seconds": 28.00425434112549, "tool_id": "deeptools_plot_pca", "tool_version": "3.5.4+galaxy0"}
                ]]></error>
            
            <system-out><![CDATA[
            
            ]]></system-out>
            <system-err><![CDATA[
            
            ]]></system-err>
        
    </testcase>
    
    <testcase classname="fastp (Test #1)" name="0" time="0.09944868087768555">
        
            <error type="error" message="Input staging problem: Traceback (most recent call last):
  File "/opt/hostedtoolcache/Python/3.12.10/x64/lib/python3.12/site-packages/galaxy/tool_util/verify/interactor.py", line 1434, in verify_tool
    stage_data_in_history(
  File "/opt/hostedtoolcache/Python/3.12.10/x64/lib/python3.12/site-packages/galaxy/tool_util/verify/interactor.py", line 163, in stage_data_in_history
    test_dict = galaxy_interactor.remote_to_input(
                ^^^^^^^^^^^^^^^^^^^^^^^^^^^^^^^^^^
  File "/opt/hostedtoolcache/Python/3.12.10/x64/lib/python3.12/site-packages/galaxy/tool_util/verify/interactor.py", line 582, in remote_to_input
    path_or_location = self._get_path_or_location(
                       ^^^^^^^^^^^^^^^^^^^^^^^^^^^
  File "/opt/hostedtoolcache/Python/3.12.10/x64/lib/python3.12/site-packages/galaxy/tool_util/verify/interactor.py", line 619, in _get_path_or_location
    path = self.test_data_download(
           ^^^^^^^^^^^^^^^^^^^^^^^^
  File "/opt/hostedtoolcache/Python/3.12.10/x64/lib/python3.12/site-packages/galaxy/tool_util/verify/interactor.py", line 525, in test_data_download
    raise AssertionError(f"Test input file ({filename}) cannot be found.")
AssertionError: Test input file (R1.fq) cannot be found.
"><![CDATA[
                { "execution_problem": "Input staging problem: Traceback (most recent call last):\n  File \"/opt/hostedtoolcache/Python/3.12.10/x64/lib/python3.12/site-packages/galaxy/tool_util/verify/interactor.py\", line 1434, in verify_tool\n    stage_data_in_history(\n  File \"/opt/hostedtoolcache/Python/3.12.10/x64/lib/python3.12/site-packages/galaxy/tool_util/verify/interactor.py\", line 163, in stage_data_in_history\n    test_dict = galaxy_interactor.remote_to_input(\n                ^^^^^^^^^^^^^^^^^^^^^^^^^^^^^^^^^^\n  File \"/opt/hostedtoolcache/Python/3.12.10/x64/lib/python3.12/site-packages/galaxy/tool_util/verify/interactor.py\", line 582, in remote_to_input\n    path_or_location = self._get_path_or_location(\n                       ^^^^^^^^^^^^^^^^^^^^^^^^^^^\n  File \"/opt/hostedtoolcache/Python/3.12.10/x64/lib/python3.12/site-packages/galaxy/tool_util/verify/interactor.py\", line 619, in _get_path_or_location\n    path = self.test_data_download(\n           ^^^^^^^^^^^^^^^^^^^^^^^^\n  File \"/opt/hostedtoolcache/Python/3.12.10/x64/lib/python3.12/site-packages/galaxy/tool_util/verify/interactor.py\", line 525, in test_data_download\n    raise AssertionError(f\"Test input file ({filename}) cannot be found.\")\nAssertionError: Test input file (R1.fq) cannot be found.\n", "status": "error", "test_index": 0, "time_seconds": 0.09944868087768555, "tool_id": "fastp", "tool_version": "0.24.0+galaxy3"}
            ]]></error>
        
    </testcase>
    
    <testcase classname="fastp (Test #2)" name="1" time="0.05424833297729492">
        
            <error type="error" message="Input staging problem: Traceback (most recent call last):
  File "/opt/hostedtoolcache/Python/3.12.10/x64/lib/python3.12/site-packages/galaxy/tool_util/verify/interactor.py", line 1434, in verify_tool
    stage_data_in_history(
  File "/opt/hostedtoolcache/Python/3.12.10/x64/lib/python3.12/site-packages/galaxy/tool_util/verify/interactor.py", line 163, in stage_data_in_history
    test_dict = galaxy_interactor.remote_to_input(
                ^^^^^^^^^^^^^^^^^^^^^^^^^^^^^^^^^^
  File "/opt/hostedtoolcache/Python/3.12.10/x64/lib/python3.12/site-packages/galaxy/tool_util/verify/interactor.py", line 582, in remote_to_input
    path_or_location = self._get_path_or_location(
                       ^^^^^^^^^^^^^^^^^^^^^^^^^^^
  File "/opt/hostedtoolcache/Python/3.12.10/x64/lib/python3.12/site-packages/galaxy/tool_util/verify/interactor.py", line 619, in _get_path_or_location
    path = self.test_data_download(
           ^^^^^^^^^^^^^^^^^^^^^^^^
  File "/opt/hostedtoolcache/Python/3.12.10/x64/lib/python3.12/site-packages/galaxy/tool_util/verify/interactor.py", line 525, in test_data_download
    raise AssertionError(f"Test input file ({filename}) cannot be found.")
AssertionError: Test input file (bwa-mem-fastq1.fq) cannot be found.
"><![CDATA[
                { "execution_problem": "Input staging problem: Traceback (most recent call last):\n  File \"/opt/hostedtoolcache/Python/3.12.10/x64/lib/python3.12/site-packages/galaxy/tool_util/verify/interactor.py\", line 1434, in verify_tool\n    stage_data_in_history(\n  File \"/opt/hostedtoolcache/Python/3.12.10/x64/lib/python3.12/site-packages/galaxy/tool_util/verify/interactor.py\", line 163, in stage_data_in_history\n    test_dict = galaxy_interactor.remote_to_input(\n                ^^^^^^^^^^^^^^^^^^^^^^^^^^^^^^^^^^\n  File \"/opt/hostedtoolcache/Python/3.12.10/x64/lib/python3.12/site-packages/galaxy/tool_util/verify/interactor.py\", line 582, in remote_to_input\n    path_or_location = self._get_path_or_location(\n                       ^^^^^^^^^^^^^^^^^^^^^^^^^^^\n  File \"/opt/hostedtoolcache/Python/3.12.10/x64/lib/python3.12/site-packages/galaxy/tool_util/verify/interactor.py\", line 619, in _get_path_or_location\n    path = self.test_data_download(\n           ^^^^^^^^^^^^^^^^^^^^^^^^\n  File \"/opt/hostedtoolcache/Python/3.12.10/x64/lib/python3.12/site-packages/galaxy/tool_util/verify/interactor.py\", line 525, in test_data_download\n    raise AssertionError(f\"Test input file ({filename}) cannot be found.\")\nAssertionError: Test input file (bwa-mem-fastq1.fq) cannot be found.\n", "status": "error", "test_index": 1, "time_seconds": 0.05424833297729492, "tool_id": "fastp", "tool_version": "0.24.0+galaxy3"}
            ]]></error>
        
    </testcase>
    
    <testcase classname="fastp (Test #11)" name="10" time="0.05485892295837402">
        
            <error type="error" message="Input staging problem: Traceback (most recent call last):
  File "/opt/hostedtoolcache/Python/3.12.10/x64/lib/python3.12/site-packages/galaxy/tool_util/verify/interactor.py", line 1434, in verify_tool
    stage_data_in_history(
  File "/opt/hostedtoolcache/Python/3.12.10/x64/lib/python3.12/site-packages/galaxy/tool_util/verify/interactor.py", line 163, in stage_data_in_history
    test_dict = galaxy_interactor.remote_to_input(
                ^^^^^^^^^^^^^^^^^^^^^^^^^^^^^^^^^^
  File "/opt/hostedtoolcache/Python/3.12.10/x64/lib/python3.12/site-packages/galaxy/tool_util/verify/interactor.py", line 582, in remote_to_input
    path_or_location = self._get_path_or_location(
                       ^^^^^^^^^^^^^^^^^^^^^^^^^^^
  File "/opt/hostedtoolcache/Python/3.12.10/x64/lib/python3.12/site-packages/galaxy/tool_util/verify/interactor.py", line 619, in _get_path_or_location
    path = self.test_data_download(
           ^^^^^^^^^^^^^^^^^^^^^^^^
  File "/opt/hostedtoolcache/Python/3.12.10/x64/lib/python3.12/site-packages/galaxy/tool_util/verify/interactor.py", line 525, in test_data_download
    raise AssertionError(f"Test input file ({filename}) cannot be found.")
AssertionError: Test input file (R1.fq.gz) cannot be found.
"><![CDATA[
                { "execution_problem": "Input staging problem: Traceback (most recent call last):\n  File \"/opt/hostedtoolcache/Python/3.12.10/x64/lib/python3.12/site-packages/galaxy/tool_util/verify/interactor.py\", line 1434, in verify_tool\n    stage_data_in_history(\n  File \"/opt/hostedtoolcache/Python/3.12.10/x64/lib/python3.12/site-packages/galaxy/tool_util/verify/interactor.py\", line 163, in stage_data_in_history\n    test_dict = galaxy_interactor.remote_to_input(\n                ^^^^^^^^^^^^^^^^^^^^^^^^^^^^^^^^^^\n  File \"/opt/hostedtoolcache/Python/3.12.10/x64/lib/python3.12/site-packages/galaxy/tool_util/verify/interactor.py\", line 582, in remote_to_input\n    path_or_location = self._get_path_or_location(\n                       ^^^^^^^^^^^^^^^^^^^^^^^^^^^\n  File \"/opt/hostedtoolcache/Python/3.12.10/x64/lib/python3.12/site-packages/galaxy/tool_util/verify/interactor.py\", line 619, in _get_path_or_location\n    path = self.test_data_download(\n           ^^^^^^^^^^^^^^^^^^^^^^^^\n  File \"/opt/hostedtoolcache/Python/3.12.10/x64/lib/python3.12/site-packages/galaxy/tool_util/verify/interactor.py\", line 525, in test_data_download\n    raise AssertionError(f\"Test input file ({filename}) cannot be found.\")\nAssertionError: Test input file (R1.fq.gz) cannot be found.\n", "status": "error", "test_index": 10, "time_seconds": 0.05485892295837402, "tool_id": "fastp", "tool_version": "0.24.0+galaxy3"}
            ]]></error>
        
    </testcase>
    
    <testcase classname="fastp (Test #12)" name="11" time="0.05334115028381348">
        
            <error type="error" message="Input staging problem: Traceback (most recent call last):
  File "/opt/hostedtoolcache/Python/3.12.10/x64/lib/python3.12/site-packages/galaxy/tool_util/verify/interactor.py", line 1434, in verify_tool
    stage_data_in_history(
  File "/opt/hostedtoolcache/Python/3.12.10/x64/lib/python3.12/site-packages/galaxy/tool_util/verify/interactor.py", line 163, in stage_data_in_history
    test_dict = galaxy_interactor.remote_to_input(
                ^^^^^^^^^^^^^^^^^^^^^^^^^^^^^^^^^^
  File "/opt/hostedtoolcache/Python/3.12.10/x64/lib/python3.12/site-packages/galaxy/tool_util/verify/interactor.py", line 582, in remote_to_input
    path_or_location = self._get_path_or_location(
                       ^^^^^^^^^^^^^^^^^^^^^^^^^^^
  File "/opt/hostedtoolcache/Python/3.12.10/x64/lib/python3.12/site-packages/galaxy/tool_util/verify/interactor.py", line 619, in _get_path_or_location
    path = self.test_data_download(
           ^^^^^^^^^^^^^^^^^^^^^^^^
  File "/opt/hostedtoolcache/Python/3.12.10/x64/lib/python3.12/site-packages/galaxy/tool_util/verify/interactor.py", line 525, in test_data_download
    raise AssertionError(f"Test input file ({filename}) cannot be found.")
AssertionError: Test input file (bwa-mem-fastq1.fq) cannot be found.
"><![CDATA[
                { "execution_problem": "Input staging problem: Traceback (most recent call last):\n  File \"/opt/hostedtoolcache/Python/3.12.10/x64/lib/python3.12/site-packages/galaxy/tool_util/verify/interactor.py\", line 1434, in verify_tool\n    stage_data_in_history(\n  File \"/opt/hostedtoolcache/Python/3.12.10/x64/lib/python3.12/site-packages/galaxy/tool_util/verify/interactor.py\", line 163, in stage_data_in_history\n    test_dict = galaxy_interactor.remote_to_input(\n                ^^^^^^^^^^^^^^^^^^^^^^^^^^^^^^^^^^\n  File \"/opt/hostedtoolcache/Python/3.12.10/x64/lib/python3.12/site-packages/galaxy/tool_util/verify/interactor.py\", line 582, in remote_to_input\n    path_or_location = self._get_path_or_location(\n                       ^^^^^^^^^^^^^^^^^^^^^^^^^^^\n  File \"/opt/hostedtoolcache/Python/3.12.10/x64/lib/python3.12/site-packages/galaxy/tool_util/verify/interactor.py\", line 619, in _get_path_or_location\n    path = self.test_data_download(\n           ^^^^^^^^^^^^^^^^^^^^^^^^\n  File \"/opt/hostedtoolcache/Python/3.12.10/x64/lib/python3.12/site-packages/galaxy/tool_util/verify/interactor.py\", line 525, in test_data_download\n    raise AssertionError(f\"Test input file ({filename}) cannot be found.\")\nAssertionError: Test input file (bwa-mem-fastq1.fq) cannot be found.\n", "status": "error", "test_index": 11, "time_seconds": 0.05334115028381348, "tool_id": "fastp", "tool_version": "0.24.0+galaxy3"}
            ]]></error>
        
    </testcase>
    
    <testcase classname="fastp (Test #13)" name="12" time="0.05554485321044922">
        
            <error type="error" message="Input staging problem: Traceback (most recent call last):
  File "/opt/hostedtoolcache/Python/3.12.10/x64/lib/python3.12/site-packages/galaxy/tool_util/verify/interactor.py", line 1434, in verify_tool
    stage_data_in_history(
  File "/opt/hostedtoolcache/Python/3.12.10/x64/lib/python3.12/site-packages/galaxy/tool_util/verify/interactor.py", line 163, in stage_data_in_history
    test_dict = galaxy_interactor.remote_to_input(
                ^^^^^^^^^^^^^^^^^^^^^^^^^^^^^^^^^^
  File "/opt/hostedtoolcache/Python/3.12.10/x64/lib/python3.12/site-packages/galaxy/tool_util/verify/interactor.py", line 582, in remote_to_input
    path_or_location = self._get_path_or_location(
                       ^^^^^^^^^^^^^^^^^^^^^^^^^^^
  File "/opt/hostedtoolcache/Python/3.12.10/x64/lib/python3.12/site-packages/galaxy/tool_util/verify/interactor.py", line 619, in _get_path_or_location
    path = self.test_data_download(
           ^^^^^^^^^^^^^^^^^^^^^^^^
  File "/opt/hostedtoolcache/Python/3.12.10/x64/lib/python3.12/site-packages/galaxy/tool_util/verify/interactor.py", line 525, in test_data_download
    raise AssertionError(f"Test input file ({filename}) cannot be found.")
AssertionError: Test input file (bwa-mem-fastq1.fq) cannot be found.
"><![CDATA[
                { "execution_problem": "Input staging problem: Traceback (most recent call last):\n  File \"/opt/hostedtoolcache/Python/3.12.10/x64/lib/python3.12/site-packages/galaxy/tool_util/verify/interactor.py\", line 1434, in verify_tool\n    stage_data_in_history(\n  File \"/opt/hostedtoolcache/Python/3.12.10/x64/lib/python3.12/site-packages/galaxy/tool_util/verify/interactor.py\", line 163, in stage_data_in_history\n    test_dict = galaxy_interactor.remote_to_input(\n                ^^^^^^^^^^^^^^^^^^^^^^^^^^^^^^^^^^\n  File \"/opt/hostedtoolcache/Python/3.12.10/x64/lib/python3.12/site-packages/galaxy/tool_util/verify/interactor.py\", line 582, in remote_to_input\n    path_or_location = self._get_path_or_location(\n                       ^^^^^^^^^^^^^^^^^^^^^^^^^^^\n  File \"/opt/hostedtoolcache/Python/3.12.10/x64/lib/python3.12/site-packages/galaxy/tool_util/verify/interactor.py\", line 619, in _get_path_or_location\n    path = self.test_data_download(\n           ^^^^^^^^^^^^^^^^^^^^^^^^\n  File \"/opt/hostedtoolcache/Python/3.12.10/x64/lib/python3.12/site-packages/galaxy/tool_util/verify/interactor.py\", line 525, in test_data_download\n    raise AssertionError(f\"Test input file ({filename}) cannot be found.\")\nAssertionError: Test input file (bwa-mem-fastq1.fq) cannot be found.\n", "status": "error", "test_index": 12, "time_seconds": 0.05554485321044922, "tool_id": "fastp", "tool_version": "0.24.0+galaxy3"}
            ]]></error>
        
    </testcase>
    
    <testcase classname="fastp (Test #14)" name="13" time="0.055457353591918945">
        
            <error type="error" message="Input staging problem: Traceback (most recent call last):
  File "/opt/hostedtoolcache/Python/3.12.10/x64/lib/python3.12/site-packages/galaxy/tool_util/verify/interactor.py", line 1434, in verify_tool
    stage_data_in_history(
  File "/opt/hostedtoolcache/Python/3.12.10/x64/lib/python3.12/site-packages/galaxy/tool_util/verify/interactor.py", line 163, in stage_data_in_history
    test_dict = galaxy_interactor.remote_to_input(
                ^^^^^^^^^^^^^^^^^^^^^^^^^^^^^^^^^^
  File "/opt/hostedtoolcache/Python/3.12.10/x64/lib/python3.12/site-packages/galaxy/tool_util/verify/interactor.py", line 582, in remote_to_input
    path_or_location = self._get_path_or_location(
                       ^^^^^^^^^^^^^^^^^^^^^^^^^^^
  File "/opt/hostedtoolcache/Python/3.12.10/x64/lib/python3.12/site-packages/galaxy/tool_util/verify/interactor.py", line 619, in _get_path_or_location
    path = self.test_data_download(
           ^^^^^^^^^^^^^^^^^^^^^^^^
  File "/opt/hostedtoolcache/Python/3.12.10/x64/lib/python3.12/site-packages/galaxy/tool_util/verify/interactor.py", line 525, in test_data_download
    raise AssertionError(f"Test input file ({filename}) cannot be found.")
AssertionError: Test input file (bwa-mem-fastq1.fq) cannot be found.
"><![CDATA[
                { "execution_problem": "Input staging problem: Traceback (most recent call last):\n  File \"/opt/hostedtoolcache/Python/3.12.10/x64/lib/python3.12/site-packages/galaxy/tool_util/verify/interactor.py\", line 1434, in verify_tool\n    stage_data_in_history(\n  File \"/opt/hostedtoolcache/Python/3.12.10/x64/lib/python3.12/site-packages/galaxy/tool_util/verify/interactor.py\", line 163, in stage_data_in_history\n    test_dict = galaxy_interactor.remote_to_input(\n                ^^^^^^^^^^^^^^^^^^^^^^^^^^^^^^^^^^\n  File \"/opt/hostedtoolcache/Python/3.12.10/x64/lib/python3.12/site-packages/galaxy/tool_util/verify/interactor.py\", line 582, in remote_to_input\n    path_or_location = self._get_path_or_location(\n                       ^^^^^^^^^^^^^^^^^^^^^^^^^^^\n  File \"/opt/hostedtoolcache/Python/3.12.10/x64/lib/python3.12/site-packages/galaxy/tool_util/verify/interactor.py\", line 619, in _get_path_or_location\n    path = self.test_data_download(\n           ^^^^^^^^^^^^^^^^^^^^^^^^\n  File \"/opt/hostedtoolcache/Python/3.12.10/x64/lib/python3.12/site-packages/galaxy/tool_util/verify/interactor.py\", line 525, in test_data_download\n    raise AssertionError(f\"Test input file ({filename}) cannot be found.\")\nAssertionError: Test input file (bwa-mem-fastq1.fq) cannot be found.\n", "status": "error", "test_index": 13, "time_seconds": 0.055457353591918945, "tool_id": "fastp", "tool_version": "0.24.0+galaxy3"}
            ]]></error>
        
    </testcase>
    
    <testcase classname="fastp (Test #15)" name="14" time="0.05565929412841797">
        
            <error type="error" message="Input staging problem: Traceback (most recent call last):
  File "/opt/hostedtoolcache/Python/3.12.10/x64/lib/python3.12/site-packages/galaxy/tool_util/verify/interactor.py", line 1434, in verify_tool
    stage_data_in_history(
  File "/opt/hostedtoolcache/Python/3.12.10/x64/lib/python3.12/site-packages/galaxy/tool_util/verify/interactor.py", line 163, in stage_data_in_history
    test_dict = galaxy_interactor.remote_to_input(
                ^^^^^^^^^^^^^^^^^^^^^^^^^^^^^^^^^^
  File "/opt/hostedtoolcache/Python/3.12.10/x64/lib/python3.12/site-packages/galaxy/tool_util/verify/interactor.py", line 582, in remote_to_input
    path_or_location = self._get_path_or_location(
                       ^^^^^^^^^^^^^^^^^^^^^^^^^^^
  File "/opt/hostedtoolcache/Python/3.12.10/x64/lib/python3.12/site-packages/galaxy/tool_util/verify/interactor.py", line 619, in _get_path_or_location
    path = self.test_data_download(
           ^^^^^^^^^^^^^^^^^^^^^^^^
  File "/opt/hostedtoolcache/Python/3.12.10/x64/lib/python3.12/site-packages/galaxy/tool_util/verify/interactor.py", line 525, in test_data_download
    raise AssertionError(f"Test input file ({filename}) cannot be found.")
AssertionError: Test input file (bwa-mem-fastq-paired-collection/input_forward.fastqsanger.gz) cannot be found.
"><![CDATA[
                { "execution_problem": "Input staging problem: Traceback (most recent call last):\n  File \"/opt/hostedtoolcache/Python/3.12.10/x64/lib/python3.12/site-packages/galaxy/tool_util/verify/interactor.py\", line 1434, in verify_tool\n    stage_data_in_history(\n  File \"/opt/hostedtoolcache/Python/3.12.10/x64/lib/python3.12/site-packages/galaxy/tool_util/verify/interactor.py\", line 163, in stage_data_in_history\n    test_dict = galaxy_interactor.remote_to_input(\n                ^^^^^^^^^^^^^^^^^^^^^^^^^^^^^^^^^^\n  File \"/opt/hostedtoolcache/Python/3.12.10/x64/lib/python3.12/site-packages/galaxy/tool_util/verify/interactor.py\", line 582, in remote_to_input\n    path_or_location = self._get_path_or_location(\n                       ^^^^^^^^^^^^^^^^^^^^^^^^^^^\n  File \"/opt/hostedtoolcache/Python/3.12.10/x64/lib/python3.12/site-packages/galaxy/tool_util/verify/interactor.py\", line 619, in _get_path_or_location\n    path = self.test_data_download(\n           ^^^^^^^^^^^^^^^^^^^^^^^^\n  File \"/opt/hostedtoolcache/Python/3.12.10/x64/lib/python3.12/site-packages/galaxy/tool_util/verify/interactor.py\", line 525, in test_data_download\n    raise AssertionError(f\"Test input file ({filename}) cannot be found.\")\nAssertionError: Test input file (bwa-mem-fastq-paired-collection/input_forward.fastqsanger.gz) cannot be found.\n", "status": "error", "test_index": 14, "time_seconds": 0.05565929412841797, "tool_id": "fastp", "tool_version": "0.24.0+galaxy3"}
            ]]></error>
        
    </testcase>
    
    <testcase classname="fastp (Test #3)" name="2" time="0.05559277534484863">
        
            <error type="error" message="Input staging problem: Traceback (most recent call last):
  File "/opt/hostedtoolcache/Python/3.12.10/x64/lib/python3.12/site-packages/galaxy/tool_util/verify/interactor.py", line 1434, in verify_tool
    stage_data_in_history(
  File "/opt/hostedtoolcache/Python/3.12.10/x64/lib/python3.12/site-packages/galaxy/tool_util/verify/interactor.py", line 163, in stage_data_in_history
    test_dict = galaxy_interactor.remote_to_input(
                ^^^^^^^^^^^^^^^^^^^^^^^^^^^^^^^^^^
  File "/opt/hostedtoolcache/Python/3.12.10/x64/lib/python3.12/site-packages/galaxy/tool_util/verify/interactor.py", line 582, in remote_to_input
    path_or_location = self._get_path_or_location(
                       ^^^^^^^^^^^^^^^^^^^^^^^^^^^
  File "/opt/hostedtoolcache/Python/3.12.10/x64/lib/python3.12/site-packages/galaxy/tool_util/verify/interactor.py", line 619, in _get_path_or_location
    path = self.test_data_download(
           ^^^^^^^^^^^^^^^^^^^^^^^^
  File "/opt/hostedtoolcache/Python/3.12.10/x64/lib/python3.12/site-packages/galaxy/tool_util/verify/interactor.py", line 525, in test_data_download
    raise AssertionError(f"Test input file ({filename}) cannot be found.")
AssertionError: Test input file (R1.fq) cannot be found.
"><![CDATA[
                { "execution_problem": "Input staging problem: Traceback (most recent call last):\n  File \"/opt/hostedtoolcache/Python/3.12.10/x64/lib/python3.12/site-packages/galaxy/tool_util/verify/interactor.py\", line 1434, in verify_tool\n    stage_data_in_history(\n  File \"/opt/hostedtoolcache/Python/3.12.10/x64/lib/python3.12/site-packages/galaxy/tool_util/verify/interactor.py\", line 163, in stage_data_in_history\n    test_dict = galaxy_interactor.remote_to_input(\n                ^^^^^^^^^^^^^^^^^^^^^^^^^^^^^^^^^^\n  File \"/opt/hostedtoolcache/Python/3.12.10/x64/lib/python3.12/site-packages/galaxy/tool_util/verify/interactor.py\", line 582, in remote_to_input\n    path_or_location = self._get_path_or_location(\n                       ^^^^^^^^^^^^^^^^^^^^^^^^^^^\n  File \"/opt/hostedtoolcache/Python/3.12.10/x64/lib/python3.12/site-packages/galaxy/tool_util/verify/interactor.py\", line 619, in _get_path_or_location\n    path = self.test_data_download(\n           ^^^^^^^^^^^^^^^^^^^^^^^^\n  File \"/opt/hostedtoolcache/Python/3.12.10/x64/lib/python3.12/site-packages/galaxy/tool_util/verify/interactor.py\", line 525, in test_data_download\n    raise AssertionError(f\"Test input file ({filename}) cannot be found.\")\nAssertionError: Test input file (R1.fq) cannot be found.\n", "status": "error", "test_index": 2, "time_seconds": 0.05559277534484863, "tool_id": "fastp", "tool_version": "0.24.0+galaxy3"}
            ]]></error>
        
    </testcase>
    
    <testcase classname="fastp (Test #4)" name="3" time="0.055364131927490234">
        
            <error type="error" message="Input staging problem: Traceback (most recent call last):
  File "/opt/hostedtoolcache/Python/3.12.10/x64/lib/python3.12/site-packages/galaxy/tool_util/verify/interactor.py", line 1434, in verify_tool
    stage_data_in_history(
  File "/opt/hostedtoolcache/Python/3.12.10/x64/lib/python3.12/site-packages/galaxy/tool_util/verify/interactor.py", line 163, in stage_data_in_history
    test_dict = galaxy_interactor.remote_to_input(
                ^^^^^^^^^^^^^^^^^^^^^^^^^^^^^^^^^^
  File "/opt/hostedtoolcache/Python/3.12.10/x64/lib/python3.12/site-packages/galaxy/tool_util/verify/interactor.py", line 582, in remote_to_input
    path_or_location = self._get_path_or_location(
                       ^^^^^^^^^^^^^^^^^^^^^^^^^^^
  File "/opt/hostedtoolcache/Python/3.12.10/x64/lib/python3.12/site-packages/galaxy/tool_util/verify/interactor.py", line 619, in _get_path_or_location
    path = self.test_data_download(
           ^^^^^^^^^^^^^^^^^^^^^^^^
  File "/opt/hostedtoolcache/Python/3.12.10/x64/lib/python3.12/site-packages/galaxy/tool_util/verify/interactor.py", line 525, in test_data_download
    raise AssertionError(f"Test input file ({filename}) cannot be found.")
AssertionError: Test input file (R1.fq) cannot be found.
"><![CDATA[
                { "execution_problem": "Input staging problem: Traceback (most recent call last):\n  File \"/opt/hostedtoolcache/Python/3.12.10/x64/lib/python3.12/site-packages/galaxy/tool_util/verify/interactor.py\", line 1434, in verify_tool\n    stage_data_in_history(\n  File \"/opt/hostedtoolcache/Python/3.12.10/x64/lib/python3.12/site-packages/galaxy/tool_util/verify/interactor.py\", line 163, in stage_data_in_history\n    test_dict = galaxy_interactor.remote_to_input(\n                ^^^^^^^^^^^^^^^^^^^^^^^^^^^^^^^^^^\n  File \"/opt/hostedtoolcache/Python/3.12.10/x64/lib/python3.12/site-packages/galaxy/tool_util/verify/interactor.py\", line 582, in remote_to_input\n    path_or_location = self._get_path_or_location(\n                       ^^^^^^^^^^^^^^^^^^^^^^^^^^^\n  File \"/opt/hostedtoolcache/Python/3.12.10/x64/lib/python3.12/site-packages/galaxy/tool_util/verify/interactor.py\", line 619, in _get_path_or_location\n    path = self.test_data_download(\n           ^^^^^^^^^^^^^^^^^^^^^^^^\n  File \"/opt/hostedtoolcache/Python/3.12.10/x64/lib/python3.12/site-packages/galaxy/tool_util/verify/interactor.py\", line 525, in test_data_download\n    raise AssertionError(f\"Test input file ({filename}) cannot be found.\")\nAssertionError: Test input file (R1.fq) cannot be found.\n", "status": "error", "test_index": 3, "time_seconds": 0.055364131927490234, "tool_id": "fastp", "tool_version": "0.24.0+galaxy3"}
            ]]></error>
        
    </testcase>
    
    <testcase classname="fastp (Test #5)" name="4" time="0.05301713943481445">
        
            <error type="error" message="Input staging problem: Traceback (most recent call last):
  File "/opt/hostedtoolcache/Python/3.12.10/x64/lib/python3.12/site-packages/galaxy/tool_util/verify/interactor.py", line 1434, in verify_tool
    stage_data_in_history(
  File "/opt/hostedtoolcache/Python/3.12.10/x64/lib/python3.12/site-packages/galaxy/tool_util/verify/interactor.py", line 163, in stage_data_in_history
    test_dict = galaxy_interactor.remote_to_input(
                ^^^^^^^^^^^^^^^^^^^^^^^^^^^^^^^^^^
  File "/opt/hostedtoolcache/Python/3.12.10/x64/lib/python3.12/site-packages/galaxy/tool_util/verify/interactor.py", line 582, in remote_to_input
    path_or_location = self._get_path_or_location(
                       ^^^^^^^^^^^^^^^^^^^^^^^^^^^
  File "/opt/hostedtoolcache/Python/3.12.10/x64/lib/python3.12/site-packages/galaxy/tool_util/verify/interactor.py", line 619, in _get_path_or_location
    path = self.test_data_download(
           ^^^^^^^^^^^^^^^^^^^^^^^^
  File "/opt/hostedtoolcache/Python/3.12.10/x64/lib/python3.12/site-packages/galaxy/tool_util/verify/interactor.py", line 525, in test_data_download
    raise AssertionError(f"Test input file ({filename}) cannot be found.")
AssertionError: Test input file (R1.fq) cannot be found.
"><![CDATA[
                { "execution_problem": "Input staging problem: Traceback (most recent call last):\n  File \"/opt/hostedtoolcache/Python/3.12.10/x64/lib/python3.12/site-packages/galaxy/tool_util/verify/interactor.py\", line 1434, in verify_tool\n    stage_data_in_history(\n  File \"/opt/hostedtoolcache/Python/3.12.10/x64/lib/python3.12/site-packages/galaxy/tool_util/verify/interactor.py\", line 163, in stage_data_in_history\n    test_dict = galaxy_interactor.remote_to_input(\n                ^^^^^^^^^^^^^^^^^^^^^^^^^^^^^^^^^^\n  File \"/opt/hostedtoolcache/Python/3.12.10/x64/lib/python3.12/site-packages/galaxy/tool_util/verify/interactor.py\", line 582, in remote_to_input\n    path_or_location = self._get_path_or_location(\n                       ^^^^^^^^^^^^^^^^^^^^^^^^^^^\n  File \"/opt/hostedtoolcache/Python/3.12.10/x64/lib/python3.12/site-packages/galaxy/tool_util/verify/interactor.py\", line 619, in _get_path_or_location\n    path = self.test_data_download(\n           ^^^^^^^^^^^^^^^^^^^^^^^^\n  File \"/opt/hostedtoolcache/Python/3.12.10/x64/lib/python3.12/site-packages/galaxy/tool_util/verify/interactor.py\", line 525, in test_data_download\n    raise AssertionError(f\"Test input file ({filename}) cannot be found.\")\nAssertionError: Test input file (R1.fq) cannot be found.\n", "status": "error", "test_index": 4, "time_seconds": 0.05301713943481445, "tool_id": "fastp", "tool_version": "0.24.0+galaxy3"}
            ]]></error>
        
    </testcase>
    
    <testcase classname="fastp (Test #6)" name="5" time="0.055225372314453125">
        
            <error type="error" message="Input staging problem: Traceback (most recent call last):
  File "/opt/hostedtoolcache/Python/3.12.10/x64/lib/python3.12/site-packages/galaxy/tool_util/verify/interactor.py", line 1434, in verify_tool
    stage_data_in_history(
  File "/opt/hostedtoolcache/Python/3.12.10/x64/lib/python3.12/site-packages/galaxy/tool_util/verify/interactor.py", line 163, in stage_data_in_history
    test_dict = galaxy_interactor.remote_to_input(
                ^^^^^^^^^^^^^^^^^^^^^^^^^^^^^^^^^^
  File "/opt/hostedtoolcache/Python/3.12.10/x64/lib/python3.12/site-packages/galaxy/tool_util/verify/interactor.py", line 582, in remote_to_input
    path_or_location = self._get_path_or_location(
                       ^^^^^^^^^^^^^^^^^^^^^^^^^^^
  File "/opt/hostedtoolcache/Python/3.12.10/x64/lib/python3.12/site-packages/galaxy/tool_util/verify/interactor.py", line 619, in _get_path_or_location
    path = self.test_data_download(
           ^^^^^^^^^^^^^^^^^^^^^^^^
  File "/opt/hostedtoolcache/Python/3.12.10/x64/lib/python3.12/site-packages/galaxy/tool_util/verify/interactor.py", line 525, in test_data_download
    raise AssertionError(f"Test input file ({filename}) cannot be found.")
AssertionError: Test input file (bwa-mem-fastq1.fq) cannot be found.
"><![CDATA[
                { "execution_problem": "Input staging problem: Traceback (most recent call last):\n  File \"/opt/hostedtoolcache/Python/3.12.10/x64/lib/python3.12/site-packages/galaxy/tool_util/verify/interactor.py\", line 1434, in verify_tool\n    stage_data_in_history(\n  File \"/opt/hostedtoolcache/Python/3.12.10/x64/lib/python3.12/site-packages/galaxy/tool_util/verify/interactor.py\", line 163, in stage_data_in_history\n    test_dict = galaxy_interactor.remote_to_input(\n                ^^^^^^^^^^^^^^^^^^^^^^^^^^^^^^^^^^\n  File \"/opt/hostedtoolcache/Python/3.12.10/x64/lib/python3.12/site-packages/galaxy/tool_util/verify/interactor.py\", line 582, in remote_to_input\n    path_or_location = self._get_path_or_location(\n                       ^^^^^^^^^^^^^^^^^^^^^^^^^^^\n  File \"/opt/hostedtoolcache/Python/3.12.10/x64/lib/python3.12/site-packages/galaxy/tool_util/verify/interactor.py\", line 619, in _get_path_or_location\n    path = self.test_data_download(\n           ^^^^^^^^^^^^^^^^^^^^^^^^\n  File \"/opt/hostedtoolcache/Python/3.12.10/x64/lib/python3.12/site-packages/galaxy/tool_util/verify/interactor.py\", line 525, in test_data_download\n    raise AssertionError(f\"Test input file ({filename}) cannot be found.\")\nAssertionError: Test input file (bwa-mem-fastq1.fq) cannot be found.\n", "status": "error", "test_index": 5, "time_seconds": 0.055225372314453125, "tool_id": "fastp", "tool_version": "0.24.0+galaxy3"}
            ]]></error>
        
    </testcase>
    
    <testcase classname="fastp (Test #7)" name="6" time="0.055060386657714844">
        
            <error type="error" message="Input staging problem: Traceback (most recent call last):
  File "/opt/hostedtoolcache/Python/3.12.10/x64/lib/python3.12/site-packages/galaxy/tool_util/verify/interactor.py", line 1434, in verify_tool
    stage_data_in_history(
  File "/opt/hostedtoolcache/Python/3.12.10/x64/lib/python3.12/site-packages/galaxy/tool_util/verify/interactor.py", line 163, in stage_data_in_history
    test_dict = galaxy_interactor.remote_to_input(
                ^^^^^^^^^^^^^^^^^^^^^^^^^^^^^^^^^^
  File "/opt/hostedtoolcache/Python/3.12.10/x64/lib/python3.12/site-packages/galaxy/tool_util/verify/interactor.py", line 582, in remote_to_input
    path_or_location = self._get_path_or_location(
                       ^^^^^^^^^^^^^^^^^^^^^^^^^^^
  File "/opt/hostedtoolcache/Python/3.12.10/x64/lib/python3.12/site-packages/galaxy/tool_util/verify/interactor.py", line 619, in _get_path_or_location
    path = self.test_data_download(
           ^^^^^^^^^^^^^^^^^^^^^^^^
  File "/opt/hostedtoolcache/Python/3.12.10/x64/lib/python3.12/site-packages/galaxy/tool_util/verify/interactor.py", line 525, in test_data_download
    raise AssertionError(f"Test input file ({filename}) cannot be found.")
AssertionError: Test input file (bwa-mem-fastq1.fq) cannot be found.
"><![CDATA[
                { "execution_problem": "Input staging problem: Traceback (most recent call last):\n  File \"/opt/hostedtoolcache/Python/3.12.10/x64/lib/python3.12/site-packages/galaxy/tool_util/verify/interactor.py\", line 1434, in verify_tool\n    stage_data_in_history(\n  File \"/opt/hostedtoolcache/Python/3.12.10/x64/lib/python3.12/site-packages/galaxy/tool_util/verify/interactor.py\", line 163, in stage_data_in_history\n    test_dict = galaxy_interactor.remote_to_input(\n                ^^^^^^^^^^^^^^^^^^^^^^^^^^^^^^^^^^\n  File \"/opt/hostedtoolcache/Python/3.12.10/x64/lib/python3.12/site-packages/galaxy/tool_util/verify/interactor.py\", line 582, in remote_to_input\n    path_or_location = self._get_path_or_location(\n                       ^^^^^^^^^^^^^^^^^^^^^^^^^^^\n  File \"/opt/hostedtoolcache/Python/3.12.10/x64/lib/python3.12/site-packages/galaxy/tool_util/verify/interactor.py\", line 619, in _get_path_or_location\n    path = self.test_data_download(\n           ^^^^^^^^^^^^^^^^^^^^^^^^\n  File \"/opt/hostedtoolcache/Python/3.12.10/x64/lib/python3.12/site-packages/galaxy/tool_util/verify/interactor.py\", line 525, in test_data_download\n    raise AssertionError(f\"Test input file ({filename}) cannot be found.\")\nAssertionError: Test input file (bwa-mem-fastq1.fq) cannot be found.\n", "status": "error", "test_index": 6, "time_seconds": 0.055060386657714844, "tool_id": "fastp", "tool_version": "0.24.0+galaxy3"}
            ]]></error>
        
    </testcase>
    
    <testcase classname="fastp (Test #8)" name="7" time="0.053662776947021484">
        
            <error type="error" message="Input staging problem: Traceback (most recent call last):
  File "/opt/hostedtoolcache/Python/3.12.10/x64/lib/python3.12/site-packages/galaxy/tool_util/verify/interactor.py", line 1434, in verify_tool
    stage_data_in_history(
  File "/opt/hostedtoolcache/Python/3.12.10/x64/lib/python3.12/site-packages/galaxy/tool_util/verify/interactor.py", line 163, in stage_data_in_history
    test_dict = galaxy_interactor.remote_to_input(
                ^^^^^^^^^^^^^^^^^^^^^^^^^^^^^^^^^^
  File "/opt/hostedtoolcache/Python/3.12.10/x64/lib/python3.12/site-packages/galaxy/tool_util/verify/interactor.py", line 582, in remote_to_input
    path_or_location = self._get_path_or_location(
                       ^^^^^^^^^^^^^^^^^^^^^^^^^^^
  File "/opt/hostedtoolcache/Python/3.12.10/x64/lib/python3.12/site-packages/galaxy/tool_util/verify/interactor.py", line 619, in _get_path_or_location
    path = self.test_data_download(
           ^^^^^^^^^^^^^^^^^^^^^^^^
  File "/opt/hostedtoolcache/Python/3.12.10/x64/lib/python3.12/site-packages/galaxy/tool_util/verify/interactor.py", line 525, in test_data_download
    raise AssertionError(f"Test input file ({filename}) cannot be found.")
AssertionError: Test input file (bwa-mem-fastq1.fq) cannot be found.
"><![CDATA[
                { "execution_problem": "Input staging problem: Traceback (most recent call last):\n  File \"/opt/hostedtoolcache/Python/3.12.10/x64/lib/python3.12/site-packages/galaxy/tool_util/verify/interactor.py\", line 1434, in verify_tool\n    stage_data_in_history(\n  File \"/opt/hostedtoolcache/Python/3.12.10/x64/lib/python3.12/site-packages/galaxy/tool_util/verify/interactor.py\", line 163, in stage_data_in_history\n    test_dict = galaxy_interactor.remote_to_input(\n                ^^^^^^^^^^^^^^^^^^^^^^^^^^^^^^^^^^\n  File \"/opt/hostedtoolcache/Python/3.12.10/x64/lib/python3.12/site-packages/galaxy/tool_util/verify/interactor.py\", line 582, in remote_to_input\n    path_or_location = self._get_path_or_location(\n                       ^^^^^^^^^^^^^^^^^^^^^^^^^^^\n  File \"/opt/hostedtoolcache/Python/3.12.10/x64/lib/python3.12/site-packages/galaxy/tool_util/verify/interactor.py\", line 619, in _get_path_or_location\n    path = self.test_data_download(\n           ^^^^^^^^^^^^^^^^^^^^^^^^\n  File \"/opt/hostedtoolcache/Python/3.12.10/x64/lib/python3.12/site-packages/galaxy/tool_util/verify/interactor.py\", line 525, in test_data_download\n    raise AssertionError(f\"Test input file ({filename}) cannot be found.\")\nAssertionError: Test input file (bwa-mem-fastq1.fq) cannot be found.\n", "status": "error", "test_index": 7, "time_seconds": 0.053662776947021484, "tool_id": "fastp", "tool_version": "0.24.0+galaxy3"}
            ]]></error>
        
    </testcase>
    
    <testcase classname="fastp (Test #9)" name="8" time="0.055571556091308594">
        
            <error type="error" message="Input staging problem: Traceback (most recent call last):
  File "/opt/hostedtoolcache/Python/3.12.10/x64/lib/python3.12/site-packages/galaxy/tool_util/verify/interactor.py", line 1434, in verify_tool
    stage_data_in_history(
  File "/opt/hostedtoolcache/Python/3.12.10/x64/lib/python3.12/site-packages/galaxy/tool_util/verify/interactor.py", line 163, in stage_data_in_history
    test_dict = galaxy_interactor.remote_to_input(
                ^^^^^^^^^^^^^^^^^^^^^^^^^^^^^^^^^^
  File "/opt/hostedtoolcache/Python/3.12.10/x64/lib/python3.12/site-packages/galaxy/tool_util/verify/interactor.py", line 582, in remote_to_input
    path_or_location = self._get_path_or_location(
                       ^^^^^^^^^^^^^^^^^^^^^^^^^^^
  File "/opt/hostedtoolcache/Python/3.12.10/x64/lib/python3.12/site-packages/galaxy/tool_util/verify/interactor.py", line 619, in _get_path_or_location
    path = self.test_data_download(
           ^^^^^^^^^^^^^^^^^^^^^^^^
  File "/opt/hostedtoolcache/Python/3.12.10/x64/lib/python3.12/site-packages/galaxy/tool_util/verify/interactor.py", line 525, in test_data_download
    raise AssertionError(f"Test input file ({filename}) cannot be found.")
AssertionError: Test input file (R1.fq) cannot be found.
"><![CDATA[
                { "execution_problem": "Input staging problem: Traceback (most recent call last):\n  File \"/opt/hostedtoolcache/Python/3.12.10/x64/lib/python3.12/site-packages/galaxy/tool_util/verify/interactor.py\", line 1434, in verify_tool\n    stage_data_in_history(\n  File \"/opt/hostedtoolcache/Python/3.12.10/x64/lib/python3.12/site-packages/galaxy/tool_util/verify/interactor.py\", line 163, in stage_data_in_history\n    test_dict = galaxy_interactor.remote_to_input(\n                ^^^^^^^^^^^^^^^^^^^^^^^^^^^^^^^^^^\n  File \"/opt/hostedtoolcache/Python/3.12.10/x64/lib/python3.12/site-packages/galaxy/tool_util/verify/interactor.py\", line 582, in remote_to_input\n    path_or_location = self._get_path_or_location(\n                       ^^^^^^^^^^^^^^^^^^^^^^^^^^^\n  File \"/opt/hostedtoolcache/Python/3.12.10/x64/lib/python3.12/site-packages/galaxy/tool_util/verify/interactor.py\", line 619, in _get_path_or_location\n    path = self.test_data_download(\n           ^^^^^^^^^^^^^^^^^^^^^^^^\n  File \"/opt/hostedtoolcache/Python/3.12.10/x64/lib/python3.12/site-packages/galaxy/tool_util/verify/interactor.py\", line 525, in test_data_download\n    raise AssertionError(f\"Test input file ({filename}) cannot be found.\")\nAssertionError: Test input file (R1.fq) cannot be found.\n", "status": "error", "test_index": 8, "time_seconds": 0.055571556091308594, "tool_id": "fastp", "tool_version": "0.24.0+galaxy3"}
            ]]></error>
        
    </testcase>
    
    <testcase classname="fastp (Test #10)" name="9" time="0.054073333740234375">
        
            <error type="error" message="Input staging problem: Traceback (most recent call last):
  File "/opt/hostedtoolcache/Python/3.12.10/x64/lib/python3.12/site-packages/galaxy/tool_util/verify/interactor.py", line 1434, in verify_tool
    stage_data_in_history(
  File "/opt/hostedtoolcache/Python/3.12.10/x64/lib/python3.12/site-packages/galaxy/tool_util/verify/interactor.py", line 163, in stage_data_in_history
    test_dict = galaxy_interactor.remote_to_input(
                ^^^^^^^^^^^^^^^^^^^^^^^^^^^^^^^^^^
  File "/opt/hostedtoolcache/Python/3.12.10/x64/lib/python3.12/site-packages/galaxy/tool_util/verify/interactor.py", line 582, in remote_to_input
    path_or_location = self._get_path_or_location(
                       ^^^^^^^^^^^^^^^^^^^^^^^^^^^
  File "/opt/hostedtoolcache/Python/3.12.10/x64/lib/python3.12/site-packages/galaxy/tool_util/verify/interactor.py", line 619, in _get_path_or_location
    path = self.test_data_download(
           ^^^^^^^^^^^^^^^^^^^^^^^^
  File "/opt/hostedtoolcache/Python/3.12.10/x64/lib/python3.12/site-packages/galaxy/tool_util/verify/interactor.py", line 525, in test_data_download
    raise AssertionError(f"Test input file ({filename}) cannot be found.")
AssertionError: Test input file (R1.fq.gz) cannot be found.
"><![CDATA[
                { "execution_problem": "Input staging problem: Traceback (most recent call last):\n  File \"/opt/hostedtoolcache/Python/3.12.10/x64/lib/python3.12/site-packages/galaxy/tool_util/verify/interactor.py\", line 1434, in verify_tool\n    stage_data_in_history(\n  File \"/opt/hostedtoolcache/Python/3.12.10/x64/lib/python3.12/site-packages/galaxy/tool_util/verify/interactor.py\", line 163, in stage_data_in_history\n    test_dict = galaxy_interactor.remote_to_input(\n                ^^^^^^^^^^^^^^^^^^^^^^^^^^^^^^^^^^\n  File \"/opt/hostedtoolcache/Python/3.12.10/x64/lib/python3.12/site-packages/galaxy/tool_util/verify/interactor.py\", line 582, in remote_to_input\n    path_or_location = self._get_path_or_location(\n                       ^^^^^^^^^^^^^^^^^^^^^^^^^^^\n  File \"/opt/hostedtoolcache/Python/3.12.10/x64/lib/python3.12/site-packages/galaxy/tool_util/verify/interactor.py\", line 619, in _get_path_or_location\n    path = self.test_data_download(\n           ^^^^^^^^^^^^^^^^^^^^^^^^\n  File \"/opt/hostedtoolcache/Python/3.12.10/x64/lib/python3.12/site-packages/galaxy/tool_util/verify/interactor.py\", line 525, in test_data_download\n    raise AssertionError(f\"Test input file ({filename}) cannot be found.\")\nAssertionError: Test input file (R1.fq.gz) cannot be found.\n", "status": "error", "test_index": 9, "time_seconds": 0.054073333740234375, "tool_id": "fastp", "tool_version": "0.24.0+galaxy3"}
            ]]></error>
        
    </testcase>
    
    <testcase classname="ivar_variants (Test #1)" name="0" time="50.92310094833374">
        
            
            <system-out><![CDATA[
            A GFF file containing the open reading frames (ORFs) has not been provided. Amino acid translation will not be done.A reference sequence has not been supplied. Amino acid translation will not be done.
            ]]></system-out>
            <system-err><![CDATA[
            [mpileup] 1 samples in 1 input files[mpileup] Max depth set to maximum value (2147483647)
            ]]></system-err>
        
    </testcase>
    
    <testcase classname="ivar_variants (Test #2)" name="1" time="19.050797939300537">
        
            <error type="error" message="Input staging problem: Traceback (most recent call last):
  File "/opt/hostedtoolcache/Python/3.12.10/x64/lib/python3.12/site-packages/galaxy/tool_util/verify/interactor.py", line 1434, in verify_tool
    stage_data_in_history(
  File "/opt/hostedtoolcache/Python/3.12.10/x64/lib/python3.12/site-packages/galaxy/tool_util/verify/interactor.py", line 175, in stage_data_in_history
    staging_interface.handle_jobs()
  File "/opt/hostedtoolcache/Python/3.12.10/x64/lib/python3.12/site-packages/galaxy/tool_util/verify/interactor.py", line 212, in handle_jobs
    self.galaxy_interactor.wait_for_job(job_response["id"], job_response["history_id"], self.maxseconds)
  File "/opt/hostedtoolcache/Python/3.12.10/x64/lib/python3.12/site-packages/galaxy/tool_util/verify/interactor.py", line 399, in wait_for_job
    self.wait_for(lambda: self.__job_ready(job_id, history_id), maxseconds=maxseconds)
  File "/opt/hostedtoolcache/Python/3.12.10/x64/lib/python3.12/site-packages/galaxy/tool_util/verify/interactor.py", line 403, in wait_for
    wait_on(func, what, walltime_exceeded)
  File "/opt/hostedtoolcache/Python/3.12.10/x64/lib/python3.12/site-packages/galaxy/tool_util/verify/wait.py", line 38, in wait_on
    value = function()
            ^^^^^^^^^^
  File "/opt/hostedtoolcache/Python/3.12.10/x64/lib/python3.12/site-packages/galaxy/tool_util/verify/interactor.py", line 399, in <lambda>
    self.wait_for(lambda: self.__job_ready(job_id, history_id), maxseconds=maxseconds)
                          ^^^^^^^^^^^^^^^^^^^^^^^^^^^^^^^^^^^^
  File "/opt/hostedtoolcache/Python/3.12.10/x64/lib/python3.12/site-packages/galaxy/tool_util/verify/interactor.py", line 747, in __job_ready
    return self._state_ready(job_id, error_msg="Job in error state.")
           ^^^^^^^^^^^^^^^^^^^^^^^^^^^^^^^^^^^^^^^^^^^^^^^^^^^^^^^^^^
  File "/opt/hostedtoolcache/Python/3.12.10/x64/lib/python3.12/site-packages/galaxy/tool_util/verify/interactor.py", line 839, in _state_ready
    raise Exception(
Exception: Job in error state.. tool_id: __DATA_FETCH__, exit_code: None, stderr: .
"><![CDATA[
                { "execution_problem": "Input staging problem: Traceback (most recent call last):\n  File \"/opt/hostedtoolcache/Python/3.12.10/x64/lib/python3.12/site-packages/galaxy/tool_util/verify/interactor.py\", line 1434, in verify_tool\n    stage_data_in_history(\n  File \"/opt/hostedtoolcache/Python/3.12.10/x64/lib/python3.12/site-packages/galaxy/tool_util/verify/interactor.py\", line 175, in stage_data_in_history\n    staging_interface.handle_jobs()\n  File \"/opt/hostedtoolcache/Python/3.12.10/x64/lib/python3.12/site-packages/galaxy/tool_util/verify/interactor.py\", line 212, in handle_jobs\n    self.galaxy_interactor.wait_for_job(job_response[\"id\"], job_response[\"history_id\"], self.maxseconds)\n  File \"/opt/hostedtoolcache/Python/3.12.10/x64/lib/python3.12/site-packages/galaxy/tool_util/verify/interactor.py\", line 399, in wait_for_job\n    self.wait_for(lambda: self.__job_ready(job_id, history_id), maxseconds=maxseconds)\n  File \"/opt/hostedtoolcache/Python/3.12.10/x64/lib/python3.12/site-packages/galaxy/tool_util/verify/interactor.py\", line 403, in wait_for\n    wait_on(func, what, walltime_exceeded)\n  File \"/opt/hostedtoolcache/Python/3.12.10/x64/lib/python3.12/site-packages/galaxy/tool_util/verify/wait.py\", line 38, in wait_on\n    value = function()\n            ^^^^^^^^^^\n  File \"/opt/hostedtoolcache/Python/3.12.10/x64/lib/python3.12/site-packages/galaxy/tool_util/verify/interactor.py\", line 399, in \u003clambda\u003e\n    self.wait_for(lambda: self.__job_ready(job_id, history_id), maxseconds=maxseconds)\n                          ^^^^^^^^^^^^^^^^^^^^^^^^^^^^^^^^^^^^\n  File \"/opt/hostedtoolcache/Python/3.12.10/x64/lib/python3.12/site-packages/galaxy/tool_util/verify/interactor.py\", line 747, in __job_ready\n    return self._state_ready(job_id, error_msg=\"Job in error state.\")\n           ^^^^^^^^^^^^^^^^^^^^^^^^^^^^^^^^^^^^^^^^^^^^^^^^^^^^^^^^^^\n  File \"/opt/hostedtoolcache/Python/3.12.10/x64/lib/python3.12/site-packages/galaxy/tool_util/verify/interactor.py\", line 839, in _state_ready\n    raise Exception(\nException: Job in error state.. tool_id: __DATA_FETCH__, exit_code: None, stderr: .\n", "status": "error", "test_index": 1, "time_seconds": 19.050797939300537, "tool_id": "ivar_variants", "tool_version": "1.4.3+galaxy1"}
            ]]></error>
        
    </testcase>
    
    <testcase classname="ivar_variants (Test #3)" name="2" time="35.23093342781067">
        
            
            <system-out><![CDATA[
            A GFF file containing the open reading frames (ORFs) has not been provided. Amino acid translation will not be done.A reference sequence has not been supplied. Amino acid translation will not be done.sampleDELINSSNPvariants0010
            ]]></system-out>
            <system-err><![CDATA[
            [mpileup] 1 samples in 1 input files[mpileup] Max depth set to maximum value (2147483647)
            ]]></system-err>
        
    </testcase>
    
    <testcase classname="ivar_variants (Test #4)" name="3" time="21.54085373878479">
        
            <error type="error" message="Input staging problem: Traceback (most recent call last):
  File "/opt/hostedtoolcache/Python/3.12.10/x64/lib/python3.12/site-packages/galaxy/tool_util/verify/interactor.py", line 1434, in verify_tool
    stage_data_in_history(
  File "/opt/hostedtoolcache/Python/3.12.10/x64/lib/python3.12/site-packages/galaxy/tool_util/verify/interactor.py", line 175, in stage_data_in_history
    staging_interface.handle_jobs()
  File "/opt/hostedtoolcache/Python/3.12.10/x64/lib/python3.12/site-packages/galaxy/tool_util/verify/interactor.py", line 212, in handle_jobs
    self.galaxy_interactor.wait_for_job(job_response["id"], job_response["history_id"], self.maxseconds)
  File "/opt/hostedtoolcache/Python/3.12.10/x64/lib/python3.12/site-packages/galaxy/tool_util/verify/interactor.py", line 399, in wait_for_job
    self.wait_for(lambda: self.__job_ready(job_id, history_id), maxseconds=maxseconds)
  File "/opt/hostedtoolcache/Python/3.12.10/x64/lib/python3.12/site-packages/galaxy/tool_util/verify/interactor.py", line 403, in wait_for
    wait_on(func, what, walltime_exceeded)
  File "/opt/hostedtoolcache/Python/3.12.10/x64/lib/python3.12/site-packages/galaxy/tool_util/verify/wait.py", line 38, in wait_on
    value = function()
            ^^^^^^^^^^
  File "/opt/hostedtoolcache/Python/3.12.10/x64/lib/python3.12/site-packages/galaxy/tool_util/verify/interactor.py", line 399, in <lambda>
    self.wait_for(lambda: self.__job_ready(job_id, history_id), maxseconds=maxseconds)
                          ^^^^^^^^^^^^^^^^^^^^^^^^^^^^^^^^^^^^
  File "/opt/hostedtoolcache/Python/3.12.10/x64/lib/python3.12/site-packages/galaxy/tool_util/verify/interactor.py", line 747, in __job_ready
    return self._state_ready(job_id, error_msg="Job in error state.")
           ^^^^^^^^^^^^^^^^^^^^^^^^^^^^^^^^^^^^^^^^^^^^^^^^^^^^^^^^^^
  File "/opt/hostedtoolcache/Python/3.12.10/x64/lib/python3.12/site-packages/galaxy/tool_util/verify/interactor.py", line 839, in _state_ready
    raise Exception(
Exception: Job in error state.. tool_id: __DATA_FETCH__, exit_code: None, stderr: .
"><![CDATA[
                { "execution_problem": "Input staging problem: Traceback (most recent call last):\n  File \"/opt/hostedtoolcache/Python/3.12.10/x64/lib/python3.12/site-packages/galaxy/tool_util/verify/interactor.py\", line 1434, in verify_tool\n    stage_data_in_history(\n  File \"/opt/hostedtoolcache/Python/3.12.10/x64/lib/python3.12/site-packages/galaxy/tool_util/verify/interactor.py\", line 175, in stage_data_in_history\n    staging_interface.handle_jobs()\n  File \"/opt/hostedtoolcache/Python/3.12.10/x64/lib/python3.12/site-packages/galaxy/tool_util/verify/interactor.py\", line 212, in handle_jobs\n    self.galaxy_interactor.wait_for_job(job_response[\"id\"], job_response[\"history_id\"], self.maxseconds)\n  File \"/opt/hostedtoolcache/Python/3.12.10/x64/lib/python3.12/site-packages/galaxy/tool_util/verify/interactor.py\", line 399, in wait_for_job\n    self.wait_for(lambda: self.__job_ready(job_id, history_id), maxseconds=maxseconds)\n  File \"/opt/hostedtoolcache/Python/3.12.10/x64/lib/python3.12/site-packages/galaxy/tool_util/verify/interactor.py\", line 403, in wait_for\n    wait_on(func, what, walltime_exceeded)\n  File \"/opt/hostedtoolcache/Python/3.12.10/x64/lib/python3.12/site-packages/galaxy/tool_util/verify/wait.py\", line 38, in wait_on\n    value = function()\n            ^^^^^^^^^^\n  File \"/opt/hostedtoolcache/Python/3.12.10/x64/lib/python3.12/site-packages/galaxy/tool_util/verify/interactor.py\", line 399, in \u003clambda\u003e\n    self.wait_for(lambda: self.__job_ready(job_id, history_id), maxseconds=maxseconds)\n                          ^^^^^^^^^^^^^^^^^^^^^^^^^^^^^^^^^^^^\n  File \"/opt/hostedtoolcache/Python/3.12.10/x64/lib/python3.12/site-packages/galaxy/tool_util/verify/interactor.py\", line 747, in __job_ready\n    return self._state_ready(job_id, error_msg=\"Job in error state.\")\n           ^^^^^^^^^^^^^^^^^^^^^^^^^^^^^^^^^^^^^^^^^^^^^^^^^^^^^^^^^^\n  File \"/opt/hostedtoolcache/Python/3.12.10/x64/lib/python3.12/site-packages/galaxy/tool_util/verify/interactor.py\", line 839, in _state_ready\n    raise Exception(\nException: Job in error state.. tool_id: __DATA_FETCH__, exit_code: None, stderr: .\n", "status": "error", "test_index": 3, "time_seconds": 21.54085373878479, "tool_id": "ivar_variants", "tool_version": "1.4.3+galaxy1"}
            ]]></error>
        
    </testcase>
    
    <testcase classname="ivar_variants (Test #5)" name="4" time="38.24347424507141">
        
            
                <error type="error" message="Tool exit code: None"><![CDATA[
                    { "inputs": {  "input_bam": {   "id": "898d0e5caf100857",   "src": "hda"  },  "output_format|choice": "tabular_and_vcf",  "output_format|gtf": {   "id": "3225c95da828bb36",   "src": "hda"  },  "output_format|pass_only": true,  "ref": {   "id": "822eaa48d858d539",   "src": "hda"  } }, "job": {  "command_line": "ln -s \u0027/galaxy/server/database/objects/c/1/1/dataset_c11bab16-3b41-4a2f-ba7a-8ddbb31b1990.dat\u0027 ref.fa \u0026\u0026 ln -s \u0027/galaxy/server/database/objects/6/3/b/dataset_63b661c7-813e-4764-ae4e-57b840c10dd2.dat\u0027 sorted.bam \u0026\u0026 samtools mpileup -A -d 0 --reference ref.fa -B -Q 0 sorted.bam | ivar variants -p variants -q 20 -t 0.03 -r ref.fa -g \u0027/galaxy/server/database/objects/5/f/f/dataset_5ff39995-91ed-4c2d-952b-b67cbd0351a9.dat\u0027 \u0026\u0026 python \u0027/cvmfs/cloud.galaxyproject.org/tools/toolshed.g2.bx.psu.edu/repos/iuc/ivar_variants/abbc8041e8ec/ivar_variants/ivar_variants_to_vcf.py\u0027 --pass_only variants.tsv variants.vcf",  "command_version": null,  "copied_from_job_id": null,  "create_time": "2025-05-23T01:12:16.470811",  "dependencies": [],  "exit_code": null,  "external_id": "gxy-zvvms",  "galaxy_version": "24.1",  "handler": null,  "history_id": "bb3312a29e4a1991",  "id": "822eaa48d858d539",  "inputs": {   "input_bam": {    "id": "898d0e5caf100857",    "src": "hda",    "uuid": "63b661c7-813e-4764-ae4e-57b840c10dd2"   },   "output_format|gtf": {    "id": "3225c95da828bb36",    "src": "hda",    "uuid": "5ff39995-91ed-4c2d-952b-b67cbd0351a9"   },   "ref": {    "id": "822eaa48d858d539",    "src": "hda",    "uuid": "c11bab16-3b41-4a2f-ba7a-8ddbb31b1990"   }  },  "job_messages": null,  "job_metrics": [],  "job_runner_name": null,  "job_stderr": null,  "job_stdout": null,  "model_class": "Job",  "output_collections": {},  "outputs": {   "output_variants_tabular": {    "id": "902a23011c42ec11",    "src": "hda",    "uuid": "df4d6449-dca7-419c-bfb6-a7bc8ef468cc"   },   "output_variants_vcf": {    "id": "b7f4e5cc5ce0b6d3",    "src": "hda",    "uuid": "0726ee01-4394-497b-8f1c-c88459680642"   }  },  "params": {   "__input_ext": "\"input\"",   "chromInfo": "\"/cvmfs/data.galaxyproject.org/managed/len/ucsc/?.len\"",   "dbkey": "\"?\"",   "min_freq": "\"0.03\"",   "min_qual": "\"20\"",   "output_format": "{\"__current_case__\": 1, \"choice\": \"tabular_and_vcf\", \"gtf\": {\"values\": [{\"id\": 62, \"src\": \"hda\"}]}, \"pass_only\": true}"  },  "state": "error",  "stderr": "[mpileup] 1 samples in 1 input files\n[mpileup] Max depth set to maximum value (2147483647)\n",  "stdout": "sample\tDEL\tINS\tSNP\nvariants\t0\t0\t10\n",  "tool_id": "toolshed.g2.bx.psu.edu/repos/iuc/ivar_variants/ivar_variants/1.4.3+galaxy1",  "tool_stderr": "[mpileup] 1 samples in 1 input files\n[mpileup] Max depth set to maximum value (2147483647)\n",  "tool_stdout": "sample\tDEL\tINS\tSNP\nvariants\t0\t0\t10\n",  "update_time": "2025-05-23T01:12:27.615067",  "user_email": "tests@fake.org" }, "output_problems": [  "Job in error state.. tool_id: toolshed.g2.bx.psu.edu/repos/iuc/ivar_variants/ivar_variants/1.4.3+galaxy1, exit_code: None, stderr: [mpileup] 1 samples in 1 input files\n[mpileup] Max depth set to maximum value (2147483647)\n.",  "Job in error state.. tool_id: toolshed.g2.bx.psu.edu/repos/iuc/ivar_variants/ivar_variants/1.4.3+galaxy1, exit_code: None, stderr: [mpileup] 1 samples in 1 input files\n[mpileup] Max depth set to maximum value (2147483647)\n.",  "Job in error state.. tool_id: toolshed.g2.bx.psu.edu/repos/iuc/ivar_variants/ivar_variants/1.4.3+galaxy1, exit_code: None, stderr: [mpileup] 1 samples in 1 input files\n[mpileup] Max depth set to maximum value (2147483647)\n." ], "status": "failure", "test_index": 4, "time_seconds": 38.24347424507141, "tool_id": "ivar_variants", "tool_version": "1.4.3+galaxy1"}
                ]]></error>
            
            <system-out><![CDATA[
            sampleDELINSSNPvariants0010
            ]]></system-out>
            <system-err><![CDATA[
            [mpileup] 1 samples in 1 input files[mpileup] Max depth set to maximum value (2147483647)
            ]]></system-err>
        
    </testcase>
    
    <testcase classname="lofreq_viterbi (Test #1)" name="0" time="34.749550342559814">
        
            
                <error type="error" message="Tool exit code: None"><![CDATA[
                    { "inputs": {  "reads": {   "id": "85176e9bd26d049d",   "src": "hda"  },  "reference_source|ref": {   "id": "be01e6e195a6fc8a",   "src": "hda"  },  "reference_source|ref_selector": "history" }, "job": {  "command_line": "ln -s \u0027/galaxy/server/database/objects/9/e/a/dataset_9eabe7bd-f10f-403a-9e6c-0befef13e05e.dat\u0027 reference.fa \u0026\u0026 lofreq faidx reference.fa 2\u003e\u00261 || echo \"Error running samtools faidx for indexing fasta reference for lofreq\" \u003e\u00262 \u0026\u0026  lofreq viterbi --ref \u0027reference.fa\u0027  --defqual 2 --out tmp.bam \u0027/galaxy/server/database/objects/2/2/4/dataset_224a7c57-cb08-491f-86e2-cfea06f80f0e.dat\u0027 \u0026\u0026  samtools sort --no-PG -T \"${TMPDIR:-.}\" -@ ${GALAXY_SLOTS:-1} -O BAM -o \u0027/galaxy/server/database/objects/5/3/6/dataset_5369ba2d-dedf-4399-a8fc-9ea255e944a0.dat\u0027 tmp.bam",  "command_version": null,  "copied_from_job_id": null,  "create_time": "2025-05-23T01:08:50.663408",  "dependencies": [],  "exit_code": null,  "external_id": "gxy-pq7x9",  "galaxy_version": "24.1",  "handler": null,  "history_id": "bb3312a29e4a1991",  "id": "be01e6e195a6fc8a",  "inputs": {   "reads": {    "id": "85176e9bd26d049d",    "src": "hda",    "uuid": "224a7c57-cb08-491f-86e2-cfea06f80f0e"   },   "reference_source|ref": {    "id": "be01e6e195a6fc8a",    "src": "hda",    "uuid": "9eabe7bd-f10f-403a-9e6c-0befef13e05e"   }  },  "job_messages": null,  "job_metrics": [],  "job_runner_name": null,  "job_stderr": null,  "job_stdout": null,  "model_class": "Job",  "output_collections": {},  "outputs": {   "realigned": {    "id": "0d3a7ce7047228ad",    "src": "hda",    "uuid": "5369ba2d-dedf-4399-a8fc-9ea255e944a0"   }  },  "params": {   "__input_ext": "\"input\"",   "adv_options": "{\"bq2_handling\": {\"__current_case__\": 0, \"defqual\": \"2\", \"replace_bq2\": \"keep\"}, \"keepflags\": false}",   "chromInfo": "\"/cvmfs/data.galaxyproject.org/managed/len/ucsc/?.len\"",   "dbkey": "\"?\"",   "reference_source": "{\"__current_case__\": 1, \"ref\": {\"values\": [{\"id\": 43, \"src\": \"hda\"}]}, \"ref_selector\": \"history\"}"  },  "state": "error",  "stderr": "[bam_sort_core] merging from 0 files and 4 in-memory blocks...\n",  "stdout": "",  "tool_id": "toolshed.g2.bx.psu.edu/repos/iuc/lofreq_viterbi/lofreq_viterbi/2.1.5+galaxy0",  "tool_stderr": "[bam_sort_core] merging from 0 files and 4 in-memory blocks...\n",  "tool_stdout": "",  "update_time": "2025-05-23T01:09:04.895961",  "user_email": "tests@fake.org" }, "output_problems": [  "Job in error state.. tool_id: toolshed.g2.bx.psu.edu/repos/iuc/lofreq_viterbi/lofreq_viterbi/2.1.5+galaxy0, exit_code: None, stderr: [bam_sort_core] merging from 0 files and 4 in-memory blocks...\n.",  "Job in error state.. tool_id: toolshed.g2.bx.psu.edu/repos/iuc/lofreq_viterbi/lofreq_viterbi/2.1.5+galaxy0, exit_code: None, stderr: [bam_sort_core] merging from 0 files and 4 in-memory blocks...\n." ], "status": "failure", "test_index": 0, "time_seconds": 34.749550342559814, "tool_id": "lofreq_viterbi", "tool_version": "2.1.5+galaxy0"}
                ]]></error>
            
            <system-out><![CDATA[
            
            ]]></system-out>
            <system-err><![CDATA[
            [bam_sort_core] merging from 0 files and 4 in-memory blocks...
            ]]></system-err>
        
    </testcase>
    
    <testcase classname="lofreq_viterbi (Test #2)" name="1" time="36.63514471054077">
        
            
            <system-out><![CDATA[
            
            ]]></system-out>
            <system-err><![CDATA[
            [bam_sort_core] merging from 0 files and 4 in-memory blocks...
            ]]></system-err>
        
    </testcase>
    
    <testcase classname="poretools_events (Test #1)" name="0" time="58.699286460876465">
        
            
                <error type="error" message="Tool exit code: 1"><![CDATA[
                    { "inputs": {  "input": {   "id": "3d42f78f82108829",   "src": "hda"  },  "precalled": false }, "job": {  "command_line": "poretools events  \u0027/galaxy/server/database/objects/3/c/9/dataset_3c927e64-301a-458d-bb1f-c0eadd68a3e6.dat\u0027 \u003e \u0027/galaxy/server/database/objects/9/7/0/dataset_9706e5fb-fb4a-4c70-9382-27d8e97888f5.dat\u0027",  "command_version": "",  "copied_from_job_id": null,  "create_time": "2025-05-23T01:05:53.007127",  "dependencies": [],  "exit_code": 1,  "external_id": "gxy-bms44",  "galaxy_version": "24.1",  "handler": null,  "history_id": "bb3312a29e4a1991",  "id": "dca76b8bbb427cf8",  "inputs": {   "input": {    "id": "3d42f78f82108829",    "src": "hda",    "uuid": "3c927e64-301a-458d-bb1f-c0eadd68a3e6"   }  },  "job_messages": [   {    "code_desc": "",    "desc": "Fatal error: Exit code 1 ()",    "error_level": 3,    "exit_code": 1,    "type": "exit_code"   },   {    "code_desc": "",    "desc": "Fatal error: ",    "error_level": 3,    "match": "Error:",    "stream": "stderr",    "type": "regex"   }  ],  "job_metrics": [   {    "name": "galaxy_slots",    "plugin": "core",    "raw_value": "1.0000000",    "title": "Cores Allocated",    "value": "1"   },   {    "name": "galaxy_memory_mb",    "plugin": "core",    "raw_value": "12240.0000000",    "title": "Memory Allocated (MB)",    "value": "12240"   },   {    "name": "start_epoch",    "plugin": "core",    "raw_value": "1747962371.0000000",    "title": "Job Start Time",    "value": "2025-05-23 01:06:11"   },   {    "name": "end_epoch",    "plugin": "core",    "raw_value": "1747962372.0000000",    "title": "Job End Time",    "value": "2025-05-23 01:06:12"   },   {    "name": "runtime_seconds",    "plugin": "core",    "raw_value": "1.0000000",    "title": "Job Runtime (Wall Clock)",    "value": "1 second"   }  ],  "job_runner_name": null,  "job_stderr": "",  "job_stdout": "",  "model_class": "Job",  "output_collections": {},  "outputs": {   "output": {    "id": "dca76b8bbb427cf8",    "src": "hda",    "uuid": "9706e5fb-fb4a-4c70-9382-27d8e97888f5"   }  },  "params": {   "__input_ext": "\"input\"",   "chromInfo": "\"/cvmfs/data.galaxyproject.org/managed/len/ucsc/?.len\"",   "dbkey": "\"?\"",   "precalled": "false"  },  "state": "error",  "stderr": "Traceback (most recent call last):\n  File \"/usr/local/bin/poretools\", line 11, in \u003cmodule\u003e\n    load_entry_point(\u0027poretools==0.6.0\u0027, \u0027console_scripts\u0027, \u0027poretools\u0027)()\n  File \"/usr/local/lib/python2.7/site-packages/poretools/poretools_main.py\", line 543, in main\n    args.func(parser, args)\n  File \"/usr/local/lib/python2.7/site-packages/poretools/poretools_main.py\", line 55, in run_subtool\n    submodule.run(parser, args)\n  File \"/usr/local/lib/python2.7/site-packages/poretools/events.py\", line 17, in run\n    for fast5 in Fast5File.Fast5FileSet(args.files):\n  File \"/usr/local/lib/python2.7/site-packages/poretools/Fast5File.py\", line 110, in next\n    shutil.rmtree(PORETOOLS_TMPDIR)\n  File \"/usr/local/lib/python2.7/shutil.py\", line 261, in rmtree\n    rmtree(fullname, ignore_errors, onerror)\n  File \"/usr/local/lib/python2.7/shutil.py\", line 270, in rmtree\n    onerror(os.rmdir, path, sys.exc_info())\n  File \"/usr/local/lib/python2.7/shutil.py\", line 268, in rmtree\n    os.rmdir(path)\nOSError: [Errno 39] Directory not empty: \u0027.poretools_tmp/test-data\u0027\n",  "stdout": "",  "tool_id": "toolshed.g2.bx.psu.edu/repos/iuc/poretools_events/poretools_events/0.6.1a1.1",  "tool_stderr": "Traceback (most recent call last):\n  File \"/usr/local/bin/poretools\", line 11, in \u003cmodule\u003e\n    load_entry_point(\u0027poretools==0.6.0\u0027, \u0027console_scripts\u0027, \u0027poretools\u0027)()\n  File \"/usr/local/lib/python2.7/site-packages/poretools/poretools_main.py\", line 543, in main\n    args.func(parser, args)\n  File \"/usr/local/lib/python2.7/site-packages/poretools/poretools_main.py\", line 55, in run_subtool\n    submodule.run(parser, args)\n  File \"/usr/local/lib/python2.7/site-packages/poretools/events.py\", line 17, in run\n    for fast5 in Fast5File.Fast5FileSet(args.files):\n  File \"/usr/local/lib/python2.7/site-packages/poretools/Fast5File.py\", line 110, in next\n    shutil.rmtree(PORETOOLS_TMPDIR)\n  File \"/usr/local/lib/python2.7/shutil.py\", line 261, in rmtree\n    rmtree(fullname, ignore_errors, onerror)\n  File \"/usr/local/lib/python2.7/shutil.py\", line 270, in rmtree\n    onerror(os.rmdir, path, sys.exc_info())\n  File \"/usr/local/lib/python2.7/shutil.py\", line 268, in rmtree\n    os.rmdir(path)\nOSError: [Errno 39] Directory not empty: \u0027.poretools_tmp/test-data\u0027\n",  "tool_stdout": "",  "update_time": "2025-05-23T01:06:31.709847",  "user_email": "tests@fake.org" }, "output_problems": [  "Job in error state.. tool_id: toolshed.g2.bx.psu.edu/repos/iuc/poretools_events/poretools_events/0.6.1a1.1, exit_code: 1, stderr: Traceback (most recent call last):\n  File \"/usr/local/bin/poretools\", line 11, in \u003cmodule\u003e\n    load_entry_point(\u0027poretools==0.6.0\u0027, \u0027console_scripts\u0027, \u0027poretools\u0027)()\n  File \"/usr/local/lib/python2.7/site-packages/poretools/poretools_main.py\", line 543, in main\n    args.func(parser, args)\n  File \"/usr/local/lib/python2.7/site-packages/poretools/poretools_main.py\", line 55, in run_subtool\n    submodule.run(parser, args)\n  File \"/usr/local/lib/python2.7/site-packages/poretools/events.py\", line 17, in run\n    for fast5 in Fast5File.Fast5FileSet(args.files):\n  File \"/usr/local/lib/python2.7/site-packages/poretools/Fast5File.py\", line 110, in next\n    shutil.rmtree(PORETOOLS_TMPDIR)\n  File \"/usr/local/lib/python2.7/shutil.py\", line 261, in rmtree\n    rmtree(fullname, ignore_errors, onerror)\n  File \"/usr/local/lib/python2.7/shutil.py\", line 270, in rmtree\n    onerror(os.rmdir, path, sys.exc_info())\n  File \"/usr/local/lib/python2.7/shutil.py\", line 268, in rmtree\n    os.rmdir(path)\nOSError: [Errno 39] Directory not empty: \u0027.poretools_tmp/test-data\u0027\n.",  "Job in error state.. tool_id: toolshed.g2.bx.psu.edu/repos/iuc/poretools_events/poretools_events/0.6.1a1.1, exit_code: 1, stderr: Traceback (most recent call last):\n  File \"/usr/local/bin/poretools\", line 11, in \u003cmodule\u003e\n    load_entry_point(\u0027poretools==0.6.0\u0027, \u0027console_scripts\u0027, \u0027poretools\u0027)()\n  File \"/usr/local/lib/python2.7/site-packages/poretools/poretools_main.py\", line 543, in main\n    args.func(parser, args)\n  File \"/usr/local/lib/python2.7/site-packages/poretools/poretools_main.py\", line 55, in run_subtool\n    submodule.run(parser, args)\n  File \"/usr/local/lib/python2.7/site-packages/poretools/events.py\", line 17, in run\n    for fast5 in Fast5File.Fast5FileSet(args.files):\n  File \"/usr/local/lib/python2.7/site-packages/poretools/Fast5File.py\", line 110, in next\n    shutil.rmtree(PORETOOLS_TMPDIR)\n  File \"/usr/local/lib/python2.7/shutil.py\", line 261, in rmtree\n    rmtree(fullname, ignore_errors, onerror)\n  File \"/usr/local/lib/python2.7/shutil.py\", line 270, in rmtree\n    onerror(os.rmdir, path, sys.exc_info())\n  File \"/usr/local/lib/python2.7/shutil.py\", line 268, in rmtree\n    os.rmdir(path)\nOSError: [Errno 39] Directory not empty: \u0027.poretools_tmp/test-data\u0027\n." ], "status": "failure", "test_index": 0, "time_seconds": 58.699286460876465, "tool_id": "poretools_events", "tool_version": "0.6.1a1.1"}
                ]]></error>
            
            <system-out><![CDATA[
            
            ]]></system-out>
            <system-err><![CDATA[
            Traceback (most recent call last):  File "/usr/local/bin/poretools", line 11, in <module>    load_entry_point('poretools==0.6.0', 'console_scripts', 'poretools')()  File "/usr/local/lib/python2.7/site-packages/poretools/poretools_main.py", line 543, in main    args.func(parser, args)  File "/usr/local/lib/python2.7/site-packages/poretools/poretools_main.py", line 55, in run_subtool    submodule.run(parser, args)  File "/usr/local/lib/python2.7/site-packages/poretools/events.py", line 17, in run    for fast5 in Fast5File.Fast5FileSet(args.files):  File "/usr/local/lib/python2.7/site-packages/poretools/Fast5File.py", line 110, in next    shutil.rmtree(PORETOOLS_TMPDIR)  File "/usr/local/lib/python2.7/shutil.py", line 261, in rmtree    rmtree(fullname, ignore_errors, onerror)  File "/usr/local/lib/python2.7/shutil.py", line 270, in rmtree    onerror(os.rmdir, path, sys.exc_info())  File "/usr/local/lib/python2.7/shutil.py", line 268, in rmtree    os.rmdir(path)OSError: [Errno 39] Directory not empty: '.poretools_tmp/test-data'
            ]]></system-err>
        
    </testcase>
    
    <testcase classname="poretools_events (Test #2)" name="1" time="34.506988763809204">
        
            
                <error type="error" message="Tool exit code: 1"><![CDATA[
                    { "inputs": {  "input": {   "id": "9ff1c56d32f1fb7f",   "src": "hda"  },  "precalled": true }, "job": {  "command_line": "poretools events --pre-basecalled \u0027/galaxy/server/database/objects/9/6/7/dataset_96791b7b-fe7a-48a6-a30d-12f82c8fec34.dat\u0027 \u003e \u0027/galaxy/server/database/objects/e/8/d/dataset_e8d01bfb-3d2c-4e61-a973-a6e4cb354ff1.dat\u0027",  "command_version": "",  "copied_from_job_id": null,  "create_time": "2025-05-23T01:06:51.831559",  "dependencies": [],  "exit_code": 1,  "external_id": "gxy-jk65n",  "galaxy_version": "24.1",  "handler": null,  "history_id": "bb3312a29e4a1991",  "id": "d8276aaf956691b4",  "inputs": {   "input": {    "id": "9ff1c56d32f1fb7f",    "src": "hda",    "uuid": "96791b7b-fe7a-48a6-a30d-12f82c8fec34"   }  },  "job_messages": [   {    "code_desc": "",    "desc": "Fatal error: Exit code 1 ()",    "error_level": 3,    "exit_code": 1,    "type": "exit_code"   },   {    "code_desc": "",    "desc": "Fatal error: ",    "error_level": 3,    "match": "Error:",    "stream": "stderr",    "type": "regex"   }  ],  "job_metrics": [   {    "name": "galaxy_slots",    "plugin": "core",    "raw_value": "1.0000000",    "title": "Cores Allocated",    "value": "1"   },   {    "name": "galaxy_memory_mb",    "plugin": "core",    "raw_value": "12240.0000000",    "title": "Memory Allocated (MB)",    "value": "12240"   },   {    "name": "start_epoch",    "plugin": "core",    "raw_value": "1747962414.0000000",    "title": "Job Start Time",    "value": "2025-05-23 01:06:54"   },   {    "name": "end_epoch",    "plugin": "core",    "raw_value": "1747962415.0000000",    "title": "Job End Time",    "value": "2025-05-23 01:06:55"   },   {    "name": "runtime_seconds",    "plugin": "core",    "raw_value": "1.0000000",    "title": "Job Runtime (Wall Clock)",    "value": "1 second"   }  ],  "job_runner_name": null,  "job_stderr": "",  "job_stdout": "",  "model_class": "Job",  "output_collections": {},  "outputs": {   "output": {    "id": "d8276aaf956691b4",    "src": "hda",    "uuid": "e8d01bfb-3d2c-4e61-a973-a6e4cb354ff1"   }  },  "params": {   "__input_ext": "\"input\"",   "chromInfo": "\"/cvmfs/data.galaxyproject.org/managed/len/ucsc/?.len\"",   "dbkey": "\"?\"",   "precalled": "true"  },  "state": "error",  "stderr": "Traceback (most recent call last):\n  File \"/usr/local/bin/poretools\", line 11, in \u003cmodule\u003e\n    load_entry_point(\u0027poretools==0.6.0\u0027, \u0027console_scripts\u0027, \u0027poretools\u0027)()\n  File \"/usr/local/lib/python2.7/site-packages/poretools/poretools_main.py\", line 543, in main\n    args.func(parser, args)\n  File \"/usr/local/lib/python2.7/site-packages/poretools/poretools_main.py\", line 55, in run_subtool\n    submodule.run(parser, args)\n  File \"/usr/local/lib/python2.7/site-packages/poretools/events.py\", line 13, in run\n    for fast5 in Fast5File.Fast5FileSet(args.files):\n  File \"/usr/local/lib/python2.7/site-packages/poretools/Fast5File.py\", line 110, in next\n    shutil.rmtree(PORETOOLS_TMPDIR)\n  File \"/usr/local/lib/python2.7/shutil.py\", line 261, in rmtree\n    rmtree(fullname, ignore_errors, onerror)\n  File \"/usr/local/lib/python2.7/shutil.py\", line 270, in rmtree\n    onerror(os.rmdir, path, sys.exc_info())\n  File \"/usr/local/lib/python2.7/shutil.py\", line 268, in rmtree\n    os.rmdir(path)\nOSError: [Errno 39] Directory not empty: \u0027.poretools_tmp/test-data\u0027\n",  "stdout": "",  "tool_id": "toolshed.g2.bx.psu.edu/repos/iuc/poretools_events/poretools_events/0.6.1a1.1",  "tool_stderr": "Traceback (most recent call last):\n  File \"/usr/local/bin/poretools\", line 11, in \u003cmodule\u003e\n    load_entry_point(\u0027poretools==0.6.0\u0027, \u0027console_scripts\u0027, \u0027poretools\u0027)()\n  File \"/usr/local/lib/python2.7/site-packages/poretools/poretools_main.py\", line 543, in main\n    args.func(parser, args)\n  File \"/usr/local/lib/python2.7/site-packages/poretools/poretools_main.py\", line 55, in run_subtool\n    submodule.run(parser, args)\n  File \"/usr/local/lib/python2.7/site-packages/poretools/events.py\", line 13, in run\n    for fast5 in Fast5File.Fast5FileSet(args.files):\n  File \"/usr/local/lib/python2.7/site-packages/poretools/Fast5File.py\", line 110, in next\n    shutil.rmtree(PORETOOLS_TMPDIR)\n  File \"/usr/local/lib/python2.7/shutil.py\", line 261, in rmtree\n    rmtree(fullname, ignore_errors, onerror)\n  File \"/usr/local/lib/python2.7/shutil.py\", line 270, in rmtree\n    onerror(os.rmdir, path, sys.exc_info())\n  File \"/usr/local/lib/python2.7/shutil.py\", line 268, in rmtree\n    os.rmdir(path)\nOSError: [Errno 39] Directory not empty: \u0027.poretools_tmp/test-data\u0027\n",  "tool_stdout": "",  "update_time": "2025-05-23T01:07:06.260877",  "user_email": "tests@fake.org" }, "output_problems": [  "Job in error state.. tool_id: toolshed.g2.bx.psu.edu/repos/iuc/poretools_events/poretools_events/0.6.1a1.1, exit_code: 1, stderr: Traceback (most recent call last):\n  File \"/usr/local/bin/poretools\", line 11, in \u003cmodule\u003e\n    load_entry_point(\u0027poretools==0.6.0\u0027, \u0027console_scripts\u0027, \u0027poretools\u0027)()\n  File \"/usr/local/lib/python2.7/site-packages/poretools/poretools_main.py\", line 543, in main\n    args.func(parser, args)\n  File \"/usr/local/lib/python2.7/site-packages/poretools/poretools_main.py\", line 55, in run_subtool\n    submodule.run(parser, args)\n  File \"/usr/local/lib/python2.7/site-packages/poretools/events.py\", line 13, in run\n    for fast5 in Fast5File.Fast5FileSet(args.files):\n  File \"/usr/local/lib/python2.7/site-packages/poretools/Fast5File.py\", line 110, in next\n    shutil.rmtree(PORETOOLS_TMPDIR)\n  File \"/usr/local/lib/python2.7/shutil.py\", line 261, in rmtree\n    rmtree(fullname, ignore_errors, onerror)\n  File \"/usr/local/lib/python2.7/shutil.py\", line 270, in rmtree\n    onerror(os.rmdir, path, sys.exc_info())\n  File \"/usr/local/lib/python2.7/shutil.py\", line 268, in rmtree\n    os.rmdir(path)\nOSError: [Errno 39] Directory not empty: \u0027.poretools_tmp/test-data\u0027\n.",  "Job in error state.. tool_id: toolshed.g2.bx.psu.edu/repos/iuc/poretools_events/poretools_events/0.6.1a1.1, exit_code: 1, stderr: Traceback (most recent call last):\n  File \"/usr/local/bin/poretools\", line 11, in \u003cmodule\u003e\n    load_entry_point(\u0027poretools==0.6.0\u0027, \u0027console_scripts\u0027, \u0027poretools\u0027)()\n  File \"/usr/local/lib/python2.7/site-packages/poretools/poretools_main.py\", line 543, in main\n    args.func(parser, args)\n  File \"/usr/local/lib/python2.7/site-packages/poretools/poretools_main.py\", line 55, in run_subtool\n    submodule.run(parser, args)\n  File \"/usr/local/lib/python2.7/site-packages/poretools/events.py\", line 13, in run\n    for fast5 in Fast5File.Fast5FileSet(args.files):\n  File \"/usr/local/lib/python2.7/site-packages/poretools/Fast5File.py\", line 110, in next\n    shutil.rmtree(PORETOOLS_TMPDIR)\n  File \"/usr/local/lib/python2.7/shutil.py\", line 261, in rmtree\n    rmtree(fullname, ignore_errors, onerror)\n  File \"/usr/local/lib/python2.7/shutil.py\", line 270, in rmtree\n    onerror(os.rmdir, path, sys.exc_info())\n  File \"/usr/local/lib/python2.7/shutil.py\", line 268, in rmtree\n    os.rmdir(path)\nOSError: [Errno 39] Directory not empty: \u0027.poretools_tmp/test-data\u0027\n." ], "status": "failure", "test_index": 1, "time_seconds": 34.506988763809204, "tool_id": "poretools_events", "tool_version": "0.6.1a1.1"}
                ]]></error>
            
            <system-out><![CDATA[
            
            ]]></system-out>
            <system-err><![CDATA[
            Traceback (most recent call last):  File "/usr/local/bin/poretools", line 11, in <module>    load_entry_point('poretools==0.6.0', 'console_scripts', 'poretools')()  File "/usr/local/lib/python2.7/site-packages/poretools/poretools_main.py", line 543, in main    args.func(parser, args)  File "/usr/local/lib/python2.7/site-packages/poretools/poretools_main.py", line 55, in run_subtool    submodule.run(parser, args)  File "/usr/local/lib/python2.7/site-packages/poretools/events.py", line 13, in run    for fast5 in Fast5File.Fast5FileSet(args.files):  File "/usr/local/lib/python2.7/site-packages/poretools/Fast5File.py", line 110, in next    shutil.rmtree(PORETOOLS_TMPDIR)  File "/usr/local/lib/python2.7/shutil.py", line 261, in rmtree    rmtree(fullname, ignore_errors, onerror)  File "/usr/local/lib/python2.7/shutil.py", line 270, in rmtree    onerror(os.rmdir, path, sys.exc_info())  File "/usr/local/lib/python2.7/shutil.py", line 268, in rmtree    os.rmdir(path)OSError: [Errno 39] Directory not empty: '.poretools_tmp/test-data'
            ]]></system-err>
        
    </testcase>
    
    <testcase classname="samtools_merge (Test #1)" name="0" time="0.10417819023132324">
        
            <error type="error" message="Input staging problem: Traceback (most recent call last):
  File "/opt/hostedtoolcache/Python/3.12.10/x64/lib/python3.12/site-packages/galaxy/tool_util/verify/interactor.py", line 1434, in verify_tool
    stage_data_in_history(
  File "/opt/hostedtoolcache/Python/3.12.10/x64/lib/python3.12/site-packages/galaxy/tool_util/verify/interactor.py", line 163, in stage_data_in_history
    test_dict = galaxy_interactor.remote_to_input(
                ^^^^^^^^^^^^^^^^^^^^^^^^^^^^^^^^^^
  File "/opt/hostedtoolcache/Python/3.12.10/x64/lib/python3.12/site-packages/galaxy/tool_util/verify/interactor.py", line 582, in remote_to_input
    path_or_location = self._get_path_or_location(
                       ^^^^^^^^^^^^^^^^^^^^^^^^^^^
  File "/opt/hostedtoolcache/Python/3.12.10/x64/lib/python3.12/site-packages/galaxy/tool_util/verify/interactor.py", line 619, in _get_path_or_location
    path = self.test_data_download(
           ^^^^^^^^^^^^^^^^^^^^^^^^
  File "/opt/hostedtoolcache/Python/3.12.10/x64/lib/python3.12/site-packages/galaxy/tool_util/verify/interactor.py", line 525, in test_data_download
    raise AssertionError(f"Test input file ({filename}) cannot be found.")
AssertionError: Test input file (test_input_1_a.sam) cannot be found.
"><![CDATA[
                { "execution_problem": "Input staging problem: Traceback (most recent call last):\n  File \"/opt/hostedtoolcache/Python/3.12.10/x64/lib/python3.12/site-packages/galaxy/tool_util/verify/interactor.py\", line 1434, in verify_tool\n    stage_data_in_history(\n  File \"/opt/hostedtoolcache/Python/3.12.10/x64/lib/python3.12/site-packages/galaxy/tool_util/verify/interactor.py\", line 163, in stage_data_in_history\n    test_dict = galaxy_interactor.remote_to_input(\n                ^^^^^^^^^^^^^^^^^^^^^^^^^^^^^^^^^^\n  File \"/opt/hostedtoolcache/Python/3.12.10/x64/lib/python3.12/site-packages/galaxy/tool_util/verify/interactor.py\", line 582, in remote_to_input\n    path_or_location = self._get_path_or_location(\n                       ^^^^^^^^^^^^^^^^^^^^^^^^^^^\n  File \"/opt/hostedtoolcache/Python/3.12.10/x64/lib/python3.12/site-packages/galaxy/tool_util/verify/interactor.py\", line 619, in _get_path_or_location\n    path = self.test_data_download(\n           ^^^^^^^^^^^^^^^^^^^^^^^^\n  File \"/opt/hostedtoolcache/Python/3.12.10/x64/lib/python3.12/site-packages/galaxy/tool_util/verify/interactor.py\", line 525, in test_data_download\n    raise AssertionError(f\"Test input file ({filename}) cannot be found.\")\nAssertionError: Test input file (test_input_1_a.sam) cannot be found.\n", "status": "error", "test_index": 0, "time_seconds": 0.10417819023132324, "tool_id": "samtools_merge", "tool_version": "1.9"}
            ]]></error>
        
    </testcase>
    
    <testcase classname="samtools_merge (Test #2)" name="1" time="0.053063154220581055">
        
            <error type="error" message="Input staging problem: Traceback (most recent call last):
  File "/opt/hostedtoolcache/Python/3.12.10/x64/lib/python3.12/site-packages/galaxy/tool_util/verify/interactor.py", line 1434, in verify_tool
    stage_data_in_history(
  File "/opt/hostedtoolcache/Python/3.12.10/x64/lib/python3.12/site-packages/galaxy/tool_util/verify/interactor.py", line 163, in stage_data_in_history
    test_dict = galaxy_interactor.remote_to_input(
                ^^^^^^^^^^^^^^^^^^^^^^^^^^^^^^^^^^
  File "/opt/hostedtoolcache/Python/3.12.10/x64/lib/python3.12/site-packages/galaxy/tool_util/verify/interactor.py", line 582, in remote_to_input
    path_or_location = self._get_path_or_location(
                       ^^^^^^^^^^^^^^^^^^^^^^^^^^^
  File "/opt/hostedtoolcache/Python/3.12.10/x64/lib/python3.12/site-packages/galaxy/tool_util/verify/interactor.py", line 619, in _get_path_or_location
    path = self.test_data_download(
           ^^^^^^^^^^^^^^^^^^^^^^^^
  File "/opt/hostedtoolcache/Python/3.12.10/x64/lib/python3.12/site-packages/galaxy/tool_util/verify/interactor.py", line 525, in test_data_download
    raise AssertionError(f"Test input file ({filename}) cannot be found.")
AssertionError: Test input file (test_input_1_a.bam) cannot be found.
"><![CDATA[
                { "execution_problem": "Input staging problem: Traceback (most recent call last):\n  File \"/opt/hostedtoolcache/Python/3.12.10/x64/lib/python3.12/site-packages/galaxy/tool_util/verify/interactor.py\", line 1434, in verify_tool\n    stage_data_in_history(\n  File \"/opt/hostedtoolcache/Python/3.12.10/x64/lib/python3.12/site-packages/galaxy/tool_util/verify/interactor.py\", line 163, in stage_data_in_history\n    test_dict = galaxy_interactor.remote_to_input(\n                ^^^^^^^^^^^^^^^^^^^^^^^^^^^^^^^^^^\n  File \"/opt/hostedtoolcache/Python/3.12.10/x64/lib/python3.12/site-packages/galaxy/tool_util/verify/interactor.py\", line 582, in remote_to_input\n    path_or_location = self._get_path_or_location(\n                       ^^^^^^^^^^^^^^^^^^^^^^^^^^^\n  File \"/opt/hostedtoolcache/Python/3.12.10/x64/lib/python3.12/site-packages/galaxy/tool_util/verify/interactor.py\", line 619, in _get_path_or_location\n    path = self.test_data_download(\n           ^^^^^^^^^^^^^^^^^^^^^^^^\n  File \"/opt/hostedtoolcache/Python/3.12.10/x64/lib/python3.12/site-packages/galaxy/tool_util/verify/interactor.py\", line 525, in test_data_download\n    raise AssertionError(f\"Test input file ({filename}) cannot be found.\")\nAssertionError: Test input file (test_input_1_a.bam) cannot be found.\n", "status": "error", "test_index": 1, "time_seconds": 0.053063154220581055, "tool_id": "samtools_merge", "tool_version": "1.9"}
            ]]></error>
        
    </testcase>
    
    <testcase classname="samtools_merge (Test #3)" name="2" time="0.05422091484069824">
        
            <error type="error" message="Input staging problem: Traceback (most recent call last):
  File "/opt/hostedtoolcache/Python/3.12.10/x64/lib/python3.12/site-packages/galaxy/tool_util/verify/interactor.py", line 1434, in verify_tool
    stage_data_in_history(
  File "/opt/hostedtoolcache/Python/3.12.10/x64/lib/python3.12/site-packages/galaxy/tool_util/verify/interactor.py", line 163, in stage_data_in_history
    test_dict = galaxy_interactor.remote_to_input(
                ^^^^^^^^^^^^^^^^^^^^^^^^^^^^^^^^^^
  File "/opt/hostedtoolcache/Python/3.12.10/x64/lib/python3.12/site-packages/galaxy/tool_util/verify/interactor.py", line 582, in remote_to_input
    path_or_location = self._get_path_or_location(
                       ^^^^^^^^^^^^^^^^^^^^^^^^^^^
  File "/opt/hostedtoolcache/Python/3.12.10/x64/lib/python3.12/site-packages/galaxy/tool_util/verify/interactor.py", line 619, in _get_path_or_location
    path = self.test_data_download(
           ^^^^^^^^^^^^^^^^^^^^^^^^
  File "/opt/hostedtoolcache/Python/3.12.10/x64/lib/python3.12/site-packages/galaxy/tool_util/verify/interactor.py", line 525, in test_data_download
    raise AssertionError(f"Test input file ({filename}) cannot be found.")
AssertionError: Test input file (test_input_1_b.bam) cannot be found.
"><![CDATA[
                { "execution_problem": "Input staging problem: Traceback (most recent call last):\n  File \"/opt/hostedtoolcache/Python/3.12.10/x64/lib/python3.12/site-packages/galaxy/tool_util/verify/interactor.py\", line 1434, in verify_tool\n    stage_data_in_history(\n  File \"/opt/hostedtoolcache/Python/3.12.10/x64/lib/python3.12/site-packages/galaxy/tool_util/verify/interactor.py\", line 163, in stage_data_in_history\n    test_dict = galaxy_interactor.remote_to_input(\n                ^^^^^^^^^^^^^^^^^^^^^^^^^^^^^^^^^^\n  File \"/opt/hostedtoolcache/Python/3.12.10/x64/lib/python3.12/site-packages/galaxy/tool_util/verify/interactor.py\", line 582, in remote_to_input\n    path_or_location = self._get_path_or_location(\n                       ^^^^^^^^^^^^^^^^^^^^^^^^^^^\n  File \"/opt/hostedtoolcache/Python/3.12.10/x64/lib/python3.12/site-packages/galaxy/tool_util/verify/interactor.py\", line 619, in _get_path_or_location\n    path = self.test_data_download(\n           ^^^^^^^^^^^^^^^^^^^^^^^^\n  File \"/opt/hostedtoolcache/Python/3.12.10/x64/lib/python3.12/site-packages/galaxy/tool_util/verify/interactor.py\", line 525, in test_data_download\n    raise AssertionError(f\"Test input file ({filename}) cannot be found.\")\nAssertionError: Test input file (test_input_1_b.bam) cannot be found.\n", "status": "error", "test_index": 2, "time_seconds": 0.05422091484069824, "tool_id": "samtools_merge", "tool_version": "1.9"}
            ]]></error>
        
    </testcase>
    
    <testcase classname="samtools_merge (Test #4)" name="3" time="0.0546870231628418">
        
            <error type="error" message="Input staging problem: Traceback (most recent call last):
  File "/opt/hostedtoolcache/Python/3.12.10/x64/lib/python3.12/site-packages/galaxy/tool_util/verify/interactor.py", line 1434, in verify_tool
    stage_data_in_history(
  File "/opt/hostedtoolcache/Python/3.12.10/x64/lib/python3.12/site-packages/galaxy/tool_util/verify/interactor.py", line 163, in stage_data_in_history
    test_dict = galaxy_interactor.remote_to_input(
                ^^^^^^^^^^^^^^^^^^^^^^^^^^^^^^^^^^
  File "/opt/hostedtoolcache/Python/3.12.10/x64/lib/python3.12/site-packages/galaxy/tool_util/verify/interactor.py", line 582, in remote_to_input
    path_or_location = self._get_path_or_location(
                       ^^^^^^^^^^^^^^^^^^^^^^^^^^^
  File "/opt/hostedtoolcache/Python/3.12.10/x64/lib/python3.12/site-packages/galaxy/tool_util/verify/interactor.py", line 619, in _get_path_or_location
    path = self.test_data_download(
           ^^^^^^^^^^^^^^^^^^^^^^^^
  File "/opt/hostedtoolcache/Python/3.12.10/x64/lib/python3.12/site-packages/galaxy/tool_util/verify/interactor.py", line 525, in test_data_download
    raise AssertionError(f"Test input file ({filename}) cannot be found.")
AssertionError: Test input file (test_input_1_a.bam) cannot be found.
"><![CDATA[
                { "execution_problem": "Input staging problem: Traceback (most recent call last):\n  File \"/opt/hostedtoolcache/Python/3.12.10/x64/lib/python3.12/site-packages/galaxy/tool_util/verify/interactor.py\", line 1434, in verify_tool\n    stage_data_in_history(\n  File \"/opt/hostedtoolcache/Python/3.12.10/x64/lib/python3.12/site-packages/galaxy/tool_util/verify/interactor.py\", line 163, in stage_data_in_history\n    test_dict = galaxy_interactor.remote_to_input(\n                ^^^^^^^^^^^^^^^^^^^^^^^^^^^^^^^^^^\n  File \"/opt/hostedtoolcache/Python/3.12.10/x64/lib/python3.12/site-packages/galaxy/tool_util/verify/interactor.py\", line 582, in remote_to_input\n    path_or_location = self._get_path_or_location(\n                       ^^^^^^^^^^^^^^^^^^^^^^^^^^^\n  File \"/opt/hostedtoolcache/Python/3.12.10/x64/lib/python3.12/site-packages/galaxy/tool_util/verify/interactor.py\", line 619, in _get_path_or_location\n    path = self.test_data_download(\n           ^^^^^^^^^^^^^^^^^^^^^^^^\n  File \"/opt/hostedtoolcache/Python/3.12.10/x64/lib/python3.12/site-packages/galaxy/tool_util/verify/interactor.py\", line 525, in test_data_download\n    raise AssertionError(f\"Test input file ({filename}) cannot be found.\")\nAssertionError: Test input file (test_input_1_a.bam) cannot be found.\n", "status": "error", "test_index": 3, "time_seconds": 0.0546870231628418, "tool_id": "samtools_merge", "tool_version": "1.9"}
            ]]></error>
        
    </testcase>
    
    <testcase classname="samtools_merge (Test #5)" name="4" time="0.05628657341003418">
        
            <error type="error" message="Input staging problem: Traceback (most recent call last):
  File "/opt/hostedtoolcache/Python/3.12.10/x64/lib/python3.12/site-packages/galaxy/tool_util/verify/interactor.py", line 1434, in verify_tool
    stage_data_in_history(
  File "/opt/hostedtoolcache/Python/3.12.10/x64/lib/python3.12/site-packages/galaxy/tool_util/verify/interactor.py", line 163, in stage_data_in_history
    test_dict = galaxy_interactor.remote_to_input(
                ^^^^^^^^^^^^^^^^^^^^^^^^^^^^^^^^^^
  File "/opt/hostedtoolcache/Python/3.12.10/x64/lib/python3.12/site-packages/galaxy/tool_util/verify/interactor.py", line 582, in remote_to_input
    path_or_location = self._get_path_or_location(
                       ^^^^^^^^^^^^^^^^^^^^^^^^^^^
  File "/opt/hostedtoolcache/Python/3.12.10/x64/lib/python3.12/site-packages/galaxy/tool_util/verify/interactor.py", line 619, in _get_path_or_location
    path = self.test_data_download(
           ^^^^^^^^^^^^^^^^^^^^^^^^
  File "/opt/hostedtoolcache/Python/3.12.10/x64/lib/python3.12/site-packages/galaxy/tool_util/verify/interactor.py", line 525, in test_data_download
    raise AssertionError(f"Test input file ({filename}) cannot be found.")
AssertionError: Test input file (test_input_1_a_regex.sam) cannot be found.
"><![CDATA[
                { "execution_problem": "Input staging problem: Traceback (most recent call last):\n  File \"/opt/hostedtoolcache/Python/3.12.10/x64/lib/python3.12/site-packages/galaxy/tool_util/verify/interactor.py\", line 1434, in verify_tool\n    stage_data_in_history(\n  File \"/opt/hostedtoolcache/Python/3.12.10/x64/lib/python3.12/site-packages/galaxy/tool_util/verify/interactor.py\", line 163, in stage_data_in_history\n    test_dict = galaxy_interactor.remote_to_input(\n                ^^^^^^^^^^^^^^^^^^^^^^^^^^^^^^^^^^\n  File \"/opt/hostedtoolcache/Python/3.12.10/x64/lib/python3.12/site-packages/galaxy/tool_util/verify/interactor.py\", line 582, in remote_to_input\n    path_or_location = self._get_path_or_location(\n                       ^^^^^^^^^^^^^^^^^^^^^^^^^^^\n  File \"/opt/hostedtoolcache/Python/3.12.10/x64/lib/python3.12/site-packages/galaxy/tool_util/verify/interactor.py\", line 619, in _get_path_or_location\n    path = self.test_data_download(\n           ^^^^^^^^^^^^^^^^^^^^^^^^\n  File \"/opt/hostedtoolcache/Python/3.12.10/x64/lib/python3.12/site-packages/galaxy/tool_util/verify/interactor.py\", line 525, in test_data_download\n    raise AssertionError(f\"Test input file ({filename}) cannot be found.\")\nAssertionError: Test input file (test_input_1_a_regex.sam) cannot be found.\n", "status": "error", "test_index": 4, "time_seconds": 0.05628657341003418, "tool_id": "samtools_merge", "tool_version": "1.9"}
            ]]></error>
        
    </testcase>
    
    <testcase classname="vcfannotategenotypes (Test #1)" name="0" time="40.77766537666321">
        
            
            <system-out><![CDATA[
            
            ]]></system-out>
            <system-err><![CDATA[
            
            ]]></system-err>
        
    </testcase>
    
    <testcase classname="vcfsort (Test #1)" name="0" time="11.310503721237183">
        
            <error type="error" message="Input staging problem: Traceback (most recent call last):
  File "/opt/hostedtoolcache/Python/3.12.10/x64/lib/python3.12/site-packages/galaxy/tool_util/verify/interactor.py", line 1434, in verify_tool
    stage_data_in_history(
  File "/opt/hostedtoolcache/Python/3.12.10/x64/lib/python3.12/site-packages/galaxy/tool_util/verify/interactor.py", line 175, in stage_data_in_history
    staging_interface.handle_jobs()
  File "/opt/hostedtoolcache/Python/3.12.10/x64/lib/python3.12/site-packages/galaxy/tool_util/verify/interactor.py", line 212, in handle_jobs
    self.galaxy_interactor.wait_for_job(job_response["id"], job_response["history_id"], self.maxseconds)
  File "/opt/hostedtoolcache/Python/3.12.10/x64/lib/python3.12/site-packages/galaxy/tool_util/verify/interactor.py", line 399, in wait_for_job
    self.wait_for(lambda: self.__job_ready(job_id, history_id), maxseconds=maxseconds)
  File "/opt/hostedtoolcache/Python/3.12.10/x64/lib/python3.12/site-packages/galaxy/tool_util/verify/interactor.py", line 403, in wait_for
    wait_on(func, what, walltime_exceeded)
  File "/opt/hostedtoolcache/Python/3.12.10/x64/lib/python3.12/site-packages/galaxy/tool_util/verify/wait.py", line 38, in wait_on
    value = function()
            ^^^^^^^^^^
  File "/opt/hostedtoolcache/Python/3.12.10/x64/lib/python3.12/site-packages/galaxy/tool_util/verify/interactor.py", line 399, in <lambda>
    self.wait_for(lambda: self.__job_ready(job_id, history_id), maxseconds=maxseconds)
                          ^^^^^^^^^^^^^^^^^^^^^^^^^^^^^^^^^^^^
  File "/opt/hostedtoolcache/Python/3.12.10/x64/lib/python3.12/site-packages/galaxy/tool_util/verify/interactor.py", line 747, in __job_ready
    return self._state_ready(job_id, error_msg="Job in error state.")
           ^^^^^^^^^^^^^^^^^^^^^^^^^^^^^^^^^^^^^^^^^^^^^^^^^^^^^^^^^^
  File "/opt/hostedtoolcache/Python/3.12.10/x64/lib/python3.12/site-packages/galaxy/tool_util/verify/interactor.py", line 839, in _state_ready
    raise Exception(
Exception: Job in error state.. tool_id: __DATA_FETCH__, exit_code: None, stderr: .
"><![CDATA[
                { "execution_problem": "Input staging problem: Traceback (most recent call last):\n  File \"/opt/hostedtoolcache/Python/3.12.10/x64/lib/python3.12/site-packages/galaxy/tool_util/verify/interactor.py\", line 1434, in verify_tool\n    stage_data_in_history(\n  File \"/opt/hostedtoolcache/Python/3.12.10/x64/lib/python3.12/site-packages/galaxy/tool_util/verify/interactor.py\", line 175, in stage_data_in_history\n    staging_interface.handle_jobs()\n  File \"/opt/hostedtoolcache/Python/3.12.10/x64/lib/python3.12/site-packages/galaxy/tool_util/verify/interactor.py\", line 212, in handle_jobs\n    self.galaxy_interactor.wait_for_job(job_response[\"id\"], job_response[\"history_id\"], self.maxseconds)\n  File \"/opt/hostedtoolcache/Python/3.12.10/x64/lib/python3.12/site-packages/galaxy/tool_util/verify/interactor.py\", line 399, in wait_for_job\n    self.wait_for(lambda: self.__job_ready(job_id, history_id), maxseconds=maxseconds)\n  File \"/opt/hostedtoolcache/Python/3.12.10/x64/lib/python3.12/site-packages/galaxy/tool_util/verify/interactor.py\", line 403, in wait_for\n    wait_on(func, what, walltime_exceeded)\n  File \"/opt/hostedtoolcache/Python/3.12.10/x64/lib/python3.12/site-packages/galaxy/tool_util/verify/wait.py\", line 38, in wait_on\n    value = function()\n            ^^^^^^^^^^\n  File \"/opt/hostedtoolcache/Python/3.12.10/x64/lib/python3.12/site-packages/galaxy/tool_util/verify/interactor.py\", line 399, in \u003clambda\u003e\n    self.wait_for(lambda: self.__job_ready(job_id, history_id), maxseconds=maxseconds)\n                          ^^^^^^^^^^^^^^^^^^^^^^^^^^^^^^^^^^^^\n  File \"/opt/hostedtoolcache/Python/3.12.10/x64/lib/python3.12/site-packages/galaxy/tool_util/verify/interactor.py\", line 747, in __job_ready\n    return self._state_ready(job_id, error_msg=\"Job in error state.\")\n           ^^^^^^^^^^^^^^^^^^^^^^^^^^^^^^^^^^^^^^^^^^^^^^^^^^^^^^^^^^\n  File \"/opt/hostedtoolcache/Python/3.12.10/x64/lib/python3.12/site-packages/galaxy/tool_util/verify/interactor.py\", line 839, in _state_ready\n    raise Exception(\nException: Job in error state.. tool_id: __DATA_FETCH__, exit_code: None, stderr: .\n", "status": "error", "test_index": 0, "time_seconds": 11.310503721237183, "tool_id": "vcfsort", "tool_version": "1.0.0_rc3+galaxy0"}
            ]]></error>
        
    </testcase>
    
    <testcase classname="volcanoplot (Test #1)" name="0" time="10.895628929138184">
        
            <error type="error" message="Input staging problem: Traceback (most recent call last):
  File "/opt/hostedtoolcache/Python/3.12.10/x64/lib/python3.12/site-packages/galaxy/tool_util/verify/interactor.py", line 1434, in verify_tool
    stage_data_in_history(
  File "/opt/hostedtoolcache/Python/3.12.10/x64/lib/python3.12/site-packages/galaxy/tool_util/verify/interactor.py", line 175, in stage_data_in_history
    staging_interface.handle_jobs()
  File "/opt/hostedtoolcache/Python/3.12.10/x64/lib/python3.12/site-packages/galaxy/tool_util/verify/interactor.py", line 212, in handle_jobs
    self.galaxy_interactor.wait_for_job(job_response["id"], job_response["history_id"], self.maxseconds)
  File "/opt/hostedtoolcache/Python/3.12.10/x64/lib/python3.12/site-packages/galaxy/tool_util/verify/interactor.py", line 399, in wait_for_job
    self.wait_for(lambda: self.__job_ready(job_id, history_id), maxseconds=maxseconds)
  File "/opt/hostedtoolcache/Python/3.12.10/x64/lib/python3.12/site-packages/galaxy/tool_util/verify/interactor.py", line 403, in wait_for
    wait_on(func, what, walltime_exceeded)
  File "/opt/hostedtoolcache/Python/3.12.10/x64/lib/python3.12/site-packages/galaxy/tool_util/verify/wait.py", line 38, in wait_on
    value = function()
            ^^^^^^^^^^
  File "/opt/hostedtoolcache/Python/3.12.10/x64/lib/python3.12/site-packages/galaxy/tool_util/verify/interactor.py", line 399, in <lambda>
    self.wait_for(lambda: self.__job_ready(job_id, history_id), maxseconds=maxseconds)
                          ^^^^^^^^^^^^^^^^^^^^^^^^^^^^^^^^^^^^
  File "/opt/hostedtoolcache/Python/3.12.10/x64/lib/python3.12/site-packages/galaxy/tool_util/verify/interactor.py", line 747, in __job_ready
    return self._state_ready(job_id, error_msg="Job in error state.")
           ^^^^^^^^^^^^^^^^^^^^^^^^^^^^^^^^^^^^^^^^^^^^^^^^^^^^^^^^^^
  File "/opt/hostedtoolcache/Python/3.12.10/x64/lib/python3.12/site-packages/galaxy/tool_util/verify/interactor.py", line 839, in _state_ready
    raise Exception(
Exception: Job in error state.. tool_id: __DATA_FETCH__, exit_code: None, stderr: .
"><![CDATA[
                { "execution_problem": "Input staging problem: Traceback (most recent call last):\n  File \"/opt/hostedtoolcache/Python/3.12.10/x64/lib/python3.12/site-packages/galaxy/tool_util/verify/interactor.py\", line 1434, in verify_tool\n    stage_data_in_history(\n  File \"/opt/hostedtoolcache/Python/3.12.10/x64/lib/python3.12/site-packages/galaxy/tool_util/verify/interactor.py\", line 175, in stage_data_in_history\n    staging_interface.handle_jobs()\n  File \"/opt/hostedtoolcache/Python/3.12.10/x64/lib/python3.12/site-packages/galaxy/tool_util/verify/interactor.py\", line 212, in handle_jobs\n    self.galaxy_interactor.wait_for_job(job_response[\"id\"], job_response[\"history_id\"], self.maxseconds)\n  File \"/opt/hostedtoolcache/Python/3.12.10/x64/lib/python3.12/site-packages/galaxy/tool_util/verify/interactor.py\", line 399, in wait_for_job\n    self.wait_for(lambda: self.__job_ready(job_id, history_id), maxseconds=maxseconds)\n  File \"/opt/hostedtoolcache/Python/3.12.10/x64/lib/python3.12/site-packages/galaxy/tool_util/verify/interactor.py\", line 403, in wait_for\n    wait_on(func, what, walltime_exceeded)\n  File \"/opt/hostedtoolcache/Python/3.12.10/x64/lib/python3.12/site-packages/galaxy/tool_util/verify/wait.py\", line 38, in wait_on\n    value = function()\n            ^^^^^^^^^^\n  File \"/opt/hostedtoolcache/Python/3.12.10/x64/lib/python3.12/site-packages/galaxy/tool_util/verify/interactor.py\", line 399, in \u003clambda\u003e\n    self.wait_for(lambda: self.__job_ready(job_id, history_id), maxseconds=maxseconds)\n                          ^^^^^^^^^^^^^^^^^^^^^^^^^^^^^^^^^^^^\n  File \"/opt/hostedtoolcache/Python/3.12.10/x64/lib/python3.12/site-packages/galaxy/tool_util/verify/interactor.py\", line 747, in __job_ready\n    return self._state_ready(job_id, error_msg=\"Job in error state.\")\n           ^^^^^^^^^^^^^^^^^^^^^^^^^^^^^^^^^^^^^^^^^^^^^^^^^^^^^^^^^^\n  File \"/opt/hostedtoolcache/Python/3.12.10/x64/lib/python3.12/site-packages/galaxy/tool_util/verify/interactor.py\", line 839, in _state_ready\n    raise Exception(\nException: Job in error state.. tool_id: __DATA_FETCH__, exit_code: None, stderr: .\n", "status": "error", "test_index": 0, "time_seconds": 10.895628929138184, "tool_id": "volcanoplot", "tool_version": "0.0.7"}
            ]]></error>
        
    </testcase>
    
    <testcase classname="volcanoplot (Test #2)" name="1" time="61.05155420303345">
        
            
            <system-out><![CDATA[
            [1] "Header row detected"null device           1 R version 4.0.5 (2021-03-31)Platform: x86_64-conda-linux-gnu (64-bit)Running under: Debian GNU/Linux 10 (buster)Matrix products: defaultBLAS/LAPACK: /usr/local/lib/libopenblasp-r0.3.15.solocale: [1] LC_CTYPE=C.UTF-8       LC_NUMERIC=C           LC_TIME=C.UTF-8        [4] LC_COLLATE=C.UTF-8     LC_MONETARY=C.UTF-8    LC_MESSAGES=C.UTF-8    [7] LC_PAPER=C.UTF-8       LC_NAME=C              LC_ADDRESS=C          [10] LC_TELEPHONE=C         LC_MEASUREMENT=C.UTF-8 LC_IDENTIFICATION=C   attached base packages:[1] stats     graphics  grDevices utils     datasets  methods   base     other attached packages:[1] ggrepel_0.9.1 ggplot2_3.3.3 dplyr_1.0.6  loaded via a namespace (and not attached): [1] Rcpp_1.0.6       magrittr_2.0.1   tidyselect_1.1.1 munsell_0.5.0    [5] colorspace_2.0-1 R6_2.5.0         rlang_0.4.11     fansi_0.5.0      [9] grid_4.0.5       gtable_0.3.0     utf8_1.2.1       withr_2.4.2     [13] ellipsis_0.3.2   digest_0.6.27    tibble_3.1.2     lifecycle_1.0.0 [17] crayon_1.4.1     purrr_0.3.4      farver_2.1.0     vctrs_0.3.8     [21] glue_1.4.2       labeling_0.4.2   compiler_4.0.5   pillar_1.6.1    [25] generics_0.1.0   scales_1.1.1     pkgconfig_2.0.3 
            ]]></system-out>
            <system-err><![CDATA[
            Warning message:In Sys.setlocale("LC_MESSAGES", "en_US.UTF-8") :  OS reports request to set locale to "en_US.UTF-8" cannot be honored
            ]]></system-err>
        
    </testcase>
    
    <testcase classname="volcanoplot (Test #3)" name="2" time="38.43975353240967">
        
            
            <system-out><![CDATA[
            null device           1 R version 4.0.5 (2021-03-31)Platform: x86_64-conda-linux-gnu (64-bit)Running under: Debian GNU/Linux 10 (buster)Matrix products: defaultBLAS/LAPACK: /usr/local/lib/libopenblasp-r0.3.15.solocale: [1] LC_CTYPE=C.UTF-8       LC_NUMERIC=C           LC_TIME=C.UTF-8        [4] LC_COLLATE=C.UTF-8     LC_MONETARY=C.UTF-8    LC_MESSAGES=C.UTF-8    [7] LC_PAPER=C.UTF-8       LC_NAME=C              LC_ADDRESS=C          [10] LC_TELEPHONE=C         LC_MEASUREMENT=C.UTF-8 LC_IDENTIFICATION=C   attached base packages:[1] stats     graphics  grDevices utils     datasets  methods   base     other attached packages:[1] ggrepel_0.9.1 ggplot2_3.3.3 dplyr_1.0.6  loaded via a namespace (and not attached): [1] Rcpp_1.0.6       magrittr_2.0.1   tidyselect_1.1.1 munsell_0.5.0    [5] colorspace_2.0-1 R6_2.5.0         rlang_0.4.11     fansi_0.5.0      [9] grid_4.0.5       gtable_0.3.0     utf8_1.2.1       withr_2.4.2     [13] ellipsis_0.3.2   digest_0.6.27    tibble_3.1.2     lifecycle_1.0.0 [17] crayon_1.4.1     purrr_0.3.4      farver_2.1.0     vctrs_0.3.8     [21] glue_1.4.2       labeling_0.4.2   compiler_4.0.5   pillar_1.6.1    [25] generics_0.1.0   scales_1.1.1     pkgconfig_2.0.3 
            ]]></system-out>
            <system-err><![CDATA[
            Warning message:In Sys.setlocale("LC_MESSAGES", "en_US.UTF-8") :  OS reports request to set locale to "en_US.UTF-8" cannot be honored
            ]]></system-err>
        
    </testcase>
    
    <testcase classname="volcanoplot (Test #4)" name="3" time="37.94664430618286">
        
            
            <system-out><![CDATA[
            [1] "Header row detected"null device           1 R version 4.0.5 (2021-03-31)Platform: x86_64-conda-linux-gnu (64-bit)Running under: Debian GNU/Linux 10 (buster)Matrix products: defaultBLAS/LAPACK: /usr/local/lib/libopenblasp-r0.3.15.solocale: [1] LC_CTYPE=C.UTF-8       LC_NUMERIC=C           LC_TIME=C.UTF-8        [4] LC_COLLATE=C.UTF-8     LC_MONETARY=C.UTF-8    LC_MESSAGES=C.UTF-8    [7] LC_PAPER=C.UTF-8       LC_NAME=C              LC_ADDRESS=C          [10] LC_TELEPHONE=C         LC_MEASUREMENT=C.UTF-8 LC_IDENTIFICATION=C   attached base packages:[1] stats     graphics  grDevices utils     datasets  methods   base     other attached packages:[1] ggrepel_0.9.1 ggplot2_3.3.3 dplyr_1.0.6  loaded via a namespace (and not attached): [1] Rcpp_1.0.6       magrittr_2.0.1   tidyselect_1.1.1 munsell_0.5.0    [5] colorspace_2.0-1 R6_2.5.0         rlang_0.4.11     fansi_0.5.0      [9] grid_4.0.5       gtable_0.3.0     utf8_1.2.1       withr_2.4.2     [13] ellipsis_0.3.2   digest_0.6.27    tibble_3.1.2     lifecycle_1.0.0 [17] crayon_1.4.1     purrr_0.3.4      farver_2.1.0     vctrs_0.3.8     [21] glue_1.4.2       labeling_0.4.2   compiler_4.0.5   pillar_1.6.1    [25] generics_0.1.0   scales_1.1.1     pkgconfig_2.0.3 
            ]]></system-out>
            <system-err><![CDATA[
            Warning message:In Sys.setlocale("LC_MESSAGES", "en_US.UTF-8") :  OS reports request to set locale to "en_US.UTF-8" cannot be honored
            ]]></system-err>
        
    </testcase>
    
    <testcase classname="volcanoplot (Test #5)" name="4" time="36.852484464645386">
        
            
            <system-out><![CDATA[
            [1] "Header row detected"null device           1 R version 4.0.5 (2021-03-31)Platform: x86_64-conda-linux-gnu (64-bit)Running under: Debian GNU/Linux 10 (buster)Matrix products: defaultBLAS/LAPACK: /usr/local/lib/libopenblasp-r0.3.15.solocale: [1] LC_CTYPE=C.UTF-8       LC_NUMERIC=C           LC_TIME=C.UTF-8        [4] LC_COLLATE=C.UTF-8     LC_MONETARY=C.UTF-8    LC_MESSAGES=C.UTF-8    [7] LC_PAPER=C.UTF-8       LC_NAME=C              LC_ADDRESS=C          [10] LC_TELEPHONE=C         LC_MEASUREMENT=C.UTF-8 LC_IDENTIFICATION=C   attached base packages:[1] stats     graphics  grDevices utils     datasets  methods   base     other attached packages:[1] ggrepel_0.9.1 ggplot2_3.3.3 dplyr_1.0.6  loaded via a namespace (and not attached): [1] Rcpp_1.0.6       magrittr_2.0.1   tidyselect_1.1.1 munsell_0.5.0    [5] colorspace_2.0-1 R6_2.5.0         rlang_0.4.11     fansi_0.5.0      [9] grid_4.0.5       gtable_0.3.0     utf8_1.2.1       withr_2.4.2     [13] ellipsis_0.3.2   digest_0.6.27    tibble_3.1.2     lifecycle_1.0.0 [17] crayon_1.4.1     purrr_0.3.4      farver_2.1.0     vctrs_0.3.8     [21] glue_1.4.2       labeling_0.4.2   compiler_4.0.5   pillar_1.6.1    [25] generics_0.1.0   scales_1.1.1     pkgconfig_2.0.3 
            ]]></system-out>
            <system-err><![CDATA[
            Warning message:In Sys.setlocale("LC_MESSAGES", "en_US.UTF-8") :  OS reports request to set locale to "en_US.UTF-8" cannot be honored
            ]]></system-err>
        
    </testcase>
    
</testsuite>