<?xml version="1.0" encoding="UTF-8"?>
<testsuite name="Results (powered by Planemo)"
           tests="45"
           errors="14"
           failures="4"
           skip="0">
    
    <testcase classname="bcftools_cnv (Test #1)" name="0" time="72.82420063018799">
        
            
            <system-out><![CDATA[
            
            ]]></system-out>
            <system-err><![CDATA[
            Number of lines: total/processed: 184/184
            ]]></system-err>
        
    </testcase>
    
    <testcase classname="bcftools_cnv (Test #2)" name="1" time="37.852030754089355">
        
            
            <system-out><![CDATA[
            
            ]]></system-out>
            <system-err><![CDATA[
            Number of lines: total/processed: 184/184
            ]]></system-err>
        
    </testcase>
    
    <testcase classname="bcftools_cnv (Test #3)" name="2" time="44.83878946304321">
        
            
            <system-out><![CDATA[
            
            ]]></system-out>
            <system-err><![CDATA[
            Number of lines: total/processed: 184/184
            ]]></system-err>
        
    </testcase>
    
    <testcase classname="bcftools_cnv (Test #4)" name="3" time="36.532596588134766">
        
            
            <system-out><![CDATA[
            
            ]]></system-out>
            <system-err><![CDATA[
            Number of lines: total/processed: 184/184
            ]]></system-err>
        
    </testcase>
    
    <testcase classname="bcftools_cnv (Test #5)" name="4" time="38.754419565200806">
        
            
            <system-out><![CDATA[
            
            ]]></system-out>
            <system-err><![CDATA[
            Number of lines: total/processed: 184/184
            ]]></system-err>
        
    </testcase>
    
    <testcase classname="bcftools_roh (Test #1)" name="0" time="44.587005376815796">
        
            
            <system-out><![CDATA[
            
            ]]></system-out>
            <system-err><![CDATA[
            Number of target samples: 1Number of --estimate-AF samples: 0Number of sites in the buffer/overlap: unlimitedNumber of lines total/processed: 8890/8889Number of lines filtered/no AF/no alt/multiallelic/dup: 0/0/0/1/0
            ]]></system-err>
        
    </testcase>
    
    <testcase classname="bcftools_roh (Test #2)" name="1" time="38.10777807235718">
        
            
            <system-out><![CDATA[
            
            ]]></system-out>
            <system-err><![CDATA[
            Number of target samples: 1Number of --estimate-AF samples: 0Number of sites in the buffer/overlap: unlimitedNumber of lines total/processed: 8890/8889Number of lines filtered/no AF/no alt/multiallelic/dup: 0/0/0/1/0
            ]]></system-err>
        
    </testcase>
    
    <testcase classname="bcftools_roh (Test #3)" name="2" time="36.2423734664917">
        
            
            <system-out><![CDATA[
            
            ]]></system-out>
            <system-err><![CDATA[
            Number of target samples: 1Number of --estimate-AF samples: 0Number of sites in the buffer/overlap: unlimitedNumber of lines total/processed: 8890/8889Number of lines filtered/no AF/no alt/multiallelic/dup: 0/0/0/1/0
            ]]></system-err>
        
    </testcase>
    
    <testcase classname="bcftools_roh (Test #4)" name="3" time="37.240293741226196">
        
            
            <system-out><![CDATA[
            
            ]]></system-out>
            <system-err><![CDATA[
            Number of target samples: 1Number of --estimate-AF samples: 0Number of sites in the buffer/overlap: unlimitedNumber of lines total/processed: 8890/8889Number of lines filtered/no AF/no alt/multiallelic/dup: 0/0/0/1/0
            ]]></system-err>
        
    </testcase>
    
    <testcase classname="deeptools_bam_coverage (Test #1)" name="0" time="38.89045214653015">
        
            
            <system-out><![CDATA[
            
            ]]></system-out>
            <system-err><![CDATA[
            bamFilesList: ['one.bam']binLength: 10numberOfSamples: NoneblackListFileName: NoneskipZeroOverZero: Falsebed_and_bin: FalsegenomeChunkSize: NonedefaultFragmentLength: read lengthnumberOfProcessors: 8verbose: Falseregion: NonebedFile: NoneminMappingQuality: NoneignoreDuplicates: FalsechrsToSkip: []stepSize: 10center_read: FalsesamFlag_include: NonesamFlag_exclude: NoneminFragmentLength: 0maxFragmentLength: 0zerosToNans: FalsesmoothLength: Nonesave_data: Falseout_file_for_raw_data: NonemaxPairedFragmentLength: 1000
            ]]></system-err>
        
    </testcase>
    
    <testcase classname="deeptools_bam_coverage (Test #2)" name="1" time="39.51619362831116">
        
            
            <system-out><![CDATA[
            
            ]]></system-out>
            <system-err><![CDATA[
            normalization: 1x (effective genome size 2451960000)bamFilesList: ['one.bam']binLength: 10numberOfSamples: NoneblackListFileName: NoneskipZeroOverZero: Falsebed_and_bin: FalsegenomeChunkSize: NonedefaultFragmentLength: read lengthnumberOfProcessors: 8verbose: Falseregion: NonebedFile: NoneminMappingQuality: NoneignoreDuplicates: FalsechrsToSkip: []stepSize: 10center_read: FalsesamFlag_include: NonesamFlag_exclude: NoneminFragmentLength: 0maxFragmentLength: 0zerosToNans: FalsesmoothLength: Nonesave_data: Falseout_file_for_raw_data: NonemaxPairedFragmentLength: 1000
            ]]></system-err>
        
    </testcase>
    
    <testcase classname="deeptools_bam_coverage (Test #3)" name="2" time="37.28748917579651">
        
            
            <system-out><![CDATA[
            
            ]]></system-out>
            <system-err><![CDATA[
            normalization: 1x (effective genome size 2451960000)bamFilesList: ['one.bam']binLength: 10numberOfSamples: NoneblackListFileName: NoneskipZeroOverZero: Falsebed_and_bin: FalsegenomeChunkSize: NonedefaultFragmentLength: read lengthnumberOfProcessors: 8verbose: Falseregion: NonebedFile: NoneminMappingQuality: NoneignoreDuplicates: FalsechrsToSkip: []stepSize: 10center_read: FalsesamFlag_include: NonesamFlag_exclude: NoneminFragmentLength: 0maxFragmentLength: 0zerosToNans: FalsesmoothLength: Nonesave_data: Falseout_file_for_raw_data: NonemaxPairedFragmentLength: 1000
            ]]></system-err>
        
    </testcase>
    
    <testcase classname="deeptools_bam_coverage (Test #4)" name="3" time="39.19441509246826">
        
            
            <system-out><![CDATA[
            
            ]]></system-out>
            <system-err><![CDATA[
            normalization: 1x (effective genome size 2451960000)bamFilesList: ['one.bam']binLength: 10numberOfSamples: NoneblackListFileName: NoneskipZeroOverZero: Falsebed_and_bin: FalsegenomeChunkSize: NonedefaultFragmentLength: read lengthnumberOfProcessors: 8verbose: Falseregion: NonebedFile: NoneminMappingQuality: NoneignoreDuplicates: FalsechrsToSkip: []stepSize: 10center_read: FalsesamFlag_include: NonesamFlag_exclude: NoneminFragmentLength: 0maxFragmentLength: 0zerosToNans: FalsesmoothLength: Nonesave_data: Falseout_file_for_raw_data: NonemaxPairedFragmentLength: 1000
            ]]></system-err>
        
    </testcase>
    
    <testcase classname="deeptools_bam_coverage (Test #5)" name="4" time="12.184536933898926">
        
            <error type="error" message="Input staging problem: Traceback (most recent call last):
  File "/opt/hostedtoolcache/Python/3.12.9/x64/lib/python3.12/site-packages/galaxy/tool_util/verify/interactor.py", line 1434, in verify_tool
    stage_data_in_history(
  File "/opt/hostedtoolcache/Python/3.12.9/x64/lib/python3.12/site-packages/galaxy/tool_util/verify/interactor.py", line 175, in stage_data_in_history
    staging_interface.handle_jobs()
  File "/opt/hostedtoolcache/Python/3.12.9/x64/lib/python3.12/site-packages/galaxy/tool_util/verify/interactor.py", line 212, in handle_jobs
    self.galaxy_interactor.wait_for_job(job_response["id"], job_response["history_id"], self.maxseconds)
  File "/opt/hostedtoolcache/Python/3.12.9/x64/lib/python3.12/site-packages/galaxy/tool_util/verify/interactor.py", line 399, in wait_for_job
    self.wait_for(lambda: self.__job_ready(job_id, history_id), maxseconds=maxseconds)
  File "/opt/hostedtoolcache/Python/3.12.9/x64/lib/python3.12/site-packages/galaxy/tool_util/verify/interactor.py", line 403, in wait_for
    wait_on(func, what, walltime_exceeded)
  File "/opt/hostedtoolcache/Python/3.12.9/x64/lib/python3.12/site-packages/galaxy/tool_util/verify/wait.py", line 38, in wait_on
    value = function()
            ^^^^^^^^^^
  File "/opt/hostedtoolcache/Python/3.12.9/x64/lib/python3.12/site-packages/galaxy/tool_util/verify/interactor.py", line 399, in <lambda>
    self.wait_for(lambda: self.__job_ready(job_id, history_id), maxseconds=maxseconds)
                          ^^^^^^^^^^^^^^^^^^^^^^^^^^^^^^^^^^^^
  File "/opt/hostedtoolcache/Python/3.12.9/x64/lib/python3.12/site-packages/galaxy/tool_util/verify/interactor.py", line 747, in __job_ready
    return self._state_ready(job_id, error_msg="Job in error state.")
           ^^^^^^^^^^^^^^^^^^^^^^^^^^^^^^^^^^^^^^^^^^^^^^^^^^^^^^^^^^
  File "/opt/hostedtoolcache/Python/3.12.9/x64/lib/python3.12/site-packages/galaxy/tool_util/verify/interactor.py", line 839, in _state_ready
    raise Exception(
Exception: Job in error state.. tool_id: __DATA_FETCH__, exit_code: None, stderr: .
"><![CDATA[
                { "execution_problem": "Input staging problem: Traceback (most recent call last):\n  File \"/opt/hostedtoolcache/Python/3.12.9/x64/lib/python3.12/site-packages/galaxy/tool_util/verify/interactor.py\", line 1434, in verify_tool\n    stage_data_in_history(\n  File \"/opt/hostedtoolcache/Python/3.12.9/x64/lib/python3.12/site-packages/galaxy/tool_util/verify/interactor.py\", line 175, in stage_data_in_history\n    staging_interface.handle_jobs()\n  File \"/opt/hostedtoolcache/Python/3.12.9/x64/lib/python3.12/site-packages/galaxy/tool_util/verify/interactor.py\", line 212, in handle_jobs\n    self.galaxy_interactor.wait_for_job(job_response[\"id\"], job_response[\"history_id\"], self.maxseconds)\n  File \"/opt/hostedtoolcache/Python/3.12.9/x64/lib/python3.12/site-packages/galaxy/tool_util/verify/interactor.py\", line 399, in wait_for_job\n    self.wait_for(lambda: self.__job_ready(job_id, history_id), maxseconds=maxseconds)\n  File \"/opt/hostedtoolcache/Python/3.12.9/x64/lib/python3.12/site-packages/galaxy/tool_util/verify/interactor.py\", line 403, in wait_for\n    wait_on(func, what, walltime_exceeded)\n  File \"/opt/hostedtoolcache/Python/3.12.9/x64/lib/python3.12/site-packages/galaxy/tool_util/verify/wait.py\", line 38, in wait_on\n    value = function()\n            ^^^^^^^^^^\n  File \"/opt/hostedtoolcache/Python/3.12.9/x64/lib/python3.12/site-packages/galaxy/tool_util/verify/interactor.py\", line 399, in \u003clambda\u003e\n    self.wait_for(lambda: self.__job_ready(job_id, history_id), maxseconds=maxseconds)\n                          ^^^^^^^^^^^^^^^^^^^^^^^^^^^^^^^^^^^^\n  File \"/opt/hostedtoolcache/Python/3.12.9/x64/lib/python3.12/site-packages/galaxy/tool_util/verify/interactor.py\", line 747, in __job_ready\n    return self._state_ready(job_id, error_msg=\"Job in error state.\")\n           ^^^^^^^^^^^^^^^^^^^^^^^^^^^^^^^^^^^^^^^^^^^^^^^^^^^^^^^^^^\n  File \"/opt/hostedtoolcache/Python/3.12.9/x64/lib/python3.12/site-packages/galaxy/tool_util/verify/interactor.py\", line 839, in _state_ready\n    raise Exception(\nException: Job in error state.. tool_id: __DATA_FETCH__, exit_code: None, stderr: .\n", "status": "error", "test_index": 4, "time_seconds": 12.184536933898926, "tool_id": "deeptools_bam_coverage", "tool_version": "3.5.4+galaxy0"}
            ]]></error>
        
    </testcase>
    
    <testcase classname="deeptools_bam_coverage (Test #6)" name="5" time="38.95093131065369">
        
            
            <system-out><![CDATA[
            Due to filtering, 51.08108108108108% of the aforementioned alignments will be used 1115.6108108108108
            ]]></system-out>
            <system-err><![CDATA[
            normalization: 1x (effective genome size 2451960000)bamFilesList: ['one.bam']binLength: 10numberOfSamples: NoneblackListFileName: NoneskipZeroOverZero: Falsebed_and_bin: FalsegenomeChunkSize: NonedefaultFragmentLength: read lengthnumberOfProcessors: 8verbose: Falseregion: NonebedFile: NoneminMappingQuality: 1ignoreDuplicates: FalsechrsToSkip: []stepSize: 10center_read: FalsesamFlag_include: NonesamFlag_exclude: NoneminFragmentLength: 0maxFragmentLength: 0zerosToNans: FalsesmoothLength: Nonesave_data: Falseout_file_for_raw_data: NonemaxPairedFragmentLength: 1000filter_strand: reverseOffset: [1, -1]
            ]]></system-err>
        
    </testcase>
    
    <testcase classname="deeptools_bam_coverage (Test #7)" name="6" time="38.51913857460022">
        
            
            <system-out><![CDATA[
            
            ]]></system-out>
            <system-err><![CDATA[
            bamFilesList: ['one.bam']binLength: 10numberOfSamples: NoneblackListFileName: NoneskipZeroOverZero: Falsebed_and_bin: FalsegenomeChunkSize: NonedefaultFragmentLength: 242numberOfProcessors: 8verbose: Falseregion: NonebedFile: NoneminMappingQuality: NoneignoreDuplicates: FalsechrsToSkip: []stepSize: 10center_read: FalsesamFlag_include: NonesamFlag_exclude: NoneminFragmentLength: 0maxFragmentLength: 0zerosToNans: FalsesmoothLength: Nonesave_data: Falseout_file_for_raw_data: NonemaxPairedFragmentLength: 968filter_strand: NoneOffset: [-4, -1]
            ]]></system-err>
        
    </testcase>
    
    <testcase classname="deeptools_compute_matrix (Test #1)" name="0" time="58.68304371833801">
        
            
            <system-out><![CDATA[
            
            ]]></system-out>
            <system-err><![CDATA[
            
            ]]></system-err>
        
    </testcase>
    
    <testcase classname="deeptools_compute_matrix (Test #2)" name="1" time="22.580681085586548">
        
            <error type="error" message="Input staging problem: Traceback (most recent call last):
  File "/opt/hostedtoolcache/Python/3.12.9/x64/lib/python3.12/site-packages/galaxy/tool_util/verify/interactor.py", line 1434, in verify_tool
    stage_data_in_history(
  File "/opt/hostedtoolcache/Python/3.12.9/x64/lib/python3.12/site-packages/galaxy/tool_util/verify/interactor.py", line 175, in stage_data_in_history
    staging_interface.handle_jobs()
  File "/opt/hostedtoolcache/Python/3.12.9/x64/lib/python3.12/site-packages/galaxy/tool_util/verify/interactor.py", line 212, in handle_jobs
    self.galaxy_interactor.wait_for_job(job_response["id"], job_response["history_id"], self.maxseconds)
  File "/opt/hostedtoolcache/Python/3.12.9/x64/lib/python3.12/site-packages/galaxy/tool_util/verify/interactor.py", line 399, in wait_for_job
    self.wait_for(lambda: self.__job_ready(job_id, history_id), maxseconds=maxseconds)
  File "/opt/hostedtoolcache/Python/3.12.9/x64/lib/python3.12/site-packages/galaxy/tool_util/verify/interactor.py", line 403, in wait_for
    wait_on(func, what, walltime_exceeded)
  File "/opt/hostedtoolcache/Python/3.12.9/x64/lib/python3.12/site-packages/galaxy/tool_util/verify/wait.py", line 38, in wait_on
    value = function()
            ^^^^^^^^^^
  File "/opt/hostedtoolcache/Python/3.12.9/x64/lib/python3.12/site-packages/galaxy/tool_util/verify/interactor.py", line 399, in <lambda>
    self.wait_for(lambda: self.__job_ready(job_id, history_id), maxseconds=maxseconds)
                          ^^^^^^^^^^^^^^^^^^^^^^^^^^^^^^^^^^^^
  File "/opt/hostedtoolcache/Python/3.12.9/x64/lib/python3.12/site-packages/galaxy/tool_util/verify/interactor.py", line 747, in __job_ready
    return self._state_ready(job_id, error_msg="Job in error state.")
           ^^^^^^^^^^^^^^^^^^^^^^^^^^^^^^^^^^^^^^^^^^^^^^^^^^^^^^^^^^
  File "/opt/hostedtoolcache/Python/3.12.9/x64/lib/python3.12/site-packages/galaxy/tool_util/verify/interactor.py", line 839, in _state_ready
    raise Exception(
Exception: Job in error state.. tool_id: __DATA_FETCH__, exit_code: None, stderr: .
"><![CDATA[
                { "execution_problem": "Input staging problem: Traceback (most recent call last):\n  File \"/opt/hostedtoolcache/Python/3.12.9/x64/lib/python3.12/site-packages/galaxy/tool_util/verify/interactor.py\", line 1434, in verify_tool\n    stage_data_in_history(\n  File \"/opt/hostedtoolcache/Python/3.12.9/x64/lib/python3.12/site-packages/galaxy/tool_util/verify/interactor.py\", line 175, in stage_data_in_history\n    staging_interface.handle_jobs()\n  File \"/opt/hostedtoolcache/Python/3.12.9/x64/lib/python3.12/site-packages/galaxy/tool_util/verify/interactor.py\", line 212, in handle_jobs\n    self.galaxy_interactor.wait_for_job(job_response[\"id\"], job_response[\"history_id\"], self.maxseconds)\n  File \"/opt/hostedtoolcache/Python/3.12.9/x64/lib/python3.12/site-packages/galaxy/tool_util/verify/interactor.py\", line 399, in wait_for_job\n    self.wait_for(lambda: self.__job_ready(job_id, history_id), maxseconds=maxseconds)\n  File \"/opt/hostedtoolcache/Python/3.12.9/x64/lib/python3.12/site-packages/galaxy/tool_util/verify/interactor.py\", line 403, in wait_for\n    wait_on(func, what, walltime_exceeded)\n  File \"/opt/hostedtoolcache/Python/3.12.9/x64/lib/python3.12/site-packages/galaxy/tool_util/verify/wait.py\", line 38, in wait_on\n    value = function()\n            ^^^^^^^^^^\n  File \"/opt/hostedtoolcache/Python/3.12.9/x64/lib/python3.12/site-packages/galaxy/tool_util/verify/interactor.py\", line 399, in \u003clambda\u003e\n    self.wait_for(lambda: self.__job_ready(job_id, history_id), maxseconds=maxseconds)\n                          ^^^^^^^^^^^^^^^^^^^^^^^^^^^^^^^^^^^^\n  File \"/opt/hostedtoolcache/Python/3.12.9/x64/lib/python3.12/site-packages/galaxy/tool_util/verify/interactor.py\", line 747, in __job_ready\n    return self._state_ready(job_id, error_msg=\"Job in error state.\")\n           ^^^^^^^^^^^^^^^^^^^^^^^^^^^^^^^^^^^^^^^^^^^^^^^^^^^^^^^^^^\n  File \"/opt/hostedtoolcache/Python/3.12.9/x64/lib/python3.12/site-packages/galaxy/tool_util/verify/interactor.py\", line 839, in _state_ready\n    raise Exception(\nException: Job in error state.. tool_id: __DATA_FETCH__, exit_code: None, stderr: .\n", "status": "error", "test_index": 1, "time_seconds": 22.580681085586548, "tool_id": "deeptools_compute_matrix", "tool_version": "3.5.4+galaxy0"}
            ]]></error>
        
    </testcase>
    
    <testcase classname="deeptools_compute_matrix (Test #3)" name="2" time="21.59241247177124">
        
            <error type="error" message="Input staging problem: Traceback (most recent call last):
  File "/opt/hostedtoolcache/Python/3.12.9/x64/lib/python3.12/site-packages/galaxy/tool_util/verify/interactor.py", line 1434, in verify_tool
    stage_data_in_history(
  File "/opt/hostedtoolcache/Python/3.12.9/x64/lib/python3.12/site-packages/galaxy/tool_util/verify/interactor.py", line 175, in stage_data_in_history
    staging_interface.handle_jobs()
  File "/opt/hostedtoolcache/Python/3.12.9/x64/lib/python3.12/site-packages/galaxy/tool_util/verify/interactor.py", line 212, in handle_jobs
    self.galaxy_interactor.wait_for_job(job_response["id"], job_response["history_id"], self.maxseconds)
  File "/opt/hostedtoolcache/Python/3.12.9/x64/lib/python3.12/site-packages/galaxy/tool_util/verify/interactor.py", line 399, in wait_for_job
    self.wait_for(lambda: self.__job_ready(job_id, history_id), maxseconds=maxseconds)
  File "/opt/hostedtoolcache/Python/3.12.9/x64/lib/python3.12/site-packages/galaxy/tool_util/verify/interactor.py", line 403, in wait_for
    wait_on(func, what, walltime_exceeded)
  File "/opt/hostedtoolcache/Python/3.12.9/x64/lib/python3.12/site-packages/galaxy/tool_util/verify/wait.py", line 38, in wait_on
    value = function()
            ^^^^^^^^^^
  File "/opt/hostedtoolcache/Python/3.12.9/x64/lib/python3.12/site-packages/galaxy/tool_util/verify/interactor.py", line 399, in <lambda>
    self.wait_for(lambda: self.__job_ready(job_id, history_id), maxseconds=maxseconds)
                          ^^^^^^^^^^^^^^^^^^^^^^^^^^^^^^^^^^^^
  File "/opt/hostedtoolcache/Python/3.12.9/x64/lib/python3.12/site-packages/galaxy/tool_util/verify/interactor.py", line 747, in __job_ready
    return self._state_ready(job_id, error_msg="Job in error state.")
           ^^^^^^^^^^^^^^^^^^^^^^^^^^^^^^^^^^^^^^^^^^^^^^^^^^^^^^^^^^
  File "/opt/hostedtoolcache/Python/3.12.9/x64/lib/python3.12/site-packages/galaxy/tool_util/verify/interactor.py", line 839, in _state_ready
    raise Exception(
Exception: Job in error state.. tool_id: __DATA_FETCH__, exit_code: None, stderr: .
"><![CDATA[
                { "execution_problem": "Input staging problem: Traceback (most recent call last):\n  File \"/opt/hostedtoolcache/Python/3.12.9/x64/lib/python3.12/site-packages/galaxy/tool_util/verify/interactor.py\", line 1434, in verify_tool\n    stage_data_in_history(\n  File \"/opt/hostedtoolcache/Python/3.12.9/x64/lib/python3.12/site-packages/galaxy/tool_util/verify/interactor.py\", line 175, in stage_data_in_history\n    staging_interface.handle_jobs()\n  File \"/opt/hostedtoolcache/Python/3.12.9/x64/lib/python3.12/site-packages/galaxy/tool_util/verify/interactor.py\", line 212, in handle_jobs\n    self.galaxy_interactor.wait_for_job(job_response[\"id\"], job_response[\"history_id\"], self.maxseconds)\n  File \"/opt/hostedtoolcache/Python/3.12.9/x64/lib/python3.12/site-packages/galaxy/tool_util/verify/interactor.py\", line 399, in wait_for_job\n    self.wait_for(lambda: self.__job_ready(job_id, history_id), maxseconds=maxseconds)\n  File \"/opt/hostedtoolcache/Python/3.12.9/x64/lib/python3.12/site-packages/galaxy/tool_util/verify/interactor.py\", line 403, in wait_for\n    wait_on(func, what, walltime_exceeded)\n  File \"/opt/hostedtoolcache/Python/3.12.9/x64/lib/python3.12/site-packages/galaxy/tool_util/verify/wait.py\", line 38, in wait_on\n    value = function()\n            ^^^^^^^^^^\n  File \"/opt/hostedtoolcache/Python/3.12.9/x64/lib/python3.12/site-packages/galaxy/tool_util/verify/interactor.py\", line 399, in \u003clambda\u003e\n    self.wait_for(lambda: self.__job_ready(job_id, history_id), maxseconds=maxseconds)\n                          ^^^^^^^^^^^^^^^^^^^^^^^^^^^^^^^^^^^^\n  File \"/opt/hostedtoolcache/Python/3.12.9/x64/lib/python3.12/site-packages/galaxy/tool_util/verify/interactor.py\", line 747, in __job_ready\n    return self._state_ready(job_id, error_msg=\"Job in error state.\")\n           ^^^^^^^^^^^^^^^^^^^^^^^^^^^^^^^^^^^^^^^^^^^^^^^^^^^^^^^^^^\n  File \"/opt/hostedtoolcache/Python/3.12.9/x64/lib/python3.12/site-packages/galaxy/tool_util/verify/interactor.py\", line 839, in _state_ready\n    raise Exception(\nException: Job in error state.. tool_id: __DATA_FETCH__, exit_code: None, stderr: .\n", "status": "error", "test_index": 2, "time_seconds": 21.59241247177124, "tool_id": "deeptools_compute_matrix", "tool_version": "3.5.4+galaxy0"}
            ]]></error>
        
    </testcase>
    
    <testcase classname="fastqc (Test #1)" name="0" time="0.09913396835327148">
        
            <error type="error" message="Input staging problem: Traceback (most recent call last):
  File "/opt/hostedtoolcache/Python/3.12.9/x64/lib/python3.12/site-packages/galaxy/tool_util/verify/interactor.py", line 1434, in verify_tool
    stage_data_in_history(
  File "/opt/hostedtoolcache/Python/3.12.9/x64/lib/python3.12/site-packages/galaxy/tool_util/verify/interactor.py", line 163, in stage_data_in_history
    test_dict = galaxy_interactor.remote_to_input(
                ^^^^^^^^^^^^^^^^^^^^^^^^^^^^^^^^^^
  File "/opt/hostedtoolcache/Python/3.12.9/x64/lib/python3.12/site-packages/galaxy/tool_util/verify/interactor.py", line 582, in remote_to_input
    path_or_location = self._get_path_or_location(
                       ^^^^^^^^^^^^^^^^^^^^^^^^^^^
  File "/opt/hostedtoolcache/Python/3.12.9/x64/lib/python3.12/site-packages/galaxy/tool_util/verify/interactor.py", line 619, in _get_path_or_location
    path = self.test_data_download(
           ^^^^^^^^^^^^^^^^^^^^^^^^
  File "/opt/hostedtoolcache/Python/3.12.9/x64/lib/python3.12/site-packages/galaxy/tool_util/verify/interactor.py", line 525, in test_data_download
    raise AssertionError(f"Test input file ({filename}) cannot be found.")
AssertionError: Test input file (1000trimmed.fastq) cannot be found.
"><![CDATA[
                { "execution_problem": "Input staging problem: Traceback (most recent call last):\n  File \"/opt/hostedtoolcache/Python/3.12.9/x64/lib/python3.12/site-packages/galaxy/tool_util/verify/interactor.py\", line 1434, in verify_tool\n    stage_data_in_history(\n  File \"/opt/hostedtoolcache/Python/3.12.9/x64/lib/python3.12/site-packages/galaxy/tool_util/verify/interactor.py\", line 163, in stage_data_in_history\n    test_dict = galaxy_interactor.remote_to_input(\n                ^^^^^^^^^^^^^^^^^^^^^^^^^^^^^^^^^^\n  File \"/opt/hostedtoolcache/Python/3.12.9/x64/lib/python3.12/site-packages/galaxy/tool_util/verify/interactor.py\", line 582, in remote_to_input\n    path_or_location = self._get_path_or_location(\n                       ^^^^^^^^^^^^^^^^^^^^^^^^^^^\n  File \"/opt/hostedtoolcache/Python/3.12.9/x64/lib/python3.12/site-packages/galaxy/tool_util/verify/interactor.py\", line 619, in _get_path_or_location\n    path = self.test_data_download(\n           ^^^^^^^^^^^^^^^^^^^^^^^^\n  File \"/opt/hostedtoolcache/Python/3.12.9/x64/lib/python3.12/site-packages/galaxy/tool_util/verify/interactor.py\", line 525, in test_data_download\n    raise AssertionError(f\"Test input file ({filename}) cannot be found.\")\nAssertionError: Test input file (1000trimmed.fastq) cannot be found.\n", "status": "error", "test_index": 0, "time_seconds": 0.09913396835327148, "tool_id": "fastqc", "tool_version": "0.74+galaxy1"}
            ]]></error>
        
    </testcase>
    
    <testcase classname="fastqc (Test #2)" name="1" time="0.05402803421020508">
        
            <error type="error" message="Input staging problem: Traceback (most recent call last):
  File "/opt/hostedtoolcache/Python/3.12.9/x64/lib/python3.12/site-packages/galaxy/tool_util/verify/interactor.py", line 1434, in verify_tool
    stage_data_in_history(
  File "/opt/hostedtoolcache/Python/3.12.9/x64/lib/python3.12/site-packages/galaxy/tool_util/verify/interactor.py", line 163, in stage_data_in_history
    test_dict = galaxy_interactor.remote_to_input(
                ^^^^^^^^^^^^^^^^^^^^^^^^^^^^^^^^^^
  File "/opt/hostedtoolcache/Python/3.12.9/x64/lib/python3.12/site-packages/galaxy/tool_util/verify/interactor.py", line 582, in remote_to_input
    path_or_location = self._get_path_or_location(
                       ^^^^^^^^^^^^^^^^^^^^^^^^^^^
  File "/opt/hostedtoolcache/Python/3.12.9/x64/lib/python3.12/site-packages/galaxy/tool_util/verify/interactor.py", line 619, in _get_path_or_location
    path = self.test_data_download(
           ^^^^^^^^^^^^^^^^^^^^^^^^
  File "/opt/hostedtoolcache/Python/3.12.9/x64/lib/python3.12/site-packages/galaxy/tool_util/verify/interactor.py", line 525, in test_data_download
    raise AssertionError(f"Test input file ({filename}) cannot be found.")
AssertionError: Test input file (1000trimmed.fastq) cannot be found.
"><![CDATA[
                { "execution_problem": "Input staging problem: Traceback (most recent call last):\n  File \"/opt/hostedtoolcache/Python/3.12.9/x64/lib/python3.12/site-packages/galaxy/tool_util/verify/interactor.py\", line 1434, in verify_tool\n    stage_data_in_history(\n  File \"/opt/hostedtoolcache/Python/3.12.9/x64/lib/python3.12/site-packages/galaxy/tool_util/verify/interactor.py\", line 163, in stage_data_in_history\n    test_dict = galaxy_interactor.remote_to_input(\n                ^^^^^^^^^^^^^^^^^^^^^^^^^^^^^^^^^^\n  File \"/opt/hostedtoolcache/Python/3.12.9/x64/lib/python3.12/site-packages/galaxy/tool_util/verify/interactor.py\", line 582, in remote_to_input\n    path_or_location = self._get_path_or_location(\n                       ^^^^^^^^^^^^^^^^^^^^^^^^^^^\n  File \"/opt/hostedtoolcache/Python/3.12.9/x64/lib/python3.12/site-packages/galaxy/tool_util/verify/interactor.py\", line 619, in _get_path_or_location\n    path = self.test_data_download(\n           ^^^^^^^^^^^^^^^^^^^^^^^^\n  File \"/opt/hostedtoolcache/Python/3.12.9/x64/lib/python3.12/site-packages/galaxy/tool_util/verify/interactor.py\", line 525, in test_data_download\n    raise AssertionError(f\"Test input file ({filename}) cannot be found.\")\nAssertionError: Test input file (1000trimmed.fastq) cannot be found.\n", "status": "error", "test_index": 1, "time_seconds": 0.05402803421020508, "tool_id": "fastqc", "tool_version": "0.74+galaxy1"}
            ]]></error>
        
    </testcase>
    
    <testcase classname="fastqc (Test #3)" name="2" time="0.05626368522644043">
        
            <error type="error" message="Input staging problem: Traceback (most recent call last):
  File "/opt/hostedtoolcache/Python/3.12.9/x64/lib/python3.12/site-packages/galaxy/tool_util/verify/interactor.py", line 1434, in verify_tool
    stage_data_in_history(
  File "/opt/hostedtoolcache/Python/3.12.9/x64/lib/python3.12/site-packages/galaxy/tool_util/verify/interactor.py", line 163, in stage_data_in_history
    test_dict = galaxy_interactor.remote_to_input(
                ^^^^^^^^^^^^^^^^^^^^^^^^^^^^^^^^^^
  File "/opt/hostedtoolcache/Python/3.12.9/x64/lib/python3.12/site-packages/galaxy/tool_util/verify/interactor.py", line 582, in remote_to_input
    path_or_location = self._get_path_or_location(
                       ^^^^^^^^^^^^^^^^^^^^^^^^^^^
  File "/opt/hostedtoolcache/Python/3.12.9/x64/lib/python3.12/site-packages/galaxy/tool_util/verify/interactor.py", line 619, in _get_path_or_location
    path = self.test_data_download(
           ^^^^^^^^^^^^^^^^^^^^^^^^
  File "/opt/hostedtoolcache/Python/3.12.9/x64/lib/python3.12/site-packages/galaxy/tool_util/verify/interactor.py", line 525, in test_data_download
    raise AssertionError(f"Test input file ({filename}) cannot be found.")
AssertionError: Test input file (1000trimmed.fastq) cannot be found.
"><![CDATA[
                { "execution_problem": "Input staging problem: Traceback (most recent call last):\n  File \"/opt/hostedtoolcache/Python/3.12.9/x64/lib/python3.12/site-packages/galaxy/tool_util/verify/interactor.py\", line 1434, in verify_tool\n    stage_data_in_history(\n  File \"/opt/hostedtoolcache/Python/3.12.9/x64/lib/python3.12/site-packages/galaxy/tool_util/verify/interactor.py\", line 163, in stage_data_in_history\n    test_dict = galaxy_interactor.remote_to_input(\n                ^^^^^^^^^^^^^^^^^^^^^^^^^^^^^^^^^^\n  File \"/opt/hostedtoolcache/Python/3.12.9/x64/lib/python3.12/site-packages/galaxy/tool_util/verify/interactor.py\", line 582, in remote_to_input\n    path_or_location = self._get_path_or_location(\n                       ^^^^^^^^^^^^^^^^^^^^^^^^^^^\n  File \"/opt/hostedtoolcache/Python/3.12.9/x64/lib/python3.12/site-packages/galaxy/tool_util/verify/interactor.py\", line 619, in _get_path_or_location\n    path = self.test_data_download(\n           ^^^^^^^^^^^^^^^^^^^^^^^^\n  File \"/opt/hostedtoolcache/Python/3.12.9/x64/lib/python3.12/site-packages/galaxy/tool_util/verify/interactor.py\", line 525, in test_data_download\n    raise AssertionError(f\"Test input file ({filename}) cannot be found.\")\nAssertionError: Test input file (1000trimmed.fastq) cannot be found.\n", "status": "error", "test_index": 2, "time_seconds": 0.05626368522644043, "tool_id": "fastqc", "tool_version": "0.74+galaxy1"}
            ]]></error>
        
    </testcase>
    
    <testcase classname="fastqc (Test #4)" name="3" time="0.053493499755859375">
        
            <error type="error" message="Input staging problem: Traceback (most recent call last):
  File "/opt/hostedtoolcache/Python/3.12.9/x64/lib/python3.12/site-packages/galaxy/tool_util/verify/interactor.py", line 1434, in verify_tool
    stage_data_in_history(
  File "/opt/hostedtoolcache/Python/3.12.9/x64/lib/python3.12/site-packages/galaxy/tool_util/verify/interactor.py", line 163, in stage_data_in_history
    test_dict = galaxy_interactor.remote_to_input(
                ^^^^^^^^^^^^^^^^^^^^^^^^^^^^^^^^^^
  File "/opt/hostedtoolcache/Python/3.12.9/x64/lib/python3.12/site-packages/galaxy/tool_util/verify/interactor.py", line 582, in remote_to_input
    path_or_location = self._get_path_or_location(
                       ^^^^^^^^^^^^^^^^^^^^^^^^^^^
  File "/opt/hostedtoolcache/Python/3.12.9/x64/lib/python3.12/site-packages/galaxy/tool_util/verify/interactor.py", line 619, in _get_path_or_location
    path = self.test_data_download(
           ^^^^^^^^^^^^^^^^^^^^^^^^
  File "/opt/hostedtoolcache/Python/3.12.9/x64/lib/python3.12/site-packages/galaxy/tool_util/verify/interactor.py", line 525, in test_data_download
    raise AssertionError(f"Test input file ({filename}) cannot be found.")
AssertionError: Test input file (1000trimmed.fastq) cannot be found.
"><![CDATA[
                { "execution_problem": "Input staging problem: Traceback (most recent call last):\n  File \"/opt/hostedtoolcache/Python/3.12.9/x64/lib/python3.12/site-packages/galaxy/tool_util/verify/interactor.py\", line 1434, in verify_tool\n    stage_data_in_history(\n  File \"/opt/hostedtoolcache/Python/3.12.9/x64/lib/python3.12/site-packages/galaxy/tool_util/verify/interactor.py\", line 163, in stage_data_in_history\n    test_dict = galaxy_interactor.remote_to_input(\n                ^^^^^^^^^^^^^^^^^^^^^^^^^^^^^^^^^^\n  File \"/opt/hostedtoolcache/Python/3.12.9/x64/lib/python3.12/site-packages/galaxy/tool_util/verify/interactor.py\", line 582, in remote_to_input\n    path_or_location = self._get_path_or_location(\n                       ^^^^^^^^^^^^^^^^^^^^^^^^^^^\n  File \"/opt/hostedtoolcache/Python/3.12.9/x64/lib/python3.12/site-packages/galaxy/tool_util/verify/interactor.py\", line 619, in _get_path_or_location\n    path = self.test_data_download(\n           ^^^^^^^^^^^^^^^^^^^^^^^^\n  File \"/opt/hostedtoolcache/Python/3.12.9/x64/lib/python3.12/site-packages/galaxy/tool_util/verify/interactor.py\", line 525, in test_data_download\n    raise AssertionError(f\"Test input file ({filename}) cannot be found.\")\nAssertionError: Test input file (1000trimmed.fastq) cannot be found.\n", "status": "error", "test_index": 3, "time_seconds": 0.053493499755859375, "tool_id": "fastqc", "tool_version": "0.74+galaxy1"}
            ]]></error>
        
    </testcase>
    
    <testcase classname="fastqc (Test #5)" name="4" time="0.054972171783447266">
        
            <error type="error" message="Input staging problem: Traceback (most recent call last):
  File "/opt/hostedtoolcache/Python/3.12.9/x64/lib/python3.12/site-packages/galaxy/tool_util/verify/interactor.py", line 1434, in verify_tool
    stage_data_in_history(
  File "/opt/hostedtoolcache/Python/3.12.9/x64/lib/python3.12/site-packages/galaxy/tool_util/verify/interactor.py", line 163, in stage_data_in_history
    test_dict = galaxy_interactor.remote_to_input(
                ^^^^^^^^^^^^^^^^^^^^^^^^^^^^^^^^^^
  File "/opt/hostedtoolcache/Python/3.12.9/x64/lib/python3.12/site-packages/galaxy/tool_util/verify/interactor.py", line 582, in remote_to_input
    path_or_location = self._get_path_or_location(
                       ^^^^^^^^^^^^^^^^^^^^^^^^^^^
  File "/opt/hostedtoolcache/Python/3.12.9/x64/lib/python3.12/site-packages/galaxy/tool_util/verify/interactor.py", line 619, in _get_path_or_location
    path = self.test_data_download(
           ^^^^^^^^^^^^^^^^^^^^^^^^
  File "/opt/hostedtoolcache/Python/3.12.9/x64/lib/python3.12/site-packages/galaxy/tool_util/verify/interactor.py", line 525, in test_data_download
    raise AssertionError(f"Test input file ({filename}) cannot be found.")
AssertionError: Test input file (1000trimmed.fastq) cannot be found.
"><![CDATA[
                { "execution_problem": "Input staging problem: Traceback (most recent call last):\n  File \"/opt/hostedtoolcache/Python/3.12.9/x64/lib/python3.12/site-packages/galaxy/tool_util/verify/interactor.py\", line 1434, in verify_tool\n    stage_data_in_history(\n  File \"/opt/hostedtoolcache/Python/3.12.9/x64/lib/python3.12/site-packages/galaxy/tool_util/verify/interactor.py\", line 163, in stage_data_in_history\n    test_dict = galaxy_interactor.remote_to_input(\n                ^^^^^^^^^^^^^^^^^^^^^^^^^^^^^^^^^^\n  File \"/opt/hostedtoolcache/Python/3.12.9/x64/lib/python3.12/site-packages/galaxy/tool_util/verify/interactor.py\", line 582, in remote_to_input\n    path_or_location = self._get_path_or_location(\n                       ^^^^^^^^^^^^^^^^^^^^^^^^^^^\n  File \"/opt/hostedtoolcache/Python/3.12.9/x64/lib/python3.12/site-packages/galaxy/tool_util/verify/interactor.py\", line 619, in _get_path_or_location\n    path = self.test_data_download(\n           ^^^^^^^^^^^^^^^^^^^^^^^^\n  File \"/opt/hostedtoolcache/Python/3.12.9/x64/lib/python3.12/site-packages/galaxy/tool_util/verify/interactor.py\", line 525, in test_data_download\n    raise AssertionError(f\"Test input file ({filename}) cannot be found.\")\nAssertionError: Test input file (1000trimmed.fastq) cannot be found.\n", "status": "error", "test_index": 4, "time_seconds": 0.054972171783447266, "tool_id": "fastqc", "tool_version": "0.74+galaxy1"}
            ]]></error>
        
    </testcase>
    
    <testcase classname="fastqc (Test #6)" name="5" time="0.05428361892700195">
        
            <error type="error" message="Input staging problem: Traceback (most recent call last):
  File "/opt/hostedtoolcache/Python/3.12.9/x64/lib/python3.12/site-packages/galaxy/tool_util/verify/interactor.py", line 1434, in verify_tool
    stage_data_in_history(
  File "/opt/hostedtoolcache/Python/3.12.9/x64/lib/python3.12/site-packages/galaxy/tool_util/verify/interactor.py", line 163, in stage_data_in_history
    test_dict = galaxy_interactor.remote_to_input(
                ^^^^^^^^^^^^^^^^^^^^^^^^^^^^^^^^^^
  File "/opt/hostedtoolcache/Python/3.12.9/x64/lib/python3.12/site-packages/galaxy/tool_util/verify/interactor.py", line 582, in remote_to_input
    path_or_location = self._get_path_or_location(
                       ^^^^^^^^^^^^^^^^^^^^^^^^^^^
  File "/opt/hostedtoolcache/Python/3.12.9/x64/lib/python3.12/site-packages/galaxy/tool_util/verify/interactor.py", line 619, in _get_path_or_location
    path = self.test_data_download(
           ^^^^^^^^^^^^^^^^^^^^^^^^
  File "/opt/hostedtoolcache/Python/3.12.9/x64/lib/python3.12/site-packages/galaxy/tool_util/verify/interactor.py", line 525, in test_data_download
    raise AssertionError(f"Test input file ({filename}) cannot be found.")
AssertionError: Test input file (1000trimmed.fastq) cannot be found.
"><![CDATA[
                { "execution_problem": "Input staging problem: Traceback (most recent call last):\n  File \"/opt/hostedtoolcache/Python/3.12.9/x64/lib/python3.12/site-packages/galaxy/tool_util/verify/interactor.py\", line 1434, in verify_tool\n    stage_data_in_history(\n  File \"/opt/hostedtoolcache/Python/3.12.9/x64/lib/python3.12/site-packages/galaxy/tool_util/verify/interactor.py\", line 163, in stage_data_in_history\n    test_dict = galaxy_interactor.remote_to_input(\n                ^^^^^^^^^^^^^^^^^^^^^^^^^^^^^^^^^^\n  File \"/opt/hostedtoolcache/Python/3.12.9/x64/lib/python3.12/site-packages/galaxy/tool_util/verify/interactor.py\", line 582, in remote_to_input\n    path_or_location = self._get_path_or_location(\n                       ^^^^^^^^^^^^^^^^^^^^^^^^^^^\n  File \"/opt/hostedtoolcache/Python/3.12.9/x64/lib/python3.12/site-packages/galaxy/tool_util/verify/interactor.py\", line 619, in _get_path_or_location\n    path = self.test_data_download(\n           ^^^^^^^^^^^^^^^^^^^^^^^^\n  File \"/opt/hostedtoolcache/Python/3.12.9/x64/lib/python3.12/site-packages/galaxy/tool_util/verify/interactor.py\", line 525, in test_data_download\n    raise AssertionError(f\"Test input file ({filename}) cannot be found.\")\nAssertionError: Test input file (1000trimmed.fastq) cannot be found.\n", "status": "error", "test_index": 5, "time_seconds": 0.05428361892700195, "tool_id": "fastqc", "tool_version": "0.74+galaxy1"}
            ]]></error>
        
    </testcase>
    
    <testcase classname="fastqc (Test #7)" name="6" time="0.05787158012390137">
        
            <error type="error" message="Input staging problem: Traceback (most recent call last):
  File "/opt/hostedtoolcache/Python/3.12.9/x64/lib/python3.12/site-packages/galaxy/tool_util/verify/interactor.py", line 1434, in verify_tool
    stage_data_in_history(
  File "/opt/hostedtoolcache/Python/3.12.9/x64/lib/python3.12/site-packages/galaxy/tool_util/verify/interactor.py", line 163, in stage_data_in_history
    test_dict = galaxy_interactor.remote_to_input(
                ^^^^^^^^^^^^^^^^^^^^^^^^^^^^^^^^^^
  File "/opt/hostedtoolcache/Python/3.12.9/x64/lib/python3.12/site-packages/galaxy/tool_util/verify/interactor.py", line 582, in remote_to_input
    path_or_location = self._get_path_or_location(
                       ^^^^^^^^^^^^^^^^^^^^^^^^^^^
  File "/opt/hostedtoolcache/Python/3.12.9/x64/lib/python3.12/site-packages/galaxy/tool_util/verify/interactor.py", line 619, in _get_path_or_location
    path = self.test_data_download(
           ^^^^^^^^^^^^^^^^^^^^^^^^
  File "/opt/hostedtoolcache/Python/3.12.9/x64/lib/python3.12/site-packages/galaxy/tool_util/verify/interactor.py", line 525, in test_data_download
    raise AssertionError(f"Test input file ({filename}) cannot be found.")
AssertionError: Test input file (1000trimmed.fastq) cannot be found.
"><![CDATA[
                { "execution_problem": "Input staging problem: Traceback (most recent call last):\n  File \"/opt/hostedtoolcache/Python/3.12.9/x64/lib/python3.12/site-packages/galaxy/tool_util/verify/interactor.py\", line 1434, in verify_tool\n    stage_data_in_history(\n  File \"/opt/hostedtoolcache/Python/3.12.9/x64/lib/python3.12/site-packages/galaxy/tool_util/verify/interactor.py\", line 163, in stage_data_in_history\n    test_dict = galaxy_interactor.remote_to_input(\n                ^^^^^^^^^^^^^^^^^^^^^^^^^^^^^^^^^^\n  File \"/opt/hostedtoolcache/Python/3.12.9/x64/lib/python3.12/site-packages/galaxy/tool_util/verify/interactor.py\", line 582, in remote_to_input\n    path_or_location = self._get_path_or_location(\n                       ^^^^^^^^^^^^^^^^^^^^^^^^^^^\n  File \"/opt/hostedtoolcache/Python/3.12.9/x64/lib/python3.12/site-packages/galaxy/tool_util/verify/interactor.py\", line 619, in _get_path_or_location\n    path = self.test_data_download(\n           ^^^^^^^^^^^^^^^^^^^^^^^^\n  File \"/opt/hostedtoolcache/Python/3.12.9/x64/lib/python3.12/site-packages/galaxy/tool_util/verify/interactor.py\", line 525, in test_data_download\n    raise AssertionError(f\"Test input file ({filename}) cannot be found.\")\nAssertionError: Test input file (1000trimmed.fastq) cannot be found.\n", "status": "error", "test_index": 6, "time_seconds": 0.05787158012390137, "tool_id": "fastqc", "tool_version": "0.74+galaxy1"}
            ]]></error>
        
    </testcase>
    
    <testcase classname="fastqc (Test #8)" name="7" time="0.08983874320983887">
        
            <error type="error" message="Input staging problem: Traceback (most recent call last):
  File "/opt/hostedtoolcache/Python/3.12.9/x64/lib/python3.12/site-packages/galaxy/tool_util/verify/interactor.py", line 1434, in verify_tool
    stage_data_in_history(
  File "/opt/hostedtoolcache/Python/3.12.9/x64/lib/python3.12/site-packages/galaxy/tool_util/verify/interactor.py", line 163, in stage_data_in_history
    test_dict = galaxy_interactor.remote_to_input(
                ^^^^^^^^^^^^^^^^^^^^^^^^^^^^^^^^^^
  File "/opt/hostedtoolcache/Python/3.12.9/x64/lib/python3.12/site-packages/galaxy/tool_util/verify/interactor.py", line 582, in remote_to_input
    path_or_location = self._get_path_or_location(
                       ^^^^^^^^^^^^^^^^^^^^^^^^^^^
  File "/opt/hostedtoolcache/Python/3.12.9/x64/lib/python3.12/site-packages/galaxy/tool_util/verify/interactor.py", line 619, in _get_path_or_location
    path = self.test_data_download(
           ^^^^^^^^^^^^^^^^^^^^^^^^
  File "/opt/hostedtoolcache/Python/3.12.9/x64/lib/python3.12/site-packages/galaxy/tool_util/verify/interactor.py", line 525, in test_data_download
    raise AssertionError(f"Test input file ({filename}) cannot be found.")
AssertionError: Test input file (hisat_output_1.bam) cannot be found.
"><![CDATA[
                { "execution_problem": "Input staging problem: Traceback (most recent call last):\n  File \"/opt/hostedtoolcache/Python/3.12.9/x64/lib/python3.12/site-packages/galaxy/tool_util/verify/interactor.py\", line 1434, in verify_tool\n    stage_data_in_history(\n  File \"/opt/hostedtoolcache/Python/3.12.9/x64/lib/python3.12/site-packages/galaxy/tool_util/verify/interactor.py\", line 163, in stage_data_in_history\n    test_dict = galaxy_interactor.remote_to_input(\n                ^^^^^^^^^^^^^^^^^^^^^^^^^^^^^^^^^^\n  File \"/opt/hostedtoolcache/Python/3.12.9/x64/lib/python3.12/site-packages/galaxy/tool_util/verify/interactor.py\", line 582, in remote_to_input\n    path_or_location = self._get_path_or_location(\n                       ^^^^^^^^^^^^^^^^^^^^^^^^^^^\n  File \"/opt/hostedtoolcache/Python/3.12.9/x64/lib/python3.12/site-packages/galaxy/tool_util/verify/interactor.py\", line 619, in _get_path_or_location\n    path = self.test_data_download(\n           ^^^^^^^^^^^^^^^^^^^^^^^^\n  File \"/opt/hostedtoolcache/Python/3.12.9/x64/lib/python3.12/site-packages/galaxy/tool_util/verify/interactor.py\", line 525, in test_data_download\n    raise AssertionError(f\"Test input file ({filename}) cannot be found.\")\nAssertionError: Test input file (hisat_output_1.bam) cannot be found.\n", "status": "error", "test_index": 7, "time_seconds": 0.08983874320983887, "tool_id": "fastqc", "tool_version": "0.74+galaxy1"}
            ]]></error>
        
    </testcase>
    
    <testcase classname="lofreq_indelqual (Test #1)" name="0" time="12.594212293624878">
        
            <error type="error" message="Input staging problem: Traceback (most recent call last):
  File "/opt/hostedtoolcache/Python/3.12.9/x64/lib/python3.12/site-packages/galaxy/tool_util/verify/interactor.py", line 1434, in verify_tool
    stage_data_in_history(
  File "/opt/hostedtoolcache/Python/3.12.9/x64/lib/python3.12/site-packages/galaxy/tool_util/verify/interactor.py", line 175, in stage_data_in_history
    staging_interface.handle_jobs()
  File "/opt/hostedtoolcache/Python/3.12.9/x64/lib/python3.12/site-packages/galaxy/tool_util/verify/interactor.py", line 212, in handle_jobs
    self.galaxy_interactor.wait_for_job(job_response["id"], job_response["history_id"], self.maxseconds)
  File "/opt/hostedtoolcache/Python/3.12.9/x64/lib/python3.12/site-packages/galaxy/tool_util/verify/interactor.py", line 399, in wait_for_job
    self.wait_for(lambda: self.__job_ready(job_id, history_id), maxseconds=maxseconds)
  File "/opt/hostedtoolcache/Python/3.12.9/x64/lib/python3.12/site-packages/galaxy/tool_util/verify/interactor.py", line 403, in wait_for
    wait_on(func, what, walltime_exceeded)
  File "/opt/hostedtoolcache/Python/3.12.9/x64/lib/python3.12/site-packages/galaxy/tool_util/verify/wait.py", line 38, in wait_on
    value = function()
            ^^^^^^^^^^
  File "/opt/hostedtoolcache/Python/3.12.9/x64/lib/python3.12/site-packages/galaxy/tool_util/verify/interactor.py", line 399, in <lambda>
    self.wait_for(lambda: self.__job_ready(job_id, history_id), maxseconds=maxseconds)
                          ^^^^^^^^^^^^^^^^^^^^^^^^^^^^^^^^^^^^
  File "/opt/hostedtoolcache/Python/3.12.9/x64/lib/python3.12/site-packages/galaxy/tool_util/verify/interactor.py", line 747, in __job_ready
    return self._state_ready(job_id, error_msg="Job in error state.")
           ^^^^^^^^^^^^^^^^^^^^^^^^^^^^^^^^^^^^^^^^^^^^^^^^^^^^^^^^^^
  File "/opt/hostedtoolcache/Python/3.12.9/x64/lib/python3.12/site-packages/galaxy/tool_util/verify/interactor.py", line 839, in _state_ready
    raise Exception(
Exception: Job in error state.. tool_id: __DATA_FETCH__, exit_code: None, stderr: .
"><![CDATA[
                { "execution_problem": "Input staging problem: Traceback (most recent call last):\n  File \"/opt/hostedtoolcache/Python/3.12.9/x64/lib/python3.12/site-packages/galaxy/tool_util/verify/interactor.py\", line 1434, in verify_tool\n    stage_data_in_history(\n  File \"/opt/hostedtoolcache/Python/3.12.9/x64/lib/python3.12/site-packages/galaxy/tool_util/verify/interactor.py\", line 175, in stage_data_in_history\n    staging_interface.handle_jobs()\n  File \"/opt/hostedtoolcache/Python/3.12.9/x64/lib/python3.12/site-packages/galaxy/tool_util/verify/interactor.py\", line 212, in handle_jobs\n    self.galaxy_interactor.wait_for_job(job_response[\"id\"], job_response[\"history_id\"], self.maxseconds)\n  File \"/opt/hostedtoolcache/Python/3.12.9/x64/lib/python3.12/site-packages/galaxy/tool_util/verify/interactor.py\", line 399, in wait_for_job\n    self.wait_for(lambda: self.__job_ready(job_id, history_id), maxseconds=maxseconds)\n  File \"/opt/hostedtoolcache/Python/3.12.9/x64/lib/python3.12/site-packages/galaxy/tool_util/verify/interactor.py\", line 403, in wait_for\n    wait_on(func, what, walltime_exceeded)\n  File \"/opt/hostedtoolcache/Python/3.12.9/x64/lib/python3.12/site-packages/galaxy/tool_util/verify/wait.py\", line 38, in wait_on\n    value = function()\n            ^^^^^^^^^^\n  File \"/opt/hostedtoolcache/Python/3.12.9/x64/lib/python3.12/site-packages/galaxy/tool_util/verify/interactor.py\", line 399, in \u003clambda\u003e\n    self.wait_for(lambda: self.__job_ready(job_id, history_id), maxseconds=maxseconds)\n                          ^^^^^^^^^^^^^^^^^^^^^^^^^^^^^^^^^^^^\n  File \"/opt/hostedtoolcache/Python/3.12.9/x64/lib/python3.12/site-packages/galaxy/tool_util/verify/interactor.py\", line 747, in __job_ready\n    return self._state_ready(job_id, error_msg=\"Job in error state.\")\n           ^^^^^^^^^^^^^^^^^^^^^^^^^^^^^^^^^^^^^^^^^^^^^^^^^^^^^^^^^^\n  File \"/opt/hostedtoolcache/Python/3.12.9/x64/lib/python3.12/site-packages/galaxy/tool_util/verify/interactor.py\", line 839, in _state_ready\n    raise Exception(\nException: Job in error state.. tool_id: __DATA_FETCH__, exit_code: None, stderr: .\n", "status": "error", "test_index": 0, "time_seconds": 12.594212293624878, "tool_id": "lofreq_indelqual", "tool_version": "2.1.5+galaxy1"}
            ]]></error>
        
    </testcase>
    
    <testcase classname="lofreq_indelqual (Test #2)" name="1" time="58.61187982559204">
        
            
            <system-out><![CDATA[
            
            ]]></system-out>
            <system-err><![CDATA[
            
            ]]></system-err>
        
    </testcase>
    
    <testcase classname="lofreq_indelqual (Test #3)" name="2" time="38.26687455177307">
        
            
            <system-out><![CDATA[
            
            ]]></system-out>
            <system-err><![CDATA[
            
            ]]></system-err>
        
    </testcase>
    
    <testcase classname="mummer_nucmer (Test #1)" name="0" time="21.28102469444275">
        
            <error type="error" message="Input staging problem: Traceback (most recent call last):
  File "/opt/hostedtoolcache/Python/3.12.9/x64/lib/python3.12/site-packages/galaxy/tool_util/verify/interactor.py", line 1434, in verify_tool
    stage_data_in_history(
  File "/opt/hostedtoolcache/Python/3.12.9/x64/lib/python3.12/site-packages/galaxy/tool_util/verify/interactor.py", line 175, in stage_data_in_history
    staging_interface.handle_jobs()
  File "/opt/hostedtoolcache/Python/3.12.9/x64/lib/python3.12/site-packages/galaxy/tool_util/verify/interactor.py", line 212, in handle_jobs
    self.galaxy_interactor.wait_for_job(job_response["id"], job_response["history_id"], self.maxseconds)
  File "/opt/hostedtoolcache/Python/3.12.9/x64/lib/python3.12/site-packages/galaxy/tool_util/verify/interactor.py", line 399, in wait_for_job
    self.wait_for(lambda: self.__job_ready(job_id, history_id), maxseconds=maxseconds)
  File "/opt/hostedtoolcache/Python/3.12.9/x64/lib/python3.12/site-packages/galaxy/tool_util/verify/interactor.py", line 403, in wait_for
    wait_on(func, what, walltime_exceeded)
  File "/opt/hostedtoolcache/Python/3.12.9/x64/lib/python3.12/site-packages/galaxy/tool_util/verify/wait.py", line 38, in wait_on
    value = function()
            ^^^^^^^^^^
  File "/opt/hostedtoolcache/Python/3.12.9/x64/lib/python3.12/site-packages/galaxy/tool_util/verify/interactor.py", line 399, in <lambda>
    self.wait_for(lambda: self.__job_ready(job_id, history_id), maxseconds=maxseconds)
                          ^^^^^^^^^^^^^^^^^^^^^^^^^^^^^^^^^^^^
  File "/opt/hostedtoolcache/Python/3.12.9/x64/lib/python3.12/site-packages/galaxy/tool_util/verify/interactor.py", line 747, in __job_ready
    return self._state_ready(job_id, error_msg="Job in error state.")
           ^^^^^^^^^^^^^^^^^^^^^^^^^^^^^^^^^^^^^^^^^^^^^^^^^^^^^^^^^^
  File "/opt/hostedtoolcache/Python/3.12.9/x64/lib/python3.12/site-packages/galaxy/tool_util/verify/interactor.py", line 839, in _state_ready
    raise Exception(
Exception: Job in error state.. tool_id: __DATA_FETCH__, exit_code: None, stderr: .
"><![CDATA[
                { "execution_problem": "Input staging problem: Traceback (most recent call last):\n  File \"/opt/hostedtoolcache/Python/3.12.9/x64/lib/python3.12/site-packages/galaxy/tool_util/verify/interactor.py\", line 1434, in verify_tool\n    stage_data_in_history(\n  File \"/opt/hostedtoolcache/Python/3.12.9/x64/lib/python3.12/site-packages/galaxy/tool_util/verify/interactor.py\", line 175, in stage_data_in_history\n    staging_interface.handle_jobs()\n  File \"/opt/hostedtoolcache/Python/3.12.9/x64/lib/python3.12/site-packages/galaxy/tool_util/verify/interactor.py\", line 212, in handle_jobs\n    self.galaxy_interactor.wait_for_job(job_response[\"id\"], job_response[\"history_id\"], self.maxseconds)\n  File \"/opt/hostedtoolcache/Python/3.12.9/x64/lib/python3.12/site-packages/galaxy/tool_util/verify/interactor.py\", line 399, in wait_for_job\n    self.wait_for(lambda: self.__job_ready(job_id, history_id), maxseconds=maxseconds)\n  File \"/opt/hostedtoolcache/Python/3.12.9/x64/lib/python3.12/site-packages/galaxy/tool_util/verify/interactor.py\", line 403, in wait_for\n    wait_on(func, what, walltime_exceeded)\n  File \"/opt/hostedtoolcache/Python/3.12.9/x64/lib/python3.12/site-packages/galaxy/tool_util/verify/wait.py\", line 38, in wait_on\n    value = function()\n            ^^^^^^^^^^\n  File \"/opt/hostedtoolcache/Python/3.12.9/x64/lib/python3.12/site-packages/galaxy/tool_util/verify/interactor.py\", line 399, in \u003clambda\u003e\n    self.wait_for(lambda: self.__job_ready(job_id, history_id), maxseconds=maxseconds)\n                          ^^^^^^^^^^^^^^^^^^^^^^^^^^^^^^^^^^^^\n  File \"/opt/hostedtoolcache/Python/3.12.9/x64/lib/python3.12/site-packages/galaxy/tool_util/verify/interactor.py\", line 747, in __job_ready\n    return self._state_ready(job_id, error_msg=\"Job in error state.\")\n           ^^^^^^^^^^^^^^^^^^^^^^^^^^^^^^^^^^^^^^^^^^^^^^^^^^^^^^^^^^\n  File \"/opt/hostedtoolcache/Python/3.12.9/x64/lib/python3.12/site-packages/galaxy/tool_util/verify/interactor.py\", line 839, in _state_ready\n    raise Exception(\nException: Job in error state.. tool_id: __DATA_FETCH__, exit_code: None, stderr: .\n", "status": "error", "test_index": 0, "time_seconds": 21.28102469444275, "tool_id": "mummer_nucmer", "tool_version": "4.0.0rc1+galaxy3"}
            ]]></error>
        
    </testcase>
    
    <testcase classname="mummer_nucmer (Test #2)" name="1" time="12.64612102508545">
        
            <error type="error" message="Input staging problem: Traceback (most recent call last):
  File "/opt/hostedtoolcache/Python/3.12.9/x64/lib/python3.12/site-packages/galaxy/tool_util/verify/interactor.py", line 1434, in verify_tool
    stage_data_in_history(
  File "/opt/hostedtoolcache/Python/3.12.9/x64/lib/python3.12/site-packages/galaxy/tool_util/verify/interactor.py", line 175, in stage_data_in_history
    staging_interface.handle_jobs()
  File "/opt/hostedtoolcache/Python/3.12.9/x64/lib/python3.12/site-packages/galaxy/tool_util/verify/interactor.py", line 212, in handle_jobs
    self.galaxy_interactor.wait_for_job(job_response["id"], job_response["history_id"], self.maxseconds)
  File "/opt/hostedtoolcache/Python/3.12.9/x64/lib/python3.12/site-packages/galaxy/tool_util/verify/interactor.py", line 399, in wait_for_job
    self.wait_for(lambda: self.__job_ready(job_id, history_id), maxseconds=maxseconds)
  File "/opt/hostedtoolcache/Python/3.12.9/x64/lib/python3.12/site-packages/galaxy/tool_util/verify/interactor.py", line 403, in wait_for
    wait_on(func, what, walltime_exceeded)
  File "/opt/hostedtoolcache/Python/3.12.9/x64/lib/python3.12/site-packages/galaxy/tool_util/verify/wait.py", line 38, in wait_on
    value = function()
            ^^^^^^^^^^
  File "/opt/hostedtoolcache/Python/3.12.9/x64/lib/python3.12/site-packages/galaxy/tool_util/verify/interactor.py", line 399, in <lambda>
    self.wait_for(lambda: self.__job_ready(job_id, history_id), maxseconds=maxseconds)
                          ^^^^^^^^^^^^^^^^^^^^^^^^^^^^^^^^^^^^
  File "/opt/hostedtoolcache/Python/3.12.9/x64/lib/python3.12/site-packages/galaxy/tool_util/verify/interactor.py", line 747, in __job_ready
    return self._state_ready(job_id, error_msg="Job in error state.")
           ^^^^^^^^^^^^^^^^^^^^^^^^^^^^^^^^^^^^^^^^^^^^^^^^^^^^^^^^^^
  File "/opt/hostedtoolcache/Python/3.12.9/x64/lib/python3.12/site-packages/galaxy/tool_util/verify/interactor.py", line 839, in _state_ready
    raise Exception(
Exception: Job in error state.. tool_id: __DATA_FETCH__, exit_code: None, stderr: .
"><![CDATA[
                { "execution_problem": "Input staging problem: Traceback (most recent call last):\n  File \"/opt/hostedtoolcache/Python/3.12.9/x64/lib/python3.12/site-packages/galaxy/tool_util/verify/interactor.py\", line 1434, in verify_tool\n    stage_data_in_history(\n  File \"/opt/hostedtoolcache/Python/3.12.9/x64/lib/python3.12/site-packages/galaxy/tool_util/verify/interactor.py\", line 175, in stage_data_in_history\n    staging_interface.handle_jobs()\n  File \"/opt/hostedtoolcache/Python/3.12.9/x64/lib/python3.12/site-packages/galaxy/tool_util/verify/interactor.py\", line 212, in handle_jobs\n    self.galaxy_interactor.wait_for_job(job_response[\"id\"], job_response[\"history_id\"], self.maxseconds)\n  File \"/opt/hostedtoolcache/Python/3.12.9/x64/lib/python3.12/site-packages/galaxy/tool_util/verify/interactor.py\", line 399, in wait_for_job\n    self.wait_for(lambda: self.__job_ready(job_id, history_id), maxseconds=maxseconds)\n  File \"/opt/hostedtoolcache/Python/3.12.9/x64/lib/python3.12/site-packages/galaxy/tool_util/verify/interactor.py\", line 403, in wait_for\n    wait_on(func, what, walltime_exceeded)\n  File \"/opt/hostedtoolcache/Python/3.12.9/x64/lib/python3.12/site-packages/galaxy/tool_util/verify/wait.py\", line 38, in wait_on\n    value = function()\n            ^^^^^^^^^^\n  File \"/opt/hostedtoolcache/Python/3.12.9/x64/lib/python3.12/site-packages/galaxy/tool_util/verify/interactor.py\", line 399, in \u003clambda\u003e\n    self.wait_for(lambda: self.__job_ready(job_id, history_id), maxseconds=maxseconds)\n                          ^^^^^^^^^^^^^^^^^^^^^^^^^^^^^^^^^^^^\n  File \"/opt/hostedtoolcache/Python/3.12.9/x64/lib/python3.12/site-packages/galaxy/tool_util/verify/interactor.py\", line 747, in __job_ready\n    return self._state_ready(job_id, error_msg=\"Job in error state.\")\n           ^^^^^^^^^^^^^^^^^^^^^^^^^^^^^^^^^^^^^^^^^^^^^^^^^^^^^^^^^^\n  File \"/opt/hostedtoolcache/Python/3.12.9/x64/lib/python3.12/site-packages/galaxy/tool_util/verify/interactor.py\", line 839, in _state_ready\n    raise Exception(\nException: Job in error state.. tool_id: __DATA_FETCH__, exit_code: None, stderr: .\n", "status": "error", "test_index": 1, "time_seconds": 12.64612102508545, "tool_id": "mummer_nucmer", "tool_version": "4.0.0rc1+galaxy3"}
            ]]></error>
        
    </testcase>
    
    <testcase classname="mummer_nucmer (Test #3)" name="2" time="69.26763153076172">
        
            
            <system-out><![CDATA[
            
            ]]></system-out>
            <system-err><![CDATA[
            
            ]]></system-err>
        
    </testcase>
    
    <testcase classname="poretools_hist (Test #1)" name="0" time="67.90913081169128">
        
            
            <system-out><![CDATA[
            
            ]]></system-out>
            <system-err><![CDATA[
            
            ]]></system-err>
        
    </testcase>
    
    <testcase classname="poretools_hist (Test #2)" name="1" time="39.41834330558777">
        
            
            <system-out><![CDATA[
            
            ]]></system-out>
            <system-err><![CDATA[
            
            ]]></system-err>
        
    </testcase>
    
    <testcase classname="poretools_hist (Test #3)" name="2" time="41.28959798812866">
        
            
            <system-out><![CDATA[
            
            ]]></system-out>
            <system-err><![CDATA[
            
            ]]></system-err>
        
    </testcase>
    
    <testcase classname="samtools_markdup (Test #1)" name="0" time="45.43385887145996">
        
            
                <error type="error" message="Tool exit code: 0"><![CDATA[
                    { "inputs": {  "bamfile": {   "id": "5dfee7a8cf728d08",   "src": "hda"  } }, "job": {  "command_line": "addthreads=${GALAXY_SLOTS:-1} \u0026\u0026 (( addthreads-- )) \u0026\u0026  samtools sort -@ $addthreads -m ${GALAXY_MEMORY_MB:-768}M -T \"${TMPDIR:-.}\" -O sam -o coordsort.sam \u0027/galaxy/server/database/objects/9/4/f/dataset_94fc55d1-f4b9-437a-a468-e6c647804421.dat\u0027 \u0026\u0026  samtools markdup  -@ $addthreads    coordsort.sam \u0027/galaxy/server/database/objects/4/a/b/dataset_4ab3b490-4bf3-42ef-a1cd-4668dc4b1822.dat\u0027",  "command_version": "Version: 1.9 (using htslib 1.9)",  "copied_from_job_id": null,  "create_time": "2025-03-21T12:55:43.740247",  "dependencies": [],  "exit_code": 0,  "external_id": "gxy-cddwt",  "galaxy_version": "24.1",  "handler": null,  "history_id": "3aa3f8e330cc8fd3",  "id": "37c8eb0ed8ae3f14",  "inputs": {   "bamfile": {    "id": "5dfee7a8cf728d08",    "src": "hda",    "uuid": "94fc55d1-f4b9-437a-a468-e6c647804421"   }  },  "job_messages": [],  "job_metrics": [   {    "name": "runtime_seconds",    "plugin": "core",    "raw_value": "0E-7",    "title": "Job Runtime (Wall Clock)",    "value": "0 seconds"   },   {    "name": "end_epoch",    "plugin": "core",    "raw_value": "1742561753.0000000",    "title": "Job End Time",    "value": "2025-03-21 12:55:53"   },   {    "name": "start_epoch",    "plugin": "core",    "raw_value": "1742561753.0000000",    "title": "Job Start Time",    "value": "2025-03-21 12:55:53"   },   {    "name": "galaxy_memory_mb",    "plugin": "core",    "raw_value": "4080.0000000",    "title": "Memory Allocated (MB)",    "value": "4080"   },   {    "name": "galaxy_slots",    "plugin": "core",    "raw_value": "1.0000000",    "title": "Cores Allocated",    "value": "1"   }  ],  "job_runner_name": null,  "job_stderr": "",  "job_stdout": "",  "model_class": "Job",  "output_collections": {},  "outputs": {   "output": {    "id": "37c8eb0ed8ae3f14",    "src": "hda",    "uuid": "4ab3b490-4bf3-42ef-a1cd-4668dc4b1822"   }  },  "params": {   "__input_ext": "\"sam\"",   "chromInfo": "\"/cvmfs/data.galaxyproject.org/managed/len/ucsc/?.len\"",   "dbkey": "\"?\"",   "maxlen": "\"\"",   "remove": "false",   "stats": "false",   "supp": "false"  },  "state": "ok",  "stderr": "",  "stdout": "",  "tool_id": "toolshed.g2.bx.psu.edu/repos/iuc/samtools_markdup/samtools_markdup/1.9+galaxy2",  "tool_stderr": "",  "tool_stdout": "",  "update_time": "2025-03-21T12:56:06.397243",  "user_email": "tests@fake.org" }, "output_problems": [  "Output output: Test output file (5_markdup.expected.bam) is missing. If you are using planemo, try adding --update_test_data to generate it." ], "status": "failure", "test_index": 0, "time_seconds": 45.43385887145996, "tool_id": "samtools_markdup", "tool_version": "1.9+galaxy2"}
                ]]></error>
            
            <system-out><![CDATA[
            
            ]]></system-out>
            <system-err><![CDATA[
            
            ]]></system-err>
        
    </testcase>
    
    <testcase classname="samtools_markdup (Test #2)" name="1" time="36.38047218322754">
        
            
                <error type="error" message="Tool exit code: 0"><![CDATA[
                    { "inputs": {  "bamfile": {   "id": "f83ce032376a0c40",   "src": "hda"  },  "remove": true }, "job": {  "command_line": "addthreads=${GALAXY_SLOTS:-1} \u0026\u0026 (( addthreads-- )) \u0026\u0026  samtools sort -@ $addthreads -m ${GALAXY_MEMORY_MB:-768}M -T \"${TMPDIR:-.}\" -O sam -o coordsort.sam \u0027/galaxy/server/database/objects/a/f/5/dataset_af5dfb62-5a34-4df4-9796-20a1758afda5.dat\u0027 \u0026\u0026  samtools markdup  -@ $addthreads -r   coordsort.sam \u0027/galaxy/server/database/objects/e/a/c/dataset_eacb9983-2b44-47ea-bdde-dc796bdc71ff.dat\u0027",  "command_version": "Version: 1.9 (using htslib 1.9)",  "copied_from_job_id": null,  "create_time": "2025-03-21T12:56:28.797726",  "dependencies": [],  "exit_code": 0,  "external_id": "gxy-5t8fq",  "galaxy_version": "24.1",  "handler": null,  "history_id": "3aa3f8e330cc8fd3",  "id": "408494e6b3a127ab",  "inputs": {   "bamfile": {    "id": "f83ce032376a0c40",    "src": "hda",    "uuid": "af5dfb62-5a34-4df4-9796-20a1758afda5"   }  },  "job_messages": [],  "job_metrics": [   {    "name": "runtime_seconds",    "plugin": "core",    "raw_value": "0E-7",    "title": "Job Runtime (Wall Clock)",    "value": "0 seconds"   },   {    "name": "end_epoch",    "plugin": "core",    "raw_value": "1742561790.0000000",    "title": "Job End Time",    "value": "2025-03-21 12:56:30"   },   {    "name": "start_epoch",    "plugin": "core",    "raw_value": "1742561790.0000000",    "title": "Job Start Time",    "value": "2025-03-21 12:56:30"   },   {    "name": "galaxy_memory_mb",    "plugin": "core",    "raw_value": "4080.0000000",    "title": "Memory Allocated (MB)",    "value": "4080"   },   {    "name": "galaxy_slots",    "plugin": "core",    "raw_value": "1.0000000",    "title": "Cores Allocated",    "value": "1"   }  ],  "job_runner_name": null,  "job_stderr": "",  "job_stdout": "",  "model_class": "Job",  "output_collections": {},  "outputs": {   "output": {    "id": "408494e6b3a127ab",    "src": "hda",    "uuid": "eacb9983-2b44-47ea-bdde-dc796bdc71ff"   }  },  "params": {   "__input_ext": "\"sam\"",   "chromInfo": "\"/cvmfs/data.galaxyproject.org/managed/len/ucsc/?.len\"",   "dbkey": "\"?\"",   "maxlen": "\"\"",   "remove": "true",   "stats": "false",   "supp": "false"  },  "state": "ok",  "stderr": "",  "stdout": "",  "tool_id": "toolshed.g2.bx.psu.edu/repos/iuc/samtools_markdup/samtools_markdup/1.9+galaxy2",  "tool_stderr": "",  "tool_stdout": "",  "update_time": "2025-03-21T12:56:42.682875",  "user_email": "tests@fake.org" }, "output_problems": [  "Output output: Test output file (6_remove_dups.expected.bam) is missing. If you are using planemo, try adding --update_test_data to generate it." ], "status": "failure", "test_index": 1, "time_seconds": 36.38047218322754, "tool_id": "samtools_markdup", "tool_version": "1.9+galaxy2"}
                ]]></error>
            
            <system-out><![CDATA[
            
            ]]></system-out>
            <system-err><![CDATA[
            
            ]]></system-err>
        
    </testcase>
    
    <testcase classname="samtools_markdup (Test #3)" name="2" time="37.36270189285278">
        
            
                <error type="error" message="Tool exit code: 0"><![CDATA[
                    { "inputs": {  "bamfile": {   "id": "c031fdfdead7b89f",   "src": "hda"  },  "supp": true }, "job": {  "command_line": "addthreads=${GALAXY_SLOTS:-1} \u0026\u0026 (( addthreads-- )) \u0026\u0026  ln -s \u0027/galaxy/server/database/objects/a/d/c/dataset_adcaae85-abeb-4e16-a8af-55761c1222f6.dat\u0027 coordsort.sam \u0026\u0026  samtools markdup  -@ $addthreads   -S coordsort.sam \u0027/galaxy/server/database/objects/e/b/2/dataset_eb26146c-9339-4a8e-946c-82d60df08c8f.dat\u0027",  "command_version": "Version: 1.9 (using htslib 1.9)",  "copied_from_job_id": null,  "create_time": "2025-03-21T12:57:05.296176",  "dependencies": [],  "exit_code": 0,  "external_id": "gxy-v8zvr",  "galaxy_version": "24.1",  "handler": null,  "history_id": "3aa3f8e330cc8fd3",  "id": "35ad5b915afe69b1",  "inputs": {   "bamfile": {    "id": "c031fdfdead7b89f",    "src": "hda",    "uuid": "adcaae85-abeb-4e16-a8af-55761c1222f6"   }  },  "job_messages": [],  "job_metrics": [   {    "name": "runtime_seconds",    "plugin": "core",    "raw_value": "0E-7",    "title": "Job Runtime (Wall Clock)",    "value": "0 seconds"   },   {    "name": "end_epoch",    "plugin": "core",    "raw_value": "1742561827.0000000",    "title": "Job End Time",    "value": "2025-03-21 12:57:07"   },   {    "name": "start_epoch",    "plugin": "core",    "raw_value": "1742561827.0000000",    "title": "Job Start Time",    "value": "2025-03-21 12:57:07"   },   {    "name": "galaxy_memory_mb",    "plugin": "core",    "raw_value": "4080.0000000",    "title": "Memory Allocated (MB)",    "value": "4080"   },   {    "name": "galaxy_slots",    "plugin": "core",    "raw_value": "1.0000000",    "title": "Cores Allocated",    "value": "1"   }  ],  "job_runner_name": null,  "job_stderr": "",  "job_stdout": "",  "model_class": "Job",  "output_collections": {},  "outputs": {   "output": {    "id": "35ad5b915afe69b1",    "src": "hda",    "uuid": "eb26146c-9339-4a8e-946c-82d60df08c8f"   }  },  "params": {   "__input_ext": "\"bam\"",   "chromInfo": "\"/cvmfs/data.galaxyproject.org/managed/len/ucsc/?.len\"",   "dbkey": "\"?\"",   "maxlen": "\"\"",   "remove": "false",   "stats": "false",   "supp": "true"  },  "state": "ok",  "stderr": "",  "stdout": "",  "tool_id": "toolshed.g2.bx.psu.edu/repos/iuc/samtools_markdup/samtools_markdup/1.9+galaxy2",  "tool_stderr": "",  "tool_stdout": "",  "update_time": "2025-03-21T12:57:20.326889",  "user_email": "tests@fake.org" }, "output_problems": [  "Output output: Test output file (7_mark_supp_dup.expected.bam) is missing. If you are using planemo, try adding --update_test_data to generate it." ], "status": "failure", "test_index": 2, "time_seconds": 37.36270189285278, "tool_id": "samtools_markdup", "tool_version": "1.9+galaxy2"}
                ]]></error>
            
            <system-out><![CDATA[
            
            ]]></system-out>
            <system-err><![CDATA[
            
            ]]></system-err>
        
    </testcase>
    
    <testcase classname="samtools_markdup (Test #4)" name="3" time="37.763532876968384">
        
            
                <error type="error" message="Tool exit code: 0"><![CDATA[
                    { "inputs": {  "bamfile": {   "id": "b9e3734e35e05b26",   "src": "hda"  },  "stats": true }, "job": {  "command_line": "addthreads=${GALAXY_SLOTS:-1} \u0026\u0026 (( addthreads-- )) \u0026\u0026  samtools sort -@ $addthreads -m ${GALAXY_MEMORY_MB:-768}M -T \"${TMPDIR:-.}\" -O sam -o coordsort.sam \u0027/galaxy/server/database/objects/9/1/d/dataset_91d4320f-ae47-4cd9-9cc6-19bc6599a359.dat\u0027 \u0026\u0026  samtools markdup  -@ $addthreads  -s  coordsort.sam \u0027/galaxy/server/database/objects/6/f/a/dataset_6fa98e6d-d489-424d-988f-a6e07c9b031e.dat\u0027 2\u003e \u0027/galaxy/server/database/objects/2/8/0/dataset_280cdefb-0979-44eb-b76e-1037d6c5c25b.dat\u0027",  "command_version": "Version: 1.9 (using htslib 1.9)",  "copied_from_job_id": null,  "create_time": "2025-03-21T12:57:42.959929",  "dependencies": [],  "exit_code": 0,  "external_id": "gxy-xlq97",  "galaxy_version": "24.1",  "handler": null,  "history_id": "3aa3f8e330cc8fd3",  "id": "415f3597dc480e42",  "inputs": {   "bamfile": {    "id": "b9e3734e35e05b26",    "src": "hda",    "uuid": "91d4320f-ae47-4cd9-9cc6-19bc6599a359"   }  },  "job_messages": [],  "job_metrics": [   {    "name": "runtime_seconds",    "plugin": "core",    "raw_value": "0E-7",    "title": "Job Runtime (Wall Clock)",    "value": "0 seconds"   },   {    "name": "end_epoch",    "plugin": "core",    "raw_value": "1742561864.0000000",    "title": "Job End Time",    "value": "2025-03-21 12:57:44"   },   {    "name": "start_epoch",    "plugin": "core",    "raw_value": "1742561864.0000000",    "title": "Job Start Time",    "value": "2025-03-21 12:57:44"   },   {    "name": "galaxy_memory_mb",    "plugin": "core",    "raw_value": "4080.0000000",    "title": "Memory Allocated (MB)",    "value": "4080"   },   {    "name": "galaxy_slots",    "plugin": "core",    "raw_value": "1.0000000",    "title": "Cores Allocated",    "value": "1"   }  ],  "job_runner_name": null,  "job_stderr": "",  "job_stdout": "",  "model_class": "Job",  "output_collections": {},  "outputs": {   "output": {    "id": "415f3597dc480e42",    "src": "hda",    "uuid": "6fa98e6d-d489-424d-988f-a6e07c9b031e"   },   "stats_output": {    "id": "40af80eedd2650b1",    "src": "hda",    "uuid": "280cdefb-0979-44eb-b76e-1037d6c5c25b"   }  },  "params": {   "__input_ext": "\"sam\"",   "chromInfo": "\"/cvmfs/data.galaxyproject.org/managed/len/ucsc/?.len\"",   "dbkey": "\"?\"",   "maxlen": "\"\"",   "remove": "false",   "stats": "true",   "supp": "false"  },  "state": "ok",  "stderr": "",  "stdout": "",  "tool_id": "toolshed.g2.bx.psu.edu/repos/iuc/samtools_markdup/samtools_markdup/1.9+galaxy2",  "tool_stderr": "",  "tool_stdout": "",  "update_time": "2025-03-21T12:57:57.897173",  "user_email": "tests@fake.org" }, "output_problems": [  "Output output: Test output file (5_markdup.expected.bam) is missing. If you are using planemo, try adding --update_test_data to generate it.",  "Output stats_output:  different than expected, difference (using diff):\n( /tmp/tmpzr25l_trstats.txt v. /tmp/tmpftj1ukkdstats.txt )\n--- local_file\n+++ history_data\n@@ -1,17 +1,5 @@\n-COMMAND: samtools markdup -@ 0 -m t -s -f /tmp/tmpo1hsz7dc/job_working_directory/000/8/outputs/dataset_9e69bd59-3165-4ede-92bf-2f438627a6a1.dat -O BAM coordsort.sam /tmp/tmpo1hsz7dc/job_working_directory/000/8/outputs/dataset_ccf59cfe-ffbd-41d5-9412-d7a7ac6e65d9.dat\n-READ: 16\n-WRITTEN: 16\n-EXCLUDED: 3\n-EXAMINED: 13\n-PAIRED: 10\n-SINGLE: 3\n-DUPLICATE PAIR: 4\n-DUPLICATE SINGLE: 2\n-DUPLICATE PAIR OPTICAL: 0\n-DUPLICATE SINGLE OPTICAL: 0\n-DUPLICATE NON PRIMARY: 0\n-DUPLICATE NON PRIMARY OPTICAL: 0\n-DUPLICATE PRIMARY TOTAL: 6\n-DUPLICATE TOTAL: 6\n-ESTIMATED_LIBRARY_SIZE: 4\n-\n+READ 16 WRITTEN 16 \n+EXCLUDED 3 EXAMINED 13\n+PAIRED 10 SINGLE 3\n+DULPICATE PAIR 4 DUPLICATE SINGLE 2\n+DUPLICATE TOTAL 6\n" ], "status": "failure", "test_index": 3, "time_seconds": 37.763532876968384, "tool_id": "samtools_markdup", "tool_version": "1.9+galaxy2"}
                ]]></error>
            
            <system-out><![CDATA[
            
            ]]></system-out>
            <system-err><![CDATA[
            
            ]]></system-err>
        
    </testcase>
    
    <testcase classname="sqlite_to_tabular (Test #1)" name="0" time="82.83336114883423">
        
            
            <system-out><![CDATA[
            
            ]]></system-out>
            <system-err><![CDATA[
            
            ]]></system-err>
        
    </testcase>
    
    <testcase classname="vcfbedintersect (Test #1)" name="0" time="51.74339294433594">
        
            
            <system-out><![CDATA[
            
            ]]></system-out>
            <system-err><![CDATA[
            
            ]]></system-err>
        
    </testcase>
    
    <testcase classname="vcfbedintersect (Test #2)" name="1" time="37.44327712059021">
        
            
            <system-out><![CDATA[
            
            ]]></system-out>
            <system-err><![CDATA[
            
            ]]></system-err>
        
    </testcase>
    
    <testcase classname="vcfvcfintersect (Test #1)" name="0" time="42.632081508636475">
        
            
            <system-out><![CDATA[
            
            ]]></system-out>
            <system-err><![CDATA[
            index file localref.fa.fai not found, generating...
            ]]></system-err>
        
    </testcase>
    
    <testcase classname="vcfvcfintersect (Test #2)" name="1" time="41.955320835113525">
        
            
            <system-out><![CDATA[
            
            ]]></system-out>
            <system-err><![CDATA[
            index file localref.fa.fai not found, generating...
            ]]></system-err>
        
    </testcase>
    
</testsuite>