<?xml version="1.0" encoding="UTF-8"?>
<testsuite name="Results (powered by Planemo)"
           tests="35"
           errors="10"
           failures="7"
           skip="0">
    
    <testcase classname="bcftools_convert_to_vcf (Test #1)" name="0" time="33.756067752838135">
        
            
                <error type="error" message="Tool exit code: None"><![CDATA[
                    { "inputs": {  "convert|convert_from": "gen_sample",  "convert|input_file": {   "id": "02282e423fb62cb0",   "src": "hda"  },  "convert|input_sample": {   "id": "e8f89ced3bc79030",   "src": "hda"  },  "output_type": "v" }, "job": {  "command_line": "export BCFTOOLS_PLUGINS=`which bcftools | sed \u0027s,bin/bcftools,libexec/bcftools,\u0027`;    bcftools convert   --output-type \u0027v\u0027   --gensample2vcf \u0027/galaxy/server/database/objects/8/1/d/dataset_81d8fbe9-27b7-4b1f-9aee-2342f232eec4.dat,/galaxy/server/database/objects/c/3/e/dataset_c3e6046b-cc32-4e3d-9b5e-c3b27079f0e8.dat\u0027 \u003e \u0027/galaxy/server/database/objects/3/3/0/dataset_330deba9-2df4-4d02-b40c-3eb64a331f3c.dat\u0027",  "command_version": null,  "copied_from_job_id": null,  "create_time": "2025-05-07T13:06:56.438601",  "dependencies": [],  "exit_code": null,  "external_id": "gxy-xfp9g",  "galaxy_version": "24.1",  "handler": null,  "history_id": "3ffb4f16db81f4ab",  "id": "c82f9bb9e3c00b98",  "inputs": {   "convert|input_file": {    "id": "02282e423fb62cb0",    "src": "hda",    "uuid": "81d8fbe9-27b7-4b1f-9aee-2342f232eec4"   },   "convert|input_sample": {    "id": "e8f89ced3bc79030",    "src": "hda",    "uuid": "c3e6046b-cc32-4e3d-9b5e-c3b27079f0e8"   }  },  "job_messages": null,  "job_metrics": [],  "job_runner_name": null,  "job_stderr": null,  "job_stdout": null,  "model_class": "Job",  "output_collections": {},  "outputs": {   "output_file": {    "id": "1c9478ca195c2167",    "src": "hda",    "uuid": "330deba9-2df4-4d02-b40c-3eb64a331f3c"   }  },  "params": {   "__input_ext": "\"input\"",   "chromInfo": "\"/cvmfs/data.galaxyproject.org/managed/len/ucsc/?.len\"",   "convert": "{\"__current_case__\": 2, \"convert_from\": \"gen_sample\", \"input_file\": {\"values\": [{\"id\": 34, \"src\": \"hda\"}]}, \"input_sample\": {\"values\": [{\"id\": 35, \"src\": \"hda\"}]}}",   "dbkey": "\"?\"",   "output_type": "\"v\""  },  "state": "error",  "stderr": "Number of processed rows: \t32\n",  "stdout": "",  "tool_id": "toolshed.g2.bx.psu.edu/repos/iuc/bcftools_convert_to_vcf/bcftools_convert_to_vcf/1.15.1+galaxy4",  "tool_stderr": "Number of processed rows: \t32\n",  "tool_stdout": "",  "update_time": "2025-05-07T13:07:08.389398",  "user_email": "tests@fake.org" }, "output_problems": [  "Job in error state.. tool_id: toolshed.g2.bx.psu.edu/repos/iuc/bcftools_convert_to_vcf/bcftools_convert_to_vcf/1.15.1+galaxy4, exit_code: None, stderr: Number of processed rows: \t32\n.",  "Job in error state.. tool_id: toolshed.g2.bx.psu.edu/repos/iuc/bcftools_convert_to_vcf/bcftools_convert_to_vcf/1.15.1+galaxy4, exit_code: None, stderr: Number of processed rows: \t32\n." ], "status": "failure", "test_index": 0, "time_seconds": 33.756067752838135, "tool_id": "bcftools_convert_to_vcf", "tool_version": "1.15.1+galaxy4"}
                ]]></error>
            
            <system-out><![CDATA[
            
            ]]></system-out>
            <system-err><![CDATA[
            Number of processed rows: 32
            ]]></system-err>
        
    </testcase>
    
    <testcase classname="bcftools_convert_to_vcf (Test #2)" name="1" time="18.217082500457764">
        
            <error type="error" message="Input staging problem: Traceback (most recent call last):
  File "/opt/hostedtoolcache/Python/3.12.10/x64/lib/python3.12/site-packages/galaxy/tool_util/verify/interactor.py", line 1434, in verify_tool
    stage_data_in_history(
  File "/opt/hostedtoolcache/Python/3.12.10/x64/lib/python3.12/site-packages/galaxy/tool_util/verify/interactor.py", line 175, in stage_data_in_history
    staging_interface.handle_jobs()
  File "/opt/hostedtoolcache/Python/3.12.10/x64/lib/python3.12/site-packages/galaxy/tool_util/verify/interactor.py", line 212, in handle_jobs
    self.galaxy_interactor.wait_for_job(job_response["id"], job_response["history_id"], self.maxseconds)
  File "/opt/hostedtoolcache/Python/3.12.10/x64/lib/python3.12/site-packages/galaxy/tool_util/verify/interactor.py", line 399, in wait_for_job
    self.wait_for(lambda: self.__job_ready(job_id, history_id), maxseconds=maxseconds)
  File "/opt/hostedtoolcache/Python/3.12.10/x64/lib/python3.12/site-packages/galaxy/tool_util/verify/interactor.py", line 403, in wait_for
    wait_on(func, what, walltime_exceeded)
  File "/opt/hostedtoolcache/Python/3.12.10/x64/lib/python3.12/site-packages/galaxy/tool_util/verify/wait.py", line 38, in wait_on
    value = function()
            ^^^^^^^^^^
  File "/opt/hostedtoolcache/Python/3.12.10/x64/lib/python3.12/site-packages/galaxy/tool_util/verify/interactor.py", line 399, in <lambda>
    self.wait_for(lambda: self.__job_ready(job_id, history_id), maxseconds=maxseconds)
                          ^^^^^^^^^^^^^^^^^^^^^^^^^^^^^^^^^^^^
  File "/opt/hostedtoolcache/Python/3.12.10/x64/lib/python3.12/site-packages/galaxy/tool_util/verify/interactor.py", line 747, in __job_ready
    return self._state_ready(job_id, error_msg="Job in error state.")
           ^^^^^^^^^^^^^^^^^^^^^^^^^^^^^^^^^^^^^^^^^^^^^^^^^^^^^^^^^^
  File "/opt/hostedtoolcache/Python/3.12.10/x64/lib/python3.12/site-packages/galaxy/tool_util/verify/interactor.py", line 839, in _state_ready
    raise Exception(
Exception: Job in error state.. tool_id: __DATA_FETCH__, exit_code: None, stderr: .
"><![CDATA[
                { "execution_problem": "Input staging problem: Traceback (most recent call last):\n  File \"/opt/hostedtoolcache/Python/3.12.10/x64/lib/python3.12/site-packages/galaxy/tool_util/verify/interactor.py\", line 1434, in verify_tool\n    stage_data_in_history(\n  File \"/opt/hostedtoolcache/Python/3.12.10/x64/lib/python3.12/site-packages/galaxy/tool_util/verify/interactor.py\", line 175, in stage_data_in_history\n    staging_interface.handle_jobs()\n  File \"/opt/hostedtoolcache/Python/3.12.10/x64/lib/python3.12/site-packages/galaxy/tool_util/verify/interactor.py\", line 212, in handle_jobs\n    self.galaxy_interactor.wait_for_job(job_response[\"id\"], job_response[\"history_id\"], self.maxseconds)\n  File \"/opt/hostedtoolcache/Python/3.12.10/x64/lib/python3.12/site-packages/galaxy/tool_util/verify/interactor.py\", line 399, in wait_for_job\n    self.wait_for(lambda: self.__job_ready(job_id, history_id), maxseconds=maxseconds)\n  File \"/opt/hostedtoolcache/Python/3.12.10/x64/lib/python3.12/site-packages/galaxy/tool_util/verify/interactor.py\", line 403, in wait_for\n    wait_on(func, what, walltime_exceeded)\n  File \"/opt/hostedtoolcache/Python/3.12.10/x64/lib/python3.12/site-packages/galaxy/tool_util/verify/wait.py\", line 38, in wait_on\n    value = function()\n            ^^^^^^^^^^\n  File \"/opt/hostedtoolcache/Python/3.12.10/x64/lib/python3.12/site-packages/galaxy/tool_util/verify/interactor.py\", line 399, in \u003clambda\u003e\n    self.wait_for(lambda: self.__job_ready(job_id, history_id), maxseconds=maxseconds)\n                          ^^^^^^^^^^^^^^^^^^^^^^^^^^^^^^^^^^^^\n  File \"/opt/hostedtoolcache/Python/3.12.10/x64/lib/python3.12/site-packages/galaxy/tool_util/verify/interactor.py\", line 747, in __job_ready\n    return self._state_ready(job_id, error_msg=\"Job in error state.\")\n           ^^^^^^^^^^^^^^^^^^^^^^^^^^^^^^^^^^^^^^^^^^^^^^^^^^^^^^^^^^\n  File \"/opt/hostedtoolcache/Python/3.12.10/x64/lib/python3.12/site-packages/galaxy/tool_util/verify/interactor.py\", line 839, in _state_ready\n    raise Exception(\nException: Job in error state.. tool_id: __DATA_FETCH__, exit_code: None, stderr: .\n", "status": "error", "test_index": 1, "time_seconds": 18.217082500457764, "tool_id": "bcftools_convert_to_vcf", "tool_version": "1.15.1+galaxy4"}
            ]]></error>
        
    </testcase>
    
    <testcase classname="bcftools_convert_to_vcf (Test #3)" name="2" time="29.585372924804688">
        
            
                <error type="error" message="Tool exit code: None"><![CDATA[
                    { "inputs": {  "convert|convert_from": "hap_legend_sample",  "convert|input_file": {   "id": "8e00130db5e2bffe",   "src": "hda"  },  "convert|input_legend": {   "id": "1303ad2e280f72ae",   "src": "hda"  },  "convert|input_sample": {   "id": "881f284bf600905d",   "src": "hda"  },  "output_type": "v" }, "job": {  "command_line": "export BCFTOOLS_PLUGINS=`which bcftools | sed \u0027s,bin/bcftools,libexec/bcftools,\u0027`;    bcftools convert   --output-type \u0027v\u0027   --haplegendsample2vcf \u0027/galaxy/server/database/objects/f/1/4/dataset_f142677f-71a1-4a2e-9c75-353a91920d2b.dat,/galaxy/server/database/objects/8/1/a/dataset_81a2429f-082c-4079-ad1b-a8a998d5eea2.dat,/galaxy/server/database/objects/8/c/3/dataset_8c37329f-990c-4f6c-8d39-6dea02a633f6.dat\u0027 \u003e \u0027/galaxy/server/database/objects/0/a/d/dataset_0ad8e455-c81e-4365-bf84-24a75f1acc6e.dat\u0027",  "command_version": null,  "copied_from_job_id": null,  "create_time": "2025-05-07T13:07:50.377699",  "dependencies": [],  "exit_code": null,  "external_id": "gxy-7qkqf",  "galaxy_version": "24.1",  "handler": null,  "history_id": "3ffb4f16db81f4ab",  "id": "b6417153a2f98b59",  "inputs": {   "convert|input_file": {    "id": "8e00130db5e2bffe",    "src": "hda",    "uuid": "f142677f-71a1-4a2e-9c75-353a91920d2b"   },   "convert|input_legend": {    "id": "1303ad2e280f72ae",    "src": "hda",    "uuid": "81a2429f-082c-4079-ad1b-a8a998d5eea2"   },   "convert|input_sample": {    "id": "881f284bf600905d",    "src": "hda",    "uuid": "8c37329f-990c-4f6c-8d39-6dea02a633f6"   }  },  "job_messages": null,  "job_metrics": [],  "job_runner_name": null,  "job_stderr": null,  "job_stdout": null,  "model_class": "Job",  "output_collections": {},  "outputs": {   "output_file": {    "id": "6ee7c10cdfba8ee6",    "src": "hda",    "uuid": "0ad8e455-c81e-4365-bf84-24a75f1acc6e"   }  },  "params": {   "__input_ext": "\"input\"",   "chromInfo": "\"/cvmfs/data.galaxyproject.org/managed/len/ucsc/?.len\"",   "convert": "{\"__current_case__\": 4, \"convert_from\": \"hap_legend_sample\", \"input_file\": {\"values\": [{\"id\": 39, \"src\": \"hda\"}]}, \"input_legend\": {\"values\": [{\"id\": 40, \"src\": \"hda\"}]}, \"input_sample\": {\"values\": [{\"id\": 41, \"src\": \"hda\"}]}}",   "dbkey": "\"?\"",   "output_type": "\"v\""  },  "state": "error",  "stderr": "Number of processed rows: \t35\n",  "stdout": "",  "tool_id": "toolshed.g2.bx.psu.edu/repos/iuc/bcftools_convert_to_vcf/bcftools_convert_to_vcf/1.15.1+galaxy4",  "tool_stderr": "Number of processed rows: \t35\n",  "tool_stdout": "",  "update_time": "2025-05-07T13:07:56.182708",  "user_email": "tests@fake.org" }, "output_problems": [  "Job in error state.. tool_id: toolshed.g2.bx.psu.edu/repos/iuc/bcftools_convert_to_vcf/bcftools_convert_to_vcf/1.15.1+galaxy4, exit_code: None, stderr: Number of processed rows: \t35\n.",  "Job in error state.. tool_id: toolshed.g2.bx.psu.edu/repos/iuc/bcftools_convert_to_vcf/bcftools_convert_to_vcf/1.15.1+galaxy4, exit_code: None, stderr: Number of processed rows: \t35\n." ], "status": "failure", "test_index": 2, "time_seconds": 29.585372924804688, "tool_id": "bcftools_convert_to_vcf", "tool_version": "1.15.1+galaxy4"}
                ]]></error>
            
            <system-out><![CDATA[
            
            ]]></system-out>
            <system-err><![CDATA[
            Number of processed rows: 35
            ]]></system-err>
        
    </testcase>
    
    <testcase classname="bcftools_convert_to_vcf (Test #4)" name="3" time="12.112993955612183">
        
            <error type="error" message="Input staging problem: Traceback (most recent call last):
  File "/opt/hostedtoolcache/Python/3.12.10/x64/lib/python3.12/site-packages/galaxy/tool_util/verify/interactor.py", line 1434, in verify_tool
    stage_data_in_history(
  File "/opt/hostedtoolcache/Python/3.12.10/x64/lib/python3.12/site-packages/galaxy/tool_util/verify/interactor.py", line 175, in stage_data_in_history
    staging_interface.handle_jobs()
  File "/opt/hostedtoolcache/Python/3.12.10/x64/lib/python3.12/site-packages/galaxy/tool_util/verify/interactor.py", line 212, in handle_jobs
    self.galaxy_interactor.wait_for_job(job_response["id"], job_response["history_id"], self.maxseconds)
  File "/opt/hostedtoolcache/Python/3.12.10/x64/lib/python3.12/site-packages/galaxy/tool_util/verify/interactor.py", line 399, in wait_for_job
    self.wait_for(lambda: self.__job_ready(job_id, history_id), maxseconds=maxseconds)
  File "/opt/hostedtoolcache/Python/3.12.10/x64/lib/python3.12/site-packages/galaxy/tool_util/verify/interactor.py", line 403, in wait_for
    wait_on(func, what, walltime_exceeded)
  File "/opt/hostedtoolcache/Python/3.12.10/x64/lib/python3.12/site-packages/galaxy/tool_util/verify/wait.py", line 38, in wait_on
    value = function()
            ^^^^^^^^^^
  File "/opt/hostedtoolcache/Python/3.12.10/x64/lib/python3.12/site-packages/galaxy/tool_util/verify/interactor.py", line 399, in <lambda>
    self.wait_for(lambda: self.__job_ready(job_id, history_id), maxseconds=maxseconds)
                          ^^^^^^^^^^^^^^^^^^^^^^^^^^^^^^^^^^^^
  File "/opt/hostedtoolcache/Python/3.12.10/x64/lib/python3.12/site-packages/galaxy/tool_util/verify/interactor.py", line 747, in __job_ready
    return self._state_ready(job_id, error_msg="Job in error state.")
           ^^^^^^^^^^^^^^^^^^^^^^^^^^^^^^^^^^^^^^^^^^^^^^^^^^^^^^^^^^
  File "/opt/hostedtoolcache/Python/3.12.10/x64/lib/python3.12/site-packages/galaxy/tool_util/verify/interactor.py", line 839, in _state_ready
    raise Exception(
Exception: Job in error state.. tool_id: __DATA_FETCH__, exit_code: None, stderr: .
"><![CDATA[
                { "execution_problem": "Input staging problem: Traceback (most recent call last):\n  File \"/opt/hostedtoolcache/Python/3.12.10/x64/lib/python3.12/site-packages/galaxy/tool_util/verify/interactor.py\", line 1434, in verify_tool\n    stage_data_in_history(\n  File \"/opt/hostedtoolcache/Python/3.12.10/x64/lib/python3.12/site-packages/galaxy/tool_util/verify/interactor.py\", line 175, in stage_data_in_history\n    staging_interface.handle_jobs()\n  File \"/opt/hostedtoolcache/Python/3.12.10/x64/lib/python3.12/site-packages/galaxy/tool_util/verify/interactor.py\", line 212, in handle_jobs\n    self.galaxy_interactor.wait_for_job(job_response[\"id\"], job_response[\"history_id\"], self.maxseconds)\n  File \"/opt/hostedtoolcache/Python/3.12.10/x64/lib/python3.12/site-packages/galaxy/tool_util/verify/interactor.py\", line 399, in wait_for_job\n    self.wait_for(lambda: self.__job_ready(job_id, history_id), maxseconds=maxseconds)\n  File \"/opt/hostedtoolcache/Python/3.12.10/x64/lib/python3.12/site-packages/galaxy/tool_util/verify/interactor.py\", line 403, in wait_for\n    wait_on(func, what, walltime_exceeded)\n  File \"/opt/hostedtoolcache/Python/3.12.10/x64/lib/python3.12/site-packages/galaxy/tool_util/verify/wait.py\", line 38, in wait_on\n    value = function()\n            ^^^^^^^^^^\n  File \"/opt/hostedtoolcache/Python/3.12.10/x64/lib/python3.12/site-packages/galaxy/tool_util/verify/interactor.py\", line 399, in \u003clambda\u003e\n    self.wait_for(lambda: self.__job_ready(job_id, history_id), maxseconds=maxseconds)\n                          ^^^^^^^^^^^^^^^^^^^^^^^^^^^^^^^^^^^^\n  File \"/opt/hostedtoolcache/Python/3.12.10/x64/lib/python3.12/site-packages/galaxy/tool_util/verify/interactor.py\", line 747, in __job_ready\n    return self._state_ready(job_id, error_msg=\"Job in error state.\")\n           ^^^^^^^^^^^^^^^^^^^^^^^^^^^^^^^^^^^^^^^^^^^^^^^^^^^^^^^^^^\n  File \"/opt/hostedtoolcache/Python/3.12.10/x64/lib/python3.12/site-packages/galaxy/tool_util/verify/interactor.py\", line 839, in _state_ready\n    raise Exception(\nException: Job in error state.. tool_id: __DATA_FETCH__, exit_code: None, stderr: .\n", "status": "error", "test_index": 3, "time_seconds": 12.112993955612183, "tool_id": "bcftools_convert_to_vcf", "tool_version": "1.15.1+galaxy4"}
            ]]></error>
        
    </testcase>
    
    <testcase classname="bcftools_convert_to_vcf (Test #5)" name="4" time="">
        
            <error type="error" message=""><![CDATA[
                { "status": "skip", "test_index": 4, "tool_id": "bcftools_convert_to_vcf", "tool_version": "1.15.1+galaxy4"}
            ]]></error>
        
    </testcase>
    
    <testcase classname="bcftools_convert_to_vcf (Test #6)" name="5" time="19.493720531463623">
        
            <error type="error" message="Input staging problem: Traceback (most recent call last):
  File "/opt/hostedtoolcache/Python/3.12.10/x64/lib/python3.12/site-packages/galaxy/tool_util/verify/interactor.py", line 1434, in verify_tool
    stage_data_in_history(
  File "/opt/hostedtoolcache/Python/3.12.10/x64/lib/python3.12/site-packages/galaxy/tool_util/verify/interactor.py", line 175, in stage_data_in_history
    staging_interface.handle_jobs()
  File "/opt/hostedtoolcache/Python/3.12.10/x64/lib/python3.12/site-packages/galaxy/tool_util/verify/interactor.py", line 212, in handle_jobs
    self.galaxy_interactor.wait_for_job(job_response["id"], job_response["history_id"], self.maxseconds)
  File "/opt/hostedtoolcache/Python/3.12.10/x64/lib/python3.12/site-packages/galaxy/tool_util/verify/interactor.py", line 399, in wait_for_job
    self.wait_for(lambda: self.__job_ready(job_id, history_id), maxseconds=maxseconds)
  File "/opt/hostedtoolcache/Python/3.12.10/x64/lib/python3.12/site-packages/galaxy/tool_util/verify/interactor.py", line 403, in wait_for
    wait_on(func, what, walltime_exceeded)
  File "/opt/hostedtoolcache/Python/3.12.10/x64/lib/python3.12/site-packages/galaxy/tool_util/verify/wait.py", line 38, in wait_on
    value = function()
            ^^^^^^^^^^
  File "/opt/hostedtoolcache/Python/3.12.10/x64/lib/python3.12/site-packages/galaxy/tool_util/verify/interactor.py", line 399, in <lambda>
    self.wait_for(lambda: self.__job_ready(job_id, history_id), maxseconds=maxseconds)
                          ^^^^^^^^^^^^^^^^^^^^^^^^^^^^^^^^^^^^
  File "/opt/hostedtoolcache/Python/3.12.10/x64/lib/python3.12/site-packages/galaxy/tool_util/verify/interactor.py", line 747, in __job_ready
    return self._state_ready(job_id, error_msg="Job in error state.")
           ^^^^^^^^^^^^^^^^^^^^^^^^^^^^^^^^^^^^^^^^^^^^^^^^^^^^^^^^^^
  File "/opt/hostedtoolcache/Python/3.12.10/x64/lib/python3.12/site-packages/galaxy/tool_util/verify/interactor.py", line 839, in _state_ready
    raise Exception(
Exception: Job in error state.. tool_id: __DATA_FETCH__, exit_code: None, stderr: .
"><![CDATA[
                { "execution_problem": "Input staging problem: Traceback (most recent call last):\n  File \"/opt/hostedtoolcache/Python/3.12.10/x64/lib/python3.12/site-packages/galaxy/tool_util/verify/interactor.py\", line 1434, in verify_tool\n    stage_data_in_history(\n  File \"/opt/hostedtoolcache/Python/3.12.10/x64/lib/python3.12/site-packages/galaxy/tool_util/verify/interactor.py\", line 175, in stage_data_in_history\n    staging_interface.handle_jobs()\n  File \"/opt/hostedtoolcache/Python/3.12.10/x64/lib/python3.12/site-packages/galaxy/tool_util/verify/interactor.py\", line 212, in handle_jobs\n    self.galaxy_interactor.wait_for_job(job_response[\"id\"], job_response[\"history_id\"], self.maxseconds)\n  File \"/opt/hostedtoolcache/Python/3.12.10/x64/lib/python3.12/site-packages/galaxy/tool_util/verify/interactor.py\", line 399, in wait_for_job\n    self.wait_for(lambda: self.__job_ready(job_id, history_id), maxseconds=maxseconds)\n  File \"/opt/hostedtoolcache/Python/3.12.10/x64/lib/python3.12/site-packages/galaxy/tool_util/verify/interactor.py\", line 403, in wait_for\n    wait_on(func, what, walltime_exceeded)\n  File \"/opt/hostedtoolcache/Python/3.12.10/x64/lib/python3.12/site-packages/galaxy/tool_util/verify/wait.py\", line 38, in wait_on\n    value = function()\n            ^^^^^^^^^^\n  File \"/opt/hostedtoolcache/Python/3.12.10/x64/lib/python3.12/site-packages/galaxy/tool_util/verify/interactor.py\", line 399, in \u003clambda\u003e\n    self.wait_for(lambda: self.__job_ready(job_id, history_id), maxseconds=maxseconds)\n                          ^^^^^^^^^^^^^^^^^^^^^^^^^^^^^^^^^^^^\n  File \"/opt/hostedtoolcache/Python/3.12.10/x64/lib/python3.12/site-packages/galaxy/tool_util/verify/interactor.py\", line 747, in __job_ready\n    return self._state_ready(job_id, error_msg=\"Job in error state.\")\n           ^^^^^^^^^^^^^^^^^^^^^^^^^^^^^^^^^^^^^^^^^^^^^^^^^^^^^^^^^^\n  File \"/opt/hostedtoolcache/Python/3.12.10/x64/lib/python3.12/site-packages/galaxy/tool_util/verify/interactor.py\", line 839, in _state_ready\n    raise Exception(\nException: Job in error state.. tool_id: __DATA_FETCH__, exit_code: None, stderr: .\n", "status": "error", "test_index": 5, "time_seconds": 19.493720531463623, "tool_id": "bcftools_convert_to_vcf", "tool_version": "1.15.1+galaxy4"}
            ]]></error>
        
    </testcase>
    
    <testcase classname="bcftools_convert_to_vcf (Test #7)" name="6" time="">
        
            <error type="error" message=""><![CDATA[
                { "status": "skip", "test_index": 6, "tool_id": "bcftools_convert_to_vcf", "tool_version": "1.15.1+galaxy4"}
            ]]></error>
        
    </testcase>
    
    <testcase classname="bcftools_plugin_fill_an_ac (Test #1)" name="0" time="36.714690923690796">
        
            
            <system-out><![CDATA[
            
            ]]></system-out>
            <system-err><![CDATA[
            
            ]]></system-err>
        
    </testcase>
    
    <testcase classname="collection_column_join (Test #1)" name="0" time="0.13627934455871582">
        
            <error type="error" message="Input staging problem: Traceback (most recent call last):
  File "/opt/hostedtoolcache/Python/3.12.10/x64/lib/python3.12/site-packages/galaxy/tool_util/verify/interactor.py", line 1434, in verify_tool
    stage_data_in_history(
  File "/opt/hostedtoolcache/Python/3.12.10/x64/lib/python3.12/site-packages/galaxy/tool_util/verify/interactor.py", line 163, in stage_data_in_history
    test_dict = galaxy_interactor.remote_to_input(
                ^^^^^^^^^^^^^^^^^^^^^^^^^^^^^^^^^^
  File "/opt/hostedtoolcache/Python/3.12.10/x64/lib/python3.12/site-packages/galaxy/tool_util/verify/interactor.py", line 582, in remote_to_input
    path_or_location = self._get_path_or_location(
                       ^^^^^^^^^^^^^^^^^^^^^^^^^^^
  File "/opt/hostedtoolcache/Python/3.12.10/x64/lib/python3.12/site-packages/galaxy/tool_util/verify/interactor.py", line 619, in _get_path_or_location
    path = self.test_data_download(
           ^^^^^^^^^^^^^^^^^^^^^^^^
  File "/opt/hostedtoolcache/Python/3.12.10/x64/lib/python3.12/site-packages/galaxy/tool_util/verify/interactor.py", line 525, in test_data_download
    raise AssertionError(f"Test input file ({filename}) cannot be found.")
AssertionError: Test input file (in_1.tabular) cannot be found.
"><![CDATA[
                { "execution_problem": "Input staging problem: Traceback (most recent call last):\n  File \"/opt/hostedtoolcache/Python/3.12.10/x64/lib/python3.12/site-packages/galaxy/tool_util/verify/interactor.py\", line 1434, in verify_tool\n    stage_data_in_history(\n  File \"/opt/hostedtoolcache/Python/3.12.10/x64/lib/python3.12/site-packages/galaxy/tool_util/verify/interactor.py\", line 163, in stage_data_in_history\n    test_dict = galaxy_interactor.remote_to_input(\n                ^^^^^^^^^^^^^^^^^^^^^^^^^^^^^^^^^^\n  File \"/opt/hostedtoolcache/Python/3.12.10/x64/lib/python3.12/site-packages/galaxy/tool_util/verify/interactor.py\", line 582, in remote_to_input\n    path_or_location = self._get_path_or_location(\n                       ^^^^^^^^^^^^^^^^^^^^^^^^^^^\n  File \"/opt/hostedtoolcache/Python/3.12.10/x64/lib/python3.12/site-packages/galaxy/tool_util/verify/interactor.py\", line 619, in _get_path_or_location\n    path = self.test_data_download(\n           ^^^^^^^^^^^^^^^^^^^^^^^^\n  File \"/opt/hostedtoolcache/Python/3.12.10/x64/lib/python3.12/site-packages/galaxy/tool_util/verify/interactor.py\", line 525, in test_data_download\n    raise AssertionError(f\"Test input file ({filename}) cannot be found.\")\nAssertionError: Test input file (in_1.tabular) cannot be found.\n", "status": "error", "test_index": 0, "time_seconds": 0.13627934455871582, "tool_id": "collection_column_join", "tool_version": "0.0.3"}
            ]]></error>
        
    </testcase>
    
    <testcase classname="collection_column_join (Test #2)" name="1" time="0.07179045677185059">
        
            <error type="error" message="Input staging problem: Traceback (most recent call last):
  File "/opt/hostedtoolcache/Python/3.12.10/x64/lib/python3.12/site-packages/galaxy/tool_util/verify/interactor.py", line 1434, in verify_tool
    stage_data_in_history(
  File "/opt/hostedtoolcache/Python/3.12.10/x64/lib/python3.12/site-packages/galaxy/tool_util/verify/interactor.py", line 163, in stage_data_in_history
    test_dict = galaxy_interactor.remote_to_input(
                ^^^^^^^^^^^^^^^^^^^^^^^^^^^^^^^^^^
  File "/opt/hostedtoolcache/Python/3.12.10/x64/lib/python3.12/site-packages/galaxy/tool_util/verify/interactor.py", line 582, in remote_to_input
    path_or_location = self._get_path_or_location(
                       ^^^^^^^^^^^^^^^^^^^^^^^^^^^
  File "/opt/hostedtoolcache/Python/3.12.10/x64/lib/python3.12/site-packages/galaxy/tool_util/verify/interactor.py", line 619, in _get_path_or_location
    path = self.test_data_download(
           ^^^^^^^^^^^^^^^^^^^^^^^^
  File "/opt/hostedtoolcache/Python/3.12.10/x64/lib/python3.12/site-packages/galaxy/tool_util/verify/interactor.py", line 525, in test_data_download
    raise AssertionError(f"Test input file ({filename}) cannot be found.")
AssertionError: Test input file (in_1_headerless.tabular) cannot be found.
"><![CDATA[
                { "execution_problem": "Input staging problem: Traceback (most recent call last):\n  File \"/opt/hostedtoolcache/Python/3.12.10/x64/lib/python3.12/site-packages/galaxy/tool_util/verify/interactor.py\", line 1434, in verify_tool\n    stage_data_in_history(\n  File \"/opt/hostedtoolcache/Python/3.12.10/x64/lib/python3.12/site-packages/galaxy/tool_util/verify/interactor.py\", line 163, in stage_data_in_history\n    test_dict = galaxy_interactor.remote_to_input(\n                ^^^^^^^^^^^^^^^^^^^^^^^^^^^^^^^^^^\n  File \"/opt/hostedtoolcache/Python/3.12.10/x64/lib/python3.12/site-packages/galaxy/tool_util/verify/interactor.py\", line 582, in remote_to_input\n    path_or_location = self._get_path_or_location(\n                       ^^^^^^^^^^^^^^^^^^^^^^^^^^^\n  File \"/opt/hostedtoolcache/Python/3.12.10/x64/lib/python3.12/site-packages/galaxy/tool_util/verify/interactor.py\", line 619, in _get_path_or_location\n    path = self.test_data_download(\n           ^^^^^^^^^^^^^^^^^^^^^^^^\n  File \"/opt/hostedtoolcache/Python/3.12.10/x64/lib/python3.12/site-packages/galaxy/tool_util/verify/interactor.py\", line 525, in test_data_download\n    raise AssertionError(f\"Test input file ({filename}) cannot be found.\")\nAssertionError: Test input file (in_1_headerless.tabular) cannot be found.\n", "status": "error", "test_index": 1, "time_seconds": 0.07179045677185059, "tool_id": "collection_column_join", "tool_version": "0.0.3"}
            ]]></error>
        
    </testcase>
    
    <testcase classname="collection_column_join (Test #3)" name="2" time="0.07176470756530762">
        
            <error type="error" message="Input staging problem: Traceback (most recent call last):
  File "/opt/hostedtoolcache/Python/3.12.10/x64/lib/python3.12/site-packages/galaxy/tool_util/verify/interactor.py", line 1434, in verify_tool
    stage_data_in_history(
  File "/opt/hostedtoolcache/Python/3.12.10/x64/lib/python3.12/site-packages/galaxy/tool_util/verify/interactor.py", line 163, in stage_data_in_history
    test_dict = galaxy_interactor.remote_to_input(
                ^^^^^^^^^^^^^^^^^^^^^^^^^^^^^^^^^^
  File "/opt/hostedtoolcache/Python/3.12.10/x64/lib/python3.12/site-packages/galaxy/tool_util/verify/interactor.py", line 582, in remote_to_input
    path_or_location = self._get_path_or_location(
                       ^^^^^^^^^^^^^^^^^^^^^^^^^^^
  File "/opt/hostedtoolcache/Python/3.12.10/x64/lib/python3.12/site-packages/galaxy/tool_util/verify/interactor.py", line 619, in _get_path_or_location
    path = self.test_data_download(
           ^^^^^^^^^^^^^^^^^^^^^^^^
  File "/opt/hostedtoolcache/Python/3.12.10/x64/lib/python3.12/site-packages/galaxy/tool_util/verify/interactor.py", line 525, in test_data_download
    raise AssertionError(f"Test input file ({filename}) cannot be found.")
AssertionError: Test input file (in_1.tabular) cannot be found.
"><![CDATA[
                { "execution_problem": "Input staging problem: Traceback (most recent call last):\n  File \"/opt/hostedtoolcache/Python/3.12.10/x64/lib/python3.12/site-packages/galaxy/tool_util/verify/interactor.py\", line 1434, in verify_tool\n    stage_data_in_history(\n  File \"/opt/hostedtoolcache/Python/3.12.10/x64/lib/python3.12/site-packages/galaxy/tool_util/verify/interactor.py\", line 163, in stage_data_in_history\n    test_dict = galaxy_interactor.remote_to_input(\n                ^^^^^^^^^^^^^^^^^^^^^^^^^^^^^^^^^^\n  File \"/opt/hostedtoolcache/Python/3.12.10/x64/lib/python3.12/site-packages/galaxy/tool_util/verify/interactor.py\", line 582, in remote_to_input\n    path_or_location = self._get_path_or_location(\n                       ^^^^^^^^^^^^^^^^^^^^^^^^^^^\n  File \"/opt/hostedtoolcache/Python/3.12.10/x64/lib/python3.12/site-packages/galaxy/tool_util/verify/interactor.py\", line 619, in _get_path_or_location\n    path = self.test_data_download(\n           ^^^^^^^^^^^^^^^^^^^^^^^^\n  File \"/opt/hostedtoolcache/Python/3.12.10/x64/lib/python3.12/site-packages/galaxy/tool_util/verify/interactor.py\", line 525, in test_data_download\n    raise AssertionError(f\"Test input file ({filename}) cannot be found.\")\nAssertionError: Test input file (in_1.tabular) cannot be found.\n", "status": "error", "test_index": 2, "time_seconds": 0.07176470756530762, "tool_id": "collection_column_join", "tool_version": "0.0.3"}
            ]]></error>
        
    </testcase>
    
    <testcase classname="collection_column_join (Test #4)" name="3" time="0.07015180587768555">
        
            <error type="error" message="Input staging problem: Traceback (most recent call last):
  File "/opt/hostedtoolcache/Python/3.12.10/x64/lib/python3.12/site-packages/galaxy/tool_util/verify/interactor.py", line 1434, in verify_tool
    stage_data_in_history(
  File "/opt/hostedtoolcache/Python/3.12.10/x64/lib/python3.12/site-packages/galaxy/tool_util/verify/interactor.py", line 163, in stage_data_in_history
    test_dict = galaxy_interactor.remote_to_input(
                ^^^^^^^^^^^^^^^^^^^^^^^^^^^^^^^^^^
  File "/opt/hostedtoolcache/Python/3.12.10/x64/lib/python3.12/site-packages/galaxy/tool_util/verify/interactor.py", line 582, in remote_to_input
    path_or_location = self._get_path_or_location(
                       ^^^^^^^^^^^^^^^^^^^^^^^^^^^
  File "/opt/hostedtoolcache/Python/3.12.10/x64/lib/python3.12/site-packages/galaxy/tool_util/verify/interactor.py", line 619, in _get_path_or_location
    path = self.test_data_download(
           ^^^^^^^^^^^^^^^^^^^^^^^^
  File "/opt/hostedtoolcache/Python/3.12.10/x64/lib/python3.12/site-packages/galaxy/tool_util/verify/interactor.py", line 525, in test_data_download
    raise AssertionError(f"Test input file ({filename}) cannot be found.")
AssertionError: Test input file (in_1_headerless.tabular) cannot be found.
"><![CDATA[
                { "execution_problem": "Input staging problem: Traceback (most recent call last):\n  File \"/opt/hostedtoolcache/Python/3.12.10/x64/lib/python3.12/site-packages/galaxy/tool_util/verify/interactor.py\", line 1434, in verify_tool\n    stage_data_in_history(\n  File \"/opt/hostedtoolcache/Python/3.12.10/x64/lib/python3.12/site-packages/galaxy/tool_util/verify/interactor.py\", line 163, in stage_data_in_history\n    test_dict = galaxy_interactor.remote_to_input(\n                ^^^^^^^^^^^^^^^^^^^^^^^^^^^^^^^^^^\n  File \"/opt/hostedtoolcache/Python/3.12.10/x64/lib/python3.12/site-packages/galaxy/tool_util/verify/interactor.py\", line 582, in remote_to_input\n    path_or_location = self._get_path_or_location(\n                       ^^^^^^^^^^^^^^^^^^^^^^^^^^^\n  File \"/opt/hostedtoolcache/Python/3.12.10/x64/lib/python3.12/site-packages/galaxy/tool_util/verify/interactor.py\", line 619, in _get_path_or_location\n    path = self.test_data_download(\n           ^^^^^^^^^^^^^^^^^^^^^^^^\n  File \"/opt/hostedtoolcache/Python/3.12.10/x64/lib/python3.12/site-packages/galaxy/tool_util/verify/interactor.py\", line 525, in test_data_download\n    raise AssertionError(f\"Test input file ({filename}) cannot be found.\")\nAssertionError: Test input file (in_1_headerless.tabular) cannot be found.\n", "status": "error", "test_index": 3, "time_seconds": 0.07015180587768555, "tool_id": "collection_column_join", "tool_version": "0.0.3"}
            ]]></error>
        
    </testcase>
    
    <testcase classname="deeptools_plot_coverage (Test #1)" name="0" time="51.68040204048157">
        
            
            <system-out><![CDATA[
            samplemeanstdmin25%50%75%maxbowtie2 test1.bam0.504.1000.00.00.035bowtie2 test1.bam0.504.1000.00.00.035
            ]]></system-out>
            <system-err><![CDATA[
            
            ]]></system-err>
        
    </testcase>
    
    <testcase classname="deeptools_plot_coverage (Test #2)" name="1" time="33.85231924057007">
        
            
            <system-out><![CDATA[
            samplemeanstdmin25%50%75%maxbowtie2 test1.bam0.504.1000.00.00.035bowtie2 test1.bam0.504.1000.00.00.035
            ]]></system-out>
            <system-err><![CDATA[
            
            ]]></system-err>
        
    </testcase>
    
    <testcase classname="fastq_paired_end_interlacer (Test #1)" name="0" time="42.64741659164429">
        
            
            <system-out><![CDATA[
            There were 0 single reads.Interlaced 5 pairs of sequences.
            ]]></system-out>
            <system-err><![CDATA[
            
            ]]></system-err>
        
    </testcase>
    
    <testcase classname="fastq_paired_end_interlacer (Test #2)" name="1" time="33.3494086265564">
        
            
            <system-out><![CDATA[
            There were 4 single reads.Interlaced 3 pairs of sequences.
            ]]></system-out>
            <system-err><![CDATA[
            
            ]]></system-err>
        
    </testcase>
    
    <testcase classname="fastq_paired_end_interlacer (Test #3)" name="2" time="31.664379358291626">
        
            
            <system-out><![CDATA[
            There were 4 single reads.Interlaced 3 pairs of sequences.
            ]]></system-out>
            <system-err><![CDATA[
            
            ]]></system-err>
        
    </testcase>
    
    <testcase classname="fastq_paired_end_interlacer (Test #4)" name="3" time="31.373042345046997">
        
            
            <system-out><![CDATA[
            There were 4 single reads.Interlaced 3 pairs of sequences.
            ]]></system-out>
            <system-err><![CDATA[
            
            ]]></system-err>
        
    </testcase>
    
    <testcase classname="fastq_paired_end_interlacer (Test #5)" name="4" time="10.537148714065552">
        
            <error type="error" message="Input staging problem: Traceback (most recent call last):
  File "/opt/hostedtoolcache/Python/3.12.10/x64/lib/python3.12/site-packages/galaxy/tool_util/verify/interactor.py", line 1434, in verify_tool
    stage_data_in_history(
  File "/opt/hostedtoolcache/Python/3.12.10/x64/lib/python3.12/site-packages/galaxy/tool_util/verify/interactor.py", line 175, in stage_data_in_history
    staging_interface.handle_jobs()
  File "/opt/hostedtoolcache/Python/3.12.10/x64/lib/python3.12/site-packages/galaxy/tool_util/verify/interactor.py", line 212, in handle_jobs
    self.galaxy_interactor.wait_for_job(job_response["id"], job_response["history_id"], self.maxseconds)
  File "/opt/hostedtoolcache/Python/3.12.10/x64/lib/python3.12/site-packages/galaxy/tool_util/verify/interactor.py", line 399, in wait_for_job
    self.wait_for(lambda: self.__job_ready(job_id, history_id), maxseconds=maxseconds)
  File "/opt/hostedtoolcache/Python/3.12.10/x64/lib/python3.12/site-packages/galaxy/tool_util/verify/interactor.py", line 403, in wait_for
    wait_on(func, what, walltime_exceeded)
  File "/opt/hostedtoolcache/Python/3.12.10/x64/lib/python3.12/site-packages/galaxy/tool_util/verify/wait.py", line 38, in wait_on
    value = function()
            ^^^^^^^^^^
  File "/opt/hostedtoolcache/Python/3.12.10/x64/lib/python3.12/site-packages/galaxy/tool_util/verify/interactor.py", line 399, in <lambda>
    self.wait_for(lambda: self.__job_ready(job_id, history_id), maxseconds=maxseconds)
                          ^^^^^^^^^^^^^^^^^^^^^^^^^^^^^^^^^^^^
  File "/opt/hostedtoolcache/Python/3.12.10/x64/lib/python3.12/site-packages/galaxy/tool_util/verify/interactor.py", line 747, in __job_ready
    return self._state_ready(job_id, error_msg="Job in error state.")
           ^^^^^^^^^^^^^^^^^^^^^^^^^^^^^^^^^^^^^^^^^^^^^^^^^^^^^^^^^^
  File "/opt/hostedtoolcache/Python/3.12.10/x64/lib/python3.12/site-packages/galaxy/tool_util/verify/interactor.py", line 839, in _state_ready
    raise Exception(
Exception: Job in error state.. tool_id: __DATA_FETCH__, exit_code: None, stderr: .
"><![CDATA[
                { "execution_problem": "Input staging problem: Traceback (most recent call last):\n  File \"/opt/hostedtoolcache/Python/3.12.10/x64/lib/python3.12/site-packages/galaxy/tool_util/verify/interactor.py\", line 1434, in verify_tool\n    stage_data_in_history(\n  File \"/opt/hostedtoolcache/Python/3.12.10/x64/lib/python3.12/site-packages/galaxy/tool_util/verify/interactor.py\", line 175, in stage_data_in_history\n    staging_interface.handle_jobs()\n  File \"/opt/hostedtoolcache/Python/3.12.10/x64/lib/python3.12/site-packages/galaxy/tool_util/verify/interactor.py\", line 212, in handle_jobs\n    self.galaxy_interactor.wait_for_job(job_response[\"id\"], job_response[\"history_id\"], self.maxseconds)\n  File \"/opt/hostedtoolcache/Python/3.12.10/x64/lib/python3.12/site-packages/galaxy/tool_util/verify/interactor.py\", line 399, in wait_for_job\n    self.wait_for(lambda: self.__job_ready(job_id, history_id), maxseconds=maxseconds)\n  File \"/opt/hostedtoolcache/Python/3.12.10/x64/lib/python3.12/site-packages/galaxy/tool_util/verify/interactor.py\", line 403, in wait_for\n    wait_on(func, what, walltime_exceeded)\n  File \"/opt/hostedtoolcache/Python/3.12.10/x64/lib/python3.12/site-packages/galaxy/tool_util/verify/wait.py\", line 38, in wait_on\n    value = function()\n            ^^^^^^^^^^\n  File \"/opt/hostedtoolcache/Python/3.12.10/x64/lib/python3.12/site-packages/galaxy/tool_util/verify/interactor.py\", line 399, in \u003clambda\u003e\n    self.wait_for(lambda: self.__job_ready(job_id, history_id), maxseconds=maxseconds)\n                          ^^^^^^^^^^^^^^^^^^^^^^^^^^^^^^^^^^^^\n  File \"/opt/hostedtoolcache/Python/3.12.10/x64/lib/python3.12/site-packages/galaxy/tool_util/verify/interactor.py\", line 747, in __job_ready\n    return self._state_ready(job_id, error_msg=\"Job in error state.\")\n           ^^^^^^^^^^^^^^^^^^^^^^^^^^^^^^^^^^^^^^^^^^^^^^^^^^^^^^^^^^\n  File \"/opt/hostedtoolcache/Python/3.12.10/x64/lib/python3.12/site-packages/galaxy/tool_util/verify/interactor.py\", line 839, in _state_ready\n    raise Exception(\nException: Job in error state.. tool_id: __DATA_FETCH__, exit_code: None, stderr: .\n", "status": "error", "test_index": 4, "time_seconds": 10.537148714065552, "tool_id": "fastq_paired_end_interlacer", "tool_version": "1.2.0.1+galaxy0"}
            ]]></error>
        
    </testcase>
    
    <testcase classname="ivar_consensus (Test #1)" name="0" time="40.83544158935547">
        
            
            <system-out><![CDATA[
            Minimum Quality: 20Threshold: 0Minimum depth: 10Minimum Insert Threshold: 0.8Regions with depth less than minimum depth covered by: NReference length: 29903Positions with 0 depth: 113Positions with depth below 10: 1034
            ]]></system-out>
            <system-err><![CDATA[
            [mpileup] 1 samples in 1 input files[mpileup] Max depth set to maximum value (2147483647)
            ]]></system-err>
        
    </testcase>
    
    <testcase classname="jq (Test #1)" name="0" time="66.38766717910767">
        
            
            <system-out><![CDATA[
            
            ]]></system-out>
            <system-err><![CDATA[
            
            ]]></system-err>
        
    </testcase>
    
    <testcase classname="jq (Test #2)" name="1" time="23.130515813827515">
        
            
                <error type="error" message="Tool exit code: None"><![CDATA[
                    { "inputs": {  "filter": "{\"a\": env}",  "input": {   "id": "1a690a24dbe6e6ed",   "src": "hda"  },  "tsv": false }, "job": {  "command_line": "JQ_BIN=`which jq` \u0026\u0026 cat \u0027/galaxy/server/database/objects/9/3/1/dataset_9311f970-5fcc-4188-aab8-ac9eb4c9a370.dat\u0027 | env -i JQ_BIN=$JQ_BIN $JQ_BIN -r -S \u0027{\"a\": env} \u0027 \u003e \u0027/galaxy/server/database/objects/7/6/b/dataset_76bf73bb-0ad1-4dce-b9ab-4cca8d1c763b.dat\u0027",  "command_version": null,  "copied_from_job_id": null,  "create_time": "2025-05-07T13:00:57.815749",  "dependencies": [],  "exit_code": null,  "external_id": "gxy-q65v2",  "galaxy_version": "24.1",  "handler": null,  "history_id": "3ffb4f16db81f4ab",  "id": "2ea7b75921c8a1bb",  "inputs": {   "input": {    "id": "1a690a24dbe6e6ed",    "src": "hda",    "uuid": "9311f970-5fcc-4188-aab8-ac9eb4c9a370"   }  },  "job_messages": null,  "job_metrics": [],  "job_runner_name": null,  "job_stderr": null,  "job_stdout": null,  "model_class": "Job",  "output_collections": {},  "outputs": {   "output": {    "id": "2ea7b75921c8a1bb",    "src": "hda",    "uuid": "76bf73bb-0ad1-4dce-b9ab-4cca8d1c763b"   }  },  "params": {   "__input_ext": "\"json\"",   "chromInfo": "\"/cvmfs/data.galaxyproject.org/managed/len/ucsc/?.len\"",   "dbkey": "\"?\"",   "filter": "\"{\\\"a\\\": env}\"",   "tsv": "false"  },  "state": "error",  "stderr": "",  "stdout": "",  "tool_id": "toolshed.g2.bx.psu.edu/repos/iuc/jq/jq/1.0",  "tool_stderr": "",  "tool_stdout": "",  "update_time": "2025-05-07T13:01:02.793819",  "user_email": "tests@fake.org" }, "output_problems": [  "Job in error state.. tool_id: toolshed.g2.bx.psu.edu/repos/iuc/jq/jq/1.0, exit_code: None, stderr: .",  "Job in error state.. tool_id: toolshed.g2.bx.psu.edu/repos/iuc/jq/jq/1.0, exit_code: None, stderr: ." ], "status": "failure", "test_index": 1, "time_seconds": 23.130515813827515, "tool_id": "jq", "tool_version": "1.0"}
                ]]></error>
            
            <system-out><![CDATA[
            
            ]]></system-out>
            <system-err><![CDATA[
            
            ]]></system-err>
        
    </testcase>
    
    <testcase classname="medaka_variant_pipeline (Test #1)" name="0" time="">
        
            <error type="error" message=""><![CDATA[
                { "status": "skip", "test_index": 0, "tool_id": "medaka_variant_pipeline", "tool_version": "1.4.4+galaxy1"}
            ]]></error>
        
    </testcase>
    
    <testcase classname="miniasm (Test #1)" name="0" time="47.787768602371216">
        
            
            <system-out><![CDATA[
            
            ]]></system-out>
            <system-err><![CDATA[
            [M::main] ===> Step 1: reading read mappings <===[M::ma_hit_read::0.099*1.00] read 100000 hits; stored 187742 hits and 12067 sequences (111354001 bp)[M::main] ===> Step 2: 1-pass (crude) read selection <===[M::ma_hit_sub::0.113*1.00] 9155 query sequences remain after sub[M::ma_hit_cut::0.115*1.00] 161122 hits remain after cut[M::ma_hit_flt::0.117*1.00] 156936 hits remain after filtering; crude coverage after filtering: 11.85[M::main] ===> Step 3: 2-pass (fine) read selection <===[M::ma_hit_sub::0.122*1.00] 9023 query sequences remain after sub[M::ma_hit_cut::0.124*1.00] 152071 hits remain after cut[M::ma_hit_contained::0.127*1.00] 1536 sequences and 8359 hits remain after containment removal[M::main] ===> Step 4: graph cleaning <===[M::ma_sg_gen] read 8236 arcs[M::main] ===> Step 4.1: transitive reduction <===[M::asg_arc_del_trans] transitively reduced 4182 arcs[M::asg_arc_del_multi] removed 0 multi-arcs[M::asg_arc_del_asymm] removed 362 asymmetric arcs[M::main] ===> Step 4.2: initial tip cutting and bubble popping <===[M::asg_cut_tip] cut 260 tips[M::asg_pop_bubble] popped 105 bubbles and trimmed 4 tips[M::main] ===> Step 4.3: cutting short overlaps (3 rounds in total) <===[M::asg_arc_del_multi] removed 0 multi-arcs[M::asg_arc_del_asymm] removed 29 asymmetric arcs[M::asg_arc_del_short] removed 37 short overlaps[M::asg_cut_tip] cut 104 tips[M::asg_pop_bubble] popped 1 bubbles and trimmed 0 tips[M::asg_arc_del_multi] removed 0 multi-arcs[M::asg_arc_del_asymm] removed 1 asymmetric arcs[M::asg_arc_del_short] removed 1 short overlaps[M::asg_cut_tip] cut 3 tips[M::asg_pop_bubble] popped 0 bubbles and trimmed 0 tips[M::asg_arc_del_short] removed 0 short overlaps[M::main] ===> Step 4.4: removing short internal sequences and bi-loops <===[M::asg_cut_internal] cut 0 internal sequences[M::asg_cut_biloop] cut 0 small bi-loops[M::asg_cut_tip] cut 0 tips[M::asg_pop_bubble] popped 0 bubbles and trimmed 0 tips[M::main] ===> Step 4.5: aggressively cutting short overlaps <===[M::asg_arc_del_short] removed 0 short overlaps[M::main] ===> Step 5: generating unitigs <===[M::main] Version: 0.3-r179[M::main] CMD: miniasm -f /galaxy/server/database/objects/9/9/f/dataset_99fa890b-7bcf-4842-9718-be13abbda63d.dat -m 100 -i 0.05 -s 1000 -c 3 -o 1000 -h 1000 -I 0.08 -g 1000 -d 50000 -e 4 -n 3 -F 0.8 /galaxy/server/database/objects/4/f/e/dataset_4fe40925-14f3-42e4-b0be-6ceb2ef06879.dat[M::main] Real time: 0.135 sec; CPU: 0.134 sec
            ]]></system-err>
        
    </testcase>
    
    <testcase classname="miniasm (Test #2)" name="1" time="11.951184511184692">
        
            <error type="error" message="Input staging problem: Traceback (most recent call last):
  File "/opt/hostedtoolcache/Python/3.12.10/x64/lib/python3.12/site-packages/galaxy/tool_util/verify/interactor.py", line 1434, in verify_tool
    stage_data_in_history(
  File "/opt/hostedtoolcache/Python/3.12.10/x64/lib/python3.12/site-packages/galaxy/tool_util/verify/interactor.py", line 175, in stage_data_in_history
    staging_interface.handle_jobs()
  File "/opt/hostedtoolcache/Python/3.12.10/x64/lib/python3.12/site-packages/galaxy/tool_util/verify/interactor.py", line 212, in handle_jobs
    self.galaxy_interactor.wait_for_job(job_response["id"], job_response["history_id"], self.maxseconds)
  File "/opt/hostedtoolcache/Python/3.12.10/x64/lib/python3.12/site-packages/galaxy/tool_util/verify/interactor.py", line 399, in wait_for_job
    self.wait_for(lambda: self.__job_ready(job_id, history_id), maxseconds=maxseconds)
  File "/opt/hostedtoolcache/Python/3.12.10/x64/lib/python3.12/site-packages/galaxy/tool_util/verify/interactor.py", line 403, in wait_for
    wait_on(func, what, walltime_exceeded)
  File "/opt/hostedtoolcache/Python/3.12.10/x64/lib/python3.12/site-packages/galaxy/tool_util/verify/wait.py", line 38, in wait_on
    value = function()
            ^^^^^^^^^^
  File "/opt/hostedtoolcache/Python/3.12.10/x64/lib/python3.12/site-packages/galaxy/tool_util/verify/interactor.py", line 399, in <lambda>
    self.wait_for(lambda: self.__job_ready(job_id, history_id), maxseconds=maxseconds)
                          ^^^^^^^^^^^^^^^^^^^^^^^^^^^^^^^^^^^^
  File "/opt/hostedtoolcache/Python/3.12.10/x64/lib/python3.12/site-packages/galaxy/tool_util/verify/interactor.py", line 747, in __job_ready
    return self._state_ready(job_id, error_msg="Job in error state.")
           ^^^^^^^^^^^^^^^^^^^^^^^^^^^^^^^^^^^^^^^^^^^^^^^^^^^^^^^^^^
  File "/opt/hostedtoolcache/Python/3.12.10/x64/lib/python3.12/site-packages/galaxy/tool_util/verify/interactor.py", line 839, in _state_ready
    raise Exception(
Exception: Job in error state.. tool_id: __DATA_FETCH__, exit_code: None, stderr: .
"><![CDATA[
                { "execution_problem": "Input staging problem: Traceback (most recent call last):\n  File \"/opt/hostedtoolcache/Python/3.12.10/x64/lib/python3.12/site-packages/galaxy/tool_util/verify/interactor.py\", line 1434, in verify_tool\n    stage_data_in_history(\n  File \"/opt/hostedtoolcache/Python/3.12.10/x64/lib/python3.12/site-packages/galaxy/tool_util/verify/interactor.py\", line 175, in stage_data_in_history\n    staging_interface.handle_jobs()\n  File \"/opt/hostedtoolcache/Python/3.12.10/x64/lib/python3.12/site-packages/galaxy/tool_util/verify/interactor.py\", line 212, in handle_jobs\n    self.galaxy_interactor.wait_for_job(job_response[\"id\"], job_response[\"history_id\"], self.maxseconds)\n  File \"/opt/hostedtoolcache/Python/3.12.10/x64/lib/python3.12/site-packages/galaxy/tool_util/verify/interactor.py\", line 399, in wait_for_job\n    self.wait_for(lambda: self.__job_ready(job_id, history_id), maxseconds=maxseconds)\n  File \"/opt/hostedtoolcache/Python/3.12.10/x64/lib/python3.12/site-packages/galaxy/tool_util/verify/interactor.py\", line 403, in wait_for\n    wait_on(func, what, walltime_exceeded)\n  File \"/opt/hostedtoolcache/Python/3.12.10/x64/lib/python3.12/site-packages/galaxy/tool_util/verify/wait.py\", line 38, in wait_on\n    value = function()\n            ^^^^^^^^^^\n  File \"/opt/hostedtoolcache/Python/3.12.10/x64/lib/python3.12/site-packages/galaxy/tool_util/verify/interactor.py\", line 399, in \u003clambda\u003e\n    self.wait_for(lambda: self.__job_ready(job_id, history_id), maxseconds=maxseconds)\n                          ^^^^^^^^^^^^^^^^^^^^^^^^^^^^^^^^^^^^\n  File \"/opt/hostedtoolcache/Python/3.12.10/x64/lib/python3.12/site-packages/galaxy/tool_util/verify/interactor.py\", line 747, in __job_ready\n    return self._state_ready(job_id, error_msg=\"Job in error state.\")\n           ^^^^^^^^^^^^^^^^^^^^^^^^^^^^^^^^^^^^^^^^^^^^^^^^^^^^^^^^^^\n  File \"/opt/hostedtoolcache/Python/3.12.10/x64/lib/python3.12/site-packages/galaxy/tool_util/verify/interactor.py\", line 839, in _state_ready\n    raise Exception(\nException: Job in error state.. tool_id: __DATA_FETCH__, exit_code: None, stderr: .\n", "status": "error", "test_index": 1, "time_seconds": 11.951184511184692, "tool_id": "miniasm", "tool_version": "0.3_r179+galaxy1"}
            ]]></error>
        
    </testcase>
    
    <testcase classname="poretools_qualdist (Test #1)" name="0" time="55.31456995010376">
        
            
            <system-out><![CDATA[
            
            ]]></system-out>
            <system-err><![CDATA[
            
            ]]></system-err>
        
    </testcase>
    
    <testcase classname="poretools_qualdist (Test #2)" name="1" time="24.461843013763428">
        
            
                <error type="error" message="Tool exit code: None"><![CDATA[
                    { "inputs": {  "input": {   "id": "11953eccd2ec51d1",   "src": "hda"  } }, "job": {  "command_line": "poretools qualdist \u0027/galaxy/server/database/objects/8/7/b/dataset_87b71313-bdac-4f13-a908-c41a9b3e3c8e.dat\u0027 \u003e \u0027/galaxy/server/database/objects/4/e/c/dataset_4ecaecaf-5cd6-4ace-9ced-a1cc7eb4c244.dat\u0027",  "command_version": null,  "copied_from_job_id": null,  "create_time": "2025-05-07T13:11:20.173631",  "dependencies": [],  "exit_code": null,  "external_id": "gxy-hql28",  "galaxy_version": "24.1",  "handler": null,  "history_id": "3ffb4f16db81f4ab",  "id": "eb22f4a6e41a6f58",  "inputs": {   "input": {    "id": "11953eccd2ec51d1",    "src": "hda",    "uuid": "87b71313-bdac-4f13-a908-c41a9b3e3c8e"   }  },  "job_messages": null,  "job_metrics": [],  "job_runner_name": null,  "job_stderr": null,  "job_stdout": null,  "model_class": "Job",  "output_collections": {},  "outputs": {   "output": {    "id": "111033f6ea449ba8",    "src": "hda",    "uuid": "4ecaecaf-5cd6-4ace-9ced-a1cc7eb4c244"   }  },  "params": {   "__input_ext": "\"input\"",   "chromInfo": "\"/cvmfs/data.galaxyproject.org/managed/len/ucsc/?.len\"",   "dbkey": "\"?\""  },  "state": "error",  "stderr": "",  "stdout": "",  "tool_id": "toolshed.g2.bx.psu.edu/repos/iuc/poretools_qualdist/poretools_qualdist/0.6.1a1.0",  "tool_stderr": "",  "tool_stdout": "",  "update_time": "2025-05-07T13:11:26.006061",  "user_email": "tests@fake.org" }, "output_problems": [  "Job in error state.. tool_id: toolshed.g2.bx.psu.edu/repos/iuc/poretools_qualdist/poretools_qualdist/0.6.1a1.0, exit_code: None, stderr: .",  "Job in error state.. tool_id: toolshed.g2.bx.psu.edu/repos/iuc/poretools_qualdist/poretools_qualdist/0.6.1a1.0, exit_code: None, stderr: ." ], "status": "failure", "test_index": 1, "time_seconds": 24.461843013763428, "tool_id": "poretools_qualdist", "tool_version": "0.6.1a1.0"}
                ]]></error>
            
            <system-out><![CDATA[
            
            ]]></system-out>
            <system-err><![CDATA[
            
            ]]></system-err>
        
    </testcase>
    
    <testcase classname="sam2interval (Test #1)" name="0" time="42.66806721687317">
        
            
            <system-out><![CDATA[
            
            ]]></system-out>
            <system-err><![CDATA[
            
            ]]></system-err>
        
    </testcase>
    
    <testcase classname="sam2interval (Test #2)" name="1" time="32.58552622795105">
        
            
            <system-out><![CDATA[
            
            ]]></system-out>
            <system-err><![CDATA[
            
            ]]></system-err>
        
    </testcase>
    
    <testcase classname="sam2interval (Test #3)" name="2" time="24.2270028591156">
        
            
                <error type="error" message="Tool exit code: None"><![CDATA[
                    { "inputs": {  "input1": {   "id": "fed200b0d8aa63a5",   "src": "hda"  },  "print_all": "" }, "job": {  "command_line": "python \u0027/cvmfs/cloud.galaxyproject.org/tools/toolshed.g2.bx.psu.edu/repos/devteam/sam2interval/75557c0908a9/sam2interval/sam2interval.py\u0027 --input_sam_file=\u0027/galaxy/server/database/objects/4/a/0/dataset_4a0fb92c-dfe1-4ee4-a608-3757a030ab11.dat\u0027  \u003e \u0027/galaxy/server/database/objects/f/1/5/dataset_f151438f-f3ac-4eed-83f0-e3635c08fdd1.dat\u0027",  "command_version": null,  "copied_from_job_id": null,  "create_time": "2025-05-07T13:05:09.630588",  "dependencies": [],  "exit_code": null,  "external_id": "gxy-vn2hj",  "galaxy_version": "24.1",  "handler": null,  "history_id": "3ffb4f16db81f4ab",  "id": "ebd63f338ed65415",  "inputs": {   "input1": {    "id": "fed200b0d8aa63a5",    "src": "hda",    "uuid": "4a0fb92c-dfe1-4ee4-a608-3757a030ab11"   }  },  "job_messages": null,  "job_metrics": [],  "job_runner_name": null,  "job_stderr": null,  "job_stdout": null,  "model_class": "Job",  "output_collections": {},  "outputs": {   "out_file1": {    "id": "c6ddd88086903cb7",    "src": "hda",    "uuid": "f151438f-f3ac-4eed-83f0-e3635c08fdd1"   }  },  "params": {   "__input_ext": "\"input\"",   "chromInfo": "\"/cvmfs/data.galaxyproject.org/managed/len/ucsc/?.len\"",   "dbkey": "\"?\"",   "print_all": "\"\""  },  "state": "error",  "stderr": "",  "stdout": "",  "tool_id": "toolshed.g2.bx.psu.edu/repos/devteam/sam2interval/sam2interval/1.0.2",  "tool_stderr": "",  "tool_stdout": "",  "update_time": "2025-05-07T13:05:14.598109",  "user_email": "tests@fake.org" }, "output_problems": [  "Job in error state.. tool_id: toolshed.g2.bx.psu.edu/repos/devteam/sam2interval/sam2interval/1.0.2, exit_code: None, stderr: .",  "Job in error state.. tool_id: toolshed.g2.bx.psu.edu/repos/devteam/sam2interval/sam2interval/1.0.2, exit_code: None, stderr: ." ], "status": "failure", "test_index": 2, "time_seconds": 24.2270028591156, "tool_id": "sam2interval", "tool_version": "1.0.2"}
                ]]></error>
            
            <system-out><![CDATA[
            
            ]]></system-out>
            <system-err><![CDATA[
            
            ]]></system-err>
        
    </testcase>
    
    <testcase classname="samtools_flagstat (Test #1)" name="0" time="12.399574279785156">
        
            <error type="error" message="Input staging problem: Traceback (most recent call last):
  File "/opt/hostedtoolcache/Python/3.12.10/x64/lib/python3.12/site-packages/galaxy/tool_util/verify/interactor.py", line 1434, in verify_tool
    stage_data_in_history(
  File "/opt/hostedtoolcache/Python/3.12.10/x64/lib/python3.12/site-packages/galaxy/tool_util/verify/interactor.py", line 175, in stage_data_in_history
    staging_interface.handle_jobs()
  File "/opt/hostedtoolcache/Python/3.12.10/x64/lib/python3.12/site-packages/galaxy/tool_util/verify/interactor.py", line 212, in handle_jobs
    self.galaxy_interactor.wait_for_job(job_response["id"], job_response["history_id"], self.maxseconds)
  File "/opt/hostedtoolcache/Python/3.12.10/x64/lib/python3.12/site-packages/galaxy/tool_util/verify/interactor.py", line 399, in wait_for_job
    self.wait_for(lambda: self.__job_ready(job_id, history_id), maxseconds=maxseconds)
  File "/opt/hostedtoolcache/Python/3.12.10/x64/lib/python3.12/site-packages/galaxy/tool_util/verify/interactor.py", line 403, in wait_for
    wait_on(func, what, walltime_exceeded)
  File "/opt/hostedtoolcache/Python/3.12.10/x64/lib/python3.12/site-packages/galaxy/tool_util/verify/wait.py", line 38, in wait_on
    value = function()
            ^^^^^^^^^^
  File "/opt/hostedtoolcache/Python/3.12.10/x64/lib/python3.12/site-packages/galaxy/tool_util/verify/interactor.py", line 399, in <lambda>
    self.wait_for(lambda: self.__job_ready(job_id, history_id), maxseconds=maxseconds)
                          ^^^^^^^^^^^^^^^^^^^^^^^^^^^^^^^^^^^^
  File "/opt/hostedtoolcache/Python/3.12.10/x64/lib/python3.12/site-packages/galaxy/tool_util/verify/interactor.py", line 747, in __job_ready
    return self._state_ready(job_id, error_msg="Job in error state.")
           ^^^^^^^^^^^^^^^^^^^^^^^^^^^^^^^^^^^^^^^^^^^^^^^^^^^^^^^^^^
  File "/opt/hostedtoolcache/Python/3.12.10/x64/lib/python3.12/site-packages/galaxy/tool_util/verify/interactor.py", line 839, in _state_ready
    raise Exception(
Exception: Job in error state.. tool_id: __DATA_FETCH__, exit_code: None, stderr: .
"><![CDATA[
                { "execution_problem": "Input staging problem: Traceback (most recent call last):\n  File \"/opt/hostedtoolcache/Python/3.12.10/x64/lib/python3.12/site-packages/galaxy/tool_util/verify/interactor.py\", line 1434, in verify_tool\n    stage_data_in_history(\n  File \"/opt/hostedtoolcache/Python/3.12.10/x64/lib/python3.12/site-packages/galaxy/tool_util/verify/interactor.py\", line 175, in stage_data_in_history\n    staging_interface.handle_jobs()\n  File \"/opt/hostedtoolcache/Python/3.12.10/x64/lib/python3.12/site-packages/galaxy/tool_util/verify/interactor.py\", line 212, in handle_jobs\n    self.galaxy_interactor.wait_for_job(job_response[\"id\"], job_response[\"history_id\"], self.maxseconds)\n  File \"/opt/hostedtoolcache/Python/3.12.10/x64/lib/python3.12/site-packages/galaxy/tool_util/verify/interactor.py\", line 399, in wait_for_job\n    self.wait_for(lambda: self.__job_ready(job_id, history_id), maxseconds=maxseconds)\n  File \"/opt/hostedtoolcache/Python/3.12.10/x64/lib/python3.12/site-packages/galaxy/tool_util/verify/interactor.py\", line 403, in wait_for\n    wait_on(func, what, walltime_exceeded)\n  File \"/opt/hostedtoolcache/Python/3.12.10/x64/lib/python3.12/site-packages/galaxy/tool_util/verify/wait.py\", line 38, in wait_on\n    value = function()\n            ^^^^^^^^^^\n  File \"/opt/hostedtoolcache/Python/3.12.10/x64/lib/python3.12/site-packages/galaxy/tool_util/verify/interactor.py\", line 399, in \u003clambda\u003e\n    self.wait_for(lambda: self.__job_ready(job_id, history_id), maxseconds=maxseconds)\n                          ^^^^^^^^^^^^^^^^^^^^^^^^^^^^^^^^^^^^\n  File \"/opt/hostedtoolcache/Python/3.12.10/x64/lib/python3.12/site-packages/galaxy/tool_util/verify/interactor.py\", line 747, in __job_ready\n    return self._state_ready(job_id, error_msg=\"Job in error state.\")\n           ^^^^^^^^^^^^^^^^^^^^^^^^^^^^^^^^^^^^^^^^^^^^^^^^^^^^^^^^^^\n  File \"/opt/hostedtoolcache/Python/3.12.10/x64/lib/python3.12/site-packages/galaxy/tool_util/verify/interactor.py\", line 839, in _state_ready\n    raise Exception(\nException: Job in error state.. tool_id: __DATA_FETCH__, exit_code: None, stderr: .\n", "status": "error", "test_index": 0, "time_seconds": 12.399574279785156, "tool_id": "samtools_flagstat", "tool_version": "2.0.5"}
            ]]></error>
        
    </testcase>
    
    <testcase classname="samtools_flagstat (Test #2)" name="1" time="32.60114312171936">
        
            
            <system-out><![CDATA[
            
            ]]></system-out>
            <system-err><![CDATA[
            
            ]]></system-err>
        
    </testcase>
    
    <testcase classname="samtools_flagstat (Test #3)" name="2" time="32.56496834754944">
        
            
            <system-out><![CDATA[
            
            ]]></system-out>
            <system-err><![CDATA[
            
            ]]></system-err>
        
    </testcase>
    
    <testcase classname="vcfaddinfo (Test #1)" name="0" time="31.04130983352661">
        
            
                <error type="error" message="Tool exit code: None"><![CDATA[
                    { "inputs": {  "input1": {   "id": "95415701b39afcc3",   "src": "hda"  },  "input2": {   "id": "55229dacc14c3482",   "src": "hda"  } }, "job": {  "command_line": "vcfaddinfo \u0027/galaxy/server/database/objects/4/8/a/dataset_48a1429c-b806-4cc1-ad50-e79f0f4ef12d.dat\u0027 \u0027/galaxy/server/database/objects/3/6/5/dataset_36516ece-8a84-4cd5-8489-dcd3dc3ba1e9.dat\u0027 \u003e \u0027/galaxy/server/database/objects/e/8/8/dataset_e88858f7-42bb-43f9-ae0b-58c18e029c57.dat\u0027",  "command_version": null,  "copied_from_job_id": null,  "create_time": "2025-05-07T13:09:26.029625",  "dependencies": [],  "exit_code": null,  "external_id": "gxy-rm4rv",  "galaxy_version": "24.1",  "handler": null,  "history_id": "3ffb4f16db81f4ab",  "id": "4da2627898d54b48",  "inputs": {   "input1": {    "id": "95415701b39afcc3",    "src": "hda",    "uuid": "48a1429c-b806-4cc1-ad50-e79f0f4ef12d"   },   "input2": {    "id": "55229dacc14c3482",    "src": "hda",    "uuid": "36516ece-8a84-4cd5-8489-dcd3dc3ba1e9"   }  },  "job_messages": null,  "job_metrics": [],  "job_runner_name": null,  "job_stderr": null,  "job_stdout": null,  "model_class": "Job",  "output_collections": {},  "outputs": {   "out_file1": {    "id": "8de4cefec7f514fc",    "src": "hda",    "uuid": "e88858f7-42bb-43f9-ae0b-58c18e029c57"   }  },  "params": {   "__input_ext": "\"vcf\"",   "chromInfo": "\"/cvmfs/data.galaxyproject.org/managed/len/ucsc/?.len\"",   "dbkey": "\"?\""  },  "state": "error",  "stderr": "",  "stdout": "",  "tool_id": "toolshed.g2.bx.psu.edu/repos/devteam/vcfaddinfo/vcfaddinfo/1.0.0_rc3+galaxy0",  "tool_stderr": "",  "tool_stdout": "",  "update_time": "2025-05-07T13:09:38.100101",  "user_email": "tests@fake.org" }, "output_problems": [  "Job in error state.. tool_id: toolshed.g2.bx.psu.edu/repos/devteam/vcfaddinfo/vcfaddinfo/1.0.0_rc3+galaxy0, exit_code: None, stderr: .",  "Job in error state.. tool_id: toolshed.g2.bx.psu.edu/repos/devteam/vcfaddinfo/vcfaddinfo/1.0.0_rc3+galaxy0, exit_code: None, stderr: ." ], "status": "failure", "test_index": 0, "time_seconds": 31.04130983352661, "tool_id": "vcfaddinfo", "tool_version": "1.0.0_rc3+galaxy0"}
                ]]></error>
            
            <system-out><![CDATA[
            
            ]]></system-out>
            <system-err><![CDATA[
            
            ]]></system-err>
        
    </testcase>
    
    <testcase classname="vcfleftalign (Test #1)" name="0" time="24.45264959335327">
        
            
                <error type="error" message="Tool exit code: None"><![CDATA[
                    { "inputs": {  "input_vcf": {   "id": "c75a114c6e2f9705",   "src": "hda"  },  "reference_source|ref_file": {   "id": "1e71fe52bb3db247",   "src": "hda"  },  "reference_source|reference_source_selector": "history",  "window_size": "150" }, "job": {  "command_line": "ln -s \u0027/galaxy/server/database/objects/a/7/6/dataset_a767cd89-16a5-4c82-bf1b-289ef86d0d7a.dat\u0027 \u0027localref.fa\u0027 \u0026\u0026 vcfleftalign -r \u0027localref.fa\u0027 -w \"150\" \u0027/galaxy/server/database/objects/7/6/1/dataset_761cdf6a-cb41-4d22-aadc-c6561121da54.dat\u0027 \u003e \u0027/galaxy/server/database/objects/8/4/0/dataset_8407fbe3-04e6-427e-aba5-609b7a1779fc.dat\u0027",  "command_version": null,  "copied_from_job_id": null,  "create_time": "2025-05-07T13:09:58.302288",  "dependencies": [],  "exit_code": null,  "external_id": "gxy-xbb2s",  "galaxy_version": "24.1",  "handler": null,  "history_id": "3ffb4f16db81f4ab",  "id": "55229dacc14c3482",  "inputs": {   "input_vcf": {    "id": "c75a114c6e2f9705",    "src": "hda",    "uuid": "761cdf6a-cb41-4d22-aadc-c6561121da54"   },   "reference_source|ref_file": {    "id": "1e71fe52bb3db247",    "src": "hda",    "uuid": "a767cd89-16a5-4c82-bf1b-289ef86d0d7a"   }  },  "job_messages": null,  "job_metrics": [],  "job_runner_name": null,  "job_stderr": null,  "job_stdout": null,  "model_class": "Job",  "output_collections": {},  "outputs": {   "out_file1": {    "id": "eb22f4a6e41a6f58",    "src": "hda",    "uuid": "8407fbe3-04e6-427e-aba5-609b7a1779fc"   }  },  "params": {   "__input_ext": "\"vcf\"",   "chromInfo": "\"/cvmfs/data.galaxyproject.org/managed/len/ucsc/?.len\"",   "dbkey": "\"?\"",   "reference_source": "{\"__current_case__\": 1, \"ref_file\": {\"values\": [{\"id\": 53, \"src\": \"hda\"}]}, \"reference_source_selector\": \"history\"}",   "window_size": "\"150\""  },  "state": "error",  "stderr": "index file localref.fa.fai not found, generating...\n",  "stdout": "",  "tool_id": "toolshed.g2.bx.psu.edu/repos/devteam/vcfleftalign/vcfleftalign/1.0.0_rc3+galaxy0",  "tool_stderr": "index file localref.fa.fai not found, generating...\n",  "tool_stdout": "",  "update_time": "2025-05-07T13:10:03.780448",  "user_email": "tests@fake.org" }, "output_problems": [  "Job in error state.. tool_id: toolshed.g2.bx.psu.edu/repos/devteam/vcfleftalign/vcfleftalign/1.0.0_rc3+galaxy0, exit_code: None, stderr: index file localref.fa.fai not found, generating...\n.",  "Job in error state.. tool_id: toolshed.g2.bx.psu.edu/repos/devteam/vcfleftalign/vcfleftalign/1.0.0_rc3+galaxy0, exit_code: None, stderr: index file localref.fa.fai not found, generating...\n." ], "status": "failure", "test_index": 0, "time_seconds": 24.45264959335327, "tool_id": "vcfleftalign", "tool_version": "1.0.0_rc3+galaxy0"}
                ]]></error>
            
            <system-out><![CDATA[
            
            ]]></system-out>
            <system-err><![CDATA[
            index file localref.fa.fai not found, generating...
            ]]></system-err>
        
    </testcase>
    
</testsuite>