<?xml version="1.0" encoding="UTF-8"?>
<testsuite name="Results (powered by Planemo)"
           tests="50"
           errors="16"
           failures="6"
           skip="0">
    
    <testcase classname="bam_to_sam (Test #1)" name="0" time="30.09903359413147">
        
            
                <error type="error" message="Tool exit code: None"><![CDATA[
                    { "inputs": {  "header": "-h",  "input1": {   "id": "2854d2772f64af3e",   "src": "hda"  } }, "job": {  "command_line": "samtools view -o \u0027/galaxy/server/database/objects/b/5/1/dataset_b51b19da-b08a-4255-9234-07b2c2934257.dat\u0027 -h \u0027/galaxy/server/database/objects/5/0/e/dataset_50eade68-76b2-46c6-b3c8-06af39a58e74.dat\u0027",  "command_version": null,  "copied_from_job_id": null,  "create_time": "2025-05-30T01:06:34.993258",  "dependencies": [],  "exit_code": null,  "external_id": "gxy-wgl82",  "galaxy_version": "24.1",  "handler": null,  "history_id": "288caeae45c8003a",  "id": "783d4cbd4dbb69bf",  "inputs": {   "input1": {    "id": "2854d2772f64af3e",    "src": "hda",    "uuid": "50eade68-76b2-46c6-b3c8-06af39a58e74"   }  },  "job_messages": null,  "job_metrics": [],  "job_runner_name": null,  "job_stderr": null,  "job_stdout": null,  "model_class": "Job",  "output_collections": {},  "outputs": {   "output1": {    "id": "185312ce8a15aa68",    "src": "hda",    "uuid": "b51b19da-b08a-4255-9234-07b2c2934257"   }  },  "params": {   "__input_ext": "\"input\"",   "chromInfo": "\"/cvmfs/data.galaxyproject.org/managed/len/ucsc/?.len\"",   "dbkey": "\"?\"",   "header": "\"-h\""  },  "state": "error",  "stderr": "",  "stdout": "",  "tool_id": "toolshed.g2.bx.psu.edu/repos/devteam/bam_to_sam/bam_to_sam/2.0.4",  "tool_stderr": "",  "tool_stdout": "",  "update_time": "2025-05-30T01:06:44.585732",  "user_email": "tests@fake.org" }, "output_problems": [  "Job in error state.. tool_id: toolshed.g2.bx.psu.edu/repos/devteam/bam_to_sam/bam_to_sam/2.0.4, exit_code: None, stderr: .",  "Job in error state.. tool_id: toolshed.g2.bx.psu.edu/repos/devteam/bam_to_sam/bam_to_sam/2.0.4, exit_code: None, stderr: ." ], "status": "failure", "test_index": 0, "time_seconds": 30.09903359413147, "tool_id": "bam_to_sam", "tool_version": "2.0.4"}
                ]]></error>
            
            <system-out><![CDATA[
            
            ]]></system-out>
            <system-err><![CDATA[
            
            ]]></system-err>
        
    </testcase>
    
    <testcase classname="bam_to_sam (Test #2)" name="1" time="34.56241750717163">
        
            
            <system-out><![CDATA[
            
            ]]></system-out>
            <system-err><![CDATA[
            
            ]]></system-err>
        
    </testcase>
    
    <testcase classname="bam_to_sam (Test #3)" name="2" time="33.082988023757935">
        
            
            <system-out><![CDATA[
            
            ]]></system-out>
            <system-err><![CDATA[
            
            ]]></system-err>
        
    </testcase>
    
    <testcase classname="bcftools_merge (Test #1)" name="0" time="40.46421813964844">
        
            
            <system-out><![CDATA[
            
            ]]></system-out>
            <system-err><![CDATA[
            
            ]]></system-err>
        
    </testcase>
    
    <testcase classname="bcftools_merge (Test #2)" name="1" time="34.941832065582275">
        
            
            <system-out><![CDATA[
            
            ]]></system-out>
            <system-err><![CDATA[
            
            ]]></system-err>
        
    </testcase>
    
    <testcase classname="bcftools_merge (Test #3)" name="2" time="33.87630033493042">
        
            
            <system-out><![CDATA[
            
            ]]></system-out>
            <system-err><![CDATA[
            
            ]]></system-err>
        
    </testcase>
    
    <testcase classname="bcftools_merge (Test #4)" name="3" time="34.666202783584595">
        
            
            <system-out><![CDATA[
            
            ]]></system-out>
            <system-err><![CDATA[
            
            ]]></system-err>
        
    </testcase>
    
    <testcase classname="bcftools_merge (Test #5)" name="4" time="19.806573390960693">
        
            <error type="error" message="Input staging problem: Traceback (most recent call last):
  File "/opt/hostedtoolcache/Python/3.12.10/x64/lib/python3.12/site-packages/galaxy/tool_util/verify/interactor.py", line 1434, in verify_tool
    stage_data_in_history(
  File "/opt/hostedtoolcache/Python/3.12.10/x64/lib/python3.12/site-packages/galaxy/tool_util/verify/interactor.py", line 175, in stage_data_in_history
    staging_interface.handle_jobs()
  File "/opt/hostedtoolcache/Python/3.12.10/x64/lib/python3.12/site-packages/galaxy/tool_util/verify/interactor.py", line 212, in handle_jobs
    self.galaxy_interactor.wait_for_job(job_response["id"], job_response["history_id"], self.maxseconds)
  File "/opt/hostedtoolcache/Python/3.12.10/x64/lib/python3.12/site-packages/galaxy/tool_util/verify/interactor.py", line 399, in wait_for_job
    self.wait_for(lambda: self.__job_ready(job_id, history_id), maxseconds=maxseconds)
  File "/opt/hostedtoolcache/Python/3.12.10/x64/lib/python3.12/site-packages/galaxy/tool_util/verify/interactor.py", line 403, in wait_for
    wait_on(func, what, walltime_exceeded)
  File "/opt/hostedtoolcache/Python/3.12.10/x64/lib/python3.12/site-packages/galaxy/tool_util/verify/wait.py", line 38, in wait_on
    value = function()
            ^^^^^^^^^^
  File "/opt/hostedtoolcache/Python/3.12.10/x64/lib/python3.12/site-packages/galaxy/tool_util/verify/interactor.py", line 399, in <lambda>
    self.wait_for(lambda: self.__job_ready(job_id, history_id), maxseconds=maxseconds)
                          ^^^^^^^^^^^^^^^^^^^^^^^^^^^^^^^^^^^^
  File "/opt/hostedtoolcache/Python/3.12.10/x64/lib/python3.12/site-packages/galaxy/tool_util/verify/interactor.py", line 747, in __job_ready
    return self._state_ready(job_id, error_msg="Job in error state.")
           ^^^^^^^^^^^^^^^^^^^^^^^^^^^^^^^^^^^^^^^^^^^^^^^^^^^^^^^^^^
  File "/opt/hostedtoolcache/Python/3.12.10/x64/lib/python3.12/site-packages/galaxy/tool_util/verify/interactor.py", line 839, in _state_ready
    raise Exception(
Exception: Job in error state.. tool_id: __DATA_FETCH__, exit_code: None, stderr: .
"><![CDATA[
                { "execution_problem": "Input staging problem: Traceback (most recent call last):\n  File \"/opt/hostedtoolcache/Python/3.12.10/x64/lib/python3.12/site-packages/galaxy/tool_util/verify/interactor.py\", line 1434, in verify_tool\n    stage_data_in_history(\n  File \"/opt/hostedtoolcache/Python/3.12.10/x64/lib/python3.12/site-packages/galaxy/tool_util/verify/interactor.py\", line 175, in stage_data_in_history\n    staging_interface.handle_jobs()\n  File \"/opt/hostedtoolcache/Python/3.12.10/x64/lib/python3.12/site-packages/galaxy/tool_util/verify/interactor.py\", line 212, in handle_jobs\n    self.galaxy_interactor.wait_for_job(job_response[\"id\"], job_response[\"history_id\"], self.maxseconds)\n  File \"/opt/hostedtoolcache/Python/3.12.10/x64/lib/python3.12/site-packages/galaxy/tool_util/verify/interactor.py\", line 399, in wait_for_job\n    self.wait_for(lambda: self.__job_ready(job_id, history_id), maxseconds=maxseconds)\n  File \"/opt/hostedtoolcache/Python/3.12.10/x64/lib/python3.12/site-packages/galaxy/tool_util/verify/interactor.py\", line 403, in wait_for\n    wait_on(func, what, walltime_exceeded)\n  File \"/opt/hostedtoolcache/Python/3.12.10/x64/lib/python3.12/site-packages/galaxy/tool_util/verify/wait.py\", line 38, in wait_on\n    value = function()\n            ^^^^^^^^^^\n  File \"/opt/hostedtoolcache/Python/3.12.10/x64/lib/python3.12/site-packages/galaxy/tool_util/verify/interactor.py\", line 399, in \u003clambda\u003e\n    self.wait_for(lambda: self.__job_ready(job_id, history_id), maxseconds=maxseconds)\n                          ^^^^^^^^^^^^^^^^^^^^^^^^^^^^^^^^^^^^\n  File \"/opt/hostedtoolcache/Python/3.12.10/x64/lib/python3.12/site-packages/galaxy/tool_util/verify/interactor.py\", line 747, in __job_ready\n    return self._state_ready(job_id, error_msg=\"Job in error state.\")\n           ^^^^^^^^^^^^^^^^^^^^^^^^^^^^^^^^^^^^^^^^^^^^^^^^^^^^^^^^^^\n  File \"/opt/hostedtoolcache/Python/3.12.10/x64/lib/python3.12/site-packages/galaxy/tool_util/verify/interactor.py\", line 839, in _state_ready\n    raise Exception(\nException: Job in error state.. tool_id: __DATA_FETCH__, exit_code: None, stderr: .\n", "status": "error", "test_index": 4, "time_seconds": 19.806573390960693, "tool_id": "bcftools_merge", "tool_version": "1.15.1+galaxy4"}
            ]]></error>
        
    </testcase>
    
    <testcase classname="bcftools_merge (Test #6)" name="5" time="25.78206753730774">
        
            
                <error type="error" message="Tool exit code: None"><![CDATA[
                    { "inputs": {  "input_files": [   {    "id": "970b4948f07824fc",    "src": "hda"   },   {    "id": "415a98fd22e142ae",    "src": "hda"   }  ],  "output_type": "v",  "sec_merge|force_samples": true,  "sec_merge|merge": "id",  "sec_merge|no_index": true }, "job": {  "command_line": "export BCFTOOLS_PLUGINS=`which bcftools | sed \u0027s,bin/bcftools,libexec/bcftools,\u0027`;     bgzip -c \u0027/galaxy/server/database/objects/5/a/4/dataset_5a45a126-4e7f-4025-98b5-77e03675dd9f.dat\u0027 \u003e input0.vcf.gz \u0026\u0026 bcftools index input0.vcf.gz \u0026\u0026 echo \u0027input0.vcf.gz\u0027 \u003e\u003e vcfs_list \u0026\u0026  bgzip -c \u0027/galaxy/server/database/objects/4/b/b/dataset_4bb74445-42bf-4c90-84f6-5168ce007bf3.dat\u0027 \u003e input1.vcf.gz \u0026\u0026 bcftools index input1.vcf.gz \u0026\u0026 echo \u0027input1.vcf.gz\u0027 \u003e\u003e vcfs_list \u0026\u0026         bcftools merge    --force-samples   --merge \"id\" --no-index           --output-type \u0027v\u0027   --threads ${GALAXY_SLOTS:-4}    input0.vcf.gz input1.vcf.gz  \u003e \u0027/galaxy/server/database/objects/5/e/3/dataset_5e3ea3bd-5c95-4d35-a8e9-64d094749006.dat\u0027",  "command_version": null,  "copied_from_job_id": null,  "create_time": "2025-05-30T01:11:33.608450",  "dependencies": [],  "exit_code": null,  "external_id": "gxy-fq94c",  "galaxy_version": "24.1",  "handler": null,  "history_id": "288caeae45c8003a",  "id": "6b5c26810e83ddaa",  "inputs": {   "input_files": {    "id": "970b4948f07824fc",    "src": "hda",    "uuid": "5a45a126-4e7f-4025-98b5-77e03675dd9f"   },   "input_files1": {    "id": "970b4948f07824fc",    "src": "hda",    "uuid": "5a45a126-4e7f-4025-98b5-77e03675dd9f"   },   "input_files2": {    "id": "415a98fd22e142ae",    "src": "hda",    "uuid": "4bb74445-42bf-4c90-84f6-5168ce007bf3"   }  },  "job_messages": null,  "job_metrics": [],  "job_runner_name": null,  "job_stderr": null,  "job_stdout": null,  "model_class": "Job",  "output_collections": {},  "outputs": {   "output_file": {    "id": "8ae3725735fbf5c9",    "src": "hda",    "uuid": "5e3ea3bd-5c95-4d35-a8e9-64d094749006"   }  },  "params": {   "__input_ext": "\"input\"",   "chromInfo": "\"/cvmfs/data.galaxyproject.org/managed/len/ucsc/?.len\"",   "dbkey": "\"?\"",   "output_type": "\"v\"",   "sec_header": "{\"print_header\": false, \"use_header\": null}",   "sec_merge": "{\"force_samples\": true, \"info_rules\": null, \"merge\": \"id\", \"no_index\": true}",   "sec_restrict": "{\"apply_filters\": \"\", \"regions\": {\"__current_case__\": 0, \"regions_src\": \"__none__\"}, \"regions_overlap\": null}"  },  "state": "error",  "stderr": "[W::bcf_sr_add_reader] Using multiple unindexed files may produce errors, make sure chromosomes are in the same order!\n",  "stdout": "",  "tool_id": "toolshed.g2.bx.psu.edu/repos/iuc/bcftools_merge/bcftools_merge/1.15.1+galaxy4",  "tool_stderr": "[W::bcf_sr_add_reader] Using multiple unindexed files may produce errors, make sure chromosomes are in the same order!\n",  "tool_stdout": "",  "update_time": "2025-05-30T01:11:38.694764",  "user_email": "tests@fake.org" }, "output_problems": [  "Job in error state.. tool_id: toolshed.g2.bx.psu.edu/repos/iuc/bcftools_merge/bcftools_merge/1.15.1+galaxy4, exit_code: None, stderr: [W::bcf_sr_add_reader] Using multiple unindexed files may produce errors, make sure chromosomes are in the same order!\n.",  "Job in error state.. tool_id: toolshed.g2.bx.psu.edu/repos/iuc/bcftools_merge/bcftools_merge/1.15.1+galaxy4, exit_code: None, stderr: [W::bcf_sr_add_reader] Using multiple unindexed files may produce errors, make sure chromosomes are in the same order!\n." ], "status": "failure", "test_index": 5, "time_seconds": 25.78206753730774, "tool_id": "bcftools_merge", "tool_version": "1.15.1+galaxy4"}
                ]]></error>
            
            <system-out><![CDATA[
            
            ]]></system-out>
            <system-err><![CDATA[
            [W::bcf_sr_add_reader] Using multiple unindexed files may produce errors, make sure chromosomes are in the same order!
            ]]></system-err>
        
    </testcase>
    
    <testcase classname="bcftools_merge (Test #7)" name="6" time="34.354480266571045">
        
            
            <system-out><![CDATA[
            
            ]]></system-out>
            <system-err><![CDATA[
            
            ]]></system-err>
        
    </testcase>
    
    <testcase classname="bcftools_plugin_missing2ref (Test #1)" name="0" time="34.35067677497864">
        
            
                <error type="error" message="Tool exit code: None"><![CDATA[
                    { "inputs": {  "input_file": {   "id": "ef9808f329fa9754",   "src": "hda"  },  "output_type": "v" }, "job": {  "command_line": "export BCFTOOLS_PLUGINS=`which bcftools | sed \u0027s,bin/bcftools,libexec/bcftools,\u0027`;     bgzip -c \u0027/galaxy/server/database/objects/f/0/f/dataset_f0f5b87e-6410-4b3f-9f82-229a781135ae.dat\u0027 \u003e input.vcf.gz \u0026\u0026 bcftools index input.vcf.gz \u0026\u0026            bcftools plugin missing2ref                 --output-type \u0027v\u0027   --threads ${GALAXY_SLOTS:-4}    input.vcf.gz   \u003e \u0027/galaxy/server/database/objects/2/9/2/dataset_292527ee-60a3-408d-a61e-8b3f86db3d9b.dat\u0027",  "command_version": null,  "copied_from_job_id": null,  "create_time": "2025-05-30T01:08:13.973145",  "dependencies": [],  "exit_code": null,  "external_id": "gxy-rt66r",  "galaxy_version": "24.1",  "handler": null,  "history_id": "288caeae45c8003a",  "id": "644a7b78e5179776",  "inputs": {   "input_file": {    "id": "ef9808f329fa9754",    "src": "hda",    "uuid": "f0f5b87e-6410-4b3f-9f82-229a781135ae"   }  },  "job_messages": null,  "job_metrics": [],  "job_runner_name": null,  "job_stderr": null,  "job_stdout": null,  "model_class": "Job",  "output_collections": {},  "outputs": {   "output_file": {    "id": "c7a80addf1e94035",    "src": "hda",    "uuid": "292527ee-60a3-408d-a61e-8b3f86db3d9b"   }  },  "params": {   "__input_ext": "\"input\"",   "chromInfo": "\"/cvmfs/data.galaxyproject.org/managed/len/ucsc/?.len\"",   "dbkey": "\"?\"",   "output_type": "\"v\"",   "sec_plugin": "{\"major\": false, \"phased\": false}",   "sec_restrict": "{\"exclude\": null, \"include\": null, \"regions\": {\"__current_case__\": 0, \"regions_src\": \"__none__\"}, \"regions_overlap\": null, \"targets\": {\"__current_case__\": 0, \"targets_src\": \"__none__\"}, \"targets_overlap\": null}"  },  "state": "error",  "stderr": "Filled 44 REF alleles\n",  "stdout": "",  "tool_id": "toolshed.g2.bx.psu.edu/repos/iuc/bcftools_plugin_missing2ref/bcftools_plugin_missing2ref/1.15.1+galaxy4",  "tool_stderr": "Filled 44 REF alleles\n",  "tool_stdout": "",  "update_time": "2025-05-30T01:08:27.892241",  "user_email": "tests@fake.org" }, "output_problems": [  "Job in error state.. tool_id: toolshed.g2.bx.psu.edu/repos/iuc/bcftools_plugin_missing2ref/bcftools_plugin_missing2ref/1.15.1+galaxy4, exit_code: None, stderr: Filled 44 REF alleles\n.",  "Job in error state.. tool_id: toolshed.g2.bx.psu.edu/repos/iuc/bcftools_plugin_missing2ref/bcftools_plugin_missing2ref/1.15.1+galaxy4, exit_code: None, stderr: Filled 44 REF alleles\n." ], "status": "failure", "test_index": 0, "time_seconds": 34.35067677497864, "tool_id": "bcftools_plugin_missing2ref", "tool_version": "1.15.1+galaxy4"}
                ]]></error>
            
            <system-out><![CDATA[
            
            ]]></system-out>
            <system-err><![CDATA[
            Filled 44 REF alleles
            ]]></system-err>
        
    </testcase>
    
    <testcase classname="column_order_header_sort (Test #1)" name="0" time="70.00676155090332">
        
            
                <error type="error" message="Tool exit code: None"><![CDATA[
                    { "inputs": {  "input_tabular": {   "id": "288caeae45c8003a",   "src": "hda"  },  "key_column": "1" }, "job": {  "command_line": "python \u0027/cvmfs/cloud.galaxyproject.org/tools/toolshed.g2.bx.psu.edu/repos/iuc/column_order_header_sort/6ae9724caf4d/column_order_header_sort/column_order_header_sort.py\u0027 \u0027/galaxy/server/database/objects/2/9/4/dataset_2946e1db-998a-44f1-8652-f138bbf2161b.dat\u0027 \u0027/galaxy/server/database/objects/6/b/e/dataset_6be9516b-26f8-4a8a-b1cd-7e47333ae673.dat\u0027 \u0027\t\u0027 \u00271\u0027",  "command_version": null,  "copied_from_job_id": null,  "create_time": "2025-05-30T01:00:13.203141",  "dependencies": [],  "exit_code": null,  "external_id": "gxy-jrcrg",  "galaxy_version": "24.1",  "handler": null,  "history_id": "288caeae45c8003a",  "id": "6b95ee0a1abba974",  "inputs": {   "input_tabular": {    "id": "288caeae45c8003a",    "src": "hda",    "uuid": "2946e1db-998a-44f1-8652-f138bbf2161b"   }  },  "job_messages": null,  "job_metrics": [],  "job_runner_name": null,  "job_stderr": null,  "job_stdout": null,  "model_class": "Job",  "output_collections": {},  "outputs": {   "output_tabular": {    "id": "6b95ee0a1abba974",    "src": "hda",    "uuid": "6be9516b-26f8-4a8a-b1cd-7e47333ae673"   }  },  "params": {   "__input_ext": "\"tabular\"",   "chromInfo": "\"/cvmfs/data.galaxyproject.org/managed/len/ucsc/?.len\"",   "dbkey": "\"?\"",   "key_column": "\"1\""  },  "state": "error",  "stderr": "",  "stdout": "",  "tool_id": "toolshed.g2.bx.psu.edu/repos/iuc/column_order_header_sort/column_order_header_sort/0.0.1",  "tool_stderr": "",  "tool_stdout": "",  "update_time": "2025-05-30T01:00:55.866434",  "user_email": "tests@fake.org" }, "output_problems": [  "Job in error state.. tool_id: toolshed.g2.bx.psu.edu/repos/iuc/column_order_header_sort/column_order_header_sort/0.0.1, exit_code: None, stderr: .",  "Job in error state.. tool_id: toolshed.g2.bx.psu.edu/repos/iuc/column_order_header_sort/column_order_header_sort/0.0.1, exit_code: None, stderr: ." ], "status": "failure", "test_index": 0, "time_seconds": 70.00676155090332, "tool_id": "column_order_header_sort", "tool_version": "0.0.1"}
                ]]></error>
            
            <system-out><![CDATA[
            
            ]]></system-out>
            <system-err><![CDATA[
            
            ]]></system-err>
        
    </testcase>
    
    <testcase classname="deeptools_plot_pca (Test #1)" name="0" time="65.45070838928223">
        
            
            <system-out><![CDATA[
            
            ]]></system-out>
            <system-err><![CDATA[
            
            ]]></system-err>
        
    </testcase>
    
    <testcase classname="deeptools_plot_pca (Test #2)" name="1" time="39.790149450302124">
        
            
            <system-out><![CDATA[
            
            ]]></system-out>
            <system-err><![CDATA[
            
            ]]></system-err>
        
    </testcase>
    
    <testcase classname="fastp (Test #1)" name="0" time="0.11667895317077637">
        
            <error type="error" message="Input staging problem: Traceback (most recent call last):
  File "/opt/hostedtoolcache/Python/3.12.10/x64/lib/python3.12/site-packages/galaxy/tool_util/verify/interactor.py", line 1434, in verify_tool
    stage_data_in_history(
  File "/opt/hostedtoolcache/Python/3.12.10/x64/lib/python3.12/site-packages/galaxy/tool_util/verify/interactor.py", line 163, in stage_data_in_history
    test_dict = galaxy_interactor.remote_to_input(
                ^^^^^^^^^^^^^^^^^^^^^^^^^^^^^^^^^^
  File "/opt/hostedtoolcache/Python/3.12.10/x64/lib/python3.12/site-packages/galaxy/tool_util/verify/interactor.py", line 582, in remote_to_input
    path_or_location = self._get_path_or_location(
                       ^^^^^^^^^^^^^^^^^^^^^^^^^^^
  File "/opt/hostedtoolcache/Python/3.12.10/x64/lib/python3.12/site-packages/galaxy/tool_util/verify/interactor.py", line 619, in _get_path_or_location
    path = self.test_data_download(
           ^^^^^^^^^^^^^^^^^^^^^^^^
  File "/opt/hostedtoolcache/Python/3.12.10/x64/lib/python3.12/site-packages/galaxy/tool_util/verify/interactor.py", line 525, in test_data_download
    raise AssertionError(f"Test input file ({filename}) cannot be found.")
AssertionError: Test input file (R1.fq) cannot be found.
"><![CDATA[
                { "execution_problem": "Input staging problem: Traceback (most recent call last):\n  File \"/opt/hostedtoolcache/Python/3.12.10/x64/lib/python3.12/site-packages/galaxy/tool_util/verify/interactor.py\", line 1434, in verify_tool\n    stage_data_in_history(\n  File \"/opt/hostedtoolcache/Python/3.12.10/x64/lib/python3.12/site-packages/galaxy/tool_util/verify/interactor.py\", line 163, in stage_data_in_history\n    test_dict = galaxy_interactor.remote_to_input(\n                ^^^^^^^^^^^^^^^^^^^^^^^^^^^^^^^^^^\n  File \"/opt/hostedtoolcache/Python/3.12.10/x64/lib/python3.12/site-packages/galaxy/tool_util/verify/interactor.py\", line 582, in remote_to_input\n    path_or_location = self._get_path_or_location(\n                       ^^^^^^^^^^^^^^^^^^^^^^^^^^^\n  File \"/opt/hostedtoolcache/Python/3.12.10/x64/lib/python3.12/site-packages/galaxy/tool_util/verify/interactor.py\", line 619, in _get_path_or_location\n    path = self.test_data_download(\n           ^^^^^^^^^^^^^^^^^^^^^^^^\n  File \"/opt/hostedtoolcache/Python/3.12.10/x64/lib/python3.12/site-packages/galaxy/tool_util/verify/interactor.py\", line 525, in test_data_download\n    raise AssertionError(f\"Test input file ({filename}) cannot be found.\")\nAssertionError: Test input file (R1.fq) cannot be found.\n", "status": "error", "test_index": 0, "time_seconds": 0.11667895317077637, "tool_id": "fastp", "tool_version": "0.24.0+galaxy3"}
            ]]></error>
        
    </testcase>
    
    <testcase classname="fastp (Test #2)" name="1" time="0.06176948547363281">
        
            <error type="error" message="Input staging problem: Traceback (most recent call last):
  File "/opt/hostedtoolcache/Python/3.12.10/x64/lib/python3.12/site-packages/galaxy/tool_util/verify/interactor.py", line 1434, in verify_tool
    stage_data_in_history(
  File "/opt/hostedtoolcache/Python/3.12.10/x64/lib/python3.12/site-packages/galaxy/tool_util/verify/interactor.py", line 163, in stage_data_in_history
    test_dict = galaxy_interactor.remote_to_input(
                ^^^^^^^^^^^^^^^^^^^^^^^^^^^^^^^^^^
  File "/opt/hostedtoolcache/Python/3.12.10/x64/lib/python3.12/site-packages/galaxy/tool_util/verify/interactor.py", line 582, in remote_to_input
    path_or_location = self._get_path_or_location(
                       ^^^^^^^^^^^^^^^^^^^^^^^^^^^
  File "/opt/hostedtoolcache/Python/3.12.10/x64/lib/python3.12/site-packages/galaxy/tool_util/verify/interactor.py", line 619, in _get_path_or_location
    path = self.test_data_download(
           ^^^^^^^^^^^^^^^^^^^^^^^^
  File "/opt/hostedtoolcache/Python/3.12.10/x64/lib/python3.12/site-packages/galaxy/tool_util/verify/interactor.py", line 525, in test_data_download
    raise AssertionError(f"Test input file ({filename}) cannot be found.")
AssertionError: Test input file (bwa-mem-fastq1.fq) cannot be found.
"><![CDATA[
                { "execution_problem": "Input staging problem: Traceback (most recent call last):\n  File \"/opt/hostedtoolcache/Python/3.12.10/x64/lib/python3.12/site-packages/galaxy/tool_util/verify/interactor.py\", line 1434, in verify_tool\n    stage_data_in_history(\n  File \"/opt/hostedtoolcache/Python/3.12.10/x64/lib/python3.12/site-packages/galaxy/tool_util/verify/interactor.py\", line 163, in stage_data_in_history\n    test_dict = galaxy_interactor.remote_to_input(\n                ^^^^^^^^^^^^^^^^^^^^^^^^^^^^^^^^^^\n  File \"/opt/hostedtoolcache/Python/3.12.10/x64/lib/python3.12/site-packages/galaxy/tool_util/verify/interactor.py\", line 582, in remote_to_input\n    path_or_location = self._get_path_or_location(\n                       ^^^^^^^^^^^^^^^^^^^^^^^^^^^\n  File \"/opt/hostedtoolcache/Python/3.12.10/x64/lib/python3.12/site-packages/galaxy/tool_util/verify/interactor.py\", line 619, in _get_path_or_location\n    path = self.test_data_download(\n           ^^^^^^^^^^^^^^^^^^^^^^^^\n  File \"/opt/hostedtoolcache/Python/3.12.10/x64/lib/python3.12/site-packages/galaxy/tool_util/verify/interactor.py\", line 525, in test_data_download\n    raise AssertionError(f\"Test input file ({filename}) cannot be found.\")\nAssertionError: Test input file (bwa-mem-fastq1.fq) cannot be found.\n", "status": "error", "test_index": 1, "time_seconds": 0.06176948547363281, "tool_id": "fastp", "tool_version": "0.24.0+galaxy3"}
            ]]></error>
        
    </testcase>
    
    <testcase classname="fastp (Test #11)" name="10" time="12.351178646087646">
        
            <error type="error" message="Input staging problem: Traceback (most recent call last):
  File "/opt/hostedtoolcache/Python/3.12.10/x64/lib/python3.12/site-packages/galaxy/tool_util/verify/interactor.py", line 1434, in verify_tool
    stage_data_in_history(
  File "/opt/hostedtoolcache/Python/3.12.10/x64/lib/python3.12/site-packages/galaxy/tool_util/verify/interactor.py", line 175, in stage_data_in_history
    staging_interface.handle_jobs()
  File "/opt/hostedtoolcache/Python/3.12.10/x64/lib/python3.12/site-packages/galaxy/tool_util/verify/interactor.py", line 212, in handle_jobs
    self.galaxy_interactor.wait_for_job(job_response["id"], job_response["history_id"], self.maxseconds)
  File "/opt/hostedtoolcache/Python/3.12.10/x64/lib/python3.12/site-packages/galaxy/tool_util/verify/interactor.py", line 399, in wait_for_job
    self.wait_for(lambda: self.__job_ready(job_id, history_id), maxseconds=maxseconds)
  File "/opt/hostedtoolcache/Python/3.12.10/x64/lib/python3.12/site-packages/galaxy/tool_util/verify/interactor.py", line 403, in wait_for
    wait_on(func, what, walltime_exceeded)
  File "/opt/hostedtoolcache/Python/3.12.10/x64/lib/python3.12/site-packages/galaxy/tool_util/verify/wait.py", line 38, in wait_on
    value = function()
            ^^^^^^^^^^
  File "/opt/hostedtoolcache/Python/3.12.10/x64/lib/python3.12/site-packages/galaxy/tool_util/verify/interactor.py", line 399, in <lambda>
    self.wait_for(lambda: self.__job_ready(job_id, history_id), maxseconds=maxseconds)
                          ^^^^^^^^^^^^^^^^^^^^^^^^^^^^^^^^^^^^
  File "/opt/hostedtoolcache/Python/3.12.10/x64/lib/python3.12/site-packages/galaxy/tool_util/verify/interactor.py", line 747, in __job_ready
    return self._state_ready(job_id, error_msg="Job in error state.")
           ^^^^^^^^^^^^^^^^^^^^^^^^^^^^^^^^^^^^^^^^^^^^^^^^^^^^^^^^^^
  File "/opt/hostedtoolcache/Python/3.12.10/x64/lib/python3.12/site-packages/galaxy/tool_util/verify/interactor.py", line 839, in _state_ready
    raise Exception(
Exception: Job in error state.. tool_id: __DATA_FETCH__, exit_code: None, stderr: .
"><![CDATA[
                { "execution_problem": "Input staging problem: Traceback (most recent call last):\n  File \"/opt/hostedtoolcache/Python/3.12.10/x64/lib/python3.12/site-packages/galaxy/tool_util/verify/interactor.py\", line 1434, in verify_tool\n    stage_data_in_history(\n  File \"/opt/hostedtoolcache/Python/3.12.10/x64/lib/python3.12/site-packages/galaxy/tool_util/verify/interactor.py\", line 175, in stage_data_in_history\n    staging_interface.handle_jobs()\n  File \"/opt/hostedtoolcache/Python/3.12.10/x64/lib/python3.12/site-packages/galaxy/tool_util/verify/interactor.py\", line 212, in handle_jobs\n    self.galaxy_interactor.wait_for_job(job_response[\"id\"], job_response[\"history_id\"], self.maxseconds)\n  File \"/opt/hostedtoolcache/Python/3.12.10/x64/lib/python3.12/site-packages/galaxy/tool_util/verify/interactor.py\", line 399, in wait_for_job\n    self.wait_for(lambda: self.__job_ready(job_id, history_id), maxseconds=maxseconds)\n  File \"/opt/hostedtoolcache/Python/3.12.10/x64/lib/python3.12/site-packages/galaxy/tool_util/verify/interactor.py\", line 403, in wait_for\n    wait_on(func, what, walltime_exceeded)\n  File \"/opt/hostedtoolcache/Python/3.12.10/x64/lib/python3.12/site-packages/galaxy/tool_util/verify/wait.py\", line 38, in wait_on\n    value = function()\n            ^^^^^^^^^^\n  File \"/opt/hostedtoolcache/Python/3.12.10/x64/lib/python3.12/site-packages/galaxy/tool_util/verify/interactor.py\", line 399, in \u003clambda\u003e\n    self.wait_for(lambda: self.__job_ready(job_id, history_id), maxseconds=maxseconds)\n                          ^^^^^^^^^^^^^^^^^^^^^^^^^^^^^^^^^^^^\n  File \"/opt/hostedtoolcache/Python/3.12.10/x64/lib/python3.12/site-packages/galaxy/tool_util/verify/interactor.py\", line 747, in __job_ready\n    return self._state_ready(job_id, error_msg=\"Job in error state.\")\n           ^^^^^^^^^^^^^^^^^^^^^^^^^^^^^^^^^^^^^^^^^^^^^^^^^^^^^^^^^^\n  File \"/opt/hostedtoolcache/Python/3.12.10/x64/lib/python3.12/site-packages/galaxy/tool_util/verify/interactor.py\", line 839, in _state_ready\n    raise Exception(\nException: Job in error state.. tool_id: __DATA_FETCH__, exit_code: None, stderr: .\n", "status": "error", "test_index": 10, "time_seconds": 12.351178646087646, "tool_id": "fastp", "tool_version": "0.24.0+galaxy3"}
            ]]></error>
        
    </testcase>
    
    <testcase classname="fastp (Test #12)" name="11" time="41.784990072250366">
        
            
            <system-out><![CDATA[
            
            ]]></system-out>
            <system-err><![CDATA[
            WARNNIG: different read numbers of the 0 packRead1 pack size: 99Read2 pack size: 100ERROR: input files don't contain identical amount of reads
            ]]></system-err>
        
    </testcase>
    
    <testcase classname="fastp (Test #13)" name="12" time="38.126662731170654">
        
            
            <system-out><![CDATA[
            
            ]]></system-out>
            <system-err><![CDATA[
            Read1 before filtering:total reads: 99total bases: 24849Q20 bases: 23268(93.6376%)Q30 bases: 22391(90.1083%)Read2 before filtering:total reads: 99total bases: 24849Q20 bases: 22676(91.2552%)Q30 bases: 21532(86.6514%)Merged and filtered:total reads: 97total bases: 25703Q20 bases: 24459(95.1601%)Q30 bases: 23743(92.3744%)Filtering result:reads passed filter: 196reads failed due to low quality: 2reads failed due to too many N: 0reads failed due to too short: 0reads with adapter trimmed: 68bases trimmed due to adapters: 2824reads corrected by overlap analysis: 55bases corrected by overlap analysis: 101Duplication rate: 0%Insert size peak (evaluated by paired-end reads): 308Read pairs merged: 97% of original read pairs: 97.9798%% in reads after filtering: 100%JSON report: fastp.jsonHTML report: fastp.htmlfastp --thread 4 --report_title fastp report for bwa-mem-fastq1_fq.fastqsanger -i bwa-mem-fastq1_fq.fastqsanger -I bwa-mem-fastq2_fq_R2.fastqsanger --merge --merged_out /galaxy/server/database/objects/7/b/0/dataset_7b0e613d-8999-4871-a518-e652494dac91.dat --out1 /galaxy/server/database/objects/6/2/7/dataset_627fbaad-6dcf-4b3d-b9a3-48a491dded00.dat --out2 /galaxy/server/database/objects/3/f/9/dataset_3f9af981-cdb4-4d40-a7ec-dbd3d63fd9e9.dat --unpaired1 /galaxy/server/database/objects/5/3/4/dataset_5343ffbc-78e4-4bea-81c5-2912feecfe5c.dat --unpaired2 /galaxy/server/database/objects/6/d/5/dataset_6d5c757f-fde5-46a3-adae-cc54d5011ca3.dat fastp v0.24.0, time used: 1 seconds
            ]]></system-err>
        
    </testcase>
    
    <testcase classname="fastp (Test #14)" name="13" time="34.01371097564697">
        
            
            <system-out><![CDATA[
            
            ]]></system-out>
            <system-err><![CDATA[
            Read1 before filtering:total reads: 99total bases: 24849Q20 bases: 23268(93.6376%)Q30 bases: 22391(90.1083%)Read2 before filtering:total reads: 99total bases: 24849Q20 bases: 22676(91.2552%)Q30 bases: 21532(86.6514%)Merged and filtered:total reads: 100total bases: 26456Q20 bases: 25141(95.0295%)Q30 bases: 24378(92.1454%)Filtering result:reads passed filter: 197reads failed due to low quality: 1reads failed due to too many N: 0reads failed due to too short: 0reads with adapter trimmed: 68bases trimmed due to adapters: 2824reads corrected by overlap analysis: 55bases corrected by overlap analysis: 101Duplication rate: 0%Insert size peak (evaluated by paired-end reads): 308Read pairs merged: 97% of original read pairs: 97.9798%% in reads after filtering: 97%JSON report: fastp.jsonHTML report: fastp.htmlfastp --thread 4 --report_title fastp report for Unnamed Collection.fastqsanger -i Unnamed Collection.fastqsanger -I Unnamed Collection_R2.fastqsanger --merge --merged_out /galaxy/server/database/objects/0/7/2/dataset_0723e8f7-42dd-481e-b32c-794cebb60b91.dat --include_unmerged fastp v0.24.0, time used: 0 seconds
            ]]></system-err>
        
    </testcase>
    
    <testcase classname="fastp (Test #15)" name="14" time="35.562445640563965">
        
            
            <system-out><![CDATA[
            
            ]]></system-out>
            <system-err><![CDATA[
            Read1 before filtering:total reads: 99total bases: 24849Q20 bases: 22676(91.2552%)Q30 bases: 21532(86.6514%)Read2 before filtering:total reads: 99total bases: 24849Q20 bases: 23268(93.6376%)Q30 bases: 22391(90.1083%)Read1 after filtering:total reads: 97total bases: 22942Q20 bases: 21535(93.8671%)Q30 bases: 20672(90.1055%)Read2 after filtering:total reads: 97total bases: 22942Q20 bases: 21680(94.4992%)Q30 bases: 20981(91.4524%)Filtering result:reads passed filter: 194reads failed due to low quality: 2reads failed due to too many N: 2reads failed due to too short: 0reads with adapter trimmed: 68bases trimmed due to adapters: 2824Duplication rate: 0%Insert size peak (evaluated by paired-end reads): 308JSON report: fastp.jsonHTML report: fastp.htmlfastp --thread 4 --report_title fastp report for Unnamed Collection.fastqsanger.gz -i Unnamed Collection.fastqsanger.gz -I Unnamed Collection_R2.fastqsanger.gz -o first.fastqsanger.gz -O second.fastqsanger.gz fastp v0.24.0, time used: 1 seconds
            ]]></system-err>
        
    </testcase>
    
    <testcase classname="fastp (Test #3)" name="2" time="0.062268972396850586">
        
            <error type="error" message="Input staging problem: Traceback (most recent call last):
  File "/opt/hostedtoolcache/Python/3.12.10/x64/lib/python3.12/site-packages/galaxy/tool_util/verify/interactor.py", line 1434, in verify_tool
    stage_data_in_history(
  File "/opt/hostedtoolcache/Python/3.12.10/x64/lib/python3.12/site-packages/galaxy/tool_util/verify/interactor.py", line 163, in stage_data_in_history
    test_dict = galaxy_interactor.remote_to_input(
                ^^^^^^^^^^^^^^^^^^^^^^^^^^^^^^^^^^
  File "/opt/hostedtoolcache/Python/3.12.10/x64/lib/python3.12/site-packages/galaxy/tool_util/verify/interactor.py", line 582, in remote_to_input
    path_or_location = self._get_path_or_location(
                       ^^^^^^^^^^^^^^^^^^^^^^^^^^^
  File "/opt/hostedtoolcache/Python/3.12.10/x64/lib/python3.12/site-packages/galaxy/tool_util/verify/interactor.py", line 619, in _get_path_or_location
    path = self.test_data_download(
           ^^^^^^^^^^^^^^^^^^^^^^^^
  File "/opt/hostedtoolcache/Python/3.12.10/x64/lib/python3.12/site-packages/galaxy/tool_util/verify/interactor.py", line 525, in test_data_download
    raise AssertionError(f"Test input file ({filename}) cannot be found.")
AssertionError: Test input file (R1.fq) cannot be found.
"><![CDATA[
                { "execution_problem": "Input staging problem: Traceback (most recent call last):\n  File \"/opt/hostedtoolcache/Python/3.12.10/x64/lib/python3.12/site-packages/galaxy/tool_util/verify/interactor.py\", line 1434, in verify_tool\n    stage_data_in_history(\n  File \"/opt/hostedtoolcache/Python/3.12.10/x64/lib/python3.12/site-packages/galaxy/tool_util/verify/interactor.py\", line 163, in stage_data_in_history\n    test_dict = galaxy_interactor.remote_to_input(\n                ^^^^^^^^^^^^^^^^^^^^^^^^^^^^^^^^^^\n  File \"/opt/hostedtoolcache/Python/3.12.10/x64/lib/python3.12/site-packages/galaxy/tool_util/verify/interactor.py\", line 582, in remote_to_input\n    path_or_location = self._get_path_or_location(\n                       ^^^^^^^^^^^^^^^^^^^^^^^^^^^\n  File \"/opt/hostedtoolcache/Python/3.12.10/x64/lib/python3.12/site-packages/galaxy/tool_util/verify/interactor.py\", line 619, in _get_path_or_location\n    path = self.test_data_download(\n           ^^^^^^^^^^^^^^^^^^^^^^^^\n  File \"/opt/hostedtoolcache/Python/3.12.10/x64/lib/python3.12/site-packages/galaxy/tool_util/verify/interactor.py\", line 525, in test_data_download\n    raise AssertionError(f\"Test input file ({filename}) cannot be found.\")\nAssertionError: Test input file (R1.fq) cannot be found.\n", "status": "error", "test_index": 2, "time_seconds": 0.062268972396850586, "tool_id": "fastp", "tool_version": "0.24.0+galaxy3"}
            ]]></error>
        
    </testcase>
    
    <testcase classname="fastp (Test #4)" name="3" time="0.06531572341918945">
        
            <error type="error" message="Input staging problem: Traceback (most recent call last):
  File "/opt/hostedtoolcache/Python/3.12.10/x64/lib/python3.12/site-packages/galaxy/tool_util/verify/interactor.py", line 1434, in verify_tool
    stage_data_in_history(
  File "/opt/hostedtoolcache/Python/3.12.10/x64/lib/python3.12/site-packages/galaxy/tool_util/verify/interactor.py", line 163, in stage_data_in_history
    test_dict = galaxy_interactor.remote_to_input(
                ^^^^^^^^^^^^^^^^^^^^^^^^^^^^^^^^^^
  File "/opt/hostedtoolcache/Python/3.12.10/x64/lib/python3.12/site-packages/galaxy/tool_util/verify/interactor.py", line 582, in remote_to_input
    path_or_location = self._get_path_or_location(
                       ^^^^^^^^^^^^^^^^^^^^^^^^^^^
  File "/opt/hostedtoolcache/Python/3.12.10/x64/lib/python3.12/site-packages/galaxy/tool_util/verify/interactor.py", line 619, in _get_path_or_location
    path = self.test_data_download(
           ^^^^^^^^^^^^^^^^^^^^^^^^
  File "/opt/hostedtoolcache/Python/3.12.10/x64/lib/python3.12/site-packages/galaxy/tool_util/verify/interactor.py", line 525, in test_data_download
    raise AssertionError(f"Test input file ({filename}) cannot be found.")
AssertionError: Test input file (R1.fq) cannot be found.
"><![CDATA[
                { "execution_problem": "Input staging problem: Traceback (most recent call last):\n  File \"/opt/hostedtoolcache/Python/3.12.10/x64/lib/python3.12/site-packages/galaxy/tool_util/verify/interactor.py\", line 1434, in verify_tool\n    stage_data_in_history(\n  File \"/opt/hostedtoolcache/Python/3.12.10/x64/lib/python3.12/site-packages/galaxy/tool_util/verify/interactor.py\", line 163, in stage_data_in_history\n    test_dict = galaxy_interactor.remote_to_input(\n                ^^^^^^^^^^^^^^^^^^^^^^^^^^^^^^^^^^\n  File \"/opt/hostedtoolcache/Python/3.12.10/x64/lib/python3.12/site-packages/galaxy/tool_util/verify/interactor.py\", line 582, in remote_to_input\n    path_or_location = self._get_path_or_location(\n                       ^^^^^^^^^^^^^^^^^^^^^^^^^^^\n  File \"/opt/hostedtoolcache/Python/3.12.10/x64/lib/python3.12/site-packages/galaxy/tool_util/verify/interactor.py\", line 619, in _get_path_or_location\n    path = self.test_data_download(\n           ^^^^^^^^^^^^^^^^^^^^^^^^\n  File \"/opt/hostedtoolcache/Python/3.12.10/x64/lib/python3.12/site-packages/galaxy/tool_util/verify/interactor.py\", line 525, in test_data_download\n    raise AssertionError(f\"Test input file ({filename}) cannot be found.\")\nAssertionError: Test input file (R1.fq) cannot be found.\n", "status": "error", "test_index": 3, "time_seconds": 0.06531572341918945, "tool_id": "fastp", "tool_version": "0.24.0+galaxy3"}
            ]]></error>
        
    </testcase>
    
    <testcase classname="fastp (Test #5)" name="4" time="0.062177181243896484">
        
            <error type="error" message="Input staging problem: Traceback (most recent call last):
  File "/opt/hostedtoolcache/Python/3.12.10/x64/lib/python3.12/site-packages/galaxy/tool_util/verify/interactor.py", line 1434, in verify_tool
    stage_data_in_history(
  File "/opt/hostedtoolcache/Python/3.12.10/x64/lib/python3.12/site-packages/galaxy/tool_util/verify/interactor.py", line 163, in stage_data_in_history
    test_dict = galaxy_interactor.remote_to_input(
                ^^^^^^^^^^^^^^^^^^^^^^^^^^^^^^^^^^
  File "/opt/hostedtoolcache/Python/3.12.10/x64/lib/python3.12/site-packages/galaxy/tool_util/verify/interactor.py", line 582, in remote_to_input
    path_or_location = self._get_path_or_location(
                       ^^^^^^^^^^^^^^^^^^^^^^^^^^^
  File "/opt/hostedtoolcache/Python/3.12.10/x64/lib/python3.12/site-packages/galaxy/tool_util/verify/interactor.py", line 619, in _get_path_or_location
    path = self.test_data_download(
           ^^^^^^^^^^^^^^^^^^^^^^^^
  File "/opt/hostedtoolcache/Python/3.12.10/x64/lib/python3.12/site-packages/galaxy/tool_util/verify/interactor.py", line 525, in test_data_download
    raise AssertionError(f"Test input file ({filename}) cannot be found.")
AssertionError: Test input file (R1.fq) cannot be found.
"><![CDATA[
                { "execution_problem": "Input staging problem: Traceback (most recent call last):\n  File \"/opt/hostedtoolcache/Python/3.12.10/x64/lib/python3.12/site-packages/galaxy/tool_util/verify/interactor.py\", line 1434, in verify_tool\n    stage_data_in_history(\n  File \"/opt/hostedtoolcache/Python/3.12.10/x64/lib/python3.12/site-packages/galaxy/tool_util/verify/interactor.py\", line 163, in stage_data_in_history\n    test_dict = galaxy_interactor.remote_to_input(\n                ^^^^^^^^^^^^^^^^^^^^^^^^^^^^^^^^^^\n  File \"/opt/hostedtoolcache/Python/3.12.10/x64/lib/python3.12/site-packages/galaxy/tool_util/verify/interactor.py\", line 582, in remote_to_input\n    path_or_location = self._get_path_or_location(\n                       ^^^^^^^^^^^^^^^^^^^^^^^^^^^\n  File \"/opt/hostedtoolcache/Python/3.12.10/x64/lib/python3.12/site-packages/galaxy/tool_util/verify/interactor.py\", line 619, in _get_path_or_location\n    path = self.test_data_download(\n           ^^^^^^^^^^^^^^^^^^^^^^^^\n  File \"/opt/hostedtoolcache/Python/3.12.10/x64/lib/python3.12/site-packages/galaxy/tool_util/verify/interactor.py\", line 525, in test_data_download\n    raise AssertionError(f\"Test input file ({filename}) cannot be found.\")\nAssertionError: Test input file (R1.fq) cannot be found.\n", "status": "error", "test_index": 4, "time_seconds": 0.062177181243896484, "tool_id": "fastp", "tool_version": "0.24.0+galaxy3"}
            ]]></error>
        
    </testcase>
    
    <testcase classname="fastp (Test #6)" name="5" time="0.0633230209350586">
        
            <error type="error" message="Input staging problem: Traceback (most recent call last):
  File "/opt/hostedtoolcache/Python/3.12.10/x64/lib/python3.12/site-packages/galaxy/tool_util/verify/interactor.py", line 1434, in verify_tool
    stage_data_in_history(
  File "/opt/hostedtoolcache/Python/3.12.10/x64/lib/python3.12/site-packages/galaxy/tool_util/verify/interactor.py", line 163, in stage_data_in_history
    test_dict = galaxy_interactor.remote_to_input(
                ^^^^^^^^^^^^^^^^^^^^^^^^^^^^^^^^^^
  File "/opt/hostedtoolcache/Python/3.12.10/x64/lib/python3.12/site-packages/galaxy/tool_util/verify/interactor.py", line 582, in remote_to_input
    path_or_location = self._get_path_or_location(
                       ^^^^^^^^^^^^^^^^^^^^^^^^^^^
  File "/opt/hostedtoolcache/Python/3.12.10/x64/lib/python3.12/site-packages/galaxy/tool_util/verify/interactor.py", line 619, in _get_path_or_location
    path = self.test_data_download(
           ^^^^^^^^^^^^^^^^^^^^^^^^
  File "/opt/hostedtoolcache/Python/3.12.10/x64/lib/python3.12/site-packages/galaxy/tool_util/verify/interactor.py", line 525, in test_data_download
    raise AssertionError(f"Test input file ({filename}) cannot be found.")
AssertionError: Test input file (bwa-mem-fastq1.fq) cannot be found.
"><![CDATA[
                { "execution_problem": "Input staging problem: Traceback (most recent call last):\n  File \"/opt/hostedtoolcache/Python/3.12.10/x64/lib/python3.12/site-packages/galaxy/tool_util/verify/interactor.py\", line 1434, in verify_tool\n    stage_data_in_history(\n  File \"/opt/hostedtoolcache/Python/3.12.10/x64/lib/python3.12/site-packages/galaxy/tool_util/verify/interactor.py\", line 163, in stage_data_in_history\n    test_dict = galaxy_interactor.remote_to_input(\n                ^^^^^^^^^^^^^^^^^^^^^^^^^^^^^^^^^^\n  File \"/opt/hostedtoolcache/Python/3.12.10/x64/lib/python3.12/site-packages/galaxy/tool_util/verify/interactor.py\", line 582, in remote_to_input\n    path_or_location = self._get_path_or_location(\n                       ^^^^^^^^^^^^^^^^^^^^^^^^^^^\n  File \"/opt/hostedtoolcache/Python/3.12.10/x64/lib/python3.12/site-packages/galaxy/tool_util/verify/interactor.py\", line 619, in _get_path_or_location\n    path = self.test_data_download(\n           ^^^^^^^^^^^^^^^^^^^^^^^^\n  File \"/opt/hostedtoolcache/Python/3.12.10/x64/lib/python3.12/site-packages/galaxy/tool_util/verify/interactor.py\", line 525, in test_data_download\n    raise AssertionError(f\"Test input file ({filename}) cannot be found.\")\nAssertionError: Test input file (bwa-mem-fastq1.fq) cannot be found.\n", "status": "error", "test_index": 5, "time_seconds": 0.0633230209350586, "tool_id": "fastp", "tool_version": "0.24.0+galaxy3"}
            ]]></error>
        
    </testcase>
    
    <testcase classname="fastp (Test #7)" name="6" time="0.06320476531982422">
        
            <error type="error" message="Input staging problem: Traceback (most recent call last):
  File "/opt/hostedtoolcache/Python/3.12.10/x64/lib/python3.12/site-packages/galaxy/tool_util/verify/interactor.py", line 1434, in verify_tool
    stage_data_in_history(
  File "/opt/hostedtoolcache/Python/3.12.10/x64/lib/python3.12/site-packages/galaxy/tool_util/verify/interactor.py", line 163, in stage_data_in_history
    test_dict = galaxy_interactor.remote_to_input(
                ^^^^^^^^^^^^^^^^^^^^^^^^^^^^^^^^^^
  File "/opt/hostedtoolcache/Python/3.12.10/x64/lib/python3.12/site-packages/galaxy/tool_util/verify/interactor.py", line 582, in remote_to_input
    path_or_location = self._get_path_or_location(
                       ^^^^^^^^^^^^^^^^^^^^^^^^^^^
  File "/opt/hostedtoolcache/Python/3.12.10/x64/lib/python3.12/site-packages/galaxy/tool_util/verify/interactor.py", line 619, in _get_path_or_location
    path = self.test_data_download(
           ^^^^^^^^^^^^^^^^^^^^^^^^
  File "/opt/hostedtoolcache/Python/3.12.10/x64/lib/python3.12/site-packages/galaxy/tool_util/verify/interactor.py", line 525, in test_data_download
    raise AssertionError(f"Test input file ({filename}) cannot be found.")
AssertionError: Test input file (bwa-mem-fastq1.fq) cannot be found.
"><![CDATA[
                { "execution_problem": "Input staging problem: Traceback (most recent call last):\n  File \"/opt/hostedtoolcache/Python/3.12.10/x64/lib/python3.12/site-packages/galaxy/tool_util/verify/interactor.py\", line 1434, in verify_tool\n    stage_data_in_history(\n  File \"/opt/hostedtoolcache/Python/3.12.10/x64/lib/python3.12/site-packages/galaxy/tool_util/verify/interactor.py\", line 163, in stage_data_in_history\n    test_dict = galaxy_interactor.remote_to_input(\n                ^^^^^^^^^^^^^^^^^^^^^^^^^^^^^^^^^^\n  File \"/opt/hostedtoolcache/Python/3.12.10/x64/lib/python3.12/site-packages/galaxy/tool_util/verify/interactor.py\", line 582, in remote_to_input\n    path_or_location = self._get_path_or_location(\n                       ^^^^^^^^^^^^^^^^^^^^^^^^^^^\n  File \"/opt/hostedtoolcache/Python/3.12.10/x64/lib/python3.12/site-packages/galaxy/tool_util/verify/interactor.py\", line 619, in _get_path_or_location\n    path = self.test_data_download(\n           ^^^^^^^^^^^^^^^^^^^^^^^^\n  File \"/opt/hostedtoolcache/Python/3.12.10/x64/lib/python3.12/site-packages/galaxy/tool_util/verify/interactor.py\", line 525, in test_data_download\n    raise AssertionError(f\"Test input file ({filename}) cannot be found.\")\nAssertionError: Test input file (bwa-mem-fastq1.fq) cannot be found.\n", "status": "error", "test_index": 6, "time_seconds": 0.06320476531982422, "tool_id": "fastp", "tool_version": "0.24.0+galaxy3"}
            ]]></error>
        
    </testcase>
    
    <testcase classname="fastp (Test #8)" name="7" time="0.06491947174072266">
        
            <error type="error" message="Input staging problem: Traceback (most recent call last):
  File "/opt/hostedtoolcache/Python/3.12.10/x64/lib/python3.12/site-packages/galaxy/tool_util/verify/interactor.py", line 1434, in verify_tool
    stage_data_in_history(
  File "/opt/hostedtoolcache/Python/3.12.10/x64/lib/python3.12/site-packages/galaxy/tool_util/verify/interactor.py", line 163, in stage_data_in_history
    test_dict = galaxy_interactor.remote_to_input(
                ^^^^^^^^^^^^^^^^^^^^^^^^^^^^^^^^^^
  File "/opt/hostedtoolcache/Python/3.12.10/x64/lib/python3.12/site-packages/galaxy/tool_util/verify/interactor.py", line 582, in remote_to_input
    path_or_location = self._get_path_or_location(
                       ^^^^^^^^^^^^^^^^^^^^^^^^^^^
  File "/opt/hostedtoolcache/Python/3.12.10/x64/lib/python3.12/site-packages/galaxy/tool_util/verify/interactor.py", line 619, in _get_path_or_location
    path = self.test_data_download(
           ^^^^^^^^^^^^^^^^^^^^^^^^
  File "/opt/hostedtoolcache/Python/3.12.10/x64/lib/python3.12/site-packages/galaxy/tool_util/verify/interactor.py", line 525, in test_data_download
    raise AssertionError(f"Test input file ({filename}) cannot be found.")
AssertionError: Test input file (bwa-mem-fastq1.fq) cannot be found.
"><![CDATA[
                { "execution_problem": "Input staging problem: Traceback (most recent call last):\n  File \"/opt/hostedtoolcache/Python/3.12.10/x64/lib/python3.12/site-packages/galaxy/tool_util/verify/interactor.py\", line 1434, in verify_tool\n    stage_data_in_history(\n  File \"/opt/hostedtoolcache/Python/3.12.10/x64/lib/python3.12/site-packages/galaxy/tool_util/verify/interactor.py\", line 163, in stage_data_in_history\n    test_dict = galaxy_interactor.remote_to_input(\n                ^^^^^^^^^^^^^^^^^^^^^^^^^^^^^^^^^^\n  File \"/opt/hostedtoolcache/Python/3.12.10/x64/lib/python3.12/site-packages/galaxy/tool_util/verify/interactor.py\", line 582, in remote_to_input\n    path_or_location = self._get_path_or_location(\n                       ^^^^^^^^^^^^^^^^^^^^^^^^^^^\n  File \"/opt/hostedtoolcache/Python/3.12.10/x64/lib/python3.12/site-packages/galaxy/tool_util/verify/interactor.py\", line 619, in _get_path_or_location\n    path = self.test_data_download(\n           ^^^^^^^^^^^^^^^^^^^^^^^^\n  File \"/opt/hostedtoolcache/Python/3.12.10/x64/lib/python3.12/site-packages/galaxy/tool_util/verify/interactor.py\", line 525, in test_data_download\n    raise AssertionError(f\"Test input file ({filename}) cannot be found.\")\nAssertionError: Test input file (bwa-mem-fastq1.fq) cannot be found.\n", "status": "error", "test_index": 7, "time_seconds": 0.06491947174072266, "tool_id": "fastp", "tool_version": "0.24.0+galaxy3"}
            ]]></error>
        
    </testcase>
    
    <testcase classname="fastp (Test #9)" name="8" time="0.06538867950439453">
        
            <error type="error" message="Input staging problem: Traceback (most recent call last):
  File "/opt/hostedtoolcache/Python/3.12.10/x64/lib/python3.12/site-packages/galaxy/tool_util/verify/interactor.py", line 1434, in verify_tool
    stage_data_in_history(
  File "/opt/hostedtoolcache/Python/3.12.10/x64/lib/python3.12/site-packages/galaxy/tool_util/verify/interactor.py", line 163, in stage_data_in_history
    test_dict = galaxy_interactor.remote_to_input(
                ^^^^^^^^^^^^^^^^^^^^^^^^^^^^^^^^^^
  File "/opt/hostedtoolcache/Python/3.12.10/x64/lib/python3.12/site-packages/galaxy/tool_util/verify/interactor.py", line 582, in remote_to_input
    path_or_location = self._get_path_or_location(
                       ^^^^^^^^^^^^^^^^^^^^^^^^^^^
  File "/opt/hostedtoolcache/Python/3.12.10/x64/lib/python3.12/site-packages/galaxy/tool_util/verify/interactor.py", line 619, in _get_path_or_location
    path = self.test_data_download(
           ^^^^^^^^^^^^^^^^^^^^^^^^
  File "/opt/hostedtoolcache/Python/3.12.10/x64/lib/python3.12/site-packages/galaxy/tool_util/verify/interactor.py", line 525, in test_data_download
    raise AssertionError(f"Test input file ({filename}) cannot be found.")
AssertionError: Test input file (R1.fq) cannot be found.
"><![CDATA[
                { "execution_problem": "Input staging problem: Traceback (most recent call last):\n  File \"/opt/hostedtoolcache/Python/3.12.10/x64/lib/python3.12/site-packages/galaxy/tool_util/verify/interactor.py\", line 1434, in verify_tool\n    stage_data_in_history(\n  File \"/opt/hostedtoolcache/Python/3.12.10/x64/lib/python3.12/site-packages/galaxy/tool_util/verify/interactor.py\", line 163, in stage_data_in_history\n    test_dict = galaxy_interactor.remote_to_input(\n                ^^^^^^^^^^^^^^^^^^^^^^^^^^^^^^^^^^\n  File \"/opt/hostedtoolcache/Python/3.12.10/x64/lib/python3.12/site-packages/galaxy/tool_util/verify/interactor.py\", line 582, in remote_to_input\n    path_or_location = self._get_path_or_location(\n                       ^^^^^^^^^^^^^^^^^^^^^^^^^^^\n  File \"/opt/hostedtoolcache/Python/3.12.10/x64/lib/python3.12/site-packages/galaxy/tool_util/verify/interactor.py\", line 619, in _get_path_or_location\n    path = self.test_data_download(\n           ^^^^^^^^^^^^^^^^^^^^^^^^\n  File \"/opt/hostedtoolcache/Python/3.12.10/x64/lib/python3.12/site-packages/galaxy/tool_util/verify/interactor.py\", line 525, in test_data_download\n    raise AssertionError(f\"Test input file ({filename}) cannot be found.\")\nAssertionError: Test input file (R1.fq) cannot be found.\n", "status": "error", "test_index": 8, "time_seconds": 0.06538867950439453, "tool_id": "fastp", "tool_version": "0.24.0+galaxy3"}
            ]]></error>
        
    </testcase>
    
    <testcase classname="fastp (Test #10)" name="9" time="0.0655670166015625">
        
            <error type="error" message="Input staging problem: Traceback (most recent call last):
  File "/opt/hostedtoolcache/Python/3.12.10/x64/lib/python3.12/site-packages/galaxy/tool_util/verify/interactor.py", line 1434, in verify_tool
    stage_data_in_history(
  File "/opt/hostedtoolcache/Python/3.12.10/x64/lib/python3.12/site-packages/galaxy/tool_util/verify/interactor.py", line 163, in stage_data_in_history
    test_dict = galaxy_interactor.remote_to_input(
                ^^^^^^^^^^^^^^^^^^^^^^^^^^^^^^^^^^
  File "/opt/hostedtoolcache/Python/3.12.10/x64/lib/python3.12/site-packages/galaxy/tool_util/verify/interactor.py", line 582, in remote_to_input
    path_or_location = self._get_path_or_location(
                       ^^^^^^^^^^^^^^^^^^^^^^^^^^^
  File "/opt/hostedtoolcache/Python/3.12.10/x64/lib/python3.12/site-packages/galaxy/tool_util/verify/interactor.py", line 619, in _get_path_or_location
    path = self.test_data_download(
           ^^^^^^^^^^^^^^^^^^^^^^^^
  File "/opt/hostedtoolcache/Python/3.12.10/x64/lib/python3.12/site-packages/galaxy/tool_util/verify/interactor.py", line 525, in test_data_download
    raise AssertionError(f"Test input file ({filename}) cannot be found.")
AssertionError: Test input file (R1.fq.gz) cannot be found.
"><![CDATA[
                { "execution_problem": "Input staging problem: Traceback (most recent call last):\n  File \"/opt/hostedtoolcache/Python/3.12.10/x64/lib/python3.12/site-packages/galaxy/tool_util/verify/interactor.py\", line 1434, in verify_tool\n    stage_data_in_history(\n  File \"/opt/hostedtoolcache/Python/3.12.10/x64/lib/python3.12/site-packages/galaxy/tool_util/verify/interactor.py\", line 163, in stage_data_in_history\n    test_dict = galaxy_interactor.remote_to_input(\n                ^^^^^^^^^^^^^^^^^^^^^^^^^^^^^^^^^^\n  File \"/opt/hostedtoolcache/Python/3.12.10/x64/lib/python3.12/site-packages/galaxy/tool_util/verify/interactor.py\", line 582, in remote_to_input\n    path_or_location = self._get_path_or_location(\n                       ^^^^^^^^^^^^^^^^^^^^^^^^^^^\n  File \"/opt/hostedtoolcache/Python/3.12.10/x64/lib/python3.12/site-packages/galaxy/tool_util/verify/interactor.py\", line 619, in _get_path_or_location\n    path = self.test_data_download(\n           ^^^^^^^^^^^^^^^^^^^^^^^^\n  File \"/opt/hostedtoolcache/Python/3.12.10/x64/lib/python3.12/site-packages/galaxy/tool_util/verify/interactor.py\", line 525, in test_data_download\n    raise AssertionError(f\"Test input file ({filename}) cannot be found.\")\nAssertionError: Test input file (R1.fq.gz) cannot be found.\n", "status": "error", "test_index": 9, "time_seconds": 0.0655670166015625, "tool_id": "fastp", "tool_version": "0.24.0+galaxy3"}
            ]]></error>
        
    </testcase>
    
    <testcase classname="ivar_variants (Test #1)" name="0" time="43.69472599029541">
        
            
            <system-out><![CDATA[
            A GFF file containing the open reading frames (ORFs) has not been provided. Amino acid translation will not be done.A reference sequence has not been supplied. Amino acid translation will not be done.
            ]]></system-out>
            <system-err><![CDATA[
            [mpileup] 1 samples in 1 input files[mpileup] Max depth set to maximum value (2147483647)
            ]]></system-err>
        
    </testcase>
    
    <testcase classname="ivar_variants (Test #2)" name="1" time="29.587095260620117">
        
            
                <error type="error" message="Tool exit code: None"><![CDATA[
                    { "inputs": {  "input_bam": {   "id": "e272d385d7104cdc",   "src": "hda"  },  "output_format|choice": "vcf",  "ref": {   "id": "6105a48e399970cd",   "src": "hda"  } }, "job": {  "command_line": "ln -s \u0027/galaxy/server/database/objects/f/f/a/dataset_ffa664de-2505-498c-9a09-03ceebbd1975.dat\u0027 ref.fa \u0026\u0026 ln -s \u0027/galaxy/server/database/objects/9/2/e/dataset_92e3db44-df34-45e8-8dff-e319722a9a40.dat\u0027 sorted.bam \u0026\u0026 samtools mpileup -A -d 0 --reference ref.fa -B -Q 0 sorted.bam | ivar variants -p variants -q 20 -t 0.03 \u0026\u0026 python \u0027/cvmfs/cloud.galaxyproject.org/tools/toolshed.g2.bx.psu.edu/repos/iuc/ivar_variants/abbc8041e8ec/ivar_variants/ivar_variants_to_vcf.py\u0027  variants.tsv variants.vcf",  "command_version": null,  "copied_from_job_id": null,  "create_time": "2025-05-30T01:19:19.035745",  "dependencies": [],  "exit_code": null,  "external_id": "gxy-x4zkw",  "galaxy_version": "24.1",  "handler": null,  "history_id": "288caeae45c8003a",  "id": "716d56740c872905",  "inputs": {   "input_bam": {    "id": "e272d385d7104cdc",    "src": "hda",    "uuid": "92e3db44-df34-45e8-8dff-e319722a9a40"   },   "ref": {    "id": "6105a48e399970cd",    "src": "hda",    "uuid": "ffa664de-2505-498c-9a09-03ceebbd1975"   }  },  "job_messages": null,  "job_metrics": [],  "job_runner_name": null,  "job_stderr": null,  "job_stdout": null,  "model_class": "Job",  "output_collections": {},  "outputs": {   "output_variants_vcf": {    "id": "9374ab1e2fe265de",    "src": "hda",    "uuid": "84926d64-a722-4b68-94db-ce0b9af822e1"   }  },  "params": {   "__input_ext": "\"input\"",   "chromInfo": "\"/cvmfs/data.galaxyproject.org/managed/len/ucsc/?.len\"",   "dbkey": "\"?\"",   "min_freq": "\"0.03\"",   "min_qual": "\"20\"",   "output_format": "{\"__current_case__\": 0, \"choice\": \"vcf\", \"pass_only\": false}"  },  "state": "error",  "stderr": "[mpileup] 1 samples in 1 input files\n[mpileup] Max depth set to maximum value (2147483647)\n",  "stdout": "A GFF file containing the open reading frames (ORFs) has not been provided. Amino acid translation will not be done.\nA reference sequence has not been supplied. Amino acid translation will not be done.\nsample\tDEL\tINS\tSNP\nvariants\t0\t1\t15\n",  "tool_id": "toolshed.g2.bx.psu.edu/repos/iuc/ivar_variants/ivar_variants/1.4.3+galaxy1",  "tool_stderr": "[mpileup] 1 samples in 1 input files\n[mpileup] Max depth set to maximum value (2147483647)\n",  "tool_stdout": "A GFF file containing the open reading frames (ORFs) has not been provided. Amino acid translation will not be done.\nA reference sequence has not been supplied. Amino acid translation will not be done.\nsample\tDEL\tINS\tSNP\nvariants\t0\t1\t15\n",  "update_time": "2025-05-30T01:19:25.826108",  "user_email": "tests@fake.org" }, "output_problems": [  "Job in error state.. tool_id: toolshed.g2.bx.psu.edu/repos/iuc/ivar_variants/ivar_variants/1.4.3+galaxy1, exit_code: None, stderr: [mpileup] 1 samples in 1 input files\n[mpileup] Max depth set to maximum value (2147483647)\n.",  "Job in error state.. tool_id: toolshed.g2.bx.psu.edu/repos/iuc/ivar_variants/ivar_variants/1.4.3+galaxy1, exit_code: None, stderr: [mpileup] 1 samples in 1 input files\n[mpileup] Max depth set to maximum value (2147483647)\n." ], "status": "failure", "test_index": 1, "time_seconds": 29.587095260620117, "tool_id": "ivar_variants", "tool_version": "1.4.3+galaxy1"}
                ]]></error>
            
            <system-out><![CDATA[
            A GFF file containing the open reading frames (ORFs) has not been provided. Amino acid translation will not be done.A reference sequence has not been supplied. Amino acid translation will not be done.sampleDELINSSNPvariants0115
            ]]></system-out>
            <system-err><![CDATA[
            [mpileup] 1 samples in 1 input files[mpileup] Max depth set to maximum value (2147483647)
            ]]></system-err>
        
    </testcase>
    
    <testcase classname="ivar_variants (Test #3)" name="2" time="12.352977514266968">
        
            <error type="error" message="Input staging problem: Traceback (most recent call last):
  File "/opt/hostedtoolcache/Python/3.12.10/x64/lib/python3.12/site-packages/galaxy/tool_util/verify/interactor.py", line 1434, in verify_tool
    stage_data_in_history(
  File "/opt/hostedtoolcache/Python/3.12.10/x64/lib/python3.12/site-packages/galaxy/tool_util/verify/interactor.py", line 175, in stage_data_in_history
    staging_interface.handle_jobs()
  File "/opt/hostedtoolcache/Python/3.12.10/x64/lib/python3.12/site-packages/galaxy/tool_util/verify/interactor.py", line 212, in handle_jobs
    self.galaxy_interactor.wait_for_job(job_response["id"], job_response["history_id"], self.maxseconds)
  File "/opt/hostedtoolcache/Python/3.12.10/x64/lib/python3.12/site-packages/galaxy/tool_util/verify/interactor.py", line 399, in wait_for_job
    self.wait_for(lambda: self.__job_ready(job_id, history_id), maxseconds=maxseconds)
  File "/opt/hostedtoolcache/Python/3.12.10/x64/lib/python3.12/site-packages/galaxy/tool_util/verify/interactor.py", line 403, in wait_for
    wait_on(func, what, walltime_exceeded)
  File "/opt/hostedtoolcache/Python/3.12.10/x64/lib/python3.12/site-packages/galaxy/tool_util/verify/wait.py", line 38, in wait_on
    value = function()
            ^^^^^^^^^^
  File "/opt/hostedtoolcache/Python/3.12.10/x64/lib/python3.12/site-packages/galaxy/tool_util/verify/interactor.py", line 399, in <lambda>
    self.wait_for(lambda: self.__job_ready(job_id, history_id), maxseconds=maxseconds)
                          ^^^^^^^^^^^^^^^^^^^^^^^^^^^^^^^^^^^^
  File "/opt/hostedtoolcache/Python/3.12.10/x64/lib/python3.12/site-packages/galaxy/tool_util/verify/interactor.py", line 747, in __job_ready
    return self._state_ready(job_id, error_msg="Job in error state.")
           ^^^^^^^^^^^^^^^^^^^^^^^^^^^^^^^^^^^^^^^^^^^^^^^^^^^^^^^^^^
  File "/opt/hostedtoolcache/Python/3.12.10/x64/lib/python3.12/site-packages/galaxy/tool_util/verify/interactor.py", line 839, in _state_ready
    raise Exception(
Exception: Job in error state.. tool_id: __DATA_FETCH__, exit_code: None, stderr: .
"><![CDATA[
                { "execution_problem": "Input staging problem: Traceback (most recent call last):\n  File \"/opt/hostedtoolcache/Python/3.12.10/x64/lib/python3.12/site-packages/galaxy/tool_util/verify/interactor.py\", line 1434, in verify_tool\n    stage_data_in_history(\n  File \"/opt/hostedtoolcache/Python/3.12.10/x64/lib/python3.12/site-packages/galaxy/tool_util/verify/interactor.py\", line 175, in stage_data_in_history\n    staging_interface.handle_jobs()\n  File \"/opt/hostedtoolcache/Python/3.12.10/x64/lib/python3.12/site-packages/galaxy/tool_util/verify/interactor.py\", line 212, in handle_jobs\n    self.galaxy_interactor.wait_for_job(job_response[\"id\"], job_response[\"history_id\"], self.maxseconds)\n  File \"/opt/hostedtoolcache/Python/3.12.10/x64/lib/python3.12/site-packages/galaxy/tool_util/verify/interactor.py\", line 399, in wait_for_job\n    self.wait_for(lambda: self.__job_ready(job_id, history_id), maxseconds=maxseconds)\n  File \"/opt/hostedtoolcache/Python/3.12.10/x64/lib/python3.12/site-packages/galaxy/tool_util/verify/interactor.py\", line 403, in wait_for\n    wait_on(func, what, walltime_exceeded)\n  File \"/opt/hostedtoolcache/Python/3.12.10/x64/lib/python3.12/site-packages/galaxy/tool_util/verify/wait.py\", line 38, in wait_on\n    value = function()\n            ^^^^^^^^^^\n  File \"/opt/hostedtoolcache/Python/3.12.10/x64/lib/python3.12/site-packages/galaxy/tool_util/verify/interactor.py\", line 399, in \u003clambda\u003e\n    self.wait_for(lambda: self.__job_ready(job_id, history_id), maxseconds=maxseconds)\n                          ^^^^^^^^^^^^^^^^^^^^^^^^^^^^^^^^^^^^\n  File \"/opt/hostedtoolcache/Python/3.12.10/x64/lib/python3.12/site-packages/galaxy/tool_util/verify/interactor.py\", line 747, in __job_ready\n    return self._state_ready(job_id, error_msg=\"Job in error state.\")\n           ^^^^^^^^^^^^^^^^^^^^^^^^^^^^^^^^^^^^^^^^^^^^^^^^^^^^^^^^^^\n  File \"/opt/hostedtoolcache/Python/3.12.10/x64/lib/python3.12/site-packages/galaxy/tool_util/verify/interactor.py\", line 839, in _state_ready\n    raise Exception(\nException: Job in error state.. tool_id: __DATA_FETCH__, exit_code: None, stderr: .\n", "status": "error", "test_index": 2, "time_seconds": 12.352977514266968, "tool_id": "ivar_variants", "tool_version": "1.4.3+galaxy1"}
            ]]></error>
        
    </testcase>
    
    <testcase classname="ivar_variants (Test #4)" name="3" time="40.9078586101532">
        
            
            <system-out><![CDATA[
            
            ]]></system-out>
            <system-err><![CDATA[
            [mpileup] 1 samples in 1 input files[mpileup] Max depth set to maximum value (2147483647)
            ]]></system-err>
        
    </testcase>
    
    <testcase classname="ivar_variants (Test #5)" name="4" time="42.44119954109192">
        
            
            <system-out><![CDATA[
            sampleDELINSSNPvariants0010
            ]]></system-out>
            <system-err><![CDATA[
            [mpileup] 1 samples in 1 input files[mpileup] Max depth set to maximum value (2147483647)
            ]]></system-err>
        
    </testcase>
    
    <testcase classname="lofreq_viterbi (Test #1)" name="0" time="47.50707674026489">
        
            
            <system-out><![CDATA[
            
            ]]></system-out>
            <system-err><![CDATA[
            [bam_sort_core] merging from 0 files and 4 in-memory blocks...
            ]]></system-err>
        
    </testcase>
    
    <testcase classname="lofreq_viterbi (Test #2)" name="1" time="34.766028881073">
        
            
            <system-out><![CDATA[
            
            ]]></system-out>
            <system-err><![CDATA[
            [bam_sort_core] merging from 0 files and 4 in-memory blocks...
            ]]></system-err>
        
    </testcase>
    
    <testcase classname="poretools_events (Test #1)" name="0" time="67.83082985877991">
        
            
                <error type="error" message="Tool exit code: 1"><![CDATA[
                    { "inputs": {  "input": {   "id": "90aa155378d52200",   "src": "hda"  },  "precalled": false }, "job": {  "command_line": "poretools events  \u0027/galaxy/server/database/objects/d/e/d/dataset_ded1f47f-0fef-4625-9a24-b10490fd4229.dat\u0027 \u003e \u0027/galaxy/server/database/objects/1/1/1/dataset_11112934-6347-45b8-a6ab-5832a447d8b0.dat\u0027",  "command_version": "",  "copied_from_job_id": null,  "create_time": "2025-05-30T01:14:01.790156",  "dependencies": [],  "exit_code": 1,  "external_id": "gxy-ffn99",  "galaxy_version": "24.1",  "handler": null,  "history_id": "288caeae45c8003a",  "id": "8ae3725735fbf5c9",  "inputs": {   "input": {    "id": "90aa155378d52200",    "src": "hda",    "uuid": "ded1f47f-0fef-4625-9a24-b10490fd4229"   }  },  "job_messages": [   {    "code_desc": "",    "desc": "Fatal error: Exit code 1 ()",    "error_level": 3,    "exit_code": 1,    "type": "exit_code"   },   {    "code_desc": "",    "desc": "Fatal error: ",    "error_level": 3,    "match": "Error:",    "stream": "stderr",    "type": "regex"   }  ],  "job_metrics": [   {    "name": "runtime_seconds",    "plugin": "core",    "raw_value": "1.0000000",    "title": "Job Runtime (Wall Clock)",    "value": "1 second"   },   {    "name": "end_epoch",    "plugin": "core",    "raw_value": "1748567670.0000000",    "title": "Job End Time",    "value": "2025-05-30 01:14:30"   },   {    "name": "start_epoch",    "plugin": "core",    "raw_value": "1748567669.0000000",    "title": "Job Start Time",    "value": "2025-05-30 01:14:29"   },   {    "name": "galaxy_memory_mb",    "plugin": "core",    "raw_value": "12240.0000000",    "title": "Memory Allocated (MB)",    "value": "12240"   },   {    "name": "galaxy_slots",    "plugin": "core",    "raw_value": "1.0000000",    "title": "Cores Allocated",    "value": "1"   }  ],  "job_runner_name": null,  "job_stderr": "",  "job_stdout": "",  "model_class": "Job",  "output_collections": {},  "outputs": {   "output": {    "id": "9f1aa8e79600f905",    "src": "hda",    "uuid": "11112934-6347-45b8-a6ab-5832a447d8b0"   }  },  "params": {   "__input_ext": "\"input\"",   "chromInfo": "\"/cvmfs/data.galaxyproject.org/managed/len/ucsc/?.len\"",   "dbkey": "\"?\"",   "precalled": "false"  },  "state": "error",  "stderr": "Traceback (most recent call last):\n  File \"/usr/local/bin/poretools\", line 11, in \u003cmodule\u003e\n    load_entry_point(\u0027poretools==0.6.0\u0027, \u0027console_scripts\u0027, \u0027poretools\u0027)()\n  File \"/usr/local/lib/python2.7/site-packages/poretools/poretools_main.py\", line 543, in main\n    args.func(parser, args)\n  File \"/usr/local/lib/python2.7/site-packages/poretools/poretools_main.py\", line 55, in run_subtool\n    submodule.run(parser, args)\n  File \"/usr/local/lib/python2.7/site-packages/poretools/events.py\", line 17, in run\n    for fast5 in Fast5File.Fast5FileSet(args.files):\n  File \"/usr/local/lib/python2.7/site-packages/poretools/Fast5File.py\", line 110, in next\n    shutil.rmtree(PORETOOLS_TMPDIR)\n  File \"/usr/local/lib/python2.7/shutil.py\", line 261, in rmtree\n    rmtree(fullname, ignore_errors, onerror)\n  File \"/usr/local/lib/python2.7/shutil.py\", line 270, in rmtree\n    onerror(os.rmdir, path, sys.exc_info())\n  File \"/usr/local/lib/python2.7/shutil.py\", line 268, in rmtree\n    os.rmdir(path)\nOSError: [Errno 39] Directory not empty: \u0027.poretools_tmp/test-data\u0027\n",  "stdout": "",  "tool_id": "toolshed.g2.bx.psu.edu/repos/iuc/poretools_events/poretools_events/0.6.1a1.1",  "tool_stderr": "Traceback (most recent call last):\n  File \"/usr/local/bin/poretools\", line 11, in \u003cmodule\u003e\n    load_entry_point(\u0027poretools==0.6.0\u0027, \u0027console_scripts\u0027, \u0027poretools\u0027)()\n  File \"/usr/local/lib/python2.7/site-packages/poretools/poretools_main.py\", line 543, in main\n    args.func(parser, args)\n  File \"/usr/local/lib/python2.7/site-packages/poretools/poretools_main.py\", line 55, in run_subtool\n    submodule.run(parser, args)\n  File \"/usr/local/lib/python2.7/site-packages/poretools/events.py\", line 17, in run\n    for fast5 in Fast5File.Fast5FileSet(args.files):\n  File \"/usr/local/lib/python2.7/site-packages/poretools/Fast5File.py\", line 110, in next\n    shutil.rmtree(PORETOOLS_TMPDIR)\n  File \"/usr/local/lib/python2.7/shutil.py\", line 261, in rmtree\n    rmtree(fullname, ignore_errors, onerror)\n  File \"/usr/local/lib/python2.7/shutil.py\", line 270, in rmtree\n    onerror(os.rmdir, path, sys.exc_info())\n  File \"/usr/local/lib/python2.7/shutil.py\", line 268, in rmtree\n    os.rmdir(path)\nOSError: [Errno 39] Directory not empty: \u0027.poretools_tmp/test-data\u0027\n",  "tool_stdout": "",  "update_time": "2025-05-30T01:14:48.424903",  "user_email": "tests@fake.org" }, "output_problems": [  "Job in error state.. tool_id: toolshed.g2.bx.psu.edu/repos/iuc/poretools_events/poretools_events/0.6.1a1.1, exit_code: 1, stderr: Traceback (most recent call last):\n  File \"/usr/local/bin/poretools\", line 11, in \u003cmodule\u003e\n    load_entry_point(\u0027poretools==0.6.0\u0027, \u0027console_scripts\u0027, \u0027poretools\u0027)()\n  File \"/usr/local/lib/python2.7/site-packages/poretools/poretools_main.py\", line 543, in main\n    args.func(parser, args)\n  File \"/usr/local/lib/python2.7/site-packages/poretools/poretools_main.py\", line 55, in run_subtool\n    submodule.run(parser, args)\n  File \"/usr/local/lib/python2.7/site-packages/poretools/events.py\", line 17, in run\n    for fast5 in Fast5File.Fast5FileSet(args.files):\n  File \"/usr/local/lib/python2.7/site-packages/poretools/Fast5File.py\", line 110, in next\n    shutil.rmtree(PORETOOLS_TMPDIR)\n  File \"/usr/local/lib/python2.7/shutil.py\", line 261, in rmtree\n    rmtree(fullname, ignore_errors, onerror)\n  File \"/usr/local/lib/python2.7/shutil.py\", line 270, in rmtree\n    onerror(os.rmdir, path, sys.exc_info())\n  File \"/usr/local/lib/python2.7/shutil.py\", line 268, in rmtree\n    os.rmdir(path)\nOSError: [Errno 39] Directory not empty: \u0027.poretools_tmp/test-data\u0027\n.",  "Job in error state.. tool_id: toolshed.g2.bx.psu.edu/repos/iuc/poretools_events/poretools_events/0.6.1a1.1, exit_code: 1, stderr: Traceback (most recent call last):\n  File \"/usr/local/bin/poretools\", line 11, in \u003cmodule\u003e\n    load_entry_point(\u0027poretools==0.6.0\u0027, \u0027console_scripts\u0027, \u0027poretools\u0027)()\n  File \"/usr/local/lib/python2.7/site-packages/poretools/poretools_main.py\", line 543, in main\n    args.func(parser, args)\n  File \"/usr/local/lib/python2.7/site-packages/poretools/poretools_main.py\", line 55, in run_subtool\n    submodule.run(parser, args)\n  File \"/usr/local/lib/python2.7/site-packages/poretools/events.py\", line 17, in run\n    for fast5 in Fast5File.Fast5FileSet(args.files):\n  File \"/usr/local/lib/python2.7/site-packages/poretools/Fast5File.py\", line 110, in next\n    shutil.rmtree(PORETOOLS_TMPDIR)\n  File \"/usr/local/lib/python2.7/shutil.py\", line 261, in rmtree\n    rmtree(fullname, ignore_errors, onerror)\n  File \"/usr/local/lib/python2.7/shutil.py\", line 270, in rmtree\n    onerror(os.rmdir, path, sys.exc_info())\n  File \"/usr/local/lib/python2.7/shutil.py\", line 268, in rmtree\n    os.rmdir(path)\nOSError: [Errno 39] Directory not empty: \u0027.poretools_tmp/test-data\u0027\n." ], "status": "failure", "test_index": 0, "time_seconds": 67.83082985877991, "tool_id": "poretools_events", "tool_version": "0.6.1a1.1"}
                ]]></error>
            
            <system-out><![CDATA[
            
            ]]></system-out>
            <system-err><![CDATA[
            Traceback (most recent call last):  File "/usr/local/bin/poretools", line 11, in <module>    load_entry_point('poretools==0.6.0', 'console_scripts', 'poretools')()  File "/usr/local/lib/python2.7/site-packages/poretools/poretools_main.py", line 543, in main    args.func(parser, args)  File "/usr/local/lib/python2.7/site-packages/poretools/poretools_main.py", line 55, in run_subtool    submodule.run(parser, args)  File "/usr/local/lib/python2.7/site-packages/poretools/events.py", line 17, in run    for fast5 in Fast5File.Fast5FileSet(args.files):  File "/usr/local/lib/python2.7/site-packages/poretools/Fast5File.py", line 110, in next    shutil.rmtree(PORETOOLS_TMPDIR)  File "/usr/local/lib/python2.7/shutil.py", line 261, in rmtree    rmtree(fullname, ignore_errors, onerror)  File "/usr/local/lib/python2.7/shutil.py", line 270, in rmtree    onerror(os.rmdir, path, sys.exc_info())  File "/usr/local/lib/python2.7/shutil.py", line 268, in rmtree    os.rmdir(path)OSError: [Errno 39] Directory not empty: '.poretools_tmp/test-data'
            ]]></system-err>
        
    </testcase>
    
    <testcase classname="poretools_events (Test #2)" name="1" time="12.066094636917114">
        
            <error type="error" message="Input staging problem: Traceback (most recent call last):
  File "/opt/hostedtoolcache/Python/3.12.10/x64/lib/python3.12/site-packages/galaxy/tool_util/verify/interactor.py", line 1434, in verify_tool
    stage_data_in_history(
  File "/opt/hostedtoolcache/Python/3.12.10/x64/lib/python3.12/site-packages/galaxy/tool_util/verify/interactor.py", line 175, in stage_data_in_history
    staging_interface.handle_jobs()
  File "/opt/hostedtoolcache/Python/3.12.10/x64/lib/python3.12/site-packages/galaxy/tool_util/verify/interactor.py", line 212, in handle_jobs
    self.galaxy_interactor.wait_for_job(job_response["id"], job_response["history_id"], self.maxseconds)
  File "/opt/hostedtoolcache/Python/3.12.10/x64/lib/python3.12/site-packages/galaxy/tool_util/verify/interactor.py", line 399, in wait_for_job
    self.wait_for(lambda: self.__job_ready(job_id, history_id), maxseconds=maxseconds)
  File "/opt/hostedtoolcache/Python/3.12.10/x64/lib/python3.12/site-packages/galaxy/tool_util/verify/interactor.py", line 403, in wait_for
    wait_on(func, what, walltime_exceeded)
  File "/opt/hostedtoolcache/Python/3.12.10/x64/lib/python3.12/site-packages/galaxy/tool_util/verify/wait.py", line 38, in wait_on
    value = function()
            ^^^^^^^^^^
  File "/opt/hostedtoolcache/Python/3.12.10/x64/lib/python3.12/site-packages/galaxy/tool_util/verify/interactor.py", line 399, in <lambda>
    self.wait_for(lambda: self.__job_ready(job_id, history_id), maxseconds=maxseconds)
                          ^^^^^^^^^^^^^^^^^^^^^^^^^^^^^^^^^^^^
  File "/opt/hostedtoolcache/Python/3.12.10/x64/lib/python3.12/site-packages/galaxy/tool_util/verify/interactor.py", line 747, in __job_ready
    return self._state_ready(job_id, error_msg="Job in error state.")
           ^^^^^^^^^^^^^^^^^^^^^^^^^^^^^^^^^^^^^^^^^^^^^^^^^^^^^^^^^^
  File "/opt/hostedtoolcache/Python/3.12.10/x64/lib/python3.12/site-packages/galaxy/tool_util/verify/interactor.py", line 839, in _state_ready
    raise Exception(
Exception: Job in error state.. tool_id: __DATA_FETCH__, exit_code: None, stderr: .
"><![CDATA[
                { "execution_problem": "Input staging problem: Traceback (most recent call last):\n  File \"/opt/hostedtoolcache/Python/3.12.10/x64/lib/python3.12/site-packages/galaxy/tool_util/verify/interactor.py\", line 1434, in verify_tool\n    stage_data_in_history(\n  File \"/opt/hostedtoolcache/Python/3.12.10/x64/lib/python3.12/site-packages/galaxy/tool_util/verify/interactor.py\", line 175, in stage_data_in_history\n    staging_interface.handle_jobs()\n  File \"/opt/hostedtoolcache/Python/3.12.10/x64/lib/python3.12/site-packages/galaxy/tool_util/verify/interactor.py\", line 212, in handle_jobs\n    self.galaxy_interactor.wait_for_job(job_response[\"id\"], job_response[\"history_id\"], self.maxseconds)\n  File \"/opt/hostedtoolcache/Python/3.12.10/x64/lib/python3.12/site-packages/galaxy/tool_util/verify/interactor.py\", line 399, in wait_for_job\n    self.wait_for(lambda: self.__job_ready(job_id, history_id), maxseconds=maxseconds)\n  File \"/opt/hostedtoolcache/Python/3.12.10/x64/lib/python3.12/site-packages/galaxy/tool_util/verify/interactor.py\", line 403, in wait_for\n    wait_on(func, what, walltime_exceeded)\n  File \"/opt/hostedtoolcache/Python/3.12.10/x64/lib/python3.12/site-packages/galaxy/tool_util/verify/wait.py\", line 38, in wait_on\n    value = function()\n            ^^^^^^^^^^\n  File \"/opt/hostedtoolcache/Python/3.12.10/x64/lib/python3.12/site-packages/galaxy/tool_util/verify/interactor.py\", line 399, in \u003clambda\u003e\n    self.wait_for(lambda: self.__job_ready(job_id, history_id), maxseconds=maxseconds)\n                          ^^^^^^^^^^^^^^^^^^^^^^^^^^^^^^^^^^^^\n  File \"/opt/hostedtoolcache/Python/3.12.10/x64/lib/python3.12/site-packages/galaxy/tool_util/verify/interactor.py\", line 747, in __job_ready\n    return self._state_ready(job_id, error_msg=\"Job in error state.\")\n           ^^^^^^^^^^^^^^^^^^^^^^^^^^^^^^^^^^^^^^^^^^^^^^^^^^^^^^^^^^\n  File \"/opt/hostedtoolcache/Python/3.12.10/x64/lib/python3.12/site-packages/galaxy/tool_util/verify/interactor.py\", line 839, in _state_ready\n    raise Exception(\nException: Job in error state.. tool_id: __DATA_FETCH__, exit_code: None, stderr: .\n", "status": "error", "test_index": 1, "time_seconds": 12.066094636917114, "tool_id": "poretools_events", "tool_version": "0.6.1a1.1"}
            ]]></error>
        
    </testcase>
    
    <testcase classname="samtools_merge (Test #1)" name="0" time="19.962532997131348">
        
            <error type="error" message="Input staging problem: Traceback (most recent call last):
  File "/opt/hostedtoolcache/Python/3.12.10/x64/lib/python3.12/site-packages/galaxy/tool_util/verify/interactor.py", line 1434, in verify_tool
    stage_data_in_history(
  File "/opt/hostedtoolcache/Python/3.12.10/x64/lib/python3.12/site-packages/galaxy/tool_util/verify/interactor.py", line 175, in stage_data_in_history
    staging_interface.handle_jobs()
  File "/opt/hostedtoolcache/Python/3.12.10/x64/lib/python3.12/site-packages/galaxy/tool_util/verify/interactor.py", line 212, in handle_jobs
    self.galaxy_interactor.wait_for_job(job_response["id"], job_response["history_id"], self.maxseconds)
  File "/opt/hostedtoolcache/Python/3.12.10/x64/lib/python3.12/site-packages/galaxy/tool_util/verify/interactor.py", line 399, in wait_for_job
    self.wait_for(lambda: self.__job_ready(job_id, history_id), maxseconds=maxseconds)
  File "/opt/hostedtoolcache/Python/3.12.10/x64/lib/python3.12/site-packages/galaxy/tool_util/verify/interactor.py", line 403, in wait_for
    wait_on(func, what, walltime_exceeded)
  File "/opt/hostedtoolcache/Python/3.12.10/x64/lib/python3.12/site-packages/galaxy/tool_util/verify/wait.py", line 38, in wait_on
    value = function()
            ^^^^^^^^^^
  File "/opt/hostedtoolcache/Python/3.12.10/x64/lib/python3.12/site-packages/galaxy/tool_util/verify/interactor.py", line 399, in <lambda>
    self.wait_for(lambda: self.__job_ready(job_id, history_id), maxseconds=maxseconds)
                          ^^^^^^^^^^^^^^^^^^^^^^^^^^^^^^^^^^^^
  File "/opt/hostedtoolcache/Python/3.12.10/x64/lib/python3.12/site-packages/galaxy/tool_util/verify/interactor.py", line 747, in __job_ready
    return self._state_ready(job_id, error_msg="Job in error state.")
           ^^^^^^^^^^^^^^^^^^^^^^^^^^^^^^^^^^^^^^^^^^^^^^^^^^^^^^^^^^
  File "/opt/hostedtoolcache/Python/3.12.10/x64/lib/python3.12/site-packages/galaxy/tool_util/verify/interactor.py", line 839, in _state_ready
    raise Exception(
Exception: Job in error state.. tool_id: __DATA_FETCH__, exit_code: None, stderr: .
"><![CDATA[
                { "execution_problem": "Input staging problem: Traceback (most recent call last):\n  File \"/opt/hostedtoolcache/Python/3.12.10/x64/lib/python3.12/site-packages/galaxy/tool_util/verify/interactor.py\", line 1434, in verify_tool\n    stage_data_in_history(\n  File \"/opt/hostedtoolcache/Python/3.12.10/x64/lib/python3.12/site-packages/galaxy/tool_util/verify/interactor.py\", line 175, in stage_data_in_history\n    staging_interface.handle_jobs()\n  File \"/opt/hostedtoolcache/Python/3.12.10/x64/lib/python3.12/site-packages/galaxy/tool_util/verify/interactor.py\", line 212, in handle_jobs\n    self.galaxy_interactor.wait_for_job(job_response[\"id\"], job_response[\"history_id\"], self.maxseconds)\n  File \"/opt/hostedtoolcache/Python/3.12.10/x64/lib/python3.12/site-packages/galaxy/tool_util/verify/interactor.py\", line 399, in wait_for_job\n    self.wait_for(lambda: self.__job_ready(job_id, history_id), maxseconds=maxseconds)\n  File \"/opt/hostedtoolcache/Python/3.12.10/x64/lib/python3.12/site-packages/galaxy/tool_util/verify/interactor.py\", line 403, in wait_for\n    wait_on(func, what, walltime_exceeded)\n  File \"/opt/hostedtoolcache/Python/3.12.10/x64/lib/python3.12/site-packages/galaxy/tool_util/verify/wait.py\", line 38, in wait_on\n    value = function()\n            ^^^^^^^^^^\n  File \"/opt/hostedtoolcache/Python/3.12.10/x64/lib/python3.12/site-packages/galaxy/tool_util/verify/interactor.py\", line 399, in \u003clambda\u003e\n    self.wait_for(lambda: self.__job_ready(job_id, history_id), maxseconds=maxseconds)\n                          ^^^^^^^^^^^^^^^^^^^^^^^^^^^^^^^^^^^^\n  File \"/opt/hostedtoolcache/Python/3.12.10/x64/lib/python3.12/site-packages/galaxy/tool_util/verify/interactor.py\", line 747, in __job_ready\n    return self._state_ready(job_id, error_msg=\"Job in error state.\")\n           ^^^^^^^^^^^^^^^^^^^^^^^^^^^^^^^^^^^^^^^^^^^^^^^^^^^^^^^^^^\n  File \"/opt/hostedtoolcache/Python/3.12.10/x64/lib/python3.12/site-packages/galaxy/tool_util/verify/interactor.py\", line 839, in _state_ready\n    raise Exception(\nException: Job in error state.. tool_id: __DATA_FETCH__, exit_code: None, stderr: .\n", "status": "error", "test_index": 0, "time_seconds": 19.962532997131348, "tool_id": "samtools_merge", "tool_version": "1.9"}
            ]]></error>
        
    </testcase>
    
    <testcase classname="samtools_merge (Test #2)" name="1" time="43.52592706680298">
        
            
            <system-out><![CDATA[
            
            ]]></system-out>
            <system-err><![CDATA[
            [bam_translate] PG tag "colt" on read "r001" encountered with no corresponding entry in header, tag lost. Unknown tags are only reported once per input file for each tag ID.
            ]]></system-err>
        
    </testcase>
    
    <testcase classname="samtools_merge (Test #3)" name="2" time="34.446253538131714">
        
            
            <system-out><![CDATA[
            
            ]]></system-out>
            <system-err><![CDATA[
            
            ]]></system-err>
        
    </testcase>
    
    <testcase classname="samtools_merge (Test #4)" name="3" time="19.885026216506958">
        
            <error type="error" message="Input staging problem: Traceback (most recent call last):
  File "/opt/hostedtoolcache/Python/3.12.10/x64/lib/python3.12/site-packages/galaxy/tool_util/verify/interactor.py", line 1434, in verify_tool
    stage_data_in_history(
  File "/opt/hostedtoolcache/Python/3.12.10/x64/lib/python3.12/site-packages/galaxy/tool_util/verify/interactor.py", line 175, in stage_data_in_history
    staging_interface.handle_jobs()
  File "/opt/hostedtoolcache/Python/3.12.10/x64/lib/python3.12/site-packages/galaxy/tool_util/verify/interactor.py", line 212, in handle_jobs
    self.galaxy_interactor.wait_for_job(job_response["id"], job_response["history_id"], self.maxseconds)
  File "/opt/hostedtoolcache/Python/3.12.10/x64/lib/python3.12/site-packages/galaxy/tool_util/verify/interactor.py", line 399, in wait_for_job
    self.wait_for(lambda: self.__job_ready(job_id, history_id), maxseconds=maxseconds)
  File "/opt/hostedtoolcache/Python/3.12.10/x64/lib/python3.12/site-packages/galaxy/tool_util/verify/interactor.py", line 403, in wait_for
    wait_on(func, what, walltime_exceeded)
  File "/opt/hostedtoolcache/Python/3.12.10/x64/lib/python3.12/site-packages/galaxy/tool_util/verify/wait.py", line 38, in wait_on
    value = function()
            ^^^^^^^^^^
  File "/opt/hostedtoolcache/Python/3.12.10/x64/lib/python3.12/site-packages/galaxy/tool_util/verify/interactor.py", line 399, in <lambda>
    self.wait_for(lambda: self.__job_ready(job_id, history_id), maxseconds=maxseconds)
                          ^^^^^^^^^^^^^^^^^^^^^^^^^^^^^^^^^^^^
  File "/opt/hostedtoolcache/Python/3.12.10/x64/lib/python3.12/site-packages/galaxy/tool_util/verify/interactor.py", line 747, in __job_ready
    return self._state_ready(job_id, error_msg="Job in error state.")
           ^^^^^^^^^^^^^^^^^^^^^^^^^^^^^^^^^^^^^^^^^^^^^^^^^^^^^^^^^^
  File "/opt/hostedtoolcache/Python/3.12.10/x64/lib/python3.12/site-packages/galaxy/tool_util/verify/interactor.py", line 839, in _state_ready
    raise Exception(
Exception: Job in error state.. tool_id: __DATA_FETCH__, exit_code: None, stderr: .
"><![CDATA[
                { "execution_problem": "Input staging problem: Traceback (most recent call last):\n  File \"/opt/hostedtoolcache/Python/3.12.10/x64/lib/python3.12/site-packages/galaxy/tool_util/verify/interactor.py\", line 1434, in verify_tool\n    stage_data_in_history(\n  File \"/opt/hostedtoolcache/Python/3.12.10/x64/lib/python3.12/site-packages/galaxy/tool_util/verify/interactor.py\", line 175, in stage_data_in_history\n    staging_interface.handle_jobs()\n  File \"/opt/hostedtoolcache/Python/3.12.10/x64/lib/python3.12/site-packages/galaxy/tool_util/verify/interactor.py\", line 212, in handle_jobs\n    self.galaxy_interactor.wait_for_job(job_response[\"id\"], job_response[\"history_id\"], self.maxseconds)\n  File \"/opt/hostedtoolcache/Python/3.12.10/x64/lib/python3.12/site-packages/galaxy/tool_util/verify/interactor.py\", line 399, in wait_for_job\n    self.wait_for(lambda: self.__job_ready(job_id, history_id), maxseconds=maxseconds)\n  File \"/opt/hostedtoolcache/Python/3.12.10/x64/lib/python3.12/site-packages/galaxy/tool_util/verify/interactor.py\", line 403, in wait_for\n    wait_on(func, what, walltime_exceeded)\n  File \"/opt/hostedtoolcache/Python/3.12.10/x64/lib/python3.12/site-packages/galaxy/tool_util/verify/wait.py\", line 38, in wait_on\n    value = function()\n            ^^^^^^^^^^\n  File \"/opt/hostedtoolcache/Python/3.12.10/x64/lib/python3.12/site-packages/galaxy/tool_util/verify/interactor.py\", line 399, in \u003clambda\u003e\n    self.wait_for(lambda: self.__job_ready(job_id, history_id), maxseconds=maxseconds)\n                          ^^^^^^^^^^^^^^^^^^^^^^^^^^^^^^^^^^^^\n  File \"/opt/hostedtoolcache/Python/3.12.10/x64/lib/python3.12/site-packages/galaxy/tool_util/verify/interactor.py\", line 747, in __job_ready\n    return self._state_ready(job_id, error_msg=\"Job in error state.\")\n           ^^^^^^^^^^^^^^^^^^^^^^^^^^^^^^^^^^^^^^^^^^^^^^^^^^^^^^^^^^\n  File \"/opt/hostedtoolcache/Python/3.12.10/x64/lib/python3.12/site-packages/galaxy/tool_util/verify/interactor.py\", line 839, in _state_ready\n    raise Exception(\nException: Job in error state.. tool_id: __DATA_FETCH__, exit_code: None, stderr: .\n", "status": "error", "test_index": 3, "time_seconds": 19.885026216506958, "tool_id": "samtools_merge", "tool_version": "1.9"}
            ]]></error>
        
    </testcase>
    
    <testcase classname="samtools_merge (Test #5)" name="4" time="33.69013953208923">
        
            
            <system-out><![CDATA[
            
            ]]></system-out>
            <system-err><![CDATA[
            [bam_translate] PG tag "colt" on read "r001" encountered with no corresponding entry in header, tag lost. Unknown tags are only reported once per input file for each tag ID.
            ]]></system-err>
        
    </testcase>
    
    <testcase classname="vcfannotategenotypes (Test #1)" name="0" time="46.88612604141235">
        
            
            <system-out><![CDATA[
            
            ]]></system-out>
            <system-err><![CDATA[
            
            ]]></system-err>
        
    </testcase>
    
    <testcase classname="vcfsort (Test #1)" name="0" time="36.93926477432251">
        
            
            <system-out><![CDATA[
            
            ]]></system-out>
            <system-err><![CDATA[
            
            ]]></system-err>
        
    </testcase>
    
    <testcase classname="volcanoplot (Test #1)" name="0" time="78.74712014198303">
        
            
            <system-out><![CDATA[
            [1] "Header row detected"null device           1 R version 4.0.5 (2021-03-31)Platform: x86_64-conda-linux-gnu (64-bit)Running under: Debian GNU/Linux 10 (buster)Matrix products: defaultBLAS/LAPACK: /usr/local/lib/libopenblasp-r0.3.15.solocale: [1] LC_CTYPE=C.UTF-8       LC_NUMERIC=C           LC_TIME=C.UTF-8        [4] LC_COLLATE=C.UTF-8     LC_MONETARY=C.UTF-8    LC_MESSAGES=C.UTF-8    [7] LC_PAPER=C.UTF-8       LC_NAME=C              LC_ADDRESS=C          [10] LC_TELEPHONE=C         LC_MEASUREMENT=C.UTF-8 LC_IDENTIFICATION=C   attached base packages:[1] stats     graphics  grDevices utils     datasets  methods   base     other attached packages:[1] ggrepel_0.9.1 ggplot2_3.3.3 dplyr_1.0.6  loaded via a namespace (and not attached): [1] Rcpp_1.0.6       magrittr_2.0.1   tidyselect_1.1.1 munsell_0.5.0    [5] colorspace_2.0-1 R6_2.5.0         rlang_0.4.11     fansi_0.5.0      [9] grid_4.0.5       gtable_0.3.0     utf8_1.2.1       withr_2.4.2     [13] ellipsis_0.3.2   digest_0.6.27    tibble_3.1.2     lifecycle_1.0.0 [17] crayon_1.4.1     purrr_0.3.4      farver_2.1.0     vctrs_0.3.8     [21] glue_1.4.2       labeling_0.4.2   compiler_4.0.5   pillar_1.6.1    [25] generics_0.1.0   scales_1.1.1     pkgconfig_2.0.3 
            ]]></system-out>
            <system-err><![CDATA[
            Warning message:In Sys.setlocale("LC_MESSAGES", "en_US.UTF-8") :  OS reports request to set locale to "en_US.UTF-8" cannot be honored
            ]]></system-err>
        
    </testcase>
    
    <testcase classname="volcanoplot (Test #2)" name="1" time="38.67780375480652">
        
            
            <system-out><![CDATA[
            [1] "Header row detected"null device           1 R version 4.0.5 (2021-03-31)Platform: x86_64-conda-linux-gnu (64-bit)Running under: Debian GNU/Linux 10 (buster)Matrix products: defaultBLAS/LAPACK: /usr/local/lib/libopenblasp-r0.3.15.solocale: [1] LC_CTYPE=C.UTF-8       LC_NUMERIC=C           LC_TIME=C.UTF-8        [4] LC_COLLATE=C.UTF-8     LC_MONETARY=C.UTF-8    LC_MESSAGES=C.UTF-8    [7] LC_PAPER=C.UTF-8       LC_NAME=C              LC_ADDRESS=C          [10] LC_TELEPHONE=C         LC_MEASUREMENT=C.UTF-8 LC_IDENTIFICATION=C   attached base packages:[1] stats     graphics  grDevices utils     datasets  methods   base     other attached packages:[1] ggrepel_0.9.1 ggplot2_3.3.3 dplyr_1.0.6  loaded via a namespace (and not attached): [1] Rcpp_1.0.6       magrittr_2.0.1   tidyselect_1.1.1 munsell_0.5.0    [5] colorspace_2.0-1 R6_2.5.0         rlang_0.4.11     fansi_0.5.0      [9] grid_4.0.5       gtable_0.3.0     utf8_1.2.1       withr_2.4.2     [13] ellipsis_0.3.2   digest_0.6.27    tibble_3.1.2     lifecycle_1.0.0 [17] crayon_1.4.1     purrr_0.3.4      farver_2.1.0     vctrs_0.3.8     [21] glue_1.4.2       labeling_0.4.2   compiler_4.0.5   pillar_1.6.1    [25] generics_0.1.0   scales_1.1.1     pkgconfig_2.0.3 
            ]]></system-out>
            <system-err><![CDATA[
            Warning message:In Sys.setlocale("LC_MESSAGES", "en_US.UTF-8") :  OS reports request to set locale to "en_US.UTF-8" cannot be honored
            ]]></system-err>
        
    </testcase>
    
    <testcase classname="volcanoplot (Test #3)" name="2" time="38.60168647766113">
        
            
            <system-out><![CDATA[
            null device           1 R version 4.0.5 (2021-03-31)Platform: x86_64-conda-linux-gnu (64-bit)Running under: Debian GNU/Linux 10 (buster)Matrix products: defaultBLAS/LAPACK: /usr/local/lib/libopenblasp-r0.3.15.solocale: [1] LC_CTYPE=C.UTF-8       LC_NUMERIC=C           LC_TIME=C.UTF-8        [4] LC_COLLATE=C.UTF-8     LC_MONETARY=C.UTF-8    LC_MESSAGES=C.UTF-8    [7] LC_PAPER=C.UTF-8       LC_NAME=C              LC_ADDRESS=C          [10] LC_TELEPHONE=C         LC_MEASUREMENT=C.UTF-8 LC_IDENTIFICATION=C   attached base packages:[1] stats     graphics  grDevices utils     datasets  methods   base     other attached packages:[1] ggrepel_0.9.1 ggplot2_3.3.3 dplyr_1.0.6  loaded via a namespace (and not attached): [1] Rcpp_1.0.6       magrittr_2.0.1   tidyselect_1.1.1 munsell_0.5.0    [5] colorspace_2.0-1 R6_2.5.0         rlang_0.4.11     fansi_0.5.0      [9] grid_4.0.5       gtable_0.3.0     utf8_1.2.1       withr_2.4.2     [13] ellipsis_0.3.2   digest_0.6.27    tibble_3.1.2     lifecycle_1.0.0 [17] crayon_1.4.1     purrr_0.3.4      farver_2.1.0     vctrs_0.3.8     [21] glue_1.4.2       labeling_0.4.2   compiler_4.0.5   pillar_1.6.1    [25] generics_0.1.0   scales_1.1.1     pkgconfig_2.0.3 
            ]]></system-out>
            <system-err><![CDATA[
            Warning message:In Sys.setlocale("LC_MESSAGES", "en_US.UTF-8") :  OS reports request to set locale to "en_US.UTF-8" cannot be honored
            ]]></system-err>
        
    </testcase>
    
    <testcase classname="volcanoplot (Test #4)" name="3" time="35.984612464904785">
        
            
            <system-out><![CDATA[
            [1] "Header row detected"null device           1 R version 4.0.5 (2021-03-31)Platform: x86_64-conda-linux-gnu (64-bit)Running under: Debian GNU/Linux 10 (buster)Matrix products: defaultBLAS/LAPACK: /usr/local/lib/libopenblasp-r0.3.15.solocale: [1] LC_CTYPE=C.UTF-8       LC_NUMERIC=C           LC_TIME=C.UTF-8        [4] LC_COLLATE=C.UTF-8     LC_MONETARY=C.UTF-8    LC_MESSAGES=C.UTF-8    [7] LC_PAPER=C.UTF-8       LC_NAME=C              LC_ADDRESS=C          [10] LC_TELEPHONE=C         LC_MEASUREMENT=C.UTF-8 LC_IDENTIFICATION=C   attached base packages:[1] stats     graphics  grDevices utils     datasets  methods   base     other attached packages:[1] ggrepel_0.9.1 ggplot2_3.3.3 dplyr_1.0.6  loaded via a namespace (and not attached): [1] Rcpp_1.0.6       magrittr_2.0.1   tidyselect_1.1.1 munsell_0.5.0    [5] colorspace_2.0-1 R6_2.5.0         rlang_0.4.11     fansi_0.5.0      [9] grid_4.0.5       gtable_0.3.0     utf8_1.2.1       withr_2.4.2     [13] ellipsis_0.3.2   digest_0.6.27    tibble_3.1.2     lifecycle_1.0.0 [17] crayon_1.4.1     purrr_0.3.4      farver_2.1.0     vctrs_0.3.8     [21] glue_1.4.2       labeling_0.4.2   compiler_4.0.5   pillar_1.6.1    [25] generics_0.1.0   scales_1.1.1     pkgconfig_2.0.3 
            ]]></system-out>
            <system-err><![CDATA[
            Warning message:In Sys.setlocale("LC_MESSAGES", "en_US.UTF-8") :  OS reports request to set locale to "en_US.UTF-8" cannot be honored
            ]]></system-err>
        
    </testcase>
    
    <testcase classname="volcanoplot (Test #5)" name="4" time="38.13410830497742">
        
            
            <system-out><![CDATA[
            [1] "Header row detected"null device           1 R version 4.0.5 (2021-03-31)Platform: x86_64-conda-linux-gnu (64-bit)Running under: Debian GNU/Linux 10 (buster)Matrix products: defaultBLAS/LAPACK: /usr/local/lib/libopenblasp-r0.3.15.solocale: [1] LC_CTYPE=C.UTF-8       LC_NUMERIC=C           LC_TIME=C.UTF-8        [4] LC_COLLATE=C.UTF-8     LC_MONETARY=C.UTF-8    LC_MESSAGES=C.UTF-8    [7] LC_PAPER=C.UTF-8       LC_NAME=C              LC_ADDRESS=C          [10] LC_TELEPHONE=C         LC_MEASUREMENT=C.UTF-8 LC_IDENTIFICATION=C   attached base packages:[1] stats     graphics  grDevices utils     datasets  methods   base     other attached packages:[1] ggrepel_0.9.1 ggplot2_3.3.3 dplyr_1.0.6  loaded via a namespace (and not attached): [1] Rcpp_1.0.6       magrittr_2.0.1   tidyselect_1.1.1 munsell_0.5.0    [5] colorspace_2.0-1 R6_2.5.0         rlang_0.4.11     fansi_0.5.0      [9] grid_4.0.5       gtable_0.3.0     utf8_1.2.1       withr_2.4.2     [13] ellipsis_0.3.2   digest_0.6.27    tibble_3.1.2     lifecycle_1.0.0 [17] crayon_1.4.1     purrr_0.3.4      farver_2.1.0     vctrs_0.3.8     [21] glue_1.4.2       labeling_0.4.2   compiler_4.0.5   pillar_1.6.1    [25] generics_0.1.0   scales_1.1.1     pkgconfig_2.0.3 
            ]]></system-out>
            <system-err><![CDATA[
            Warning message:In Sys.setlocale("LC_MESSAGES", "en_US.UTF-8") :  OS reports request to set locale to "en_US.UTF-8" cannot be honored
            ]]></system-err>
        
    </testcase>
    
</testsuite>