<?xml version="1.0" encoding="UTF-8"?>
<testsuite name="Results (powered by Planemo)"
           tests="35"
           errors="10"
           failures="1"
           skip="0">
    
    <testcase classname="bcftools_convert_to_vcf (Test #1)" name="0" time="46.61557340621948">
        
            
            <system-out><![CDATA[
            
            ]]></system-out>
            <system-err><![CDATA[
            Number of processed rows: 32
            ]]></system-err>
        
    </testcase>
    
    <testcase classname="bcftools_convert_to_vcf (Test #2)" name="1" time="38.788012742996216">
        
            
            <system-out><![CDATA[
            
            ]]></system-out>
            <system-err><![CDATA[
            Number of processed rows: 35
            ]]></system-err>
        
    </testcase>
    
    <testcase classname="bcftools_convert_to_vcf (Test #3)" name="2" time="22.562655925750732">
        
            <error type="error" message="Input staging problem: Traceback (most recent call last):
  File "/opt/hostedtoolcache/Python/3.12.11/x64/lib/python3.12/site-packages/galaxy/tool_util/verify/interactor.py", line 1436, in verify_tool
    stage_data_in_history(
  File "/opt/hostedtoolcache/Python/3.12.11/x64/lib/python3.12/site-packages/galaxy/tool_util/verify/interactor.py", line 175, in stage_data_in_history
    staging_interface.handle_jobs()
  File "/opt/hostedtoolcache/Python/3.12.11/x64/lib/python3.12/site-packages/galaxy/tool_util/verify/interactor.py", line 212, in handle_jobs
    self.galaxy_interactor.wait_for_job(job_response["id"], job_response["history_id"], self.maxseconds)
  File "/opt/hostedtoolcache/Python/3.12.11/x64/lib/python3.12/site-packages/galaxy/tool_util/verify/interactor.py", line 399, in wait_for_job
    self.wait_for(lambda: self.__job_ready(job_id, history_id), maxseconds=maxseconds)
  File "/opt/hostedtoolcache/Python/3.12.11/x64/lib/python3.12/site-packages/galaxy/tool_util/verify/interactor.py", line 403, in wait_for
    wait_on(func, what, walltime_exceeded)
  File "/opt/hostedtoolcache/Python/3.12.11/x64/lib/python3.12/site-packages/galaxy/tool_util/verify/wait.py", line 38, in wait_on
    value = function()
            ^^^^^^^^^^
  File "/opt/hostedtoolcache/Python/3.12.11/x64/lib/python3.12/site-packages/galaxy/tool_util/verify/interactor.py", line 399, in <lambda>
    self.wait_for(lambda: self.__job_ready(job_id, history_id), maxseconds=maxseconds)
                          ^^^^^^^^^^^^^^^^^^^^^^^^^^^^^^^^^^^^
  File "/opt/hostedtoolcache/Python/3.12.11/x64/lib/python3.12/site-packages/galaxy/tool_util/verify/interactor.py", line 749, in __job_ready
    return self._state_ready(job_id, error_msg="Job in error state.")
           ^^^^^^^^^^^^^^^^^^^^^^^^^^^^^^^^^^^^^^^^^^^^^^^^^^^^^^^^^^
  File "/opt/hostedtoolcache/Python/3.12.11/x64/lib/python3.12/site-packages/galaxy/tool_util/verify/interactor.py", line 841, in _state_ready
    raise Exception(
Exception: Job in error state.. tool_id: __DATA_FETCH__, exit_code: None, stderr: .
"><![CDATA[
                { "execution_problem": "Input staging problem: Traceback (most recent call last):\n  File \"/opt/hostedtoolcache/Python/3.12.11/x64/lib/python3.12/site-packages/galaxy/tool_util/verify/interactor.py\", line 1436, in verify_tool\n    stage_data_in_history(\n  File \"/opt/hostedtoolcache/Python/3.12.11/x64/lib/python3.12/site-packages/galaxy/tool_util/verify/interactor.py\", line 175, in stage_data_in_history\n    staging_interface.handle_jobs()\n  File \"/opt/hostedtoolcache/Python/3.12.11/x64/lib/python3.12/site-packages/galaxy/tool_util/verify/interactor.py\", line 212, in handle_jobs\n    self.galaxy_interactor.wait_for_job(job_response[\"id\"], job_response[\"history_id\"], self.maxseconds)\n  File \"/opt/hostedtoolcache/Python/3.12.11/x64/lib/python3.12/site-packages/galaxy/tool_util/verify/interactor.py\", line 399, in wait_for_job\n    self.wait_for(lambda: self.__job_ready(job_id, history_id), maxseconds=maxseconds)\n  File \"/opt/hostedtoolcache/Python/3.12.11/x64/lib/python3.12/site-packages/galaxy/tool_util/verify/interactor.py\", line 403, in wait_for\n    wait_on(func, what, walltime_exceeded)\n  File \"/opt/hostedtoolcache/Python/3.12.11/x64/lib/python3.12/site-packages/galaxy/tool_util/verify/wait.py\", line 38, in wait_on\n    value = function()\n            ^^^^^^^^^^\n  File \"/opt/hostedtoolcache/Python/3.12.11/x64/lib/python3.12/site-packages/galaxy/tool_util/verify/interactor.py\", line 399, in \u003clambda\u003e\n    self.wait_for(lambda: self.__job_ready(job_id, history_id), maxseconds=maxseconds)\n                          ^^^^^^^^^^^^^^^^^^^^^^^^^^^^^^^^^^^^\n  File \"/opt/hostedtoolcache/Python/3.12.11/x64/lib/python3.12/site-packages/galaxy/tool_util/verify/interactor.py\", line 749, in __job_ready\n    return self._state_ready(job_id, error_msg=\"Job in error state.\")\n           ^^^^^^^^^^^^^^^^^^^^^^^^^^^^^^^^^^^^^^^^^^^^^^^^^^^^^^^^^^\n  File \"/opt/hostedtoolcache/Python/3.12.11/x64/lib/python3.12/site-packages/galaxy/tool_util/verify/interactor.py\", line 841, in _state_ready\n    raise Exception(\nException: Job in error state.. tool_id: __DATA_FETCH__, exit_code: None, stderr: .\n", "status": "error", "test_index": 2, "time_seconds": 22.562655925750732, "tool_id": "bcftools_convert_to_vcf", "tool_version": "1.15.1+galaxy4"}
            ]]></error>
        
    </testcase>
    
    <testcase classname="bcftools_convert_to_vcf (Test #4)" name="3" time="38.46791982650757">
        
            
            <system-out><![CDATA[
            
            ]]></system-out>
            <system-err><![CDATA[
            
            ]]></system-err>
        
    </testcase>
    
    <testcase classname="bcftools_convert_to_vcf (Test #5)" name="4" time="">
        
            <error type="error" message=""><![CDATA[
                { "status": "skip", "test_index": 4, "tool_id": "bcftools_convert_to_vcf", "tool_version": "1.15.1+galaxy4"}
            ]]></error>
        
    </testcase>
    
    <testcase classname="bcftools_convert_to_vcf (Test #6)" name="5" time="38.2630033493042">
        
            
            <system-out><![CDATA[
            
            ]]></system-out>
            <system-err><![CDATA[
            Rows total: 27Rows skipped: 0Missing GTs: 1Hom RR: 14Het RA: 7Hom AA: 5Het AA: 0
            ]]></system-err>
        
    </testcase>
    
    <testcase classname="bcftools_convert_to_vcf (Test #7)" name="6" time="">
        
            <error type="error" message=""><![CDATA[
                { "status": "skip", "test_index": 6, "tool_id": "bcftools_convert_to_vcf", "tool_version": "1.15.1+galaxy4"}
            ]]></error>
        
    </testcase>
    
    <testcase classname="bcftools_plugin_fill_an_ac (Test #1)" name="0" time="44.176509380340576">
        
            
            <system-out><![CDATA[
            
            ]]></system-out>
            <system-err><![CDATA[
            
            ]]></system-err>
        
    </testcase>
    
    <testcase classname="collection_column_join (Test #1)" name="0" time="30.401469945907593">
        
            <error type="error" message="Input staging problem: Traceback (most recent call last):
  File "/opt/hostedtoolcache/Python/3.12.11/x64/lib/python3.12/site-packages/galaxy/tool_util/verify/interactor.py", line 1436, in verify_tool
    stage_data_in_history(
  File "/opt/hostedtoolcache/Python/3.12.11/x64/lib/python3.12/site-packages/galaxy/tool_util/verify/interactor.py", line 175, in stage_data_in_history
    staging_interface.handle_jobs()
  File "/opt/hostedtoolcache/Python/3.12.11/x64/lib/python3.12/site-packages/galaxy/tool_util/verify/interactor.py", line 212, in handle_jobs
    self.galaxy_interactor.wait_for_job(job_response["id"], job_response["history_id"], self.maxseconds)
  File "/opt/hostedtoolcache/Python/3.12.11/x64/lib/python3.12/site-packages/galaxy/tool_util/verify/interactor.py", line 399, in wait_for_job
    self.wait_for(lambda: self.__job_ready(job_id, history_id), maxseconds=maxseconds)
  File "/opt/hostedtoolcache/Python/3.12.11/x64/lib/python3.12/site-packages/galaxy/tool_util/verify/interactor.py", line 403, in wait_for
    wait_on(func, what, walltime_exceeded)
  File "/opt/hostedtoolcache/Python/3.12.11/x64/lib/python3.12/site-packages/galaxy/tool_util/verify/wait.py", line 38, in wait_on
    value = function()
            ^^^^^^^^^^
  File "/opt/hostedtoolcache/Python/3.12.11/x64/lib/python3.12/site-packages/galaxy/tool_util/verify/interactor.py", line 399, in <lambda>
    self.wait_for(lambda: self.__job_ready(job_id, history_id), maxseconds=maxseconds)
                          ^^^^^^^^^^^^^^^^^^^^^^^^^^^^^^^^^^^^
  File "/opt/hostedtoolcache/Python/3.12.11/x64/lib/python3.12/site-packages/galaxy/tool_util/verify/interactor.py", line 749, in __job_ready
    return self._state_ready(job_id, error_msg="Job in error state.")
           ^^^^^^^^^^^^^^^^^^^^^^^^^^^^^^^^^^^^^^^^^^^^^^^^^^^^^^^^^^
  File "/opt/hostedtoolcache/Python/3.12.11/x64/lib/python3.12/site-packages/galaxy/tool_util/verify/interactor.py", line 841, in _state_ready
    raise Exception(
Exception: Job in error state.. tool_id: __DATA_FETCH__, exit_code: None, stderr: .
"><![CDATA[
                { "execution_problem": "Input staging problem: Traceback (most recent call last):\n  File \"/opt/hostedtoolcache/Python/3.12.11/x64/lib/python3.12/site-packages/galaxy/tool_util/verify/interactor.py\", line 1436, in verify_tool\n    stage_data_in_history(\n  File \"/opt/hostedtoolcache/Python/3.12.11/x64/lib/python3.12/site-packages/galaxy/tool_util/verify/interactor.py\", line 175, in stage_data_in_history\n    staging_interface.handle_jobs()\n  File \"/opt/hostedtoolcache/Python/3.12.11/x64/lib/python3.12/site-packages/galaxy/tool_util/verify/interactor.py\", line 212, in handle_jobs\n    self.galaxy_interactor.wait_for_job(job_response[\"id\"], job_response[\"history_id\"], self.maxseconds)\n  File \"/opt/hostedtoolcache/Python/3.12.11/x64/lib/python3.12/site-packages/galaxy/tool_util/verify/interactor.py\", line 399, in wait_for_job\n    self.wait_for(lambda: self.__job_ready(job_id, history_id), maxseconds=maxseconds)\n  File \"/opt/hostedtoolcache/Python/3.12.11/x64/lib/python3.12/site-packages/galaxy/tool_util/verify/interactor.py\", line 403, in wait_for\n    wait_on(func, what, walltime_exceeded)\n  File \"/opt/hostedtoolcache/Python/3.12.11/x64/lib/python3.12/site-packages/galaxy/tool_util/verify/wait.py\", line 38, in wait_on\n    value = function()\n            ^^^^^^^^^^\n  File \"/opt/hostedtoolcache/Python/3.12.11/x64/lib/python3.12/site-packages/galaxy/tool_util/verify/interactor.py\", line 399, in \u003clambda\u003e\n    self.wait_for(lambda: self.__job_ready(job_id, history_id), maxseconds=maxseconds)\n                          ^^^^^^^^^^^^^^^^^^^^^^^^^^^^^^^^^^^^\n  File \"/opt/hostedtoolcache/Python/3.12.11/x64/lib/python3.12/site-packages/galaxy/tool_util/verify/interactor.py\", line 749, in __job_ready\n    return self._state_ready(job_id, error_msg=\"Job in error state.\")\n           ^^^^^^^^^^^^^^^^^^^^^^^^^^^^^^^^^^^^^^^^^^^^^^^^^^^^^^^^^^\n  File \"/opt/hostedtoolcache/Python/3.12.11/x64/lib/python3.12/site-packages/galaxy/tool_util/verify/interactor.py\", line 841, in _state_ready\n    raise Exception(\nException: Job in error state.. tool_id: __DATA_FETCH__, exit_code: None, stderr: .\n", "status": "error", "test_index": 0, "time_seconds": 30.401469945907593, "tool_id": "collection_column_join", "tool_version": "0.0.3"}
            ]]></error>
        
    </testcase>
    
    <testcase classname="collection_column_join (Test #2)" name="1" time="13.849914073944092">
        
            <error type="error" message="Input staging problem: Traceback (most recent call last):
  File "/opt/hostedtoolcache/Python/3.12.11/x64/lib/python3.12/site-packages/galaxy/tool_util/verify/interactor.py", line 1436, in verify_tool
    stage_data_in_history(
  File "/opt/hostedtoolcache/Python/3.12.11/x64/lib/python3.12/site-packages/galaxy/tool_util/verify/interactor.py", line 175, in stage_data_in_history
    staging_interface.handle_jobs()
  File "/opt/hostedtoolcache/Python/3.12.11/x64/lib/python3.12/site-packages/galaxy/tool_util/verify/interactor.py", line 212, in handle_jobs
    self.galaxy_interactor.wait_for_job(job_response["id"], job_response["history_id"], self.maxseconds)
  File "/opt/hostedtoolcache/Python/3.12.11/x64/lib/python3.12/site-packages/galaxy/tool_util/verify/interactor.py", line 399, in wait_for_job
    self.wait_for(lambda: self.__job_ready(job_id, history_id), maxseconds=maxseconds)
  File "/opt/hostedtoolcache/Python/3.12.11/x64/lib/python3.12/site-packages/galaxy/tool_util/verify/interactor.py", line 403, in wait_for
    wait_on(func, what, walltime_exceeded)
  File "/opt/hostedtoolcache/Python/3.12.11/x64/lib/python3.12/site-packages/galaxy/tool_util/verify/wait.py", line 38, in wait_on
    value = function()
            ^^^^^^^^^^
  File "/opt/hostedtoolcache/Python/3.12.11/x64/lib/python3.12/site-packages/galaxy/tool_util/verify/interactor.py", line 399, in <lambda>
    self.wait_for(lambda: self.__job_ready(job_id, history_id), maxseconds=maxseconds)
                          ^^^^^^^^^^^^^^^^^^^^^^^^^^^^^^^^^^^^
  File "/opt/hostedtoolcache/Python/3.12.11/x64/lib/python3.12/site-packages/galaxy/tool_util/verify/interactor.py", line 749, in __job_ready
    return self._state_ready(job_id, error_msg="Job in error state.")
           ^^^^^^^^^^^^^^^^^^^^^^^^^^^^^^^^^^^^^^^^^^^^^^^^^^^^^^^^^^
  File "/opt/hostedtoolcache/Python/3.12.11/x64/lib/python3.12/site-packages/galaxy/tool_util/verify/interactor.py", line 841, in _state_ready
    raise Exception(
Exception: Job in error state.. tool_id: __DATA_FETCH__, exit_code: None, stderr: .
"><![CDATA[
                { "execution_problem": "Input staging problem: Traceback (most recent call last):\n  File \"/opt/hostedtoolcache/Python/3.12.11/x64/lib/python3.12/site-packages/galaxy/tool_util/verify/interactor.py\", line 1436, in verify_tool\n    stage_data_in_history(\n  File \"/opt/hostedtoolcache/Python/3.12.11/x64/lib/python3.12/site-packages/galaxy/tool_util/verify/interactor.py\", line 175, in stage_data_in_history\n    staging_interface.handle_jobs()\n  File \"/opt/hostedtoolcache/Python/3.12.11/x64/lib/python3.12/site-packages/galaxy/tool_util/verify/interactor.py\", line 212, in handle_jobs\n    self.galaxy_interactor.wait_for_job(job_response[\"id\"], job_response[\"history_id\"], self.maxseconds)\n  File \"/opt/hostedtoolcache/Python/3.12.11/x64/lib/python3.12/site-packages/galaxy/tool_util/verify/interactor.py\", line 399, in wait_for_job\n    self.wait_for(lambda: self.__job_ready(job_id, history_id), maxseconds=maxseconds)\n  File \"/opt/hostedtoolcache/Python/3.12.11/x64/lib/python3.12/site-packages/galaxy/tool_util/verify/interactor.py\", line 403, in wait_for\n    wait_on(func, what, walltime_exceeded)\n  File \"/opt/hostedtoolcache/Python/3.12.11/x64/lib/python3.12/site-packages/galaxy/tool_util/verify/wait.py\", line 38, in wait_on\n    value = function()\n            ^^^^^^^^^^\n  File \"/opt/hostedtoolcache/Python/3.12.11/x64/lib/python3.12/site-packages/galaxy/tool_util/verify/interactor.py\", line 399, in \u003clambda\u003e\n    self.wait_for(lambda: self.__job_ready(job_id, history_id), maxseconds=maxseconds)\n                          ^^^^^^^^^^^^^^^^^^^^^^^^^^^^^^^^^^^^\n  File \"/opt/hostedtoolcache/Python/3.12.11/x64/lib/python3.12/site-packages/galaxy/tool_util/verify/interactor.py\", line 749, in __job_ready\n    return self._state_ready(job_id, error_msg=\"Job in error state.\")\n           ^^^^^^^^^^^^^^^^^^^^^^^^^^^^^^^^^^^^^^^^^^^^^^^^^^^^^^^^^^\n  File \"/opt/hostedtoolcache/Python/3.12.11/x64/lib/python3.12/site-packages/galaxy/tool_util/verify/interactor.py\", line 841, in _state_ready\n    raise Exception(\nException: Job in error state.. tool_id: __DATA_FETCH__, exit_code: None, stderr: .\n", "status": "error", "test_index": 1, "time_seconds": 13.849914073944092, "tool_id": "collection_column_join", "tool_version": "0.0.3"}
            ]]></error>
        
    </testcase>
    
    <testcase classname="collection_column_join (Test #3)" name="2" time="88.32331442832947">
        
            
            <system-out><![CDATA[
            
            ]]></system-out>
            <system-err><![CDATA[
            
            ]]></system-err>
        
    </testcase>
    
    <testcase classname="collection_column_join (Test #4)" name="3" time="43.337318897247314">
        
            
            <system-out><![CDATA[
            
            ]]></system-out>
            <system-err><![CDATA[
            
            ]]></system-err>
        
    </testcase>
    
    <testcase classname="deeptools_plot_coverage (Test #1)" name="0" time="13.534191846847534">
        
            <error type="error" message="Input staging problem: Traceback (most recent call last):
  File "/opt/hostedtoolcache/Python/3.12.11/x64/lib/python3.12/site-packages/galaxy/tool_util/verify/interactor.py", line 1436, in verify_tool
    stage_data_in_history(
  File "/opt/hostedtoolcache/Python/3.12.11/x64/lib/python3.12/site-packages/galaxy/tool_util/verify/interactor.py", line 175, in stage_data_in_history
    staging_interface.handle_jobs()
  File "/opt/hostedtoolcache/Python/3.12.11/x64/lib/python3.12/site-packages/galaxy/tool_util/verify/interactor.py", line 212, in handle_jobs
    self.galaxy_interactor.wait_for_job(job_response["id"], job_response["history_id"], self.maxseconds)
  File "/opt/hostedtoolcache/Python/3.12.11/x64/lib/python3.12/site-packages/galaxy/tool_util/verify/interactor.py", line 399, in wait_for_job
    self.wait_for(lambda: self.__job_ready(job_id, history_id), maxseconds=maxseconds)
  File "/opt/hostedtoolcache/Python/3.12.11/x64/lib/python3.12/site-packages/galaxy/tool_util/verify/interactor.py", line 403, in wait_for
    wait_on(func, what, walltime_exceeded)
  File "/opt/hostedtoolcache/Python/3.12.11/x64/lib/python3.12/site-packages/galaxy/tool_util/verify/wait.py", line 38, in wait_on
    value = function()
            ^^^^^^^^^^
  File "/opt/hostedtoolcache/Python/3.12.11/x64/lib/python3.12/site-packages/galaxy/tool_util/verify/interactor.py", line 399, in <lambda>
    self.wait_for(lambda: self.__job_ready(job_id, history_id), maxseconds=maxseconds)
                          ^^^^^^^^^^^^^^^^^^^^^^^^^^^^^^^^^^^^
  File "/opt/hostedtoolcache/Python/3.12.11/x64/lib/python3.12/site-packages/galaxy/tool_util/verify/interactor.py", line 749, in __job_ready
    return self._state_ready(job_id, error_msg="Job in error state.")
           ^^^^^^^^^^^^^^^^^^^^^^^^^^^^^^^^^^^^^^^^^^^^^^^^^^^^^^^^^^
  File "/opt/hostedtoolcache/Python/3.12.11/x64/lib/python3.12/site-packages/galaxy/tool_util/verify/interactor.py", line 841, in _state_ready
    raise Exception(
Exception: Job in error state.. tool_id: __DATA_FETCH__, exit_code: None, stderr: .
"><![CDATA[
                { "execution_problem": "Input staging problem: Traceback (most recent call last):\n  File \"/opt/hostedtoolcache/Python/3.12.11/x64/lib/python3.12/site-packages/galaxy/tool_util/verify/interactor.py\", line 1436, in verify_tool\n    stage_data_in_history(\n  File \"/opt/hostedtoolcache/Python/3.12.11/x64/lib/python3.12/site-packages/galaxy/tool_util/verify/interactor.py\", line 175, in stage_data_in_history\n    staging_interface.handle_jobs()\n  File \"/opt/hostedtoolcache/Python/3.12.11/x64/lib/python3.12/site-packages/galaxy/tool_util/verify/interactor.py\", line 212, in handle_jobs\n    self.galaxy_interactor.wait_for_job(job_response[\"id\"], job_response[\"history_id\"], self.maxseconds)\n  File \"/opt/hostedtoolcache/Python/3.12.11/x64/lib/python3.12/site-packages/galaxy/tool_util/verify/interactor.py\", line 399, in wait_for_job\n    self.wait_for(lambda: self.__job_ready(job_id, history_id), maxseconds=maxseconds)\n  File \"/opt/hostedtoolcache/Python/3.12.11/x64/lib/python3.12/site-packages/galaxy/tool_util/verify/interactor.py\", line 403, in wait_for\n    wait_on(func, what, walltime_exceeded)\n  File \"/opt/hostedtoolcache/Python/3.12.11/x64/lib/python3.12/site-packages/galaxy/tool_util/verify/wait.py\", line 38, in wait_on\n    value = function()\n            ^^^^^^^^^^\n  File \"/opt/hostedtoolcache/Python/3.12.11/x64/lib/python3.12/site-packages/galaxy/tool_util/verify/interactor.py\", line 399, in \u003clambda\u003e\n    self.wait_for(lambda: self.__job_ready(job_id, history_id), maxseconds=maxseconds)\n                          ^^^^^^^^^^^^^^^^^^^^^^^^^^^^^^^^^^^^\n  File \"/opt/hostedtoolcache/Python/3.12.11/x64/lib/python3.12/site-packages/galaxy/tool_util/verify/interactor.py\", line 749, in __job_ready\n    return self._state_ready(job_id, error_msg=\"Job in error state.\")\n           ^^^^^^^^^^^^^^^^^^^^^^^^^^^^^^^^^^^^^^^^^^^^^^^^^^^^^^^^^^\n  File \"/opt/hostedtoolcache/Python/3.12.11/x64/lib/python3.12/site-packages/galaxy/tool_util/verify/interactor.py\", line 841, in _state_ready\n    raise Exception(\nException: Job in error state.. tool_id: __DATA_FETCH__, exit_code: None, stderr: .\n", "status": "error", "test_index": 0, "time_seconds": 13.534191846847534, "tool_id": "deeptools_plot_coverage", "tool_version": "3.5.4+galaxy0"}
            ]]></error>
        
    </testcase>
    
    <testcase classname="deeptools_plot_coverage (Test #2)" name="1" time="62.0747275352478">
        
            
            <system-out><![CDATA[
            samplemeanstdmin25%50%75%maxbowtie2 test1.bam0.504.1000.00.00.035bowtie2 test1.bam0.504.1000.00.00.035
            ]]></system-out>
            <system-err><![CDATA[
            
            ]]></system-err>
        
    </testcase>
    
    <testcase classname="fastq_paired_end_interlacer (Test #1)" name="0" time="12.725717544555664">
        
            <error type="error" message="Input staging problem: Traceback (most recent call last):
  File "/opt/hostedtoolcache/Python/3.12.11/x64/lib/python3.12/site-packages/galaxy/tool_util/verify/interactor.py", line 1436, in verify_tool
    stage_data_in_history(
  File "/opt/hostedtoolcache/Python/3.12.11/x64/lib/python3.12/site-packages/galaxy/tool_util/verify/interactor.py", line 175, in stage_data_in_history
    staging_interface.handle_jobs()
  File "/opt/hostedtoolcache/Python/3.12.11/x64/lib/python3.12/site-packages/galaxy/tool_util/verify/interactor.py", line 212, in handle_jobs
    self.galaxy_interactor.wait_for_job(job_response["id"], job_response["history_id"], self.maxseconds)
  File "/opt/hostedtoolcache/Python/3.12.11/x64/lib/python3.12/site-packages/galaxy/tool_util/verify/interactor.py", line 399, in wait_for_job
    self.wait_for(lambda: self.__job_ready(job_id, history_id), maxseconds=maxseconds)
  File "/opt/hostedtoolcache/Python/3.12.11/x64/lib/python3.12/site-packages/galaxy/tool_util/verify/interactor.py", line 403, in wait_for
    wait_on(func, what, walltime_exceeded)
  File "/opt/hostedtoolcache/Python/3.12.11/x64/lib/python3.12/site-packages/galaxy/tool_util/verify/wait.py", line 38, in wait_on
    value = function()
            ^^^^^^^^^^
  File "/opt/hostedtoolcache/Python/3.12.11/x64/lib/python3.12/site-packages/galaxy/tool_util/verify/interactor.py", line 399, in <lambda>
    self.wait_for(lambda: self.__job_ready(job_id, history_id), maxseconds=maxseconds)
                          ^^^^^^^^^^^^^^^^^^^^^^^^^^^^^^^^^^^^
  File "/opt/hostedtoolcache/Python/3.12.11/x64/lib/python3.12/site-packages/galaxy/tool_util/verify/interactor.py", line 749, in __job_ready
    return self._state_ready(job_id, error_msg="Job in error state.")
           ^^^^^^^^^^^^^^^^^^^^^^^^^^^^^^^^^^^^^^^^^^^^^^^^^^^^^^^^^^
  File "/opt/hostedtoolcache/Python/3.12.11/x64/lib/python3.12/site-packages/galaxy/tool_util/verify/interactor.py", line 841, in _state_ready
    raise Exception(
Exception: Job in error state.. tool_id: __DATA_FETCH__, exit_code: None, stderr: .
"><![CDATA[
                { "execution_problem": "Input staging problem: Traceback (most recent call last):\n  File \"/opt/hostedtoolcache/Python/3.12.11/x64/lib/python3.12/site-packages/galaxy/tool_util/verify/interactor.py\", line 1436, in verify_tool\n    stage_data_in_history(\n  File \"/opt/hostedtoolcache/Python/3.12.11/x64/lib/python3.12/site-packages/galaxy/tool_util/verify/interactor.py\", line 175, in stage_data_in_history\n    staging_interface.handle_jobs()\n  File \"/opt/hostedtoolcache/Python/3.12.11/x64/lib/python3.12/site-packages/galaxy/tool_util/verify/interactor.py\", line 212, in handle_jobs\n    self.galaxy_interactor.wait_for_job(job_response[\"id\"], job_response[\"history_id\"], self.maxseconds)\n  File \"/opt/hostedtoolcache/Python/3.12.11/x64/lib/python3.12/site-packages/galaxy/tool_util/verify/interactor.py\", line 399, in wait_for_job\n    self.wait_for(lambda: self.__job_ready(job_id, history_id), maxseconds=maxseconds)\n  File \"/opt/hostedtoolcache/Python/3.12.11/x64/lib/python3.12/site-packages/galaxy/tool_util/verify/interactor.py\", line 403, in wait_for\n    wait_on(func, what, walltime_exceeded)\n  File \"/opt/hostedtoolcache/Python/3.12.11/x64/lib/python3.12/site-packages/galaxy/tool_util/verify/wait.py\", line 38, in wait_on\n    value = function()\n            ^^^^^^^^^^\n  File \"/opt/hostedtoolcache/Python/3.12.11/x64/lib/python3.12/site-packages/galaxy/tool_util/verify/interactor.py\", line 399, in \u003clambda\u003e\n    self.wait_for(lambda: self.__job_ready(job_id, history_id), maxseconds=maxseconds)\n                          ^^^^^^^^^^^^^^^^^^^^^^^^^^^^^^^^^^^^\n  File \"/opt/hostedtoolcache/Python/3.12.11/x64/lib/python3.12/site-packages/galaxy/tool_util/verify/interactor.py\", line 749, in __job_ready\n    return self._state_ready(job_id, error_msg=\"Job in error state.\")\n           ^^^^^^^^^^^^^^^^^^^^^^^^^^^^^^^^^^^^^^^^^^^^^^^^^^^^^^^^^^\n  File \"/opt/hostedtoolcache/Python/3.12.11/x64/lib/python3.12/site-packages/galaxy/tool_util/verify/interactor.py\", line 841, in _state_ready\n    raise Exception(\nException: Job in error state.. tool_id: __DATA_FETCH__, exit_code: None, stderr: .\n", "status": "error", "test_index": 0, "time_seconds": 12.725717544555664, "tool_id": "fastq_paired_end_interlacer", "tool_version": "1.2.0.1+galaxy0"}
            ]]></error>
        
    </testcase>
    
    <testcase classname="fastq_paired_end_interlacer (Test #2)" name="1" time="48.413060903549194">
        
            
            <system-out><![CDATA[
            There were 4 single reads.Interlaced 3 pairs of sequences.
            ]]></system-out>
            <system-err><![CDATA[
            
            ]]></system-err>
        
    </testcase>
    
    <testcase classname="fastq_paired_end_interlacer (Test #3)" name="2" time="23.361079216003418">
        
            <error type="error" message="Input staging problem: Traceback (most recent call last):
  File "/opt/hostedtoolcache/Python/3.12.11/x64/lib/python3.12/site-packages/galaxy/tool_util/verify/interactor.py", line 1436, in verify_tool
    stage_data_in_history(
  File "/opt/hostedtoolcache/Python/3.12.11/x64/lib/python3.12/site-packages/galaxy/tool_util/verify/interactor.py", line 175, in stage_data_in_history
    staging_interface.handle_jobs()
  File "/opt/hostedtoolcache/Python/3.12.11/x64/lib/python3.12/site-packages/galaxy/tool_util/verify/interactor.py", line 212, in handle_jobs
    self.galaxy_interactor.wait_for_job(job_response["id"], job_response["history_id"], self.maxseconds)
  File "/opt/hostedtoolcache/Python/3.12.11/x64/lib/python3.12/site-packages/galaxy/tool_util/verify/interactor.py", line 399, in wait_for_job
    self.wait_for(lambda: self.__job_ready(job_id, history_id), maxseconds=maxseconds)
  File "/opt/hostedtoolcache/Python/3.12.11/x64/lib/python3.12/site-packages/galaxy/tool_util/verify/interactor.py", line 403, in wait_for
    wait_on(func, what, walltime_exceeded)
  File "/opt/hostedtoolcache/Python/3.12.11/x64/lib/python3.12/site-packages/galaxy/tool_util/verify/wait.py", line 38, in wait_on
    value = function()
            ^^^^^^^^^^
  File "/opt/hostedtoolcache/Python/3.12.11/x64/lib/python3.12/site-packages/galaxy/tool_util/verify/interactor.py", line 399, in <lambda>
    self.wait_for(lambda: self.__job_ready(job_id, history_id), maxseconds=maxseconds)
                          ^^^^^^^^^^^^^^^^^^^^^^^^^^^^^^^^^^^^
  File "/opt/hostedtoolcache/Python/3.12.11/x64/lib/python3.12/site-packages/galaxy/tool_util/verify/interactor.py", line 749, in __job_ready
    return self._state_ready(job_id, error_msg="Job in error state.")
           ^^^^^^^^^^^^^^^^^^^^^^^^^^^^^^^^^^^^^^^^^^^^^^^^^^^^^^^^^^
  File "/opt/hostedtoolcache/Python/3.12.11/x64/lib/python3.12/site-packages/galaxy/tool_util/verify/interactor.py", line 841, in _state_ready
    raise Exception(
Exception: Job in error state.. tool_id: __DATA_FETCH__, exit_code: None, stderr: .
"><![CDATA[
                { "execution_problem": "Input staging problem: Traceback (most recent call last):\n  File \"/opt/hostedtoolcache/Python/3.12.11/x64/lib/python3.12/site-packages/galaxy/tool_util/verify/interactor.py\", line 1436, in verify_tool\n    stage_data_in_history(\n  File \"/opt/hostedtoolcache/Python/3.12.11/x64/lib/python3.12/site-packages/galaxy/tool_util/verify/interactor.py\", line 175, in stage_data_in_history\n    staging_interface.handle_jobs()\n  File \"/opt/hostedtoolcache/Python/3.12.11/x64/lib/python3.12/site-packages/galaxy/tool_util/verify/interactor.py\", line 212, in handle_jobs\n    self.galaxy_interactor.wait_for_job(job_response[\"id\"], job_response[\"history_id\"], self.maxseconds)\n  File \"/opt/hostedtoolcache/Python/3.12.11/x64/lib/python3.12/site-packages/galaxy/tool_util/verify/interactor.py\", line 399, in wait_for_job\n    self.wait_for(lambda: self.__job_ready(job_id, history_id), maxseconds=maxseconds)\n  File \"/opt/hostedtoolcache/Python/3.12.11/x64/lib/python3.12/site-packages/galaxy/tool_util/verify/interactor.py\", line 403, in wait_for\n    wait_on(func, what, walltime_exceeded)\n  File \"/opt/hostedtoolcache/Python/3.12.11/x64/lib/python3.12/site-packages/galaxy/tool_util/verify/wait.py\", line 38, in wait_on\n    value = function()\n            ^^^^^^^^^^\n  File \"/opt/hostedtoolcache/Python/3.12.11/x64/lib/python3.12/site-packages/galaxy/tool_util/verify/interactor.py\", line 399, in \u003clambda\u003e\n    self.wait_for(lambda: self.__job_ready(job_id, history_id), maxseconds=maxseconds)\n                          ^^^^^^^^^^^^^^^^^^^^^^^^^^^^^^^^^^^^\n  File \"/opt/hostedtoolcache/Python/3.12.11/x64/lib/python3.12/site-packages/galaxy/tool_util/verify/interactor.py\", line 749, in __job_ready\n    return self._state_ready(job_id, error_msg=\"Job in error state.\")\n           ^^^^^^^^^^^^^^^^^^^^^^^^^^^^^^^^^^^^^^^^^^^^^^^^^^^^^^^^^^\n  File \"/opt/hostedtoolcache/Python/3.12.11/x64/lib/python3.12/site-packages/galaxy/tool_util/verify/interactor.py\", line 841, in _state_ready\n    raise Exception(\nException: Job in error state.. tool_id: __DATA_FETCH__, exit_code: None, stderr: .\n", "status": "error", "test_index": 2, "time_seconds": 23.361079216003418, "tool_id": "fastq_paired_end_interlacer", "tool_version": "1.2.0.1+galaxy0"}
            ]]></error>
        
    </testcase>
    
    <testcase classname="fastq_paired_end_interlacer (Test #4)" name="3" time="30.056954860687256">
        
            
                <error type="error" message="Tool exit code: None"><![CDATA[
                    { "inputs": {  "reads|input1_file": {   "id": "3a75e7bd62a25aea",   "src": "hda"  },  "reads|input2_file": {   "id": "5f351c6b8349b880",   "src": "hda"  },  "reads|reads_selector": "paired" }, "job": {  "command_line": "gx-fastq-paired-end-interlacer \u0027/galaxy/server/database/objects/a/0/8/dataset_a08c2221-c619-4cf9-ae2d-a73e3850e02d.dat\u0027 sanger.bz2 \u0027/galaxy/server/database/objects/b/d/d/dataset_bdd967ab-2bf9-4d19-8197-696a1c2136f0.dat\u0027 sanger.bz2 \u0027/galaxy/server/database/objects/6/0/d/dataset_60df94c4-b7c6-4c00-92ba-07d7f0fb9904.dat\u0027 \u0027/galaxy/server/database/objects/6/3/e/dataset_63ef4897-adc1-40b3-9b57-930edbbb64da.dat\u0027",  "command_version": null,  "copied_from_job_id": null,  "create_time": "2025-07-09T13:07:26.386483",  "dependencies": [],  "exit_code": null,  "external_id": "gxy-2glsx",  "galaxy_version": "24.1",  "handler": null,  "history_id": "de5ddda094177f64",  "id": "5f351c6b8349b880",  "inputs": {   "reads|input1_file": {    "id": "3a75e7bd62a25aea",    "src": "hda",    "uuid": "a08c2221-c619-4cf9-ae2d-a73e3850e02d"   },   "reads|input2_file": {    "id": "5f351c6b8349b880",    "src": "hda",    "uuid": "bdd967ab-2bf9-4d19-8197-696a1c2136f0"   }  },  "job_messages": null,  "job_metrics": [],  "job_runner_name": null,  "job_stderr": null,  "job_stdout": null,  "model_class": "Job",  "output_collections": {},  "outputs": {   "outfile_pairs": {    "id": "f9abb38c49e1be49",    "src": "hda",    "uuid": "60df94c4-b7c6-4c00-92ba-07d7f0fb9904"   },   "outfile_singles": {    "id": "2ee66a054d150f00",    "src": "hda",    "uuid": "63ef4897-adc1-40b3-9b57-930edbbb64da"   }  },  "params": {   "__input_ext": "\"fastqsanger.bz2\"",   "chromInfo": "\"/cvmfs/data.galaxyproject.org/managed/len/ucsc/?.len\"",   "dbkey": "\"?\"",   "reads": "{\"__current_case__\": 0, \"input1_file\": {\"values\": [{\"id\": 26, \"src\": \"hda\"}]}, \"input2_file\": {\"values\": [{\"id\": 27, \"src\": \"hda\"}]}, \"reads_selector\": \"paired\"}"  },  "state": "error",  "stderr": "",  "stdout": "There were 4 single reads.\nInterlaced 3 pairs of sequences.\n",  "tool_id": "toolshed.g2.bx.psu.edu/repos/devteam/fastq_paired_end_interlacer/fastq_paired_end_interlacer/1.2.0.1+galaxy0",  "tool_stderr": "",  "tool_stdout": "There were 4 single reads.\nInterlaced 3 pairs of sequences.\n",  "update_time": "2025-07-09T13:07:31.467328",  "user_email": "tests@fake.org" }, "output_problems": [  "Job in error state.. tool_id: toolshed.g2.bx.psu.edu/repos/devteam/fastq_paired_end_interlacer/fastq_paired_end_interlacer/1.2.0.1+galaxy0, exit_code: None, stderr: .",  "Job in error state.. tool_id: toolshed.g2.bx.psu.edu/repos/devteam/fastq_paired_end_interlacer/fastq_paired_end_interlacer/1.2.0.1+galaxy0, exit_code: None, stderr: .",  "Job in error state.. tool_id: toolshed.g2.bx.psu.edu/repos/devteam/fastq_paired_end_interlacer/fastq_paired_end_interlacer/1.2.0.1+galaxy0, exit_code: None, stderr: ." ], "status": "failure", "test_index": 3, "time_seconds": 30.056954860687256, "tool_id": "fastq_paired_end_interlacer", "tool_version": "1.2.0.1+galaxy0"}
                ]]></error>
            
            <system-out><![CDATA[
            There were 4 single reads.Interlaced 3 pairs of sequences.
            ]]></system-out>
            <system-err><![CDATA[
            
            ]]></system-err>
        
    </testcase>
    
    <testcase classname="fastq_paired_end_interlacer (Test #5)" name="4" time="40.219364166259766">
        
            
            <system-out><![CDATA[
            There were 0 single reads.Interlaced 5 pairs of sequences.
            ]]></system-out>
            <system-err><![CDATA[
            
            ]]></system-err>
        
    </testcase>
    
    <testcase classname="ivar_consensus (Test #1)" name="0" time="49.81406569480896">
        
            
            <system-out><![CDATA[
            Minimum Quality: 20Threshold: 0Minimum depth: 10Minimum Insert Threshold: 0.8Regions with depth less than minimum depth covered by: NReference length: 29903Positions with 0 depth: 113Positions with depth below 10: 1034
            ]]></system-out>
            <system-err><![CDATA[
            [mpileup] 1 samples in 1 input files[mpileup] Max depth set to maximum value (2147483647)
            ]]></system-err>
        
    </testcase>
    
    <testcase classname="jq (Test #1)" name="0" time="12.50124979019165">
        
            <error type="error" message="Input staging problem: Traceback (most recent call last):
  File "/opt/hostedtoolcache/Python/3.12.11/x64/lib/python3.12/site-packages/galaxy/tool_util/verify/interactor.py", line 1436, in verify_tool
    stage_data_in_history(
  File "/opt/hostedtoolcache/Python/3.12.11/x64/lib/python3.12/site-packages/galaxy/tool_util/verify/interactor.py", line 175, in stage_data_in_history
    staging_interface.handle_jobs()
  File "/opt/hostedtoolcache/Python/3.12.11/x64/lib/python3.12/site-packages/galaxy/tool_util/verify/interactor.py", line 212, in handle_jobs
    self.galaxy_interactor.wait_for_job(job_response["id"], job_response["history_id"], self.maxseconds)
  File "/opt/hostedtoolcache/Python/3.12.11/x64/lib/python3.12/site-packages/galaxy/tool_util/verify/interactor.py", line 399, in wait_for_job
    self.wait_for(lambda: self.__job_ready(job_id, history_id), maxseconds=maxseconds)
  File "/opt/hostedtoolcache/Python/3.12.11/x64/lib/python3.12/site-packages/galaxy/tool_util/verify/interactor.py", line 403, in wait_for
    wait_on(func, what, walltime_exceeded)
  File "/opt/hostedtoolcache/Python/3.12.11/x64/lib/python3.12/site-packages/galaxy/tool_util/verify/wait.py", line 38, in wait_on
    value = function()
            ^^^^^^^^^^
  File "/opt/hostedtoolcache/Python/3.12.11/x64/lib/python3.12/site-packages/galaxy/tool_util/verify/interactor.py", line 399, in <lambda>
    self.wait_for(lambda: self.__job_ready(job_id, history_id), maxseconds=maxseconds)
                          ^^^^^^^^^^^^^^^^^^^^^^^^^^^^^^^^^^^^
  File "/opt/hostedtoolcache/Python/3.12.11/x64/lib/python3.12/site-packages/galaxy/tool_util/verify/interactor.py", line 749, in __job_ready
    return self._state_ready(job_id, error_msg="Job in error state.")
           ^^^^^^^^^^^^^^^^^^^^^^^^^^^^^^^^^^^^^^^^^^^^^^^^^^^^^^^^^^
  File "/opt/hostedtoolcache/Python/3.12.11/x64/lib/python3.12/site-packages/galaxy/tool_util/verify/interactor.py", line 841, in _state_ready
    raise Exception(
Exception: Job in error state.. tool_id: __DATA_FETCH__, exit_code: None, stderr: .
"><![CDATA[
                { "execution_problem": "Input staging problem: Traceback (most recent call last):\n  File \"/opt/hostedtoolcache/Python/3.12.11/x64/lib/python3.12/site-packages/galaxy/tool_util/verify/interactor.py\", line 1436, in verify_tool\n    stage_data_in_history(\n  File \"/opt/hostedtoolcache/Python/3.12.11/x64/lib/python3.12/site-packages/galaxy/tool_util/verify/interactor.py\", line 175, in stage_data_in_history\n    staging_interface.handle_jobs()\n  File \"/opt/hostedtoolcache/Python/3.12.11/x64/lib/python3.12/site-packages/galaxy/tool_util/verify/interactor.py\", line 212, in handle_jobs\n    self.galaxy_interactor.wait_for_job(job_response[\"id\"], job_response[\"history_id\"], self.maxseconds)\n  File \"/opt/hostedtoolcache/Python/3.12.11/x64/lib/python3.12/site-packages/galaxy/tool_util/verify/interactor.py\", line 399, in wait_for_job\n    self.wait_for(lambda: self.__job_ready(job_id, history_id), maxseconds=maxseconds)\n  File \"/opt/hostedtoolcache/Python/3.12.11/x64/lib/python3.12/site-packages/galaxy/tool_util/verify/interactor.py\", line 403, in wait_for\n    wait_on(func, what, walltime_exceeded)\n  File \"/opt/hostedtoolcache/Python/3.12.11/x64/lib/python3.12/site-packages/galaxy/tool_util/verify/wait.py\", line 38, in wait_on\n    value = function()\n            ^^^^^^^^^^\n  File \"/opt/hostedtoolcache/Python/3.12.11/x64/lib/python3.12/site-packages/galaxy/tool_util/verify/interactor.py\", line 399, in \u003clambda\u003e\n    self.wait_for(lambda: self.__job_ready(job_id, history_id), maxseconds=maxseconds)\n                          ^^^^^^^^^^^^^^^^^^^^^^^^^^^^^^^^^^^^\n  File \"/opt/hostedtoolcache/Python/3.12.11/x64/lib/python3.12/site-packages/galaxy/tool_util/verify/interactor.py\", line 749, in __job_ready\n    return self._state_ready(job_id, error_msg=\"Job in error state.\")\n           ^^^^^^^^^^^^^^^^^^^^^^^^^^^^^^^^^^^^^^^^^^^^^^^^^^^^^^^^^^\n  File \"/opt/hostedtoolcache/Python/3.12.11/x64/lib/python3.12/site-packages/galaxy/tool_util/verify/interactor.py\", line 841, in _state_ready\n    raise Exception(\nException: Job in error state.. tool_id: __DATA_FETCH__, exit_code: None, stderr: .\n", "status": "error", "test_index": 0, "time_seconds": 12.50124979019165, "tool_id": "jq", "tool_version": "1.0"}
            ]]></error>
        
    </testcase>
    
    <testcase classname="jq (Test #2)" name="1" time="39.74897909164429">
        
            
            <system-out><![CDATA[
            
            ]]></system-out>
            <system-err><![CDATA[
            
            ]]></system-err>
        
    </testcase>
    
    <testcase classname="medaka_variant_pipeline (Test #1)" name="0" time="">
        
            <error type="error" message=""><![CDATA[
                { "status": "skip", "test_index": 0, "tool_id": "medaka_variant_pipeline", "tool_version": "1.4.4+galaxy1"}
            ]]></error>
        
    </testcase>
    
    <testcase classname="miniasm (Test #1)" name="0" time="23.491780281066895">
        
            <error type="error" message="Input staging problem: Traceback (most recent call last):
  File "/opt/hostedtoolcache/Python/3.12.11/x64/lib/python3.12/site-packages/galaxy/tool_util/verify/interactor.py", line 1436, in verify_tool
    stage_data_in_history(
  File "/opt/hostedtoolcache/Python/3.12.11/x64/lib/python3.12/site-packages/galaxy/tool_util/verify/interactor.py", line 175, in stage_data_in_history
    staging_interface.handle_jobs()
  File "/opt/hostedtoolcache/Python/3.12.11/x64/lib/python3.12/site-packages/galaxy/tool_util/verify/interactor.py", line 212, in handle_jobs
    self.galaxy_interactor.wait_for_job(job_response["id"], job_response["history_id"], self.maxseconds)
  File "/opt/hostedtoolcache/Python/3.12.11/x64/lib/python3.12/site-packages/galaxy/tool_util/verify/interactor.py", line 399, in wait_for_job
    self.wait_for(lambda: self.__job_ready(job_id, history_id), maxseconds=maxseconds)
  File "/opt/hostedtoolcache/Python/3.12.11/x64/lib/python3.12/site-packages/galaxy/tool_util/verify/interactor.py", line 403, in wait_for
    wait_on(func, what, walltime_exceeded)
  File "/opt/hostedtoolcache/Python/3.12.11/x64/lib/python3.12/site-packages/galaxy/tool_util/verify/wait.py", line 38, in wait_on
    value = function()
            ^^^^^^^^^^
  File "/opt/hostedtoolcache/Python/3.12.11/x64/lib/python3.12/site-packages/galaxy/tool_util/verify/interactor.py", line 399, in <lambda>
    self.wait_for(lambda: self.__job_ready(job_id, history_id), maxseconds=maxseconds)
                          ^^^^^^^^^^^^^^^^^^^^^^^^^^^^^^^^^^^^
  File "/opt/hostedtoolcache/Python/3.12.11/x64/lib/python3.12/site-packages/galaxy/tool_util/verify/interactor.py", line 749, in __job_ready
    return self._state_ready(job_id, error_msg="Job in error state.")
           ^^^^^^^^^^^^^^^^^^^^^^^^^^^^^^^^^^^^^^^^^^^^^^^^^^^^^^^^^^
  File "/opt/hostedtoolcache/Python/3.12.11/x64/lib/python3.12/site-packages/galaxy/tool_util/verify/interactor.py", line 841, in _state_ready
    raise Exception(
Exception: Job in error state.. tool_id: __DATA_FETCH__, exit_code: None, stderr: .
"><![CDATA[
                { "execution_problem": "Input staging problem: Traceback (most recent call last):\n  File \"/opt/hostedtoolcache/Python/3.12.11/x64/lib/python3.12/site-packages/galaxy/tool_util/verify/interactor.py\", line 1436, in verify_tool\n    stage_data_in_history(\n  File \"/opt/hostedtoolcache/Python/3.12.11/x64/lib/python3.12/site-packages/galaxy/tool_util/verify/interactor.py\", line 175, in stage_data_in_history\n    staging_interface.handle_jobs()\n  File \"/opt/hostedtoolcache/Python/3.12.11/x64/lib/python3.12/site-packages/galaxy/tool_util/verify/interactor.py\", line 212, in handle_jobs\n    self.galaxy_interactor.wait_for_job(job_response[\"id\"], job_response[\"history_id\"], self.maxseconds)\n  File \"/opt/hostedtoolcache/Python/3.12.11/x64/lib/python3.12/site-packages/galaxy/tool_util/verify/interactor.py\", line 399, in wait_for_job\n    self.wait_for(lambda: self.__job_ready(job_id, history_id), maxseconds=maxseconds)\n  File \"/opt/hostedtoolcache/Python/3.12.11/x64/lib/python3.12/site-packages/galaxy/tool_util/verify/interactor.py\", line 403, in wait_for\n    wait_on(func, what, walltime_exceeded)\n  File \"/opt/hostedtoolcache/Python/3.12.11/x64/lib/python3.12/site-packages/galaxy/tool_util/verify/wait.py\", line 38, in wait_on\n    value = function()\n            ^^^^^^^^^^\n  File \"/opt/hostedtoolcache/Python/3.12.11/x64/lib/python3.12/site-packages/galaxy/tool_util/verify/interactor.py\", line 399, in \u003clambda\u003e\n    self.wait_for(lambda: self.__job_ready(job_id, history_id), maxseconds=maxseconds)\n                          ^^^^^^^^^^^^^^^^^^^^^^^^^^^^^^^^^^^^\n  File \"/opt/hostedtoolcache/Python/3.12.11/x64/lib/python3.12/site-packages/galaxy/tool_util/verify/interactor.py\", line 749, in __job_ready\n    return self._state_ready(job_id, error_msg=\"Job in error state.\")\n           ^^^^^^^^^^^^^^^^^^^^^^^^^^^^^^^^^^^^^^^^^^^^^^^^^^^^^^^^^^\n  File \"/opt/hostedtoolcache/Python/3.12.11/x64/lib/python3.12/site-packages/galaxy/tool_util/verify/interactor.py\", line 841, in _state_ready\n    raise Exception(\nException: Job in error state.. tool_id: __DATA_FETCH__, exit_code: None, stderr: .\n", "status": "error", "test_index": 0, "time_seconds": 23.491780281066895, "tool_id": "miniasm", "tool_version": "0.3_r179+galaxy1"}
            ]]></error>
        
    </testcase>
    
    <testcase classname="miniasm (Test #2)" name="1" time="14.716681480407715">
        
            <error type="error" message="Input staging problem: Traceback (most recent call last):
  File "/opt/hostedtoolcache/Python/3.12.11/x64/lib/python3.12/site-packages/galaxy/tool_util/verify/interactor.py", line 1436, in verify_tool
    stage_data_in_history(
  File "/opt/hostedtoolcache/Python/3.12.11/x64/lib/python3.12/site-packages/galaxy/tool_util/verify/interactor.py", line 175, in stage_data_in_history
    staging_interface.handle_jobs()
  File "/opt/hostedtoolcache/Python/3.12.11/x64/lib/python3.12/site-packages/galaxy/tool_util/verify/interactor.py", line 212, in handle_jobs
    self.galaxy_interactor.wait_for_job(job_response["id"], job_response["history_id"], self.maxseconds)
  File "/opt/hostedtoolcache/Python/3.12.11/x64/lib/python3.12/site-packages/galaxy/tool_util/verify/interactor.py", line 399, in wait_for_job
    self.wait_for(lambda: self.__job_ready(job_id, history_id), maxseconds=maxseconds)
  File "/opt/hostedtoolcache/Python/3.12.11/x64/lib/python3.12/site-packages/galaxy/tool_util/verify/interactor.py", line 403, in wait_for
    wait_on(func, what, walltime_exceeded)
  File "/opt/hostedtoolcache/Python/3.12.11/x64/lib/python3.12/site-packages/galaxy/tool_util/verify/wait.py", line 38, in wait_on
    value = function()
            ^^^^^^^^^^
  File "/opt/hostedtoolcache/Python/3.12.11/x64/lib/python3.12/site-packages/galaxy/tool_util/verify/interactor.py", line 399, in <lambda>
    self.wait_for(lambda: self.__job_ready(job_id, history_id), maxseconds=maxseconds)
                          ^^^^^^^^^^^^^^^^^^^^^^^^^^^^^^^^^^^^
  File "/opt/hostedtoolcache/Python/3.12.11/x64/lib/python3.12/site-packages/galaxy/tool_util/verify/interactor.py", line 749, in __job_ready
    return self._state_ready(job_id, error_msg="Job in error state.")
           ^^^^^^^^^^^^^^^^^^^^^^^^^^^^^^^^^^^^^^^^^^^^^^^^^^^^^^^^^^
  File "/opt/hostedtoolcache/Python/3.12.11/x64/lib/python3.12/site-packages/galaxy/tool_util/verify/interactor.py", line 841, in _state_ready
    raise Exception(
Exception: Job in error state.. tool_id: __DATA_FETCH__, exit_code: None, stderr: .
"><![CDATA[
                { "execution_problem": "Input staging problem: Traceback (most recent call last):\n  File \"/opt/hostedtoolcache/Python/3.12.11/x64/lib/python3.12/site-packages/galaxy/tool_util/verify/interactor.py\", line 1436, in verify_tool\n    stage_data_in_history(\n  File \"/opt/hostedtoolcache/Python/3.12.11/x64/lib/python3.12/site-packages/galaxy/tool_util/verify/interactor.py\", line 175, in stage_data_in_history\n    staging_interface.handle_jobs()\n  File \"/opt/hostedtoolcache/Python/3.12.11/x64/lib/python3.12/site-packages/galaxy/tool_util/verify/interactor.py\", line 212, in handle_jobs\n    self.galaxy_interactor.wait_for_job(job_response[\"id\"], job_response[\"history_id\"], self.maxseconds)\n  File \"/opt/hostedtoolcache/Python/3.12.11/x64/lib/python3.12/site-packages/galaxy/tool_util/verify/interactor.py\", line 399, in wait_for_job\n    self.wait_for(lambda: self.__job_ready(job_id, history_id), maxseconds=maxseconds)\n  File \"/opt/hostedtoolcache/Python/3.12.11/x64/lib/python3.12/site-packages/galaxy/tool_util/verify/interactor.py\", line 403, in wait_for\n    wait_on(func, what, walltime_exceeded)\n  File \"/opt/hostedtoolcache/Python/3.12.11/x64/lib/python3.12/site-packages/galaxy/tool_util/verify/wait.py\", line 38, in wait_on\n    value = function()\n            ^^^^^^^^^^\n  File \"/opt/hostedtoolcache/Python/3.12.11/x64/lib/python3.12/site-packages/galaxy/tool_util/verify/interactor.py\", line 399, in \u003clambda\u003e\n    self.wait_for(lambda: self.__job_ready(job_id, history_id), maxseconds=maxseconds)\n                          ^^^^^^^^^^^^^^^^^^^^^^^^^^^^^^^^^^^^\n  File \"/opt/hostedtoolcache/Python/3.12.11/x64/lib/python3.12/site-packages/galaxy/tool_util/verify/interactor.py\", line 749, in __job_ready\n    return self._state_ready(job_id, error_msg=\"Job in error state.\")\n           ^^^^^^^^^^^^^^^^^^^^^^^^^^^^^^^^^^^^^^^^^^^^^^^^^^^^^^^^^^\n  File \"/opt/hostedtoolcache/Python/3.12.11/x64/lib/python3.12/site-packages/galaxy/tool_util/verify/interactor.py\", line 841, in _state_ready\n    raise Exception(\nException: Job in error state.. tool_id: __DATA_FETCH__, exit_code: None, stderr: .\n", "status": "error", "test_index": 1, "time_seconds": 14.716681480407715, "tool_id": "miniasm", "tool_version": "0.3_r179+galaxy1"}
            ]]></error>
        
    </testcase>
    
    <testcase classname="poretools_qualdist (Test #1)" name="0" time="71.99882912635803">
        
            
            <system-out><![CDATA[
            
            ]]></system-out>
            <system-err><![CDATA[
            
            ]]></system-err>
        
    </testcase>
    
    <testcase classname="poretools_qualdist (Test #2)" name="1" time="39.732128381729126">
        
            
            <system-out><![CDATA[
            
            ]]></system-out>
            <system-err><![CDATA[
            
            ]]></system-err>
        
    </testcase>
    
    <testcase classname="sam2interval (Test #1)" name="0" time="47.59953856468201">
        
            
            <system-out><![CDATA[
            
            ]]></system-out>
            <system-err><![CDATA[
            
            ]]></system-err>
        
    </testcase>
    
    <testcase classname="sam2interval (Test #2)" name="1" time="38.65130805969238">
        
            
            <system-out><![CDATA[
            
            ]]></system-out>
            <system-err><![CDATA[
            
            ]]></system-err>
        
    </testcase>
    
    <testcase classname="sam2interval (Test #3)" name="2" time="36.55368947982788">
        
            
            <system-out><![CDATA[
            
            ]]></system-out>
            <system-err><![CDATA[
            
            ]]></system-err>
        
    </testcase>
    
    <testcase classname="samtools_flagstat (Test #1)" name="0" time="43.909385204315186">
        
            
            <system-out><![CDATA[
            
            ]]></system-out>
            <system-err><![CDATA[
            
            ]]></system-err>
        
    </testcase>
    
    <testcase classname="samtools_flagstat (Test #2)" name="1" time="39.0740270614624">
        
            
            <system-out><![CDATA[
            
            ]]></system-out>
            <system-err><![CDATA[
            
            ]]></system-err>
        
    </testcase>
    
    <testcase classname="samtools_flagstat (Test #3)" name="2" time="39.32503962516785">
        
            
            <system-out><![CDATA[
            
            ]]></system-out>
            <system-err><![CDATA[
            
            ]]></system-err>
        
    </testcase>
    
    <testcase classname="vcfaddinfo (Test #1)" name="0" time="22.83962917327881">
        
            <error type="error" message="Input staging problem: Traceback (most recent call last):
  File "/opt/hostedtoolcache/Python/3.12.11/x64/lib/python3.12/site-packages/galaxy/tool_util/verify/interactor.py", line 1436, in verify_tool
    stage_data_in_history(
  File "/opt/hostedtoolcache/Python/3.12.11/x64/lib/python3.12/site-packages/galaxy/tool_util/verify/interactor.py", line 175, in stage_data_in_history
    staging_interface.handle_jobs()
  File "/opt/hostedtoolcache/Python/3.12.11/x64/lib/python3.12/site-packages/galaxy/tool_util/verify/interactor.py", line 212, in handle_jobs
    self.galaxy_interactor.wait_for_job(job_response["id"], job_response["history_id"], self.maxseconds)
  File "/opt/hostedtoolcache/Python/3.12.11/x64/lib/python3.12/site-packages/galaxy/tool_util/verify/interactor.py", line 399, in wait_for_job
    self.wait_for(lambda: self.__job_ready(job_id, history_id), maxseconds=maxseconds)
  File "/opt/hostedtoolcache/Python/3.12.11/x64/lib/python3.12/site-packages/galaxy/tool_util/verify/interactor.py", line 403, in wait_for
    wait_on(func, what, walltime_exceeded)
  File "/opt/hostedtoolcache/Python/3.12.11/x64/lib/python3.12/site-packages/galaxy/tool_util/verify/wait.py", line 38, in wait_on
    value = function()
            ^^^^^^^^^^
  File "/opt/hostedtoolcache/Python/3.12.11/x64/lib/python3.12/site-packages/galaxy/tool_util/verify/interactor.py", line 399, in <lambda>
    self.wait_for(lambda: self.__job_ready(job_id, history_id), maxseconds=maxseconds)
                          ^^^^^^^^^^^^^^^^^^^^^^^^^^^^^^^^^^^^
  File "/opt/hostedtoolcache/Python/3.12.11/x64/lib/python3.12/site-packages/galaxy/tool_util/verify/interactor.py", line 749, in __job_ready
    return self._state_ready(job_id, error_msg="Job in error state.")
           ^^^^^^^^^^^^^^^^^^^^^^^^^^^^^^^^^^^^^^^^^^^^^^^^^^^^^^^^^^
  File "/opt/hostedtoolcache/Python/3.12.11/x64/lib/python3.12/site-packages/galaxy/tool_util/verify/interactor.py", line 841, in _state_ready
    raise Exception(
Exception: Job in error state.. tool_id: __DATA_FETCH__, exit_code: None, stderr: .
"><![CDATA[
                { "execution_problem": "Input staging problem: Traceback (most recent call last):\n  File \"/opt/hostedtoolcache/Python/3.12.11/x64/lib/python3.12/site-packages/galaxy/tool_util/verify/interactor.py\", line 1436, in verify_tool\n    stage_data_in_history(\n  File \"/opt/hostedtoolcache/Python/3.12.11/x64/lib/python3.12/site-packages/galaxy/tool_util/verify/interactor.py\", line 175, in stage_data_in_history\n    staging_interface.handle_jobs()\n  File \"/opt/hostedtoolcache/Python/3.12.11/x64/lib/python3.12/site-packages/galaxy/tool_util/verify/interactor.py\", line 212, in handle_jobs\n    self.galaxy_interactor.wait_for_job(job_response[\"id\"], job_response[\"history_id\"], self.maxseconds)\n  File \"/opt/hostedtoolcache/Python/3.12.11/x64/lib/python3.12/site-packages/galaxy/tool_util/verify/interactor.py\", line 399, in wait_for_job\n    self.wait_for(lambda: self.__job_ready(job_id, history_id), maxseconds=maxseconds)\n  File \"/opt/hostedtoolcache/Python/3.12.11/x64/lib/python3.12/site-packages/galaxy/tool_util/verify/interactor.py\", line 403, in wait_for\n    wait_on(func, what, walltime_exceeded)\n  File \"/opt/hostedtoolcache/Python/3.12.11/x64/lib/python3.12/site-packages/galaxy/tool_util/verify/wait.py\", line 38, in wait_on\n    value = function()\n            ^^^^^^^^^^\n  File \"/opt/hostedtoolcache/Python/3.12.11/x64/lib/python3.12/site-packages/galaxy/tool_util/verify/interactor.py\", line 399, in \u003clambda\u003e\n    self.wait_for(lambda: self.__job_ready(job_id, history_id), maxseconds=maxseconds)\n                          ^^^^^^^^^^^^^^^^^^^^^^^^^^^^^^^^^^^^\n  File \"/opt/hostedtoolcache/Python/3.12.11/x64/lib/python3.12/site-packages/galaxy/tool_util/verify/interactor.py\", line 749, in __job_ready\n    return self._state_ready(job_id, error_msg=\"Job in error state.\")\n           ^^^^^^^^^^^^^^^^^^^^^^^^^^^^^^^^^^^^^^^^^^^^^^^^^^^^^^^^^^\n  File \"/opt/hostedtoolcache/Python/3.12.11/x64/lib/python3.12/site-packages/galaxy/tool_util/verify/interactor.py\", line 841, in _state_ready\n    raise Exception(\nException: Job in error state.. tool_id: __DATA_FETCH__, exit_code: None, stderr: .\n", "status": "error", "test_index": 0, "time_seconds": 22.83962917327881, "tool_id": "vcfaddinfo", "tool_version": "1.0.0_rc3+galaxy0"}
            ]]></error>
        
    </testcase>
    
    <testcase classname="vcfleftalign (Test #1)" name="0" time="45.159090518951416">
        
            
            <system-out><![CDATA[
            
            ]]></system-out>
            <system-err><![CDATA[
            index file localref.fa.fai not found, generating...
            ]]></system-err>
        
    </testcase>
    
</testsuite>