<?xml version="1.0" encoding="UTF-8"?>
<testsuite name="Results (powered by Planemo)"
           tests="50"
           errors="21"
           failures="5"
           skip="0">
    
    <testcase classname="bam_to_sam (Test #1)" name="0" time="42.20769166946411">
        
            
            <system-out><![CDATA[
            
            ]]></system-out>
            <system-err><![CDATA[
            
            ]]></system-err>
        
    </testcase>
    
    <testcase classname="bam_to_sam (Test #2)" name="1" time="36.1305091381073">
        
            
            <system-out><![CDATA[
            
            ]]></system-out>
            <system-err><![CDATA[
            
            ]]></system-err>
        
    </testcase>
    
    <testcase classname="bam_to_sam (Test #3)" name="2" time="12.177440881729126">
        
            <error type="error" message="Input staging problem: Traceback (most recent call last):
  File "/opt/hostedtoolcache/Python/3.12.9/x64/lib/python3.12/site-packages/galaxy/tool_util/verify/interactor.py", line 1434, in verify_tool
    stage_data_in_history(
  File "/opt/hostedtoolcache/Python/3.12.9/x64/lib/python3.12/site-packages/galaxy/tool_util/verify/interactor.py", line 175, in stage_data_in_history
    staging_interface.handle_jobs()
  File "/opt/hostedtoolcache/Python/3.12.9/x64/lib/python3.12/site-packages/galaxy/tool_util/verify/interactor.py", line 212, in handle_jobs
    self.galaxy_interactor.wait_for_job(job_response["id"], job_response["history_id"], self.maxseconds)
  File "/opt/hostedtoolcache/Python/3.12.9/x64/lib/python3.12/site-packages/galaxy/tool_util/verify/interactor.py", line 399, in wait_for_job
    self.wait_for(lambda: self.__job_ready(job_id, history_id), maxseconds=maxseconds)
  File "/opt/hostedtoolcache/Python/3.12.9/x64/lib/python3.12/site-packages/galaxy/tool_util/verify/interactor.py", line 403, in wait_for
    wait_on(func, what, walltime_exceeded)
  File "/opt/hostedtoolcache/Python/3.12.9/x64/lib/python3.12/site-packages/galaxy/tool_util/verify/wait.py", line 38, in wait_on
    value = function()
            ^^^^^^^^^^
  File "/opt/hostedtoolcache/Python/3.12.9/x64/lib/python3.12/site-packages/galaxy/tool_util/verify/interactor.py", line 399, in <lambda>
    self.wait_for(lambda: self.__job_ready(job_id, history_id), maxseconds=maxseconds)
                          ^^^^^^^^^^^^^^^^^^^^^^^^^^^^^^^^^^^^
  File "/opt/hostedtoolcache/Python/3.12.9/x64/lib/python3.12/site-packages/galaxy/tool_util/verify/interactor.py", line 747, in __job_ready
    return self._state_ready(job_id, error_msg="Job in error state.")
           ^^^^^^^^^^^^^^^^^^^^^^^^^^^^^^^^^^^^^^^^^^^^^^^^^^^^^^^^^^
  File "/opt/hostedtoolcache/Python/3.12.9/x64/lib/python3.12/site-packages/galaxy/tool_util/verify/interactor.py", line 839, in _state_ready
    raise Exception(
Exception: Job in error state.. tool_id: __DATA_FETCH__, exit_code: None, stderr: .
"><![CDATA[
                { "execution_problem": "Input staging problem: Traceback (most recent call last):\n  File \"/opt/hostedtoolcache/Python/3.12.9/x64/lib/python3.12/site-packages/galaxy/tool_util/verify/interactor.py\", line 1434, in verify_tool\n    stage_data_in_history(\n  File \"/opt/hostedtoolcache/Python/3.12.9/x64/lib/python3.12/site-packages/galaxy/tool_util/verify/interactor.py\", line 175, in stage_data_in_history\n    staging_interface.handle_jobs()\n  File \"/opt/hostedtoolcache/Python/3.12.9/x64/lib/python3.12/site-packages/galaxy/tool_util/verify/interactor.py\", line 212, in handle_jobs\n    self.galaxy_interactor.wait_for_job(job_response[\"id\"], job_response[\"history_id\"], self.maxseconds)\n  File \"/opt/hostedtoolcache/Python/3.12.9/x64/lib/python3.12/site-packages/galaxy/tool_util/verify/interactor.py\", line 399, in wait_for_job\n    self.wait_for(lambda: self.__job_ready(job_id, history_id), maxseconds=maxseconds)\n  File \"/opt/hostedtoolcache/Python/3.12.9/x64/lib/python3.12/site-packages/galaxy/tool_util/verify/interactor.py\", line 403, in wait_for\n    wait_on(func, what, walltime_exceeded)\n  File \"/opt/hostedtoolcache/Python/3.12.9/x64/lib/python3.12/site-packages/galaxy/tool_util/verify/wait.py\", line 38, in wait_on\n    value = function()\n            ^^^^^^^^^^\n  File \"/opt/hostedtoolcache/Python/3.12.9/x64/lib/python3.12/site-packages/galaxy/tool_util/verify/interactor.py\", line 399, in \u003clambda\u003e\n    self.wait_for(lambda: self.__job_ready(job_id, history_id), maxseconds=maxseconds)\n                          ^^^^^^^^^^^^^^^^^^^^^^^^^^^^^^^^^^^^\n  File \"/opt/hostedtoolcache/Python/3.12.9/x64/lib/python3.12/site-packages/galaxy/tool_util/verify/interactor.py\", line 747, in __job_ready\n    return self._state_ready(job_id, error_msg=\"Job in error state.\")\n           ^^^^^^^^^^^^^^^^^^^^^^^^^^^^^^^^^^^^^^^^^^^^^^^^^^^^^^^^^^\n  File \"/opt/hostedtoolcache/Python/3.12.9/x64/lib/python3.12/site-packages/galaxy/tool_util/verify/interactor.py\", line 839, in _state_ready\n    raise Exception(\nException: Job in error state.. tool_id: __DATA_FETCH__, exit_code: None, stderr: .\n", "status": "error", "test_index": 2, "time_seconds": 12.177440881729126, "tool_id": "bam_to_sam", "tool_version": "2.0.4"}
            ]]></error>
        
    </testcase>
    
    <testcase classname="bcftools_merge (Test #1)" name="0" time="42.0037841796875">
        
            
            <system-out><![CDATA[
            
            ]]></system-out>
            <system-err><![CDATA[
            
            ]]></system-err>
        
    </testcase>
    
    <testcase classname="bcftools_merge (Test #2)" name="1" time="35.789244174957275">
        
            
            <system-out><![CDATA[
            
            ]]></system-out>
            <system-err><![CDATA[
            
            ]]></system-err>
        
    </testcase>
    
    <testcase classname="bcftools_merge (Test #3)" name="2" time="34.05192255973816">
        
            
            <system-out><![CDATA[
            
            ]]></system-out>
            <system-err><![CDATA[
            
            ]]></system-err>
        
    </testcase>
    
    <testcase classname="bcftools_merge (Test #4)" name="3" time="10.43602466583252">
        
            <error type="error" message="Input staging problem: Traceback (most recent call last):
  File "/opt/hostedtoolcache/Python/3.12.9/x64/lib/python3.12/site-packages/galaxy/tool_util/verify/interactor.py", line 1434, in verify_tool
    stage_data_in_history(
  File "/opt/hostedtoolcache/Python/3.12.9/x64/lib/python3.12/site-packages/galaxy/tool_util/verify/interactor.py", line 175, in stage_data_in_history
    staging_interface.handle_jobs()
  File "/opt/hostedtoolcache/Python/3.12.9/x64/lib/python3.12/site-packages/galaxy/tool_util/verify/interactor.py", line 212, in handle_jobs
    self.galaxy_interactor.wait_for_job(job_response["id"], job_response["history_id"], self.maxseconds)
  File "/opt/hostedtoolcache/Python/3.12.9/x64/lib/python3.12/site-packages/galaxy/tool_util/verify/interactor.py", line 399, in wait_for_job
    self.wait_for(lambda: self.__job_ready(job_id, history_id), maxseconds=maxseconds)
  File "/opt/hostedtoolcache/Python/3.12.9/x64/lib/python3.12/site-packages/galaxy/tool_util/verify/interactor.py", line 403, in wait_for
    wait_on(func, what, walltime_exceeded)
  File "/opt/hostedtoolcache/Python/3.12.9/x64/lib/python3.12/site-packages/galaxy/tool_util/verify/wait.py", line 38, in wait_on
    value = function()
            ^^^^^^^^^^
  File "/opt/hostedtoolcache/Python/3.12.9/x64/lib/python3.12/site-packages/galaxy/tool_util/verify/interactor.py", line 399, in <lambda>
    self.wait_for(lambda: self.__job_ready(job_id, history_id), maxseconds=maxseconds)
                          ^^^^^^^^^^^^^^^^^^^^^^^^^^^^^^^^^^^^
  File "/opt/hostedtoolcache/Python/3.12.9/x64/lib/python3.12/site-packages/galaxy/tool_util/verify/interactor.py", line 747, in __job_ready
    return self._state_ready(job_id, error_msg="Job in error state.")
           ^^^^^^^^^^^^^^^^^^^^^^^^^^^^^^^^^^^^^^^^^^^^^^^^^^^^^^^^^^
  File "/opt/hostedtoolcache/Python/3.12.9/x64/lib/python3.12/site-packages/galaxy/tool_util/verify/interactor.py", line 839, in _state_ready
    raise Exception(
Exception: Job in error state.. tool_id: __DATA_FETCH__, exit_code: None, stderr: .
"><![CDATA[
                { "execution_problem": "Input staging problem: Traceback (most recent call last):\n  File \"/opt/hostedtoolcache/Python/3.12.9/x64/lib/python3.12/site-packages/galaxy/tool_util/verify/interactor.py\", line 1434, in verify_tool\n    stage_data_in_history(\n  File \"/opt/hostedtoolcache/Python/3.12.9/x64/lib/python3.12/site-packages/galaxy/tool_util/verify/interactor.py\", line 175, in stage_data_in_history\n    staging_interface.handle_jobs()\n  File \"/opt/hostedtoolcache/Python/3.12.9/x64/lib/python3.12/site-packages/galaxy/tool_util/verify/interactor.py\", line 212, in handle_jobs\n    self.galaxy_interactor.wait_for_job(job_response[\"id\"], job_response[\"history_id\"], self.maxseconds)\n  File \"/opt/hostedtoolcache/Python/3.12.9/x64/lib/python3.12/site-packages/galaxy/tool_util/verify/interactor.py\", line 399, in wait_for_job\n    self.wait_for(lambda: self.__job_ready(job_id, history_id), maxseconds=maxseconds)\n  File \"/opt/hostedtoolcache/Python/3.12.9/x64/lib/python3.12/site-packages/galaxy/tool_util/verify/interactor.py\", line 403, in wait_for\n    wait_on(func, what, walltime_exceeded)\n  File \"/opt/hostedtoolcache/Python/3.12.9/x64/lib/python3.12/site-packages/galaxy/tool_util/verify/wait.py\", line 38, in wait_on\n    value = function()\n            ^^^^^^^^^^\n  File \"/opt/hostedtoolcache/Python/3.12.9/x64/lib/python3.12/site-packages/galaxy/tool_util/verify/interactor.py\", line 399, in \u003clambda\u003e\n    self.wait_for(lambda: self.__job_ready(job_id, history_id), maxseconds=maxseconds)\n                          ^^^^^^^^^^^^^^^^^^^^^^^^^^^^^^^^^^^^\n  File \"/opt/hostedtoolcache/Python/3.12.9/x64/lib/python3.12/site-packages/galaxy/tool_util/verify/interactor.py\", line 747, in __job_ready\n    return self._state_ready(job_id, error_msg=\"Job in error state.\")\n           ^^^^^^^^^^^^^^^^^^^^^^^^^^^^^^^^^^^^^^^^^^^^^^^^^^^^^^^^^^\n  File \"/opt/hostedtoolcache/Python/3.12.9/x64/lib/python3.12/site-packages/galaxy/tool_util/verify/interactor.py\", line 839, in _state_ready\n    raise Exception(\nException: Job in error state.. tool_id: __DATA_FETCH__, exit_code: None, stderr: .\n", "status": "error", "test_index": 3, "time_seconds": 10.43602466583252, "tool_id": "bcftools_merge", "tool_version": "1.15.1+galaxy4"}
            ]]></error>
        
    </testcase>
    
    <testcase classname="bcftools_merge (Test #5)" name="4" time="34.542258977890015">
        
            
            <system-out><![CDATA[
            
            ]]></system-out>
            <system-err><![CDATA[
            
            ]]></system-err>
        
    </testcase>
    
    <testcase classname="bcftools_merge (Test #6)" name="5" time="36.357162952423096">
        
            
            <system-out><![CDATA[
            
            ]]></system-out>
            <system-err><![CDATA[
            [W::bcf_sr_add_reader] Using multiple unindexed files may produce errors, make sure chromosomes are in the same order!
            ]]></system-err>
        
    </testcase>
    
    <testcase classname="bcftools_merge (Test #7)" name="6" time="26.776204347610474">
        
            
                <error type="error" message="Tool exit code: None"><![CDATA[
                    { "inputs": {  "input_files": [   {    "id": "d839cb5b85348bba",    "src": "hda"   },   {    "id": "f23869c228494a48",    "src": "hda"   }  ],  "output_type": "v",  "sec_merge|force_samples": true,  "sec_merge|merge": "id",  "sec_restrict|regions_overlap": "1" }, "job": {  "command_line": "export BCFTOOLS_PLUGINS=`which bcftools | sed \u0027s,bin/bcftools,libexec/bcftools,\u0027`;     bgzip -c \u0027/galaxy/server/database/objects/9/c/e/dataset_9ce9b0e7-e160-4b6a-999d-4cf7a41a4b76.dat\u0027 \u003e input0.vcf.gz \u0026\u0026 bcftools index input0.vcf.gz \u0026\u0026 echo \u0027input0.vcf.gz\u0027 \u003e\u003e vcfs_list \u0026\u0026  bgzip -c \u0027/galaxy/server/database/objects/1/0/7/dataset_107d8ad4-9e00-4fb3-8ce2-544bf81d9058.dat\u0027 \u003e input1.vcf.gz \u0026\u0026 bcftools index input1.vcf.gz \u0026\u0026 echo \u0027input1.vcf.gz\u0027 \u003e\u003e vcfs_list \u0026\u0026         bcftools merge    --force-samples   --merge \"id\"       --regions-overlap 1      --output-type \u0027v\u0027   --threads ${GALAXY_SLOTS:-4}    input0.vcf.gz input1.vcf.gz  \u003e \u0027/galaxy/server/database/objects/5/f/9/dataset_5f9334ca-be7e-436f-b86d-236e40e49759.dat\u0027",  "command_version": null,  "copied_from_job_id": null,  "create_time": "2025-03-21T01:04:41.990902",  "dependencies": [],  "exit_code": null,  "external_id": "gxy-d6j8s",  "galaxy_version": "24.1",  "handler": null,  "history_id": "d60d56cf2d7d9acd",  "id": "a518716b7e0a67d7",  "inputs": {   "input_files": {    "id": "d839cb5b85348bba",    "src": "hda",    "uuid": "9ce9b0e7-e160-4b6a-999d-4cf7a41a4b76"   },   "input_files1": {    "id": "d839cb5b85348bba",    "src": "hda",    "uuid": "9ce9b0e7-e160-4b6a-999d-4cf7a41a4b76"   },   "input_files2": {    "id": "f23869c228494a48",    "src": "hda",    "uuid": "107d8ad4-9e00-4fb3-8ce2-544bf81d9058"   }  },  "job_messages": null,  "job_metrics": [],  "job_runner_name": null,  "job_stderr": null,  "job_stdout": null,  "model_class": "Job",  "output_collections": {},  "outputs": {   "output_file": {    "id": "a518716b7e0a67d7",    "src": "hda",    "uuid": "5f9334ca-be7e-436f-b86d-236e40e49759"   }  },  "params": {   "__input_ext": "\"input\"",   "chromInfo": "\"/cvmfs/data.galaxyproject.org/managed/len/ucsc/?.len\"",   "dbkey": "\"?\"",   "output_type": "\"v\"",   "sec_header": "{\"print_header\": false, \"use_header\": null}",   "sec_merge": "{\"force_samples\": true, \"info_rules\": null, \"merge\": \"id\", \"no_index\": false}",   "sec_restrict": "{\"apply_filters\": \"\", \"regions\": {\"__current_case__\": 0, \"regions_src\": \"__none__\"}, \"regions_overlap\": \"1\"}"  },  "state": "error",  "stderr": "",  "stdout": "",  "tool_id": "toolshed.g2.bx.psu.edu/repos/iuc/bcftools_merge/bcftools_merge/1.15.1+galaxy4",  "tool_stderr": "",  "tool_stdout": "",  "update_time": "2025-03-21T01:04:48.094914",  "user_email": "tests@fake.org" }, "output_problems": [  "Job in error state.. tool_id: toolshed.g2.bx.psu.edu/repos/iuc/bcftools_merge/bcftools_merge/1.15.1+galaxy4, exit_code: None, stderr: .",  "Job in error state.. tool_id: toolshed.g2.bx.psu.edu/repos/iuc/bcftools_merge/bcftools_merge/1.15.1+galaxy4, exit_code: None, stderr: ." ], "status": "failure", "test_index": 6, "time_seconds": 26.776204347610474, "tool_id": "bcftools_merge", "tool_version": "1.15.1+galaxy4"}
                ]]></error>
            
            <system-out><![CDATA[
            
            ]]></system-out>
            <system-err><![CDATA[
            
            ]]></system-err>
        
    </testcase>
    
    <testcase classname="bcftools_plugin_missing2ref (Test #1)" name="0" time="40.56944036483765">
        
            
            <system-out><![CDATA[
            
            ]]></system-out>
            <system-err><![CDATA[
            Filled 44 REF alleles
            ]]></system-err>
        
    </testcase>
    
    <testcase classname="column_order_header_sort (Test #1)" name="0" time="0.2933998107910156">
        
            <error type="error" message="Input staging problem: Traceback (most recent call last):
  File "/opt/hostedtoolcache/Python/3.12.9/x64/lib/python3.12/site-packages/galaxy/tool_util/verify/interactor.py", line 1434, in verify_tool
    stage_data_in_history(
  File "/opt/hostedtoolcache/Python/3.12.9/x64/lib/python3.12/site-packages/galaxy/tool_util/verify/interactor.py", line 163, in stage_data_in_history
    test_dict = galaxy_interactor.remote_to_input(
                ^^^^^^^^^^^^^^^^^^^^^^^^^^^^^^^^^^
  File "/opt/hostedtoolcache/Python/3.12.9/x64/lib/python3.12/site-packages/galaxy/tool_util/verify/interactor.py", line 582, in remote_to_input
    path_or_location = self._get_path_or_location(
                       ^^^^^^^^^^^^^^^^^^^^^^^^^^^
  File "/opt/hostedtoolcache/Python/3.12.9/x64/lib/python3.12/site-packages/galaxy/tool_util/verify/interactor.py", line 619, in _get_path_or_location
    path = self.test_data_download(
           ^^^^^^^^^^^^^^^^^^^^^^^^
  File "/opt/hostedtoolcache/Python/3.12.9/x64/lib/python3.12/site-packages/galaxy/tool_util/verify/interactor.py", line 525, in test_data_download
    raise AssertionError(f"Test input file ({filename}) cannot be found.")
AssertionError: Test input file (in_1.tabular) cannot be found.
"><![CDATA[
                { "execution_problem": "Input staging problem: Traceback (most recent call last):\n  File \"/opt/hostedtoolcache/Python/3.12.9/x64/lib/python3.12/site-packages/galaxy/tool_util/verify/interactor.py\", line 1434, in verify_tool\n    stage_data_in_history(\n  File \"/opt/hostedtoolcache/Python/3.12.9/x64/lib/python3.12/site-packages/galaxy/tool_util/verify/interactor.py\", line 163, in stage_data_in_history\n    test_dict = galaxy_interactor.remote_to_input(\n                ^^^^^^^^^^^^^^^^^^^^^^^^^^^^^^^^^^\n  File \"/opt/hostedtoolcache/Python/3.12.9/x64/lib/python3.12/site-packages/galaxy/tool_util/verify/interactor.py\", line 582, in remote_to_input\n    path_or_location = self._get_path_or_location(\n                       ^^^^^^^^^^^^^^^^^^^^^^^^^^^\n  File \"/opt/hostedtoolcache/Python/3.12.9/x64/lib/python3.12/site-packages/galaxy/tool_util/verify/interactor.py\", line 619, in _get_path_or_location\n    path = self.test_data_download(\n           ^^^^^^^^^^^^^^^^^^^^^^^^\n  File \"/opt/hostedtoolcache/Python/3.12.9/x64/lib/python3.12/site-packages/galaxy/tool_util/verify/interactor.py\", line 525, in test_data_download\n    raise AssertionError(f\"Test input file ({filename}) cannot be found.\")\nAssertionError: Test input file (in_1.tabular) cannot be found.\n", "status": "error", "test_index": 0, "time_seconds": 0.2933998107910156, "tool_id": "column_order_header_sort", "tool_version": "0.0.1"}
            ]]></error>
        
    </testcase>
    
    <testcase classname="deeptools_plot_pca (Test #1)" name="0" time="11.78103494644165">
        
            <error type="error" message="Input staging problem: Traceback (most recent call last):
  File "/opt/hostedtoolcache/Python/3.12.9/x64/lib/python3.12/site-packages/galaxy/tool_util/verify/interactor.py", line 1434, in verify_tool
    stage_data_in_history(
  File "/opt/hostedtoolcache/Python/3.12.9/x64/lib/python3.12/site-packages/galaxy/tool_util/verify/interactor.py", line 175, in stage_data_in_history
    staging_interface.handle_jobs()
  File "/opt/hostedtoolcache/Python/3.12.9/x64/lib/python3.12/site-packages/galaxy/tool_util/verify/interactor.py", line 212, in handle_jobs
    self.galaxy_interactor.wait_for_job(job_response["id"], job_response["history_id"], self.maxseconds)
  File "/opt/hostedtoolcache/Python/3.12.9/x64/lib/python3.12/site-packages/galaxy/tool_util/verify/interactor.py", line 399, in wait_for_job
    self.wait_for(lambda: self.__job_ready(job_id, history_id), maxseconds=maxseconds)
  File "/opt/hostedtoolcache/Python/3.12.9/x64/lib/python3.12/site-packages/galaxy/tool_util/verify/interactor.py", line 403, in wait_for
    wait_on(func, what, walltime_exceeded)
  File "/opt/hostedtoolcache/Python/3.12.9/x64/lib/python3.12/site-packages/galaxy/tool_util/verify/wait.py", line 38, in wait_on
    value = function()
            ^^^^^^^^^^
  File "/opt/hostedtoolcache/Python/3.12.9/x64/lib/python3.12/site-packages/galaxy/tool_util/verify/interactor.py", line 399, in <lambda>
    self.wait_for(lambda: self.__job_ready(job_id, history_id), maxseconds=maxseconds)
                          ^^^^^^^^^^^^^^^^^^^^^^^^^^^^^^^^^^^^
  File "/opt/hostedtoolcache/Python/3.12.9/x64/lib/python3.12/site-packages/galaxy/tool_util/verify/interactor.py", line 747, in __job_ready
    return self._state_ready(job_id, error_msg="Job in error state.")
           ^^^^^^^^^^^^^^^^^^^^^^^^^^^^^^^^^^^^^^^^^^^^^^^^^^^^^^^^^^
  File "/opt/hostedtoolcache/Python/3.12.9/x64/lib/python3.12/site-packages/galaxy/tool_util/verify/interactor.py", line 839, in _state_ready
    raise Exception(
Exception: Job in error state.. tool_id: __DATA_FETCH__, exit_code: None, stderr: .
"><![CDATA[
                { "execution_problem": "Input staging problem: Traceback (most recent call last):\n  File \"/opt/hostedtoolcache/Python/3.12.9/x64/lib/python3.12/site-packages/galaxy/tool_util/verify/interactor.py\", line 1434, in verify_tool\n    stage_data_in_history(\n  File \"/opt/hostedtoolcache/Python/3.12.9/x64/lib/python3.12/site-packages/galaxy/tool_util/verify/interactor.py\", line 175, in stage_data_in_history\n    staging_interface.handle_jobs()\n  File \"/opt/hostedtoolcache/Python/3.12.9/x64/lib/python3.12/site-packages/galaxy/tool_util/verify/interactor.py\", line 212, in handle_jobs\n    self.galaxy_interactor.wait_for_job(job_response[\"id\"], job_response[\"history_id\"], self.maxseconds)\n  File \"/opt/hostedtoolcache/Python/3.12.9/x64/lib/python3.12/site-packages/galaxy/tool_util/verify/interactor.py\", line 399, in wait_for_job\n    self.wait_for(lambda: self.__job_ready(job_id, history_id), maxseconds=maxseconds)\n  File \"/opt/hostedtoolcache/Python/3.12.9/x64/lib/python3.12/site-packages/galaxy/tool_util/verify/interactor.py\", line 403, in wait_for\n    wait_on(func, what, walltime_exceeded)\n  File \"/opt/hostedtoolcache/Python/3.12.9/x64/lib/python3.12/site-packages/galaxy/tool_util/verify/wait.py\", line 38, in wait_on\n    value = function()\n            ^^^^^^^^^^\n  File \"/opt/hostedtoolcache/Python/3.12.9/x64/lib/python3.12/site-packages/galaxy/tool_util/verify/interactor.py\", line 399, in \u003clambda\u003e\n    self.wait_for(lambda: self.__job_ready(job_id, history_id), maxseconds=maxseconds)\n                          ^^^^^^^^^^^^^^^^^^^^^^^^^^^^^^^^^^^^\n  File \"/opt/hostedtoolcache/Python/3.12.9/x64/lib/python3.12/site-packages/galaxy/tool_util/verify/interactor.py\", line 747, in __job_ready\n    return self._state_ready(job_id, error_msg=\"Job in error state.\")\n           ^^^^^^^^^^^^^^^^^^^^^^^^^^^^^^^^^^^^^^^^^^^^^^^^^^^^^^^^^^\n  File \"/opt/hostedtoolcache/Python/3.12.9/x64/lib/python3.12/site-packages/galaxy/tool_util/verify/interactor.py\", line 839, in _state_ready\n    raise Exception(\nException: Job in error state.. tool_id: __DATA_FETCH__, exit_code: None, stderr: .\n", "status": "error", "test_index": 0, "time_seconds": 11.78103494644165, "tool_id": "deeptools_plot_pca", "tool_version": "3.5.4+galaxy0"}
            ]]></error>
        
    </testcase>
    
    <testcase classname="deeptools_plot_pca (Test #2)" name="1" time="53.30719470977783">
        
            
            <system-out><![CDATA[
            
            ]]></system-out>
            <system-err><![CDATA[
            
            ]]></system-err>
        
    </testcase>
    
    <testcase classname="fastp (Test #1)" name="0" time="0.29843807220458984">
        
            <error type="error" message="Input staging problem: Traceback (most recent call last):
  File "/opt/hostedtoolcache/Python/3.12.9/x64/lib/python3.12/site-packages/galaxy/tool_util/verify/interactor.py", line 1434, in verify_tool
    stage_data_in_history(
  File "/opt/hostedtoolcache/Python/3.12.9/x64/lib/python3.12/site-packages/galaxy/tool_util/verify/interactor.py", line 163, in stage_data_in_history
    test_dict = galaxy_interactor.remote_to_input(
                ^^^^^^^^^^^^^^^^^^^^^^^^^^^^^^^^^^
  File "/opt/hostedtoolcache/Python/3.12.9/x64/lib/python3.12/site-packages/galaxy/tool_util/verify/interactor.py", line 582, in remote_to_input
    path_or_location = self._get_path_or_location(
                       ^^^^^^^^^^^^^^^^^^^^^^^^^^^
  File "/opt/hostedtoolcache/Python/3.12.9/x64/lib/python3.12/site-packages/galaxy/tool_util/verify/interactor.py", line 619, in _get_path_or_location
    path = self.test_data_download(
           ^^^^^^^^^^^^^^^^^^^^^^^^
  File "/opt/hostedtoolcache/Python/3.12.9/x64/lib/python3.12/site-packages/galaxy/tool_util/verify/interactor.py", line 525, in test_data_download
    raise AssertionError(f"Test input file ({filename}) cannot be found.")
AssertionError: Test input file (R1.fq) cannot be found.
"><![CDATA[
                { "execution_problem": "Input staging problem: Traceback (most recent call last):\n  File \"/opt/hostedtoolcache/Python/3.12.9/x64/lib/python3.12/site-packages/galaxy/tool_util/verify/interactor.py\", line 1434, in verify_tool\n    stage_data_in_history(\n  File \"/opt/hostedtoolcache/Python/3.12.9/x64/lib/python3.12/site-packages/galaxy/tool_util/verify/interactor.py\", line 163, in stage_data_in_history\n    test_dict = galaxy_interactor.remote_to_input(\n                ^^^^^^^^^^^^^^^^^^^^^^^^^^^^^^^^^^\n  File \"/opt/hostedtoolcache/Python/3.12.9/x64/lib/python3.12/site-packages/galaxy/tool_util/verify/interactor.py\", line 582, in remote_to_input\n    path_or_location = self._get_path_or_location(\n                       ^^^^^^^^^^^^^^^^^^^^^^^^^^^\n  File \"/opt/hostedtoolcache/Python/3.12.9/x64/lib/python3.12/site-packages/galaxy/tool_util/verify/interactor.py\", line 619, in _get_path_or_location\n    path = self.test_data_download(\n           ^^^^^^^^^^^^^^^^^^^^^^^^\n  File \"/opt/hostedtoolcache/Python/3.12.9/x64/lib/python3.12/site-packages/galaxy/tool_util/verify/interactor.py\", line 525, in test_data_download\n    raise AssertionError(f\"Test input file ({filename}) cannot be found.\")\nAssertionError: Test input file (R1.fq) cannot be found.\n", "status": "error", "test_index": 0, "time_seconds": 0.29843807220458984, "tool_id": "fastp", "tool_version": "0.24.0+galaxy3"}
            ]]></error>
        
    </testcase>
    
    <testcase classname="fastp (Test #2)" name="1" time="0.1555945873260498">
        
            <error type="error" message="Input staging problem: Traceback (most recent call last):
  File "/opt/hostedtoolcache/Python/3.12.9/x64/lib/python3.12/site-packages/galaxy/tool_util/verify/interactor.py", line 1434, in verify_tool
    stage_data_in_history(
  File "/opt/hostedtoolcache/Python/3.12.9/x64/lib/python3.12/site-packages/galaxy/tool_util/verify/interactor.py", line 163, in stage_data_in_history
    test_dict = galaxy_interactor.remote_to_input(
                ^^^^^^^^^^^^^^^^^^^^^^^^^^^^^^^^^^
  File "/opt/hostedtoolcache/Python/3.12.9/x64/lib/python3.12/site-packages/galaxy/tool_util/verify/interactor.py", line 582, in remote_to_input
    path_or_location = self._get_path_or_location(
                       ^^^^^^^^^^^^^^^^^^^^^^^^^^^
  File "/opt/hostedtoolcache/Python/3.12.9/x64/lib/python3.12/site-packages/galaxy/tool_util/verify/interactor.py", line 619, in _get_path_or_location
    path = self.test_data_download(
           ^^^^^^^^^^^^^^^^^^^^^^^^
  File "/opt/hostedtoolcache/Python/3.12.9/x64/lib/python3.12/site-packages/galaxy/tool_util/verify/interactor.py", line 525, in test_data_download
    raise AssertionError(f"Test input file ({filename}) cannot be found.")
AssertionError: Test input file (bwa-mem-fastq1.fq) cannot be found.
"><![CDATA[
                { "execution_problem": "Input staging problem: Traceback (most recent call last):\n  File \"/opt/hostedtoolcache/Python/3.12.9/x64/lib/python3.12/site-packages/galaxy/tool_util/verify/interactor.py\", line 1434, in verify_tool\n    stage_data_in_history(\n  File \"/opt/hostedtoolcache/Python/3.12.9/x64/lib/python3.12/site-packages/galaxy/tool_util/verify/interactor.py\", line 163, in stage_data_in_history\n    test_dict = galaxy_interactor.remote_to_input(\n                ^^^^^^^^^^^^^^^^^^^^^^^^^^^^^^^^^^\n  File \"/opt/hostedtoolcache/Python/3.12.9/x64/lib/python3.12/site-packages/galaxy/tool_util/verify/interactor.py\", line 582, in remote_to_input\n    path_or_location = self._get_path_or_location(\n                       ^^^^^^^^^^^^^^^^^^^^^^^^^^^\n  File \"/opt/hostedtoolcache/Python/3.12.9/x64/lib/python3.12/site-packages/galaxy/tool_util/verify/interactor.py\", line 619, in _get_path_or_location\n    path = self.test_data_download(\n           ^^^^^^^^^^^^^^^^^^^^^^^^\n  File \"/opt/hostedtoolcache/Python/3.12.9/x64/lib/python3.12/site-packages/galaxy/tool_util/verify/interactor.py\", line 525, in test_data_download\n    raise AssertionError(f\"Test input file ({filename}) cannot be found.\")\nAssertionError: Test input file (bwa-mem-fastq1.fq) cannot be found.\n", "status": "error", "test_index": 1, "time_seconds": 0.1555945873260498, "tool_id": "fastp", "tool_version": "0.24.0+galaxy3"}
            ]]></error>
        
    </testcase>
    
    <testcase classname="fastp (Test #11)" name="10" time="0.15498924255371094">
        
            <error type="error" message="Input staging problem: Traceback (most recent call last):
  File "/opt/hostedtoolcache/Python/3.12.9/x64/lib/python3.12/site-packages/galaxy/tool_util/verify/interactor.py", line 1434, in verify_tool
    stage_data_in_history(
  File "/opt/hostedtoolcache/Python/3.12.9/x64/lib/python3.12/site-packages/galaxy/tool_util/verify/interactor.py", line 163, in stage_data_in_history
    test_dict = galaxy_interactor.remote_to_input(
                ^^^^^^^^^^^^^^^^^^^^^^^^^^^^^^^^^^
  File "/opt/hostedtoolcache/Python/3.12.9/x64/lib/python3.12/site-packages/galaxy/tool_util/verify/interactor.py", line 582, in remote_to_input
    path_or_location = self._get_path_or_location(
                       ^^^^^^^^^^^^^^^^^^^^^^^^^^^
  File "/opt/hostedtoolcache/Python/3.12.9/x64/lib/python3.12/site-packages/galaxy/tool_util/verify/interactor.py", line 619, in _get_path_or_location
    path = self.test_data_download(
           ^^^^^^^^^^^^^^^^^^^^^^^^
  File "/opt/hostedtoolcache/Python/3.12.9/x64/lib/python3.12/site-packages/galaxy/tool_util/verify/interactor.py", line 525, in test_data_download
    raise AssertionError(f"Test input file ({filename}) cannot be found.")
AssertionError: Test input file (R1.fq.gz) cannot be found.
"><![CDATA[
                { "execution_problem": "Input staging problem: Traceback (most recent call last):\n  File \"/opt/hostedtoolcache/Python/3.12.9/x64/lib/python3.12/site-packages/galaxy/tool_util/verify/interactor.py\", line 1434, in verify_tool\n    stage_data_in_history(\n  File \"/opt/hostedtoolcache/Python/3.12.9/x64/lib/python3.12/site-packages/galaxy/tool_util/verify/interactor.py\", line 163, in stage_data_in_history\n    test_dict = galaxy_interactor.remote_to_input(\n                ^^^^^^^^^^^^^^^^^^^^^^^^^^^^^^^^^^\n  File \"/opt/hostedtoolcache/Python/3.12.9/x64/lib/python3.12/site-packages/galaxy/tool_util/verify/interactor.py\", line 582, in remote_to_input\n    path_or_location = self._get_path_or_location(\n                       ^^^^^^^^^^^^^^^^^^^^^^^^^^^\n  File \"/opt/hostedtoolcache/Python/3.12.9/x64/lib/python3.12/site-packages/galaxy/tool_util/verify/interactor.py\", line 619, in _get_path_or_location\n    path = self.test_data_download(\n           ^^^^^^^^^^^^^^^^^^^^^^^^\n  File \"/opt/hostedtoolcache/Python/3.12.9/x64/lib/python3.12/site-packages/galaxy/tool_util/verify/interactor.py\", line 525, in test_data_download\n    raise AssertionError(f\"Test input file ({filename}) cannot be found.\")\nAssertionError: Test input file (R1.fq.gz) cannot be found.\n", "status": "error", "test_index": 10, "time_seconds": 0.15498924255371094, "tool_id": "fastp", "tool_version": "0.24.0+galaxy3"}
            ]]></error>
        
    </testcase>
    
    <testcase classname="fastp (Test #12)" name="11" time="0.15638327598571777">
        
            <error type="error" message="Input staging problem: Traceback (most recent call last):
  File "/opt/hostedtoolcache/Python/3.12.9/x64/lib/python3.12/site-packages/galaxy/tool_util/verify/interactor.py", line 1434, in verify_tool
    stage_data_in_history(
  File "/opt/hostedtoolcache/Python/3.12.9/x64/lib/python3.12/site-packages/galaxy/tool_util/verify/interactor.py", line 163, in stage_data_in_history
    test_dict = galaxy_interactor.remote_to_input(
                ^^^^^^^^^^^^^^^^^^^^^^^^^^^^^^^^^^
  File "/opt/hostedtoolcache/Python/3.12.9/x64/lib/python3.12/site-packages/galaxy/tool_util/verify/interactor.py", line 582, in remote_to_input
    path_or_location = self._get_path_or_location(
                       ^^^^^^^^^^^^^^^^^^^^^^^^^^^
  File "/opt/hostedtoolcache/Python/3.12.9/x64/lib/python3.12/site-packages/galaxy/tool_util/verify/interactor.py", line 619, in _get_path_or_location
    path = self.test_data_download(
           ^^^^^^^^^^^^^^^^^^^^^^^^
  File "/opt/hostedtoolcache/Python/3.12.9/x64/lib/python3.12/site-packages/galaxy/tool_util/verify/interactor.py", line 525, in test_data_download
    raise AssertionError(f"Test input file ({filename}) cannot be found.")
AssertionError: Test input file (bwa-mem-fastq1.fq) cannot be found.
"><![CDATA[
                { "execution_problem": "Input staging problem: Traceback (most recent call last):\n  File \"/opt/hostedtoolcache/Python/3.12.9/x64/lib/python3.12/site-packages/galaxy/tool_util/verify/interactor.py\", line 1434, in verify_tool\n    stage_data_in_history(\n  File \"/opt/hostedtoolcache/Python/3.12.9/x64/lib/python3.12/site-packages/galaxy/tool_util/verify/interactor.py\", line 163, in stage_data_in_history\n    test_dict = galaxy_interactor.remote_to_input(\n                ^^^^^^^^^^^^^^^^^^^^^^^^^^^^^^^^^^\n  File \"/opt/hostedtoolcache/Python/3.12.9/x64/lib/python3.12/site-packages/galaxy/tool_util/verify/interactor.py\", line 582, in remote_to_input\n    path_or_location = self._get_path_or_location(\n                       ^^^^^^^^^^^^^^^^^^^^^^^^^^^\n  File \"/opt/hostedtoolcache/Python/3.12.9/x64/lib/python3.12/site-packages/galaxy/tool_util/verify/interactor.py\", line 619, in _get_path_or_location\n    path = self.test_data_download(\n           ^^^^^^^^^^^^^^^^^^^^^^^^\n  File \"/opt/hostedtoolcache/Python/3.12.9/x64/lib/python3.12/site-packages/galaxy/tool_util/verify/interactor.py\", line 525, in test_data_download\n    raise AssertionError(f\"Test input file ({filename}) cannot be found.\")\nAssertionError: Test input file (bwa-mem-fastq1.fq) cannot be found.\n", "status": "error", "test_index": 11, "time_seconds": 0.15638327598571777, "tool_id": "fastp", "tool_version": "0.24.0+galaxy3"}
            ]]></error>
        
    </testcase>
    
    <testcase classname="fastp (Test #13)" name="12" time="0.14604568481445312">
        
            <error type="error" message="Input staging problem: Traceback (most recent call last):
  File "/opt/hostedtoolcache/Python/3.12.9/x64/lib/python3.12/site-packages/galaxy/tool_util/verify/interactor.py", line 1434, in verify_tool
    stage_data_in_history(
  File "/opt/hostedtoolcache/Python/3.12.9/x64/lib/python3.12/site-packages/galaxy/tool_util/verify/interactor.py", line 163, in stage_data_in_history
    test_dict = galaxy_interactor.remote_to_input(
                ^^^^^^^^^^^^^^^^^^^^^^^^^^^^^^^^^^
  File "/opt/hostedtoolcache/Python/3.12.9/x64/lib/python3.12/site-packages/galaxy/tool_util/verify/interactor.py", line 582, in remote_to_input
    path_or_location = self._get_path_or_location(
                       ^^^^^^^^^^^^^^^^^^^^^^^^^^^
  File "/opt/hostedtoolcache/Python/3.12.9/x64/lib/python3.12/site-packages/galaxy/tool_util/verify/interactor.py", line 619, in _get_path_or_location
    path = self.test_data_download(
           ^^^^^^^^^^^^^^^^^^^^^^^^
  File "/opt/hostedtoolcache/Python/3.12.9/x64/lib/python3.12/site-packages/galaxy/tool_util/verify/interactor.py", line 525, in test_data_download
    raise AssertionError(f"Test input file ({filename}) cannot be found.")
AssertionError: Test input file (bwa-mem-fastq1.fq) cannot be found.
"><![CDATA[
                { "execution_problem": "Input staging problem: Traceback (most recent call last):\n  File \"/opt/hostedtoolcache/Python/3.12.9/x64/lib/python3.12/site-packages/galaxy/tool_util/verify/interactor.py\", line 1434, in verify_tool\n    stage_data_in_history(\n  File \"/opt/hostedtoolcache/Python/3.12.9/x64/lib/python3.12/site-packages/galaxy/tool_util/verify/interactor.py\", line 163, in stage_data_in_history\n    test_dict = galaxy_interactor.remote_to_input(\n                ^^^^^^^^^^^^^^^^^^^^^^^^^^^^^^^^^^\n  File \"/opt/hostedtoolcache/Python/3.12.9/x64/lib/python3.12/site-packages/galaxy/tool_util/verify/interactor.py\", line 582, in remote_to_input\n    path_or_location = self._get_path_or_location(\n                       ^^^^^^^^^^^^^^^^^^^^^^^^^^^\n  File \"/opt/hostedtoolcache/Python/3.12.9/x64/lib/python3.12/site-packages/galaxy/tool_util/verify/interactor.py\", line 619, in _get_path_or_location\n    path = self.test_data_download(\n           ^^^^^^^^^^^^^^^^^^^^^^^^\n  File \"/opt/hostedtoolcache/Python/3.12.9/x64/lib/python3.12/site-packages/galaxy/tool_util/verify/interactor.py\", line 525, in test_data_download\n    raise AssertionError(f\"Test input file ({filename}) cannot be found.\")\nAssertionError: Test input file (bwa-mem-fastq1.fq) cannot be found.\n", "status": "error", "test_index": 12, "time_seconds": 0.14604568481445312, "tool_id": "fastp", "tool_version": "0.24.0+galaxy3"}
            ]]></error>
        
    </testcase>
    
    <testcase classname="fastp (Test #14)" name="13" time="0.15343141555786133">
        
            <error type="error" message="Input staging problem: Traceback (most recent call last):
  File "/opt/hostedtoolcache/Python/3.12.9/x64/lib/python3.12/site-packages/galaxy/tool_util/verify/interactor.py", line 1434, in verify_tool
    stage_data_in_history(
  File "/opt/hostedtoolcache/Python/3.12.9/x64/lib/python3.12/site-packages/galaxy/tool_util/verify/interactor.py", line 163, in stage_data_in_history
    test_dict = galaxy_interactor.remote_to_input(
                ^^^^^^^^^^^^^^^^^^^^^^^^^^^^^^^^^^
  File "/opt/hostedtoolcache/Python/3.12.9/x64/lib/python3.12/site-packages/galaxy/tool_util/verify/interactor.py", line 582, in remote_to_input
    path_or_location = self._get_path_or_location(
                       ^^^^^^^^^^^^^^^^^^^^^^^^^^^
  File "/opt/hostedtoolcache/Python/3.12.9/x64/lib/python3.12/site-packages/galaxy/tool_util/verify/interactor.py", line 619, in _get_path_or_location
    path = self.test_data_download(
           ^^^^^^^^^^^^^^^^^^^^^^^^
  File "/opt/hostedtoolcache/Python/3.12.9/x64/lib/python3.12/site-packages/galaxy/tool_util/verify/interactor.py", line 525, in test_data_download
    raise AssertionError(f"Test input file ({filename}) cannot be found.")
AssertionError: Test input file (bwa-mem-fastq1.fq) cannot be found.
"><![CDATA[
                { "execution_problem": "Input staging problem: Traceback (most recent call last):\n  File \"/opt/hostedtoolcache/Python/3.12.9/x64/lib/python3.12/site-packages/galaxy/tool_util/verify/interactor.py\", line 1434, in verify_tool\n    stage_data_in_history(\n  File \"/opt/hostedtoolcache/Python/3.12.9/x64/lib/python3.12/site-packages/galaxy/tool_util/verify/interactor.py\", line 163, in stage_data_in_history\n    test_dict = galaxy_interactor.remote_to_input(\n                ^^^^^^^^^^^^^^^^^^^^^^^^^^^^^^^^^^\n  File \"/opt/hostedtoolcache/Python/3.12.9/x64/lib/python3.12/site-packages/galaxy/tool_util/verify/interactor.py\", line 582, in remote_to_input\n    path_or_location = self._get_path_or_location(\n                       ^^^^^^^^^^^^^^^^^^^^^^^^^^^\n  File \"/opt/hostedtoolcache/Python/3.12.9/x64/lib/python3.12/site-packages/galaxy/tool_util/verify/interactor.py\", line 619, in _get_path_or_location\n    path = self.test_data_download(\n           ^^^^^^^^^^^^^^^^^^^^^^^^\n  File \"/opt/hostedtoolcache/Python/3.12.9/x64/lib/python3.12/site-packages/galaxy/tool_util/verify/interactor.py\", line 525, in test_data_download\n    raise AssertionError(f\"Test input file ({filename}) cannot be found.\")\nAssertionError: Test input file (bwa-mem-fastq1.fq) cannot be found.\n", "status": "error", "test_index": 13, "time_seconds": 0.15343141555786133, "tool_id": "fastp", "tool_version": "0.24.0+galaxy3"}
            ]]></error>
        
    </testcase>
    
    <testcase classname="fastp (Test #15)" name="14" time="0.14766359329223633">
        
            <error type="error" message="Input staging problem: Traceback (most recent call last):
  File "/opt/hostedtoolcache/Python/3.12.9/x64/lib/python3.12/site-packages/galaxy/tool_util/verify/interactor.py", line 1434, in verify_tool
    stage_data_in_history(
  File "/opt/hostedtoolcache/Python/3.12.9/x64/lib/python3.12/site-packages/galaxy/tool_util/verify/interactor.py", line 163, in stage_data_in_history
    test_dict = galaxy_interactor.remote_to_input(
                ^^^^^^^^^^^^^^^^^^^^^^^^^^^^^^^^^^
  File "/opt/hostedtoolcache/Python/3.12.9/x64/lib/python3.12/site-packages/galaxy/tool_util/verify/interactor.py", line 582, in remote_to_input
    path_or_location = self._get_path_or_location(
                       ^^^^^^^^^^^^^^^^^^^^^^^^^^^
  File "/opt/hostedtoolcache/Python/3.12.9/x64/lib/python3.12/site-packages/galaxy/tool_util/verify/interactor.py", line 619, in _get_path_or_location
    path = self.test_data_download(
           ^^^^^^^^^^^^^^^^^^^^^^^^
  File "/opt/hostedtoolcache/Python/3.12.9/x64/lib/python3.12/site-packages/galaxy/tool_util/verify/interactor.py", line 525, in test_data_download
    raise AssertionError(f"Test input file ({filename}) cannot be found.")
AssertionError: Test input file (bwa-mem-fastq-paired-collection/input_forward.fastqsanger.gz) cannot be found.
"><![CDATA[
                { "execution_problem": "Input staging problem: Traceback (most recent call last):\n  File \"/opt/hostedtoolcache/Python/3.12.9/x64/lib/python3.12/site-packages/galaxy/tool_util/verify/interactor.py\", line 1434, in verify_tool\n    stage_data_in_history(\n  File \"/opt/hostedtoolcache/Python/3.12.9/x64/lib/python3.12/site-packages/galaxy/tool_util/verify/interactor.py\", line 163, in stage_data_in_history\n    test_dict = galaxy_interactor.remote_to_input(\n                ^^^^^^^^^^^^^^^^^^^^^^^^^^^^^^^^^^\n  File \"/opt/hostedtoolcache/Python/3.12.9/x64/lib/python3.12/site-packages/galaxy/tool_util/verify/interactor.py\", line 582, in remote_to_input\n    path_or_location = self._get_path_or_location(\n                       ^^^^^^^^^^^^^^^^^^^^^^^^^^^\n  File \"/opt/hostedtoolcache/Python/3.12.9/x64/lib/python3.12/site-packages/galaxy/tool_util/verify/interactor.py\", line 619, in _get_path_or_location\n    path = self.test_data_download(\n           ^^^^^^^^^^^^^^^^^^^^^^^^\n  File \"/opt/hostedtoolcache/Python/3.12.9/x64/lib/python3.12/site-packages/galaxy/tool_util/verify/interactor.py\", line 525, in test_data_download\n    raise AssertionError(f\"Test input file ({filename}) cannot be found.\")\nAssertionError: Test input file (bwa-mem-fastq-paired-collection/input_forward.fastqsanger.gz) cannot be found.\n", "status": "error", "test_index": 14, "time_seconds": 0.14766359329223633, "tool_id": "fastp", "tool_version": "0.24.0+galaxy3"}
            ]]></error>
        
    </testcase>
    
    <testcase classname="fastp (Test #3)" name="2" time="0.14597129821777344">
        
            <error type="error" message="Input staging problem: Traceback (most recent call last):
  File "/opt/hostedtoolcache/Python/3.12.9/x64/lib/python3.12/site-packages/galaxy/tool_util/verify/interactor.py", line 1434, in verify_tool
    stage_data_in_history(
  File "/opt/hostedtoolcache/Python/3.12.9/x64/lib/python3.12/site-packages/galaxy/tool_util/verify/interactor.py", line 163, in stage_data_in_history
    test_dict = galaxy_interactor.remote_to_input(
                ^^^^^^^^^^^^^^^^^^^^^^^^^^^^^^^^^^
  File "/opt/hostedtoolcache/Python/3.12.9/x64/lib/python3.12/site-packages/galaxy/tool_util/verify/interactor.py", line 582, in remote_to_input
    path_or_location = self._get_path_or_location(
                       ^^^^^^^^^^^^^^^^^^^^^^^^^^^
  File "/opt/hostedtoolcache/Python/3.12.9/x64/lib/python3.12/site-packages/galaxy/tool_util/verify/interactor.py", line 619, in _get_path_or_location
    path = self.test_data_download(
           ^^^^^^^^^^^^^^^^^^^^^^^^
  File "/opt/hostedtoolcache/Python/3.12.9/x64/lib/python3.12/site-packages/galaxy/tool_util/verify/interactor.py", line 525, in test_data_download
    raise AssertionError(f"Test input file ({filename}) cannot be found.")
AssertionError: Test input file (R1.fq) cannot be found.
"><![CDATA[
                { "execution_problem": "Input staging problem: Traceback (most recent call last):\n  File \"/opt/hostedtoolcache/Python/3.12.9/x64/lib/python3.12/site-packages/galaxy/tool_util/verify/interactor.py\", line 1434, in verify_tool\n    stage_data_in_history(\n  File \"/opt/hostedtoolcache/Python/3.12.9/x64/lib/python3.12/site-packages/galaxy/tool_util/verify/interactor.py\", line 163, in stage_data_in_history\n    test_dict = galaxy_interactor.remote_to_input(\n                ^^^^^^^^^^^^^^^^^^^^^^^^^^^^^^^^^^\n  File \"/opt/hostedtoolcache/Python/3.12.9/x64/lib/python3.12/site-packages/galaxy/tool_util/verify/interactor.py\", line 582, in remote_to_input\n    path_or_location = self._get_path_or_location(\n                       ^^^^^^^^^^^^^^^^^^^^^^^^^^^\n  File \"/opt/hostedtoolcache/Python/3.12.9/x64/lib/python3.12/site-packages/galaxy/tool_util/verify/interactor.py\", line 619, in _get_path_or_location\n    path = self.test_data_download(\n           ^^^^^^^^^^^^^^^^^^^^^^^^\n  File \"/opt/hostedtoolcache/Python/3.12.9/x64/lib/python3.12/site-packages/galaxy/tool_util/verify/interactor.py\", line 525, in test_data_download\n    raise AssertionError(f\"Test input file ({filename}) cannot be found.\")\nAssertionError: Test input file (R1.fq) cannot be found.\n", "status": "error", "test_index": 2, "time_seconds": 0.14597129821777344, "tool_id": "fastp", "tool_version": "0.24.0+galaxy3"}
            ]]></error>
        
    </testcase>
    
    <testcase classname="fastp (Test #4)" name="3" time="0.1522839069366455">
        
            <error type="error" message="Input staging problem: Traceback (most recent call last):
  File "/opt/hostedtoolcache/Python/3.12.9/x64/lib/python3.12/site-packages/galaxy/tool_util/verify/interactor.py", line 1434, in verify_tool
    stage_data_in_history(
  File "/opt/hostedtoolcache/Python/3.12.9/x64/lib/python3.12/site-packages/galaxy/tool_util/verify/interactor.py", line 163, in stage_data_in_history
    test_dict = galaxy_interactor.remote_to_input(
                ^^^^^^^^^^^^^^^^^^^^^^^^^^^^^^^^^^
  File "/opt/hostedtoolcache/Python/3.12.9/x64/lib/python3.12/site-packages/galaxy/tool_util/verify/interactor.py", line 582, in remote_to_input
    path_or_location = self._get_path_or_location(
                       ^^^^^^^^^^^^^^^^^^^^^^^^^^^
  File "/opt/hostedtoolcache/Python/3.12.9/x64/lib/python3.12/site-packages/galaxy/tool_util/verify/interactor.py", line 619, in _get_path_or_location
    path = self.test_data_download(
           ^^^^^^^^^^^^^^^^^^^^^^^^
  File "/opt/hostedtoolcache/Python/3.12.9/x64/lib/python3.12/site-packages/galaxy/tool_util/verify/interactor.py", line 525, in test_data_download
    raise AssertionError(f"Test input file ({filename}) cannot be found.")
AssertionError: Test input file (R1.fq) cannot be found.
"><![CDATA[
                { "execution_problem": "Input staging problem: Traceback (most recent call last):\n  File \"/opt/hostedtoolcache/Python/3.12.9/x64/lib/python3.12/site-packages/galaxy/tool_util/verify/interactor.py\", line 1434, in verify_tool\n    stage_data_in_history(\n  File \"/opt/hostedtoolcache/Python/3.12.9/x64/lib/python3.12/site-packages/galaxy/tool_util/verify/interactor.py\", line 163, in stage_data_in_history\n    test_dict = galaxy_interactor.remote_to_input(\n                ^^^^^^^^^^^^^^^^^^^^^^^^^^^^^^^^^^\n  File \"/opt/hostedtoolcache/Python/3.12.9/x64/lib/python3.12/site-packages/galaxy/tool_util/verify/interactor.py\", line 582, in remote_to_input\n    path_or_location = self._get_path_or_location(\n                       ^^^^^^^^^^^^^^^^^^^^^^^^^^^\n  File \"/opt/hostedtoolcache/Python/3.12.9/x64/lib/python3.12/site-packages/galaxy/tool_util/verify/interactor.py\", line 619, in _get_path_or_location\n    path = self.test_data_download(\n           ^^^^^^^^^^^^^^^^^^^^^^^^\n  File \"/opt/hostedtoolcache/Python/3.12.9/x64/lib/python3.12/site-packages/galaxy/tool_util/verify/interactor.py\", line 525, in test_data_download\n    raise AssertionError(f\"Test input file ({filename}) cannot be found.\")\nAssertionError: Test input file (R1.fq) cannot be found.\n", "status": "error", "test_index": 3, "time_seconds": 0.1522839069366455, "tool_id": "fastp", "tool_version": "0.24.0+galaxy3"}
            ]]></error>
        
    </testcase>
    
    <testcase classname="fastp (Test #5)" name="4" time="0.15290284156799316">
        
            <error type="error" message="Input staging problem: Traceback (most recent call last):
  File "/opt/hostedtoolcache/Python/3.12.9/x64/lib/python3.12/site-packages/galaxy/tool_util/verify/interactor.py", line 1434, in verify_tool
    stage_data_in_history(
  File "/opt/hostedtoolcache/Python/3.12.9/x64/lib/python3.12/site-packages/galaxy/tool_util/verify/interactor.py", line 163, in stage_data_in_history
    test_dict = galaxy_interactor.remote_to_input(
                ^^^^^^^^^^^^^^^^^^^^^^^^^^^^^^^^^^
  File "/opt/hostedtoolcache/Python/3.12.9/x64/lib/python3.12/site-packages/galaxy/tool_util/verify/interactor.py", line 582, in remote_to_input
    path_or_location = self._get_path_or_location(
                       ^^^^^^^^^^^^^^^^^^^^^^^^^^^
  File "/opt/hostedtoolcache/Python/3.12.9/x64/lib/python3.12/site-packages/galaxy/tool_util/verify/interactor.py", line 619, in _get_path_or_location
    path = self.test_data_download(
           ^^^^^^^^^^^^^^^^^^^^^^^^
  File "/opt/hostedtoolcache/Python/3.12.9/x64/lib/python3.12/site-packages/galaxy/tool_util/verify/interactor.py", line 525, in test_data_download
    raise AssertionError(f"Test input file ({filename}) cannot be found.")
AssertionError: Test input file (R1.fq) cannot be found.
"><![CDATA[
                { "execution_problem": "Input staging problem: Traceback (most recent call last):\n  File \"/opt/hostedtoolcache/Python/3.12.9/x64/lib/python3.12/site-packages/galaxy/tool_util/verify/interactor.py\", line 1434, in verify_tool\n    stage_data_in_history(\n  File \"/opt/hostedtoolcache/Python/3.12.9/x64/lib/python3.12/site-packages/galaxy/tool_util/verify/interactor.py\", line 163, in stage_data_in_history\n    test_dict = galaxy_interactor.remote_to_input(\n                ^^^^^^^^^^^^^^^^^^^^^^^^^^^^^^^^^^\n  File \"/opt/hostedtoolcache/Python/3.12.9/x64/lib/python3.12/site-packages/galaxy/tool_util/verify/interactor.py\", line 582, in remote_to_input\n    path_or_location = self._get_path_or_location(\n                       ^^^^^^^^^^^^^^^^^^^^^^^^^^^\n  File \"/opt/hostedtoolcache/Python/3.12.9/x64/lib/python3.12/site-packages/galaxy/tool_util/verify/interactor.py\", line 619, in _get_path_or_location\n    path = self.test_data_download(\n           ^^^^^^^^^^^^^^^^^^^^^^^^\n  File \"/opt/hostedtoolcache/Python/3.12.9/x64/lib/python3.12/site-packages/galaxy/tool_util/verify/interactor.py\", line 525, in test_data_download\n    raise AssertionError(f\"Test input file ({filename}) cannot be found.\")\nAssertionError: Test input file (R1.fq) cannot be found.\n", "status": "error", "test_index": 4, "time_seconds": 0.15290284156799316, "tool_id": "fastp", "tool_version": "0.24.0+galaxy3"}
            ]]></error>
        
    </testcase>
    
    <testcase classname="fastp (Test #6)" name="5" time="0.14618396759033203">
        
            <error type="error" message="Input staging problem: Traceback (most recent call last):
  File "/opt/hostedtoolcache/Python/3.12.9/x64/lib/python3.12/site-packages/galaxy/tool_util/verify/interactor.py", line 1434, in verify_tool
    stage_data_in_history(
  File "/opt/hostedtoolcache/Python/3.12.9/x64/lib/python3.12/site-packages/galaxy/tool_util/verify/interactor.py", line 163, in stage_data_in_history
    test_dict = galaxy_interactor.remote_to_input(
                ^^^^^^^^^^^^^^^^^^^^^^^^^^^^^^^^^^
  File "/opt/hostedtoolcache/Python/3.12.9/x64/lib/python3.12/site-packages/galaxy/tool_util/verify/interactor.py", line 582, in remote_to_input
    path_or_location = self._get_path_or_location(
                       ^^^^^^^^^^^^^^^^^^^^^^^^^^^
  File "/opt/hostedtoolcache/Python/3.12.9/x64/lib/python3.12/site-packages/galaxy/tool_util/verify/interactor.py", line 619, in _get_path_or_location
    path = self.test_data_download(
           ^^^^^^^^^^^^^^^^^^^^^^^^
  File "/opt/hostedtoolcache/Python/3.12.9/x64/lib/python3.12/site-packages/galaxy/tool_util/verify/interactor.py", line 525, in test_data_download
    raise AssertionError(f"Test input file ({filename}) cannot be found.")
AssertionError: Test input file (bwa-mem-fastq1.fq) cannot be found.
"><![CDATA[
                { "execution_problem": "Input staging problem: Traceback (most recent call last):\n  File \"/opt/hostedtoolcache/Python/3.12.9/x64/lib/python3.12/site-packages/galaxy/tool_util/verify/interactor.py\", line 1434, in verify_tool\n    stage_data_in_history(\n  File \"/opt/hostedtoolcache/Python/3.12.9/x64/lib/python3.12/site-packages/galaxy/tool_util/verify/interactor.py\", line 163, in stage_data_in_history\n    test_dict = galaxy_interactor.remote_to_input(\n                ^^^^^^^^^^^^^^^^^^^^^^^^^^^^^^^^^^\n  File \"/opt/hostedtoolcache/Python/3.12.9/x64/lib/python3.12/site-packages/galaxy/tool_util/verify/interactor.py\", line 582, in remote_to_input\n    path_or_location = self._get_path_or_location(\n                       ^^^^^^^^^^^^^^^^^^^^^^^^^^^\n  File \"/opt/hostedtoolcache/Python/3.12.9/x64/lib/python3.12/site-packages/galaxy/tool_util/verify/interactor.py\", line 619, in _get_path_or_location\n    path = self.test_data_download(\n           ^^^^^^^^^^^^^^^^^^^^^^^^\n  File \"/opt/hostedtoolcache/Python/3.12.9/x64/lib/python3.12/site-packages/galaxy/tool_util/verify/interactor.py\", line 525, in test_data_download\n    raise AssertionError(f\"Test input file ({filename}) cannot be found.\")\nAssertionError: Test input file (bwa-mem-fastq1.fq) cannot be found.\n", "status": "error", "test_index": 5, "time_seconds": 0.14618396759033203, "tool_id": "fastp", "tool_version": "0.24.0+galaxy3"}
            ]]></error>
        
    </testcase>
    
    <testcase classname="fastp (Test #7)" name="6" time="0.14713382720947266">
        
            <error type="error" message="Input staging problem: Traceback (most recent call last):
  File "/opt/hostedtoolcache/Python/3.12.9/x64/lib/python3.12/site-packages/galaxy/tool_util/verify/interactor.py", line 1434, in verify_tool
    stage_data_in_history(
  File "/opt/hostedtoolcache/Python/3.12.9/x64/lib/python3.12/site-packages/galaxy/tool_util/verify/interactor.py", line 163, in stage_data_in_history
    test_dict = galaxy_interactor.remote_to_input(
                ^^^^^^^^^^^^^^^^^^^^^^^^^^^^^^^^^^
  File "/opt/hostedtoolcache/Python/3.12.9/x64/lib/python3.12/site-packages/galaxy/tool_util/verify/interactor.py", line 582, in remote_to_input
    path_or_location = self._get_path_or_location(
                       ^^^^^^^^^^^^^^^^^^^^^^^^^^^
  File "/opt/hostedtoolcache/Python/3.12.9/x64/lib/python3.12/site-packages/galaxy/tool_util/verify/interactor.py", line 619, in _get_path_or_location
    path = self.test_data_download(
           ^^^^^^^^^^^^^^^^^^^^^^^^
  File "/opt/hostedtoolcache/Python/3.12.9/x64/lib/python3.12/site-packages/galaxy/tool_util/verify/interactor.py", line 525, in test_data_download
    raise AssertionError(f"Test input file ({filename}) cannot be found.")
AssertionError: Test input file (bwa-mem-fastq1.fq) cannot be found.
"><![CDATA[
                { "execution_problem": "Input staging problem: Traceback (most recent call last):\n  File \"/opt/hostedtoolcache/Python/3.12.9/x64/lib/python3.12/site-packages/galaxy/tool_util/verify/interactor.py\", line 1434, in verify_tool\n    stage_data_in_history(\n  File \"/opt/hostedtoolcache/Python/3.12.9/x64/lib/python3.12/site-packages/galaxy/tool_util/verify/interactor.py\", line 163, in stage_data_in_history\n    test_dict = galaxy_interactor.remote_to_input(\n                ^^^^^^^^^^^^^^^^^^^^^^^^^^^^^^^^^^\n  File \"/opt/hostedtoolcache/Python/3.12.9/x64/lib/python3.12/site-packages/galaxy/tool_util/verify/interactor.py\", line 582, in remote_to_input\n    path_or_location = self._get_path_or_location(\n                       ^^^^^^^^^^^^^^^^^^^^^^^^^^^\n  File \"/opt/hostedtoolcache/Python/3.12.9/x64/lib/python3.12/site-packages/galaxy/tool_util/verify/interactor.py\", line 619, in _get_path_or_location\n    path = self.test_data_download(\n           ^^^^^^^^^^^^^^^^^^^^^^^^\n  File \"/opt/hostedtoolcache/Python/3.12.9/x64/lib/python3.12/site-packages/galaxy/tool_util/verify/interactor.py\", line 525, in test_data_download\n    raise AssertionError(f\"Test input file ({filename}) cannot be found.\")\nAssertionError: Test input file (bwa-mem-fastq1.fq) cannot be found.\n", "status": "error", "test_index": 6, "time_seconds": 0.14713382720947266, "tool_id": "fastp", "tool_version": "0.24.0+galaxy3"}
            ]]></error>
        
    </testcase>
    
    <testcase classname="fastp (Test #8)" name="7" time="0.15483951568603516">
        
            <error type="error" message="Input staging problem: Traceback (most recent call last):
  File "/opt/hostedtoolcache/Python/3.12.9/x64/lib/python3.12/site-packages/galaxy/tool_util/verify/interactor.py", line 1434, in verify_tool
    stage_data_in_history(
  File "/opt/hostedtoolcache/Python/3.12.9/x64/lib/python3.12/site-packages/galaxy/tool_util/verify/interactor.py", line 163, in stage_data_in_history
    test_dict = galaxy_interactor.remote_to_input(
                ^^^^^^^^^^^^^^^^^^^^^^^^^^^^^^^^^^
  File "/opt/hostedtoolcache/Python/3.12.9/x64/lib/python3.12/site-packages/galaxy/tool_util/verify/interactor.py", line 582, in remote_to_input
    path_or_location = self._get_path_or_location(
                       ^^^^^^^^^^^^^^^^^^^^^^^^^^^
  File "/opt/hostedtoolcache/Python/3.12.9/x64/lib/python3.12/site-packages/galaxy/tool_util/verify/interactor.py", line 619, in _get_path_or_location
    path = self.test_data_download(
           ^^^^^^^^^^^^^^^^^^^^^^^^
  File "/opt/hostedtoolcache/Python/3.12.9/x64/lib/python3.12/site-packages/galaxy/tool_util/verify/interactor.py", line 525, in test_data_download
    raise AssertionError(f"Test input file ({filename}) cannot be found.")
AssertionError: Test input file (bwa-mem-fastq1.fq) cannot be found.
"><![CDATA[
                { "execution_problem": "Input staging problem: Traceback (most recent call last):\n  File \"/opt/hostedtoolcache/Python/3.12.9/x64/lib/python3.12/site-packages/galaxy/tool_util/verify/interactor.py\", line 1434, in verify_tool\n    stage_data_in_history(\n  File \"/opt/hostedtoolcache/Python/3.12.9/x64/lib/python3.12/site-packages/galaxy/tool_util/verify/interactor.py\", line 163, in stage_data_in_history\n    test_dict = galaxy_interactor.remote_to_input(\n                ^^^^^^^^^^^^^^^^^^^^^^^^^^^^^^^^^^\n  File \"/opt/hostedtoolcache/Python/3.12.9/x64/lib/python3.12/site-packages/galaxy/tool_util/verify/interactor.py\", line 582, in remote_to_input\n    path_or_location = self._get_path_or_location(\n                       ^^^^^^^^^^^^^^^^^^^^^^^^^^^\n  File \"/opt/hostedtoolcache/Python/3.12.9/x64/lib/python3.12/site-packages/galaxy/tool_util/verify/interactor.py\", line 619, in _get_path_or_location\n    path = self.test_data_download(\n           ^^^^^^^^^^^^^^^^^^^^^^^^\n  File \"/opt/hostedtoolcache/Python/3.12.9/x64/lib/python3.12/site-packages/galaxy/tool_util/verify/interactor.py\", line 525, in test_data_download\n    raise AssertionError(f\"Test input file ({filename}) cannot be found.\")\nAssertionError: Test input file (bwa-mem-fastq1.fq) cannot be found.\n", "status": "error", "test_index": 7, "time_seconds": 0.15483951568603516, "tool_id": "fastp", "tool_version": "0.24.0+galaxy3"}
            ]]></error>
        
    </testcase>
    
    <testcase classname="fastp (Test #9)" name="8" time="0.15644049644470215">
        
            <error type="error" message="Input staging problem: Traceback (most recent call last):
  File "/opt/hostedtoolcache/Python/3.12.9/x64/lib/python3.12/site-packages/galaxy/tool_util/verify/interactor.py", line 1434, in verify_tool
    stage_data_in_history(
  File "/opt/hostedtoolcache/Python/3.12.9/x64/lib/python3.12/site-packages/galaxy/tool_util/verify/interactor.py", line 163, in stage_data_in_history
    test_dict = galaxy_interactor.remote_to_input(
                ^^^^^^^^^^^^^^^^^^^^^^^^^^^^^^^^^^
  File "/opt/hostedtoolcache/Python/3.12.9/x64/lib/python3.12/site-packages/galaxy/tool_util/verify/interactor.py", line 582, in remote_to_input
    path_or_location = self._get_path_or_location(
                       ^^^^^^^^^^^^^^^^^^^^^^^^^^^
  File "/opt/hostedtoolcache/Python/3.12.9/x64/lib/python3.12/site-packages/galaxy/tool_util/verify/interactor.py", line 619, in _get_path_or_location
    path = self.test_data_download(
           ^^^^^^^^^^^^^^^^^^^^^^^^
  File "/opt/hostedtoolcache/Python/3.12.9/x64/lib/python3.12/site-packages/galaxy/tool_util/verify/interactor.py", line 525, in test_data_download
    raise AssertionError(f"Test input file ({filename}) cannot be found.")
AssertionError: Test input file (R1.fq) cannot be found.
"><![CDATA[
                { "execution_problem": "Input staging problem: Traceback (most recent call last):\n  File \"/opt/hostedtoolcache/Python/3.12.9/x64/lib/python3.12/site-packages/galaxy/tool_util/verify/interactor.py\", line 1434, in verify_tool\n    stage_data_in_history(\n  File \"/opt/hostedtoolcache/Python/3.12.9/x64/lib/python3.12/site-packages/galaxy/tool_util/verify/interactor.py\", line 163, in stage_data_in_history\n    test_dict = galaxy_interactor.remote_to_input(\n                ^^^^^^^^^^^^^^^^^^^^^^^^^^^^^^^^^^\n  File \"/opt/hostedtoolcache/Python/3.12.9/x64/lib/python3.12/site-packages/galaxy/tool_util/verify/interactor.py\", line 582, in remote_to_input\n    path_or_location = self._get_path_or_location(\n                       ^^^^^^^^^^^^^^^^^^^^^^^^^^^\n  File \"/opt/hostedtoolcache/Python/3.12.9/x64/lib/python3.12/site-packages/galaxy/tool_util/verify/interactor.py\", line 619, in _get_path_or_location\n    path = self.test_data_download(\n           ^^^^^^^^^^^^^^^^^^^^^^^^\n  File \"/opt/hostedtoolcache/Python/3.12.9/x64/lib/python3.12/site-packages/galaxy/tool_util/verify/interactor.py\", line 525, in test_data_download\n    raise AssertionError(f\"Test input file ({filename}) cannot be found.\")\nAssertionError: Test input file (R1.fq) cannot be found.\n", "status": "error", "test_index": 8, "time_seconds": 0.15644049644470215, "tool_id": "fastp", "tool_version": "0.24.0+galaxy3"}
            ]]></error>
        
    </testcase>
    
    <testcase classname="fastp (Test #10)" name="9" time="0.14604473114013672">
        
            <error type="error" message="Input staging problem: Traceback (most recent call last):
  File "/opt/hostedtoolcache/Python/3.12.9/x64/lib/python3.12/site-packages/galaxy/tool_util/verify/interactor.py", line 1434, in verify_tool
    stage_data_in_history(
  File "/opt/hostedtoolcache/Python/3.12.9/x64/lib/python3.12/site-packages/galaxy/tool_util/verify/interactor.py", line 163, in stage_data_in_history
    test_dict = galaxy_interactor.remote_to_input(
                ^^^^^^^^^^^^^^^^^^^^^^^^^^^^^^^^^^
  File "/opt/hostedtoolcache/Python/3.12.9/x64/lib/python3.12/site-packages/galaxy/tool_util/verify/interactor.py", line 582, in remote_to_input
    path_or_location = self._get_path_or_location(
                       ^^^^^^^^^^^^^^^^^^^^^^^^^^^
  File "/opt/hostedtoolcache/Python/3.12.9/x64/lib/python3.12/site-packages/galaxy/tool_util/verify/interactor.py", line 619, in _get_path_or_location
    path = self.test_data_download(
           ^^^^^^^^^^^^^^^^^^^^^^^^
  File "/opt/hostedtoolcache/Python/3.12.9/x64/lib/python3.12/site-packages/galaxy/tool_util/verify/interactor.py", line 525, in test_data_download
    raise AssertionError(f"Test input file ({filename}) cannot be found.")
AssertionError: Test input file (R1.fq.gz) cannot be found.
"><![CDATA[
                { "execution_problem": "Input staging problem: Traceback (most recent call last):\n  File \"/opt/hostedtoolcache/Python/3.12.9/x64/lib/python3.12/site-packages/galaxy/tool_util/verify/interactor.py\", line 1434, in verify_tool\n    stage_data_in_history(\n  File \"/opt/hostedtoolcache/Python/3.12.9/x64/lib/python3.12/site-packages/galaxy/tool_util/verify/interactor.py\", line 163, in stage_data_in_history\n    test_dict = galaxy_interactor.remote_to_input(\n                ^^^^^^^^^^^^^^^^^^^^^^^^^^^^^^^^^^\n  File \"/opt/hostedtoolcache/Python/3.12.9/x64/lib/python3.12/site-packages/galaxy/tool_util/verify/interactor.py\", line 582, in remote_to_input\n    path_or_location = self._get_path_or_location(\n                       ^^^^^^^^^^^^^^^^^^^^^^^^^^^\n  File \"/opt/hostedtoolcache/Python/3.12.9/x64/lib/python3.12/site-packages/galaxy/tool_util/verify/interactor.py\", line 619, in _get_path_or_location\n    path = self.test_data_download(\n           ^^^^^^^^^^^^^^^^^^^^^^^^\n  File \"/opt/hostedtoolcache/Python/3.12.9/x64/lib/python3.12/site-packages/galaxy/tool_util/verify/interactor.py\", line 525, in test_data_download\n    raise AssertionError(f\"Test input file ({filename}) cannot be found.\")\nAssertionError: Test input file (R1.fq.gz) cannot be found.\n", "status": "error", "test_index": 9, "time_seconds": 0.14604473114013672, "tool_id": "fastp", "tool_version": "0.24.0+galaxy3"}
            ]]></error>
        
    </testcase>
    
    <testcase classname="ivar_variants (Test #1)" name="0" time="37.562426805496216">
        
            
                <error type="error" message="Tool exit code: None"><![CDATA[
                    { "inputs": {  "input_bam": {   "id": "d849f2621c610d38",   "src": "hda"  },  "ref": {   "id": "25f79058c6c51715",   "src": "hda"  } }, "job": {  "command_line": "ln -s \u0027/galaxy/server/database/objects/a/d/5/dataset_ad5db7d9-02fa-4d86-b436-b2b44ed2f79f.dat\u0027 ref.fa \u0026\u0026 ln -s \u0027/galaxy/server/database/objects/8/1/5/dataset_8159b23f-c7b8-4409-a5a4-2e17baf4fad7.dat\u0027 sorted.bam \u0026\u0026 samtools mpileup -A -d 0 --reference ref.fa -B -Q 0 sorted.bam | ivar variants -p variants -q 20 -t 0.03",  "command_version": null,  "copied_from_job_id": null,  "create_time": "2025-03-21T01:11:07.106780",  "dependencies": [],  "exit_code": null,  "external_id": "gxy-zdzf6",  "galaxy_version": "24.1",  "handler": null,  "history_id": "d60d56cf2d7d9acd",  "id": "25f79058c6c51715",  "inputs": {   "input_bam": {    "id": "d849f2621c610d38",    "src": "hda",    "uuid": "8159b23f-c7b8-4409-a5a4-2e17baf4fad7"   },   "ref": {    "id": "25f79058c6c51715",    "src": "hda",    "uuid": "ad5db7d9-02fa-4d86-b436-b2b44ed2f79f"   }  },  "job_messages": null,  "job_metrics": [],  "job_runner_name": null,  "job_stderr": null,  "job_stdout": null,  "model_class": "Job",  "output_collections": {},  "outputs": {   "output_variants_tabular": {    "id": "b5f56b330279141b",    "src": "hda",    "uuid": "7da2f9d6-0db8-46c4-9493-4e170b0e2781"   }  },  "params": {   "__input_ext": "\"input\"",   "chromInfo": "\"/cvmfs/data.galaxyproject.org/managed/len/ucsc/?.len\"",   "dbkey": "\"?\"",   "min_freq": "\"0.03\"",   "min_qual": "\"20\"",   "output_format": "{\"__current_case__\": 2, \"choice\": \"tabular\", \"gtf\": null}"  },  "state": "error",  "stderr": "[mpileup] 1 samples in 1 input files\n[mpileup] Max depth set to maximum value (2147483647)\n",  "stdout": "A GFF file containing the open reading frames (ORFs) has not been provided. Amino acid translation will not be done.\nA reference sequence has not been supplied. Amino acid translation will not be done.\n",  "tool_id": "toolshed.g2.bx.psu.edu/repos/iuc/ivar_variants/ivar_variants/1.4.3+galaxy1",  "tool_stderr": "[mpileup] 1 samples in 1 input files\n[mpileup] Max depth set to maximum value (2147483647)\n",  "tool_stdout": "A GFF file containing the open reading frames (ORFs) has not been provided. Amino acid translation will not be done.\nA reference sequence has not been supplied. Amino acid translation will not be done.\n",  "update_time": "2025-03-21T01:11:21.338453",  "user_email": "tests@fake.org" }, "output_problems": [  "Job in error state.. tool_id: toolshed.g2.bx.psu.edu/repos/iuc/ivar_variants/ivar_variants/1.4.3+galaxy1, exit_code: None, stderr: [mpileup] 1 samples in 1 input files\n[mpileup] Max depth set to maximum value (2147483647)\n.",  "Job in error state.. tool_id: toolshed.g2.bx.psu.edu/repos/iuc/ivar_variants/ivar_variants/1.4.3+galaxy1, exit_code: None, stderr: [mpileup] 1 samples in 1 input files\n[mpileup] Max depth set to maximum value (2147483647)\n." ], "status": "failure", "test_index": 0, "time_seconds": 37.562426805496216, "tool_id": "ivar_variants", "tool_version": "1.4.3+galaxy1"}
                ]]></error>
            
            <system-out><![CDATA[
            A GFF file containing the open reading frames (ORFs) has not been provided. Amino acid translation will not be done.A reference sequence has not been supplied. Amino acid translation will not be done.
            ]]></system-out>
            <system-err><![CDATA[
            [mpileup] 1 samples in 1 input files[mpileup] Max depth set to maximum value (2147483647)
            ]]></system-err>
        
    </testcase>
    
    <testcase classname="ivar_variants (Test #2)" name="1" time="38.476943016052246">
        
            
            <system-out><![CDATA[
            A GFF file containing the open reading frames (ORFs) has not been provided. Amino acid translation will not be done.A reference sequence has not been supplied. Amino acid translation will not be done.sampleDELINSSNPvariants0115
            ]]></system-out>
            <system-err><![CDATA[
            [mpileup] 1 samples in 1 input files[mpileup] Max depth set to maximum value (2147483647)
            ]]></system-err>
        
    </testcase>
    
    <testcase classname="ivar_variants (Test #3)" name="2" time="21.45449447631836">
        
            <error type="error" message="Input staging problem: Traceback (most recent call last):
  File "/opt/hostedtoolcache/Python/3.12.9/x64/lib/python3.12/site-packages/galaxy/tool_util/verify/interactor.py", line 1434, in verify_tool
    stage_data_in_history(
  File "/opt/hostedtoolcache/Python/3.12.9/x64/lib/python3.12/site-packages/galaxy/tool_util/verify/interactor.py", line 175, in stage_data_in_history
    staging_interface.handle_jobs()
  File "/opt/hostedtoolcache/Python/3.12.9/x64/lib/python3.12/site-packages/galaxy/tool_util/verify/interactor.py", line 212, in handle_jobs
    self.galaxy_interactor.wait_for_job(job_response["id"], job_response["history_id"], self.maxseconds)
  File "/opt/hostedtoolcache/Python/3.12.9/x64/lib/python3.12/site-packages/galaxy/tool_util/verify/interactor.py", line 399, in wait_for_job
    self.wait_for(lambda: self.__job_ready(job_id, history_id), maxseconds=maxseconds)
  File "/opt/hostedtoolcache/Python/3.12.9/x64/lib/python3.12/site-packages/galaxy/tool_util/verify/interactor.py", line 403, in wait_for
    wait_on(func, what, walltime_exceeded)
  File "/opt/hostedtoolcache/Python/3.12.9/x64/lib/python3.12/site-packages/galaxy/tool_util/verify/wait.py", line 38, in wait_on
    value = function()
            ^^^^^^^^^^
  File "/opt/hostedtoolcache/Python/3.12.9/x64/lib/python3.12/site-packages/galaxy/tool_util/verify/interactor.py", line 399, in <lambda>
    self.wait_for(lambda: self.__job_ready(job_id, history_id), maxseconds=maxseconds)
                          ^^^^^^^^^^^^^^^^^^^^^^^^^^^^^^^^^^^^
  File "/opt/hostedtoolcache/Python/3.12.9/x64/lib/python3.12/site-packages/galaxy/tool_util/verify/interactor.py", line 747, in __job_ready
    return self._state_ready(job_id, error_msg="Job in error state.")
           ^^^^^^^^^^^^^^^^^^^^^^^^^^^^^^^^^^^^^^^^^^^^^^^^^^^^^^^^^^
  File "/opt/hostedtoolcache/Python/3.12.9/x64/lib/python3.12/site-packages/galaxy/tool_util/verify/interactor.py", line 839, in _state_ready
    raise Exception(
Exception: Job in error state.. tool_id: __DATA_FETCH__, exit_code: None, stderr: .
"><![CDATA[
                { "execution_problem": "Input staging problem: Traceback (most recent call last):\n  File \"/opt/hostedtoolcache/Python/3.12.9/x64/lib/python3.12/site-packages/galaxy/tool_util/verify/interactor.py\", line 1434, in verify_tool\n    stage_data_in_history(\n  File \"/opt/hostedtoolcache/Python/3.12.9/x64/lib/python3.12/site-packages/galaxy/tool_util/verify/interactor.py\", line 175, in stage_data_in_history\n    staging_interface.handle_jobs()\n  File \"/opt/hostedtoolcache/Python/3.12.9/x64/lib/python3.12/site-packages/galaxy/tool_util/verify/interactor.py\", line 212, in handle_jobs\n    self.galaxy_interactor.wait_for_job(job_response[\"id\"], job_response[\"history_id\"], self.maxseconds)\n  File \"/opt/hostedtoolcache/Python/3.12.9/x64/lib/python3.12/site-packages/galaxy/tool_util/verify/interactor.py\", line 399, in wait_for_job\n    self.wait_for(lambda: self.__job_ready(job_id, history_id), maxseconds=maxseconds)\n  File \"/opt/hostedtoolcache/Python/3.12.9/x64/lib/python3.12/site-packages/galaxy/tool_util/verify/interactor.py\", line 403, in wait_for\n    wait_on(func, what, walltime_exceeded)\n  File \"/opt/hostedtoolcache/Python/3.12.9/x64/lib/python3.12/site-packages/galaxy/tool_util/verify/wait.py\", line 38, in wait_on\n    value = function()\n            ^^^^^^^^^^\n  File \"/opt/hostedtoolcache/Python/3.12.9/x64/lib/python3.12/site-packages/galaxy/tool_util/verify/interactor.py\", line 399, in \u003clambda\u003e\n    self.wait_for(lambda: self.__job_ready(job_id, history_id), maxseconds=maxseconds)\n                          ^^^^^^^^^^^^^^^^^^^^^^^^^^^^^^^^^^^^\n  File \"/opt/hostedtoolcache/Python/3.12.9/x64/lib/python3.12/site-packages/galaxy/tool_util/verify/interactor.py\", line 747, in __job_ready\n    return self._state_ready(job_id, error_msg=\"Job in error state.\")\n           ^^^^^^^^^^^^^^^^^^^^^^^^^^^^^^^^^^^^^^^^^^^^^^^^^^^^^^^^^^\n  File \"/opt/hostedtoolcache/Python/3.12.9/x64/lib/python3.12/site-packages/galaxy/tool_util/verify/interactor.py\", line 839, in _state_ready\n    raise Exception(\nException: Job in error state.. tool_id: __DATA_FETCH__, exit_code: None, stderr: .\n", "status": "error", "test_index": 2, "time_seconds": 21.45449447631836, "tool_id": "ivar_variants", "tool_version": "1.4.3+galaxy1"}
            ]]></error>
        
    </testcase>
    
    <testcase classname="ivar_variants (Test #4)" name="3" time="42.51760411262512">
        
            
            <system-out><![CDATA[
            
            ]]></system-out>
            <system-err><![CDATA[
            [mpileup] 1 samples in 1 input files[mpileup] Max depth set to maximum value (2147483647)
            ]]></system-err>
        
    </testcase>
    
    <testcase classname="ivar_variants (Test #5)" name="4" time="44.98763108253479">
        
            
            <system-out><![CDATA[
            sampleDELINSSNPvariants0010
            ]]></system-out>
            <system-err><![CDATA[
            [mpileup] 1 samples in 1 input files[mpileup] Max depth set to maximum value (2147483647)
            ]]></system-err>
        
    </testcase>
    
    <testcase classname="lofreq_viterbi (Test #1)" name="0" time="49.126270055770874">
        
            
            <system-out><![CDATA[
            
            ]]></system-out>
            <system-err><![CDATA[
            [bam_sort_core] merging from 0 files and 4 in-memory blocks...
            ]]></system-err>
        
    </testcase>
    
    <testcase classname="lofreq_viterbi (Test #2)" name="1" time="38.1267032623291">
        
            
            <system-out><![CDATA[
            
            ]]></system-out>
            <system-err><![CDATA[
            [bam_sort_core] merging from 0 files and 4 in-memory blocks...
            ]]></system-err>
        
    </testcase>
    
    <testcase classname="poretools_events (Test #1)" name="0" time="71.39379215240479">
        
            
                <error type="error" message="Tool exit code: 1"><![CDATA[
                    { "inputs": {  "input": {   "id": "0ee6b37385b6fe11",   "src": "hda"  },  "precalled": false }, "job": {  "command_line": "poretools events  \u0027/galaxy/server/database/objects/1/6/6/dataset_16683644-6520-43fb-b282-0257a2bb71b1.dat\u0027 \u003e \u0027/galaxy/server/database/objects/8/0/6/dataset_806d7c5e-0a95-4cec-8e24-19d46a16e14d.dat\u0027",  "command_version": "",  "copied_from_job_id": null,  "create_time": "2025-03-21T01:06:38.956031",  "dependencies": [],  "exit_code": 1,  "external_id": "gxy-7tst9",  "galaxy_version": "24.1",  "handler": null,  "history_id": "d60d56cf2d7d9acd",  "id": "8c291e3e238b5cdb",  "inputs": {   "input": {    "id": "0ee6b37385b6fe11",    "src": "hda",    "uuid": "16683644-6520-43fb-b282-0257a2bb71b1"   }  },  "job_messages": [   {    "code_desc": "",    "desc": "Fatal error: Exit code 1 ()",    "error_level": 3,    "exit_code": 1,    "type": "exit_code"   },   {    "code_desc": "",    "desc": "Fatal error: ",    "error_level": 3,    "match": "Error:",    "stream": "stderr",    "type": "regex"   }  ],  "job_metrics": [   {    "name": "galaxy_slots",    "plugin": "core",    "raw_value": "1.0000000",    "title": "Cores Allocated",    "value": "1"   },   {    "name": "galaxy_memory_mb",    "plugin": "core",    "raw_value": "12240.0000000",    "title": "Memory Allocated (MB)",    "value": "12240"   },   {    "name": "start_epoch",    "plugin": "core",    "raw_value": "1742519229.0000000",    "title": "Job Start Time",    "value": "2025-03-21 01:07:09"   },   {    "name": "end_epoch",    "plugin": "core",    "raw_value": "1742519230.0000000",    "title": "Job End Time",    "value": "2025-03-21 01:07:10"   },   {    "name": "runtime_seconds",    "plugin": "core",    "raw_value": "1.0000000",    "title": "Job Runtime (Wall Clock)",    "value": "1 second"   }  ],  "job_runner_name": null,  "job_stderr": "",  "job_stdout": "",  "model_class": "Job",  "output_collections": {},  "outputs": {   "output": {    "id": "8c291e3e238b5cdb",    "src": "hda",    "uuid": "806d7c5e-0a95-4cec-8e24-19d46a16e14d"   }  },  "params": {   "__input_ext": "\"input\"",   "chromInfo": "\"/cvmfs/data.galaxyproject.org/managed/len/ucsc/?.len\"",   "dbkey": "\"?\"",   "precalled": "false"  },  "state": "error",  "stderr": "Traceback (most recent call last):\n  File \"/usr/local/bin/poretools\", line 11, in \u003cmodule\u003e\n    load_entry_point(\u0027poretools==0.6.0\u0027, \u0027console_scripts\u0027, \u0027poretools\u0027)()\n  File \"/usr/local/lib/python2.7/site-packages/poretools/poretools_main.py\", line 543, in main\n    args.func(parser, args)\n  File \"/usr/local/lib/python2.7/site-packages/poretools/poretools_main.py\", line 55, in run_subtool\n    submodule.run(parser, args)\n  File \"/usr/local/lib/python2.7/site-packages/poretools/events.py\", line 17, in run\n    for fast5 in Fast5File.Fast5FileSet(args.files):\n  File \"/usr/local/lib/python2.7/site-packages/poretools/Fast5File.py\", line 110, in next\n    shutil.rmtree(PORETOOLS_TMPDIR)\n  File \"/usr/local/lib/python2.7/shutil.py\", line 261, in rmtree\n    rmtree(fullname, ignore_errors, onerror)\n  File \"/usr/local/lib/python2.7/shutil.py\", line 270, in rmtree\n    onerror(os.rmdir, path, sys.exc_info())\n  File \"/usr/local/lib/python2.7/shutil.py\", line 268, in rmtree\n    os.rmdir(path)\nOSError: [Errno 39] Directory not empty: \u0027.poretools_tmp/test-data\u0027\n",  "stdout": "",  "tool_id": "toolshed.g2.bx.psu.edu/repos/iuc/poretools_events/poretools_events/0.6.1a1.1",  "tool_stderr": "Traceback (most recent call last):\n  File \"/usr/local/bin/poretools\", line 11, in \u003cmodule\u003e\n    load_entry_point(\u0027poretools==0.6.0\u0027, \u0027console_scripts\u0027, \u0027poretools\u0027)()\n  File \"/usr/local/lib/python2.7/site-packages/poretools/poretools_main.py\", line 543, in main\n    args.func(parser, args)\n  File \"/usr/local/lib/python2.7/site-packages/poretools/poretools_main.py\", line 55, in run_subtool\n    submodule.run(parser, args)\n  File \"/usr/local/lib/python2.7/site-packages/poretools/events.py\", line 17, in run\n    for fast5 in Fast5File.Fast5FileSet(args.files):\n  File \"/usr/local/lib/python2.7/site-packages/poretools/Fast5File.py\", line 110, in next\n    shutil.rmtree(PORETOOLS_TMPDIR)\n  File \"/usr/local/lib/python2.7/shutil.py\", line 261, in rmtree\n    rmtree(fullname, ignore_errors, onerror)\n  File \"/usr/local/lib/python2.7/shutil.py\", line 270, in rmtree\n    onerror(os.rmdir, path, sys.exc_info())\n  File \"/usr/local/lib/python2.7/shutil.py\", line 268, in rmtree\n    os.rmdir(path)\nOSError: [Errno 39] Directory not empty: \u0027.poretools_tmp/test-data\u0027\n",  "tool_stdout": "",  "update_time": "2025-03-21T01:07:28.112344",  "user_email": "tests@fake.org" }, "output_problems": [  "Job in error state.. tool_id: toolshed.g2.bx.psu.edu/repos/iuc/poretools_events/poretools_events/0.6.1a1.1, exit_code: 1, stderr: Traceback (most recent call last):\n  File \"/usr/local/bin/poretools\", line 11, in \u003cmodule\u003e\n    load_entry_point(\u0027poretools==0.6.0\u0027, \u0027console_scripts\u0027, \u0027poretools\u0027)()\n  File \"/usr/local/lib/python2.7/site-packages/poretools/poretools_main.py\", line 543, in main\n    args.func(parser, args)\n  File \"/usr/local/lib/python2.7/site-packages/poretools/poretools_main.py\", line 55, in run_subtool\n    submodule.run(parser, args)\n  File \"/usr/local/lib/python2.7/site-packages/poretools/events.py\", line 17, in run\n    for fast5 in Fast5File.Fast5FileSet(args.files):\n  File \"/usr/local/lib/python2.7/site-packages/poretools/Fast5File.py\", line 110, in next\n    shutil.rmtree(PORETOOLS_TMPDIR)\n  File \"/usr/local/lib/python2.7/shutil.py\", line 261, in rmtree\n    rmtree(fullname, ignore_errors, onerror)\n  File \"/usr/local/lib/python2.7/shutil.py\", line 270, in rmtree\n    onerror(os.rmdir, path, sys.exc_info())\n  File \"/usr/local/lib/python2.7/shutil.py\", line 268, in rmtree\n    os.rmdir(path)\nOSError: [Errno 39] Directory not empty: \u0027.poretools_tmp/test-data\u0027\n.",  "Job in error state.. tool_id: toolshed.g2.bx.psu.edu/repos/iuc/poretools_events/poretools_events/0.6.1a1.1, exit_code: 1, stderr: Traceback (most recent call last):\n  File \"/usr/local/bin/poretools\", line 11, in \u003cmodule\u003e\n    load_entry_point(\u0027poretools==0.6.0\u0027, \u0027console_scripts\u0027, \u0027poretools\u0027)()\n  File \"/usr/local/lib/python2.7/site-packages/poretools/poretools_main.py\", line 543, in main\n    args.func(parser, args)\n  File \"/usr/local/lib/python2.7/site-packages/poretools/poretools_main.py\", line 55, in run_subtool\n    submodule.run(parser, args)\n  File \"/usr/local/lib/python2.7/site-packages/poretools/events.py\", line 17, in run\n    for fast5 in Fast5File.Fast5FileSet(args.files):\n  File \"/usr/local/lib/python2.7/site-packages/poretools/Fast5File.py\", line 110, in next\n    shutil.rmtree(PORETOOLS_TMPDIR)\n  File \"/usr/local/lib/python2.7/shutil.py\", line 261, in rmtree\n    rmtree(fullname, ignore_errors, onerror)\n  File \"/usr/local/lib/python2.7/shutil.py\", line 270, in rmtree\n    onerror(os.rmdir, path, sys.exc_info())\n  File \"/usr/local/lib/python2.7/shutil.py\", line 268, in rmtree\n    os.rmdir(path)\nOSError: [Errno 39] Directory not empty: \u0027.poretools_tmp/test-data\u0027\n." ], "status": "failure", "test_index": 0, "time_seconds": 71.39379215240479, "tool_id": "poretools_events", "tool_version": "0.6.1a1.1"}
                ]]></error>
            
            <system-out><![CDATA[
            
            ]]></system-out>
            <system-err><![CDATA[
            Traceback (most recent call last):  File "/usr/local/bin/poretools", line 11, in <module>    load_entry_point('poretools==0.6.0', 'console_scripts', 'poretools')()  File "/usr/local/lib/python2.7/site-packages/poretools/poretools_main.py", line 543, in main    args.func(parser, args)  File "/usr/local/lib/python2.7/site-packages/poretools/poretools_main.py", line 55, in run_subtool    submodule.run(parser, args)  File "/usr/local/lib/python2.7/site-packages/poretools/events.py", line 17, in run    for fast5 in Fast5File.Fast5FileSet(args.files):  File "/usr/local/lib/python2.7/site-packages/poretools/Fast5File.py", line 110, in next    shutil.rmtree(PORETOOLS_TMPDIR)  File "/usr/local/lib/python2.7/shutil.py", line 261, in rmtree    rmtree(fullname, ignore_errors, onerror)  File "/usr/local/lib/python2.7/shutil.py", line 270, in rmtree    onerror(os.rmdir, path, sys.exc_info())  File "/usr/local/lib/python2.7/shutil.py", line 268, in rmtree    os.rmdir(path)OSError: [Errno 39] Directory not empty: '.poretools_tmp/test-data'
            ]]></system-err>
        
    </testcase>
    
    <testcase classname="poretools_events (Test #2)" name="1" time="37.519092082977295">
        
            
                <error type="error" message="Tool exit code: 1"><![CDATA[
                    { "inputs": {  "input": {   "id": "2fd6ded9f6c2ba7e",   "src": "hda"  },  "precalled": true }, "job": {  "command_line": "poretools events --pre-basecalled \u0027/galaxy/server/database/objects/3/d/8/dataset_3d8227e2-9119-42e5-b32d-f0346368f4e7.dat\u0027 \u003e \u0027/galaxy/server/database/objects/b/2/6/dataset_b2617410-4c32-41f1-bef5-c4e933a9f6f8.dat\u0027",  "command_version": "",  "copied_from_job_id": null,  "create_time": "2025-03-21T01:07:51.074998",  "dependencies": [],  "exit_code": 1,  "external_id": "gxy-btdpk",  "galaxy_version": "24.1",  "handler": null,  "history_id": "d60d56cf2d7d9acd",  "id": "e4504e4f18a71bd6",  "inputs": {   "input": {    "id": "2fd6ded9f6c2ba7e",    "src": "hda",    "uuid": "3d8227e2-9119-42e5-b32d-f0346368f4e7"   }  },  "job_messages": [   {    "code_desc": "",    "desc": "Fatal error: Exit code 1 ()",    "error_level": 3,    "exit_code": 1,    "type": "exit_code"   },   {    "code_desc": "",    "desc": "Fatal error: ",    "error_level": 3,    "match": "Error:",    "stream": "stderr",    "type": "regex"   }  ],  "job_metrics": [   {    "name": "galaxy_slots",    "plugin": "core",    "raw_value": "1.0000000",    "title": "Cores Allocated",    "value": "1"   },   {    "name": "galaxy_memory_mb",    "plugin": "core",    "raw_value": "12240.0000000",    "title": "Memory Allocated (MB)",    "value": "12240"   },   {    "name": "start_epoch",    "plugin": "core",    "raw_value": "1742519273.0000000",    "title": "Job Start Time",    "value": "2025-03-21 01:07:53"   },   {    "name": "end_epoch",    "plugin": "core",    "raw_value": "1742519274.0000000",    "title": "Job End Time",    "value": "2025-03-21 01:07:54"   },   {    "name": "runtime_seconds",    "plugin": "core",    "raw_value": "1.0000000",    "title": "Job Runtime (Wall Clock)",    "value": "1 second"   }  ],  "job_runner_name": null,  "job_stderr": "",  "job_stdout": "",  "model_class": "Job",  "output_collections": {},  "outputs": {   "output": {    "id": "e4504e4f18a71bd6",    "src": "hda",    "uuid": "b2617410-4c32-41f1-bef5-c4e933a9f6f8"   }  },  "params": {   "__input_ext": "\"input\"",   "chromInfo": "\"/cvmfs/data.galaxyproject.org/managed/len/ucsc/?.len\"",   "dbkey": "\"?\"",   "precalled": "true"  },  "state": "error",  "stderr": "Traceback (most recent call last):\n  File \"/usr/local/bin/poretools\", line 11, in \u003cmodule\u003e\n    load_entry_point(\u0027poretools==0.6.0\u0027, \u0027console_scripts\u0027, \u0027poretools\u0027)()\n  File \"/usr/local/lib/python2.7/site-packages/poretools/poretools_main.py\", line 543, in main\n    args.func(parser, args)\n  File \"/usr/local/lib/python2.7/site-packages/poretools/poretools_main.py\", line 55, in run_subtool\n    submodule.run(parser, args)\n  File \"/usr/local/lib/python2.7/site-packages/poretools/events.py\", line 13, in run\n    for fast5 in Fast5File.Fast5FileSet(args.files):\n  File \"/usr/local/lib/python2.7/site-packages/poretools/Fast5File.py\", line 110, in next\n    shutil.rmtree(PORETOOLS_TMPDIR)\n  File \"/usr/local/lib/python2.7/shutil.py\", line 261, in rmtree\n    rmtree(fullname, ignore_errors, onerror)\n  File \"/usr/local/lib/python2.7/shutil.py\", line 270, in rmtree\n    onerror(os.rmdir, path, sys.exc_info())\n  File \"/usr/local/lib/python2.7/shutil.py\", line 268, in rmtree\n    os.rmdir(path)\nOSError: [Errno 39] Directory not empty: \u0027.poretools_tmp/test-data\u0027\n",  "stdout": "",  "tool_id": "toolshed.g2.bx.psu.edu/repos/iuc/poretools_events/poretools_events/0.6.1a1.1",  "tool_stderr": "Traceback (most recent call last):\n  File \"/usr/local/bin/poretools\", line 11, in \u003cmodule\u003e\n    load_entry_point(\u0027poretools==0.6.0\u0027, \u0027console_scripts\u0027, \u0027poretools\u0027)()\n  File \"/usr/local/lib/python2.7/site-packages/poretools/poretools_main.py\", line 543, in main\n    args.func(parser, args)\n  File \"/usr/local/lib/python2.7/site-packages/poretools/poretools_main.py\", line 55, in run_subtool\n    submodule.run(parser, args)\n  File \"/usr/local/lib/python2.7/site-packages/poretools/events.py\", line 13, in run\n    for fast5 in Fast5File.Fast5FileSet(args.files):\n  File \"/usr/local/lib/python2.7/site-packages/poretools/Fast5File.py\", line 110, in next\n    shutil.rmtree(PORETOOLS_TMPDIR)\n  File \"/usr/local/lib/python2.7/shutil.py\", line 261, in rmtree\n    rmtree(fullname, ignore_errors, onerror)\n  File \"/usr/local/lib/python2.7/shutil.py\", line 270, in rmtree\n    onerror(os.rmdir, path, sys.exc_info())\n  File \"/usr/local/lib/python2.7/shutil.py\", line 268, in rmtree\n    os.rmdir(path)\nOSError: [Errno 39] Directory not empty: \u0027.poretools_tmp/test-data\u0027\n",  "tool_stdout": "",  "update_time": "2025-03-21T01:08:05.826789",  "user_email": "tests@fake.org" }, "output_problems": [  "Job in error state.. tool_id: toolshed.g2.bx.psu.edu/repos/iuc/poretools_events/poretools_events/0.6.1a1.1, exit_code: 1, stderr: Traceback (most recent call last):\n  File \"/usr/local/bin/poretools\", line 11, in \u003cmodule\u003e\n    load_entry_point(\u0027poretools==0.6.0\u0027, \u0027console_scripts\u0027, \u0027poretools\u0027)()\n  File \"/usr/local/lib/python2.7/site-packages/poretools/poretools_main.py\", line 543, in main\n    args.func(parser, args)\n  File \"/usr/local/lib/python2.7/site-packages/poretools/poretools_main.py\", line 55, in run_subtool\n    submodule.run(parser, args)\n  File \"/usr/local/lib/python2.7/site-packages/poretools/events.py\", line 13, in run\n    for fast5 in Fast5File.Fast5FileSet(args.files):\n  File \"/usr/local/lib/python2.7/site-packages/poretools/Fast5File.py\", line 110, in next\n    shutil.rmtree(PORETOOLS_TMPDIR)\n  File \"/usr/local/lib/python2.7/shutil.py\", line 261, in rmtree\n    rmtree(fullname, ignore_errors, onerror)\n  File \"/usr/local/lib/python2.7/shutil.py\", line 270, in rmtree\n    onerror(os.rmdir, path, sys.exc_info())\n  File \"/usr/local/lib/python2.7/shutil.py\", line 268, in rmtree\n    os.rmdir(path)\nOSError: [Errno 39] Directory not empty: \u0027.poretools_tmp/test-data\u0027\n.",  "Job in error state.. tool_id: toolshed.g2.bx.psu.edu/repos/iuc/poretools_events/poretools_events/0.6.1a1.1, exit_code: 1, stderr: Traceback (most recent call last):\n  File \"/usr/local/bin/poretools\", line 11, in \u003cmodule\u003e\n    load_entry_point(\u0027poretools==0.6.0\u0027, \u0027console_scripts\u0027, \u0027poretools\u0027)()\n  File \"/usr/local/lib/python2.7/site-packages/poretools/poretools_main.py\", line 543, in main\n    args.func(parser, args)\n  File \"/usr/local/lib/python2.7/site-packages/poretools/poretools_main.py\", line 55, in run_subtool\n    submodule.run(parser, args)\n  File \"/usr/local/lib/python2.7/site-packages/poretools/events.py\", line 13, in run\n    for fast5 in Fast5File.Fast5FileSet(args.files):\n  File \"/usr/local/lib/python2.7/site-packages/poretools/Fast5File.py\", line 110, in next\n    shutil.rmtree(PORETOOLS_TMPDIR)\n  File \"/usr/local/lib/python2.7/shutil.py\", line 261, in rmtree\n    rmtree(fullname, ignore_errors, onerror)\n  File \"/usr/local/lib/python2.7/shutil.py\", line 270, in rmtree\n    onerror(os.rmdir, path, sys.exc_info())\n  File \"/usr/local/lib/python2.7/shutil.py\", line 268, in rmtree\n    os.rmdir(path)\nOSError: [Errno 39] Directory not empty: \u0027.poretools_tmp/test-data\u0027\n." ], "status": "failure", "test_index": 1, "time_seconds": 37.519092082977295, "tool_id": "poretools_events", "tool_version": "0.6.1a1.1"}
                ]]></error>
            
            <system-out><![CDATA[
            
            ]]></system-out>
            <system-err><![CDATA[
            Traceback (most recent call last):  File "/usr/local/bin/poretools", line 11, in <module>    load_entry_point('poretools==0.6.0', 'console_scripts', 'poretools')()  File "/usr/local/lib/python2.7/site-packages/poretools/poretools_main.py", line 543, in main    args.func(parser, args)  File "/usr/local/lib/python2.7/site-packages/poretools/poretools_main.py", line 55, in run_subtool    submodule.run(parser, args)  File "/usr/local/lib/python2.7/site-packages/poretools/events.py", line 13, in run    for fast5 in Fast5File.Fast5FileSet(args.files):  File "/usr/local/lib/python2.7/site-packages/poretools/Fast5File.py", line 110, in next    shutil.rmtree(PORETOOLS_TMPDIR)  File "/usr/local/lib/python2.7/shutil.py", line 261, in rmtree    rmtree(fullname, ignore_errors, onerror)  File "/usr/local/lib/python2.7/shutil.py", line 270, in rmtree    onerror(os.rmdir, path, sys.exc_info())  File "/usr/local/lib/python2.7/shutil.py", line 268, in rmtree    os.rmdir(path)OSError: [Errno 39] Directory not empty: '.poretools_tmp/test-data'
            ]]></system-err>
        
    </testcase>
    
    <testcase classname="samtools_merge (Test #1)" name="0" time="77.2214744091034">
        
            
            <system-out><![CDATA[
            
            ]]></system-out>
            <system-err><![CDATA[
            
            ]]></system-err>
        
    </testcase>
    
    <testcase classname="samtools_merge (Test #2)" name="1" time="20.451323986053467">
        
            <error type="error" message="Input staging problem: Traceback (most recent call last):
  File "/opt/hostedtoolcache/Python/3.12.9/x64/lib/python3.12/site-packages/galaxy/tool_util/verify/interactor.py", line 1434, in verify_tool
    stage_data_in_history(
  File "/opt/hostedtoolcache/Python/3.12.9/x64/lib/python3.12/site-packages/galaxy/tool_util/verify/interactor.py", line 175, in stage_data_in_history
    staging_interface.handle_jobs()
  File "/opt/hostedtoolcache/Python/3.12.9/x64/lib/python3.12/site-packages/galaxy/tool_util/verify/interactor.py", line 212, in handle_jobs
    self.galaxy_interactor.wait_for_job(job_response["id"], job_response["history_id"], self.maxseconds)
  File "/opt/hostedtoolcache/Python/3.12.9/x64/lib/python3.12/site-packages/galaxy/tool_util/verify/interactor.py", line 399, in wait_for_job
    self.wait_for(lambda: self.__job_ready(job_id, history_id), maxseconds=maxseconds)
  File "/opt/hostedtoolcache/Python/3.12.9/x64/lib/python3.12/site-packages/galaxy/tool_util/verify/interactor.py", line 403, in wait_for
    wait_on(func, what, walltime_exceeded)
  File "/opt/hostedtoolcache/Python/3.12.9/x64/lib/python3.12/site-packages/galaxy/tool_util/verify/wait.py", line 38, in wait_on
    value = function()
            ^^^^^^^^^^
  File "/opt/hostedtoolcache/Python/3.12.9/x64/lib/python3.12/site-packages/galaxy/tool_util/verify/interactor.py", line 399, in <lambda>
    self.wait_for(lambda: self.__job_ready(job_id, history_id), maxseconds=maxseconds)
                          ^^^^^^^^^^^^^^^^^^^^^^^^^^^^^^^^^^^^
  File "/opt/hostedtoolcache/Python/3.12.9/x64/lib/python3.12/site-packages/galaxy/tool_util/verify/interactor.py", line 747, in __job_ready
    return self._state_ready(job_id, error_msg="Job in error state.")
           ^^^^^^^^^^^^^^^^^^^^^^^^^^^^^^^^^^^^^^^^^^^^^^^^^^^^^^^^^^
  File "/opt/hostedtoolcache/Python/3.12.9/x64/lib/python3.12/site-packages/galaxy/tool_util/verify/interactor.py", line 839, in _state_ready
    raise Exception(
Exception: Job in error state.. tool_id: __DATA_FETCH__, exit_code: None, stderr: .
"><![CDATA[
                { "execution_problem": "Input staging problem: Traceback (most recent call last):\n  File \"/opt/hostedtoolcache/Python/3.12.9/x64/lib/python3.12/site-packages/galaxy/tool_util/verify/interactor.py\", line 1434, in verify_tool\n    stage_data_in_history(\n  File \"/opt/hostedtoolcache/Python/3.12.9/x64/lib/python3.12/site-packages/galaxy/tool_util/verify/interactor.py\", line 175, in stage_data_in_history\n    staging_interface.handle_jobs()\n  File \"/opt/hostedtoolcache/Python/3.12.9/x64/lib/python3.12/site-packages/galaxy/tool_util/verify/interactor.py\", line 212, in handle_jobs\n    self.galaxy_interactor.wait_for_job(job_response[\"id\"], job_response[\"history_id\"], self.maxseconds)\n  File \"/opt/hostedtoolcache/Python/3.12.9/x64/lib/python3.12/site-packages/galaxy/tool_util/verify/interactor.py\", line 399, in wait_for_job\n    self.wait_for(lambda: self.__job_ready(job_id, history_id), maxseconds=maxseconds)\n  File \"/opt/hostedtoolcache/Python/3.12.9/x64/lib/python3.12/site-packages/galaxy/tool_util/verify/interactor.py\", line 403, in wait_for\n    wait_on(func, what, walltime_exceeded)\n  File \"/opt/hostedtoolcache/Python/3.12.9/x64/lib/python3.12/site-packages/galaxy/tool_util/verify/wait.py\", line 38, in wait_on\n    value = function()\n            ^^^^^^^^^^\n  File \"/opt/hostedtoolcache/Python/3.12.9/x64/lib/python3.12/site-packages/galaxy/tool_util/verify/interactor.py\", line 399, in \u003clambda\u003e\n    self.wait_for(lambda: self.__job_ready(job_id, history_id), maxseconds=maxseconds)\n                          ^^^^^^^^^^^^^^^^^^^^^^^^^^^^^^^^^^^^\n  File \"/opt/hostedtoolcache/Python/3.12.9/x64/lib/python3.12/site-packages/galaxy/tool_util/verify/interactor.py\", line 747, in __job_ready\n    return self._state_ready(job_id, error_msg=\"Job in error state.\")\n           ^^^^^^^^^^^^^^^^^^^^^^^^^^^^^^^^^^^^^^^^^^^^^^^^^^^^^^^^^^\n  File \"/opt/hostedtoolcache/Python/3.12.9/x64/lib/python3.12/site-packages/galaxy/tool_util/verify/interactor.py\", line 839, in _state_ready\n    raise Exception(\nException: Job in error state.. tool_id: __DATA_FETCH__, exit_code: None, stderr: .\n", "status": "error", "test_index": 1, "time_seconds": 20.451323986053467, "tool_id": "samtools_merge", "tool_version": "1.9"}
            ]]></error>
        
    </testcase>
    
    <testcase classname="samtools_merge (Test #3)" name="2" time="34.54497313499451">
        
            
            <system-out><![CDATA[
            
            ]]></system-out>
            <system-err><![CDATA[
            
            ]]></system-err>
        
    </testcase>
    
    <testcase classname="samtools_merge (Test #4)" name="3" time="40.26699352264404">
        
            
            <system-out><![CDATA[
            
            ]]></system-out>
            <system-err><![CDATA[
            [bam_translate] PG tag "colt" on read "r001" encountered with no corresponding entry in header, tag lost. Unknown tags are only reported once per input file for each tag ID.
            ]]></system-err>
        
    </testcase>
    
    <testcase classname="samtools_merge (Test #5)" name="4" time="34.21992087364197">
        
            
            <system-out><![CDATA[
            
            ]]></system-out>
            <system-err><![CDATA[
            [bam_translate] PG tag "colt" on read "r001" encountered with no corresponding entry in header, tag lost. Unknown tags are only reported once per input file for each tag ID.
            ]]></system-err>
        
    </testcase>
    
    <testcase classname="vcfannotategenotypes (Test #1)" name="0" time="42.237847089767456">
        
            
            <system-out><![CDATA[
            
            ]]></system-out>
            <system-err><![CDATA[
            
            ]]></system-err>
        
    </testcase>
    
    <testcase classname="vcfsort (Test #1)" name="0" time="42.34003019332886">
        
            
            <system-out><![CDATA[
            
            ]]></system-out>
            <system-err><![CDATA[
            
            ]]></system-err>
        
    </testcase>
    
    <testcase classname="volcanoplot (Test #1)" name="0" time="65.44094967842102">
        
            
            <system-out><![CDATA[
            [1] "Header row detected"null device           1 R version 4.0.5 (2021-03-31)Platform: x86_64-conda-linux-gnu (64-bit)Running under: Debian GNU/Linux 10 (buster)Matrix products: defaultBLAS/LAPACK: /usr/local/lib/libopenblasp-r0.3.15.solocale: [1] LC_CTYPE=C.UTF-8       LC_NUMERIC=C           LC_TIME=C.UTF-8        [4] LC_COLLATE=C.UTF-8     LC_MONETARY=C.UTF-8    LC_MESSAGES=C.UTF-8    [7] LC_PAPER=C.UTF-8       LC_NAME=C              LC_ADDRESS=C          [10] LC_TELEPHONE=C         LC_MEASUREMENT=C.UTF-8 LC_IDENTIFICATION=C   attached base packages:[1] stats     graphics  grDevices utils     datasets  methods   base     other attached packages:[1] ggrepel_0.9.1 ggplot2_3.3.3 dplyr_1.0.6  loaded via a namespace (and not attached): [1] Rcpp_1.0.6       magrittr_2.0.1   tidyselect_1.1.1 munsell_0.5.0    [5] colorspace_2.0-1 R6_2.5.0         rlang_0.4.11     fansi_0.5.0      [9] grid_4.0.5       gtable_0.3.0     utf8_1.2.1       withr_2.4.2     [13] ellipsis_0.3.2   digest_0.6.27    tibble_3.1.2     lifecycle_1.0.0 [17] crayon_1.4.1     purrr_0.3.4      farver_2.1.0     vctrs_0.3.8     [21] glue_1.4.2       labeling_0.4.2   compiler_4.0.5   pillar_1.6.1    [25] generics_0.1.0   scales_1.1.1     pkgconfig_2.0.3 
            ]]></system-out>
            <system-err><![CDATA[
            Warning message:In Sys.setlocale("LC_MESSAGES", "en_US.UTF-8") :  OS reports request to set locale to "en_US.UTF-8" cannot be honored
            ]]></system-err>
        
    </testcase>
    
    <testcase classname="volcanoplot (Test #2)" name="1" time="39.47517251968384">
        
            
            <system-out><![CDATA[
            [1] "Header row detected"null device           1 R version 4.0.5 (2021-03-31)Platform: x86_64-conda-linux-gnu (64-bit)Running under: Debian GNU/Linux 10 (buster)Matrix products: defaultBLAS/LAPACK: /usr/local/lib/libopenblasp-r0.3.15.solocale: [1] LC_CTYPE=C.UTF-8       LC_NUMERIC=C           LC_TIME=C.UTF-8        [4] LC_COLLATE=C.UTF-8     LC_MONETARY=C.UTF-8    LC_MESSAGES=C.UTF-8    [7] LC_PAPER=C.UTF-8       LC_NAME=C              LC_ADDRESS=C          [10] LC_TELEPHONE=C         LC_MEASUREMENT=C.UTF-8 LC_IDENTIFICATION=C   attached base packages:[1] stats     graphics  grDevices utils     datasets  methods   base     other attached packages:[1] ggrepel_0.9.1 ggplot2_3.3.3 dplyr_1.0.6  loaded via a namespace (and not attached): [1] Rcpp_1.0.6       magrittr_2.0.1   tidyselect_1.1.1 munsell_0.5.0    [5] colorspace_2.0-1 R6_2.5.0         rlang_0.4.11     fansi_0.5.0      [9] grid_4.0.5       gtable_0.3.0     utf8_1.2.1       withr_2.4.2     [13] ellipsis_0.3.2   digest_0.6.27    tibble_3.1.2     lifecycle_1.0.0 [17] crayon_1.4.1     purrr_0.3.4      farver_2.1.0     vctrs_0.3.8     [21] glue_1.4.2       labeling_0.4.2   compiler_4.0.5   pillar_1.6.1    [25] generics_0.1.0   scales_1.1.1     pkgconfig_2.0.3 
            ]]></system-out>
            <system-err><![CDATA[
            Warning message:In Sys.setlocale("LC_MESSAGES", "en_US.UTF-8") :  OS reports request to set locale to "en_US.UTF-8" cannot be honored
            ]]></system-err>
        
    </testcase>
    
    <testcase classname="volcanoplot (Test #3)" name="2" time="40.38689303398132">
        
            
            <system-out><![CDATA[
            null device           1 R version 4.0.5 (2021-03-31)Platform: x86_64-conda-linux-gnu (64-bit)Running under: Debian GNU/Linux 10 (buster)Matrix products: defaultBLAS/LAPACK: /usr/local/lib/libopenblasp-r0.3.15.solocale: [1] LC_CTYPE=C.UTF-8       LC_NUMERIC=C           LC_TIME=C.UTF-8        [4] LC_COLLATE=C.UTF-8     LC_MONETARY=C.UTF-8    LC_MESSAGES=C.UTF-8    [7] LC_PAPER=C.UTF-8       LC_NAME=C              LC_ADDRESS=C          [10] LC_TELEPHONE=C         LC_MEASUREMENT=C.UTF-8 LC_IDENTIFICATION=C   attached base packages:[1] stats     graphics  grDevices utils     datasets  methods   base     other attached packages:[1] ggrepel_0.9.1 ggplot2_3.3.3 dplyr_1.0.6  loaded via a namespace (and not attached): [1] Rcpp_1.0.6       magrittr_2.0.1   tidyselect_1.1.1 munsell_0.5.0    [5] colorspace_2.0-1 R6_2.5.0         rlang_0.4.11     fansi_0.5.0      [9] grid_4.0.5       gtable_0.3.0     utf8_1.2.1       withr_2.4.2     [13] ellipsis_0.3.2   digest_0.6.27    tibble_3.1.2     lifecycle_1.0.0 [17] crayon_1.4.1     purrr_0.3.4      farver_2.1.0     vctrs_0.3.8     [21] glue_1.4.2       labeling_0.4.2   compiler_4.0.5   pillar_1.6.1    [25] generics_0.1.0   scales_1.1.1     pkgconfig_2.0.3 
            ]]></system-out>
            <system-err><![CDATA[
            Warning message:In Sys.setlocale("LC_MESSAGES", "en_US.UTF-8") :  OS reports request to set locale to "en_US.UTF-8" cannot be honored
            ]]></system-err>
        
    </testcase>
    
    <testcase classname="volcanoplot (Test #4)" name="3" time="30.66558599472046">
        
            
                <error type="error" message="Tool exit code: None"><![CDATA[
                    { "inputs": {  "fdr_col": "4",  "input": {   "id": "b9ecbe464c4e003d",   "src": "hda"  },  "label_col": "1",  "labels|label_file": {   "id": "04771bcd308254b6",   "src": "hda"  },  "labels|label_select": "file",  "lfc_col": "2",  "lfc_thresh": "0",  "pval_col": "3",  "shape_col": "5",  "shape_or_facet": "facet" }, "job": {  "command_line": "Rscript \u0027/galaxy/server/database/jobs_directory/000/88/configs/tmp5k3ggqtz\u0027",  "command_version": null,  "copied_from_job_id": null,  "create_time": "2025-03-21T01:16:38.560835",  "dependencies": [],  "exit_code": null,  "external_id": "gxy-hgmw9",  "galaxy_version": "24.1",  "handler": null,  "history_id": "d60d56cf2d7d9acd",  "id": "0b634973f5667538",  "inputs": {   "input": {    "id": "b9ecbe464c4e003d",    "src": "hda",    "uuid": "8950b232-daef-43c5-b5f0-aef041536f89"   },   "labels|label_file": {    "id": "04771bcd308254b6",    "src": "hda",    "uuid": "38f0b0a7-0418-4d42-8358-873695761d4a"   }  },  "job_messages": null,  "job_metrics": [],  "job_runner_name": null,  "job_stderr": null,  "job_stdout": null,  "model_class": "Job",  "output_collections": {},  "outputs": {   "plot": {    "id": "0690d0f5ea3baf17",    "src": "hda",    "uuid": "d5a315d1-f0e3-4b16-98c3-90b5b8cd3047"   }  },  "params": {   "__input_ext": "\"input\"",   "chromInfo": "\"/cvmfs/data.galaxyproject.org/managed/len/ucsc/?.len\"",   "dbkey": "\"?\"",   "fdr_col": "\"4\"",   "header": "\"auto\"",   "label_col": "\"1\"",   "labels": "{\"__current_case__\": 1, \"label_file\": {\"values\": [{\"id\": 90, \"src\": \"hda\"}]}, \"label_select\": \"file\"}",   "lfc_col": "\"2\"",   "lfc_thresh": "\"0.0\"",   "out_options": "{\"rscript_out\": false}",   "plot_options": "{\"boxes\": false, \"legend\": null, \"legend_labs\": \"Down,Not Sig,Up\", \"title\": null, \"xlab\": null, \"xmax\": \"\", \"xmin\": \"\", \"ylab\": null, \"ymax\": \"\"}",   "pval_col": "\"3\"",   "shape_col": "\"5\"",   "shape_or_facet": "\"facet\"",   "signif_thresh": "\"0.05\""  },  "state": "error",  "stderr": "Warning message:\nIn Sys.setlocale(\"LC_MESSAGES\", \"en_US.UTF-8\") :\n  OS reports request to set locale to \"en_US.UTF-8\" cannot be honored\n",  "stdout": "[1] \"Header row detected\"\nnull device \n          1 \nR version 4.0.5 (2021-03-31)\nPlatform: x86_64-conda-linux-gnu (64-bit)\nRunning under: Debian GNU/Linux 10 (buster)\n\nMatrix products: default\nBLAS/LAPACK: /usr/local/lib/libopenblasp-r0.3.15.so\n\nlocale:\n [1] LC_CTYPE=C.UTF-8       LC_NUMERIC=C           LC_TIME=C.UTF-8       \n [4] LC_COLLATE=C.UTF-8     LC_MONETARY=C.UTF-8    LC_MESSAGES=C.UTF-8   \n [7] LC_PAPER=C.UTF-8       LC_NAME=C              LC_ADDRESS=C          \n[10] LC_TELEPHONE=C         LC_MEASUREMENT=C.UTF-8 LC_IDENTIFICATION=C   \n\nattached base packages:\n[1] stats     graphics  grDevices utils     datasets  methods   base     \n\nother attached packages:\n[1] ggrepel_0.9.1 ggplot2_3.3.3 dplyr_1.0.6  \n\nloaded via a namespace (and not attached):\n [1] Rcpp_1.0.6       magrittr_2.0.1   tidyselect_1.1.1 munsell_0.5.0   \n [5] colorspace_2.0-1 R6_2.5.0         rlang_0.4.11     fansi_0.5.0     \n [9] grid_4.0.5       gtable_0.3.0     utf8_1.2.1       withr_2.4.2     \n[13] ellipsis_0.3.2   digest_0.6.27    tibble_3.1.2     lifecycle_1.0.0 \n[17] crayon_1.4.1     purrr_0.3.4      farver_2.1.0     vctrs_0.3.8     \n[21] glue_1.4.2       labeling_0.4.2   compiler_4.0.5   pillar_1.6.1    \n[25] generics_0.1.0   scales_1.1.1     pkgconfig_2.0.3 \n",  "tool_id": "toolshed.g2.bx.psu.edu/repos/iuc/volcanoplot/volcanoplot/0.0.7",  "tool_stderr": "Warning message:\nIn Sys.setlocale(\"LC_MESSAGES\", \"en_US.UTF-8\") :\n  OS reports request to set locale to \"en_US.UTF-8\" cannot be honored\n",  "tool_stdout": "[1] \"Header row detected\"\nnull device \n          1 \nR version 4.0.5 (2021-03-31)\nPlatform: x86_64-conda-linux-gnu (64-bit)\nRunning under: Debian GNU/Linux 10 (buster)\n\nMatrix products: default\nBLAS/LAPACK: /usr/local/lib/libopenblasp-r0.3.15.so\n\nlocale:\n [1] LC_CTYPE=C.UTF-8       LC_NUMERIC=C           LC_TIME=C.UTF-8       \n [4] LC_COLLATE=C.UTF-8     LC_MONETARY=C.UTF-8    LC_MESSAGES=C.UTF-8   \n [7] LC_PAPER=C.UTF-8       LC_NAME=C              LC_ADDRESS=C          \n[10] LC_TELEPHONE=C         LC_MEASUREMENT=C.UTF-8 LC_IDENTIFICATION=C   \n\nattached base packages:\n[1] stats     graphics  grDevices utils     datasets  methods   base     \n\nother attached packages:\n[1] ggrepel_0.9.1 ggplot2_3.3.3 dplyr_1.0.6  \n\nloaded via a namespace (and not attached):\n [1] Rcpp_1.0.6       magrittr_2.0.1   tidyselect_1.1.1 munsell_0.5.0   \n [5] colorspace_2.0-1 R6_2.5.0         rlang_0.4.11     fansi_0.5.0     \n [9] grid_4.0.5       gtable_0.3.0     utf8_1.2.1       withr_2.4.2     \n[13] ellipsis_0.3.2   digest_0.6.27    tibble_3.1.2     lifecycle_1.0.0 \n[17] crayon_1.4.1     purrr_0.3.4      farver_2.1.0     vctrs_0.3.8     \n[21] glue_1.4.2       labeling_0.4.2   compiler_4.0.5   pillar_1.6.1    \n[25] generics_0.1.0   scales_1.1.1     pkgconfig_2.0.3 \n",  "update_time": "2025-03-21T01:16:47.536306",  "user_email": "tests@fake.org" }, "output_problems": [  "Job in error state.. tool_id: toolshed.g2.bx.psu.edu/repos/iuc/volcanoplot/volcanoplot/0.0.7, exit_code: None, stderr: Warning message:\nIn Sys.setlocale(\"LC_MESSAGES\", \"en_US.UTF-8\") :\n  OS reports request to set locale to \"en_US.UTF-8\" cannot be honored\n.",  "Job in error state.. tool_id: toolshed.g2.bx.psu.edu/repos/iuc/volcanoplot/volcanoplot/0.0.7, exit_code: None, stderr: Warning message:\nIn Sys.setlocale(\"LC_MESSAGES\", \"en_US.UTF-8\") :\n  OS reports request to set locale to \"en_US.UTF-8\" cannot be honored\n." ], "status": "failure", "test_index": 3, "time_seconds": 30.66558599472046, "tool_id": "volcanoplot", "tool_version": "0.0.7"}
                ]]></error>
            
            <system-out><![CDATA[
            [1] "Header row detected"null device           1 R version 4.0.5 (2021-03-31)Platform: x86_64-conda-linux-gnu (64-bit)Running under: Debian GNU/Linux 10 (buster)Matrix products: defaultBLAS/LAPACK: /usr/local/lib/libopenblasp-r0.3.15.solocale: [1] LC_CTYPE=C.UTF-8       LC_NUMERIC=C           LC_TIME=C.UTF-8        [4] LC_COLLATE=C.UTF-8     LC_MONETARY=C.UTF-8    LC_MESSAGES=C.UTF-8    [7] LC_PAPER=C.UTF-8       LC_NAME=C              LC_ADDRESS=C          [10] LC_TELEPHONE=C         LC_MEASUREMENT=C.UTF-8 LC_IDENTIFICATION=C   attached base packages:[1] stats     graphics  grDevices utils     datasets  methods   base     other attached packages:[1] ggrepel_0.9.1 ggplot2_3.3.3 dplyr_1.0.6  loaded via a namespace (and not attached): [1] Rcpp_1.0.6       magrittr_2.0.1   tidyselect_1.1.1 munsell_0.5.0    [5] colorspace_2.0-1 R6_2.5.0         rlang_0.4.11     fansi_0.5.0      [9] grid_4.0.5       gtable_0.3.0     utf8_1.2.1       withr_2.4.2     [13] ellipsis_0.3.2   digest_0.6.27    tibble_3.1.2     lifecycle_1.0.0 [17] crayon_1.4.1     purrr_0.3.4      farver_2.1.0     vctrs_0.3.8     [21] glue_1.4.2       labeling_0.4.2   compiler_4.0.5   pillar_1.6.1    [25] generics_0.1.0   scales_1.1.1     pkgconfig_2.0.3 
            ]]></system-out>
            <system-err><![CDATA[
            Warning message:In Sys.setlocale("LC_MESSAGES", "en_US.UTF-8") :  OS reports request to set locale to "en_US.UTF-8" cannot be honored
            ]]></system-err>
        
    </testcase>
    
    <testcase classname="volcanoplot (Test #5)" name="4" time="38.44981241226196">
        
            
            <system-out><![CDATA[
            [1] "Header row detected"null device           1 R version 4.0.5 (2021-03-31)Platform: x86_64-conda-linux-gnu (64-bit)Running under: Debian GNU/Linux 10 (buster)Matrix products: defaultBLAS/LAPACK: /usr/local/lib/libopenblasp-r0.3.15.solocale: [1] LC_CTYPE=C.UTF-8       LC_NUMERIC=C           LC_TIME=C.UTF-8        [4] LC_COLLATE=C.UTF-8     LC_MONETARY=C.UTF-8    LC_MESSAGES=C.UTF-8    [7] LC_PAPER=C.UTF-8       LC_NAME=C              LC_ADDRESS=C          [10] LC_TELEPHONE=C         LC_MEASUREMENT=C.UTF-8 LC_IDENTIFICATION=C   attached base packages:[1] stats     graphics  grDevices utils     datasets  methods   base     other attached packages:[1] ggrepel_0.9.1 ggplot2_3.3.3 dplyr_1.0.6  loaded via a namespace (and not attached): [1] Rcpp_1.0.6       magrittr_2.0.1   tidyselect_1.1.1 munsell_0.5.0    [5] colorspace_2.0-1 R6_2.5.0         rlang_0.4.11     fansi_0.5.0      [9] grid_4.0.5       gtable_0.3.0     utf8_1.2.1       withr_2.4.2     [13] ellipsis_0.3.2   digest_0.6.27    tibble_3.1.2     lifecycle_1.0.0 [17] crayon_1.4.1     purrr_0.3.4      farver_2.1.0     vctrs_0.3.8     [21] glue_1.4.2       labeling_0.4.2   compiler_4.0.5   pillar_1.6.1    [25] generics_0.1.0   scales_1.1.1     pkgconfig_2.0.3 
            ]]></system-out>
            <system-err><![CDATA[
            Warning message:In Sys.setlocale("LC_MESSAGES", "en_US.UTF-8") :  OS reports request to set locale to "en_US.UTF-8" cannot be honored
            ]]></system-err>
        
    </testcase>
    
</testsuite>