<?xml version="1.0" encoding="UTF-8"?>
<testsuite name="Results (powered by Planemo)"
           tests="65"
           errors="19"
           failures="3"
           skip="0">
    
    <testcase classname="bcftools_filter (Test #1)" name="0" time="12.040469884872437">
        
            <error type="error" message="Input staging problem: Traceback (most recent call last):
  File "/opt/hostedtoolcache/Python/3.12.9/x64/lib/python3.12/site-packages/galaxy/tool_util/verify/interactor.py", line 1434, in verify_tool
    stage_data_in_history(
  File "/opt/hostedtoolcache/Python/3.12.9/x64/lib/python3.12/site-packages/galaxy/tool_util/verify/interactor.py", line 175, in stage_data_in_history
    staging_interface.handle_jobs()
  File "/opt/hostedtoolcache/Python/3.12.9/x64/lib/python3.12/site-packages/galaxy/tool_util/verify/interactor.py", line 212, in handle_jobs
    self.galaxy_interactor.wait_for_job(job_response["id"], job_response["history_id"], self.maxseconds)
  File "/opt/hostedtoolcache/Python/3.12.9/x64/lib/python3.12/site-packages/galaxy/tool_util/verify/interactor.py", line 399, in wait_for_job
    self.wait_for(lambda: self.__job_ready(job_id, history_id), maxseconds=maxseconds)
  File "/opt/hostedtoolcache/Python/3.12.9/x64/lib/python3.12/site-packages/galaxy/tool_util/verify/interactor.py", line 403, in wait_for
    wait_on(func, what, walltime_exceeded)
  File "/opt/hostedtoolcache/Python/3.12.9/x64/lib/python3.12/site-packages/galaxy/tool_util/verify/wait.py", line 38, in wait_on
    value = function()
            ^^^^^^^^^^
  File "/opt/hostedtoolcache/Python/3.12.9/x64/lib/python3.12/site-packages/galaxy/tool_util/verify/interactor.py", line 399, in <lambda>
    self.wait_for(lambda: self.__job_ready(job_id, history_id), maxseconds=maxseconds)
                          ^^^^^^^^^^^^^^^^^^^^^^^^^^^^^^^^^^^^
  File "/opt/hostedtoolcache/Python/3.12.9/x64/lib/python3.12/site-packages/galaxy/tool_util/verify/interactor.py", line 747, in __job_ready
    return self._state_ready(job_id, error_msg="Job in error state.")
           ^^^^^^^^^^^^^^^^^^^^^^^^^^^^^^^^^^^^^^^^^^^^^^^^^^^^^^^^^^
  File "/opt/hostedtoolcache/Python/3.12.9/x64/lib/python3.12/site-packages/galaxy/tool_util/verify/interactor.py", line 839, in _state_ready
    raise Exception(
Exception: Job in error state.. tool_id: __DATA_FETCH__, exit_code: None, stderr: .
"><![CDATA[
                { "execution_problem": "Input staging problem: Traceback (most recent call last):\n  File \"/opt/hostedtoolcache/Python/3.12.9/x64/lib/python3.12/site-packages/galaxy/tool_util/verify/interactor.py\", line 1434, in verify_tool\n    stage_data_in_history(\n  File \"/opt/hostedtoolcache/Python/3.12.9/x64/lib/python3.12/site-packages/galaxy/tool_util/verify/interactor.py\", line 175, in stage_data_in_history\n    staging_interface.handle_jobs()\n  File \"/opt/hostedtoolcache/Python/3.12.9/x64/lib/python3.12/site-packages/galaxy/tool_util/verify/interactor.py\", line 212, in handle_jobs\n    self.galaxy_interactor.wait_for_job(job_response[\"id\"], job_response[\"history_id\"], self.maxseconds)\n  File \"/opt/hostedtoolcache/Python/3.12.9/x64/lib/python3.12/site-packages/galaxy/tool_util/verify/interactor.py\", line 399, in wait_for_job\n    self.wait_for(lambda: self.__job_ready(job_id, history_id), maxseconds=maxseconds)\n  File \"/opt/hostedtoolcache/Python/3.12.9/x64/lib/python3.12/site-packages/galaxy/tool_util/verify/interactor.py\", line 403, in wait_for\n    wait_on(func, what, walltime_exceeded)\n  File \"/opt/hostedtoolcache/Python/3.12.9/x64/lib/python3.12/site-packages/galaxy/tool_util/verify/wait.py\", line 38, in wait_on\n    value = function()\n            ^^^^^^^^^^\n  File \"/opt/hostedtoolcache/Python/3.12.9/x64/lib/python3.12/site-packages/galaxy/tool_util/verify/interactor.py\", line 399, in \u003clambda\u003e\n    self.wait_for(lambda: self.__job_ready(job_id, history_id), maxseconds=maxseconds)\n                          ^^^^^^^^^^^^^^^^^^^^^^^^^^^^^^^^^^^^\n  File \"/opt/hostedtoolcache/Python/3.12.9/x64/lib/python3.12/site-packages/galaxy/tool_util/verify/interactor.py\", line 747, in __job_ready\n    return self._state_ready(job_id, error_msg=\"Job in error state.\")\n           ^^^^^^^^^^^^^^^^^^^^^^^^^^^^^^^^^^^^^^^^^^^^^^^^^^^^^^^^^^\n  File \"/opt/hostedtoolcache/Python/3.12.9/x64/lib/python3.12/site-packages/galaxy/tool_util/verify/interactor.py\", line 839, in _state_ready\n    raise Exception(\nException: Job in error state.. tool_id: __DATA_FETCH__, exit_code: None, stderr: .\n", "status": "error", "test_index": 0, "time_seconds": 12.040469884872437, "tool_id": "bcftools_filter", "tool_version": "1.15.1+galaxy4"}
            ]]></error>
        
    </testcase>
    
    <testcase classname="bcftools_filter (Test #2)" name="1" time="46.0576651096344">
        
            
            <system-out><![CDATA[
            
            ]]></system-out>
            <system-err><![CDATA[
            
            ]]></system-err>
        
    </testcase>
    
    <testcase classname="bcftools_filter (Test #11)" name="10" time="37.25094819068909">
        
            
            <system-out><![CDATA[
            
            ]]></system-out>
            <system-err><![CDATA[
            
            ]]></system-err>
        
    </testcase>
    
    <testcase classname="bcftools_filter (Test #3)" name="2" time="38.91917371749878">
        
            
            <system-out><![CDATA[
            
            ]]></system-out>
            <system-err><![CDATA[
            
            ]]></system-err>
        
    </testcase>
    
    <testcase classname="bcftools_filter (Test #4)" name="3" time="13.39975643157959">
        
            <error type="error" message="Input staging problem: Traceback (most recent call last):
  File "/opt/hostedtoolcache/Python/3.12.9/x64/lib/python3.12/site-packages/galaxy/tool_util/verify/interactor.py", line 1434, in verify_tool
    stage_data_in_history(
  File "/opt/hostedtoolcache/Python/3.12.9/x64/lib/python3.12/site-packages/galaxy/tool_util/verify/interactor.py", line 175, in stage_data_in_history
    staging_interface.handle_jobs()
  File "/opt/hostedtoolcache/Python/3.12.9/x64/lib/python3.12/site-packages/galaxy/tool_util/verify/interactor.py", line 212, in handle_jobs
    self.galaxy_interactor.wait_for_job(job_response["id"], job_response["history_id"], self.maxseconds)
  File "/opt/hostedtoolcache/Python/3.12.9/x64/lib/python3.12/site-packages/galaxy/tool_util/verify/interactor.py", line 399, in wait_for_job
    self.wait_for(lambda: self.__job_ready(job_id, history_id), maxseconds=maxseconds)
  File "/opt/hostedtoolcache/Python/3.12.9/x64/lib/python3.12/site-packages/galaxy/tool_util/verify/interactor.py", line 403, in wait_for
    wait_on(func, what, walltime_exceeded)
  File "/opt/hostedtoolcache/Python/3.12.9/x64/lib/python3.12/site-packages/galaxy/tool_util/verify/wait.py", line 38, in wait_on
    value = function()
            ^^^^^^^^^^
  File "/opt/hostedtoolcache/Python/3.12.9/x64/lib/python3.12/site-packages/galaxy/tool_util/verify/interactor.py", line 399, in <lambda>
    self.wait_for(lambda: self.__job_ready(job_id, history_id), maxseconds=maxseconds)
                          ^^^^^^^^^^^^^^^^^^^^^^^^^^^^^^^^^^^^
  File "/opt/hostedtoolcache/Python/3.12.9/x64/lib/python3.12/site-packages/galaxy/tool_util/verify/interactor.py", line 747, in __job_ready
    return self._state_ready(job_id, error_msg="Job in error state.")
           ^^^^^^^^^^^^^^^^^^^^^^^^^^^^^^^^^^^^^^^^^^^^^^^^^^^^^^^^^^
  File "/opt/hostedtoolcache/Python/3.12.9/x64/lib/python3.12/site-packages/galaxy/tool_util/verify/interactor.py", line 839, in _state_ready
    raise Exception(
Exception: Job in error state.. tool_id: __DATA_FETCH__, exit_code: None, stderr: .
"><![CDATA[
                { "execution_problem": "Input staging problem: Traceback (most recent call last):\n  File \"/opt/hostedtoolcache/Python/3.12.9/x64/lib/python3.12/site-packages/galaxy/tool_util/verify/interactor.py\", line 1434, in verify_tool\n    stage_data_in_history(\n  File \"/opt/hostedtoolcache/Python/3.12.9/x64/lib/python3.12/site-packages/galaxy/tool_util/verify/interactor.py\", line 175, in stage_data_in_history\n    staging_interface.handle_jobs()\n  File \"/opt/hostedtoolcache/Python/3.12.9/x64/lib/python3.12/site-packages/galaxy/tool_util/verify/interactor.py\", line 212, in handle_jobs\n    self.galaxy_interactor.wait_for_job(job_response[\"id\"], job_response[\"history_id\"], self.maxseconds)\n  File \"/opt/hostedtoolcache/Python/3.12.9/x64/lib/python3.12/site-packages/galaxy/tool_util/verify/interactor.py\", line 399, in wait_for_job\n    self.wait_for(lambda: self.__job_ready(job_id, history_id), maxseconds=maxseconds)\n  File \"/opt/hostedtoolcache/Python/3.12.9/x64/lib/python3.12/site-packages/galaxy/tool_util/verify/interactor.py\", line 403, in wait_for\n    wait_on(func, what, walltime_exceeded)\n  File \"/opt/hostedtoolcache/Python/3.12.9/x64/lib/python3.12/site-packages/galaxy/tool_util/verify/wait.py\", line 38, in wait_on\n    value = function()\n            ^^^^^^^^^^\n  File \"/opt/hostedtoolcache/Python/3.12.9/x64/lib/python3.12/site-packages/galaxy/tool_util/verify/interactor.py\", line 399, in \u003clambda\u003e\n    self.wait_for(lambda: self.__job_ready(job_id, history_id), maxseconds=maxseconds)\n                          ^^^^^^^^^^^^^^^^^^^^^^^^^^^^^^^^^^^^\n  File \"/opt/hostedtoolcache/Python/3.12.9/x64/lib/python3.12/site-packages/galaxy/tool_util/verify/interactor.py\", line 747, in __job_ready\n    return self._state_ready(job_id, error_msg=\"Job in error state.\")\n           ^^^^^^^^^^^^^^^^^^^^^^^^^^^^^^^^^^^^^^^^^^^^^^^^^^^^^^^^^^\n  File \"/opt/hostedtoolcache/Python/3.12.9/x64/lib/python3.12/site-packages/galaxy/tool_util/verify/interactor.py\", line 839, in _state_ready\n    raise Exception(\nException: Job in error state.. tool_id: __DATA_FETCH__, exit_code: None, stderr: .\n", "status": "error", "test_index": 3, "time_seconds": 13.39975643157959, "tool_id": "bcftools_filter", "tool_version": "1.15.1+galaxy4"}
            ]]></error>
        
    </testcase>
    
    <testcase classname="bcftools_filter (Test #5)" name="4" time="37.62768888473511">
        
            
            <system-out><![CDATA[
            
            ]]></system-out>
            <system-err><![CDATA[
            
            ]]></system-err>
        
    </testcase>
    
    <testcase classname="bcftools_filter (Test #6)" name="5" time="40.37322783470154">
        
            
            <system-out><![CDATA[
            
            ]]></system-out>
            <system-err><![CDATA[
            
            ]]></system-err>
        
    </testcase>
    
    <testcase classname="bcftools_filter (Test #7)" name="6" time="38.238243103027344">
        
            
            <system-out><![CDATA[
            
            ]]></system-out>
            <system-err><![CDATA[
            
            ]]></system-err>
        
    </testcase>
    
    <testcase classname="bcftools_filter (Test #8)" name="7" time="39.03935122489929">
        
            
            <system-out><![CDATA[
            
            ]]></system-out>
            <system-err><![CDATA[
            
            ]]></system-err>
        
    </testcase>
    
    <testcase classname="bcftools_filter (Test #9)" name="8" time="13.016009330749512">
        
            <error type="error" message="Input staging problem: Traceback (most recent call last):
  File "/opt/hostedtoolcache/Python/3.12.9/x64/lib/python3.12/site-packages/galaxy/tool_util/verify/interactor.py", line 1434, in verify_tool
    stage_data_in_history(
  File "/opt/hostedtoolcache/Python/3.12.9/x64/lib/python3.12/site-packages/galaxy/tool_util/verify/interactor.py", line 175, in stage_data_in_history
    staging_interface.handle_jobs()
  File "/opt/hostedtoolcache/Python/3.12.9/x64/lib/python3.12/site-packages/galaxy/tool_util/verify/interactor.py", line 212, in handle_jobs
    self.galaxy_interactor.wait_for_job(job_response["id"], job_response["history_id"], self.maxseconds)
  File "/opt/hostedtoolcache/Python/3.12.9/x64/lib/python3.12/site-packages/galaxy/tool_util/verify/interactor.py", line 399, in wait_for_job
    self.wait_for(lambda: self.__job_ready(job_id, history_id), maxseconds=maxseconds)
  File "/opt/hostedtoolcache/Python/3.12.9/x64/lib/python3.12/site-packages/galaxy/tool_util/verify/interactor.py", line 403, in wait_for
    wait_on(func, what, walltime_exceeded)
  File "/opt/hostedtoolcache/Python/3.12.9/x64/lib/python3.12/site-packages/galaxy/tool_util/verify/wait.py", line 38, in wait_on
    value = function()
            ^^^^^^^^^^
  File "/opt/hostedtoolcache/Python/3.12.9/x64/lib/python3.12/site-packages/galaxy/tool_util/verify/interactor.py", line 399, in <lambda>
    self.wait_for(lambda: self.__job_ready(job_id, history_id), maxseconds=maxseconds)
                          ^^^^^^^^^^^^^^^^^^^^^^^^^^^^^^^^^^^^
  File "/opt/hostedtoolcache/Python/3.12.9/x64/lib/python3.12/site-packages/galaxy/tool_util/verify/interactor.py", line 747, in __job_ready
    return self._state_ready(job_id, error_msg="Job in error state.")
           ^^^^^^^^^^^^^^^^^^^^^^^^^^^^^^^^^^^^^^^^^^^^^^^^^^^^^^^^^^
  File "/opt/hostedtoolcache/Python/3.12.9/x64/lib/python3.12/site-packages/galaxy/tool_util/verify/interactor.py", line 839, in _state_ready
    raise Exception(
Exception: Job in error state.. tool_id: __DATA_FETCH__, exit_code: None, stderr: .
"><![CDATA[
                { "execution_problem": "Input staging problem: Traceback (most recent call last):\n  File \"/opt/hostedtoolcache/Python/3.12.9/x64/lib/python3.12/site-packages/galaxy/tool_util/verify/interactor.py\", line 1434, in verify_tool\n    stage_data_in_history(\n  File \"/opt/hostedtoolcache/Python/3.12.9/x64/lib/python3.12/site-packages/galaxy/tool_util/verify/interactor.py\", line 175, in stage_data_in_history\n    staging_interface.handle_jobs()\n  File \"/opt/hostedtoolcache/Python/3.12.9/x64/lib/python3.12/site-packages/galaxy/tool_util/verify/interactor.py\", line 212, in handle_jobs\n    self.galaxy_interactor.wait_for_job(job_response[\"id\"], job_response[\"history_id\"], self.maxseconds)\n  File \"/opt/hostedtoolcache/Python/3.12.9/x64/lib/python3.12/site-packages/galaxy/tool_util/verify/interactor.py\", line 399, in wait_for_job\n    self.wait_for(lambda: self.__job_ready(job_id, history_id), maxseconds=maxseconds)\n  File \"/opt/hostedtoolcache/Python/3.12.9/x64/lib/python3.12/site-packages/galaxy/tool_util/verify/interactor.py\", line 403, in wait_for\n    wait_on(func, what, walltime_exceeded)\n  File \"/opt/hostedtoolcache/Python/3.12.9/x64/lib/python3.12/site-packages/galaxy/tool_util/verify/wait.py\", line 38, in wait_on\n    value = function()\n            ^^^^^^^^^^\n  File \"/opt/hostedtoolcache/Python/3.12.9/x64/lib/python3.12/site-packages/galaxy/tool_util/verify/interactor.py\", line 399, in \u003clambda\u003e\n    self.wait_for(lambda: self.__job_ready(job_id, history_id), maxseconds=maxseconds)\n                          ^^^^^^^^^^^^^^^^^^^^^^^^^^^^^^^^^^^^\n  File \"/opt/hostedtoolcache/Python/3.12.9/x64/lib/python3.12/site-packages/galaxy/tool_util/verify/interactor.py\", line 747, in __job_ready\n    return self._state_ready(job_id, error_msg=\"Job in error state.\")\n           ^^^^^^^^^^^^^^^^^^^^^^^^^^^^^^^^^^^^^^^^^^^^^^^^^^^^^^^^^^\n  File \"/opt/hostedtoolcache/Python/3.12.9/x64/lib/python3.12/site-packages/galaxy/tool_util/verify/interactor.py\", line 839, in _state_ready\n    raise Exception(\nException: Job in error state.. tool_id: __DATA_FETCH__, exit_code: None, stderr: .\n", "status": "error", "test_index": 8, "time_seconds": 13.016009330749512, "tool_id": "bcftools_filter", "tool_version": "1.15.1+galaxy4"}
            ]]></error>
        
    </testcase>
    
    <testcase classname="bcftools_filter (Test #10)" name="9" time="36.723631143569946">
        
            
            <system-out><![CDATA[
            
            ]]></system-out>
            <system-err><![CDATA[
            
            ]]></system-err>
        
    </testcase>
    
    <testcase classname="bcftools_mpileup (Test #1)" name="0" time="43.208200454711914">
        
            
                <error type="error" message="Tool exit code: None"><![CDATA[
                    { "inputs": {  "input|input_bam": {   "id": "579d98e3b5236d26",   "src": "hda"  },  "input|input_number": "single",  "output_type": "v",  "reference_source|ref_file": {   "id": "4fe3b92b16a018dc",   "src": "hda"  },  "reference_source|reference_source_selector": "history" }, "job": {  "command_line": "ln -s \u0027/galaxy/server/database/objects/b/3/6/dataset_b36d6382-4789-4759-b141-13e52c8e0b1d.dat\u0027 mpileup_1.bam \u0026\u0026 ln -s \u0027/galaxy/server/database/objects/_metadata_files/0/0/8/metadata_008ab83d-361e-4403-8a2d-4f1b6f6e2012.dat\u0027 mpileup_1.bam.bai \u0026\u0026  ln -s \u0027/galaxy/server/database/objects/2/b/9/dataset_2b9d29df-642c-499c-8f9d-f0582123a5f1.dat\u0027 ref.fa \u0026\u0026 samtools faidx ref.fa \u0026\u0026           bcftools mpileup  --fasta-ref \u0027ref.fa\u0027      -d \"250\"                  --threads ${GALAXY_SLOTS:-4}   --output-type \u0027v\u0027   mpileup_1.bam \u003e \u0027/galaxy/server/database/objects/1/f/c/dataset_1fc15351-4d94-4a29-b088-c652000b3960.dat\u0027",  "command_version": null,  "copied_from_job_id": null,  "create_time": "2025-03-16T01:05:06.914504",  "dependencies": [],  "exit_code": null,  "external_id": "gxy-rdmxd",  "galaxy_version": "24.1",  "handler": null,  "history_id": "e3af7b765977f2b0",  "id": "51f5bba13e9de7db",  "inputs": {   "input|input_bam": {    "id": "579d98e3b5236d26",    "src": "hda",    "uuid": "b36d6382-4789-4759-b141-13e52c8e0b1d"   },   "reference_source|ref_file": {    "id": "4fe3b92b16a018dc",    "src": "hda",    "uuid": "2b9d29df-642c-499c-8f9d-f0582123a5f1"   }  },  "job_messages": null,  "job_metrics": [],  "job_runner_name": null,  "job_stderr": null,  "job_stdout": null,  "model_class": "Job",  "output_collections": {},  "outputs": {   "output_file": {    "id": "51f5bba13e9de7db",    "src": "hda",    "uuid": "1fc15351-4d94-4a29-b088-c652000b3960"   }  },  "params": {   "__input_ext": "\"input\"",   "chromInfo": "\"/cvmfs/data.galaxyproject.org/managed/len/ucsc/?.len\"",   "dbkey": "\"?\"",   "input": "{\"__current_case__\": 0, \"input_bam\": {\"values\": [{\"id\": 14, \"src\": \"hda\"}]}, \"input_number\": \"single\"}",   "output_type": "\"v\"",   "reference_source": "{\"__current_case__\": 1, \"ref_file\": {\"values\": [{\"id\": 15, \"src\": \"hda\"}]}, \"reference_source_selector\": \"history\"}",   "sec_filtering": "{\"filter_by_flags\": {\"__current_case__\": 1, \"filter_flags\": \"nofilter\"}, \"ignore_overlaps\": false, \"max_reads_per_bam\": \"250\", \"quality\": {\"__current_case__\": 1, \"quality_settings\": \"none\"}, \"read_groups\": {\"__current_case__\": 3, \"read_groups_selector\": \"no_limit\"}, \"skip_anomalous_read_pairs\": false}",   "sec_indel": "{\"ambig_reads\": null, \"indel_bias\": \"\", \"indel_size\": \"\", \"perform_indel_calling\": {\"__current_case__\": 0, \"perform_indel_calling_selector\": \"perform_indel_calling_def\"}}",   "sec_output_options": "{\"gvcf\": \"\", \"output_tags\": null}",   "sec_restrict": "{\"regions\": {\"__current_case__\": 0, \"regions_src\": \"__none__\"}, \"regions_overlap\": null, \"targets\": {\"__current_case__\": 0, \"targets_src\": \"__none__\"}, \"targets_overlap\": null}",   "sec_subset": "{\"invert_samples\": false, \"invert_samples_file\": false, \"samples\": \"\", \"samples_file\": null}"  },  "state": "error",  "stderr": "[mpileup] 1 samples in 1 input files\n[mpileup] maximum number of reads per input file set to -d 250\n",  "stdout": "",  "tool_id": "toolshed.g2.bx.psu.edu/repos/iuc/bcftools_mpileup/bcftools_mpileup/1.15.1+galaxy4",  "tool_stderr": "[mpileup] 1 samples in 1 input files\n[mpileup] maximum number of reads per input file set to -d 250\n",  "tool_stdout": "",  "update_time": "2025-03-16T01:05:24.132820",  "user_email": "tests@fake.org" }, "output_problems": [  "Job in error state.. tool_id: toolshed.g2.bx.psu.edu/repos/iuc/bcftools_mpileup/bcftools_mpileup/1.15.1+galaxy4, exit_code: None, stderr: [mpileup] 1 samples in 1 input files\n[mpileup] maximum number of reads per input file set to -d 250\n.",  "Job in error state.. tool_id: toolshed.g2.bx.psu.edu/repos/iuc/bcftools_mpileup/bcftools_mpileup/1.15.1+galaxy4, exit_code: None, stderr: [mpileup] 1 samples in 1 input files\n[mpileup] maximum number of reads per input file set to -d 250\n." ], "status": "failure", "test_index": 0, "time_seconds": 43.208200454711914, "tool_id": "bcftools_mpileup", "tool_version": "1.15.1+galaxy4"}
                ]]></error>
            
            <system-out><![CDATA[
            
            ]]></system-out>
            <system-err><![CDATA[
            [mpileup] 1 samples in 1 input files[mpileup] maximum number of reads per input file set to -d 250
            ]]></system-err>
        
    </testcase>
    
    <testcase classname="bcftools_mpileup (Test #2)" name="1" time="">
        
            <error type="error" message=""><![CDATA[
                { "status": "skip", "test_index": 1, "tool_id": "bcftools_mpileup", "tool_version": "1.15.1+galaxy4"}
            ]]></error>
        
    </testcase>
    
    <testcase classname="bcftools_mpileup (Test #3)" name="2" time="39.496254444122314">
        
            
            <system-out><![CDATA[
            
            ]]></system-out>
            <system-err><![CDATA[
            [mpileup] 1 samples in 1 input files[mpileup] maximum number of reads per input file set to -d 250
            ]]></system-err>
        
    </testcase>
    
    <testcase classname="bcftools_mpileup (Test #4)" name="3" time="30.270524263381958">
        
            <error type="error" message="Input staging problem: Traceback (most recent call last):
  File "/opt/hostedtoolcache/Python/3.12.9/x64/lib/python3.12/site-packages/galaxy/tool_util/verify/interactor.py", line 1434, in verify_tool
    stage_data_in_history(
  File "/opt/hostedtoolcache/Python/3.12.9/x64/lib/python3.12/site-packages/galaxy/tool_util/verify/interactor.py", line 175, in stage_data_in_history
    staging_interface.handle_jobs()
  File "/opt/hostedtoolcache/Python/3.12.9/x64/lib/python3.12/site-packages/galaxy/tool_util/verify/interactor.py", line 212, in handle_jobs
    self.galaxy_interactor.wait_for_job(job_response["id"], job_response["history_id"], self.maxseconds)
  File "/opt/hostedtoolcache/Python/3.12.9/x64/lib/python3.12/site-packages/galaxy/tool_util/verify/interactor.py", line 399, in wait_for_job
    self.wait_for(lambda: self.__job_ready(job_id, history_id), maxseconds=maxseconds)
  File "/opt/hostedtoolcache/Python/3.12.9/x64/lib/python3.12/site-packages/galaxy/tool_util/verify/interactor.py", line 403, in wait_for
    wait_on(func, what, walltime_exceeded)
  File "/opt/hostedtoolcache/Python/3.12.9/x64/lib/python3.12/site-packages/galaxy/tool_util/verify/wait.py", line 38, in wait_on
    value = function()
            ^^^^^^^^^^
  File "/opt/hostedtoolcache/Python/3.12.9/x64/lib/python3.12/site-packages/galaxy/tool_util/verify/interactor.py", line 399, in <lambda>
    self.wait_for(lambda: self.__job_ready(job_id, history_id), maxseconds=maxseconds)
                          ^^^^^^^^^^^^^^^^^^^^^^^^^^^^^^^^^^^^
  File "/opt/hostedtoolcache/Python/3.12.9/x64/lib/python3.12/site-packages/galaxy/tool_util/verify/interactor.py", line 747, in __job_ready
    return self._state_ready(job_id, error_msg="Job in error state.")
           ^^^^^^^^^^^^^^^^^^^^^^^^^^^^^^^^^^^^^^^^^^^^^^^^^^^^^^^^^^
  File "/opt/hostedtoolcache/Python/3.12.9/x64/lib/python3.12/site-packages/galaxy/tool_util/verify/interactor.py", line 839, in _state_ready
    raise Exception(
Exception: Job in error state.. tool_id: __DATA_FETCH__, exit_code: None, stderr: .
"><![CDATA[
                { "execution_problem": "Input staging problem: Traceback (most recent call last):\n  File \"/opt/hostedtoolcache/Python/3.12.9/x64/lib/python3.12/site-packages/galaxy/tool_util/verify/interactor.py\", line 1434, in verify_tool\n    stage_data_in_history(\n  File \"/opt/hostedtoolcache/Python/3.12.9/x64/lib/python3.12/site-packages/galaxy/tool_util/verify/interactor.py\", line 175, in stage_data_in_history\n    staging_interface.handle_jobs()\n  File \"/opt/hostedtoolcache/Python/3.12.9/x64/lib/python3.12/site-packages/galaxy/tool_util/verify/interactor.py\", line 212, in handle_jobs\n    self.galaxy_interactor.wait_for_job(job_response[\"id\"], job_response[\"history_id\"], self.maxseconds)\n  File \"/opt/hostedtoolcache/Python/3.12.9/x64/lib/python3.12/site-packages/galaxy/tool_util/verify/interactor.py\", line 399, in wait_for_job\n    self.wait_for(lambda: self.__job_ready(job_id, history_id), maxseconds=maxseconds)\n  File \"/opt/hostedtoolcache/Python/3.12.9/x64/lib/python3.12/site-packages/galaxy/tool_util/verify/interactor.py\", line 403, in wait_for\n    wait_on(func, what, walltime_exceeded)\n  File \"/opt/hostedtoolcache/Python/3.12.9/x64/lib/python3.12/site-packages/galaxy/tool_util/verify/wait.py\", line 38, in wait_on\n    value = function()\n            ^^^^^^^^^^\n  File \"/opt/hostedtoolcache/Python/3.12.9/x64/lib/python3.12/site-packages/galaxy/tool_util/verify/interactor.py\", line 399, in \u003clambda\u003e\n    self.wait_for(lambda: self.__job_ready(job_id, history_id), maxseconds=maxseconds)\n                          ^^^^^^^^^^^^^^^^^^^^^^^^^^^^^^^^^^^^\n  File \"/opt/hostedtoolcache/Python/3.12.9/x64/lib/python3.12/site-packages/galaxy/tool_util/verify/interactor.py\", line 747, in __job_ready\n    return self._state_ready(job_id, error_msg=\"Job in error state.\")\n           ^^^^^^^^^^^^^^^^^^^^^^^^^^^^^^^^^^^^^^^^^^^^^^^^^^^^^^^^^^\n  File \"/opt/hostedtoolcache/Python/3.12.9/x64/lib/python3.12/site-packages/galaxy/tool_util/verify/interactor.py\", line 839, in _state_ready\n    raise Exception(\nException: Job in error state.. tool_id: __DATA_FETCH__, exit_code: None, stderr: .\n", "status": "error", "test_index": 3, "time_seconds": 30.270524263381958, "tool_id": "bcftools_mpileup", "tool_version": "1.15.1+galaxy4"}
            ]]></error>
        
    </testcase>
    
    <testcase classname="bcftools_mpileup (Test #5)" name="4" time="49.81551957130432">
        
            
            <system-out><![CDATA[
            
            ]]></system-out>
            <system-err><![CDATA[
            [warning] tag DV functional, but deprecated. Please switch to `AD` in future.[mpileup] 3 samples in 3 input files[mpileup] maximum number of reads per input file set to -d 250
            ]]></system-err>
        
    </testcase>
    
    <testcase classname="bcftools_mpileup (Test #6)" name="5" time="52.24180030822754">
        
            
            <system-out><![CDATA[
            
            ]]></system-out>
            <system-err><![CDATA[
            [mpileup] 3 samples in 3 input files[mpileup] maximum number of reads per input file set to -d 250
            ]]></system-err>
        
    </testcase>
    
    <testcase classname="bcftools_mpileup (Test #7)" name="6" time="39.7849178314209">
        
            
            <system-out><![CDATA[
            
            ]]></system-out>
            <system-err><![CDATA[
            [mpileup] 1 samples in 1 input files[mpileup] maximum number of reads per input file set to -d 250
            ]]></system-err>
        
    </testcase>
    
    <testcase classname="datamash_ops (Test #1)" name="0" time="0.2837104797363281">
        
            <error type="error" message="Input staging problem: Traceback (most recent call last):
  File "/opt/hostedtoolcache/Python/3.12.9/x64/lib/python3.12/site-packages/galaxy/tool_util/verify/interactor.py", line 1434, in verify_tool
    stage_data_in_history(
  File "/opt/hostedtoolcache/Python/3.12.9/x64/lib/python3.12/site-packages/galaxy/tool_util/verify/interactor.py", line 163, in stage_data_in_history
    test_dict = galaxy_interactor.remote_to_input(
                ^^^^^^^^^^^^^^^^^^^^^^^^^^^^^^^^^^
  File "/opt/hostedtoolcache/Python/3.12.9/x64/lib/python3.12/site-packages/galaxy/tool_util/verify/interactor.py", line 582, in remote_to_input
    path_or_location = self._get_path_or_location(
                       ^^^^^^^^^^^^^^^^^^^^^^^^^^^
  File "/opt/hostedtoolcache/Python/3.12.9/x64/lib/python3.12/site-packages/galaxy/tool_util/verify/interactor.py", line 619, in _get_path_or_location
    path = self.test_data_download(
           ^^^^^^^^^^^^^^^^^^^^^^^^
  File "/opt/hostedtoolcache/Python/3.12.9/x64/lib/python3.12/site-packages/galaxy/tool_util/verify/interactor.py", line 525, in test_data_download
    raise AssertionError(f"Test input file ({filename}) cannot be found.")
AssertionError: Test input file (group_compute_input.txt) cannot be found.
"><![CDATA[
                { "execution_problem": "Input staging problem: Traceback (most recent call last):\n  File \"/opt/hostedtoolcache/Python/3.12.9/x64/lib/python3.12/site-packages/galaxy/tool_util/verify/interactor.py\", line 1434, in verify_tool\n    stage_data_in_history(\n  File \"/opt/hostedtoolcache/Python/3.12.9/x64/lib/python3.12/site-packages/galaxy/tool_util/verify/interactor.py\", line 163, in stage_data_in_history\n    test_dict = galaxy_interactor.remote_to_input(\n                ^^^^^^^^^^^^^^^^^^^^^^^^^^^^^^^^^^\n  File \"/opt/hostedtoolcache/Python/3.12.9/x64/lib/python3.12/site-packages/galaxy/tool_util/verify/interactor.py\", line 582, in remote_to_input\n    path_or_location = self._get_path_or_location(\n                       ^^^^^^^^^^^^^^^^^^^^^^^^^^^\n  File \"/opt/hostedtoolcache/Python/3.12.9/x64/lib/python3.12/site-packages/galaxy/tool_util/verify/interactor.py\", line 619, in _get_path_or_location\n    path = self.test_data_download(\n           ^^^^^^^^^^^^^^^^^^^^^^^^\n  File \"/opt/hostedtoolcache/Python/3.12.9/x64/lib/python3.12/site-packages/galaxy/tool_util/verify/interactor.py\", line 525, in test_data_download\n    raise AssertionError(f\"Test input file ({filename}) cannot be found.\")\nAssertionError: Test input file (group_compute_input.txt) cannot be found.\n", "status": "error", "test_index": 0, "time_seconds": 0.2837104797363281, "tool_id": "datamash_ops", "tool_version": "1.8+galaxy0"}
            ]]></error>
        
    </testcase>
    
    <testcase classname="datamash_ops (Test #2)" name="1" time="0.14583635330200195">
        
            <error type="error" message="Input staging problem: Traceback (most recent call last):
  File "/opt/hostedtoolcache/Python/3.12.9/x64/lib/python3.12/site-packages/galaxy/tool_util/verify/interactor.py", line 1434, in verify_tool
    stage_data_in_history(
  File "/opt/hostedtoolcache/Python/3.12.9/x64/lib/python3.12/site-packages/galaxy/tool_util/verify/interactor.py", line 163, in stage_data_in_history
    test_dict = galaxy_interactor.remote_to_input(
                ^^^^^^^^^^^^^^^^^^^^^^^^^^^^^^^^^^
  File "/opt/hostedtoolcache/Python/3.12.9/x64/lib/python3.12/site-packages/galaxy/tool_util/verify/interactor.py", line 582, in remote_to_input
    path_or_location = self._get_path_or_location(
                       ^^^^^^^^^^^^^^^^^^^^^^^^^^^
  File "/opt/hostedtoolcache/Python/3.12.9/x64/lib/python3.12/site-packages/galaxy/tool_util/verify/interactor.py", line 619, in _get_path_or_location
    path = self.test_data_download(
           ^^^^^^^^^^^^^^^^^^^^^^^^
  File "/opt/hostedtoolcache/Python/3.12.9/x64/lib/python3.12/site-packages/galaxy/tool_util/verify/interactor.py", line 525, in test_data_download
    raise AssertionError(f"Test input file ({filename}) cannot be found.")
AssertionError: Test input file (group_compute_input.txt) cannot be found.
"><![CDATA[
                { "execution_problem": "Input staging problem: Traceback (most recent call last):\n  File \"/opt/hostedtoolcache/Python/3.12.9/x64/lib/python3.12/site-packages/galaxy/tool_util/verify/interactor.py\", line 1434, in verify_tool\n    stage_data_in_history(\n  File \"/opt/hostedtoolcache/Python/3.12.9/x64/lib/python3.12/site-packages/galaxy/tool_util/verify/interactor.py\", line 163, in stage_data_in_history\n    test_dict = galaxy_interactor.remote_to_input(\n                ^^^^^^^^^^^^^^^^^^^^^^^^^^^^^^^^^^\n  File \"/opt/hostedtoolcache/Python/3.12.9/x64/lib/python3.12/site-packages/galaxy/tool_util/verify/interactor.py\", line 582, in remote_to_input\n    path_or_location = self._get_path_or_location(\n                       ^^^^^^^^^^^^^^^^^^^^^^^^^^^\n  File \"/opt/hostedtoolcache/Python/3.12.9/x64/lib/python3.12/site-packages/galaxy/tool_util/verify/interactor.py\", line 619, in _get_path_or_location\n    path = self.test_data_download(\n           ^^^^^^^^^^^^^^^^^^^^^^^^\n  File \"/opt/hostedtoolcache/Python/3.12.9/x64/lib/python3.12/site-packages/galaxy/tool_util/verify/interactor.py\", line 525, in test_data_download\n    raise AssertionError(f\"Test input file ({filename}) cannot be found.\")\nAssertionError: Test input file (group_compute_input.txt) cannot be found.\n", "status": "error", "test_index": 1, "time_seconds": 0.14583635330200195, "tool_id": "datamash_ops", "tool_version": "1.8+galaxy0"}
            ]]></error>
        
    </testcase>
    
    <testcase classname="datamash_ops (Test #3)" name="2" time="0.15369343757629395">
        
            <error type="error" message="Input staging problem: Traceback (most recent call last):
  File "/opt/hostedtoolcache/Python/3.12.9/x64/lib/python3.12/site-packages/galaxy/tool_util/verify/interactor.py", line 1434, in verify_tool
    stage_data_in_history(
  File "/opt/hostedtoolcache/Python/3.12.9/x64/lib/python3.12/site-packages/galaxy/tool_util/verify/interactor.py", line 163, in stage_data_in_history
    test_dict = galaxy_interactor.remote_to_input(
                ^^^^^^^^^^^^^^^^^^^^^^^^^^^^^^^^^^
  File "/opt/hostedtoolcache/Python/3.12.9/x64/lib/python3.12/site-packages/galaxy/tool_util/verify/interactor.py", line 582, in remote_to_input
    path_or_location = self._get_path_or_location(
                       ^^^^^^^^^^^^^^^^^^^^^^^^^^^
  File "/opt/hostedtoolcache/Python/3.12.9/x64/lib/python3.12/site-packages/galaxy/tool_util/verify/interactor.py", line 619, in _get_path_or_location
    path = self.test_data_download(
           ^^^^^^^^^^^^^^^^^^^^^^^^
  File "/opt/hostedtoolcache/Python/3.12.9/x64/lib/python3.12/site-packages/galaxy/tool_util/verify/interactor.py", line 525, in test_data_download
    raise AssertionError(f"Test input file ({filename}) cannot be found.")
AssertionError: Test input file (group_compute_input.csv) cannot be found.
"><![CDATA[
                { "execution_problem": "Input staging problem: Traceback (most recent call last):\n  File \"/opt/hostedtoolcache/Python/3.12.9/x64/lib/python3.12/site-packages/galaxy/tool_util/verify/interactor.py\", line 1434, in verify_tool\n    stage_data_in_history(\n  File \"/opt/hostedtoolcache/Python/3.12.9/x64/lib/python3.12/site-packages/galaxy/tool_util/verify/interactor.py\", line 163, in stage_data_in_history\n    test_dict = galaxy_interactor.remote_to_input(\n                ^^^^^^^^^^^^^^^^^^^^^^^^^^^^^^^^^^\n  File \"/opt/hostedtoolcache/Python/3.12.9/x64/lib/python3.12/site-packages/galaxy/tool_util/verify/interactor.py\", line 582, in remote_to_input\n    path_or_location = self._get_path_or_location(\n                       ^^^^^^^^^^^^^^^^^^^^^^^^^^^\n  File \"/opt/hostedtoolcache/Python/3.12.9/x64/lib/python3.12/site-packages/galaxy/tool_util/verify/interactor.py\", line 619, in _get_path_or_location\n    path = self.test_data_download(\n           ^^^^^^^^^^^^^^^^^^^^^^^^\n  File \"/opt/hostedtoolcache/Python/3.12.9/x64/lib/python3.12/site-packages/galaxy/tool_util/verify/interactor.py\", line 525, in test_data_download\n    raise AssertionError(f\"Test input file ({filename}) cannot be found.\")\nAssertionError: Test input file (group_compute_input.csv) cannot be found.\n", "status": "error", "test_index": 2, "time_seconds": 0.15369343757629395, "tool_id": "datamash_ops", "tool_version": "1.8+galaxy0"}
            ]]></error>
        
    </testcase>
    
    <testcase classname="datamash_ops (Test #4)" name="3" time="0.14561939239501953">
        
            <error type="error" message="Input staging problem: Traceback (most recent call last):
  File "/opt/hostedtoolcache/Python/3.12.9/x64/lib/python3.12/site-packages/galaxy/tool_util/verify/interactor.py", line 1434, in verify_tool
    stage_data_in_history(
  File "/opt/hostedtoolcache/Python/3.12.9/x64/lib/python3.12/site-packages/galaxy/tool_util/verify/interactor.py", line 163, in stage_data_in_history
    test_dict = galaxy_interactor.remote_to_input(
                ^^^^^^^^^^^^^^^^^^^^^^^^^^^^^^^^^^
  File "/opt/hostedtoolcache/Python/3.12.9/x64/lib/python3.12/site-packages/galaxy/tool_util/verify/interactor.py", line 582, in remote_to_input
    path_or_location = self._get_path_or_location(
                       ^^^^^^^^^^^^^^^^^^^^^^^^^^^
  File "/opt/hostedtoolcache/Python/3.12.9/x64/lib/python3.12/site-packages/galaxy/tool_util/verify/interactor.py", line 619, in _get_path_or_location
    path = self.test_data_download(
           ^^^^^^^^^^^^^^^^^^^^^^^^
  File "/opt/hostedtoolcache/Python/3.12.9/x64/lib/python3.12/site-packages/galaxy/tool_util/verify/interactor.py", line 525, in test_data_download
    raise AssertionError(f"Test input file ({filename}) cannot be found.")
AssertionError: Test input file (na_values_input.tsv) cannot be found.
"><![CDATA[
                { "execution_problem": "Input staging problem: Traceback (most recent call last):\n  File \"/opt/hostedtoolcache/Python/3.12.9/x64/lib/python3.12/site-packages/galaxy/tool_util/verify/interactor.py\", line 1434, in verify_tool\n    stage_data_in_history(\n  File \"/opt/hostedtoolcache/Python/3.12.9/x64/lib/python3.12/site-packages/galaxy/tool_util/verify/interactor.py\", line 163, in stage_data_in_history\n    test_dict = galaxy_interactor.remote_to_input(\n                ^^^^^^^^^^^^^^^^^^^^^^^^^^^^^^^^^^\n  File \"/opt/hostedtoolcache/Python/3.12.9/x64/lib/python3.12/site-packages/galaxy/tool_util/verify/interactor.py\", line 582, in remote_to_input\n    path_or_location = self._get_path_or_location(\n                       ^^^^^^^^^^^^^^^^^^^^^^^^^^^\n  File \"/opt/hostedtoolcache/Python/3.12.9/x64/lib/python3.12/site-packages/galaxy/tool_util/verify/interactor.py\", line 619, in _get_path_or_location\n    path = self.test_data_download(\n           ^^^^^^^^^^^^^^^^^^^^^^^^\n  File \"/opt/hostedtoolcache/Python/3.12.9/x64/lib/python3.12/site-packages/galaxy/tool_util/verify/interactor.py\", line 525, in test_data_download\n    raise AssertionError(f\"Test input file ({filename}) cannot be found.\")\nAssertionError: Test input file (na_values_input.tsv) cannot be found.\n", "status": "error", "test_index": 3, "time_seconds": 0.14561939239501953, "tool_id": "datamash_ops", "tool_version": "1.8+galaxy0"}
            ]]></error>
        
    </testcase>
    
    <testcase classname="deeptools_bam_pe_fragmentsize (Test #1)" name="0" time="14.040061473846436">
        
            <error type="error" message="Input staging problem: Traceback (most recent call last):
  File "/opt/hostedtoolcache/Python/3.12.9/x64/lib/python3.12/site-packages/galaxy/tool_util/verify/interactor.py", line 1434, in verify_tool
    stage_data_in_history(
  File "/opt/hostedtoolcache/Python/3.12.9/x64/lib/python3.12/site-packages/galaxy/tool_util/verify/interactor.py", line 175, in stage_data_in_history
    staging_interface.handle_jobs()
  File "/opt/hostedtoolcache/Python/3.12.9/x64/lib/python3.12/site-packages/galaxy/tool_util/verify/interactor.py", line 212, in handle_jobs
    self.galaxy_interactor.wait_for_job(job_response["id"], job_response["history_id"], self.maxseconds)
  File "/opt/hostedtoolcache/Python/3.12.9/x64/lib/python3.12/site-packages/galaxy/tool_util/verify/interactor.py", line 399, in wait_for_job
    self.wait_for(lambda: self.__job_ready(job_id, history_id), maxseconds=maxseconds)
  File "/opt/hostedtoolcache/Python/3.12.9/x64/lib/python3.12/site-packages/galaxy/tool_util/verify/interactor.py", line 403, in wait_for
    wait_on(func, what, walltime_exceeded)
  File "/opt/hostedtoolcache/Python/3.12.9/x64/lib/python3.12/site-packages/galaxy/tool_util/verify/wait.py", line 38, in wait_on
    value = function()
            ^^^^^^^^^^
  File "/opt/hostedtoolcache/Python/3.12.9/x64/lib/python3.12/site-packages/galaxy/tool_util/verify/interactor.py", line 399, in <lambda>
    self.wait_for(lambda: self.__job_ready(job_id, history_id), maxseconds=maxseconds)
                          ^^^^^^^^^^^^^^^^^^^^^^^^^^^^^^^^^^^^
  File "/opt/hostedtoolcache/Python/3.12.9/x64/lib/python3.12/site-packages/galaxy/tool_util/verify/interactor.py", line 747, in __job_ready
    return self._state_ready(job_id, error_msg="Job in error state.")
           ^^^^^^^^^^^^^^^^^^^^^^^^^^^^^^^^^^^^^^^^^^^^^^^^^^^^^^^^^^
  File "/opt/hostedtoolcache/Python/3.12.9/x64/lib/python3.12/site-packages/galaxy/tool_util/verify/interactor.py", line 839, in _state_ready
    raise Exception(
Exception: Job in error state.. tool_id: __DATA_FETCH__, exit_code: None, stderr: .
"><![CDATA[
                { "execution_problem": "Input staging problem: Traceback (most recent call last):\n  File \"/opt/hostedtoolcache/Python/3.12.9/x64/lib/python3.12/site-packages/galaxy/tool_util/verify/interactor.py\", line 1434, in verify_tool\n    stage_data_in_history(\n  File \"/opt/hostedtoolcache/Python/3.12.9/x64/lib/python3.12/site-packages/galaxy/tool_util/verify/interactor.py\", line 175, in stage_data_in_history\n    staging_interface.handle_jobs()\n  File \"/opt/hostedtoolcache/Python/3.12.9/x64/lib/python3.12/site-packages/galaxy/tool_util/verify/interactor.py\", line 212, in handle_jobs\n    self.galaxy_interactor.wait_for_job(job_response[\"id\"], job_response[\"history_id\"], self.maxseconds)\n  File \"/opt/hostedtoolcache/Python/3.12.9/x64/lib/python3.12/site-packages/galaxy/tool_util/verify/interactor.py\", line 399, in wait_for_job\n    self.wait_for(lambda: self.__job_ready(job_id, history_id), maxseconds=maxseconds)\n  File \"/opt/hostedtoolcache/Python/3.12.9/x64/lib/python3.12/site-packages/galaxy/tool_util/verify/interactor.py\", line 403, in wait_for\n    wait_on(func, what, walltime_exceeded)\n  File \"/opt/hostedtoolcache/Python/3.12.9/x64/lib/python3.12/site-packages/galaxy/tool_util/verify/wait.py\", line 38, in wait_on\n    value = function()\n            ^^^^^^^^^^\n  File \"/opt/hostedtoolcache/Python/3.12.9/x64/lib/python3.12/site-packages/galaxy/tool_util/verify/interactor.py\", line 399, in \u003clambda\u003e\n    self.wait_for(lambda: self.__job_ready(job_id, history_id), maxseconds=maxseconds)\n                          ^^^^^^^^^^^^^^^^^^^^^^^^^^^^^^^^^^^^\n  File \"/opt/hostedtoolcache/Python/3.12.9/x64/lib/python3.12/site-packages/galaxy/tool_util/verify/interactor.py\", line 747, in __job_ready\n    return self._state_ready(job_id, error_msg=\"Job in error state.\")\n           ^^^^^^^^^^^^^^^^^^^^^^^^^^^^^^^^^^^^^^^^^^^^^^^^^^^^^^^^^^\n  File \"/opt/hostedtoolcache/Python/3.12.9/x64/lib/python3.12/site-packages/galaxy/tool_util/verify/interactor.py\", line 839, in _state_ready\n    raise Exception(\nException: Job in error state.. tool_id: __DATA_FETCH__, exit_code: None, stderr: .\n", "status": "error", "test_index": 0, "time_seconds": 14.040061473846436, "tool_id": "deeptools_bam_pe_fragmentsize", "tool_version": "3.5.4+galaxy0"}
            ]]></error>
        
    </testcase>
    
    <testcase classname="deeptools_bam_pe_fragmentsize (Test #2)" name="1" time="71.86466860771179">
        
            
            <system-out><![CDATA[
            
            ]]></system-out>
            <system-err><![CDATA[
            
            ]]></system-err>
        
    </testcase>
    
    <testcase classname="freebayes (Test #1)" name="0" time="58.88753366470337">
        
            
            <system-out><![CDATA[
            
            ]]></system-out>
            <system-err><![CDATA[
            
            ]]></system-err>
        
    </testcase>
    
    <testcase classname="freebayes (Test #2)" name="1" time="40.901362657547">
        
            
            <system-out><![CDATA[
            
            ]]></system-out>
            <system-err><![CDATA[
            
            ]]></system-err>
        
    </testcase>
    
    <testcase classname="freebayes (Test #3)" name="2" time="41.1461443901062">
        
            
            <system-out><![CDATA[
            
            ]]></system-out>
            <system-err><![CDATA[
            
            ]]></system-err>
        
    </testcase>
    
    <testcase classname="freebayes (Test #4)" name="3" time="25.241164922714233">
        
            <error type="error" message="Input staging problem: Traceback (most recent call last):
  File "/opt/hostedtoolcache/Python/3.12.9/x64/lib/python3.12/site-packages/galaxy/tool_util/verify/interactor.py", line 1434, in verify_tool
    stage_data_in_history(
  File "/opt/hostedtoolcache/Python/3.12.9/x64/lib/python3.12/site-packages/galaxy/tool_util/verify/interactor.py", line 175, in stage_data_in_history
    staging_interface.handle_jobs()
  File "/opt/hostedtoolcache/Python/3.12.9/x64/lib/python3.12/site-packages/galaxy/tool_util/verify/interactor.py", line 212, in handle_jobs
    self.galaxy_interactor.wait_for_job(job_response["id"], job_response["history_id"], self.maxseconds)
  File "/opt/hostedtoolcache/Python/3.12.9/x64/lib/python3.12/site-packages/galaxy/tool_util/verify/interactor.py", line 399, in wait_for_job
    self.wait_for(lambda: self.__job_ready(job_id, history_id), maxseconds=maxseconds)
  File "/opt/hostedtoolcache/Python/3.12.9/x64/lib/python3.12/site-packages/galaxy/tool_util/verify/interactor.py", line 403, in wait_for
    wait_on(func, what, walltime_exceeded)
  File "/opt/hostedtoolcache/Python/3.12.9/x64/lib/python3.12/site-packages/galaxy/tool_util/verify/wait.py", line 38, in wait_on
    value = function()
            ^^^^^^^^^^
  File "/opt/hostedtoolcache/Python/3.12.9/x64/lib/python3.12/site-packages/galaxy/tool_util/verify/interactor.py", line 399, in <lambda>
    self.wait_for(lambda: self.__job_ready(job_id, history_id), maxseconds=maxseconds)
                          ^^^^^^^^^^^^^^^^^^^^^^^^^^^^^^^^^^^^
  File "/opt/hostedtoolcache/Python/3.12.9/x64/lib/python3.12/site-packages/galaxy/tool_util/verify/interactor.py", line 747, in __job_ready
    return self._state_ready(job_id, error_msg="Job in error state.")
           ^^^^^^^^^^^^^^^^^^^^^^^^^^^^^^^^^^^^^^^^^^^^^^^^^^^^^^^^^^
  File "/opt/hostedtoolcache/Python/3.12.9/x64/lib/python3.12/site-packages/galaxy/tool_util/verify/interactor.py", line 839, in _state_ready
    raise Exception(
Exception: Job in error state.. tool_id: __DATA_FETCH__, exit_code: None, stderr: .
"><![CDATA[
                { "execution_problem": "Input staging problem: Traceback (most recent call last):\n  File \"/opt/hostedtoolcache/Python/3.12.9/x64/lib/python3.12/site-packages/galaxy/tool_util/verify/interactor.py\", line 1434, in verify_tool\n    stage_data_in_history(\n  File \"/opt/hostedtoolcache/Python/3.12.9/x64/lib/python3.12/site-packages/galaxy/tool_util/verify/interactor.py\", line 175, in stage_data_in_history\n    staging_interface.handle_jobs()\n  File \"/opt/hostedtoolcache/Python/3.12.9/x64/lib/python3.12/site-packages/galaxy/tool_util/verify/interactor.py\", line 212, in handle_jobs\n    self.galaxy_interactor.wait_for_job(job_response[\"id\"], job_response[\"history_id\"], self.maxseconds)\n  File \"/opt/hostedtoolcache/Python/3.12.9/x64/lib/python3.12/site-packages/galaxy/tool_util/verify/interactor.py\", line 399, in wait_for_job\n    self.wait_for(lambda: self.__job_ready(job_id, history_id), maxseconds=maxseconds)\n  File \"/opt/hostedtoolcache/Python/3.12.9/x64/lib/python3.12/site-packages/galaxy/tool_util/verify/interactor.py\", line 403, in wait_for\n    wait_on(func, what, walltime_exceeded)\n  File \"/opt/hostedtoolcache/Python/3.12.9/x64/lib/python3.12/site-packages/galaxy/tool_util/verify/wait.py\", line 38, in wait_on\n    value = function()\n            ^^^^^^^^^^\n  File \"/opt/hostedtoolcache/Python/3.12.9/x64/lib/python3.12/site-packages/galaxy/tool_util/verify/interactor.py\", line 399, in \u003clambda\u003e\n    self.wait_for(lambda: self.__job_ready(job_id, history_id), maxseconds=maxseconds)\n                          ^^^^^^^^^^^^^^^^^^^^^^^^^^^^^^^^^^^^\n  File \"/opt/hostedtoolcache/Python/3.12.9/x64/lib/python3.12/site-packages/galaxy/tool_util/verify/interactor.py\", line 747, in __job_ready\n    return self._state_ready(job_id, error_msg=\"Job in error state.\")\n           ^^^^^^^^^^^^^^^^^^^^^^^^^^^^^^^^^^^^^^^^^^^^^^^^^^^^^^^^^^\n  File \"/opt/hostedtoolcache/Python/3.12.9/x64/lib/python3.12/site-packages/galaxy/tool_util/verify/interactor.py\", line 839, in _state_ready\n    raise Exception(\nException: Job in error state.. tool_id: __DATA_FETCH__, exit_code: None, stderr: .\n", "status": "error", "test_index": 3, "time_seconds": 25.241164922714233, "tool_id": "freebayes", "tool_version": "1.3.8+galaxy0"}
            ]]></error>
        
    </testcase>
    
    <testcase classname="freebayes (Test #5)" name="4" time="41.406352043151855">
        
            
            <system-out><![CDATA[
            
            ]]></system-out>
            <system-err><![CDATA[
            
            ]]></system-err>
        
    </testcase>
    
    <testcase classname="freebayes (Test #6)" name="5" time="34.706475257873535">
        
            
                <error type="error" message="Tool exit code: None"><![CDATA[
                    { "inputs": {  "coverage_options|coverage_options_selector": "set",  "coverage_options|limit_coverage": "400",  "options_type|options_type_selector": "simple",  "reference_source|batchmode|input_bams": {   "id": "431cbb2cacc73c47",   "src": "hda"  },  "reference_source|batchmode|processmode": "individual",  "reference_source|ref_file": {   "id": "667c3635a8158515",   "src": "hda"  },  "reference_source|reference_source_selector": "history" }, "job": {  "command_line": "ln -s -f \u0027/galaxy/server/database/objects/1/6/7/dataset_16744b0c-9c0b-45e3-b5c2-a1be66a58cba.dat\u0027 \u0027localref.fa\u0027 \u0026\u0026 samtools faidx \u0027localref.fa\u0027 2\u003e\u00261 || echo \"Error running samtools faidx for FreeBayes\" \u003e\u00262 \u0026\u0026   ln -s -f \u0027/galaxy/server/database/objects/3/a/d/dataset_3adf459d-4d3b-42ce-959a-32e1464566d1.dat\u0027 \u0027b_0.bam\u0027 \u0026\u0026 ln -s -f \u0027/galaxy/server/database/objects/_metadata_files/4/9/6/metadata_496dd6cb-2ba9-4ae8-98cb-f8a883e46892.dat\u0027 \u0027b_0.bam.bai\u0027 \u0026\u0026   samtools view -H b_0.bam| grep \u0027^@SQ\u0027 | cut -f 2- | awk \u0027{ gsub(\"^SN:\",\"\",$1); gsub(\"^LN:\",\"\",$2); print $1\"\\t0\\t\"$2; }\u0027 \u003e\u003e regions_all.bed \u0026\u0026  sort -u regions_all.bed \u003e regions_uniq.bed \u0026\u0026  mkdir vcf_output failed_alleles trace \u0026\u0026   for i in `cat regions_uniq.bed | awk \u0027{print $1\":\"$2\"..\"$3}\u0027`; do echo \"   freebayes  --region \u0027$i\u0027  --bam \u0027b_0.bam\u0027 --fasta-reference \u0027localref.fa\u0027  --vcf \u0027./vcf_output/part_$i.vcf\u0027   --min-coverage 0 --skip-coverage 0 --limit-coverage 400    \"; done \u003e freebayes_commands.sh \u0026\u0026  cat freebayes_commands.sh | parallel --will-cite -j ${GALAXY_SLOTS:-1} \u0026\u0026  grep \"^#\" \"./vcf_output/part_$i.vcf\" \u003e header.txt \u0026\u0026  for i in `cat regions_uniq.bed | awk \u0027{print $1\":\"$2\"..\"$3}\u0027`; do cat \"./vcf_output/part_$i.vcf\" | grep -v \"^#\" || true ; done | sort -k1,1 -k2,2n -k5,5 -u | cat header.txt - \u003e \u0027/galaxy/server/database/objects/d/a/8/dataset_da81d559-52f4-4633-8bb6-beb0f377e417.dat\u0027",  "command_version": null,  "copied_from_job_id": null,  "create_time": "2025-03-16T01:29:51.346232",  "dependencies": [],  "exit_code": null,  "external_id": "gxy-4mx4x",  "galaxy_version": "24.1",  "handler": null,  "history_id": "e3af7b765977f2b0",  "id": "7453416dfb4ccc98",  "inputs": {   "reference_source|batchmode|input_bams": {    "id": "431cbb2cacc73c47",    "src": "hda",    "uuid": "3adf459d-4d3b-42ce-959a-32e1464566d1"   },   "reference_source|ref_file": {    "id": "667c3635a8158515",    "src": "hda",    "uuid": "16744b0c-9c0b-45e3-b5c2-a1be66a58cba"   }  },  "job_messages": null,  "job_metrics": [],  "job_runner_name": null,  "job_stderr": null,  "job_stdout": null,  "model_class": "Job",  "output_collections": {},  "outputs": {   "output_vcf": {    "id": "ea77aad2cfef7a9c",    "src": "hda",    "uuid": "da81d559-52f4-4633-8bb6-beb0f377e417"   }  },  "params": {   "__input_ext": "\"bam\"",   "chromInfo": "\"/cvmfs/data.galaxyproject.org/managed/len/ucsc/?.len\"",   "coverage_options": "{\"__current_case__\": 0, \"coverage_options_selector\": \"set\", \"limit_coverage\": \"400\", \"min_coverage\": \"0\", \"skip_coverage\": \"0\"}",   "dbkey": "\"?\"",   "options_type": "{\"__current_case__\": 1, \"options_type_selector\": \"simple\"}",   "reference_source": "{\"__current_case__\": 1, \"batchmode\": {\"__current_case__\": 0, \"input_bams\": {\"values\": [{\"id\": 119, \"src\": \"hda\"}]}, \"processmode\": \"individual\"}, \"ref_file\": {\"values\": [{\"id\": 120, \"src\": \"hda\"}]}, \"reference_source_selector\": \"history\"}",   "target_limit_type": "{\"__current_case__\": 0, \"target_limit_type_selector\": \"do_not_limit\"}"  },  "state": "error",  "stderr": "",  "stdout": "",  "tool_id": "toolshed.g2.bx.psu.edu/repos/devteam/freebayes/freebayes/1.3.8+galaxy0",  "tool_stderr": "",  "tool_stdout": "",  "update_time": "2025-03-16T01:29:58.507601",  "user_email": "tests@fake.org" }, "output_problems": [  "Job in error state.. tool_id: toolshed.g2.bx.psu.edu/repos/devteam/freebayes/freebayes/1.3.8+galaxy0, exit_code: None, stderr: .",  "Job in error state.. tool_id: toolshed.g2.bx.psu.edu/repos/devteam/freebayes/freebayes/1.3.8+galaxy0, exit_code: None, stderr: ." ], "status": "failure", "test_index": 5, "time_seconds": 34.706475257873535, "tool_id": "freebayes", "tool_version": "1.3.8+galaxy0"}
                ]]></error>
            
            <system-out><![CDATA[
            
            ]]></system-out>
            <system-err><![CDATA[
            
            ]]></system-err>
        
    </testcase>
    
    <testcase classname="freebayes (Test #7)" name="6" time="41.592910051345825">
        
            
            <system-out><![CDATA[
            
            ]]></system-out>
            <system-err><![CDATA[
            
            ]]></system-err>
        
    </testcase>
    
    <testcase classname="freebayes (Test #8)" name="7" time="39.7893853187561">
        
            
            <system-out><![CDATA[
            
            ]]></system-out>
            <system-err><![CDATA[
            
            ]]></system-err>
        
    </testcase>
    
    <testcase classname="kallisto_quant (Test #1)" name="0" time="53.598342180252075">
        
            
            <system-out><![CDATA[
            {"n_targets": 1,"n_bootstraps": 0,"n_processed": 100,"n_pseudoaligned": 100,"n_unique": 100,"p_pseudoaligned": 100.0,"p_unique": 100.0,"kallisto_version": "0.48.0","index_version": 10,"start_time": "Sun Mar 16 01:32:00 2025","call": "kallisto quant -i reference.kallisto --bootstrap-samples 0 --seed 42 --threads 8 -o . /galaxy/server/database/objects/2/c/0/dataset_2c0e757d-dfb7-42b4-a6e4-2da2f9664163.dat /galaxy/server/database/objects/d/e/7/dataset_de7317ab-2657-4397-b1d4-1e2cc5dfada6.dat"}
            ]]></system-out>
            <system-err><![CDATA[
            [build] loading fasta file reference.fa[build] k-mer length: 31[build] counting k-mers ... done.[build] building target de Bruijn graph ...  done [build] creating equivalence classes ...  done[build] target de Bruijn graph has 1 contigs and contains 16269 k-mers [quant] fragment length distribution will be estimated from the data[index] k-mer length: 31[index] number of targets: 1[index] number of k-mers: 16,269[index] number of equivalence classes: 1[quant] running in paired-end mode[quant] will process pair 1: /galaxy/server/database/objects/2/c/0/dataset_2c0e757d-dfb7-42b4-a6e4-2da2f9664163.dat                             /galaxy/server/database/objects/d/e/7/dataset_de7317ab-2657-4397-b1d4-1e2cc5dfada6.dat[quant] finding pseudoalignments for the reads ... done[quant] processed 100 reads, 100 reads pseudoaligned[quant] estimated average fragment length: 499.12[   em] quantifying the abundances ... done[   em] the Expectation-Maximization algorithm ran for 52 rounds
            ]]></system-err>
        
    </testcase>
    
    <testcase classname="kallisto_quant (Test #2)" name="1" time="43.734580755233765">
        
            
            <system-out><![CDATA[
            {"n_targets": 1,"n_bootstraps": 0,"n_processed": 100,"n_pseudoaligned": 37,"n_unique": 37,"p_pseudoaligned": 37.0,"p_unique": 37.0,"kallisto_version": "0.48.0","index_version": 10,"start_time": "Sun Mar 16 01:32:46 2025","call": "kallisto quant -i reference.kallisto --bootstrap-samples 0 --seed 42 --threads 8 -o . --fr-stranded /galaxy/server/database/objects/2/c/a/dataset_2ca9d852-b9b1-4381-9909-23475b94c54a.dat /galaxy/server/database/objects/a/5/e/dataset_a5ea674a-00c3-41dd-893d-b0a0b1255006.dat"}
            ]]></system-out>
            <system-err><![CDATA[
            [build] loading fasta file reference.fa[build] k-mer length: 31[build] counting k-mers ... done.[build] building target de Bruijn graph ...  done [build] creating equivalence classes ...  done[build] target de Bruijn graph has 1 contigs and contains 16269 k-mers [quant] fragment length distribution will be estimated from the data[index] k-mer length: 31[index] number of targets: 1[index] number of k-mers: 16,269[index] number of equivalence classes: 1[quant] running in paired-end mode[quant] will process pair 1: /galaxy/server/database/objects/2/c/a/dataset_2ca9d852-b9b1-4381-9909-23475b94c54a.dat                             /galaxy/server/database/objects/a/5/e/dataset_a5ea674a-00c3-41dd-893d-b0a0b1255006.dat[quant] finding pseudoalignments for the reads ... done[quant] processed 100 reads, 37 reads pseudoaligned[quant] estimated average fragment length: 495.838[   em] quantifying the abundances ... done[   em] the Expectation-Maximization algorithm ran for 52 rounds
            ]]></system-err>
        
    </testcase>
    
    <testcase classname="kallisto_quant (Test #3)" name="2" time="48.49943709373474">
        
            
            <system-out><![CDATA[
            {"n_targets": 1,"n_bootstraps": 0,"n_processed": 100,"n_pseudoaligned": 100,"n_unique": 100,"p_pseudoaligned": 100.0,"p_unique": 100.0,"kallisto_version": "0.48.0","index_version": 10,"start_time": "Sun Mar 16 01:33:33 2025","call": "kallisto quant -i reference.kallisto --bootstrap-samples 0 --seed 42 --threads 8 -o . /galaxy/server/database/objects/c/9/f/dataset_c9fa9b73-bdf5-4a20-bcfe-f177b2be07d6.dat /galaxy/server/database/objects/7/1/0/dataset_7105e45b-de17-401f-a329-17da42813455.dat"}
            ]]></system-out>
            <system-err><![CDATA[
            [build] loading fasta file reference.fa[build] k-mer length: 31[build] counting k-mers ... done.[build] building target de Bruijn graph ...  done [build] creating equivalence classes ...  done[build] target de Bruijn graph has 1 contigs and contains 16269 k-mers [quant] fragment length distribution will be estimated from the data[index] k-mer length: 31[index] number of targets: 1[index] number of k-mers: 16,269[index] number of equivalence classes: 1[quant] running in paired-end mode[quant] will process pair 1: /galaxy/server/database/objects/c/9/f/dataset_c9fa9b73-bdf5-4a20-bcfe-f177b2be07d6.dat                             /galaxy/server/database/objects/7/1/0/dataset_7105e45b-de17-401f-a329-17da42813455.dat[quant] finding pseudoalignments for the reads ... done[quant] processed 100 reads, 100 reads pseudoaligned[quant] estimated average fragment length: 499.12[   em] quantifying the abundances ... done[   em] the Expectation-Maximization algorithm ran for 52 rounds
            ]]></system-err>
        
    </testcase>
    
    <testcase classname="kallisto_quant (Test #4)" name="3" time="40.00111746788025">
        
            
            <system-out><![CDATA[
            {"n_targets": 1,"n_bootstraps": 0,"n_processed": 100,"n_pseudoaligned": 100,"n_unique": 100,"p_pseudoaligned": 100.0,"p_unique": 100.0,"kallisto_version": "0.48.0","index_version": 10,"start_time": "Sun Mar 16 01:34:15 2025","call": "kallisto quant -i reference.kallisto --bootstrap-samples 0 --seed 42 --threads 8 -o . --single --fragment-length 200 --sd 20 /galaxy/server/database/objects/e/a/3/dataset_ea3f7521-9fcd-4991-9797-44fc6e792ef5.dat"}
            ]]></system-out>
            <system-err><![CDATA[
            [build] loading fasta file reference.fa[build] k-mer length: 31[build] counting k-mers ... done.[build] building target de Bruijn graph ...  done [build] creating equivalence classes ...  done[build] target de Bruijn graph has 1 contigs and contains 16269 k-mers [quant] fragment length distribution is truncated gaussian with mean = 200, sd = 20[index] k-mer length: 31[index] number of targets: 1[index] number of k-mers: 16,269[index] number of equivalence classes: 1[quant] running in single-end mode[quant] will process file 1: /galaxy/server/database/objects/e/a/3/dataset_ea3f7521-9fcd-4991-9797-44fc6e792ef5.dat[quant] finding pseudoalignments for the reads ... done[quant] processed 100 reads, 100 reads pseudoaligned[   em] quantifying the abundances ... done[   em] the Expectation-Maximization algorithm ran for 52 rounds
            ]]></system-err>
        
    </testcase>
    
    <testcase classname="kallisto_quant (Test #5)" name="4" time="47.12038040161133">
        
            
            <system-out><![CDATA[
            {"n_targets": 1,"n_bootstraps": 0,"n_processed": 200,"n_pseudoaligned": 200,"n_unique": 200,"p_pseudoaligned": 100.0,"p_unique": 100.0,"kallisto_version": "0.48.0","index_version": 10,"start_time": "Sun Mar 16 01:35:01 2025","call": "kallisto quant -i reference.kallisto --bootstrap-samples 0 --seed 42 --pseudobam -o . /galaxy/server/database/objects/7/f/5/dataset_7f5b1e54-77f9-4f51-8864-168304b2ddf3.dat /galaxy/server/database/objects/4/7/4/dataset_474ed2b3-3296-4525-81e4-68981d03aed7.dat"}
            ]]></system-out>
            <system-err><![CDATA[
            [build] loading fasta file reference.fa[build] k-mer length: 31[build] counting k-mers ... done.[build] building target de Bruijn graph ...  done [build] creating equivalence classes ...  done[build] target de Bruijn graph has 15 contigs and contains 16670 k-mers [quant] fragment length distribution will be estimated from the data[index] k-mer length: 31[index] number of targets: 1[index] number of k-mers: 16,670[index] number of equivalence classes: 1[quant] running in paired-end mode[quant] will process pair 1: /galaxy/server/database/objects/7/f/5/dataset_7f5b1e54-77f9-4f51-8864-168304b2ddf3.dat                             /galaxy/server/database/objects/4/7/4/dataset_474ed2b3-3296-4525-81e4-68981d03aed7.dat[quant] finding pseudoalignments for the reads ... done[quant] processed 200 reads, 200 reads pseudoaligned[quant] estimated average fragment length: 500.01[   em] quantifying the abundances ... done[   em] the Expectation-Maximization algorithm ran for 52 rounds[  bam] writing pseudoalignments to BAM format .. done
            ]]></system-err>
        
    </testcase>
    
    <testcase classname="kallisto_quant (Test #6)" name="5" time="13.612622737884521">
        
            <error type="error" message="Input staging problem: Traceback (most recent call last):
  File "/opt/hostedtoolcache/Python/3.12.9/x64/lib/python3.12/site-packages/galaxy/tool_util/verify/interactor.py", line 1434, in verify_tool
    stage_data_in_history(
  File "/opt/hostedtoolcache/Python/3.12.9/x64/lib/python3.12/site-packages/galaxy/tool_util/verify/interactor.py", line 175, in stage_data_in_history
    staging_interface.handle_jobs()
  File "/opt/hostedtoolcache/Python/3.12.9/x64/lib/python3.12/site-packages/galaxy/tool_util/verify/interactor.py", line 212, in handle_jobs
    self.galaxy_interactor.wait_for_job(job_response["id"], job_response["history_id"], self.maxseconds)
  File "/opt/hostedtoolcache/Python/3.12.9/x64/lib/python3.12/site-packages/galaxy/tool_util/verify/interactor.py", line 399, in wait_for_job
    self.wait_for(lambda: self.__job_ready(job_id, history_id), maxseconds=maxseconds)
  File "/opt/hostedtoolcache/Python/3.12.9/x64/lib/python3.12/site-packages/galaxy/tool_util/verify/interactor.py", line 403, in wait_for
    wait_on(func, what, walltime_exceeded)
  File "/opt/hostedtoolcache/Python/3.12.9/x64/lib/python3.12/site-packages/galaxy/tool_util/verify/wait.py", line 38, in wait_on
    value = function()
            ^^^^^^^^^^
  File "/opt/hostedtoolcache/Python/3.12.9/x64/lib/python3.12/site-packages/galaxy/tool_util/verify/interactor.py", line 399, in <lambda>
    self.wait_for(lambda: self.__job_ready(job_id, history_id), maxseconds=maxseconds)
                          ^^^^^^^^^^^^^^^^^^^^^^^^^^^^^^^^^^^^
  File "/opt/hostedtoolcache/Python/3.12.9/x64/lib/python3.12/site-packages/galaxy/tool_util/verify/interactor.py", line 747, in __job_ready
    return self._state_ready(job_id, error_msg="Job in error state.")
           ^^^^^^^^^^^^^^^^^^^^^^^^^^^^^^^^^^^^^^^^^^^^^^^^^^^^^^^^^^
  File "/opt/hostedtoolcache/Python/3.12.9/x64/lib/python3.12/site-packages/galaxy/tool_util/verify/interactor.py", line 839, in _state_ready
    raise Exception(
Exception: Job in error state.. tool_id: __DATA_FETCH__, exit_code: None, stderr: .
"><![CDATA[
                { "execution_problem": "Input staging problem: Traceback (most recent call last):\n  File \"/opt/hostedtoolcache/Python/3.12.9/x64/lib/python3.12/site-packages/galaxy/tool_util/verify/interactor.py\", line 1434, in verify_tool\n    stage_data_in_history(\n  File \"/opt/hostedtoolcache/Python/3.12.9/x64/lib/python3.12/site-packages/galaxy/tool_util/verify/interactor.py\", line 175, in stage_data_in_history\n    staging_interface.handle_jobs()\n  File \"/opt/hostedtoolcache/Python/3.12.9/x64/lib/python3.12/site-packages/galaxy/tool_util/verify/interactor.py\", line 212, in handle_jobs\n    self.galaxy_interactor.wait_for_job(job_response[\"id\"], job_response[\"history_id\"], self.maxseconds)\n  File \"/opt/hostedtoolcache/Python/3.12.9/x64/lib/python3.12/site-packages/galaxy/tool_util/verify/interactor.py\", line 399, in wait_for_job\n    self.wait_for(lambda: self.__job_ready(job_id, history_id), maxseconds=maxseconds)\n  File \"/opt/hostedtoolcache/Python/3.12.9/x64/lib/python3.12/site-packages/galaxy/tool_util/verify/interactor.py\", line 403, in wait_for\n    wait_on(func, what, walltime_exceeded)\n  File \"/opt/hostedtoolcache/Python/3.12.9/x64/lib/python3.12/site-packages/galaxy/tool_util/verify/wait.py\", line 38, in wait_on\n    value = function()\n            ^^^^^^^^^^\n  File \"/opt/hostedtoolcache/Python/3.12.9/x64/lib/python3.12/site-packages/galaxy/tool_util/verify/interactor.py\", line 399, in \u003clambda\u003e\n    self.wait_for(lambda: self.__job_ready(job_id, history_id), maxseconds=maxseconds)\n                          ^^^^^^^^^^^^^^^^^^^^^^^^^^^^^^^^^^^^\n  File \"/opt/hostedtoolcache/Python/3.12.9/x64/lib/python3.12/site-packages/galaxy/tool_util/verify/interactor.py\", line 747, in __job_ready\n    return self._state_ready(job_id, error_msg=\"Job in error state.\")\n           ^^^^^^^^^^^^^^^^^^^^^^^^^^^^^^^^^^^^^^^^^^^^^^^^^^^^^^^^^^\n  File \"/opt/hostedtoolcache/Python/3.12.9/x64/lib/python3.12/site-packages/galaxy/tool_util/verify/interactor.py\", line 839, in _state_ready\n    raise Exception(\nException: Job in error state.. tool_id: __DATA_FETCH__, exit_code: None, stderr: .\n", "status": "error", "test_index": 5, "time_seconds": 13.612622737884521, "tool_id": "kallisto_quant", "tool_version": "0.48.0+galaxy1"}
            ]]></error>
        
    </testcase>
    
    <testcase classname="kallisto_quant (Test #7)" name="6" time="14.239990234375">
        
            <error type="error" message="Input staging problem: Traceback (most recent call last):
  File "/opt/hostedtoolcache/Python/3.12.9/x64/lib/python3.12/site-packages/galaxy/tool_util/verify/interactor.py", line 1434, in verify_tool
    stage_data_in_history(
  File "/opt/hostedtoolcache/Python/3.12.9/x64/lib/python3.12/site-packages/galaxy/tool_util/verify/interactor.py", line 175, in stage_data_in_history
    staging_interface.handle_jobs()
  File "/opt/hostedtoolcache/Python/3.12.9/x64/lib/python3.12/site-packages/galaxy/tool_util/verify/interactor.py", line 212, in handle_jobs
    self.galaxy_interactor.wait_for_job(job_response["id"], job_response["history_id"], self.maxseconds)
  File "/opt/hostedtoolcache/Python/3.12.9/x64/lib/python3.12/site-packages/galaxy/tool_util/verify/interactor.py", line 399, in wait_for_job
    self.wait_for(lambda: self.__job_ready(job_id, history_id), maxseconds=maxseconds)
  File "/opt/hostedtoolcache/Python/3.12.9/x64/lib/python3.12/site-packages/galaxy/tool_util/verify/interactor.py", line 403, in wait_for
    wait_on(func, what, walltime_exceeded)
  File "/opt/hostedtoolcache/Python/3.12.9/x64/lib/python3.12/site-packages/galaxy/tool_util/verify/wait.py", line 38, in wait_on
    value = function()
            ^^^^^^^^^^
  File "/opt/hostedtoolcache/Python/3.12.9/x64/lib/python3.12/site-packages/galaxy/tool_util/verify/interactor.py", line 399, in <lambda>
    self.wait_for(lambda: self.__job_ready(job_id, history_id), maxseconds=maxseconds)
                          ^^^^^^^^^^^^^^^^^^^^^^^^^^^^^^^^^^^^
  File "/opt/hostedtoolcache/Python/3.12.9/x64/lib/python3.12/site-packages/galaxy/tool_util/verify/interactor.py", line 747, in __job_ready
    return self._state_ready(job_id, error_msg="Job in error state.")
           ^^^^^^^^^^^^^^^^^^^^^^^^^^^^^^^^^^^^^^^^^^^^^^^^^^^^^^^^^^
  File "/opt/hostedtoolcache/Python/3.12.9/x64/lib/python3.12/site-packages/galaxy/tool_util/verify/interactor.py", line 839, in _state_ready
    raise Exception(
Exception: Job in error state.. tool_id: __DATA_FETCH__, exit_code: None, stderr: .
"><![CDATA[
                { "execution_problem": "Input staging problem: Traceback (most recent call last):\n  File \"/opt/hostedtoolcache/Python/3.12.9/x64/lib/python3.12/site-packages/galaxy/tool_util/verify/interactor.py\", line 1434, in verify_tool\n    stage_data_in_history(\n  File \"/opt/hostedtoolcache/Python/3.12.9/x64/lib/python3.12/site-packages/galaxy/tool_util/verify/interactor.py\", line 175, in stage_data_in_history\n    staging_interface.handle_jobs()\n  File \"/opt/hostedtoolcache/Python/3.12.9/x64/lib/python3.12/site-packages/galaxy/tool_util/verify/interactor.py\", line 212, in handle_jobs\n    self.galaxy_interactor.wait_for_job(job_response[\"id\"], job_response[\"history_id\"], self.maxseconds)\n  File \"/opt/hostedtoolcache/Python/3.12.9/x64/lib/python3.12/site-packages/galaxy/tool_util/verify/interactor.py\", line 399, in wait_for_job\n    self.wait_for(lambda: self.__job_ready(job_id, history_id), maxseconds=maxseconds)\n  File \"/opt/hostedtoolcache/Python/3.12.9/x64/lib/python3.12/site-packages/galaxy/tool_util/verify/interactor.py\", line 403, in wait_for\n    wait_on(func, what, walltime_exceeded)\n  File \"/opt/hostedtoolcache/Python/3.12.9/x64/lib/python3.12/site-packages/galaxy/tool_util/verify/wait.py\", line 38, in wait_on\n    value = function()\n            ^^^^^^^^^^\n  File \"/opt/hostedtoolcache/Python/3.12.9/x64/lib/python3.12/site-packages/galaxy/tool_util/verify/interactor.py\", line 399, in \u003clambda\u003e\n    self.wait_for(lambda: self.__job_ready(job_id, history_id), maxseconds=maxseconds)\n                          ^^^^^^^^^^^^^^^^^^^^^^^^^^^^^^^^^^^^\n  File \"/opt/hostedtoolcache/Python/3.12.9/x64/lib/python3.12/site-packages/galaxy/tool_util/verify/interactor.py\", line 747, in __job_ready\n    return self._state_ready(job_id, error_msg=\"Job in error state.\")\n           ^^^^^^^^^^^^^^^^^^^^^^^^^^^^^^^^^^^^^^^^^^^^^^^^^^^^^^^^^^\n  File \"/opt/hostedtoolcache/Python/3.12.9/x64/lib/python3.12/site-packages/galaxy/tool_util/verify/interactor.py\", line 839, in _state_ready\n    raise Exception(\nException: Job in error state.. tool_id: __DATA_FETCH__, exit_code: None, stderr: .\n", "status": "error", "test_index": 6, "time_seconds": 14.239990234375, "tool_id": "kallisto_quant", "tool_version": "0.48.0+galaxy1"}
            ]]></error>
        
    </testcase>
    
    <testcase classname="kallisto_quant (Test #8)" name="7" time="62.63346552848816">
        
            
            <system-out><![CDATA[
            {"n_targets": 15,"n_bootstraps": 0,"n_processed": 10000,"n_pseudoaligned": 10000,"n_unique": 6937,"p_pseudoaligned": 100.0,"p_unique": 69.4,"kallisto_version": "0.48.0","index_version": 10,"start_time": "Sun Mar 16 01:36:32 2025","call": "kallisto quant -i reference.kallisto --bootstrap-samples 0 --seed 42 --threads 8 -o . --genomebam --gtf /galaxy/server/database/objects/a/0/5/dataset_a05110b2-8943-482c-befd-4e02109af706.dat --chromosomes /galaxy/server/database/objects/f/9/0/dataset_f9067f61-9ba7-414a-86e7-f37cb978d4e6.dat /galaxy/server/database/objects/c/5/5/dataset_c55592da-2f63-411e-b24f-679cedf68b95.dat /galaxy/server/database/objects/8/8/e/dataset_88e3a09b-1a05-4b81-bba8-28e0a10301df.dat"}
            ]]></system-out>
            <system-err><![CDATA[
            [build] loading fasta file reference.fa[build] k-mer length: 31[build] counting k-mers ... done.[build] building target de Bruijn graph ...  done [build] creating equivalence classes ...  done[build] target de Bruijn graph has 23 contigs and contains 18902 k-mers [quant] fragment length distribution will be estimated from the data[index] k-mer length: 31[index] number of targets: 15[index] number of k-mers: 18,902[index] number of equivalence classes: 22[quant] running in paired-end mode[quant] will process pair 1: /galaxy/server/database/objects/c/5/5/dataset_c55592da-2f63-411e-b24f-679cedf68b95.dat                             /galaxy/server/database/objects/8/8/e/dataset_88e3a09b-1a05-4b81-bba8-28e0a10301df.dat[quant] finding pseudoalignments for the reads ... done[quant] processed 10,000 reads, 10,000 reads pseudoaligned[quant] estimated average fragment length: 178.097[   em] quantifying the abundances ... done[   em] the Expectation-Maximization algorithm ran for 62 rounds[  bam] writing pseudoalignments to BAM format .. done[  bam] sorting BAM files .. done[  bam] indexing BAM file .. done
            ]]></system-err>
        
    </testcase>
    
    <testcase classname="minimap2 (Test #1)" name="0" time="14.328711748123169">
        
            <error type="error" message="Input staging problem: Traceback (most recent call last):
  File "/opt/hostedtoolcache/Python/3.12.9/x64/lib/python3.12/site-packages/galaxy/tool_util/verify/interactor.py", line 1434, in verify_tool
    stage_data_in_history(
  File "/opt/hostedtoolcache/Python/3.12.9/x64/lib/python3.12/site-packages/galaxy/tool_util/verify/interactor.py", line 175, in stage_data_in_history
    staging_interface.handle_jobs()
  File "/opt/hostedtoolcache/Python/3.12.9/x64/lib/python3.12/site-packages/galaxy/tool_util/verify/interactor.py", line 212, in handle_jobs
    self.galaxy_interactor.wait_for_job(job_response["id"], job_response["history_id"], self.maxseconds)
  File "/opt/hostedtoolcache/Python/3.12.9/x64/lib/python3.12/site-packages/galaxy/tool_util/verify/interactor.py", line 399, in wait_for_job
    self.wait_for(lambda: self.__job_ready(job_id, history_id), maxseconds=maxseconds)
  File "/opt/hostedtoolcache/Python/3.12.9/x64/lib/python3.12/site-packages/galaxy/tool_util/verify/interactor.py", line 403, in wait_for
    wait_on(func, what, walltime_exceeded)
  File "/opt/hostedtoolcache/Python/3.12.9/x64/lib/python3.12/site-packages/galaxy/tool_util/verify/wait.py", line 38, in wait_on
    value = function()
            ^^^^^^^^^^
  File "/opt/hostedtoolcache/Python/3.12.9/x64/lib/python3.12/site-packages/galaxy/tool_util/verify/interactor.py", line 399, in <lambda>
    self.wait_for(lambda: self.__job_ready(job_id, history_id), maxseconds=maxseconds)
                          ^^^^^^^^^^^^^^^^^^^^^^^^^^^^^^^^^^^^
  File "/opt/hostedtoolcache/Python/3.12.9/x64/lib/python3.12/site-packages/galaxy/tool_util/verify/interactor.py", line 747, in __job_ready
    return self._state_ready(job_id, error_msg="Job in error state.")
           ^^^^^^^^^^^^^^^^^^^^^^^^^^^^^^^^^^^^^^^^^^^^^^^^^^^^^^^^^^
  File "/opt/hostedtoolcache/Python/3.12.9/x64/lib/python3.12/site-packages/galaxy/tool_util/verify/interactor.py", line 839, in _state_ready
    raise Exception(
Exception: Job in error state.. tool_id: __DATA_FETCH__, exit_code: None, stderr: .
"><![CDATA[
                { "execution_problem": "Input staging problem: Traceback (most recent call last):\n  File \"/opt/hostedtoolcache/Python/3.12.9/x64/lib/python3.12/site-packages/galaxy/tool_util/verify/interactor.py\", line 1434, in verify_tool\n    stage_data_in_history(\n  File \"/opt/hostedtoolcache/Python/3.12.9/x64/lib/python3.12/site-packages/galaxy/tool_util/verify/interactor.py\", line 175, in stage_data_in_history\n    staging_interface.handle_jobs()\n  File \"/opt/hostedtoolcache/Python/3.12.9/x64/lib/python3.12/site-packages/galaxy/tool_util/verify/interactor.py\", line 212, in handle_jobs\n    self.galaxy_interactor.wait_for_job(job_response[\"id\"], job_response[\"history_id\"], self.maxseconds)\n  File \"/opt/hostedtoolcache/Python/3.12.9/x64/lib/python3.12/site-packages/galaxy/tool_util/verify/interactor.py\", line 399, in wait_for_job\n    self.wait_for(lambda: self.__job_ready(job_id, history_id), maxseconds=maxseconds)\n  File \"/opt/hostedtoolcache/Python/3.12.9/x64/lib/python3.12/site-packages/galaxy/tool_util/verify/interactor.py\", line 403, in wait_for\n    wait_on(func, what, walltime_exceeded)\n  File \"/opt/hostedtoolcache/Python/3.12.9/x64/lib/python3.12/site-packages/galaxy/tool_util/verify/wait.py\", line 38, in wait_on\n    value = function()\n            ^^^^^^^^^^\n  File \"/opt/hostedtoolcache/Python/3.12.9/x64/lib/python3.12/site-packages/galaxy/tool_util/verify/interactor.py\", line 399, in \u003clambda\u003e\n    self.wait_for(lambda: self.__job_ready(job_id, history_id), maxseconds=maxseconds)\n                          ^^^^^^^^^^^^^^^^^^^^^^^^^^^^^^^^^^^^\n  File \"/opt/hostedtoolcache/Python/3.12.9/x64/lib/python3.12/site-packages/galaxy/tool_util/verify/interactor.py\", line 747, in __job_ready\n    return self._state_ready(job_id, error_msg=\"Job in error state.\")\n           ^^^^^^^^^^^^^^^^^^^^^^^^^^^^^^^^^^^^^^^^^^^^^^^^^^^^^^^^^^\n  File \"/opt/hostedtoolcache/Python/3.12.9/x64/lib/python3.12/site-packages/galaxy/tool_util/verify/interactor.py\", line 839, in _state_ready\n    raise Exception(\nException: Job in error state.. tool_id: __DATA_FETCH__, exit_code: None, stderr: .\n", "status": "error", "test_index": 0, "time_seconds": 14.328711748123169, "tool_id": "minimap2", "tool_version": "2.28+galaxy1"}
            ]]></error>
        
    </testcase>
    
    <testcase classname="minimap2 (Test #2)" name="1" time="47.213064193725586">
        
            
            <system-out><![CDATA[
            
            ]]></system-out>
            <system-err><![CDATA[
            [M::mm_idx_gen::0.003*1.12] collected minimizers[M::mm_idx_gen::0.005*1.50] sorted minimizers[M::main::0.005*1.49] loaded/built the index for 1 target sequence(s)[M::mm_mapopt_update::0.005*1.49] mid_occ = 1000[M::mm_idx_stat] kmer size: 21; skip: 11; is_hpc: 0; #seq: 1[M::mm_idx_stat::0.005*1.47] distinct minimizers: 2777 (100.00% are singletons); average occurrences: 1.000; average spacing: 5.967; total length: 16569[M::worker_pipeline::0.007*1.67] mapped 100 sequences[M::main] Version: 2.28-r1209[M::main] CMD: minimap2 -x sr --q-occ-frac 0.01 -t 8 -a reference.fa /galaxy/server/database/objects/1/8/7/dataset_1878b537-5436-4eab-be84-33850e205ced.dat[M::main] Real time: 0.009 sec; CPU: 0.013 sec; Peak RSS: 0.004 GB
            ]]></system-err>
        
    </testcase>
    
    <testcase classname="minimap2 (Test #11)" name="10" time="42.98530292510986">
        
            
            <system-out><![CDATA[
            
            ]]></system-out>
            <system-err><![CDATA[
            [M::mm_idx_gen::0.038*1.00] collected minimizers[M::mm_idx_gen::0.049*2.19] sorted minimizers[M::main::0.049*2.19] loaded/built the index for 1 target sequence(s)[M::mm_mapopt_update::0.052*2.12] mid_occ = 50[M::mm_idx_stat] kmer size: 19; skip: 19; is_hpc: 0; #seq: 1[M::mm_idx_stat::0.054*2.07] distinct minimizers: 86298 (91.20% are singletons); average occurrences: 1.212; average spacing: 9.858; total length: 1031372[M::worker_pipeline::0.091*2.17] mapped 234 sequences[M::main] Version: 2.28-r1209[M::main] CMD: minimap2 -x map-hifi --q-occ-frac 0.01 -t 8 -a reference.fa /galaxy/server/database/objects/5/a/b/dataset_5ab044fe-d219-442e-9e60-b2f3c50528de.dat[M::main] Real time: 0.097 sec; CPU: 0.203 sec; Peak RSS: 0.015 GB
            ]]></system-err>
        
    </testcase>
    
    <testcase classname="minimap2 (Test #12)" name="11" time="42.777158975601196">
        
            
            <system-out><![CDATA[
            
            ]]></system-out>
            <system-err><![CDATA[
            [M::mm_idx_gen::0.020*1.00] collected minimizers[M::mm_idx_gen::0.026*2.06] sorted minimizers[M::main::0.026*2.06] loaded/built the index for 1 target sequence(s)[M::mm_mapopt_update::0.028*1.99] mid_occ = 62[M::mm_idx_stat] kmer size: 19; skip: 19; is_hpc: 0; #seq: 1[M::mm_idx_stat::0.029*1.95] distinct minimizers: 44423 (93.60% are singletons); average occurrences: 1.142; average spacing: 9.827; total length: 498556[M::worker_pipeline::0.065*2.16] mapped 234 sequences[M::main] Version: 2.28-r1209[M::main] CMD: minimap2 -x map-hifi --q-occ-frac 0.01 -t 8 -a reference.fa /galaxy/server/database/objects/6/a/c/dataset_6ac2ea14-7c6f-490e-baf9-93ab28c33d1a.dat[M::main] Real time: 0.070 sec; CPU: 0.143 sec; Peak RSS: 0.011 GB
            ]]></system-err>
        
    </testcase>
    
    <testcase classname="minimap2 (Test #13)" name="12" time="13.593772649765015">
        
            <error type="error" message="Input staging problem: Traceback (most recent call last):
  File "/opt/hostedtoolcache/Python/3.12.9/x64/lib/python3.12/site-packages/galaxy/tool_util/verify/interactor.py", line 1434, in verify_tool
    stage_data_in_history(
  File "/opt/hostedtoolcache/Python/3.12.9/x64/lib/python3.12/site-packages/galaxy/tool_util/verify/interactor.py", line 175, in stage_data_in_history
    staging_interface.handle_jobs()
  File "/opt/hostedtoolcache/Python/3.12.9/x64/lib/python3.12/site-packages/galaxy/tool_util/verify/interactor.py", line 212, in handle_jobs
    self.galaxy_interactor.wait_for_job(job_response["id"], job_response["history_id"], self.maxseconds)
  File "/opt/hostedtoolcache/Python/3.12.9/x64/lib/python3.12/site-packages/galaxy/tool_util/verify/interactor.py", line 399, in wait_for_job
    self.wait_for(lambda: self.__job_ready(job_id, history_id), maxseconds=maxseconds)
  File "/opt/hostedtoolcache/Python/3.12.9/x64/lib/python3.12/site-packages/galaxy/tool_util/verify/interactor.py", line 403, in wait_for
    wait_on(func, what, walltime_exceeded)
  File "/opt/hostedtoolcache/Python/3.12.9/x64/lib/python3.12/site-packages/galaxy/tool_util/verify/wait.py", line 38, in wait_on
    value = function()
            ^^^^^^^^^^
  File "/opt/hostedtoolcache/Python/3.12.9/x64/lib/python3.12/site-packages/galaxy/tool_util/verify/interactor.py", line 399, in <lambda>
    self.wait_for(lambda: self.__job_ready(job_id, history_id), maxseconds=maxseconds)
                          ^^^^^^^^^^^^^^^^^^^^^^^^^^^^^^^^^^^^
  File "/opt/hostedtoolcache/Python/3.12.9/x64/lib/python3.12/site-packages/galaxy/tool_util/verify/interactor.py", line 747, in __job_ready
    return self._state_ready(job_id, error_msg="Job in error state.")
           ^^^^^^^^^^^^^^^^^^^^^^^^^^^^^^^^^^^^^^^^^^^^^^^^^^^^^^^^^^
  File "/opt/hostedtoolcache/Python/3.12.9/x64/lib/python3.12/site-packages/galaxy/tool_util/verify/interactor.py", line 839, in _state_ready
    raise Exception(
Exception: Job in error state.. tool_id: __DATA_FETCH__, exit_code: None, stderr: .
"><![CDATA[
                { "execution_problem": "Input staging problem: Traceback (most recent call last):\n  File \"/opt/hostedtoolcache/Python/3.12.9/x64/lib/python3.12/site-packages/galaxy/tool_util/verify/interactor.py\", line 1434, in verify_tool\n    stage_data_in_history(\n  File \"/opt/hostedtoolcache/Python/3.12.9/x64/lib/python3.12/site-packages/galaxy/tool_util/verify/interactor.py\", line 175, in stage_data_in_history\n    staging_interface.handle_jobs()\n  File \"/opt/hostedtoolcache/Python/3.12.9/x64/lib/python3.12/site-packages/galaxy/tool_util/verify/interactor.py\", line 212, in handle_jobs\n    self.galaxy_interactor.wait_for_job(job_response[\"id\"], job_response[\"history_id\"], self.maxseconds)\n  File \"/opt/hostedtoolcache/Python/3.12.9/x64/lib/python3.12/site-packages/galaxy/tool_util/verify/interactor.py\", line 399, in wait_for_job\n    self.wait_for(lambda: self.__job_ready(job_id, history_id), maxseconds=maxseconds)\n  File \"/opt/hostedtoolcache/Python/3.12.9/x64/lib/python3.12/site-packages/galaxy/tool_util/verify/interactor.py\", line 403, in wait_for\n    wait_on(func, what, walltime_exceeded)\n  File \"/opt/hostedtoolcache/Python/3.12.9/x64/lib/python3.12/site-packages/galaxy/tool_util/verify/wait.py\", line 38, in wait_on\n    value = function()\n            ^^^^^^^^^^\n  File \"/opt/hostedtoolcache/Python/3.12.9/x64/lib/python3.12/site-packages/galaxy/tool_util/verify/interactor.py\", line 399, in \u003clambda\u003e\n    self.wait_for(lambda: self.__job_ready(job_id, history_id), maxseconds=maxseconds)\n                          ^^^^^^^^^^^^^^^^^^^^^^^^^^^^^^^^^^^^\n  File \"/opt/hostedtoolcache/Python/3.12.9/x64/lib/python3.12/site-packages/galaxy/tool_util/verify/interactor.py\", line 747, in __job_ready\n    return self._state_ready(job_id, error_msg=\"Job in error state.\")\n           ^^^^^^^^^^^^^^^^^^^^^^^^^^^^^^^^^^^^^^^^^^^^^^^^^^^^^^^^^^\n  File \"/opt/hostedtoolcache/Python/3.12.9/x64/lib/python3.12/site-packages/galaxy/tool_util/verify/interactor.py\", line 839, in _state_ready\n    raise Exception(\nException: Job in error state.. tool_id: __DATA_FETCH__, exit_code: None, stderr: .\n", "status": "error", "test_index": 12, "time_seconds": 13.593772649765015, "tool_id": "minimap2", "tool_version": "2.28+galaxy1"}
            ]]></error>
        
    </testcase>
    
    <testcase classname="minimap2 (Test #3)" name="2" time="45.63478374481201">
        
            
            <system-out><![CDATA[
            
            ]]></system-out>
            <system-err><![CDATA[
            [M::mm_idx_gen::0.004*0.98] collected minimizers[M::mm_idx_gen::0.006*1.65] sorted minimizers[M::main::0.006*1.64] loaded/built the index for 1 target sequence(s)[M::mm_mapopt_update::0.006*1.64] mid_occ = 1000[M::mm_idx_stat] kmer size: 21; skip: 11; is_hpc: 0; #seq: 1[M::mm_idx_stat::0.006*1.62] distinct minimizers: 2777 (100.00% are singletons); average occurrences: 1.000; average spacing: 5.967; total length: 16569[M::worker_pipeline::0.013*2.06] mapped 200 sequences[M::main] Version: 2.28-r1209[M::main] CMD: minimap2 -x sr --q-occ-frac 0.01 -t 8 -a reference.fa /galaxy/server/database/objects/6/b/9/dataset_6b997f93-78c3-45d9-872d-19872e8e37ab.dat /galaxy/server/database/objects/b/e/c/dataset_beca12c0-ab3a-4df2-845b-e3137c471e0b.dat[M::main] Real time: 0.014 sec; CPU: 0.027 sec; Peak RSS: 0.005 GB
            ]]></system-err>
        
    </testcase>
    
    <testcase classname="minimap2 (Test #4)" name="3" time="26.39443302154541">
        
            <error type="error" message="Input staging problem: Traceback (most recent call last):
  File "/opt/hostedtoolcache/Python/3.12.9/x64/lib/python3.12/site-packages/galaxy/tool_util/verify/interactor.py", line 1434, in verify_tool
    stage_data_in_history(
  File "/opt/hostedtoolcache/Python/3.12.9/x64/lib/python3.12/site-packages/galaxy/tool_util/verify/interactor.py", line 175, in stage_data_in_history
    staging_interface.handle_jobs()
  File "/opt/hostedtoolcache/Python/3.12.9/x64/lib/python3.12/site-packages/galaxy/tool_util/verify/interactor.py", line 212, in handle_jobs
    self.galaxy_interactor.wait_for_job(job_response["id"], job_response["history_id"], self.maxseconds)
  File "/opt/hostedtoolcache/Python/3.12.9/x64/lib/python3.12/site-packages/galaxy/tool_util/verify/interactor.py", line 399, in wait_for_job
    self.wait_for(lambda: self.__job_ready(job_id, history_id), maxseconds=maxseconds)
  File "/opt/hostedtoolcache/Python/3.12.9/x64/lib/python3.12/site-packages/galaxy/tool_util/verify/interactor.py", line 403, in wait_for
    wait_on(func, what, walltime_exceeded)
  File "/opt/hostedtoolcache/Python/3.12.9/x64/lib/python3.12/site-packages/galaxy/tool_util/verify/wait.py", line 38, in wait_on
    value = function()
            ^^^^^^^^^^
  File "/opt/hostedtoolcache/Python/3.12.9/x64/lib/python3.12/site-packages/galaxy/tool_util/verify/interactor.py", line 399, in <lambda>
    self.wait_for(lambda: self.__job_ready(job_id, history_id), maxseconds=maxseconds)
                          ^^^^^^^^^^^^^^^^^^^^^^^^^^^^^^^^^^^^
  File "/opt/hostedtoolcache/Python/3.12.9/x64/lib/python3.12/site-packages/galaxy/tool_util/verify/interactor.py", line 747, in __job_ready
    return self._state_ready(job_id, error_msg="Job in error state.")
           ^^^^^^^^^^^^^^^^^^^^^^^^^^^^^^^^^^^^^^^^^^^^^^^^^^^^^^^^^^
  File "/opt/hostedtoolcache/Python/3.12.9/x64/lib/python3.12/site-packages/galaxy/tool_util/verify/interactor.py", line 839, in _state_ready
    raise Exception(
Exception: Job in error state.. tool_id: __DATA_FETCH__, exit_code: None, stderr: .
"><![CDATA[
                { "execution_problem": "Input staging problem: Traceback (most recent call last):\n  File \"/opt/hostedtoolcache/Python/3.12.9/x64/lib/python3.12/site-packages/galaxy/tool_util/verify/interactor.py\", line 1434, in verify_tool\n    stage_data_in_history(\n  File \"/opt/hostedtoolcache/Python/3.12.9/x64/lib/python3.12/site-packages/galaxy/tool_util/verify/interactor.py\", line 175, in stage_data_in_history\n    staging_interface.handle_jobs()\n  File \"/opt/hostedtoolcache/Python/3.12.9/x64/lib/python3.12/site-packages/galaxy/tool_util/verify/interactor.py\", line 212, in handle_jobs\n    self.galaxy_interactor.wait_for_job(job_response[\"id\"], job_response[\"history_id\"], self.maxseconds)\n  File \"/opt/hostedtoolcache/Python/3.12.9/x64/lib/python3.12/site-packages/galaxy/tool_util/verify/interactor.py\", line 399, in wait_for_job\n    self.wait_for(lambda: self.__job_ready(job_id, history_id), maxseconds=maxseconds)\n  File \"/opt/hostedtoolcache/Python/3.12.9/x64/lib/python3.12/site-packages/galaxy/tool_util/verify/interactor.py\", line 403, in wait_for\n    wait_on(func, what, walltime_exceeded)\n  File \"/opt/hostedtoolcache/Python/3.12.9/x64/lib/python3.12/site-packages/galaxy/tool_util/verify/wait.py\", line 38, in wait_on\n    value = function()\n            ^^^^^^^^^^\n  File \"/opt/hostedtoolcache/Python/3.12.9/x64/lib/python3.12/site-packages/galaxy/tool_util/verify/interactor.py\", line 399, in \u003clambda\u003e\n    self.wait_for(lambda: self.__job_ready(job_id, history_id), maxseconds=maxseconds)\n                          ^^^^^^^^^^^^^^^^^^^^^^^^^^^^^^^^^^^^\n  File \"/opt/hostedtoolcache/Python/3.12.9/x64/lib/python3.12/site-packages/galaxy/tool_util/verify/interactor.py\", line 747, in __job_ready\n    return self._state_ready(job_id, error_msg=\"Job in error state.\")\n           ^^^^^^^^^^^^^^^^^^^^^^^^^^^^^^^^^^^^^^^^^^^^^^^^^^^^^^^^^^\n  File \"/opt/hostedtoolcache/Python/3.12.9/x64/lib/python3.12/site-packages/galaxy/tool_util/verify/interactor.py\", line 839, in _state_ready\n    raise Exception(\nException: Job in error state.. tool_id: __DATA_FETCH__, exit_code: None, stderr: .\n", "status": "error", "test_index": 3, "time_seconds": 26.39443302154541, "tool_id": "minimap2", "tool_version": "2.28+galaxy1"}
            ]]></error>
        
    </testcase>
    
    <testcase classname="minimap2 (Test #5)" name="4" time="46.47775316238403">
        
            
            <system-out><![CDATA[
            
            ]]></system-out>
            <system-err><![CDATA[
            [M::mm_idx_gen::0.004*1.11] collected minimizers[M::mm_idx_gen::0.005*1.74] sorted minimizers[M::main::0.005*1.73] loaded/built the index for 1 target sequence(s)[M::mm_mapopt_update::0.005*1.73] mid_occ = 1000[M::mm_idx_stat] kmer size: 21; skip: 11; is_hpc: 0; #seq: 1[M::mm_idx_stat::0.006*1.70] distinct minimizers: 2777 (100.00% are singletons); average occurrences: 1.000; average spacing: 5.967; total length: 16569[M::worker_pipeline::0.012*1.76] mapped 200 sequences[M::main] Version: 2.28-r1209[M::main] CMD: minimap2 -x sr --q-occ-frac 0.01 -t 8 -a reference.fa /galaxy/server/database/objects/b/f/a/dataset_bfafb9fd-cfbb-4415-89f7-36df195d0607.dat /galaxy/server/database/objects/c/2/0/dataset_c20401f0-a732-4cf9-a58a-bdce720d2451.dat[M::main] Real time: 0.014 sec; CPU: 0.022 sec; Peak RSS: 0.005 GB
            ]]></system-err>
        
    </testcase>
    
    <testcase classname="minimap2 (Test #6)" name="5" time="">
        
            <error type="error" message=""><![CDATA[
                { "status": "skip", "test_index": 5, "tool_id": "minimap2", "tool_version": "2.28+galaxy1"}
            ]]></error>
        
    </testcase>
    
    <testcase classname="minimap2 (Test #7)" name="6" time="">
        
            <error type="error" message=""><![CDATA[
                { "status": "skip", "test_index": 6, "tool_id": "minimap2", "tool_version": "2.28+galaxy1"}
            ]]></error>
        
    </testcase>
    
    <testcase classname="minimap2 (Test #8)" name="7" time="38.13740921020508">
        
            
            <system-out><![CDATA[
            
            ]]></system-out>
            <system-err><![CDATA[
            [M::mm_idx_gen::0.022*0.99] collected minimizers[M::mm_idx_gen::0.032*2.71] sorted minimizers[M::main::0.032*2.70] loaded/built the index for 25 target sequence(s)[M::mm_mapopt_update::0.034*2.58] mid_occ = 10[M::mm_idx_stat] kmer size: 15; skip: 5; is_hpc: 0; #seq: 25[M::mm_idx_stat::0.036*2.50] distinct minimizers: 80111 (99.87% are singletons); average occurrences: 1.002; average spacing: 2.935; total length: 235533[M::worker_pipeline::0.043*2.70] mapped 25 sequences[M::main] Version: 2.28-r1209[M::main] CMD: minimap2 -x ava-ont --q-occ-frac 0.01 -t 8 reference.fa /galaxy/server/database/objects/e/d/1/dataset_ed1c3ee1-8645-48c2-90b5-49cd5a6d0cbb.dat[M::main] Real time: 0.048 sec; CPU: 0.121 sec; Peak RSS: 0.012 GB
            ]]></system-err>
        
    </testcase>
    
    <testcase classname="minimap2 (Test #9)" name="8" time="38.110727310180664">
        
            
            <system-out><![CDATA[
            
            ]]></system-out>
            <system-err><![CDATA[
            [M::mm_idx_gen::0.004*0.90] collected minimizers[M::mm_idx_gen::0.006*1.70] sorted minimizers[M::main::0.006*1.69] loaded/built the index for 1 target sequence(s)[M::mm_mapopt_update::0.006*1.67] mid_occ = 10[M::mm_idx_stat] kmer size: 19; skip: 19; is_hpc: 0; #seq: 1[M::mm_idx_stat::0.006*1.65] distinct minimizers: 2920 (98.42% are singletons); average occurrences: 1.022; average spacing: 10.057; total length: 30000[M::worker_pipeline::0.034*1.10] mapped 1 sequences[M::main] Version: 2.28-r1209[M::main] CMD: minimap2 -DP -k19 -w19 -m200 --q-occ-frac 0.01 -t 8 -a reference.fa /galaxy/server/database/objects/0/6/5/dataset_065046b6-0559-42d8-b46c-5a15dbaf8fe3.dat[M::main] Real time: 0.035 sec; CPU: 0.038 sec; Peak RSS: 0.012 GB
            ]]></system-err>
        
    </testcase>
    
    <testcase classname="minimap2 (Test #10)" name="9" time="12.951516151428223">
        
            <error type="error" message="Input staging problem: Traceback (most recent call last):
  File "/opt/hostedtoolcache/Python/3.12.9/x64/lib/python3.12/site-packages/galaxy/tool_util/verify/interactor.py", line 1434, in verify_tool
    stage_data_in_history(
  File "/opt/hostedtoolcache/Python/3.12.9/x64/lib/python3.12/site-packages/galaxy/tool_util/verify/interactor.py", line 175, in stage_data_in_history
    staging_interface.handle_jobs()
  File "/opt/hostedtoolcache/Python/3.12.9/x64/lib/python3.12/site-packages/galaxy/tool_util/verify/interactor.py", line 212, in handle_jobs
    self.galaxy_interactor.wait_for_job(job_response["id"], job_response["history_id"], self.maxseconds)
  File "/opt/hostedtoolcache/Python/3.12.9/x64/lib/python3.12/site-packages/galaxy/tool_util/verify/interactor.py", line 399, in wait_for_job
    self.wait_for(lambda: self.__job_ready(job_id, history_id), maxseconds=maxseconds)
  File "/opt/hostedtoolcache/Python/3.12.9/x64/lib/python3.12/site-packages/galaxy/tool_util/verify/interactor.py", line 403, in wait_for
    wait_on(func, what, walltime_exceeded)
  File "/opt/hostedtoolcache/Python/3.12.9/x64/lib/python3.12/site-packages/galaxy/tool_util/verify/wait.py", line 38, in wait_on
    value = function()
            ^^^^^^^^^^
  File "/opt/hostedtoolcache/Python/3.12.9/x64/lib/python3.12/site-packages/galaxy/tool_util/verify/interactor.py", line 399, in <lambda>
    self.wait_for(lambda: self.__job_ready(job_id, history_id), maxseconds=maxseconds)
                          ^^^^^^^^^^^^^^^^^^^^^^^^^^^^^^^^^^^^
  File "/opt/hostedtoolcache/Python/3.12.9/x64/lib/python3.12/site-packages/galaxy/tool_util/verify/interactor.py", line 747, in __job_ready
    return self._state_ready(job_id, error_msg="Job in error state.")
           ^^^^^^^^^^^^^^^^^^^^^^^^^^^^^^^^^^^^^^^^^^^^^^^^^^^^^^^^^^
  File "/opt/hostedtoolcache/Python/3.12.9/x64/lib/python3.12/site-packages/galaxy/tool_util/verify/interactor.py", line 839, in _state_ready
    raise Exception(
Exception: Job in error state.. tool_id: __DATA_FETCH__, exit_code: None, stderr: .
"><![CDATA[
                { "execution_problem": "Input staging problem: Traceback (most recent call last):\n  File \"/opt/hostedtoolcache/Python/3.12.9/x64/lib/python3.12/site-packages/galaxy/tool_util/verify/interactor.py\", line 1434, in verify_tool\n    stage_data_in_history(\n  File \"/opt/hostedtoolcache/Python/3.12.9/x64/lib/python3.12/site-packages/galaxy/tool_util/verify/interactor.py\", line 175, in stage_data_in_history\n    staging_interface.handle_jobs()\n  File \"/opt/hostedtoolcache/Python/3.12.9/x64/lib/python3.12/site-packages/galaxy/tool_util/verify/interactor.py\", line 212, in handle_jobs\n    self.galaxy_interactor.wait_for_job(job_response[\"id\"], job_response[\"history_id\"], self.maxseconds)\n  File \"/opt/hostedtoolcache/Python/3.12.9/x64/lib/python3.12/site-packages/galaxy/tool_util/verify/interactor.py\", line 399, in wait_for_job\n    self.wait_for(lambda: self.__job_ready(job_id, history_id), maxseconds=maxseconds)\n  File \"/opt/hostedtoolcache/Python/3.12.9/x64/lib/python3.12/site-packages/galaxy/tool_util/verify/interactor.py\", line 403, in wait_for\n    wait_on(func, what, walltime_exceeded)\n  File \"/opt/hostedtoolcache/Python/3.12.9/x64/lib/python3.12/site-packages/galaxy/tool_util/verify/wait.py\", line 38, in wait_on\n    value = function()\n            ^^^^^^^^^^\n  File \"/opt/hostedtoolcache/Python/3.12.9/x64/lib/python3.12/site-packages/galaxy/tool_util/verify/interactor.py\", line 399, in \u003clambda\u003e\n    self.wait_for(lambda: self.__job_ready(job_id, history_id), maxseconds=maxseconds)\n                          ^^^^^^^^^^^^^^^^^^^^^^^^^^^^^^^^^^^^\n  File \"/opt/hostedtoolcache/Python/3.12.9/x64/lib/python3.12/site-packages/galaxy/tool_util/verify/interactor.py\", line 747, in __job_ready\n    return self._state_ready(job_id, error_msg=\"Job in error state.\")\n           ^^^^^^^^^^^^^^^^^^^^^^^^^^^^^^^^^^^^^^^^^^^^^^^^^^^^^^^^^^\n  File \"/opt/hostedtoolcache/Python/3.12.9/x64/lib/python3.12/site-packages/galaxy/tool_util/verify/interactor.py\", line 839, in _state_ready\n    raise Exception(\nException: Job in error state.. tool_id: __DATA_FETCH__, exit_code: None, stderr: .\n", "status": "error", "test_index": 9, "time_seconds": 12.951516151428223, "tool_id": "minimap2", "tool_version": "2.28+galaxy1"}
            ]]></error>
        
    </testcase>
    
    <testcase classname="mummer_dnadiff (Test #1)" name="0" time="56.45974612236023">
        
            
            <system-out><![CDATA[
            
            ]]></system-out>
            <system-err><![CDATA[
            Building alignmentsFiltering alignmentsExtracting alignment coordinatesAnalyzing SNPsExtracting alignment breakpointsGenerating report file
            ]]></system-err>
        
    </testcase>
    
    <testcase classname="pileup_interval (Test #1)" name="0" time="0.2907295227050781">
        
            <error type="error" message="Input staging problem: Traceback (most recent call last):
  File "/opt/hostedtoolcache/Python/3.12.9/x64/lib/python3.12/site-packages/galaxy/tool_util/verify/interactor.py", line 1434, in verify_tool
    stage_data_in_history(
  File "/opt/hostedtoolcache/Python/3.12.9/x64/lib/python3.12/site-packages/galaxy/tool_util/verify/interactor.py", line 163, in stage_data_in_history
    test_dict = galaxy_interactor.remote_to_input(
                ^^^^^^^^^^^^^^^^^^^^^^^^^^^^^^^^^^
  File "/opt/hostedtoolcache/Python/3.12.9/x64/lib/python3.12/site-packages/galaxy/tool_util/verify/interactor.py", line 582, in remote_to_input
    path_or_location = self._get_path_or_location(
                       ^^^^^^^^^^^^^^^^^^^^^^^^^^^
  File "/opt/hostedtoolcache/Python/3.12.9/x64/lib/python3.12/site-packages/galaxy/tool_util/verify/interactor.py", line 619, in _get_path_or_location
    path = self.test_data_download(
           ^^^^^^^^^^^^^^^^^^^^^^^^
  File "/opt/hostedtoolcache/Python/3.12.9/x64/lib/python3.12/site-packages/galaxy/tool_util/verify/interactor.py", line 525, in test_data_download
    raise AssertionError(f"Test input file ({filename}) cannot be found.")
AssertionError: Test input file (pileup_interval_in1.tabular) cannot be found.
"><![CDATA[
                { "execution_problem": "Input staging problem: Traceback (most recent call last):\n  File \"/opt/hostedtoolcache/Python/3.12.9/x64/lib/python3.12/site-packages/galaxy/tool_util/verify/interactor.py\", line 1434, in verify_tool\n    stage_data_in_history(\n  File \"/opt/hostedtoolcache/Python/3.12.9/x64/lib/python3.12/site-packages/galaxy/tool_util/verify/interactor.py\", line 163, in stage_data_in_history\n    test_dict = galaxy_interactor.remote_to_input(\n                ^^^^^^^^^^^^^^^^^^^^^^^^^^^^^^^^^^\n  File \"/opt/hostedtoolcache/Python/3.12.9/x64/lib/python3.12/site-packages/galaxy/tool_util/verify/interactor.py\", line 582, in remote_to_input\n    path_or_location = self._get_path_or_location(\n                       ^^^^^^^^^^^^^^^^^^^^^^^^^^^\n  File \"/opt/hostedtoolcache/Python/3.12.9/x64/lib/python3.12/site-packages/galaxy/tool_util/verify/interactor.py\", line 619, in _get_path_or_location\n    path = self.test_data_download(\n           ^^^^^^^^^^^^^^^^^^^^^^^^\n  File \"/opt/hostedtoolcache/Python/3.12.9/x64/lib/python3.12/site-packages/galaxy/tool_util/verify/interactor.py\", line 525, in test_data_download\n    raise AssertionError(f\"Test input file ({filename}) cannot be found.\")\nAssertionError: Test input file (pileup_interval_in1.tabular) cannot be found.\n", "status": "error", "test_index": 0, "time_seconds": 0.2907295227050781, "tool_id": "pileup_interval", "tool_version": "1.0.3"}
            ]]></error>
        
    </testcase>
    
    <testcase classname="pileup_interval (Test #2)" name="1" time="0.14892125129699707">
        
            <error type="error" message="Input staging problem: Traceback (most recent call last):
  File "/opt/hostedtoolcache/Python/3.12.9/x64/lib/python3.12/site-packages/galaxy/tool_util/verify/interactor.py", line 1434, in verify_tool
    stage_data_in_history(
  File "/opt/hostedtoolcache/Python/3.12.9/x64/lib/python3.12/site-packages/galaxy/tool_util/verify/interactor.py", line 163, in stage_data_in_history
    test_dict = galaxy_interactor.remote_to_input(
                ^^^^^^^^^^^^^^^^^^^^^^^^^^^^^^^^^^
  File "/opt/hostedtoolcache/Python/3.12.9/x64/lib/python3.12/site-packages/galaxy/tool_util/verify/interactor.py", line 582, in remote_to_input
    path_or_location = self._get_path_or_location(
                       ^^^^^^^^^^^^^^^^^^^^^^^^^^^
  File "/opt/hostedtoolcache/Python/3.12.9/x64/lib/python3.12/site-packages/galaxy/tool_util/verify/interactor.py", line 619, in _get_path_or_location
    path = self.test_data_download(
           ^^^^^^^^^^^^^^^^^^^^^^^^
  File "/opt/hostedtoolcache/Python/3.12.9/x64/lib/python3.12/site-packages/galaxy/tool_util/verify/interactor.py", line 525, in test_data_download
    raise AssertionError(f"Test input file ({filename}) cannot be found.")
AssertionError: Test input file (pileup_interval_in2.tabular) cannot be found.
"><![CDATA[
                { "execution_problem": "Input staging problem: Traceback (most recent call last):\n  File \"/opt/hostedtoolcache/Python/3.12.9/x64/lib/python3.12/site-packages/galaxy/tool_util/verify/interactor.py\", line 1434, in verify_tool\n    stage_data_in_history(\n  File \"/opt/hostedtoolcache/Python/3.12.9/x64/lib/python3.12/site-packages/galaxy/tool_util/verify/interactor.py\", line 163, in stage_data_in_history\n    test_dict = galaxy_interactor.remote_to_input(\n                ^^^^^^^^^^^^^^^^^^^^^^^^^^^^^^^^^^\n  File \"/opt/hostedtoolcache/Python/3.12.9/x64/lib/python3.12/site-packages/galaxy/tool_util/verify/interactor.py\", line 582, in remote_to_input\n    path_or_location = self._get_path_or_location(\n                       ^^^^^^^^^^^^^^^^^^^^^^^^^^^\n  File \"/opt/hostedtoolcache/Python/3.12.9/x64/lib/python3.12/site-packages/galaxy/tool_util/verify/interactor.py\", line 619, in _get_path_or_location\n    path = self.test_data_download(\n           ^^^^^^^^^^^^^^^^^^^^^^^^\n  File \"/opt/hostedtoolcache/Python/3.12.9/x64/lib/python3.12/site-packages/galaxy/tool_util/verify/interactor.py\", line 525, in test_data_download\n    raise AssertionError(f\"Test input file ({filename}) cannot be found.\")\nAssertionError: Test input file (pileup_interval_in2.tabular) cannot be found.\n", "status": "error", "test_index": 1, "time_seconds": 0.14892125129699707, "tool_id": "pileup_interval", "tool_version": "1.0.3"}
            ]]></error>
        
    </testcase>
    
    <testcase classname="pileup_interval (Test #3)" name="2" time="0.15404009819030762">
        
            <error type="error" message="Input staging problem: Traceback (most recent call last):
  File "/opt/hostedtoolcache/Python/3.12.9/x64/lib/python3.12/site-packages/galaxy/tool_util/verify/interactor.py", line 1434, in verify_tool
    stage_data_in_history(
  File "/opt/hostedtoolcache/Python/3.12.9/x64/lib/python3.12/site-packages/galaxy/tool_util/verify/interactor.py", line 163, in stage_data_in_history
    test_dict = galaxy_interactor.remote_to_input(
                ^^^^^^^^^^^^^^^^^^^^^^^^^^^^^^^^^^
  File "/opt/hostedtoolcache/Python/3.12.9/x64/lib/python3.12/site-packages/galaxy/tool_util/verify/interactor.py", line 582, in remote_to_input
    path_or_location = self._get_path_or_location(
                       ^^^^^^^^^^^^^^^^^^^^^^^^^^^
  File "/opt/hostedtoolcache/Python/3.12.9/x64/lib/python3.12/site-packages/galaxy/tool_util/verify/interactor.py", line 619, in _get_path_or_location
    path = self.test_data_download(
           ^^^^^^^^^^^^^^^^^^^^^^^^
  File "/opt/hostedtoolcache/Python/3.12.9/x64/lib/python3.12/site-packages/galaxy/tool_util/verify/interactor.py", line 525, in test_data_download
    raise AssertionError(f"Test input file ({filename}) cannot be found.")
AssertionError: Test input file (pileup_interval_in2.tabular) cannot be found.
"><![CDATA[
                { "execution_problem": "Input staging problem: Traceback (most recent call last):\n  File \"/opt/hostedtoolcache/Python/3.12.9/x64/lib/python3.12/site-packages/galaxy/tool_util/verify/interactor.py\", line 1434, in verify_tool\n    stage_data_in_history(\n  File \"/opt/hostedtoolcache/Python/3.12.9/x64/lib/python3.12/site-packages/galaxy/tool_util/verify/interactor.py\", line 163, in stage_data_in_history\n    test_dict = galaxy_interactor.remote_to_input(\n                ^^^^^^^^^^^^^^^^^^^^^^^^^^^^^^^^^^\n  File \"/opt/hostedtoolcache/Python/3.12.9/x64/lib/python3.12/site-packages/galaxy/tool_util/verify/interactor.py\", line 582, in remote_to_input\n    path_or_location = self._get_path_or_location(\n                       ^^^^^^^^^^^^^^^^^^^^^^^^^^^\n  File \"/opt/hostedtoolcache/Python/3.12.9/x64/lib/python3.12/site-packages/galaxy/tool_util/verify/interactor.py\", line 619, in _get_path_or_location\n    path = self.test_data_download(\n           ^^^^^^^^^^^^^^^^^^^^^^^^\n  File \"/opt/hostedtoolcache/Python/3.12.9/x64/lib/python3.12/site-packages/galaxy/tool_util/verify/interactor.py\", line 525, in test_data_download\n    raise AssertionError(f\"Test input file ({filename}) cannot be found.\")\nAssertionError: Test input file (pileup_interval_in2.tabular) cannot be found.\n", "status": "error", "test_index": 2, "time_seconds": 0.15404009819030762, "tool_id": "pileup_interval", "tool_version": "1.0.3"}
            ]]></error>
        
    </testcase>
    
    <testcase classname="poretools_squiggle (Test #1)" name="0" time="94.19243860244751">
        
            
            <system-out><![CDATA[
            
            ]]></system-out>
            <system-err><![CDATA[
            
            ]]></system-err>
        
    </testcase>
    
    <testcase classname="poretools_squiggle (Test #2)" name="1" time="54.96156549453735">
        
            
            <system-out><![CDATA[
            
            ]]></system-out>
            <system-err><![CDATA[
            
            ]]></system-err>
        
    </testcase>
    
    <testcase classname="samtools_depth (Test #1)" name="0" time="85.72575163841248">
        
            
            <system-out><![CDATA[
            
            ]]></system-out>
            <system-err><![CDATA[
            
            ]]></system-err>
        
    </testcase>
    
    <testcase classname="samtools_depth (Test #2)" name="1" time="37.010178089141846">
        
            
            <system-out><![CDATA[
            
            ]]></system-out>
            <system-err><![CDATA[
            
            ]]></system-err>
        
    </testcase>
    
    <testcase classname="samtools_depth (Test #3)" name="2" time="42.24447703361511">
        
            
            <system-out><![CDATA[
            
            ]]></system-out>
            <system-err><![CDATA[
            
            ]]></system-err>
        
    </testcase>
    
    <testcase classname="samtools_depth (Test #4)" name="3" time="30.84869623184204">
        
            
                <error type="error" message="Tool exit code: None"><![CDATA[
                    { "inputs": {  "basequality": "11",  "input_bams": [   {    "id": "eb6bcdac1aeb9a02",    "src": "hda"   },   {    "id": "2223c815ada4e564",    "src": "hda"   }  ],  "mapquality": "12",  "maxdepth": "4",  "minlength": "10" }, "job": {  "command_line": "ln -s \u0027/galaxy/server/database/objects/9/f/b/dataset_9fb7f88e-9c35-4d77-ac86-e767167e8aaa.dat\u0027 \u00270\u0027 \u0026\u0026 ln -s \u0027/galaxy/server/database/objects/_metadata_files/a/5/b/metadata_a5b599d6-154d-43e4-b7f1-bcfcbdb50677.dat\u0027 \u00270.bai\u0027 \u0026\u0026 ln -s \u0027/galaxy/server/database/objects/2/c/f/dataset_2cf6e9a8-cf1d-4fe6-b740-59f6849911ea.dat\u0027 \u00271\u0027 \u0026\u0026 ln -s \u0027/galaxy/server/database/objects/_metadata_files/f/4/7/metadata_f47ec4e7-4d99-4b95-813b-ec6c7c7a25f7.dat\u0027 \u00271.bai\u0027 \u0026\u0026   samtools depth  -l 10 -m 4 -q 11 -Q 12 0 1 \u003e \u0027/galaxy/server/database/objects/3/4/2/dataset_3423e04a-d61c-41ff-aaf8-6c088c6d0a26.dat\u0027",  "command_version": null,  "copied_from_job_id": null,  "create_time": "2025-03-16T01:03:48.054045",  "dependencies": [],  "exit_code": null,  "external_id": "gxy-n56xc",  "galaxy_version": "24.1",  "handler": null,  "history_id": "e3af7b765977f2b0",  "id": "89d89b8a254d6290",  "inputs": {   "input_bams": {    "id": "eb6bcdac1aeb9a02",    "src": "hda",    "uuid": "9fb7f88e-9c35-4d77-ac86-e767167e8aaa"   },   "input_bams1": {    "id": "eb6bcdac1aeb9a02",    "src": "hda",    "uuid": "9fb7f88e-9c35-4d77-ac86-e767167e8aaa"   },   "input_bams2": {    "id": "2223c815ada4e564",    "src": "hda",    "uuid": "2cf6e9a8-cf1d-4fe6-b740-59f6849911ea"   }  },  "job_messages": null,  "job_metrics": [],  "job_runner_name": null,  "job_stderr": null,  "job_stdout": null,  "model_class": "Job",  "output_collections": {},  "outputs": {   "output": {    "id": "89d89b8a254d6290",    "src": "hda",    "uuid": "3423e04a-d61c-41ff-aaf8-6c088c6d0a26"   }  },  "params": {   "__input_ext": "\"bam\"",   "all": "\"\"",   "basequality": "\"11\"",   "chromInfo": "\"/cvmfs/data.galaxyproject.org/managed/len/ucsc/?.len\"",   "cond_region": "{\"__current_case__\": 0, \"select_region\": \"no\"}",   "dbkey": "\"?\"",   "mapquality": "\"12\"",   "maxdepth": "\"4\"",   "minlength": "\"10\""  },  "state": "error",  "stderr": "",  "stdout": "",  "tool_id": "toolshed.g2.bx.psu.edu/repos/iuc/samtools_depth/samtools_depth/1.9",  "tool_stderr": "",  "tool_stdout": "",  "update_time": "2025-03-16T01:03:53.517932",  "user_email": "tests@fake.org" }, "output_problems": [  "Job in error state.. tool_id: toolshed.g2.bx.psu.edu/repos/iuc/samtools_depth/samtools_depth/1.9, exit_code: None, stderr: .",  "Job in error state.. tool_id: toolshed.g2.bx.psu.edu/repos/iuc/samtools_depth/samtools_depth/1.9, exit_code: None, stderr: ." ], "status": "failure", "test_index": 3, "time_seconds": 30.84869623184204, "tool_id": "samtools_depth", "tool_version": "1.9"}
                ]]></error>
            
            <system-out><![CDATA[
            
            ]]></system-out>
            <system-err><![CDATA[
            
            ]]></system-err>
        
    </testcase>
    
    <testcase classname="samtools_rmdup (Test #1)" name="0" time="44.75985598564148">
        
            
            <system-out><![CDATA[
            
            ]]></system-out>
            <system-err><![CDATA[
            [bam_rmdup_core] processing reference chrM...
            ]]></system-err>
        
    </testcase>
    
    <testcase classname="vcfcombine (Test #1)" name="0" time="49.34020781517029">
        
            
            <system-out><![CDATA[
            
            ]]></system-out>
            <system-err><![CDATA[
            
            ]]></system-err>
        
    </testcase>
    
</testsuite>